Workbook

Sheet 1. Overview
B2: TR4 — Where does the PV energy go?
B3: Prosumers vs. pure customers — every kWh traced from the raw model inputs
B5: Purpose
B6: This workbook accounts for every kWh of PV generated on transformer TR4 over one representative day, and it is fully auditable: nothing is hand-typed except the raw model outputs. Follow the data chain below — each step is a live formula, so changing any raw number updates everything.
B10: The data chain (how each number is built)
B11: Sheet 3 · Raw PV per load | C11: The PV profile of every connection, 48 half-hours. Copied verbatim from TR4_load_PV_48periods.xlsx (sheet PV_generation_kW). Customers = 0.
B12: Sheet 4 · Raw load per load | C12: The load profile of every connection, 48 half-hours, tagged prosumer / customer. Copied from TR4_load_PV_48periods.xlsx (sheet Load_P_kW).
B13: Sheet 5 · Raw batt charge | C13: Charging power of every battery, 48 half-hours. Copied from the rolling dispatch TR4_analysis_data.xlsx (sheet Charge_kW).
B14: Sheet 6 · Raw batt discharge | C14: Discharging power of every battery. Copied from the same run (Discharge_kW).
B15: Sheet 7 · PV allocation | C15: Per half-hour: the five blue inputs are AGGREGATED from sheets 3–6 by SUM / SUMIF; the amber columns then split the PV by the priority rule.
B16: Sheets 1 & 8 · Results | C16: Daily totals (Σ×0.5 h) and shares. Every headline cell links to sheet 7.
B18: The aggregation formulas (sheet 7, per half-hour)
B19: PV (all)
B20: prosumer load
B21: customer load
B22: battery charge
B23: battery discharge
B25: Headline results (all linked live to sheet 7)
B26: Quantity | C26: Value | D26: Unit
B27: Prosumers (PV + battery) | C27: 46 | D27: connections
B28: Pure customers (load only) | C28: 29 | D28: connections
B29: PV generated | C29: ='7. PV allocation (per period)'!C53 -> 1162.9933 | D29: kWh/day
B30: PV → prosumers' own load (direct) | C30: ='7. PV allocation (per period)'!I53 -> 218.51225 | D30: kWh/day
B31: PV → battery storage | C31: ='7. PV allocation (per period)'!J53 -> 155.7538 | D31: kWh/day
B32: PV → customers | C32: ='7. PV allocation (per period)'!K53 -> 100.76545 | D32: kWh/day
B33: PV → export to grid | C33: ='7. PV allocation (per period)'!L53 -> 687.9618 | D33: kWh/day
B34: PV share reaching customers | C34: ='7. PV allocation (per period)'!K53/'7. PV allocation (per period)'!C53 -> 0.08664319 | D34: % of PV
B35: Customer load covered by PV | C35: ='7. PV allocation (per period)'!K53/'7. PV allocation (per period)'!E53 -> 0.49701075 | D35: % of customer load
B36: Customer load covered by grid | C36: ='7. PV allocation (per period)'!M53/'7. PV allocation (per period)'!E53 -> 0.50298925 | D36: % of customer load
B39: Colour key & provenance
B40: • LIGHT-BLUE cell = data belonging to a prosumer (its rooftop PV, load, or battery). WHITE = a pure customer (load only). On sheet 7: VIOLET = value aggregated live from the raw sheets (SUM/SUMIF); AMBER = allocation formula; GREEN = daily total (Σ × 0.5 h).
B41: • Per-load PV & load profiles: results/tables/TR4_load_PV_48periods.xlsx (built from OpData.xls).
B42: • Per-battery charge/discharge: TR4_analysis/01_DAILY_ROLLING_DISPATCH/TR4_analysis_data.xlsx (exact-QCP rolling dispatch, RunFOR_Rolling, CPLEX).
B43: • Load classification (PV size > 0 = prosumer): sheet 'Customers' of the load/PV workbook.
B44: • Method note: priority energy allocation per half-hour; downstream network + battery round-trip losses (~3–4% of PV) are not separated out in the per-period disposition.

Sheet 2. Load classification
A1: TR4 load classification — 75 connections
A2: 46 prosumers (PV + battery) · 29 pure customers (load only)
A4: ID | B4: Load name | C4: Bus | D4: Phase | E4: PV size (kW) | F4: Type
A5: 380 | B5: Load_TR4_F1_1 | C5: TR4_one38 | D5: 2 | E5: 0 | F5: customer
A6: 387 | B6: Load_TR4_F1_16 | C6: TR4_one280 | D6: 1 | E6: 0 | F6: customer
A7: 388 | B7: Load_TR4_F1_17 | C7: TR4_one287 | D7: 2 | E7: 0 | F7: customer
A8: 390 | B8: Load_TR4_F1_19 | C8: TR4_one313 | D8: 1 | E8: 0 | F8: customer
A9: 391 | B9: Load_TR4_F1_2 | C9: TR4_one42 | D9: 2 | E9: 0 | F9: customer
A10: 396 | B10: Load_TR4_F1_24 | C10: TR4_one346 | D10: 3 | E10: 0 | F10: customer
A11: 397 | B11: Load_TR4_F1_25 | C11: TR4_one363 | D11: 3 | E11: 0 | F11: customer
A12: 399 | B12: Load_TR4_F1_27 | C12: TR4_one371 | D12: 3 | E12: 0 | F12: customer
A13: 400 | B13: Load_TR4_F1_28 | C13: TR4_one375 | D13: 3 | E13: 0 | F13: customer
A14: 406 | B14: Load_TR4_F1_33 | C14: TR4_one469 | D14: 1 | E14: 0 | F14: customer
A15: 407 | B15: Load_TR4_F1_34 | C15: TR4_one477 | D15: 1 | E15: 0 | F15: customer
A16: 409 | B16: Load_TR4_F1_36 | C16: TR4_one482 | D16: 2 | E16: 0 | F16: customer
... A79: 454 | B79: Load_TR4_F3_9 | C79: TR4_three160 | D79: 3 | E79: 4 | F79: prosumer

Sheet 3. Raw PV per load
A1: Raw PV per load
A2: Verbatim copy of PV_generation_kW (TR4_load_PV_48periods.xlsx). One row per connection, 48 half-hours (kW).
A4: Load name | B4: Type | C4: p1 | D4: p2 | E4: p3 | F4: p4 | G4: p5 | H4: p6 | I4: p7 | J4: p8 | K4: p9 | L4: p10 | M4: p11 | N4: p12 | O4: p13 | P4: p14 | Q4: p15 | R4: p16 | S4: p17 | T4: p18 | U4: p19 | V4: p20 | W4: p21 | X4: p22 | Y4: p23 | Z4: p24 | AA4: p25 | AB4: p26 | AC4: p27 | AD4: p28 | AE4: p29 | AF4: p30 | AG4: p31 | AH4: p32 | AI4: p33 | AJ4: p34 | AK4: p35 | AL4: p36 | AM4: p37 | AN4: p38 | AO4: p39 | AP4: p40 | AQ4: p41 | AR4: p42 | AS4: p43 | AT4: p44 | AU4: p45 | AV4: p46 | AW4: p47 | AX4: p48
A5: Load_TR4_F1_1 | B5: customer | C5: 0 | D5: 0 | E5: 0 | F5: 0 | G5: 0 | H5: 0 | I5: 0 | J5: 0 | K5: 0 | L5: 0 | M5: 0 | N5: 0 | O5: 0 | P5: 0 | Q5: 0 | R5: 0 | S5: 0 | T5: 0 | U5: 0 | V5: 0 | W5: 0 | X5: 0 | Y5: 0 | Z5: 0 | AA5: 0 | AB5: 0 | AC5: 0 | AD5: 0 | AE5: 0 | AF5: 0 | AG5: 0 | AH5: 0 | AI5: 0 | AJ5: 0 | AK5: 0 | AL5: 0 | AM5: 0 | AN5: 0 | AO5: 0 | AP5: 0 | AQ5: 0 | AR5: 0 | AS5: 0 | AT5: 0 | AU5: 0 | AV5: 0 | AW5: 0 | AX5: 0
A6: Load_TR4_F1_10 | B6: prosumer | C6: 0 | D6: 0 | E6: 0 | F6: 0 | G6: 0 | H6: 0 | I6: 0 | J6: 0.003 | K6: 0.0435 | L6: 0.2035 | M6: 0.4037 | N6: 0.6491 | O6: 0.9169 | P6: 1.188 | Q6: 1.4577 | R6: 1.7278 | S6: 1.9813 | T6: 2.2196 | U6: 2.4225 | V6: 2.5956 | W6: 2.7475 | X6: 2.8729 | Y6: 2.9619 | Z6: 3.0009 | AA6: 3.0122 | AB6: 2.991 | AC6: 2.92 | AD6: 2.8117 | AE6: 2.6823 | AF6: 2.5184 | AG6: 2.3442 | AH6: 2.1346 | AI6: 1.8986 | AJ6: 1.6136 | AK6: 1.3468 | AL6: 1.0727 | AM6: 0.8076 | AN6: 0.5519 | AO6: 0.3223 | AP6: 0.0938 | AQ6: 0.0173 | AR6: 0 | AS6: 0 | AT6: 0 | AU6: 0 | AV6: 0 | AW6: 0 | AX6: 0
A7: Load_TR4_F1_11 | B7: prosumer | C7: 0 | D7: 0 | E7: 0 | F7: 0 | G7: 0 | H7: 0 | I7: 0 | J7: 0.0026 | K7: 0.0373 | L7: 0.1744 | M7: 0.346 | N7: 0.5564 | O7: 0.7859 | P7: 1.0183 | Q7: 1.2495 | R7: 1.481 | S7: 1.6982 | T7: 1.9025 | U7: 2.0764 | V7: 2.2248 | W7: 2.355 | X7: 2.4625 | Y7: 2.5387 | Z7: 2.5722 | AA7: 2.5819 | AB7: 2.5637 | AC7: 2.5029 | AD7: 2.41 | AE7: 2.2991 | AF7: 2.1586 | AG7: 2.0093 | AH7: 1.8297 | AI7: 1.6274 | AJ7: 1.3831 | AK7: 1.1544 | AL7: 0.9195 | AM7: 0.6922 | AN7: 0.4731 | AO7: 0.2762 | AP7: 0.0804 | AQ7: 0.0148 | AR7: 0 | AS7: 0 | AT7: 0 | AU7: 0 | AV7: 0 | AW7: 0 | AX7: 0
A8: Load_TR4_F1_12 | B8: prosumer | C8: 0 | D8: 0 | E8: 0 | F8: 0 | G8: 0 | H8: 0 | I8: 0 | J8: 0.0034 | K8: 0.0497 | L8: 0.2326 | M8: 0.4613 | N8: 0.7419 | O8: 1.0479 | P8: 1.3577 | Q8: 1.666 | R8: 1.9746 | S8: 2.2643 | T8: 2.5367 | U8: 2.7686 | V8: 2.9664 | W8: 3.14 | X8: 3.2833 | Y8: 3.385 | Z8: 3.4296 | AA8: 3.4425 | AB8: 3.4183 | AC8: 3.3372 | AD8: 3.2133 | AE8: 3.0655 | AF8: 2.8782 | AG8: 2.6791 | AH8: 2.4396 | AI8: 2.1698 | AJ8: 1.8441 | AK8: 1.5392 | AL8: 1.2259 | AM8: 0.9229 | AN8: 0.6308 | AO8: 0.3683 | AP8: 0.1072 | AQ8: 0.0198 | AR8: 0 | AS8: 0 | AT8: 0 | AU8: 0 | AV8: 0 | AW8: 0 | AX8: 0
A9: Load_TR4_F1_13 | B9: prosumer | C9: 0 | D9: 0 | E9: 0 | F9: 0 | G9: 0 | H9: 0 | I9: 0 | J9: 0.0034 | K9: 0.0497 | L9: 0.2326 | M9: 0.4613 | N9: 0.7419 | O9: 1.0479 | P9: 1.3577 | Q9: 1.666 | R9: 1.9746 | S9: 2.2643 | T9: 2.5367 | U9: 2.7686 | V9: 2.9664 | W9: 3.14 | X9: 3.2833 | Y9: 3.385 | Z9: 3.4296 | AA9: 3.4425 | AB9: 3.4183 | AC9: 3.3372 | AD9: 3.2133 | AE9: 3.0655 | AF9: 2.8782 | AG9: 2.6791 | AH9: 2.4396 | AI9: 2.1698 | AJ9: 1.8441 | AK9: 1.5392 | AL9: 1.2259 | AM9: 0.9229 | AN9: 0.6308 | AO9: 0.3683 | AP9: 0.1072 | AQ9: 0.0198 | AR9: 0 | AS9: 0 | AT9: 0 | AU9: 0 | AV9: 0 | AW9: 0 | AX9: 0
A10: Load_TR4_F1_14 | B10: prosumer | C10: 0 | D10: 0 | E10: 0 | F10: 0 | G10: 0 | H10: 0 | I10: 0 | J10: 0.0026 | K10: 0.0373 | L10: 0.1744 | M10: 0.346 | N10: 0.5564 | O10: 0.7859 | P10: 1.0183 | Q10: 1.2495 | R10: 1.481 | S10: 1.6982 | T10: 1.9025 | U10: 2.0764 | V10: 2.2248 | W10: 2.355 | X10: 2.4625 | Y10: 2.5387 | Z10: 2.5722 | AA10: 2.5819 | AB10: 2.5637 | AC10: 2.5029 | AD10: 2.41 | AE10: 2.2991 | AF10: 2.1586 | AG10: 2.0093 | AH10: 1.8297 | AI10: 1.6274 | AJ10: 1.3831 | AK10: 1.1544 | AL10: 0.9195 | AM10: 0.6922 | AN10: 0.4731 | AO10: 0.2762 | AP10: 0.0804 | AQ10: 0.0148 | AR10: 0 | AS10: 0 | AT10: 0 | AU10: 0 | AV10: 0 | AW10: 0 | AX10: 0
A11: Load_TR4_F1_15 | B11: prosumer | C11: 0 | D11: 0 | E11: 0 | F11: 0 | G11: 0 | H11: 0 | I11: 0 | J11: 0.0034 | K11: 0.0497 | L11: 0.2326 | M11: 0.4613 | N11: 0.7419 | O11: 1.0479 | P11: 1.3577 | Q11: 1.666 | R11: 1.9746 | S11: 2.2643 | T11: 2.5367 | U11: 2.7686 | V11: 2.9664 | W11: 3.14 | X11: 3.2833 | Y11: 3.385 | Z11: 3.4296 | AA11: 3.4425 | AB11: 3.4183 | AC11: 3.3372 | AD11: 3.2133 | AE11: 3.0655 | AF11: 2.8782 | AG11: 2.6791 | AH11: 2.4396 | AI11: 2.1698 | AJ11: 1.8441 | AK11: 1.5392 | AL11: 1.2259 | AM11: 0.9229 | AN11: 0.6308 | AO11: 0.3683 | AP11: 0.1072 | AQ11: 0.0198 | AR11: 0 | AS11: 0 | AT11: 0 | AU11: 0 | AV11: 0 | AW11: 0 | AX11: 0
A12: Load_TR4_F1_16 | B12: customer | C12: 0 | D12: 0 | E12: 0 | F12: 0 | G12: 0 | H12: 0 | I12: 0 | J12: 0 | K12: 0 | L12: 0 | M12: 0 | N12: 0 | O12: 0 | P12: 0 | Q12: 0 | R12: 0 | S12: 0 | T12: 0 | U12: 0 | V12: 0 | W12: 0 | X12: 0 | Y12: 0 | Z12: 0 | AA12: 0 | AB12: 0 | AC12: 0 | AD12: 0 | AE12: 0 | AF12: 0 | AG12: 0 | AH12: 0 | AI12: 0 | AJ12: 0 | AK12: 0 | AL12: 0 | AM12: 0 | AN12: 0 | AO12: 0 | AP12: 0 | AQ12: 0 | AR12: 0 | AS12: 0 | AT12: 0 | AU12: 0 | AV12: 0 | AW12: 0 | AX12: 0
A13: Load_TR4_F1_17 | B13: customer | C13: 0 | D13: 0 | E13: 0 | F13: 0 | G13: 0 | H13: 0 | I13: 0 | J13: 0 | K13: 0 | L13: 0 | M13: 0 | N13: 0 | O13: 0 | P13: 0 | Q13: 0 | R13: 0 | S13: 0 | T13: 0 | U13: 0 | V13: 0 | W13: 0 | X13: 0 | Y13: 0 | Z13: 0 | AA13: 0 | AB13: 0 | AC13: 0 | AD13: 0 | AE13: 0 | AF13: 0 | AG13: 0 | AH13: 0 | AI13: 0 | AJ13: 0 | AK13: 0 | AL13: 0 | AM13: 0 | AN13: 0 | AO13: 0 | AP13: 0 | AQ13: 0 | AR13: 0 | AS13: 0 | AT13: 0 | AU13: 0 | AV13: 0 | AW13: 0 | AX13: 0
A14: Load_TR4_F1_18 | B14: prosumer | C14: 0 | D14: 0 | E14: 0 | F14: 0 | G14: 0 | H14: 0 | I14: 0 | J14: 0.0034 | K14: 0.0497 | L14: 0.2326 | M14: 0.4613 | N14: 0.7419 | O14: 1.0479 | P14: 1.3577 | Q14: 1.666 | R14: 1.9746 | S14: 2.2643 | T14: 2.5367 | U14: 2.7686 | V14: 2.9664 | W14: 3.14 | X14: 3.2833 | Y14: 3.385 | Z14: 3.4296 | AA14: 3.4425 | AB14: 3.4183 | AC14: 3.3372 | AD14: 3.2133 | AE14: 3.0655 | AF14: 2.8782 | AG14: 2.6791 | AH14: 2.4396 | AI14: 2.1698 | AJ14: 1.8441 | AK14: 1.5392 | AL14: 1.2259 | AM14: 0.9229 | AN14: 0.6308 | AO14: 0.3683 | AP14: 0.1072 | AQ14: 0.0198 | AR14: 0 | AS14: 0 | AT14: 0 | AU14: 0 | AV14: 0 | AW14: 0 | AX14: 0
A15: Load_TR4_F1_19 | B15: customer | C15: 0 | D15: 0 | E15: 0 | F15: 0 | G15: 0 | H15: 0 | I15: 0 | J15: 0 | K15: 0 | L15: 0 | M15: 0 | N15: 0 | O15: 0 | P15: 0 | Q15: 0 | R15: 0 | S15: 0 | T15: 0 | U15: 0 | V15: 0 | W15: 0 | X15: 0 | Y15: 0 | Z15: 0 | AA15: 0 | AB15: 0 | AC15: 0 | AD15: 0 | AE15: 0 | AF15: 0 | AG15: 0 | AH15: 0 | AI15: 0 | AJ15: 0 | AK15: 0 | AL15: 0 | AM15: 0 | AN15: 0 | AO15: 0 | AP15: 0 | AQ15: 0 | AR15: 0 | AS15: 0 | AT15: 0 | AU15: 0 | AV15: 0 | AW15: 0 | AX15: 0
A16: Load_TR4_F1_2 | B16: customer | C16: 0 | D16: 0 | E16: 0 | F16: 0 | G16: 0 | H16: 0 | I16: 0 | J16: 0 | K16: 0 | L16: 0 | M16: 0 | N16: 0 | O16: 0 | P16: 0 | Q16: 0 | R16: 0 | S16: 0 | T16: 0 | U16: 0 | V16: 0 | W16: 0 | X16: 0 | Y16: 0 | Z16: 0 | AA16: 0 | AB16: 0 | AC16: 0 | AD16: 0 | AE16: 0 | AF16: 0 | AG16: 0 | AH16: 0 | AI16: 0 | AJ16: 0 | AK16: 0 | AL16: 0 | AM16: 0 | AN16: 0 | AO16: 0 | AP16: 0 | AQ16: 0 | AR16: 0 | AS16: 0 | AT16: 0 | AU16: 0 | AV16: 0 | AW16: 0 | AX16: 0
... A79: Load_TR4_F3_9 | B79: prosumer | C79: 0 | D79: 0 | E79: 0 | F79: 0 | G79: 0 | H79: 0 | I79: 0 | J79: 0.0034 | K79: 0.0497 | L79: 0.2326 | M79: 0.4613 | N79: 0.7419 | O79: 1.0479 | P79: 1.3577 | Q79: 1.666 | R79: 1.9746 | S79: 2.2643 | T79: 2.5367 | U79: 2.7686 | V79: 2.9664 | W79: 3.14 | X79: 3.2833 | Y79: 3.385 | Z79: 3.4296 | AA79: 3.4425 | AB79: 3.4183 | AC79: 3.3372 | AD79: 3.2133 | AE79: 3.0655 | AF79: 2.8782 | AG79: 2.6791 | AH79: 2.4396 | AI79: 2.1698 | AJ79: 1.8441 | AK79: 1.5392 | AL79: 1.2259 | AM79: 0.9229 | AN79: 0.6308 | AO79: 0.3683 | AP79: 0.1072 | AQ79: 0.0198 | AR79: 0 | AS79: 0 | AT79: 0 | AU79: 0 | AV79: 0 | AW79: 0 | AX79: 0

Sheet 4. Raw load per load
A1: Raw load per load
A2: Verbatim copy of Load_P_kW (TR4_load_PV_48periods.xlsx), tagged by type. One row per connection, 48 half-hours (kW).
A4: Load name | B4: Type | C4: p1 | D4: p2 | E4: p3 | F4: p4 | G4: p5 | H4: p6 | I4: p7 | J4: p8 | K4: p9 | L4: p10 | M4: p11 | N4: p12 | O4: p13 | P4: p14 | Q4: p15 | R4: p16 | S4: p17 | T4: p18 | U4: p19 | V4: p20 | W4: p21 | X4: p22 | Y4: p23 | Z4: p24 | AA4: p25 | AB4: p26 | AC4: p27 | AD4: p28 | AE4: p29 | AF4: p30 | AG4: p31 | AH4: p32 | AI4: p33 | AJ4: p34 | AK4: p35 | AL4: p36 | AM4: p37 | AN4: p38 | AO4: p39 | AP4: p40 | AQ4: p41 | AR4: p42 | AS4: p43 | AT4: p44 | AU4: p45 | AV4: p46 | AW4: p47 | AX4: p48
A5: Load_TR4_F1_1 | B5: customer | C5: 0.2067 | D5: 0.1135 | E5: 0.0562 | F5: 0.2272 | G5: 0.1012 | H5: 0.0848 | I5: 0.2436 | J5: 0.048 | K5: 0.048 | L5: 0.2067 | M5: 0.048 | N5: 0.093 | O5: 0.2282 | P5: 0.0552 | Q5: 0.1418 | R5: 0.1129 | S5: 0.1219 | T5: 0.0628 | U5: 0.2538 | V5: 0.1077 | W5: 0.0637 | X5: 0.0985 | Y5: 0.2067 | Z5: 0.048 | AA5: 0.1076 | AB5: 0.233 | AC5: 0.0954 | AD5: 0.048 | AE5: 0.2851 | AF5: 0.048 | AG5: 0.1217 | AH5: 0.2067 | AI5: 0.048 | AJ5: 0.1866 | AK5: 0.1418 | AL5: 0.0573 | AM5: 0.2612 | AN5: 1.5529 | AO5: 1.5819 | AP5: 0.7079 | AQ5: 0.3336 | AR5: 0.4709 | AS5: 1.0342 | AT5: 1.0734 | AU5: 0.4469 | AV5: 0.687 | AW5: 0.9072 | AX5: 1.0774
A6: Load_TR4_F1_10 | B6: prosumer | C6: 0.3697 | D6: 0.049 | E6: 0.1196 | F6: 0.1776 | G6: 0.0866 | H6: 0.2106 | I6: 0.1243 | J6: 0.1479 | K6: 0.118 | L6: 0.1251 | M6: 0.1408 | N6: 0.1808 | O6: 0.1542 | P6: 0.0498 | Q6: 1.1303 | R6: 0.2848 | S6: 0.2394 | T6: 2.6547 | U6: 2.7219 | V6: 1.0703 | W6: 1.3337 | X6: 0.2487 | Y6: 0.1682 | Z6: 0.1479 | AA6: 0.4058 | AB6: 0.0747 | AC6: 0.3006 | AD6: 1.2539 | AE6: 0.1659 | AF6: 0.1245 | AG6: 0.2083 | AH6: 1.0122 | AI6: 0.2064 | AJ6: 0.5365 | AK6: 1.2464 | AL6: 0.0623 | AM6: 0.3227 | AN6: 0.3625 | AO6: 0.0985 | AP6: 0.2618 | AQ6: 0.3077 | AR6: 0.3057 | AS6: 0.1806 | AT6: 0.5383 | AU6: 0.587 | AV6: 0.4858 | AW6: 0.653 | AX6: 0.049
A7: Load_TR4_F1_11 | B7: prosumer | C7: 0.2006 | D7: 0.044 | E7: 0.044 | F7: 0.1827 | G7: 0.174 | H7: 0.044 | I7: 0.2332 | J7: 0.1234 | K7: 0.1428 | L7: 0.055 | M7: 0.2962 | N7: 0.0605 | O7: 0.2563 | P7: 0.1003 | Q7: 0.044 | R7: 0.1538 | S7: 0.2029 | T7: 0.0879 | U7: 0.3083 | V7: 0.0657 | W7: 0.1538 | X7: 0.0615 | Y7: 0.5036 | Z7: 0.054 | AA7: 0.044 | AB7: 0.1538 | AC7: 0.3065 | AD7: 0.1355 | AE7: 0.069 | AF7: 0.1758 | AG7: 2.4487 | AH7: 0.1822 | AI7: 1.4102 | AJ7: 1.289 | AK7: 0.0851 | AL7: 0.4381 | AM7: 0.3872 | AN7: 2.4522 | AO7: 0.1038 | AP7: 0.443 | AQ7: 0.3028 | AR7: 0.4099 | AS7: 0.3691 | AT7: 0.2709 | AU7: 0.179 | AV7: 0.4276 | AW7: 0.3801 | AX7: 0.187
A8: Load_TR4_F1_12 | B8: prosumer | C8: 0.163 | D8: 0.05 | E8: 0.2275 | F8: 0.05 | G8: 0.2033 | H8: 0.0742 | I8: 0.0823 | J8: 0.1952 | K8: 0.05 | L8: 0.05 | M8: 0.0742 | N8: 0.2033 | O8: 0.05 | P8: 0.2275 | Q8: 0.05 | R8: 0.1388 | S8: 0.148 | T8: 0.05 | U8: 0.2275 | V8: 0.2784 | W8: 0.171 | X8: 0.1255 | Y8: 0.062 | Z8: 1.3843 | AA8: 0.2022 | AB8: 1.5182 | AC8: 0.3755 | AD8: 0.4601 | AE8: 0.3149 | AF8: 0.1772 | AG8: 0.1193 | AH8: 0.0661 | AI8: 0.2114 | AJ8: 0.05 | AK8: 0.4362 | AL8: 0.0818 | AM8: 0.5552 | AN8: 0.3192 | AO8: 0.12 | AP8: 0.3956 | AQ8: 0.3684 | AR8: 0.577 | AS8: 0.7043 | AT8: 0.3784 | AU8: 0.5726 | AV8: 0.1673 | AW8: 0.1549 | AX8: 0.1226
A9: Load_TR4_F1_13 | B9: prosumer | C9: 0.058 | D9: 0.2545 | E9: 0.137 | F9: 0.058 | G9: 0.2518 | H9: 0.1397 | I9: 0.058 | J9: 0.193 | K9: 0.1985 | L9: 0.1709 | M9: 0.058 | N9: 0.1539 | O9: 0.1858 | P9: 0.1888 | Q9: 0.0919 | R9: 0.2545 | S9: 0.137 | T9: 0.1745 | U9: 0.217 | V9: 0.058 | W9: 0.4455 | X9: 0.3984 | Y9: 0.529 | Z9: 0.2712 | AA9: 0.2841 | AB9: 1.0891 | AC9: 0.4307 | AD9: 0.2668 | AE9: 0.3747 | AF9: 0.1401 | AG9: 0.3792 | AH9: 0.2363 | AI9: 0.058 | AJ9: 0.1923 | AK9: 0.1993 | AL9: 0.1257 | AM9: 0.2658 | AN9: 0.0749 | AO9: 0.2944 | AP9: 0.0802 | AQ9: 0.4474 | AR9: 0.2472 | AS9: 0.633 | AT9: 0.2734 | AU9: 0.5181 | AV9: 0.5824 | AW9: 0.7108 | AX9: 0.5489
A10: Load_TR4_F1_14 | B10: prosumer | C10: 0.2426 | D10: 0.3286 | E10: 0.3281 | F10: 0.2313 | G10: 0.055 | H10: 0.055 | I10: 0.055 | J10: 0.055 | K10: 0.055 | L10: 0.055 | M10: 0.055 | N10: 0.055 | O10: 0.055 | P10: 0.1846 | Q10: 0.2832 | R10: 0.1825 | S10: 0.692 | T10: 0.7799 | U10: 0.2106 | V10: 0.167 | W10: 0.2106 | X10: 0.1887 | Y10: 0.3292 | Z10: 1.1287 | AA10: 0.1342 | AB10: 0.1301 | AC10: 0.0705 | AD10: 0.0705 | AE10: 0.055 | AF10: 0.055 | AG10: 0.055 | AH10: 0.055 | AI10: 0.055 | AJ10: 0.055 | AK10: 0.2827 | AL10: 0.1486 | AM10: 0.0755 | AN10: 0.171 | AO10: 0.1316 | AP10: 0.1852 | AQ10: 0.1421 | AR10: 0.055 | AS10: 0.055 | AT10: 0.055 | AU10: 0.055 | AV10: 0.055 | AW10: 0.055 | AX10: 0.055
A11: Load_TR4_F1_15 | B11: prosumer | C11: 0.1238 | D11: 0.035 | E11: 0.035 | F11: 0.2051 | G11: 0.0885 | H11: 0.0721 | I11: 0.2215 | J11: 0.035 | K11: 0.035 | L11: 0.035 | M11: 0.191 | N11: 0.1026 | O11: 0.035 | P11: 0.2385 | Q11: 0.0551 | R11: 0.2359 | S11: 1.1403 | T11: 0.1932 | U11: 0.3129 | V11: 0.2945 | W11: 0.1494 | X11: 0.1631 | Y11: 0.0553 | Z11: 0.1984 | AA11: 0.035 | AB11: 0.1665 | AC11: 0.1142 | AD11: 0.4772 | AE11: 0.3645 | AF11: 0.1417 | AG11: 1.4256 | AH11: 1.0311 | AI11: 0.2018 | AJ11: 0.0919 | AK11: 0.1613 | AL11: 0.0756 | AM11: 0.5024 | AN11: 0.2269 | AO11: 0.2199 | AP11: 0.4072 | AQ11: 0.3589 | AR11: 0.391 | AS11: 0.035 | AT11: 0.1145 | AU11: 0.4529 | AV11: 0.1593 | AW11: 0.139 | AX11: 0.1546
A12: Load_TR4_F1_16 | B12: customer | C12: 0.5746 | D12: 0.5176 | E12: 2.1448 | F12: 0.5845 | G12: 0.6833 | H12: 0.4114 | I12: 0.048 | J12: 0.048 | K12: 0.1128 | L12: 0.101 | M12: 0.1128 | N12: 0.101 | O12: 0.101 | P12: 0.1128 | Q12: 0.0657 | R12: 0.1481 | S12: 0.2137 | T12: 1.2125 | U12: 0.3951 | V12: 0.2607 | W12: 0.4337 | X12: 0.2745 | Y12: 0.4171 | Z12: 0.6796 | AA12: 0.2715 | AB12: 0.4233 | AC12: 0.2255 | AD12: 1.333 | AE12: 0.628 | AF12: 0.1127 | AG12: 0.2006 | AH12: 0.0715 | AI12: 0.1384 | AJ12: 0.1649 | AK12: 0.048 | AL12: 0.4418 | AM12: 0.048 | AN12: 0.1422 | AO12: 0.0716 | AP12: 0.048 | AQ12: 0.048 | AR12: 0.048 | AS12: 0.1658 | AT12: 0.048 | AU12: 0.3217 | AV12: 0.048 | AW12: 0.048 | AX12: 0.0833
A13: Load_TR4_F1_17 | B13: customer | C13: 0.3078 | D13: 0.6133 | E13: 0.1305 | F13: 0.1231 | G13: 0.2202 | H13: 0.1643 | I13: 0.1467 | J13: 0.3208 | K13: 0.1176 | L13: 0.235 | M13: 0.155 | N13: 0.1176 | O13: 0.2533 | P13: 0.2013 | Q13: 0.1872 | R13: 0.3003 | S13: 0.2046 | T13: 0.2656 | U13: 0.2848 | V13: 1.0643 | W13: 0.28 | X13: 0.4218 | Y13: 0.6082 | Z13: 0.3813 | AA13: 0.125 | AB13: 0.1683 | AC13: 0.0885 | AD13: 0.2562 | AE13: 0.0604 | AF13: 0.1667 | AG13: 0.2879 | AH13: 0.1176 | AI13: 0.2183 | AJ13: 0.1716 | AK13: 0.1899 | AL13: 0.1569 | AM13: 0.1608 | AN13: 0.1602 | AO13: 0.3485 | AP13: 0.053 | AQ13: 0.2048 | AR13: 0.2498 | AS13: 0.0961 | AT13: 0.3437 | AU13: 0.1195 | AV13: 0.1166 | AW13: 0.2904 | AX13: 0.1265
A14: Load_TR4_F1_18 | B14: prosumer | C14: 0.3379 | D14: 0.052 | E14: 0.289 | F14: 0.1077 | G14: 0.1016 | H14: 0.2541 | I14: 0.093 | J14: 0.1551 | K14: 0.2416 | L14: 0.052 | M14: 0.2277 | N14: 0.169 | O14: 0.2415 | P14: 0.2745 | Q14: 0.3316 | R14: 0.4695 | S14: 0.3233 | T14: 0.2317 | U14: 0.3228 | V14: 0.3136 | W14: 0.1634 | X14: 0.9055 | Y14: 0.6534 | Z14: 0.8715 | AA14: 0.9121 | AB14: 0.1922 | AC14: 0.2252 | AD14: 0.0794 | AE14: 0.052 | AF14: 0.2079 | AG14: 0.0999 | AH14: 0.1409 | AI14: 0.1938 | AJ14: 0.203 | AK14: 0.052 | AL14: 0.1683 | AM14: 0.0725 | AN14: 0.6285 | AO14: 1.0438 | AP14: 0.3596 | AQ14: 0.2108 | AR14: 0.1371 | AS14: 0.1136 | AT14: 0.1272 | AU14: 0.2079 | AV14: 0.1136 | AW14: 0.1272 | AX14: 0.1792
A15: Load_TR4_F1_19 | B15: customer | C15: 0.084 | D15: 0.1506 | E15: 0.044 | F15: 0.1373 | G15: 0.0973 | H15: 0.044 | I15: 0.1106 | J15: 0.1239 | K15: 0.044 | L15: 0.1573 | M15: 0.0773 | N15: 0.044 | O15: 0.1906 | P15: 0.044 | Q15: 0.064 | R15: 0.1706 | S15: 0.044 | T15: 0.044 | U15: 0.1944 | V15: 0.6506 | W15: 0.7751 | X15: 0.1239 | Y15: 0.0533 | Z15: 0.1579 | AA15: 0.1029 | AB15: 0.1881 | AC15: 0.7824 | AD15: 0.4534 | AE15: 0.3136 | AF15: 0.0515 | AG15: 0.1053 | AH15: 0.2228 | AI15: 0.044 | AJ15: 0.2368 | AK15: 0.7344 | AL15: 2.5742 | AM15: 0.7202 | AN15: 0.0742 | AO15: 0.2181 | AP15: 1.3551 | AQ15: 0.044 | AR15: 0.044 | AS15: 0.1439 | AT15: 0.0906 | AU15: 0.104 | AV15: 0.1306 | AW15: 0.044 | AX15: 0.1706
A16: Load_TR4_F1_2 | B16: customer | C16: 0.1289 | D16: 0.1534 | E16: 0.1549 | F16: 0.108 | G16: 0.1594 | H16: 0.0722 | I16: 0.2362 | J16: 0.0619 | K16: 0.2334 | L16: 0.044 | M16: 0.134 | N16: 0.1744 | O16: 0.0516 | P16: 0.159 | Q16: 0.1442 | R16: 0.1296 | S16: 0.2367 | T16: 0.2346 | U16: 1.9013 | V16: 3.0874 | W16: 1.3577 | X16: 0.9339 | Y16: 0.5932 | Z16: 0.1413 | AA16: 0.1134 | AB16: 0.0842 | AC16: 0.1418 | AD16: 0.134 | AE16: 0.3061 | AF16: 0.2381 | AG16: 0.206 | AH16: 0.2978 | AI16: 0.0465 | AJ16: 0.7473 | AK16: 0.7334 | AL16: 0.2159 | AM16: 0.0824 | AN16: 0.4366 | AO16: 0.2262 | AP16: 0.294 | AQ16: 0.3739 | AR16: 0.346 | AS16: 0.3132 | AT16: 0.2096 | AU16: 0.6818 | AV16: 0.3797 | AW16: 0.4277 | AX16: 0.3418
... A79: Load_TR4_F3_9 | B79: prosumer | C79: 0.1397 | D79: 1.6505 | E79: 0.3719 | F79: 0.1535 | G79: 0.3555 | H79: 0.0645 | I79: 0.165 | J79: 0.2796 | K79: 0.057 | L79: 0.3876 | M79: 0.057 | N79: 0.1097 | O79: 0.1794 | P79: 0.2125 | Q79: 0.057 | R79: 0.1473 | S79: 0.2973 | T79: 0.057 | U79: 0.147 | V79: 0.2976 | W79: 0.057 | X79: 0.2493 | Y79: 1.7422 | Z79: 0.2763 | AA79: 0.1317 | AB79: 0.2187 | AC79: 0.6953 | AD79: 0.3698 | AE79: 0.4484 | AF79: 0.1936 | AG79: 1.2168 | AH79: 1.2794 | AI79: 0.2728 | AJ79: 0.3287 | AK79: 0.494 | AL79: 0.5755 | AM79: 0.1699 | AN79: 0.057 | AO79: 0.3876 | AP79: 0.057 | AQ79: 0.057 | AR79: 0.2446 | AS79: 0.2 | AT79: 0.1962 | AU79: 0.2485 | AV79: 0.1307 | AW79: 0.3139 | AX79: 0.057

Sheet 5. Raw batt charge
A1: Raw batt charge
A2: Verbatim copy of Charge_kW (TR4_analysis_data.xlsx). One row per half-hour, one column per battery (kW).
A4: period | B4: hour | C4: BES_TR4_one195_C | D4: BES_TR4_one223_B | E4: BES_TR4_one235_A | F4: BES_TR4_one242_B | G4: BES_TR4_one252_C | H4: BES_TR4_one260_C | I4: BES_TR4_one299_B | J4: BES_TR4_one320_B | K4: BES_TR4_one321_C | L4: BES_TR4_one328_A | M4: BES_TR4_one345_A | N4: BES_TR4_one366_B | O4: BES_TR4_one410_B | P4: BES_TR4_one50_A | Q4: BES_TR4_one416_C | R4: BES_TR4_one423_B | S4: BES_TR4_one446_B | T4: BES_TR4_one480_A | U4: BES_TR4_one61_A | V4: BES_TR4_one544_A | W4: BES_TR4_one560_C | X4: BES_TR4_one570_B | Y4: BES_TR4_one585_A | Z4: BES_TR4_one590_A | AA4: BES_TR4_one617_A | AB4: BES_TR4_one76_A | AC4: BES_TR4_one133_A | AD4: BES_TR4_one137_A | AE4: BES_TR4_one176_A | AF4: BES_TR4_three64_A | AG4: BES_TR4_three193_A | AH4: BES_TR4_three232_C | AI4: BES_TR4_three233_A | AJ4: BES_TR4_three248_C | AK4: BES_TR4_three253_C | AL4: BES_TR4_three66_C | AM4: BES_TR4_three312_A | AN4: BES_TR4_three321_B | AO4: BES_TR4_three368_A | AP4: BES_TR4_three388_A | AQ4: BES_TR4_three409_C | AR4: BES_TR4_three76_A | AS4: BES_TR4_three81_A | AT4: BES_TR4_three90_C | AU4: BES_TR4_three97_B | AV4: BES_TR4_three160_C
A5: 1 | B5: 0 | C5: 0 | D5: 0 | E5: 0 | F5: 0 | G5: 0 | H5: 0 | I5: 0 | J5: 0 | K5: 0 | L5: 0 | M5: 0 | N5: 0 | O5: 0 | P5: 0 | Q5: 0 | R5: 0 | S5: 0 | T5: 0 | U5: 0 | V5: 0 | W5: 0 | X5: 0 | Y5: 0 | Z5: 0 | AA5: 0 | AB5: 0 | AC5: 0 | AD5: 0 | AE5: 0 | AF5: 0 | AG5: 0 | AH5: 0 | AI5: 0 | AJ5: 0 | AK5: 0 | AL5: 0 | AM5: 0 | AN5: 0 | AO5: 0 | AP5: 0 | AQ5: 0 | AR5: 0 | AS5: 0 | AT5: 0 | AU5: 0 | AV5: 0
A6: 2 | B6: 0.5 | C6: 0 | D6: 0 | E6: 0 | F6: 0 | G6: 0 | H6: 0 | I6: 0 | J6: 0 | K6: 0 | L6: 0 | M6: 0 | N6: 0 | O6: 0 | P6: 0 | Q6: 0 | R6: 0 | S6: 0 | T6: 0 | U6: 0 | V6: 0 | W6: 0 | X6: 0 | Y6: 0 | Z6: 0 | AA6: 0 | AB6: 0 | AC6: 0 | AD6: 0 | AE6: 0 | AF6: 0 | AG6: 0 | AH6: 0 | AI6: 0 | AJ6: 0 | AK6: 0 | AL6: 0 | AM6: 0 | AN6: 0 | AO6: 0 | AP6: 0 | AQ6: 0 | AR6: 0 | AS6: 0 | AT6: 0 | AU6: 0 | AV6: 0
A7: 3 | B7: 1 | C7: 0 | D7: 0 | E7: 0 | F7: 0 | G7: 0 | H7: 0 | I7: 0 | J7: 0 | K7: 0 | L7: 0 | M7: 0 | N7: 0 | O7: 0 | P7: 0 | Q7: 0 | R7: 0 | S7: 0 | T7: 0 | U7: 0 | V7: 0 | W7: 0 | X7: 0 | Y7: 0 | Z7: 0 | AA7: 0 | AB7: 0 | AC7: 0 | AD7: 0 | AE7: 0 | AF7: 0 | AG7: 0 | AH7: 0 | AI7: 0 | AJ7: 0 | AK7: 0 | AL7: 0 | AM7: 0 | AN7: 0 | AO7: 0 | AP7: 0 | AQ7: 0 | AR7: 0 | AS7: 0 | AT7: 0 | AU7: 0 | AV7: 0
A8: 4 | B8: 1.5 | C8: 0 | D8: 0 | E8: 0 | F8: 0 | G8: 0 | H8: 0 | I8: 0 | J8: 0 | K8: 0 | L8: 0 | M8: 0 | N8: 0 | O8: 0 | P8: 0 | Q8: 0 | R8: 0 | S8: 0 | T8: 0 | U8: 0 | V8: 0 | W8: 0 | X8: 0 | Y8: 0 | Z8: 0 | AA8: 0 | AB8: 0 | AC8: 0 | AD8: 0 | AE8: 0 | AF8: 0 | AG8: 0 | AH8: 0 | AI8: 0 | AJ8: 0 | AK8: 0 | AL8: 0 | AM8: 0 | AN8: 0 | AO8: 0 | AP8: 0 | AQ8: 0 | AR8: 0 | AS8: 0 | AT8: 0 | AU8: 0 | AV8: 0
A9: 5 | B9: 2 | C9: 0 | D9: 0 | E9: 0 | F9: 0 | G9: 0 | H9: 0 | I9: 0 | J9: 0 | K9: 0 | L9: 0 | M9: 0 | N9: 0 | O9: 0 | P9: 0 | Q9: 0 | R9: 0 | S9: 0 | T9: 0 | U9: 0 | V9: 0 | W9: 0 | X9: 0 | Y9: 0 | Z9: 0 | AA9: 0 | AB9: 0 | AC9: 0 | AD9: 0 | AE9: 0 | AF9: 0 | AG9: 0 | AH9: 0 | AI9: 0 | AJ9: 0 | AK9: 0 | AL9: 0 | AM9: 0 | AN9: 0 | AO9: 0 | AP9: 0 | AQ9: 0 | AR9: 0 | AS9: 0 | AT9: 0 | AU9: 0 | AV9: 0
A10: 6 | B10: 2.5 | C10: 0 | D10: 0 | E10: 0 | F10: 0 | G10: 0 | H10: 0 | I10: 0 | J10: 0 | K10: 0 | L10: 0 | M10: 0 | N10: 0 | O10: 0 | P10: 0 | Q10: 0 | R10: 0 | S10: 0 | T10: 0 | U10: 0 | V10: 0 | W10: 0 | X10: 0 | Y10: 0 | Z10: 0 | AA10: 0 | AB10: 0 | AC10: 0 | AD10: 0 | AE10: 0 | AF10: 0 | AG10: 0 | AH10: 0 | AI10: 0 | AJ10: 0 | AK10: 0 | AL10: 0 | AM10: 0 | AN10: 0 | AO10: 0 | AP10: 0 | AQ10: 0 | AR10: 0 | AS10: 0 | AT10: 0 | AU10: 0 | AV10: 0
A11: 7 | B11: 3 | C11: 0 | D11: 0 | E11: 0 | F11: 0 | G11: 0 | H11: 0 | I11: 0 | J11: 0 | K11: 0 | L11: 0 | M11: 0 | N11: 0 | O11: 0 | P11: 0 | Q11: 0 | R11: 0 | S11: 0 | T11: 0 | U11: 0 | V11: 0 | W11: 0 | X11: 0 | Y11: 0 | Z11: 0 | AA11: 0 | AB11: 0 | AC11: 0 | AD11: 0 | AE11: 0 | AF11: 0 | AG11: 0 | AH11: 0 | AI11: 0 | AJ11: 0 | AK11: 0 | AL11: 0 | AM11: 0 | AN11: 0 | AO11: 0 | AP11: 0 | AQ11: 0 | AR11: 0 | AS11: 0 | AT11: 0 | AU11: 0 | AV11: 0
A12: 8 | B12: 3.5 | C12: 0 | D12: 0 | E12: 0 | F12: 0 | G12: 0 | H12: 0 | I12: 0 | J12: 0 | K12: 0 | L12: 0 | M12: 0 | N12: 0 | O12: 0 | P12: 0 | Q12: 0 | R12: 0 | S12: 0 | T12: 0 | U12: 0 | V12: 0 | W12: 0 | X12: 0 | Y12: 0 | Z12: 0 | AA12: 0 | AB12: 0 | AC12: 0 | AD12: 0 | AE12: 0 | AF12: 0 | AG12: 0 | AH12: 0 | AI12: 0 | AJ12: 0 | AK12: 0 | AL12: 0 | AM12: 0 | AN12: 0 | AO12: 0 | AP12: 0 | AQ12: 0 | AR12: 0 | AS12: 0 | AT12: 0 | AU12: 0 | AV12: 0
A13: 9 | B13: 4 | C13: 0 | D13: 0 | E13: 0 | F13: 0 | G13: 0 | H13: 0.015 | I13: 0 | J13: 0 | K13: 0 | L13: 0 | M13: 0 | N13: 0 | O13: 0 | P13: 0 | Q13: 0 | R13: 0 | S13: 0 | T13: 0 | U13: 0 | V13: 0 | W13: 0 | X13: 0 | Y13: 0 | Z13: 0 | AA13: 0 | AB13: 0 | AC13: 0 | AD13: 0 | AE13: 0 | AF13: 0 | AG13: 0 | AH13: 0 | AI13: 0 | AJ13: 0.011 | AK13: 0 | AL13: 0 | AM13: 0 | AN13: 0 | AO13: 0 | AP13: 0 | AQ13: 0 | AR13: 0 | AS13: 0 | AT13: 0 | AU13: 0 | AV13: 0
A14: 10 | B14: 4.5 | C14: 0.078 | D14: 0.119 | E14: 0.183 | F14: 0.062 | G14: 0.119 | H14: 0.198 | I14: 0.181 | J14: 0.026 | K14: 0 | L14: 0.157 | M14: 0 | N14: 0.046 | O14: 0 | P14: 0.012 | Q14: 0.181 | R14: 0.045 | S14: 0 | T14: 0.076 | U14: 0.021 | V14: 0 | W14: 0.084 | X14: 0.094 | Y14: 0.158 | Z14: 0 | AA14: 0.16 | AB14: 0.096 | AC14: 0.175 | AD14: 0.06 | AE14: 0.092 | AF14: 0.112 | AG14: 0.007 | AH14: 0 | AI14: 0.037 | AJ14: 0.03 | AK14: 0.055 | AL14: 0 | AM14: 0.095 | AN14: 0.057 | AO14: 0.017 | AP14: 0 | AQ14: 0.191 | AR14: 0.023 | AS14: 0.181 | AT14: 0.042 | AU14: 0 | AV14: 0
A15: 11 | B15: 5 | C15: 0.263 | D15: 0.05 | E15: 0.387 | F15: 0.403 | G15: 0.291 | H15: 0.27 | I15: 0.234 | J15: 0.232 | K15: 0.233 | L15: 0.253 | M15: 0.237 | N15: 0.256 | O15: 0.01 | P15: 0.123 | Q15: 0.409 | R15: 0.058 | S15: 0.116 | T15: 0.303 | U15: 0.388 | V15: 0.175 | W15: 0.355 | X15: 0.237 | Y15: 0.27 | Z15: 0.153 | AA15: 0.316 | AB15: 0.112 | AC15: 0.403 | AD15: 0.061 | AE15: 0.258 | AF15: 0.41 | AG15: 0.369 | AH15: 0.297 | AI15: 0.015 | AJ15: 0.32 | AK15: 0.018 | AL15: 0.018 | AM15: 0.408 | AN15: 0.048 | AO15: 0.03 | AP15: 0.116 | AQ15: 0.419 | AR15: 0.413 | AS15: 0.175 | AT15: 0.115 | AU15: 0.406 | AV15: 0.404
A16: 12 | B16: 5.5 | C16: 0.468 | D16: 0.496 | E16: 0.539 | F16: 0.588 | G16: 0.501 | H16: 0.639 | I16: 0.573 | J16: 0.4 | K16: 0.323 | L16: 0.609 | M16: 0.501 | N16: 0.623 | O16: 0.141 | P16: 0 | Q16: 0.69 | R16: 0.409 | S16: 0.221 | T16: 0.623 | U16: 0.668 | V16: 0.375 | W16: 0.508 | X16: 0.138 | Y16: 0.689 | Z16: 0.157 | AA16: 0.583 | AB16: 0.397 | AC16: 0.684 | AD16: 0.262 | AE16: 0.316 | AF16: 0.559 | AG16: 0.518 | AH16: 0.403 | AI16: 0.095 | AJ16: 0.501 | AK16: 0.31 | AL16: 0.209 | AM16: 0.609 | AN16: 0.104 | AO16: 0.235 | AP16: 0 | AQ16: 0.57 | AR16: 0.594 | AS16: 0.677 | AT16: 0.359 | AU16: 0.687 | AV16: 0.632
... A52: 48 | B52: 23.5 | C52: 0 | D52: 0 | E52: 0 | F52: 0 | G52: 0 | H52: 0 | I52: 0 | J52: 0 | K52: 0 | L52: 0 | M52: 0 | N52: 0 | O52: 0 | P52: 0 | Q52: 0 | R52: 0 | S52: 0 | T52: 0 | U52: 0 | V52: 0 | W52: 0 | X52: 0 | Y52: 0 | Z52: 0 | AA52: 0 | AB52: 0 | AC52: 0 | AD52: 0 | AE52: 0 | AF52: 0 | AG52: 0 | AH52: 0 | AI52: 0 | AJ52: 0 | AK52: 0 | AL52: 0 | AM52: 0 | AN52: 0 | AO52: 0 | AP52: 0 | AQ52: 0 | AR52: 0 | AS52: 0 | AT52: 0 | AU52: 0 | AV52: 0

Sheet 6. Raw batt discharge
A1: Raw batt discharge
A2: Verbatim copy of Discharge_kW (TR4_analysis_data.xlsx). One row per half-hour, one column per battery (kW).
A4: period | B4: hour | C4: BES_TR4_one195_C | D4: BES_TR4_one223_B | E4: BES_TR4_one235_A | F4: BES_TR4_one242_B | G4: BES_TR4_one252_C | H4: BES_TR4_one260_C | I4: BES_TR4_one299_B | J4: BES_TR4_one320_B | K4: BES_TR4_one321_C | L4: BES_TR4_one328_A | M4: BES_TR4_one345_A | N4: BES_TR4_one366_B | O4: BES_TR4_one410_B | P4: BES_TR4_one50_A | Q4: BES_TR4_one416_C | R4: BES_TR4_one423_B | S4: BES_TR4_one446_B | T4: BES_TR4_one480_A | U4: BES_TR4_one61_A | V4: BES_TR4_one544_A | W4: BES_TR4_one560_C | X4: BES_TR4_one570_B | Y4: BES_TR4_one585_A | Z4: BES_TR4_one590_A | AA4: BES_TR4_one617_A | AB4: BES_TR4_one76_A | AC4: BES_TR4_one133_A | AD4: BES_TR4_one137_A | AE4: BES_TR4_one176_A | AF4: BES_TR4_three64_A | AG4: BES_TR4_three193_A | AH4: BES_TR4_three232_C | AI4: BES_TR4_three233_A | AJ4: BES_TR4_three248_C | AK4: BES_TR4_three253_C | AL4: BES_TR4_three66_C | AM4: BES_TR4_three312_A | AN4: BES_TR4_three321_B | AO4: BES_TR4_three368_A | AP4: BES_TR4_three388_A | AQ4: BES_TR4_three409_C | AR4: BES_TR4_three76_A | AS4: BES_TR4_three81_A | AT4: BES_TR4_three90_C | AU4: BES_TR4_three97_B | AV4: BES_TR4_three160_C
A5: 1 | B5: 0 | C5: 0.37 | D5: 0.201 | E5: 0.163 | F5: 0.058 | G5: 0.243 | H5: 0.124 | I5: 0.338 | J5: 0.232 | K5: 0.214 | L5: 0.488 | M5: 0.312 | N5: 0.21 | O5: 0.316 | P5: 0.061 | Q5: 0.052 | R5: 0.206 | S5: 0.252 | T5: 0.105 | U5: 0.452 | V5: 0.176 | W5: 0.141 | X5: 0.268 | Y5: 0.118 | Z5: 0.072 | AA5: 0.044 | AB5: 0.122 | AC5: 0.207 | AD5: 0.599 | AE5: 0.03 | AF5: 0.066 | AG5: 0.14 | AH5: 0.071 | AI5: 0.439 | AJ5: 0.026 | AK5: 0.212 | AL5: 0.06 | AM5: 0.138 | AN5: 0.125 | AO5: 0.043 | AP5: 0.298 | AQ5: 0.485 | AR5: 0.979 | AS5: 0.245 | AT5: 0.096 | AU5: 0.131 | AV5: 0.14
A6: 2 | B6: 0.5 | C6: 0.049 | D6: 0.044 | E6: 0.05 | F6: 0.255 | G6: 0.329 | H6: 0.035 | I6: 0.052 | J6: 0.056 | K6: 0.459 | L6: 0.374 | M6: 0.253 | N6: 0.177 | O6: 0.148 | P6: 0.185 | Q6: 0.052 | R6: 0.124 | S6: 0.057 | T6: 0.286 | U6: 0.066 | V6: 0.151 | W6: 0.113 | X6: 0.391 | Y6: 0.148 | Z6: 0.31 | AA6: 0.044 | AB6: 0.084 | AC6: 0.093 | AD6: 0.102 | AE6: 0.159 | AF6: 0.206 | AG6: 0.212 | AH6: 0.286 | AI6: 0.061 | AJ6: 0.026 | AK6: 0.14 | AL6: 0.217 | AM6: 0.176 | AN6: 0.056 | AO6: 0.171 | AP6: 0.068 | AQ6: 0.042 | AR6: 0.463 | AS6: 0.065 | AT6: 0.19 | AU6: 0.201 | AV6: 1.65
A7: 3 | B7: 1 | C7: 0.12 | D7: 0.044 | E7: 0.228 | F7: 0.137 | G7: 0.328 | H7: 0.035 | I7: 0.289 | J7: 0.168 | K7: 0.055 | L7: 0.209 | M7: 0.055 | N7: 0.211 | O7: 0.046 | P7: 0.135 | Q7: 0.052 | R7: 0.158 | S7: 0.226 | T7: 0.04 | U7: 0.135 | V7: 0.112 | W7: 0.049 | X7: 0.051 | Y7: 0.053 | Z7: 0.149 | AA7: 0.11 | AB7: 0.332 | AC7: 0.058 | AD7: 0.056 | AE7: 0.03 | AF7: 0.051 | AG7: 0.078 | AH7: 0.14 | AI7: 0.155 | AJ7: 0.144 | AK7: 0.407 | AL7: 0.049 | AM7: 0.048 | AN7: 0.056 | AO7: 0.043 | AP7: 0.112 | AQ7: 0.154 | AR7: 0.07 | AS7: 0.208 | AT7: 0.157 | AU7: 0.055 | AV7: 0.372
A8: 4 | B8: 1.5 | C8: 0.178 | D8: 0.183 | E8: 0.05 | F8: 0.058 | G8: 0.231 | H8: 0.205 | I8: 0.108 | J8: 0.12 | K8: 0.164 | L8: 0.054 | M8: 0.055 | N8: 0.126 | O8: 0.128 | P8: 0.161 | Q8: 0.052 | R8: 0.142 | S8: 0.084 | T8: 0.273 | U8: 0.15 | V8: 0.19 | W8: 0.205 | X8: 0.316 | Y8: 0.148 | Z8: 0.38 | AA8: 0.044 | AB8: 0.049 | AC8: 0.084 | AD8: 0.056 | AE8: 0.118 | AF8: 0.159 | AG8: 0.195 | AH8: 0.041 | AI8: 0.172 | AJ8: 0.026 | AK8: 0.453 | AL8: 0.078 | AM8: 0.266 | AN8: 0.056 | AO8: 0.043 | AP8: 0.254 | AQ8: 0.06 | AR8: 0.194 | AS8: 0.13 | AT8: 0.034 | AU8: 0.208 | AV8: 0.154
A9: 5 | B9: 2 | C9: 0.087 | D9: 0.174 | E9: 0.203 | F9: 0.252 | G9: 0.055 | H9: 0.089 | I9: 0.102 | J9: 0.056 | K9: 0.055 | L9: 0.133 | M9: 0.226 | N9: 0.292 | O9: 0.232 | P9: 0.149 | Q9: 0.052 | R9: 0.134 | S9: 0.128 | T9: 0.117 | U9: 0.081 | V9: 0.101 | W9: 0.049 | X9: 0.051 | Y9: 0.118 | Z9: 0.155 | AA9: 0.044 | AB9: 0.213 | AC9: 0.111 | AD9: 0.064 | AE9: 0.071 | AF9: 0.113 | AG9: 0.171 | AH9: 0.139 | AI9: 0.151 | AJ9: 0.026 | AK9: 0.332 | AL9: 0.222 | AM9: 0.048 | AN9: 0.056 | AO9: 0.171 | AP9: 0.05 | AQ9: 0.042 | AR9: 0.071 | AS9: 0.052 | AT9: 0.267 | AU9: 0.124 | AV9: 0.075
A10: 6 | B10: 2.5 | C10: 0.211 | D10: 0.044 | E10: 0.074 | F10: 0.14 | G10: 0.055 | H10: 0.072 | I10: 0.254 | J10: 0.152 | K10: 0.055 | L10: 0.209 | M10: 0.082 | N10: 0.116 | O10: 0.046 | P10: 0.227 | Q10: 0.052 | R10: 0.174 | S10: 0.181 | T10: 0.072 | U10: 0.204 | V10: 0.412 | W10: 0.155 | X10: 0.186 | Y10: 0.053 | Z10: 0.105 | AA10: 0.088 | AB10: 0.075 | AC10: 0.102 | AD10: 0.215 | AE10: 0.03 | AF10: 0.051 | AG10: 0.102 | AH10: 0.238 | AI10: 0.198 | AJ10: 0.115 | AK10: 0.509 | AL10: 0.139 | AM10: 0.17 | AN10: 0.125 | AO10: 0.043 | AP10: 0.285 | AQ10: 0.137 | AR10: 0.048 | AS10: 0.052 | AT10: 0.08 | AU10: 0.097 | AV10: 0
A11: 7 | B11: 3 | C11: 0.124 | D11: 0.233 | E11: 0.082 | F11: 0.058 | G11: 0.055 | H11: 0.221 | I11: 0.093 | J11: 0.136 | K11: 0.125 | L11: 0.129 | M11: 0.091 | N11: 0.068 | O11: 0.129 | P11: 0.069 | Q11: 0.052 | R11: 0.109 | S11: 0.075 | T11: 0.212 | U11: 0.058 | V11: 0.439 | W11: 0.099 | X11: 0.072 | Y11: 0.118 | Z11: 0.451 | AA11: 0.528 | AB11: 0.049 | AC11: 0.093 | AD11: 0.056 | AE11: 0.159 | AF11: 0.221 | AG11: 0.193 | AH11: 0.12 | AI11: 0.165 | AJ11: 0.056 | AK11: 0.338 | AL11: 0.171 | AM11: 0.144 | AN11: 0.06 | AO11: 0.171 | AP11: 0.081 | AQ11: 0.077 | AR11: 0.102 | AS11: 0.138 | AT11: 0.034 | AU11: 0.235 | AV11: 0
A12: 8 | B12: 3.5 | C12: 0.145 | D12: 0.121 | E12: 0.192 | F12: 0.19 | G12: 0.052 | H12: 0.032 | I12: 0.152 | J12: 0.054 | K12: 0.092 | L12: 0.16 | M12: 0.214 | N12: 0.362 | O12: 0.23 | P12: 0.207 | Q12: 0.049 | R12: 0.239 | S12: 0.233 | T12: 0.037 | U12: 0.224 | V12: 0.229 | W12: 0.046 | X12: 0.064 | Y12: 0.144 | Z12: 0.099 | AA12: 0.258 | AB12: 0.339 | AC12: 0.055 | AD12: 0.221 | AE12: 0.028 | AF12: 0.048 | AG12: 0.156 | AH12: 0.038 | AI12: 0.179 | AJ12: 0.023 | AK12: 0 | AL12: 0.185 | AM12: 0.057 | AN12: 0.117 | AO12: 0.042 | AP12: 0.083 | AQ12: 0.039 | AR12: 0.16 | AS12: 0.196 | AT12: 0.201 | AU12: 0.052 | AV12: 0
A13: 9 | B13: 4 | C13: 0.074 | D13: 0.105 | E13: 0.0003 | F13: 0.149 | G13: 0.018 | H13: 0 | I13: 0.192 | J13: 0.137 | K13: 0.024 | L13: 0.111 | M13: 0.018 | N13: 0.01 | O13: 0.027 | P13: 0.018 | Q13: 0.002 | R13: 0.059 | S13: 0.038 | T13: 0.083 | U13: 0.008 | V13: 0.092 | W13: 0.09 | X13: 0.27 | Y13: 0.003 | Z13: 0.246 | AA13: 0.063 | AB13: 0.044 | AC13: 0.087 | AD13: 0.031 | AE13: 0.105 | AF13: 0.102 | AG13: 0.077 | AH13: 0.136 | AI13: 0.229 | AJ13: 0 | AK13: 0 | AL13: 0.079 | AM13: 0.113 | AN13: 0.014 | AO13: 0.024 | AP13: 0.189 | AQ13: 0.122 | AR13: 0.006 | AS13: 0.002 | AT13: 0.113 | AU13: 0.005 | AV13: 0
A14: 10 | B14: 4.5 | C14: 0 | D14: 0 | E14: 0 | F14: 0 | G14: 0 | H14: 0 | I14: 0 | J14: 0 | K14: 0.018 | L14: 0 | M14: 0.108 | N14: 0 | O14: 0.111 | P14: 0 | Q14: 0 | R14: 0 | S14: 0.165 | T14: 0 | U14: 0 | V14: 0.062 | W14: 0 | X14: 0 | Y14: 0 | Z14: 0.133 | AA14: 0 | AB14: 0 | AC14: 0 | AD14: 0 | AE14: 0 | AF14: 0 | AG14: 0 | AH14: 0.008 | AI14: 0 | AJ14: 0 | AK14: 0 | AL14: 0.039 | AM14: 0 | AN14: 0 | AO14: 0 | AP14: 0.037 | AQ14: 0 | AR14: 0 | AS14: 0 | AT14: 0 | AU14: 0.044 | AV14: 0
A15: 11 | B15: 5 | C15: 0 | D15: 0 | E15: 0 | F15: 0 | G15: 0 | H15: 0 | I15: 0 | J15: 0 | K15: 0 | L15: 0 | M15: 0 | N15: 0 | O15: 0 | P15: 0 | Q15: 0 | R15: 0 | S15: 0 | T15: 0 | U15: 0 | V15: 0 | W15: 0 | X15: 0 | Y15: 0 | Z15: 0 | AA15: 0 | AB15: 0 | AC15: 0 | AD15: 0 | AE15: 0 | AF15: 0 | AG15: 0 | AH15: 0 | AI15: 0 | AJ15: 0 | AK15: 0 | AL15: 0 | AM15: 0 | AN15: 0 | AO15: 0 | AP15: 0 | AQ15: 0 | AR15: 0 | AS15: 0 | AT15: 0 | AU15: 0 | AV15: 0
A16: 12 | B16: 5.5 | C16: 0 | D16: 0 | E16: 0 | F16: 0 | G16: 0 | H16: 0 | I16: 0 | J16: 0 | K16: 0 | L16: 0 | M16: 0 | N16: 0 | O16: 0 | P16: 0.055 | Q16: 0 | R16: 0 | S16: 0 | T16: 0 | U16: 0 | V16: 0 | W16: 0 | X16: 0 | Y16: 0 | Z16: 0 | AA16: 0 | AB16: 0 | AC16: 0 | AD16: 0 | AE16: 0 | AF16: 0 | AG16: 0 | AH16: 0 | AI16: 0 | AJ16: 0 | AK16: 0 | AL16: 0 | AM16: 0 | AN16: 0 | AO16: 0 | AP16: 0.008 | AQ16: 0 | AR16: 0 | AS16: 0 | AT16: 0 | AU16: 0 | AV16: 0
... A52: 48 | B52: 23.5 | C52: 0.049 | D52: 0.187 | E52: 0.123 | F52: 0.549 | G52: 0.055 | H52: 0.155 | I52: 0.179 | J52: 0 | K52: 0.156 | L52: 0.082 | M52: 0.118 | N52: 0.244 | O52: 0.46 | P52: 0.052 | Q52: 0.477 | R52: 0.784 | S52: 0.306 | T52: 0.16 | U52: 0.783 | V52: 0 | W52: 0 | X52: 0.382 | Y52: 0.104 | Z52: 0.223 | AA52: 0.264 | AB52: 0.11 | AC52: 0.785 | AD52: 0.72 | AE52: 0.03 | AF52: 0.405 | AG52: 0.104 | AH52: 0.293 | AI52: 0 | AJ52: 0 | AK52: 0 | AL52: 0.579 | AM52: 0.125 | AN52: 0.422 | AO52: 0.043 | AP52: 0 | AQ52: 0.042 | AR52: 0.048 | AS52: 0.087 | AT52: 0.51 | AU52: 0.07 | AV52: 0.057

Sheet 7. PV allocation (per period)
A1: TR4 PV allocation — per half-hour
A2: VIOLET = aggregated live from the raw sheets 3–6 (SUM / SUMIF). AMBER = priority split (MIN formulas): PV → prosumer load → battery → customer load → export.
A4: period | B4: hour (h) | C4: PV (kW) | D4: prosumer load (kW) | E4: customer load (kW) | F4: batt charge (kW) | G4: batt discharge (kW) | H4: batt net =chg−dis | I4: PV→ prosumer | J4: PV→ battery | K4: PV→ customer | L4: PV→ export | M4: customer ←grid
A5: 1 | B5: 0 | C5: =SUM('3. Raw PV per load'!C5:C79) -> 0 | D5: =SUMIF('4. Raw load per load'!$B$5:$B$79,"prosumer",'4. Raw load per load'!C5:C79) -> 9.8668 | E5: =SUMIF('4. Raw load per load'!$B$5:$B$79,"customer",'4. Raw load per load'!C5:C79) -> 9.7086 | F5: =SUM('5. Raw batt charge'!C5:AV5) -> 0 | G5: =SUM('6. Raw batt discharge'!C5:AV5) -> 9.868 | H5: =F5-G5 -> -9.868 | I5: =MIN(C5,D5) -> 0 | J5: =MIN(C5-I5,MAX(0,H5)) -> 0 | K5: =MIN(C5-I5-J5,E5) -> 0 | L5: =C5-I5-J5-K5 -> 0 | M5: =E5-K5 -> 9.7086
A6: 2 | B6: 0.5 | C6: =SUM('3. Raw PV per load'!D5:D79) -> 0 | D6: =SUMIF('4. Raw load per load'!$B$5:$B$79,"prosumer",'4. Raw load per load'!D5:D79) -> 8.8744 | E6: =SUMIF('4. Raw load per load'!$B$5:$B$79,"customer",'4. Raw load per load'!D5:D79) -> 7.6682 | F6: =SUM('5. Raw batt charge'!C6:AV6) -> 0 | G6: =SUM('6. Raw batt discharge'!C6:AV6) -> 8.876 | H6: =F6-G6 -> -8.876 | I6: =MIN(C6,D6) -> 0 | J6: =MIN(C6-I6,MAX(0,H6)) -> 0 | K6: =MIN(C6-I6-J6,E6) -> 0 | L6: =C6-I6-J6-K6 -> 0 | M6: =E6-K6 -> 7.6682
A7: 3 | B7: 1 | C7: =SUM('3. Raw PV per load'!E5:E79) -> 0 | D7: =SUMIF('4. Raw load per load'!$B$5:$B$79,"prosumer",'4. Raw load per load'!E5:E79) -> 5.9693 | E7: =SUMIF('4. Raw load per load'!$B$5:$B$79,"customer",'4. Raw load per load'!E5:E79) -> 7.1912 | F7: =SUM('5. Raw batt charge'!C7:AV7) -> 0 | G7: =SUM('6. Raw batt discharge'!C7:AV7) -> 5.97 | H7: =F7-G7 -> -5.97 | I7: =MIN(C7,D7) -> 0 | J7: =MIN(C7-I7,MAX(0,H7)) -> 0 | K7: =MIN(C7-I7-J7,E7) -> 0 | L7: =C7-I7-J7-K7 -> 0 | M7: =E7-K7 -> 7.1912
A8: 4 | B8: 1.5 | C8: =SUM('3. Raw PV per load'!F5:F79) -> 0 | D8: =SUMIF('4. Raw load per load'!$B$5:$B$79,"prosumer",'4. Raw load per load'!F5:F79) -> 6.6328 | E8: =SUMIF('4. Raw load per load'!$B$5:$B$79,"customer",'4. Raw load per load'!F5:F79) -> 4.9474 | F8: =SUM('5. Raw batt charge'!C8:AV8) -> 0 | G8: =SUM('6. Raw batt discharge'!C8:AV8) -> 6.635 | H8: =F8-G8 -> -6.635 | I8: =MIN(C8,D8) -> 0 | J8: =MIN(C8-I8,MAX(0,H8)) -> 0 | K8: =MIN(C8-I8-J8,E8) -> 0 | L8: =C8-I8-J8-K8 -> 0 | M8: =E8-K8 -> 4.9474
A9: 5 | B9: 2 | C9: =SUM('3. Raw PV per load'!G5:G79) -> 0 | D9: =SUMIF('4. Raw load per load'!$B$5:$B$79,"prosumer",'4. Raw load per load'!G5:G79) -> 5.984 | E9: =SUMIF('4. Raw load per load'!$B$5:$B$79,"customer",'4. Raw load per load'!G5:G79) -> 4.966 | F9: =SUM('5. Raw batt charge'!C9:AV9) -> 0 | G9: =SUM('6. Raw batt discharge'!C9:AV9) -> 5.704 | H9: =F9-G9 -> -5.704 | I9: =MIN(C9,D9) -> 0 | J9: =MIN(C9-I9,MAX(0,H9)) -> 0 | K9: =MIN(C9-I9-J9,E9) -> 0 | L9: =C9-I9-J9-K9 -> 0 | M9: =E9-K9 -> 4.966
A10: 6 | B10: 2.5 | C10: =SUM('3. Raw PV per load'!H5:H79) -> 0 | D10: =SUMIF('4. Raw load per load'!$B$5:$B$79,"prosumer",'4. Raw load per load'!H5:H79) -> 6.2933 | E10: =SUMIF('4. Raw load per load'!$B$5:$B$79,"customer",'4. Raw load per load'!H5:H79) -> 4.4229 | F10: =SUM('5. Raw batt charge'!C10:AV10) -> 0 | G10: =SUM('6. Raw batt discharge'!C10:AV10) -> 6.23 | H10: =F10-G10 -> -6.23 | I10: =MIN(C10,D10) -> 0 | J10: =MIN(C10-I10,MAX(0,H10)) -> 0 | K10: =MIN(C10-I10-J10,E10) -> 0 | L10: =C10-I10-J10-K10 -> 0 | M10: =E10-K10 -> 4.4229
A11: 7 | B11: 3 | C11: =SUM('3. Raw PV per load'!I5:I79) -> 0 | D11: =SUMIF('4. Raw load per load'!$B$5:$B$79,"prosumer",'4. Raw load per load'!I5:I79) -> 6.717 | E11: =SUMIF('4. Raw load per load'!$B$5:$B$79,"customer",'4. Raw load per load'!I5:I79) -> 3.78 | F11: =SUM('5. Raw batt charge'!C11:AV11) -> 0 | G11: =SUM('6. Raw batt discharge'!C11:AV11) -> 6.489 | H11: =F11-G11 -> -6.489 | I11: =MIN(C11,D11) -> 0 | J11: =MIN(C11-I11,MAX(0,H11)) -> 0 | K11: =MIN(C11-I11-J11,E11) -> 0 | L11: =C11-I11-J11-K11 -> 0 | M11: =E11-K11 -> 3.78
A12: 8 | B12: 3.5 | C12: =SUM('3. Raw PV per load'!J5:J79) -> 0.1235 | D12: =SUMIF('4. Raw load per load'!$B$5:$B$79,"prosumer",'4. Raw load per load'!J5:J79) -> 6.8527 | E12: =SUMIF('4. Raw load per load'!$B$5:$B$79,"customer",'4. Raw load per load'!J5:J79) -> 3.7684 | F12: =SUM('5. Raw batt charge'!C12:AV12) -> 0 | G12: =SUM('6. Raw batt discharge'!C12:AV12) -> 6.044 | H12: =F12-G12 -> -6.044 | I12: =MIN(C12,D12) -> 0.1235 | J12: =MIN(C12-I12,MAX(0,H12)) -> 0 | K12: =MIN(C12-I12-J12,E12) -> 0 | L12: =C12-I12-J12-K12 -> 0 | M12: =E12-K12 -> 3.7684
A13: 9 | B13: 4 | C13: =SUM('3. Raw PV per load'!K5:K79) -> 1.7902 | D13: =SUMIF('4. Raw load per load'!$B$5:$B$79,"prosumer",'4. Raw load per load'!K5:K79) -> 5.1848 | E13: =SUMIF('4. Raw load per load'!$B$5:$B$79,"customer",'4. Raw load per load'!K5:K79) -> 3.3263 | F13: =SUM('5. Raw batt charge'!C13:AV13) -> 0.026 | G13: =SUM('6. Raw batt discharge'!C13:AV13) -> 3.3153 | H13: =F13-G13 -> -3.2893 | I13: =MIN(C13,D13) -> 1.7902 | J13: =MIN(C13-I13,MAX(0,H13)) -> 0 | K13: =MIN(C13-I13-J13,E13) -> 0 | L13: =C13-I13-J13-K13 -> 0 | M13: =E13-K13 -> 3.3263
A14: 10 | B14: 4.5 | C14: =SUM('3. Raw PV per load'!L5:L79) -> 8.3734 | D14: =SUMIF('4. Raw load per load'!$B$5:$B$79,"prosumer",'4. Raw load per load'!L5:L79) -> 5.9864 | E14: =SUMIF('4. Raw load per load'!$B$5:$B$79,"customer",'4. Raw load per load'!L5:L79) -> 3.2776 | F14: =SUM('5. Raw batt charge'!C14:AV14) -> 3.27 | G14: =SUM('6. Raw batt discharge'!C14:AV14) -> 0.725 | H14: =F14-G14 -> 2.545 | I14: =MIN(C14,D14) -> 5.9864 | J14: =MIN(C14-I14,MAX(0,H14)) -> 2.387 | K14: =MIN(C14-I14-J14,E14) -> 0 | L14: =C14-I14-J14-K14 -> 0 | M14: =E14-K14 -> 3.2776
A15: 11 | B15: 5 | C15: =SUM('3. Raw PV per load'!M5:M79) -> 16.6073 | D15: =SUMIF('4. Raw load per load'!$B$5:$B$79,"prosumer",'4. Raw load per load'!M5:M79) -> 5.768 | E15: =SUMIF('4. Raw load per load'!$B$5:$B$79,"customer",'4. Raw load per load'!M5:M79) -> 3.9029 | F15: =SUM('5. Raw batt charge'!C15:AV15) -> 10.837 | G15: =SUM('6. Raw batt discharge'!C15:AV15) -> 0 | H15: =F15-G15 -> 10.837 | I15: =MIN(C15,D15) -> 5.768 | J15: =MIN(C15-I15,MAX(0,H15)) -> 10.837 | K15: =MIN(C15-I15-J15,E15) -> 0.0023 | L15: =C15-I15-J15-K15 -> 0 | M15: =E15-K15 -> 3.9006
A16: 12 | B16: 5.5 | C16: =SUM('3. Raw PV per load'!N5:N79) -> 26.7079 | D16: =SUMIF('4. Raw load per load'!$B$5:$B$79,"prosumer",'4. Raw load per load'!N5:N79) -> 6.5866 | E16: =SUMIF('4. Raw load per load'!$B$5:$B$79,"customer",'4. Raw load per load'!N5:N79) -> 3.3171 | F16: =SUM('5. Raw batt charge'!C16:AV16) -> 20.183 | G16: =SUM('6. Raw batt discharge'!C16:AV16) -> 0.063 | H16: =F16-G16 -> 20.12 | I16: =MIN(C16,D16) -> 6.5866 | J16: =MIN(C16-I16,MAX(0,H16)) -> 20.12 | K16: =MIN(C16-I16-J16,E16) -> 0.0013 | L16: =C16-I16-J16-K16 -> 0 | M16: =E16-K16 -> 3.3158
A17: 13 | B17: 6 | C17: =SUM('3. Raw PV per load'!O5:O79) -> 37.7243 | D17: =SUMIF('4. Raw load per load'!$B$5:$B$79,"prosumer",'4. Raw load per load'!O5:O79) -> 7.3662 | E17: =SUMIF('4. Raw load per load'!$B$5:$B$79,"customer",'4. Raw load per load'!O5:O79) -> 4.0637 | F17: =SUM('5. Raw batt charge'!C17:AV17) -> 30.36 | G17: =SUM('6. Raw batt discharge'!C17:AV17) -> 0 | H17: =F17-G17 -> 30.36 | I17: =MIN(C17,D17) -> 7.3662 | J17: =MIN(C17-I17,MAX(0,H17)) -> 30.3581 | K17: =MIN(C17-I17-J17,E17) -> 0 | L17: =C17-I17-J17-K17 -> 0 | M17: =E17-K17 -> 4.0637
A18: 14 | B18: 6.5 | C18: =SUM('3. Raw PV per load'!P5:P79) -> 48.8782 | D18: =SUMIF('4. Raw load per load'!$B$5:$B$79,"prosumer",'4. Raw load per load'!P5:P79) -> 10.0887 | E18: =SUMIF('4. Raw load per load'!$B$5:$B$79,"customer",'4. Raw load per load'!P5:P79) -> 3.9116 | F18: =SUM('5. Raw batt charge'!C18:AV18) -> 40.771 | G18: =SUM('6. Raw batt discharge'!C18:AV18) -> 1.981 | H18: =F18-G18 -> 38.79 | I18: =MIN(C18,D18) -> 10.0887 | J18: =MIN(C18-I18,MAX(0,H18)) -> 38.7895 | K18: =MIN(C18-I18-J18,E18) -> 0 | L18: =C18-I18-J18-K18 -> 0 | M18: =E18-K18 -> 3.9116
A19: 15 | B19: 7 | C19: =SUM('3. Raw PV per load'!Q5:Q79) -> 59.9751 | D19: =SUMIF('4. Raw load per load'!$B$5:$B$79,"prosumer",'4. Raw load per load'!Q5:Q79) -> 13.1419 | E19: =SUMIF('4. Raw load per load'!$B$5:$B$79,"customer",'4. Raw load per load'!Q5:Q79) -> 5.1565 | F19: =SUM('5. Raw batt charge'!C19:AV19) -> 47.938 | G19: =SUM('6. Raw batt discharge'!C19:AV19) -> 1.108 | H19: =F19-G19 -> 46.83 | I19: =MIN(C19,D19) -> 13.1419 | J19: =MIN(C19-I19,MAX(0,H19)) -> 46.83 | K19: =MIN(C19-I19-J19,E19) -> 0.0032 | L19: =C19-I19-J19-K19 -> 0 | M19: =E19-K19 -> 5.1533
A20: 16 | B20: 7.5 | C20: =SUM('3. Raw PV per load'!R5:R79) -> 71.0858 | D20: =SUMIF('4. Raw load per load'!$B$5:$B$79,"prosumer",'4. Raw load per load'!R5:R79) -> 12.7774 | E20: =SUMIF('4. Raw load per load'!$B$5:$B$79,"customer",'4. Raw load per load'!R5:R79) -> 7.2611 | F20: =SUM('5. Raw batt charge'!C20:AV20) -> 56.932 | G20: =SUM('6. Raw batt discharge'!C20:AV20) -> 1.411 | H20: =F20-G20 -> 55.521 | I20: =MIN(C20,D20) -> 12.7774 | J20: =MIN(C20-I20,MAX(0,H20)) -> 55.521 | K20: =MIN(C20-I20-J20,E20) -> 2.7874 | L20: =C20-I20-J20-K20 -> 0 | M20: =E20-K20 -> 4.4737
A21: 17 | B21: 8 | C21: =SUM('3. Raw PV per load'!S5:S79) -> 81.5151 | D21: =SUMIF('4. Raw load per load'!$B$5:$B$79,"prosumer",'4. Raw load per load'!S5:S79) -> 12.4083 | E21: =SUMIF('4. Raw load per load'!$B$5:$B$79,"customer",'4. Raw load per load'!S5:S79) -> 5.7465 | F21: =SUM('5. Raw batt charge'!C21:AV21) -> 38.009 | G21: =SUM('6. Raw batt discharge'!C21:AV21) -> 0.3 | H21: =F21-G21 -> 37.709 | I21: =MIN(C21,D21) -> 12.4083 | J21: =MIN(C21-I21,MAX(0,H21)) -> 37.709 | K21: =MIN(C21-I21-J21,E21) -> 5.7465 | L21: =C21-I21-J21-K21 -> 25.6513 | M21: =E21-K21 -> 0
A22: 18 | B22: 8.5 | C22: =SUM('3. Raw PV per load'!T5:T79) -> 91.3202 | D22: =SUMIF('4. Raw load per load'!$B$5:$B$79,"prosumer",'4. Raw load per load'!T5:T79) -> 16.0986 | E22: =SUMIF('4. Raw load per load'!$B$5:$B$79,"customer",'4. Raw load per load'!T5:T79) -> 9.1175 | F22: =SUM('5. Raw batt charge'!C22:AV22) -> 25.925 | G22: =SUM('6. Raw batt discharge'!C22:AV22) -> 0.768 | H22: =F22-G22 -> 25.157 | I22: =MIN(C22,D22) -> 16.0986 | J22: =MIN(C22-I22,MAX(0,H22)) -> 25.157 | K22: =MIN(C22-I22-J22,E22) -> 9.1175 | L22: =C22-I22-J22-K22 -> 40.9471 | M22: =E22-K22 -> 0
A23: 19 | B23: 9 | C23: =SUM('3. Raw PV per load'!U5:U79) -> 99.6694 | D23: =SUMIF('4. Raw load per load'!$B$5:$B$79,"prosumer",'4. Raw load per load'!U5:U79) -> 16.784 | E23: =SUMIF('4. Raw load per load'!$B$5:$B$79,"customer",'4. Raw load per load'!U5:U79) -> 8.3509 | F23: =SUM('5. Raw batt charge'!C23:AV23) -> 13.709 | G23: =SUM('6. Raw batt discharge'!C23:AV23) -> 0.673 | H23: =F23-G23 -> 13.036 | I23: =MIN(C23,D23) -> 16.784 | J23: =MIN(C23-I23,MAX(0,H23)) -> 13.036 | K23: =MIN(C23-I23-J23,E23) -> 8.3509 | L23: =C23-I23-J23-K23 -> 61.4985 | M23: =E23-K23 -> 0
A24: 20 | B24: 9.5 | C24: =SUM('3. Raw PV per load'!V5:V79) -> 106.7904 | D24: =SUMIF('4. Raw load per load'!$B$5:$B$79,"prosumer",'4. Raw load per load'!V5:V79) -> 14.3857 | E24: =SUMIF('4. Raw load per load'!$B$5:$B$79,"customer",'4. Raw load per load'!V5:V79) -> 11.9382 | F24: =SUM('5. Raw batt charge'!C24:AV24) -> 9.074 | G24: =SUM('6. Raw batt discharge'!C24:AV24) -> 0.533 | H24: =F24-G24 -> 8.541 | I24: =MIN(C24,D24) -> 14.3857 | J24: =MIN(C24-I24,MAX(0,H24)) -> 8.541 | K24: =MIN(C24-I24-J24,E24) -> 11.9382 | L24: =C24-I24-J24-K24 -> 71.9255 | M24: =E24-K24 -> 0
A25: 21 | B25: 10 | C25: =SUM('3. Raw PV per load'!W5:W79) -> 113.04 | D25: =SUMIF('4. Raw load per load'!$B$5:$B$79,"prosumer",'4. Raw load per load'!W5:W79) -> 18.0242 | E25: =SUMIF('4. Raw load per load'!$B$5:$B$79,"customer",'4. Raw load per load'!W5:W79) -> 10.5084 | F25: =SUM('5. Raw batt charge'!C25:AV25) -> 4.44 | G25: =SUM('6. Raw batt discharge'!C25:AV25) -> 1.716 | H25: =F25-G25 -> 2.724 | I25: =MIN(C25,D25) -> 18.0242 | J25: =MIN(C25-I25,MAX(0,H25)) -> 2.724 | K25: =MIN(C25-I25-J25,E25) -> 10.5084 | L25: =C25-I25-J25-K25 -> 81.7834 | M25: =E25-K25 -> 0
A26: 22 | B26: 10.5 | C26: =SUM('3. Raw PV per load'!X5:X79) -> 118.1993 | D26: =SUMIF('4. Raw load per load'!$B$5:$B$79,"prosumer",'4. Raw load per load'!X5:X79) -> 12.4105 | E26: =SUMIF('4. Raw load per load'!$B$5:$B$79,"customer",'4. Raw load per load'!X5:X79) -> 10.0205 | F26: =SUM('5. Raw batt charge'!C26:AV26) -> 6.469 | G26: =SUM('6. Raw batt discharge'!C26:AV26) -> 0.363 | H26: =F26-G26 -> 6.106 | I26: =MIN(C26,D26) -> 12.4105 | J26: =MIN(C26-I26,MAX(0,H26)) -> 6.106 | K26: =MIN(C26-I26-J26,E26) -> 10.0205 | L26: =C26-I26-J26-K26 -> 89.6623 | M26: =E26-K26 -> 0
A27: 23 | B27: 11 | C27: =SUM('3. Raw PV per load'!Y5:Y79) -> 121.8598 | D27: =SUMIF('4. Raw load per load'!$B$5:$B$79,"prosumer",'4. Raw load per load'!Y5:Y79) -> 16.7722 | E27: =SUMIF('4. Raw load per load'!$B$5:$B$79,"customer",'4. Raw load per load'!Y5:Y79) -> 7.7387 | F27: =SUM('5. Raw batt charge'!C27:AV27) -> 5.527 | G27: =SUM('6. Raw batt discharge'!C27:AV27) -> 0 | H27: =F27-G27 -> 5.527 | I27: =MIN(C27,D27) -> 16.7722 | J27: =MIN(C27-I27,MAX(0,H27)) -> 5.527 | K27: =MIN(C27-I27-J27,E27) -> 7.7387 | L27: =C27-I27-J27-K27 -> 91.8219 | M27: =E27-K27 -> 0
A28: 24 | B28: 11.5 | C28: =SUM('3. Raw PV per load'!Z5:Z79) -> 123.4656 | D28: =SUMIF('4. Raw load per load'!$B$5:$B$79,"prosumer",'4. Raw load per load'!Z5:Z79) -> 19.1239 | E28: =SUMIF('4. Raw load per load'!$B$5:$B$79,"customer",'4. Raw load per load'!Z5:Z79) -> 7.767 | F28: =SUM('5. Raw batt charge'!C28:AV28) -> 3.108 | G28: =SUM('6. Raw batt discharge'!C28:AV28) -> 0.645 | H28: =F28-G28 -> 2.463 | I28: =MIN(C28,D28) -> 19.1239 | J28: =MIN(C28-I28,MAX(0,H28)) -> 2.463 | K28: =MIN(C28-I28-J28,E28) -> 7.767 | L28: =C28-I28-J28-K28 -> 94.1117 | M28: =E28-K28 -> 0
A29: 25 | B29: 12 | C29: =SUM('3. Raw PV per load'!AA5:AA79) -> 123.9301 | D29: =SUMIF('4. Raw load per load'!$B$5:$B$79,"prosumer",'4. Raw load per load'!AA5:AA79) -> 11.4409 | E29: =SUMIF('4. Raw load per load'!$B$5:$B$79,"customer",'4. Raw load per load'!AA5:AA79) -> 8.7308 | F29: =SUM('5. Raw batt charge'!C29:AV29) -> 3.054 | G29: =SUM('6. Raw batt discharge'!C29:AV29) -> 0 | H29: =F29-G29 -> 3.054 | I29: =MIN(C29,D29) -> 11.4409 | J29: =MIN(C29-I29,MAX(0,H29)) -> 3.054 | K29: =MIN(C29-I29-J29,E29) -> 8.7308 | L29: =C29-I29-J29-K29 -> 100.7044 | M29: =E29-K29 -> 0
A30: 26 | B30: 12.5 | C30: =SUM('3. Raw PV per load'!AB5:AB79) -> 123.0596 | D30: =SUMIF('4. Raw load per load'!$B$5:$B$79,"prosumer",'4. Raw load per load'!AB5:AB79) -> 13.7145 | E30: =SUMIF('4. Raw load per load'!$B$5:$B$79,"customer",'4. Raw load per load'!AB5:AB79) -> 9.0764 | F30: =SUM('5. Raw batt charge'!C30:AV30) -> 1.294 | G30: =SUM('6. Raw batt discharge'!C30:AV30) -> 0 | H30: =F30-G30 -> 1.294 | I30: =MIN(C30,D30) -> 13.7145 | J30: =MIN(C30-I30,MAX(0,H30)) -> 1.294 | K30: =MIN(C30-I30-J30,E30) -> 9.0764 | L30: =C30-I30-J30-K30 -> 98.9747 | M30: =E30-K30 -> 0
A31: 27 | B31: 13 | C31: =SUM('3. Raw PV per load'!AC5:AC79) -> 120.1383 | D31: =SUMIF('4. Raw load per load'!$B$5:$B$79,"prosumer",'4. Raw load per load'!AC5:AC79) -> 15.926 | E31: =SUMIF('4. Raw load per load'!$B$5:$B$79,"customer",'4. Raw load per load'!AC5:AC79) -> 7.5348 | F31: =SUM('5. Raw batt charge'!C31:AV31) -> 0.566 | G31: =SUM('6. Raw batt discharge'!C31:AV31) -> 0 | H31: =F31-G31 -> 0.566 | I31: =MIN(C31,D31) -> 15.926 | J31: =MIN(C31-I31,MAX(0,H31)) -> 0.566 | K31: =MIN(C31-I31-J31,E31) -> 7.5348 | L31: =C31-I31-J31-K31 -> 96.1115 | M31: =E31-K31 -> 0
A32: 28 | B32: 13.5 | C32: =SUM('3. Raw PV per load'!AD5:AD79) -> 115.6793 | D32: =SUMIF('4. Raw load per load'!$B$5:$B$79,"prosumer",'4. Raw load per load'!AD5:AD79) -> 17.8473 | E32: =SUMIF('4. Raw load per load'!$B$5:$B$79,"customer",'4. Raw load per load'!AD5:AD79) -> 12.1221 | F32: =SUM('5. Raw batt charge'!C32:AV32) -> 0 | G32: =SUM('6. Raw batt discharge'!C32:AV32) -> 0 | H32: =F32-G32 -> 0 | I32: =MIN(C32,D32) -> 17.8473 | J32: =MIN(C32-I32,MAX(0,H32)) -> 0 | K32: =MIN(C32-I32-J32,E32) -> 12.1221 | L32: =C32-I32-J32-K32 -> 85.7099 | M32: =E32-K32 -> 0
A33: 29 | B33: 14 | C33: =SUM('3. Raw PV per load'!AE5:AE79) -> 110.3579 | D33: =SUMIF('4. Raw load per load'!$B$5:$B$79,"prosumer",'4. Raw load per load'!AE5:AE79) -> 14.6549 | E33: =SUMIF('4. Raw load per load'!$B$5:$B$79,"customer",'4. Raw load per load'!AE5:AE79) -> 9.296 | F33: =SUM('5. Raw batt charge'!C33:AV33) -> 0 | G33: =SUM('6. Raw batt discharge'!C33:AV33) -> 0 | H33: =F33-G33 -> 0 | I33: =MIN(C33,D33) -> 14.6549 | J33: =MIN(C33-I33,MAX(0,H33)) -> 0 | K33: =MIN(C33-I33-J33,E33) -> 9.296 | L33: =C33-I33-J33-K33 -> 86.407 | M33: =E33-K33 -> 0
A34: 30 | B34: 14.5 | C34: =SUM('3. Raw PV per load'!AF5:AF79) -> 103.615 | D34: =SUMIF('4. Raw load per load'!$B$5:$B$79,"prosumer",'4. Raw load per load'!AF5:AF79) -> 14.3021 | E34: =SUMIF('4. Raw load per load'!$B$5:$B$79,"customer",'4. Raw load per load'!AF5:AF79) -> 7.2099 | F34: =SUM('5. Raw batt charge'!C34:AV34) -> 0 | G34: =SUM('6. Raw batt discharge'!C34:AV34) -> 0.262 | H34: =F34-G34 -> -0.262 | I34: =MIN(C34,D34) -> 14.3021 | J34: =MIN(C34-I34,MAX(0,H34)) -> 0 | K34: =MIN(C34-I34-J34,E34) -> 7.2099 | L34: =C34-I34-J34-K34 -> 82.103 | M34: =E34-K34 -> 0
A35: 31 | B35: 15 | C35: =SUM('3. Raw PV per load'!AG5:AG79) -> 96.4484 | D35: =SUMIF('4. Raw load per load'!$B$5:$B$79,"prosumer",'4. Raw load per load'!AG5:AG79) -> 15.7459 | E35: =SUMIF('4. Raw load per load'!$B$5:$B$79,"customer",'4. Raw load per load'!AG5:AG79) -> 8.0963 | F35: =SUM('5. Raw batt charge'!C35:AV35) -> 0.291 | G35: =SUM('6. Raw batt discharge'!C35:AV35) -> 0.439 | H35: =F35-G35 -> -0.148 | I35: =MIN(C35,D35) -> 15.7459 | J35: =MIN(C35-I35,MAX(0,H35)) -> 0 | K35: =MIN(C35-I35-J35,E35) -> 8.0963 | L35: =C35-I35-J35-K35 -> 72.6062 | M35: =E35-K35 -> 0
A36: 32 | B36: 15.5 | C36: =SUM('3. Raw PV per load'!AH5:AH79) -> 87.8247 | D36: =SUMIF('4. Raw load per load'!$B$5:$B$79,"prosumer",'4. Raw load per load'!AH5:AH79) -> 14.1586 | E36: =SUMIF('4. Raw load per load'!$B$5:$B$79,"customer",'4. Raw load per load'!AH5:AH79) -> 8.4069 | F36: =SUM('5. Raw batt charge'!C36:AV36) -> 0.488 | G36: =SUM('6. Raw batt discharge'!C36:AV36) -> 0 | H36: =F36-G36 -> 0.488 | I36: =MIN(C36,D36) -> 14.1586 | J36: =MIN(C36-I36,MAX(0,H36)) -> 0.488 | K36: =MIN(C36-I36-J36,E36) -> 8.4069 | L36: =C36-I36-J36-K36 -> 64.7712 | M36: =E36-K36 -> 0
A37: 33 | B37: 16 | C37: =SUM('3. Raw PV per load'!AI5:AI79) -> 78.113 | D37: =SUMIF('4. Raw load per load'!$B$5:$B$79,"prosumer",'4. Raw load per load'!AI5:AI79) -> 16.9228 | E37: =SUMIF('4. Raw load per load'!$B$5:$B$79,"customer",'4. Raw load per load'!AI5:AI79) -> 9.6717 | F37: =SUM('5. Raw batt charge'!C37:AV37) -> 0 | G37: =SUM('6. Raw batt discharge'!C37:AV37) -> 0.311 | H37: =F37-G37 -> -0.311 | I37: =MIN(C37,D37) -> 16.9228 | J37: =MIN(C37-I37,MAX(0,H37)) -> 0 | K37: =MIN(C37-I37-J37,E37) -> 9.6717 | L37: =C37-I37-J37-K37 -> 51.5185 | M37: =E37-K37 -> 0
A38: 34 | B38: 16.5 | C38: =SUM('3. Raw PV per load'!AJ5:AJ79) -> 66.3868 | D38: =SUMIF('4. Raw load per load'!$B$5:$B$79,"prosumer",'4. Raw load per load'!AJ5:AJ79) -> 16.186 | E38: =SUMIF('4. Raw load per load'!$B$5:$B$79,"customer",'4. Raw load per load'!AJ5:AJ79) -> 12.5338 | F38: =SUM('5. Raw batt charge'!C38:AV38) -> 0.111 | G38: =SUM('6. Raw batt discharge'!C38:AV38) -> 0.194 | H38: =F38-G38 -> -0.083 | I38: =MIN(C38,D38) -> 16.186 | J38: =MIN(C38-I38,MAX(0,H38)) -> 0 | K38: =MIN(C38-I38-J38,E38) -> 12.5338 | L38: =C38-I38-J38-K38 -> 37.667 | M38: =E38-K38 -> 0
A39: 35 | B39: 17 | C39: =SUM('3. Raw PV per load'!AK5:AK79) -> 55.4112 | D39: =SUMIF('4. Raw load per load'!$B$5:$B$79,"prosumer",'4. Raw load per load'!AK5:AK79) -> 17.7417 | E39: =SUMIF('4. Raw load per load'!$B$5:$B$79,"customer",'4. Raw load per load'!AK5:AK79) -> 8.7428 | F39: =SUM('5. Raw batt charge'!C39:AV39) -> 0.439 | G39: =SUM('6. Raw batt discharge'!C39:AV39) -> 1.436 | H39: =F39-G39 -> -0.997 | I39: =MIN(C39,D39) -> 17.7417 | J39: =MIN(C39-I39,MAX(0,H39)) -> 0 | K39: =MIN(C39-I39-J39,E39) -> 8.7428 | L39: =C39-I39-J39-K39 -> 28.9267 | M39: =E39-K39 -> 0
A40: 36 | B40: 17.5 | C40: =SUM('3. Raw PV per load'!AL5:AL79) -> 44.1331 | D40: =SUMIF('4. Raw load per load'!$B$5:$B$79,"prosumer",'4. Raw load per load'!AL5:AL79) -> 19.9173 | E40: =SUMIF('4. Raw load per load'!$B$5:$B$79,"customer",'4. Raw load per load'!AL5:AL79) -> 15.1361 | F40: =SUM('5. Raw batt charge'!C40:AV40) -> 0.325 | G40: =SUM('6. Raw batt discharge'!C40:AV40) -> 6.491 | H40: =F40-G40 -> -6.166 | I40: =MIN(C40,D40) -> 19.9173 | J40: =MIN(C40-I40,MAX(0,H40)) -> 0 | K40: =MIN(C40-I40-J40,E40) -> 15.1361 | L40: =C40-I40-J40-K40 -> 9.0797 | M40: =E40-K40 -> 0
