Workbook

Sheet 1. Overview
B2: TR3 — Where does the PV energy go?
B3: Prosumers vs. pure customers — every kWh traced from the raw model inputs
B5: Purpose
B6: This workbook accounts for every kWh of PV generated on transformer TR3 over one representative day, and it is fully auditable: nothing is hand-typed except the raw model outputs. Follow the data chain below — each step is a live formula, so changing any raw number updates everything.
B10: The data chain (how each number is built)
B11: Sheet 3 · Raw PV per load | C11: The PV profile of every connection, 48 half-hours. Copied verbatim from TR3_load_PV_48periods.xlsx (sheet PV_generation_kW). Customers = 0.
B12: Sheet 4 · Raw load per load | C12: The load profile of every connection, 48 half-hours, tagged prosumer / customer. Copied from TR3_load_PV_48periods.xlsx (sheet Load_P_kW).
B13: Sheet 5 · Raw batt charge | C13: Charging power of every battery, 48 half-hours. Copied from the rolling dispatch TR3_analysis_data.xlsx (sheet Charge_kW).
B14: Sheet 6 · Raw batt discharge | C14: Discharging power of every battery. Copied from the same run (Discharge_kW).
B15: Sheet 7 · PV allocation | C15: Per half-hour: the five blue inputs are AGGREGATED from sheets 3–6 by SUM / SUMIF; the amber columns then split the PV by the priority rule.
B16: Sheets 1 & 8 · Results | C16: Daily totals (Σ×0.5 h) and shares. Every headline cell links to sheet 7.
B18: The aggregation formulas (sheet 7, per half-hour)
B19: PV (all)
B20: prosumer load
B21: customer load
B22: battery charge
B23: battery discharge
B25: Headline results (all linked live to sheet 7)
B26: Quantity | C26: Value | D26: Unit
B27: Prosumers (PV + battery) | C27: 49 | D27: connections
B28: Pure customers (load only) | C28: 21 | D28: connections
B29: PV generated | C29: ='7. PV allocation (per period)'!C53 -> 1316.4443 | D29: kWh/day
B30: PV → prosumers' own load (direct) | C30: ='7. PV allocation (per period)'!I53 -> 223.66455 | D30: kWh/day
B31: PV → battery storage | C31: ='7. PV allocation (per period)'!J53 -> 162.998 | D31: kWh/day
B32: PV → customers | C32: ='7. PV allocation (per period)'!K53 -> 84.8832 | D32: kWh/day
B33: PV → export to grid | C33: ='7. PV allocation (per period)'!L53 -> 844.8986 | D33: kWh/day
B34: PV share reaching customers | C34: ='7. PV allocation (per period)'!K53/'7. PV allocation (per period)'!C53 -> 0.06447914 | D34: % of PV
B35: Customer load covered by PV | C35: ='7. PV allocation (per period)'!K53/'7. PV allocation (per period)'!E53 -> 0.51687797 | D35: % of customer load
B36: Customer load covered by grid | C36: ='7. PV allocation (per period)'!M53/'7. PV allocation (per period)'!E53 -> 0.48312203 | D36: % of customer load
B39: Colour key & provenance
B40: • LIGHT-BLUE cell = data belonging to a prosumer (its rooftop PV, load, or battery). WHITE = a pure customer (load only). On sheet 7: VIOLET = value aggregated live from the raw sheets (SUM/SUMIF); AMBER = allocation formula; GREEN = daily total (Σ × 0.5 h).
B41: • Per-load PV & load profiles: results/tables/TR3_load_PV_48periods.xlsx (built from OpData.xls).
B42: • Per-battery charge/discharge: TR3_analysis/01_DAILY_ROLLING_DISPATCH/TR3_analysis_data.xlsx (exact-QCP rolling dispatch, RunFOR_Rolling, CPLEX).
B43: • Load classification (PV size > 0 = prosumer): sheet 'Customers' of the load/PV workbook.
B44: • Method note: priority energy allocation per half-hour; downstream network + battery round-trip losses (~3–4% of PV) are not separated out in the per-period disposition.

Sheet 2. Load classification
A1: TR3 load classification — 70 connections
A2: 49 prosumers (PV + battery) · 21 pure customers (load only)
A4: ID | B4: Load name | C4: Bus | D4: Phase | E4: PV size (kW) | F4: Type
A5: 310 | B5: Load_TR3_F1_1 | C5: TR3_one38 | D5: 2 | E5: 0 | F5: customer
A6: 312 | B6: Load_TR3_F1_11 | C6: TR3_one223 | D6: 2 | E6: 0 | F6: customer
A7: 317 | B7: Load_TR3_F1_16 | C7: TR3_one280 | D7: 1 | E7: 0 | F7: customer
A8: 318 | B8: Load_TR3_F1_17 | C8: TR3_one287 | D8: 2 | E8: 0 | F8: customer
A9: 323 | B9: Load_TR3_F1_21 | C9: TR3_one321 | D9: 3 | E9: 0 | F9: customer
A10: 324 | B10: Load_TR3_F1_22 | C10: TR3_one328 | D10: 1 | E10: 0 | F10: customer
A11: 325 | B11: Load_TR3_F1_23 | C11: TR3_one345 | D11: 1 | E11: 0 | F11: customer
A12: 333 | B12: Load_TR3_F1_30 | C12: TR3_one416 | D12: 3 | E12: 0 | F12: customer
A13: 342 | B13: Load_TR3_F1_39 | C13: TR3_one537 | D13: 1 | E13: 0 | F13: customer
A14: 347 | B14: Load_TR3_F1_43 | C14: TR3_one560 | D14: 3 | E14: 0 | F14: customer
A15: 349 | B15: Load_TR3_F1_45 | C15: TR3_one585 | D15: 1 | E15: 0 | F15: customer
A16: 350 | B16: Load_TR3_F1_46 | C16: TR3_one590 | D16: 1 | E16: 0 | F16: customer
... A74: 379 | B74: Load_TR3_F2_9 | C74: TR3_two242 | D74: 2 | E74: 2 | F74: prosumer

Sheet 3. Raw PV per load
A1: Raw PV per load
A2: Verbatim copy of PV_generation_kW (TR3_load_PV_48periods.xlsx). One row per connection, 48 half-hours (kW).
A4: Load name | B4: Type | C4: p1 | D4: p2 | E4: p3 | F4: p4 | G4: p5 | H4: p6 | I4: p7 | J4: p8 | K4: p9 | L4: p10 | M4: p11 | N4: p12 | O4: p13 | P4: p14 | Q4: p15 | R4: p16 | S4: p17 | T4: p18 | U4: p19 | V4: p20 | W4: p21 | X4: p22 | Y4: p23 | Z4: p24 | AA4: p25 | AB4: p26 | AC4: p27 | AD4: p28 | AE4: p29 | AF4: p30 | AG4: p31 | AH4: p32 | AI4: p33 | AJ4: p34 | AK4: p35 | AL4: p36 | AM4: p37 | AN4: p38 | AO4: p39 | AP4: p40 | AQ4: p41 | AR4: p42 | AS4: p43 | AT4: p44 | AU4: p45 | AV4: p46 | AW4: p47 | AX4: p48
A5: Load_TR3_F1_1 | B5: customer | C5: 0 | D5: 0 | E5: 0 | F5: 0 | G5: 0 | H5: 0 | I5: 0 | J5: 0 | K5: 0 | L5: 0 | M5: 0 | N5: 0 | O5: 0 | P5: 0 | Q5: 0 | R5: 0 | S5: 0 | T5: 0 | U5: 0 | V5: 0 | W5: 0 | X5: 0 | Y5: 0 | Z5: 0 | AA5: 0 | AB5: 0 | AC5: 0 | AD5: 0 | AE5: 0 | AF5: 0 | AG5: 0 | AH5: 0 | AI5: 0 | AJ5: 0 | AK5: 0 | AL5: 0 | AM5: 0 | AN5: 0 | AO5: 0 | AP5: 0 | AQ5: 0 | AR5: 0 | AS5: 0 | AT5: 0 | AU5: 0 | AV5: 0 | AW5: 0 | AX5: 0
A6: Load_TR3_F1_10 | B6: prosumer | C6: 0 | D6: 0 | E6: 0 | F6: 0 | G6: 0 | H6: 0 | I6: 0 | J6: 0.0034 | K6: 0.0497 | L6: 0.2326 | M6: 0.4613 | N6: 0.7419 | O6: 1.0479 | P6: 1.3577 | Q6: 1.666 | R6: 1.9746 | S6: 2.2643 | T6: 2.5367 | U6: 2.7686 | V6: 2.9664 | W6: 3.14 | X6: 3.2833 | Y6: 3.385 | Z6: 3.4296 | AA6: 3.4425 | AB6: 3.4183 | AC6: 3.3372 | AD6: 3.2133 | AE6: 3.0655 | AF6: 2.8782 | AG6: 2.6791 | AH6: 2.4396 | AI6: 2.1698 | AJ6: 1.8441 | AK6: 1.5392 | AL6: 1.2259 | AM6: 0.9229 | AN6: 0.6308 | AO6: 0.3683 | AP6: 0.1072 | AQ6: 0.0198 | AR6: 0 | AS6: 0 | AT6: 0 | AU6: 0 | AV6: 0 | AW6: 0 | AX6: 0
A7: Load_TR3_F1_11 | B7: customer | C7: 0 | D7: 0 | E7: 0 | F7: 0 | G7: 0 | H7: 0 | I7: 0 | J7: 0 | K7: 0 | L7: 0 | M7: 0 | N7: 0 | O7: 0 | P7: 0 | Q7: 0 | R7: 0 | S7: 0 | T7: 0 | U7: 0 | V7: 0 | W7: 0 | X7: 0 | Y7: 0 | Z7: 0 | AA7: 0 | AB7: 0 | AC7: 0 | AD7: 0 | AE7: 0 | AF7: 0 | AG7: 0 | AH7: 0 | AI7: 0 | AJ7: 0 | AK7: 0 | AL7: 0 | AM7: 0 | AN7: 0 | AO7: 0 | AP7: 0 | AQ7: 0 | AR7: 0 | AS7: 0 | AT7: 0 | AU7: 0 | AV7: 0 | AW7: 0 | AX7: 0
A8: Load_TR3_F1_12 | B8: prosumer | C8: 0 | D8: 0 | E8: 0 | F8: 0 | G8: 0 | H8: 0 | I8: 0 | J8: 0.0034 | K8: 0.0497 | L8: 0.2326 | M8: 0.4613 | N8: 0.7419 | O8: 1.0479 | P8: 1.3577 | Q8: 1.666 | R8: 1.9746 | S8: 2.2643 | T8: 2.5367 | U8: 2.7686 | V8: 2.9664 | W8: 3.14 | X8: 3.2833 | Y8: 3.385 | Z8: 3.4296 | AA8: 3.4425 | AB8: 3.4183 | AC8: 3.3372 | AD8: 3.2133 | AE8: 3.0655 | AF8: 2.8782 | AG8: 2.6791 | AH8: 2.4396 | AI8: 2.1698 | AJ8: 1.8441 | AK8: 1.5392 | AL8: 1.2259 | AM8: 0.9229 | AN8: 0.6308 | AO8: 0.3683 | AP8: 0.1072 | AQ8: 0.0198 | AR8: 0 | AS8: 0 | AT8: 0 | AU8: 0 | AV8: 0 | AW8: 0 | AX8: 0
A9: Load_TR3_F1_13 | B9: prosumer | C9: 0 | D9: 0 | E9: 0 | F9: 0 | G9: 0 | H9: 0 | I9: 0 | J9: 0.0034 | K9: 0.0497 | L9: 0.2326 | M9: 0.4613 | N9: 0.7419 | O9: 1.0479 | P9: 1.3577 | Q9: 1.666 | R9: 1.9746 | S9: 2.2643 | T9: 2.5367 | U9: 2.7686 | V9: 2.9664 | W9: 3.14 | X9: 3.2833 | Y9: 3.385 | Z9: 3.4296 | AA9: 3.4425 | AB9: 3.4183 | AC9: 3.3372 | AD9: 3.2133 | AE9: 3.0655 | AF9: 2.8782 | AG9: 2.6791 | AH9: 2.4396 | AI9: 2.1698 | AJ9: 1.8441 | AK9: 1.5392 | AL9: 1.2259 | AM9: 0.9229 | AN9: 0.6308 | AO9: 0.3683 | AP9: 0.1072 | AQ9: 0.0198 | AR9: 0 | AS9: 0 | AT9: 0 | AU9: 0 | AV9: 0 | AW9: 0 | AX9: 0
A10: Load_TR3_F1_14 | B10: prosumer | C10: 0 | D10: 0 | E10: 0 | F10: 0 | G10: 0 | H10: 0 | I10: 0 | J10: 0.0026 | K10: 0.0373 | L10: 0.1744 | M10: 0.346 | N10: 0.5564 | O10: 0.7859 | P10: 1.0183 | Q10: 1.2495 | R10: 1.481 | S10: 1.6982 | T10: 1.9025 | U10: 2.0764 | V10: 2.2248 | W10: 2.355 | X10: 2.4625 | Y10: 2.5387 | Z10: 2.5722 | AA10: 2.5819 | AB10: 2.5637 | AC10: 2.5029 | AD10: 2.41 | AE10: 2.2991 | AF10: 2.1586 | AG10: 2.0093 | AH10: 1.8297 | AI10: 1.6274 | AJ10: 1.3831 | AK10: 1.1544 | AL10: 0.9195 | AM10: 0.6922 | AN10: 0.4731 | AO10: 0.2762 | AP10: 0.0804 | AQ10: 0.0148 | AR10: 0 | AS10: 0 | AT10: 0 | AU10: 0 | AV10: 0 | AW10: 0 | AX10: 0
A11: Load_TR3_F1_15 | B11: prosumer | C11: 0 | D11: 0 | E11: 0 | F11: 0 | G11: 0 | H11: 0 | I11: 0 | J11: 0.0034 | K11: 0.0497 | L11: 0.2326 | M11: 0.4613 | N11: 0.7419 | O11: 1.0479 | P11: 1.3577 | Q11: 1.666 | R11: 1.9746 | S11: 2.2643 | T11: 2.5367 | U11: 2.7686 | V11: 2.9664 | W11: 3.14 | X11: 3.2833 | Y11: 3.385 | Z11: 3.4296 | AA11: 3.4425 | AB11: 3.4183 | AC11: 3.3372 | AD11: 3.2133 | AE11: 3.0655 | AF11: 2.8782 | AG11: 2.6791 | AH11: 2.4396 | AI11: 2.1698 | AJ11: 1.8441 | AK11: 1.5392 | AL11: 1.2259 | AM11: 0.9229 | AN11: 0.6308 | AO11: 0.3683 | AP11: 0.1072 | AQ11: 0.0198 | AR11: 0 | AS11: 0 | AT11: 0 | AU11: 0 | AV11: 0 | AW11: 0 | AX11: 0
A12: Load_TR3_F1_16 | B12: customer | C12: 0 | D12: 0 | E12: 0 | F12: 0 | G12: 0 | H12: 0 | I12: 0 | J12: 0 | K12: 0 | L12: 0 | M12: 0 | N12: 0 | O12: 0 | P12: 0 | Q12: 0 | R12: 0 | S12: 0 | T12: 0 | U12: 0 | V12: 0 | W12: 0 | X12: 0 | Y12: 0 | Z12: 0 | AA12: 0 | AB12: 0 | AC12: 0 | AD12: 0 | AE12: 0 | AF12: 0 | AG12: 0 | AH12: 0 | AI12: 0 | AJ12: 0 | AK12: 0 | AL12: 0 | AM12: 0 | AN12: 0 | AO12: 0 | AP12: 0 | AQ12: 0 | AR12: 0 | AS12: 0 | AT12: 0 | AU12: 0 | AV12: 0 | AW12: 0 | AX12: 0
A13: Load_TR3_F1_17 | B13: customer | C13: 0 | D13: 0 | E13: 0 | F13: 0 | G13: 0 | H13: 0 | I13: 0 | J13: 0 | K13: 0 | L13: 0 | M13: 0 | N13: 0 | O13: 0 | P13: 0 | Q13: 0 | R13: 0 | S13: 0 | T13: 0 | U13: 0 | V13: 0 | W13: 0 | X13: 0 | Y13: 0 | Z13: 0 | AA13: 0 | AB13: 0 | AC13: 0 | AD13: 0 | AE13: 0 | AF13: 0 | AG13: 0 | AH13: 0 | AI13: 0 | AJ13: 0 | AK13: 0 | AL13: 0 | AM13: 0 | AN13: 0 | AO13: 0 | AP13: 0 | AQ13: 0 | AR13: 0 | AS13: 0 | AT13: 0 | AU13: 0 | AV13: 0 | AW13: 0 | AX13: 0
A14: Load_TR3_F1_18 | B14: prosumer | C14: 0 | D14: 0 | E14: 0 | F14: 0 | G14: 0 | H14: 0 | I14: 0 | J14: 0.0034 | K14: 0.0497 | L14: 0.2326 | M14: 0.4613 | N14: 0.7419 | O14: 1.0479 | P14: 1.3577 | Q14: 1.666 | R14: 1.9746 | S14: 2.2643 | T14: 2.5367 | U14: 2.7686 | V14: 2.9664 | W14: 3.14 | X14: 3.2833 | Y14: 3.385 | Z14: 3.4296 | AA14: 3.4425 | AB14: 3.4183 | AC14: 3.3372 | AD14: 3.2133 | AE14: 3.0655 | AF14: 2.8782 | AG14: 2.6791 | AH14: 2.4396 | AI14: 2.1698 | AJ14: 1.8441 | AK14: 1.5392 | AL14: 1.2259 | AM14: 0.9229 | AN14: 0.6308 | AO14: 0.3683 | AP14: 0.1072 | AQ14: 0.0198 | AR14: 0 | AS14: 0 | AT14: 0 | AU14: 0 | AV14: 0 | AW14: 0 | AX14: 0
A15: Load_TR3_F1_19 | B15: prosumer | C15: 0 | D15: 0 | E15: 0 | F15: 0 | G15: 0 | H15: 0 | I15: 0 | J15: 0.0026 | K15: 0.0373 | L15: 0.1744 | M15: 0.346 | N15: 0.5564 | O15: 0.7859 | P15: 1.0183 | Q15: 1.2495 | R15: 1.481 | S15: 1.6982 | T15: 1.9025 | U15: 2.0764 | V15: 2.2248 | W15: 2.355 | X15: 2.4625 | Y15: 2.5387 | Z15: 2.5722 | AA15: 2.5819 | AB15: 2.5637 | AC15: 2.5029 | AD15: 2.41 | AE15: 2.2991 | AF15: 2.1586 | AG15: 2.0093 | AH15: 1.8297 | AI15: 1.6274 | AJ15: 1.3831 | AK15: 1.1544 | AL15: 0.9195 | AM15: 0.6922 | AN15: 0.4731 | AO15: 0.2762 | AP15: 0.0804 | AQ15: 0.0148 | AR15: 0 | AS15: 0 | AT15: 0 | AU15: 0 | AV15: 0 | AW15: 0 | AX15: 0
A16: Load_TR3_F1_2 | B16: prosumer | C16: 0 | D16: 0 | E16: 0 | F16: 0 | G16: 0 | H16: 0 | I16: 0 | J16: 0.003 | K16: 0.0435 | L16: 0.2035 | M16: 0.4037 | N16: 0.6491 | O16: 0.9169 | P16: 1.188 | Q16: 1.4577 | R16: 1.7278 | S16: 1.9813 | T16: 2.2196 | U16: 2.4225 | V16: 2.5956 | W16: 2.7475 | X16: 2.8729 | Y16: 2.9619 | Z16: 3.0009 | AA16: 3.0122 | AB16: 2.991 | AC16: 2.92 | AD16: 2.8117 | AE16: 2.6823 | AF16: 2.5184 | AG16: 2.3442 | AH16: 2.1346 | AI16: 1.8986 | AJ16: 1.6136 | AK16: 1.3468 | AL16: 1.0727 | AM16: 0.8076 | AN16: 0.5519 | AO16: 0.3223 | AP16: 0.0938 | AQ16: 0.0173 | AR16: 0 | AS16: 0 | AT16: 0 | AU16: 0 | AV16: 0 | AW16: 0 | AX16: 0
... A74: Load_TR3_F2_9 | B74: prosumer | C74: 0 | D74: 0 | E74: 0 | F74: 0 | G74: 0 | H74: 0 | I74: 0 | J74: 0.0017 | K74: 0.0249 | L74: 0.1163 | M74: 0.2307 | N74: 0.3709 | O74: 0.524 | P74: 0.6789 | Q74: 0.833 | R74: 0.9873 | S74: 1.1322 | T74: 1.2683 | U74: 1.3843 | V74: 1.4832 | W74: 1.57 | X74: 1.6417 | Y74: 1.6925 | Z74: 1.7148 | AA74: 1.7212 | AB74: 1.7092 | AC74: 1.6686 | AD74: 1.6067 | AE74: 1.5328 | AF74: 1.4391 | AG74: 1.3396 | AH74: 1.2198 | AI74: 1.0849 | AJ74: 0.922 | AK74: 0.7696 | AL74: 0.613 | AM74: 0.4615 | AN74: 0.3154 | AO74: 0.1842 | AP74: 0.0536 | AQ74: 0.0099 | AR74: 0 | AS74: 0 | AT74: 0 | AU74: 0 | AV74: 0 | AW74: 0 | AX74: 0

Sheet 4. Raw load per load
A1: Raw load per load
A2: Verbatim copy of Load_P_kW (TR3_load_PV_48periods.xlsx), tagged by type. One row per connection, 48 half-hours (kW).
A4: Load name | B4: Type | C4: p1 | D4: p2 | E4: p3 | F4: p4 | G4: p5 | H4: p6 | I4: p7 | J4: p8 | K4: p9 | L4: p10 | M4: p11 | N4: p12 | O4: p13 | P4: p14 | Q4: p15 | R4: p16 | S4: p17 | T4: p18 | U4: p19 | V4: p20 | W4: p21 | X4: p22 | Y4: p23 | Z4: p24 | AA4: p25 | AB4: p26 | AC4: p27 | AD4: p28 | AE4: p29 | AF4: p30 | AG4: p31 | AH4: p32 | AI4: p33 | AJ4: p34 | AK4: p35 | AL4: p36 | AM4: p37 | AN4: p38 | AO4: p39 | AP4: p40 | AQ4: p41 | AR4: p42 | AS4: p43 | AT4: p44 | AU4: p45 | AV4: p46 | AW4: p47 | AX4: p48
A5: Load_TR3_F1_1 | B5: customer | C5: 0.9617 | D5: 0.5561 | E5: 0.8354 | F5: 0.7362 | G5: 0.1576 | H5: 0.137 | I5: 0.2422 | J5: 0.2307 | K5: 0.0639 | L5: 0.2913 | M5: 0.1906 | N5: 0.4184 | O5: 0.6373 | P5: 0.3183 | Q5: 0.4199 | R5: 0.1819 | S5: 0.2082 | T5: 0.4571 | U5: 1.5202 | V5: 0.2489 | W5: 0.1637 | X5: 0.2213 | Y5: 0.3085 | Z5: 0.3175 | AA5: 0.1993 | AB5: 0.4181 | AC5: 0.1968 | AD5: 0.5473 | AE5: 0.7599 | AF5: 0.4932 | AG5: 0.2217 | AH5: 0.7588 | AI5: 0.1884 | AJ5: 0.2482 | AK5: 0.3904 | AL5: 0.5471 | AM5: 1.3444 | AN5: 0.7669 | AO5: 1.3423 | AP5: 0.2905 | AQ5: 0.3876 | AR5: 0.766 | AS5: 0.264 | AT5: 0.8794 | AU5: 1.2691 | AV5: 0.4119 | AW5: 0.6214 | AX5: 0.1681
A6: Load_TR3_F1_10 | B6: prosumer | C6: 0.1897 | D6: 0.2611 | E6: 0.0791 | F6: 0.2595 | G6: 0.1702 | H6: 0.1543 | I6: 0.2043 | J6: 0.1818 | K6: 0.1425 | L6: 0.1147 | M6: 0.2849 | N6: 0.1092 | O6: 0.2156 | P6: 0.1754 | Q6: 0.1177 | R6: 0.2523 | S6: 3.5086 | T6: 1.2015 | U6: 0.9525 | V6: 0.316 | W6: 1.4874 | X6: 1.4209 | Y6: 1.0839 | Z6: 0.4138 | AA6: 0.2612 | AB6: 0.0993 | AC6: 0.4685 | AD6: 0.1098 | AE6: 0.2649 | AF6: 0.1957 | AG6: 0.4001 | AH6: 0.2838 | AI6: 0.1625 | AJ6: 0.2981 | AK6: 0.2266 | AL6: 0.3572 | AM6: 0.2695 | AN6: 0.4171 | AO6: 0.3557 | AP6: 0.6853 | AQ6: 0.7839 | AR6: 0.6368 | AS6: 0.969 | AT6: 0.695 | AU6: 1.1144 | AV6: 0.9802 | AW6: 0.1801 | AX6: 0.9379
A7: Load_TR3_F1_11 | B7: customer | C7: 0.1034 | D7: 0.089 | E7: 0.2085 | F7: 0.2412 | G7: 0.2768 | H7: 0.046 | I7: 0.1751 | J7: 0.0747 | K7: 0.1177 | L7: 0.1321 | M7: 0.046 | N7: 0.2038 | O7: 0.046 | P7: 0.1894 | Q7: 0.0603 | R7: 0.046 | S7: 0.0494 | T7: 0.0692 | U7: 0.1751 | V7: 0.0747 | W7: 0.046 | X7: 0.0747 | Y7: 0.1751 | Z7: 0.046 | AA7: 0.3215 | AB7: 0.1177 | AC7: 0.046 | AD7: 0.2106 | AE7: 0.0601 | AF7: 0.1308 | AG7: 0.4847 | AH7: 0.245 | AI7: 0.1679 | AJ7: 0.0921 | AK7: 2.1325 | AL7: 2.5812 | AM7: 1.7829 | AN7: 0.052 | AO7: 0.1044 | AP7: 0.6324 | AQ7: 0.0603 | AR7: 0.0532 | AS7: 0.6161 | AT7: 0.4601 | AU7: 0.6164 | AV7: 0.7547 | AW7: 0.5523 | AX7: 1.4402
A8: Load_TR3_F1_12 | B8: prosumer | C8: 0.046 | D8: 0.1072 | E8: 0.1908 | F8: 0.0725 | G8: 0.1989 | H8: 0.046 | I8: 0.2431 | J8: 0.0814 | K8: 0.0858 | L8: 0.2387 | M8: 0.0681 | N8: 0.2563 | O8: 0.046 | P8: 0.1123 | Q8: 0.2121 | R8: 0.046 | S8: 0.196 | T8: 0.1534 | U8: 0.0898 | V8: 0.991 | W8: 0.5618 | X8: 0.3996 | Y8: 0.1351 | Z8: 0.258 | AA8: 0.1792 | AB8: 0.103 | AC8: 0.5726 | AD8: 0.0536 | AE8: 0.1454 | AF8: 0.0995 | AG8: 0.046 | AH8: 0.1256 | AI8: 0.0813 | AJ8: 1.1341 | AK8: 3.1862 | AL8: 2.1118 | AM8: 0.1759 | AN8: 0.1365 | AO8: 0.1237 | AP8: 0.2102 | AQ8: 0.2442 | AR8: 0.4009 | AS8: 0.5292 | AT8: 0.3365 | AU8: 0.3203 | AV8: 0.6663 | AW8: 0.046 | AX8: 0.1759
A9: Load_TR3_F1_13 | B9: prosumer | C9: 0.046 | D9: 0.3098 | E9: 0.0573 | F9: 0.1178 | G9: 0.1614 | H9: 0.0629 | I9: 0.236 | J9: 0.1311 | K9: 0.48 | L9: 0.2878 | M9: 0.2131 | N9: 0.2759 | O9: 0.1452 | P9: 0.046 | Q9: 0.2084 | R9: 0.046 | S9: 0.1808 | T9: 0.1863 | U9: 0.8571 | V9: 0.7638 | W9: 0.2577 | X9: 0.2316 | Y9: 0.1854 | Z9: 0.0869 | AA9: 0.1549 | AB9: 0.1914 | AC9: 0.2097 | AD9: 0.1813 | AE9: 0.1463 | AF9: 0.1136 | AG9: 0.046 | AH9: 0.2935 | AI9: 0.1551 | AJ9: 0.0742 | AK9: 0.2312 | AL9: 0.1077 | AM9: 0.1587 | AN9: 0.1454 | AO9: 0.32 | AP9: 0.3603 | AQ9: 0.442 | AR9: 0.5171 | AS9: 0.5757 | AT9: 0.3551 | AU9: 0.276 | AV9: 0.0742 | AW9: 0.1632 | AX9: 0.1757
A10: Load_TR3_F1_14 | B10: prosumer | C10: 0.3805 | D10: 0.1247 | E10: 0.048 | F10: 0.166 | G10: 0.048 | H10: 0.166 | I10: 0.048 | J10: 0.0716 | K10: 0.1424 | L10: 0.048 | M10: 0.166 | N10: 0.048 | O10: 0.166 | P10: 0.048 | Q10: 1.5799 | R10: 0.0716 | S10: 0.1365 | T10: 0.6076 | U10: 0.644 | V10: 1.8739 | W10: 0.056 | X10: 0.0765 | Y10: 0.2355 | Z10: 0.1938 | AA10: 0.1938 | AB10: 0.1423 | AC10: 1.3364 | AD10: 0.8488 | AE10: 0.2237 | AF10: 0.1355 | AG10: 0.1634 | AH10: 0.3957 | AI10: 0.0821 | AJ10: 0.1011 | AK10: 0.1129 | AL10: 0.2935 | AM10: 2.6605 | AN10: 2.272 | AO10: 0.1542 | AP10: 0.0598 | AQ10: 0.048 | AR10: 0.2334 | AS10: 0.1269 | AT10: 0.4062 | AU10: 0.3871 | AV10: 0.4897 | AW10: 0.2498 | AX10: 0.048
A11: Load_TR3_F1_15 | B11: prosumer | C11: 0.048 | D11: 0.2095 | E11: 0.048 | F11: 0.048 | G11: 0.0718 | H11: 0.1434 | I11: 0.048 | J11: 0.048 | K11: 0.048 | L11: 0.1672 | M11: 0.048 | N11: 0.1136 | O11: 0.1016 | P11: 0.048 | Q11: 0.0957 | R11: 0.1195 | S11: 0.048 | T11: 0.1672 | U11: 0.096 | V11: 0.1672 | W11: 0.0929 | X11: 0.0581 | Y11: 0.171 | Z11: 0.9263 | AA11: 0.048 | AB11: 0.3516 | AC11: 0.148 | AD11: 0.2672 | AE11: 0.0612 | AF11: 0.1023 | AG11: 0.3294 | AH11: 0.2348 | AI11: 0.3727 | AJ11: 0.2383 | AK11: 0.0931 | AL11: 0.3196 | AM11: 0.3716 | AN11: 0.4502 | AO11: 0.5657 | AP11: 0.2976 | AQ11: 0.1987 | AR11: 0.942 | AS11: 1.1321 | AT11: 0.4801 | AU11: 0.4652 | AV11: 0.3495 | AW11: 0.048 | AX11: 0.1672
A12: Load_TR3_F1_16 | B12: customer | C12: 0.052 | D12: 0.052 | E12: 0.052 | F12: 0.052 | G12: 0.0717 | H12: 0.1769 | I12: 0.052 | J12: 0.1769 | K12: 0.0717 | L12: 0.052 | M12: 0.1901 | N12: 0.0586 | O12: 0.0849 | P12: 0.1638 | Q12: 0.052 | R12: 0.052 | S12: 0.0798 | T12: 0.1887 | U12: 0.0876 | V12: 0.2011 | W12: 0.9673 | X12: 0.2479 | Y12: 0.1966 | Z12: 0.052 | AA12: 0.1835 | AB12: 0.0651 | AC12: 0.0651 | AD12: 0.1835 | AE12: 0.052 | AF12: 0.1966 | AG12: 0.052 | AH12: 0.1572 | AI12: 0.0914 | AJ12: 0.1177 | AK12: 0.1309 | AL12: 0.0564 | AM12: 0.3696 | AN12: 1.1587 | AO12: 0.2483 | AP12: 0.3633 | AQ12: 0.7898 | AR12: 0.4565 | AS12: 0.5198 | AT12: 0.5305 | AU12: 0.4802 | AV12: 0.4264 | AW12: 0.1608 | AX12: 0.1875
A13: Load_TR3_F1_17 | B13: customer | C13: 0.6712 | D13: 0.4177 | E13: 0.05 | F13: 0.05 | G13: 0.1163 | H13: 0.0583 | I13: 0.108 | J13: 0.0666 | K13: 0.0997 | L13: 0.0749 | M13: 0.05 | N13: 0.05 | O13: 0.05 | P13: 0.0956 | Q13: 0.079 | R13: 0.05 | S13: 2.8977 | T13: 0.121 | U13: 0.3161 | V13: 0.2878 | W13: 0.3551 | X13: 0.2553 | Y13: 0.0989 | Z13: 0.1729 | AA13: 0.6402 | AB13: 2.6501 | AC13: 3.4538 | AD13: 0.1012 | AE13: 0.0523 | AF13: 0.1741 | AG13: 0.1074 | AH13: 0.05 | AI13: 0.29 | AJ13: 0.1555 | AK13: 0.3803 | AL13: 0.6844 | AM13: 0.836 | AN13: 0.7187 | AO13: 2.0877 | AP13: 0.7713 | AQ13: 1.3992 | AR13: 0.593 | AS13: 0.6949 | AT13: 0.7518 | AU13: 0.5373 | AV13: 0.3644 | AW13: 0.5584 | AX13: 0.2376
A14: Load_TR3_F1_18 | B14: prosumer | C14: 0.1036 | D14: 0.1706 | E14: 0.0976 | F14: 0.0586 | G14: 0.2602 | H14: 0.053 | I14: 0.1323 | J14: 0.1865 | K14: 0.053 | L14: 0.174 | M14: 0.1448 | N14: 0.053 | O14: 0.1223 | P14: 0.587 | Q14: 1.4668 | R14: 0.2019 | S14: 1.5513 | T14: 0.6897 | U14: 0.3013 | V14: 0.3667 | W14: 0.2005 | X14: 0.1182 | Y14: 0.3666 | Z14: 0.3576 | AA14: 0.1422 | AB14: 0.1766 | AC14: 0.053 | AD14: 0.1422 | AE14: 0.1766 | AF14: 0.1422 | AG14: 0.053 | AH14: 0.2658 | AI14: 0.053 | AJ14: 0.1373 | AK14: 0.1716 | AL14: 0.2485 | AM14: 0.4158 | AN14: 0.3752 | AO14: 0.3559 | AP14: 0.4472 | AQ14: 0.4233 | AR14: 0.5942 | AS14: 0.442 | AT14: 1.4198 | AU14: 1.6793 | AV14: 0.4103 | AW14: 0.2411 | AX14: 0.171
A15: Load_TR3_F1_19 | B15: prosumer | C15: 0.3398 | D15: 0.053 | E15: 0.1617 | F15: 0.2429 | G15: 0.0866 | H15: 0.0866 | I15: 0.1951 | J15: 0.1562 | K15: 0.177 | L15: 0.0908 | M15: 0.2076 | N15: 0.1643 | O15: 0.1646 | P15: 0.2153 | Q15: 0.5527 | R15: 0.6306 | S15: 0.4116 | T15: 0.232 | U15: 0.1718 | V15: 0.1016 | W15: 0.202 | X15: 0.2074 | Y15: 0.1173 | Z15: 0.2429 | AA15: 0.1727 | AB15: 0.1962 | AC15: 0.3358 | AD15: 0.1472 | AE15: 0.458 | AF15: 1.2857 | AG15: 0.2749 | AH15: 0.4339 | AI15: 1.0597 | AJ15: 0.8525 | AK15: 0.4597 | AL15: 0.5032 | AM15: 0.3017 | AN15: 0.1286 | AO15: 0.2313 | AP15: 0.5028 | AQ15: 0.5858 | AR15: 0.7609 | AS15: 0.6387 | AT15: 0.7756 | AU15: 0.6367 | AV15: 0.6774 | AW15: 0.6668 | AX15: 0.1338
A16: Load_TR3_F1_2 | B16: prosumer | C16: 0.033 | D16: 0.033 | E16: 0.033 | F16: 0.0689 | G16: 0.0689 | H16: 0.033 | I16: 0.033 | J16: 0.033 | K16: 0.0969 | L16: 0.041 | M16: 0.061 | N16: 0.0769 | O16: 0.0809 | P16: 0.057 | Q16: 0.033 | R16: 0.057 | S16: 0.2721 | T16: 0.1381 | U16: 0.21 | V16: 0.0728 | W16: 0.1324 | X16: 0.089 | Y16: 3.11 | Z16: 2.2321 | AA16: 0.6365 | AB16: 0.1025 | AC16: 0.1166 | AD16: 0.0567 | AE16: 0.1186 | AF16: 0.058 | AG16: 0.053 | AH16: 0.135 | AI16: 0.2414 | AJ16: 0.069 | AK16: 0.0889 | AL16: 0.033 | AM16: 0.033 | AN16: 0.1097 | AO16: 0.0815 | AP16: 0.042 | AQ16: 0.0621 | AR16: 0.1009 | AS16: 0.033 | AT16: 0.041 | AU16: 0.0969 | AV16: 0.033 | AW16: 0.1049 | AX16: 0.033
... A74: Load_TR3_F2_9 | B74: prosumer | C74: 0.7686 | D74: 0.1095 | E74: 0.2172 | F74: 0.1095 | G74: 0.033 | H74: 0.1095 | I74: 0.0581 | J74: 0.1921 | K74: 0.0925 | L74: 0.2091 | M74: 0.0581 | N74: 0.1095 | O74: 0.2172 | P74: 0.0585 | Q74: 0.2514 | R74: 0.0497 | S74: 0.21 | T74: 0.2476 | U74: 0.0925 | V74: 0.184 | W74: 0.1512 | X74: 0.1252 | Y74: 0.1335 | Z74: 0.1346 | AA74: 0.2214 | AB74: 0.3324 | AC74: 0.4193 | AD74: 0.1346 | AE74: 0.033 | AF74: 0.0879 | AG74: 0.379 | AH74: 0.0614 | AI74: 0.2287 | AJ74: 0.5115 | AK74: 0.2686 | AL74: 0.2853 | AM74: 0.0986 | AN74: 0.0615 | AO74: 0.5209 | AP74: 1.4391 | AQ74: 1.3432 | AR74: 0.4148 | AS74: 0.2032 | AT74: 0.4023 | AU74: 0.2672 | AV74: 0.5403 | AW74: 0.5171 | AX74: 0.168

Sheet 5. Raw batt charge
A1: Raw batt charge
A2: Verbatim copy of Charge_kW (TR3_analysis_data.xlsx). One row per half-hour, one column per battery (kW).
A4: period | B4: hour | C4: BES_TR3_one195_C | D4: BES_TR3_one235_A | E4: BES_TR3_one242_B | F4: BES_TR3_one252_C | G4: BES_TR3_one260_C | H4: BES_TR3_one299_B | I4: BES_TR3_one313_A | J4: BES_TR3_one42_B | K4: BES_TR3_one320_B | L4: BES_TR3_one346_C | M4: BES_TR3_one363_C | N4: BES_TR3_one366_B | O4: BES_TR3_one371_C | P4: BES_TR3_one375_C | Q4: BES_TR3_one410_B | R4: BES_TR3_one50_A | S4: BES_TR3_one423_B | T4: BES_TR3_one446_B | U4: BES_TR3_one469_A | V4: BES_TR3_one477_A | W4: BES_TR3_one480_A | X4: BES_TR3_one482_B | Y4: BES_TR3_one521_C | Z4: BES_TR3_one528_C | AA4: BES_TR3_one61_A | AB4: BES_TR3_one544_A | AC4: BES_TR3_one552_B | AD4: BES_TR3_one559_C | AE4: BES_TR3_one570_B | AF4: BES_TR3_one605_A | AG4: BES_TR3_one614_B | AH4: BES_TR3_one617_A | AI4: BES_TR3_one73_A | AJ4: BES_TR3_one76_A | AK4: BES_TR3_one137_A | AL4: BES_TR3_one176_A | AM4: BES_TR3_two130_C | AN4: BES_TR3_two249_A | AO4: BES_TR3_two267_C | AP4: BES_TR3_two292_B | AQ4: BES_TR3_two308_A | AR4: BES_TR3_two313_C | AS4: BES_TR3_two137_B | AT4: BES_TR3_two316_A | AU4: BES_TR3_two339_A | AV4: BES_TR3_two149_B | AW4: BES_TR3_two225_C | AX4: BES_TR3_two229_A | AY4: BES_TR3_two242_B
A5: 1 | B5: 0 | C5: 0 | D5: 0 | E5: 0 | F5: 0 | G5: 0 | H5: 0 | I5: 0 | J5: 0 | K5: 0 | L5: 0 | M5: 0 | N5: 0 | O5: 0 | P5: 0 | Q5: 0 | R5: 0 | S5: 0 | T5: 0 | U5: 0 | V5: 0 | W5: 0 | X5: 0 | Y5: 0 | Z5: 0 | AA5: 0 | AB5: 0 | AC5: 0 | AD5: 0 | AE5: 0 | AF5: 0 | AG5: 0 | AH5: 0 | AI5: 0 | AJ5: 0 | AK5: 0 | AL5: 0 | AM5: 0 | AN5: 0 | AO5: 0 | AP5: 0 | AQ5: 0 | AR5: 0 | AS5: 0 | AT5: 0 | AU5: 0 | AV5: 0 | AW5: 0 | AX5: 0 | AY5: 0
A6: 2 | B6: 0.5 | C6: 0 | D6: 0 | E6: 0 | F6: 0 | G6: 0 | H6: 0 | I6: 0 | J6: 0 | K6: 0 | L6: 0 | M6: 0 | N6: 0 | O6: 0 | P6: 0 | Q6: 0 | R6: 0 | S6: 0 | T6: 0 | U6: 0 | V6: 0 | W6: 0 | X6: 0 | Y6: 0 | Z6: 0 | AA6: 0 | AB6: 0 | AC6: 0 | AD6: 0 | AE6: 0 | AF6: 0 | AG6: 0 | AH6: 0 | AI6: 0 | AJ6: 0 | AK6: 0 | AL6: 0 | AM6: 0 | AN6: 0 | AO6: 0 | AP6: 0 | AQ6: 0 | AR6: 0 | AS6: 0 | AT6: 0 | AU6: 0 | AV6: 0 | AW6: 0 | AX6: 0 | AY6: 0
A7: 3 | B7: 1 | C7: 0 | D7: 0 | E7: 0 | F7: 0 | G7: 0 | H7: 0 | I7: 0 | J7: 0 | K7: 0 | L7: 0 | M7: 0 | N7: 0 | O7: 0 | P7: 0 | Q7: 0 | R7: 0 | S7: 0 | T7: 0 | U7: 0 | V7: 0 | W7: 0 | X7: 0 | Y7: 0 | Z7: 0 | AA7: 0 | AB7: 0 | AC7: 0 | AD7: 0 | AE7: 0 | AF7: 0 | AG7: 0 | AH7: 0 | AI7: 0 | AJ7: 0 | AK7: 0 | AL7: 0 | AM7: 0 | AN7: 0 | AO7: 0 | AP7: 0 | AQ7: 0 | AR7: 0 | AS7: 0 | AT7: 0 | AU7: 0 | AV7: 0 | AW7: 0 | AX7: 0 | AY7: 0
A8: 4 | B8: 1.5 | C8: 0 | D8: 0 | E8: 0 | F8: 0 | G8: 0 | H8: 0 | I8: 0 | J8: 0 | K8: 0 | L8: 0 | M8: 0 | N8: 0 | O8: 0 | P8: 0 | Q8: 0 | R8: 0 | S8: 0 | T8: 0 | U8: 0 | V8: 0 | W8: 0 | X8: 0 | Y8: 0 | Z8: 0 | AA8: 0 | AB8: 0 | AC8: 0 | AD8: 0 | AE8: 0 | AF8: 0 | AG8: 0 | AH8: 0 | AI8: 0 | AJ8: 0 | AK8: 0 | AL8: 0 | AM8: 0 | AN8: 0 | AO8: 0 | AP8: 0 | AQ8: 0 | AR8: 0 | AS8: 0 | AT8: 0 | AU8: 0 | AV8: 0 | AW8: 0 | AX8: 0 | AY8: 0
A9: 5 | B9: 2 | C9: 0 | D9: 0 | E9: 0 | F9: 0 | G9: 0 | H9: 0 | I9: 0 | J9: 0 | K9: 0 | L9: 0 | M9: 0 | N9: 0 | O9: 0 | P9: 0 | Q9: 0 | R9: 0 | S9: 0 | T9: 0 | U9: 0 | V9: 0 | W9: 0 | X9: 0 | Y9: 0 | Z9: 0 | AA9: 0 | AB9: 0 | AC9: 0 | AD9: 0 | AE9: 0 | AF9: 0 | AG9: 0 | AH9: 0 | AI9: 0 | AJ9: 0 | AK9: 0 | AL9: 0 | AM9: 0 | AN9: 0 | AO9: 0 | AP9: 0 | AQ9: 0 | AR9: 0 | AS9: 0 | AT9: 0 | AU9: 0 | AV9: 0 | AW9: 0 | AX9: 0 | AY9: 0
A10: 6 | B10: 2.5 | C10: 0 | D10: 0 | E10: 0 | F10: 0 | G10: 0 | H10: 0 | I10: 0 | J10: 0 | K10: 0 | L10: 0 | M10: 0 | N10: 0 | O10: 0 | P10: 0 | Q10: 0 | R10: 0 | S10: 0 | T10: 0 | U10: 0 | V10: 0 | W10: 0 | X10: 0 | Y10: 0 | Z10: 0 | AA10: 0 | AB10: 0 | AC10: 0 | AD10: 0 | AE10: 0 | AF10: 0 | AG10: 0 | AH10: 0 | AI10: 0 | AJ10: 0 | AK10: 0 | AL10: 0 | AM10: 0 | AN10: 0 | AO10: 0 | AP10: 0 | AQ10: 0 | AR10: 0 | AS10: 0 | AT10: 0 | AU10: 0 | AV10: 0 | AW10: 0 | AX10: 0 | AY10: 0
A11: 7 | B11: 3 | C11: 0 | D11: 0 | E11: 0 | F11: 0 | G11: 0 | H11: 0 | I11: 0 | J11: 0 | K11: 0 | L11: 0 | M11: 0 | N11: 0 | O11: 0 | P11: 0 | Q11: 0 | R11: 0 | S11: 0 | T11: 0 | U11: 0 | V11: 0 | W11: 0 | X11: 0 | Y11: 0 | Z11: 0 | AA11: 0 | AB11: 0 | AC11: 0 | AD11: 0 | AE11: 0 | AF11: 0 | AG11: 0 | AH11: 0 | AI11: 0 | AJ11: 0 | AK11: 0 | AL11: 0 | AM11: 0 | AN11: 0 | AO11: 0 | AP11: 0 | AQ11: 0 | AR11: 0 | AS11: 0 | AT11: 0 | AU11: 0 | AV11: 0 | AW11: 0 | AX11: 0 | AY11: 0
A12: 8 | B12: 3.5 | C12: 0 | D12: 0 | E12: 0 | F12: 0 | G12: 0 | H12: 0 | I12: 0 | J12: 0 | K12: 0 | L12: 0 | M12: 0 | N12: 0 | O12: 0 | P12: 0 | Q12: 0 | R12: 0 | S12: 0 | T12: 0 | U12: 0 | V12: 0 | W12: 0 | X12: 0 | Y12: 0 | Z12: 0 | AA12: 0 | AB12: 0 | AC12: 0 | AD12: 0 | AE12: 0 | AF12: 0 | AG12: 0 | AH12: 0 | AI12: 0 | AJ12: 0 | AK12: 0 | AL12: 0 | AM12: 0 | AN12: 0 | AO12: 0 | AP12: 0 | AQ12: 0 | AR12: 0 | AS12: 0 | AT12: 0 | AU12: 0 | AV12: 0 | AW12: 0 | AX12: 0 | AY12: 0
A13: 9 | B13: 4 | C13: 0 | D13: 0 | E13: 0 | F13: 0 | G13: 0.002 | H13: 0 | I13: 0 | J13: 0 | K13: 0 | L13: 0 | M13: 0 | N13: 0 | O13: 0.008 | P13: 0 | Q13: 0 | R13: 0 | S13: 0 | T13: 0 | U13: 0 | V13: 0 | W13: 0 | X13: 0 | Y13: 0 | Z13: 0.002 | AA13: 0 | AB13: 0 | AC13: 0 | AD13: 0 | AE13: 0 | AF13: 0 | AG13: 0 | AH13: 0.014 | AI13: 0 | AJ13: 0 | AK13: 0 | AL13: 0 | AM13: 0 | AN13: 0 | AO13: 0 | AP13: 0 | AQ13: 0 | AR13: 0 | AS13: 0.01 | AT13: 0 | AU13: 0 | AV13: 0 | AW13: 0 | AX13: 0 | AY13: 0
A14: 10 | B14: 4.5 | C14: 0.118 | D14: 0 | E14: 0 | F14: 0.126 | G14: 0.065 | H14: 0.059 | I14: 0.084 | J14: 0.163 | K14: 0.124 | L14: 0.182 | M14: 0.062 | N14: 0 | O14: 0.026 | P14: 0 | Q14: 0 | R14: 0 | S14: 0.072 | T14: 0.172 | U14: 0.049 | V14: 0.007 | W14: 0.183 | X14: 0.18 | Y14: 0.029 | Z14: 0.113 | AA14: 0 | AB14: 0.164 | AC14: 0.03 | AD14: 0.042 | AE14: 0.133 | AF14: 0.18 | AG14: 0.088 | AH14: 0.033 | AI14: 0.031 | AJ14: 0.048 | AK14: 0.19 | AL14: 0 | AM14: 0.144 | AN14: 0.074 | AO14: 0.073 | AP14: 0.18 | AQ14: 0.124 | AR14: 0.092 | AS14: 0.079 | AT14: 0.12 | AU14: 0 | AV14: 0.154 | AW14: 0 | AX14: 0 | AY14: 0
A15: 11 | B15: 5 | C15: 0.176 | D15: 0.393 | E15: 0.248 | F15: 0.18 | G15: 0.413 | H15: 0.317 | I15: 0.138 | J15: 0.343 | K15: 0.415 | L15: 0.368 | M15: 0.113 | N15: 0.166 | O15: 0.419 | P15: 0.277 | Q15: 0.104 | R15: 0 | S15: 0.336 | T15: 0.241 | U15: 0.227 | V15: 0 | W15: 0.406 | X15: 0.301 | Y15: 0.411 | Z15: 0.278 | AA15: 0.126 | AB15: 0.254 | AC15: 0.294 | AD15: 0.257 | AE15: 0.266 | AF15: 0.408 | AG15: 0.164 | AH15: 0.425 | AI15: 0.235 | AJ15: 0.198 | AK15: 0.377 | AL15: 0.189 | AM15: 0.278 | AN15: 0.258 | AO15: 0.404 | AP15: 0.408 | AQ15: 0.296 | AR15: 0.235 | AS15: 0.241 | AT15: 0.203 | AU15: 0.24 | AV15: 0.27 | AW15: 0.113 | AX15: 0.029 | AY15: 0.173
A16: 12 | B16: 5.5 | C16: 0.633 | D16: 0.486 | E16: 0.466 | F16: 0.508 | G16: 0.628 | H16: 0.689 | I16: 0.392 | J16: 0.572 | K16: 0.696 | L16: 0.664 | M16: 0.317 | N16: 0.313 | O16: 0.663 | P16: 0.548 | Q16: 0.151 | R16: 0.409 | S16: 0.467 | T16: 0.636 | U16: 0.523 | V16: 0.129 | W16: 0.597 | X16: 0.689 | Y16: 0.538 | Z16: 0.642 | AA16: 0.331 | AB16: 0.634 | AC16: 0.595 | AD16: 0.682 | AE16: 0.484 | AF16: 0.687 | AG16: 0.497 | AH16: 0.706 | AI16: 0.366 | AJ16: 0.27 | AK16: 0.665 | AL16: 0.222 | AM16: 0.693 | AN16: 0.692 | AO16: 0.685 | AP16: 0.689 | AQ16: 0.506 | AR16: 0.411 | AS16: 0.615 | AT16: 0.502 | AU16: 0.404 | AV16: 0.511 | AW16: 0.15 | AX16: 0.168 | AY16: 0.261
... A52: 48 | B52: 23.5 | C52: 0 | D52: 0 | E52: 0 | F52: 0 | G52: 0 | H52: 0 | I52: 0 | J52: 0 | K52: 0 | L52: 0 | M52: 0 | N52: 0 | O52: 0 | P52: 0 | Q52: 0 | R52: 0 | S52: 0 | T52: 0 | U52: 0 | V52: 0 | W52: 0 | X52: 0 | Y52: 0 | Z52: 0 | AA52: 0 | AB52: 0 | AC52: 0 | AD52: 0 | AE52: 0 | AF52: 0 | AG52: 0 | AH52: 0 | AI52: 0 | AJ52: 0 | AK52: 0 | AL52: 0 | AM52: 0 | AN52: 0 | AO52: 0 | AP52: 0 | AQ52: 0 | AR52: 0 | AS52: 0 | AT52: 0 | AU52: 0 | AV52: 0 | AW52: 0 | AX52: 0 | AY52: 0

Sheet 6. Raw batt discharge
A1: Raw batt discharge
A2: Verbatim copy of Discharge_kW (TR3_analysis_data.xlsx). One row per half-hour, one column per battery (kW).
A4: period | B4: hour | C4: BES_TR3_one195_C | D4: BES_TR3_one235_A | E4: BES_TR3_one242_B | F4: BES_TR3_one252_C | G4: BES_TR3_one260_C | H4: BES_TR3_one299_B | I4: BES_TR3_one313_A | J4: BES_TR3_one42_B | K4: BES_TR3_one320_B | L4: BES_TR3_one346_C | M4: BES_TR3_one363_C | N4: BES_TR3_one366_B | O4: BES_TR3_one371_C | P4: BES_TR3_one375_C | Q4: BES_TR3_one410_B | R4: BES_TR3_one50_A | S4: BES_TR3_one423_B | T4: BES_TR3_one446_B | U4: BES_TR3_one469_A | V4: BES_TR3_one477_A | W4: BES_TR3_one480_A | X4: BES_TR3_one482_B | Y4: BES_TR3_one521_C | Z4: BES_TR3_one528_C | AA4: BES_TR3_one61_A | AB4: BES_TR3_one544_A | AC4: BES_TR3_one552_B | AD4: BES_TR3_one559_C | AE4: BES_TR3_one570_B | AF4: BES_TR3_one605_A | AG4: BES_TR3_one614_B | AH4: BES_TR3_one617_A | AI4: BES_TR3_one73_A | AJ4: BES_TR3_one76_A | AK4: BES_TR3_one137_A | AL4: BES_TR3_one176_A | AM4: BES_TR3_two130_C | AN4: BES_TR3_two249_A | AO4: BES_TR3_two267_C | AP4: BES_TR3_two292_B | AQ4: BES_TR3_two308_A | AR4: BES_TR3_two313_C | AS4: BES_TR3_two137_B | AT4: BES_TR3_two316_A | AU4: BES_TR3_two339_A | AV4: BES_TR3_two149_B | AW4: BES_TR3_two225_C | AX4: BES_TR3_two229_A | AY4: BES_TR3_two242_B
A5: 1 | B5: 0 | C5: 0.19 | D5: 0.046 | E5: 0.046 | F5: 0.38 | G5: 0.048 | H5: 0.104 | I5: 0.34 | J5: 0.033 | K5: 0.046 | L5: 0.098 | M5: 0.054 | N5: 0.599 | O5: 0.072 | P5: 0.144 | Q5: 0.165 | R5: 0.16 | S5: 0.131 | T5: 0.149 | U5: 0.048 | V5: 0.149 | W5: 0.15 | X5: 0.053 | Y5: 0.148 | Z5: 0.11 | AA5: 0.081 | AB5: 0.335 | AC5: 0.054 | AD5: 0.06 | AE5: 0.041 | AF5: 0.053 | AG5: 0.059 | AH5: 0.111 | AI5: 0.499 | AJ5: 0.152 | AK5: 0.043 | AL5: 0.149 | AM5: 0.049 | AN5: 0.079 | AO5: 0.138 | AP5: 0.053 | AQ5: 0.639 | AR5: 0.053 | AS5: 0.552 | AT5: 0.683 | AU5: 0.734 | AV5: 0.102 | AW5: 0.16 | AX5: 0.133 | AY5: 0.769
A6: 2 | B6: 0.5 | C6: 0.261 | D6: 0.107 | E6: 0.31 | F6: 0.125 | G6: 0.21 | H6: 0.171 | I6: 0.053 | J6: 0.033 | K6: 0.199 | L6: 0.078 | M6: 0.172 | N6: 0.544 | O6: 0.042 | P6: 0.23 | Q6: 0.047 | R6: 0.055 | S6: 0.055 | T6: 0.17 | U6: 0.091 | V6: 0.139 | W6: 0.05 | X6: 0.053 | Y6: 0.106 | Z6: 0.052 | AA6: 0.28 | AB6: 1.299 | AC6: 0.054 | AD6: 0.243 | AE6: 0.112 | AF6: 0.053 | AG6: 0.148 | AH6: 0.141 | AI6: 0.621 | AJ6: 0.041 | AK6: 0.043 | AL6: 0.082 | AM6: 0.223 | AN6: 0.196 | AO6: 0.079 | AP6: 0.053 | AQ6: 0.05 | AR6: 0.053 | AS6: 0.534 | AT6: 0.149 | AU6: 0.438 | AV6: 0.134 | AW6: 0.146 | AX6: 0.173 | AY6: 0.109
A7: 3 | B7: 1 | C7: 0.079 | D7: 0.191 | E7: 0.057 | F7: 0.048 | G7: 0.048 | H7: 0.098 | I7: 0.162 | J7: 0.033 | K7: 0.046 | L7: 0.094 | M7: 0.079 | N7: 0.548 | O7: 0.042 | P7: 0.161 | Q7: 0.221 | R7: 0.055 | S7: 0.087 | T7: 0.22 | U7: 0.163 | V7: 0.083 | W7: 0.05 | X7: 0.161 | Y7: 0.05 | Z7: 0.168 | AA7: 0.049 | AB7: 0.424 | AC7: 0.229 | AD7: 0.152 | AE7: 0.041 | AF7: 0.053 | AG7: 0.12 | AH7: 0.036 | AI7: 0.268 | AJ7: 0.243 | AK7: 0.391 | AL7: 0.042 | AM7: 0.049 | AN7: 0.137 | AO7: 0.057 | AP7: 0.053 | AQ7: 0.05 | AR7: 0.053 | AS7: 0.079 | AT7: 0.143 | AU7: 0.831 | AV7: 0.151 | AW7: 0.099 | AX7: 0.104 | AY7: 0.217
A8: 4 | B8: 1.5 | C8: 0.259 | D8: 0.073 | E8: 0.118 | F8: 0.166 | G8: 0.048 | H8: 0.059 | I8: 0.243 | J8: 0.069 | K8: 0.158 | L8: 0.051 | M8: 0.082 | N8: 0.656 | O8: 0.206 | P8: 0.153 | Q8: 0.122 | R8: 0.112 | S8: 0.163 | T8: 0.177 | U8: 0.126 | V8: 0.034 | W8: 0.105 | X8: 0.053 | Y8: 0.05 | Z8: 0.111 | AA8: 0.203 | AB8: 0.108 | AC8: 0.054 | AD8: 0.19 | AE8: 0.112 | AF8: 0.053 | AG8: 0.079 | AH8: 0.066 | AI8: 0.176 | AJ8: 0.041 | AK8: 0.219 | AL8: 0.189 | AM8: 0.049 | AN8: 0.185 | AO8: 0.16 | AP8: 0.053 | AQ8: 0.05 | AR8: 0.053 | AS8: 0.085 | AT8: 0.054 | AU8: 0.387 | AV8: 0.05 | AW8: 0.246 | AX8: 0.09 | AY8: 0.109
A9: 5 | B9: 2 | C9: 0.17 | D9: 0.199 | E9: 0.161 | F9: 0.048 | G9: 0.072 | H9: 0.26 | I9: 0.087 | J9: 0.069 | K9: 0.088 | L9: 0.051 | M9: 0.089 | N9: 0.043 | O9: 0.042 | P9: 0.096 | Q9: 0.082 | R9: 0.177 | S9: 0.055 | T9: 0.048 | U9: 0.206 | V9: 0.191 | W9: 0.095 | X9: 0.145 | Y9: 0.204 | Z9: 0.096 | AA9: 0.158 | AB9: 0.129 | AC9: 0.205 | AD9: 0.185 | AE9: 0.041 | AF9: 0.053 | AG9: 0.188 | AH9: 0.17 | AI9: 0.187 | AJ9: 0.041 | AK9: 0.225 | AL9: 0.042 | AM9: 0.223 | AN9: 0.177 | AO9: 0.057 | AP9: 0.053 | AQ9: 0.05 | AR9: 0.053 | AS9: 0.047 | AT9: 0.054 | AU9: 0 | AV9: 0.234 | AW9: 0.149 | AX9: 0.209 | AY9: 0.033
A10: 6 | B10: 2.5 | C10: 0.154 | D10: 0.046 | E10: 0.063 | F10: 0.166 | G10: 0.143 | H10: 0.053 | I10: 0.087 | J10: 0.033 | K10: 0.046 | L10: 0.051 | M10: 0.054 | N10: 0 | O10: 0.087 | P10: 0.304 | Q10: 0.091 | R10: 0.055 | S10: 0.055 | T10: 0.22 | U10: 0.126 | V10: 0.146 | W10: 0.05 | X10: 0.068 | Y10: 0.05 | Z10: 0.14 | AA10: 0.049 | AB10: 0.096 | AC10: 0.078 | AD10: 0.21 | AE10: 0.112 | AF10: 0.053 | AG10: 0.059 | AH10: 0.036 | AI10: 0.272 | AJ10: 0.213 | AK10: 0.118 | AL10: 0.042 | AM10: 0.049 | AN10: 0.061 | AO10: 0.079 | AP10: 0.053 | AQ10: 0.05 | AR10: 0.053 | AS10: 0.164 | AT10: 0.143 | AU10: 0 | AV10: 0.05 | AW10: 0.246 | AX10: 0.144 | AY10: 0.109
A11: 7 | B11: 3 | C11: 0.204 | D11: 0.243 | E11: 0.236 | F11: 0.048 | G11: 0.048 | H11: 0.132 | I11: 0.195 | J11: 0.033 | K11: 0.199 | L11: 0.121 | M11: 0.054 | N11: 0 | O11: 0.161 | P11: 0.094 | Q11: 0.192 | R11: 0.233 | S11: 0.195 | T11: 0.177 | U11: 0.048 | V11: 0.034 | W11: 0.135 | X11: 0.053 | Y11: 0.127 | Z11: 0.095 | AA11: 0.136 | AB11: 0 | AC11: 0.054 | AD11: 0.06 | AE11: 0.041 | AF11: 0.053 | AG11: 0.059 | AH11: 0.2 | AI11: 0.179 | AJ11: 0.071 | AK11: 0.043 | AL11: 0.122 | AM11: 0.049 | AN11: 0.254 | AO11: 0.138 | AP11: 0.053 | AQ11: 0.05 | AR11: 0.053 | AS11: 0.111 | AT11: 0.054 | AU11: 0 | AV11: 0.05 | AW11: 0.05 | AX11: 0.049 | AY11: 0.058
A12: 8 | B12: 3.5 | C12: 0.178 | D12: 0.078 | E12: 0.128 | F12: 0.069 | G12: 0.045 | H12: 0.183 | I12: 0.154 | J12: 0.03 | K12: 0.043 | L12: 0.048 | M12: 0.116 | N12: 0 | O12: 0.039 | P12: 0.18 | Q12: 0.082 | R12: 0.053 | S12: 0.052 | T12: 0.131 | U12: 0.263 | V12: 0.187 | W12: 0.062 | X12: 0.149 | Y12: 0.123 | Z12: 0.116 | AA12: 0.199 | AB12: 0 | AC12: 0.226 | AD12: 0.331 | AE12: 0.038 | AF12: 0.05 | AG12: 0.206 | AH12: 0.033 | AI12: 0.188 | AJ12: 0.051 | AK12: 0.04 | AL12: 0.107 | AM12: 0.188 | AN12: 0.093 | AO12: 0.054 | AP12: 0.05 | AQ12: 0.047 | AR12: 0.051 | AS12: 0.174 | AT12: 0.096 | AU12: 0 | AV12: 0.125 | AW12: 0.088 | AX12: 0.179 | AY12: 0.19
A13: 9 | B13: 4 | C13: 0.093 | D13: 0.036 | E13: 0.43 | F13: 0.105 | G13: 0 | H13: 0.003 | I13: 0.14 | J13: 0.053 | K13: 0.087 | L13: 0.001 | M13: 0.029 | N13: 0 | O13: 0 | P13: 0.141 | Q13: 0.18 | R13: 0.625 | S13: 0.075 | T13: 0.2 | U13: 0.022 | V13: 0.084 | W13: 0.0003 | X13: 0.011 | Y13: 0.0003 | Z13: 0 | AA13: 0.042 | AB13: 0 | AC13: 0.01 | AD13: 0.01 | AE13: 0.004 | AF13: 0.003 | AG13: 0.022 | AH13: 0 | AI13: 0 | AJ13: 0.144 | AK13: 0.068 | AL13: 0.044 | AM13: 0.031 | AN13: 0.0003 | AO13: 0.007 | AP13: 0.003 | AQ13: 0.013 | AR13: 0.022 | AS13: 0 | AT13: 0.061 | AU13: 0 | AV13: 0.113 | AW13: 0.154 | AX13: 0.155 | AY13: 0.068
A14: 10 | B14: 4.5 | C14: 0 | D14: 0.006 | E14: 0.055 | F14: 0 | G14: 0 | H14: 0 | I14: 0 | J14: 0 | K14: 0 | L14: 0 | M14: 0 | N14: 0 | O14: 0 | P14: 0.015 | Q14: 0.007 | R14: 0.769 | S14: 0 | T14: 0 | U14: 0 | V14: 0 | W14: 0 | X14: 0 | Y14: 0 | Z14: 0 | AA14: 0.053 | AB14: 0 | AC14: 0 | AD14: 0 | AE14: 0 | AF14: 0 | AG14: 0 | AH14: 0 | AI14: 0 | AJ14: 0 | AK14: 0 | AL14: 0.046 | AM14: 0 | AN14: 0 | AO14: 0 | AP14: 0 | AQ14: 0 | AR14: 0 | AS14: 0 | AT14: 0 | AU14: 0 | AV14: 0 | AW14: 0.06 | AX14: 0.027 | AY14: 0.093
A15: 11 | B15: 5 | C15: 0 | D15: 0 | E15: 0 | F15: 0 | G15: 0 | H15: 0 | I15: 0 | J15: 0 | K15: 0 | L15: 0 | M15: 0 | N15: 0 | O15: 0 | P15: 0 | Q15: 0 | R15: 0.096 | S15: 0 | T15: 0 | U15: 0 | V15: 0.015 | W15: 0 | X15: 0 | Y15: 0 | Z15: 0 | AA15: 0 | AB15: 0 | AC15: 0 | AD15: 0 | AE15: 0 | AF15: 0 | AG15: 0 | AH15: 0 | AI15: 0 | AJ15: 0 | AK15: 0 | AL15: 0 | AM15: 0 | AN15: 0 | AO15: 0 | AP15: 0 | AQ15: 0 | AR15: 0 | AS15: 0 | AT15: 0 | AU15: 0 | AV15: 0 | AW15: 0 | AX15: 0 | AY15: 0
A16: 12 | B16: 5.5 | C16: 0 | D16: 0 | E16: 0 | F16: 0 | G16: 0 | H16: 0 | I16: 0 | J16: 0 | K16: 0 | L16: 0 | M16: 0 | N16: 0 | O16: 0 | P16: 0 | Q16: 0 | R16: 0 | S16: 0 | T16: 0 | U16: 0 | V16: 0 | W16: 0 | X16: 0 | Y16: 0 | Z16: 0 | AA16: 0 | AB16: 0 | AC16: 0 | AD16: 0 | AE16: 0 | AF16: 0 | AG16: 0 | AH16: 0 | AI16: 0 | AJ16: 0 | AK16: 0 | AL16: 0 | AM16: 0 | AN16: 0 | AO16: 0 | AP16: 0 | AQ16: 0 | AR16: 0 | AS16: 0 | AT16: 0 | AU16: 0 | AV16: 0 | AW16: 0 | AX16: 0 | AY16: 0
... A52: 48 | B52: 23.5 | C52: 0.938 | D52: 0.176 | E52: 0.176 | F52: 0.048 | G52: 0.167 | H52: 0.171 | I52: 0.134 | J52: 0.033 | K52: 0.224 | L52: 0.182 | M52: 0.089 | N52: 0.074 | O52: 0.109 | P52: 0.149 | Q52: 1.405 | R52: 0 | S52: 0.171 | T52: 0.991 | U52: 0.233 | V52: 0 | W52: 0.239 | X52: 0.153 | Y52: 0.572 | Z52: 0.179 | AA52: 0.193 | AB52: 0.283 | AC52: 0.094 | AD52: 0 | AE52: 0.041 | AF52: 0.161 | AG52: 0 | AH52: 0.305 | AI52: 0.236 | AJ52: 0.473 | AK52: 0.043 | AL52: 0.169 | AM52: 0.483 | AN52: 0.794 | AO52: 0.123 | AP52: 0.053 | AQ52: 0.05 | AR52: 0.063 | AS52: 0.549 | AT52: 0.646 | AU52: 0.162 | AV52: 0.453 | AW52: 0.05 | AX52: 0.056 | AY52: 0.168

Sheet 7. PV allocation (per period)
A1: TR3 PV allocation — per half-hour
A2: VIOLET = aggregated live from the raw sheets 3–6 (SUM / SUMIF). AMBER = priority split (MIN formulas): PV → prosumer load → battery → customer load → export.
A4: period | B4: hour (h) | C4: PV (kW) | D4: prosumer load (kW) | E4: customer load (kW) | F4: batt charge (kW) | G4: batt discharge (kW) | H4: batt net =chg−dis | I4: PV→ prosumer | J4: PV→ battery | K4: PV→ customer | L4: PV→ export | M4: customer ←grid
A5: 1 | B5: 0 | C5: =SUM('3. Raw PV per load'!C5:C74) -> 0 | D5: =SUMIF('4. Raw load per load'!$B$5:$B$74,"prosumer",'4. Raw load per load'!C5:C74) -> 9.242 | E5: =SUMIF('4. Raw load per load'!$B$5:$B$74,"customer",'4. Raw load per load'!C5:C74) -> 6.1008 | F5: =SUM('5. Raw batt charge'!C5:AY5) -> 0 | G5: =SUM('6. Raw batt discharge'!C5:AY5) -> 9.244 | H5: =F5-G5 -> -9.244 | I5: =MIN(C5,D5) -> 0 | J5: =MIN(C5-I5,MAX(0,H5)) -> 0 | K5: =MIN(C5-I5-J5,E5) -> 0 | L5: =C5-I5-J5-K5 -> 0 | M5: =E5-K5 -> 6.1008
A6: 2 | B6: 0.5 | C6: =SUM('3. Raw PV per load'!D5:D74) -> 0 | D6: =SUMIF('4. Raw load per load'!$B$5:$B$74,"prosumer",'4. Raw load per load'!D5:D74) -> 8.8049 | E6: =SUMIF('4. Raw load per load'!$B$5:$B$74,"customer",'4. Raw load per load'!D5:D74) -> 4.1829 | F6: =SUM('5. Raw batt charge'!C6:AY6) -> 0 | G6: =SUM('6. Raw batt discharge'!C6:AY6) -> 8.807 | H6: =F6-G6 -> -8.807 | I6: =MIN(C6,D6) -> 0 | J6: =MIN(C6-I6,MAX(0,H6)) -> 0 | K6: =MIN(C6-I6-J6,E6) -> 0 | L6: =C6-I6-J6-K6 -> 0 | M6: =E6-K6 -> 4.1829
A7: 3 | B7: 1 | C7: =SUM('3. Raw PV per load'!E5:E74) -> 0 | D7: =SUMIF('4. Raw load per load'!$B$5:$B$74,"prosumer",'4. Raw load per load'!E5:E74) -> 7.015 | E7: =SUMIF('4. Raw load per load'!$B$5:$B$74,"customer",'4. Raw load per load'!E5:E74) -> 3.1018 | F7: =SUM('5. Raw batt charge'!C7:AY7) -> 0 | G7: =SUM('6. Raw batt discharge'!C7:AY7) -> 7.015 | H7: =F7-G7 -> -7.015 | I7: =MIN(C7,D7) -> 0 | J7: =MIN(C7-I7,MAX(0,H7)) -> 0 | K7: =MIN(C7-I7-J7,E7) -> 0 | L7: =C7-I7-J7-K7 -> 0 | M7: =E7-K7 -> 3.1018
A8: 4 | B8: 1.5 | C8: =SUM('3. Raw PV per load'!F5:F74) -> 0 | D8: =SUMIF('4. Raw load per load'!$B$5:$B$74,"prosumer",'4. Raw load per load'!F5:F74) -> 6.733 | E8: =SUMIF('4. Raw load per load'!$B$5:$B$74,"customer",'4. Raw load per load'!F5:F74) -> 3.1167 | F8: =SUM('5. Raw batt charge'!C8:AY8) -> 0 | G8: =SUM('6. Raw batt discharge'!C8:AY8) -> 6.455 | H8: =F8-G8 -> -6.455 | I8: =MIN(C8,D8) -> 0 | J8: =MIN(C8-I8,MAX(0,H8)) -> 0 | K8: =MIN(C8-I8-J8,E8) -> 0 | L8: =C8-I8-J8-K8 -> 0 | M8: =E8-K8 -> 3.1167
A9: 5 | B9: 2 | C9: =SUM('3. Raw PV per load'!G5:G74) -> 0 | D9: =SUMIF('4. Raw load per load'!$B$5:$B$74,"prosumer",'4. Raw load per load'!G5:G74) -> 6.5173 | E9: =SUMIF('4. Raw load per load'!$B$5:$B$74,"customer",'4. Raw load per load'!G5:G74) -> 2.9307 | F9: =SUM('5. Raw batt charge'!C9:AY9) -> 0 | G9: =SUM('6. Raw batt discharge'!C9:AY9) -> 5.737 | H9: =F9-G9 -> -5.737 | I9: =MIN(C9,D9) -> 0 | J9: =MIN(C9-I9,MAX(0,H9)) -> 0 | K9: =MIN(C9-I9-J9,E9) -> 0 | L9: =C9-I9-J9-K9 -> 0 | M9: =E9-K9 -> 2.9307
A10: 6 | B10: 2.5 | C10: =SUM('3. Raw PV per load'!H5:H74) -> 0 | D10: =SUMIF('4. Raw load per load'!$B$5:$B$74,"prosumer",'4. Raw load per load'!H5:H74) -> 5.5909 | E10: =SUMIF('4. Raw load per load'!$B$5:$B$74,"customer",'4. Raw load per load'!H5:H74) -> 3.1114 | F10: =SUM('5. Raw batt charge'!C10:AY10) -> 0 | G10: =SUM('6. Raw batt discharge'!C10:AY10) -> 4.827 | H10: =F10-G10 -> -4.827 | I10: =MIN(C10,D10) -> 0 | J10: =MIN(C10-I10,MAX(0,H10)) -> 0 | K10: =MIN(C10-I10-J10,E10) -> 0 | L10: =C10-I10-J10-K10 -> 0 | M10: =E10-K10 -> 3.1114
A11: 7 | B11: 3 | C11: =SUM('3. Raw PV per load'!I5:I74) -> 0 | D11: =SUMIF('4. Raw load per load'!$B$5:$B$74,"prosumer",'4. Raw load per load'!I5:I74) -> 5.3406 | E11: =SUMIF('4. Raw load per load'!$B$5:$B$74,"customer",'4. Raw load per load'!I5:I74) -> 3.1387 | F11: =SUM('5. Raw batt charge'!C11:AY11) -> 0 | G11: =SUM('6. Raw batt discharge'!C11:AY11) -> 5.044 | H11: =F11-G11 -> -5.044 | I11: =MIN(C11,D11) -> 0 | J11: =MIN(C11-I11,MAX(0,H11)) -> 0 | K11: =MIN(C11-I11-J11,E11) -> 0 | L11: =C11-I11-J11-K11 -> 0 | M11: =E11-K11 -> 3.1387
A12: 8 | B12: 3.5 | C12: =SUM('3. Raw PV per load'!J5:J74) -> 0.1394 | D12: =SUMIF('4. Raw load per load'!$B$5:$B$74,"prosumer",'4. Raw load per load'!J5:J74) -> 5.928 | E12: =SUMIF('4. Raw load per load'!$B$5:$B$74,"customer",'4. Raw load per load'!J5:J74) -> 4.0854 | F12: =SUM('5. Raw batt charge'!C12:AY12) -> 0 | G12: =SUM('6. Raw batt discharge'!C12:AY12) -> 5.313 | H12: =F12-G12 -> -5.313 | I12: =MIN(C12,D12) -> 0.1394 | J12: =MIN(C12-I12,MAX(0,H12)) -> 0 | K12: =MIN(C12-I12-J12,E12) -> 0 | L12: =C12-I12-J12-K12 -> 0 | M12: =E12-K12 -> 4.0854
A13: 9 | B13: 4 | C13: =SUM('3. Raw PV per load'!K5:K74) -> 2.0261 | D13: =SUMIF('4. Raw load per load'!$B$5:$B$74,"prosumer",'4. Raw load per load'!K5:K74) -> 5.6999 | E13: =SUMIF('4. Raw load per load'!$B$5:$B$74,"customer",'4. Raw load per load'!K5:K74) -> 2.3001 | F13: =SUM('5. Raw batt charge'!C13:AY13) -> 0.036 | G13: =SUM('6. Raw batt discharge'!C13:AY13) -> 3.2899 | H13: =F13-G13 -> -3.2539 | I13: =MIN(C13,D13) -> 2.0261 | J13: =MIN(C13-I13,MAX(0,H13)) -> 0 | K13: =MIN(C13-I13-J13,E13) -> 0 | L13: =C13-I13-J13-K13 -> 0 | M13: =E13-K13 -> 2.3001
A14: 10 | B14: 4.5 | C14: =SUM('3. Raw PV per load'!L5:L74) -> 9.478 | D14: =SUMIF('4. Raw load per load'!$B$5:$B$74,"prosumer",'4. Raw load per load'!L5:L74) -> 6.9676 | E14: =SUMIF('4. Raw load per load'!$B$5:$B$74,"customer",'4. Raw load per load'!L5:L74) -> 2.5583 | F14: =SUM('5. Raw batt charge'!C14:AY14) -> 3.793 | G14: =SUM('6. Raw batt discharge'!C14:AY14) -> 1.131 | H14: =F14-G14 -> 2.662 | I14: =MIN(C14,D14) -> 6.9676 | J14: =MIN(C14-I14,MAX(0,H14)) -> 2.5104 | K14: =MIN(C14-I14-J14,E14) -> 0 | L14: =C14-I14-J14-K14 -> 0 | M14: =E14-K14 -> 2.5583
A15: 11 | B15: 5 | C15: =SUM('3. Raw PV per load'!M5:M74) -> 18.7989 | D15: =SUMIF('4. Raw load per load'!$B$5:$B$74,"prosumer",'4. Raw load per load'!M5:M74) -> 6.3844 | E15: =SUMIF('4. Raw load per load'!$B$5:$B$74,"customer",'4. Raw load per load'!M5:M74) -> 2.227 | F15: =SUM('5. Raw batt charge'!C15:AY15) -> 12.611 | G15: =SUM('6. Raw batt discharge'!C15:AY15) -> 0.111 | H15: =F15-G15 -> 12.5 | I15: =MIN(C15,D15) -> 6.3844 | J15: =MIN(C15-I15,MAX(0,H15)) -> 12.4145 | K15: =MIN(C15-I15-J15,E15) -> 0 | L15: =C15-I15-J15-K15 -> 0 | M15: =E15-K15 -> 2.227
A16: 12 | B16: 5.5 | C16: =SUM('3. Raw PV per load'!N5:N74) -> 30.2315 | D16: =SUMIF('4. Raw load per load'!$B$5:$B$74,"prosumer",'4. Raw load per load'!N5:N74) -> 5.4489 | E16: =SUMIF('4. Raw load per load'!$B$5:$B$74,"customer",'4. Raw load per load'!N5:N74) -> 3.1244 | F16: =SUM('5. Raw batt charge'!C16:AY16) -> 24.782 | G16: =SUM('6. Raw batt discharge'!C16:AY16) -> 0 | H16: =F16-G16 -> 24.782 | I16: =MIN(C16,D16) -> 5.4489 | J16: =MIN(C16-I16,MAX(0,H16)) -> 24.782 | K16: =MIN(C16-I16-J16,E16) -> 0.0006 | L16: =C16-I16-J16-K16 -> 0 | M16: =E16-K16 -> 3.1238
A17: 13 | B17: 6 | C17: =SUM('3. Raw PV per load'!O5:O74) -> 42.7019 | D17: =SUMIF('4. Raw load per load'!$B$5:$B$74,"prosumer",'4. Raw load per load'!O5:O74) -> 7.668 | E17: =SUMIF('4. Raw load per load'!$B$5:$B$74,"customer",'4. Raw load per load'!O5:O74) -> 3.0125 | F17: =SUM('5. Raw batt charge'!C17:AY17) -> 35.642 | G17: =SUM('6. Raw batt discharge'!C17:AY17) -> 0.606 | H17: =F17-G17 -> 35.036 | I17: =MIN(C17,D17) -> 7.668 | J17: =MIN(C17-I17,MAX(0,H17)) -> 35.0339 | K17: =MIN(C17-I17-J17,E17) -> 0 | L17: =C17-I17-J17-K17 -> 0 | M17: =E17-K17 -> 3.0125
A18: 14 | B18: 6.5 | C18: =SUM('3. Raw PV per load'!P5:P74) -> 55.3271 | D18: =SUMIF('4. Raw load per load'!$B$5:$B$74,"prosumer",'4. Raw load per load'!P5:P74) -> 6.2176 | E18: =SUMIF('4. Raw load per load'!$B$5:$B$74,"customer",'4. Raw load per load'!P5:P74) -> 2.4709 | F18: =SUM('5. Raw batt charge'!C18:AY18) -> 49.111 | G18: =SUM('6. Raw batt discharge'!C18:AY18) -> 0 | H18: =F18-G18 -> 49.111 | I18: =MIN(C18,D18) -> 6.2176 | J18: =MIN(C18-I18,MAX(0,H18)) -> 49.1095 | K18: =MIN(C18-I18-J18,E18) -> 0 | L18: =C18-I18-J18-K18 -> 0 | M18: =E18-K18 -> 2.4709
A19: 15 | B19: 7 | C19: =SUM('3. Raw PV per load'!Q5:Q74) -> 67.8888 | D19: =SUMIF('4. Raw load per load'!$B$5:$B$74,"prosumer",'4. Raw load per load'!Q5:Q74) -> 11.4151 | E19: =SUMIF('4. Raw load per load'!$B$5:$B$74,"customer",'4. Raw load per load'!Q5:Q74) -> 3.2914 | F19: =SUM('5. Raw batt charge'!C19:AY19) -> 57.269 | G19: =SUM('6. Raw batt discharge'!C19:AY19) -> 0.795 | H19: =F19-G19 -> 56.474 | I19: =MIN(C19,D19) -> 11.4151 | J19: =MIN(C19-I19,MAX(0,H19)) -> 56.4737 | K19: =MIN(C19-I19-J19,E19) -> 0 | L19: =C19-I19-J19-K19 -> 0 | M19: =E19-K19 -> 3.2914
A20: 16 | B20: 7.5 | C20: =SUM('3. Raw PV per load'!R5:R74) -> 80.4654 | D20: =SUMIF('4. Raw load per load'!$B$5:$B$74,"prosumer",'4. Raw load per load'!R5:R74) -> 8.7084 | E20: =SUMIF('4. Raw load per load'!$B$5:$B$74,"customer",'4. Raw load per load'!R5:R74) -> 5.7132 | F20: =SUM('5. Raw batt charge'!C20:AY20) -> 62.519 | G20: =SUM('6. Raw batt discharge'!C20:AY20) -> 0 | H20: =F20-G20 -> 62.519 | I20: =MIN(C20,D20) -> 8.7084 | J20: =MIN(C20-I20,MAX(0,H20)) -> 62.519 | K20: =MIN(C20-I20-J20,E20) -> 5.7132 | L20: =C20-I20-J20-K20 -> 3.5248 | M20: =E20-K20 -> 0
A21: 17 | B21: 8 | C21: =SUM('3. Raw PV per load'!S5:S74) -> 92.2707 | D21: =SUMIF('4. Raw load per load'!$B$5:$B$74,"prosumer",'4. Raw load per load'!S5:S74) -> 15.0558 | E21: =SUMIF('4. Raw load per load'!$B$5:$B$74,"customer",'4. Raw load per load'!S5:S74) -> 8.5455 | F21: =SUM('5. Raw batt charge'!C21:AY21) -> 33.586 | G21: =SUM('6. Raw batt discharge'!C21:AY21) -> 1.244 | H21: =F21-G21 -> 32.342 | I21: =MIN(C21,D21) -> 15.0558 | J21: =MIN(C21-I21,MAX(0,H21)) -> 32.342 | K21: =MIN(C21-I21-J21,E21) -> 8.5455 | L21: =C21-I21-J21-K21 -> 36.3274 | M21: =E21-K21 -> 0
A22: 18 | B22: 8.5 | C22: =SUM('3. Raw PV per load'!T5:T74) -> 103.3697 | D22: =SUMIF('4. Raw load per load'!$B$5:$B$74,"prosumer",'4. Raw load per load'!T5:T74) -> 13.3213 | E22: =SUMIF('4. Raw load per load'!$B$5:$B$74,"customer",'4. Raw load per load'!T5:T74) -> 4.6214 | F22: =SUM('5. Raw batt charge'!C22:AY22) -> 20.595 | G22: =SUM('6. Raw batt discharge'!C22:AY22) -> 0 | H22: =F22-G22 -> 20.595 | I22: =MIN(C22,D22) -> 13.3213 | J22: =MIN(C22-I22,MAX(0,H22)) -> 20.595 | K22: =MIN(C22-I22-J22,E22) -> 4.6214 | L22: =C22-I22-J22-K22 -> 64.832 | M22: =E22-K22 -> 0
A23: 19 | B23: 9 | C23: =SUM('3. Raw PV per load'!U5:U74) -> 112.82 | D23: =SUMIF('4. Raw load per load'!$B$5:$B$74,"prosumer",'4. Raw load per load'!U5:U74) -> 19.0656 | E23: =SUMIF('4. Raw load per load'!$B$5:$B$74,"customer",'4. Raw load per load'!U5:U74) -> 6.2219 | F23: =SUM('5. Raw batt charge'!C23:AY23) -> 13.549 | G23: =SUM('6. Raw batt discharge'!C23:AY23) -> 0.242 | H23: =F23-G23 -> 13.307 | I23: =MIN(C23,D23) -> 19.0656 | J23: =MIN(C23-I23,MAX(0,H23)) -> 13.307 | K23: =MIN(C23-I23-J23,E23) -> 6.2219 | L23: =C23-I23-J23-K23 -> 74.2255 | M23: =E23-K23 -> 0
A24: 20 | B24: 9.5 | C24: =SUM('3. Raw PV per load'!V5:V74) -> 120.8808 | D24: =SUMIF('4. Raw load per load'!$B$5:$B$74,"prosumer",'4. Raw load per load'!V5:V74) -> 17.1438 | E24: =SUMIF('4. Raw load per load'!$B$5:$B$74,"customer",'4. Raw load per load'!V5:V74) -> 6.0732 | F24: =SUM('5. Raw batt charge'!C24:AY24) -> 8.739 | G24: =SUM('6. Raw batt discharge'!C24:AY24) -> 0.01 | H24: =F24-G24 -> 8.729 | I24: =MIN(C24,D24) -> 17.1438 | J24: =MIN(C24-I24,MAX(0,H24)) -> 8.729 | K24: =MIN(C24-I24-J24,E24) -> 6.0732 | L24: =C24-I24-J24-K24 -> 88.9348 | M24: =E24-K24 -> 0
A25: 21 | B25: 10 | C25: =SUM('3. Raw PV per load'!W5:W74) -> 127.955 | D25: =SUMIF('4. Raw load per load'!$B$5:$B$74,"prosumer",'4. Raw load per load'!W5:W74) -> 16.8985 | E25: =SUMIF('4. Raw load per load'!$B$5:$B$74,"customer",'4. Raw load per load'!W5:W74) -> 7.2628 | F25: =SUM('5. Raw batt charge'!C25:AY25) -> 2.701 | G25: =SUM('6. Raw batt discharge'!C25:AY25) -> 0 | H25: =F25-G25 -> 2.701 | I25: =MIN(C25,D25) -> 16.8985 | J25: =MIN(C25-I25,MAX(0,H25)) -> 2.701 | K25: =MIN(C25-I25-J25,E25) -> 7.2628 | L25: =C25-I25-J25-K25 -> 101.0927 | M25: =E25-K25 -> 0
A26: 22 | B26: 10.5 | C26: =SUM('3. Raw PV per load'!X5:X74) -> 133.7951 | D26: =SUMIF('4. Raw load per load'!$B$5:$B$74,"prosumer",'4. Raw load per load'!X5:X74) -> 14.2955 | E26: =SUMIF('4. Raw load per load'!$B$5:$B$74,"customer",'4. Raw load per load'!X5:X74) -> 5.8192 | F26: =SUM('5. Raw batt charge'!C26:AY26) -> 1.904 | G26: =SUM('6. Raw batt discharge'!C26:AY26) -> 0.137 | H26: =F26-G26 -> 1.767 | I26: =MIN(C26,D26) -> 14.2955 | J26: =MIN(C26-I26,MAX(0,H26)) -> 1.767 | K26: =MIN(C26-I26-J26,E26) -> 5.8192 | L26: =C26-I26-J26-K26 -> 111.9134 | M26: =E26-K26 -> 0
A27: 23 | B27: 11 | C27: =SUM('3. Raw PV per load'!Y5:Y74) -> 137.9386 | D27: =SUMIF('4. Raw load per load'!$B$5:$B$74,"prosumer",'4. Raw load per load'!Y5:Y74) -> 22.2333 | E27: =SUMIF('4. Raw load per load'!$B$5:$B$74,"customer",'4. Raw load per load'!Y5:Y74) -> 5.5863 | F27: =SUM('5. Raw batt charge'!C27:AY27) -> 0 | G27: =SUM('6. Raw batt discharge'!C27:AY27) -> 0.591 | H27: =F27-G27 -> -0.591 | I27: =MIN(C27,D27) -> 22.2333 | J27: =MIN(C27-I27,MAX(0,H27)) -> 0 | K27: =MIN(C27-I27-J27,E27) -> 5.5863 | L27: =C27-I27-J27-K27 -> 110.119 | M27: =E27-K27 -> 0
A28: 24 | B28: 11.5 | C28: =SUM('3. Raw PV per load'!Z5:Z74) -> 139.7562 | D28: =SUMIF('4. Raw load per load'!$B$5:$B$74,"prosumer",'4. Raw load per load'!Z5:Z74) -> 21.9888 | E28: =SUMIF('4. Raw load per load'!$B$5:$B$74,"customer",'4. Raw load per load'!Z5:Z74) -> 3.817 | F28: =SUM('5. Raw batt charge'!C28:AY28) -> 0.329 | G28: =SUM('6. Raw batt discharge'!C28:AY28) -> 0 | H28: =F28-G28 -> 0.329 | I28: =MIN(C28,D28) -> 21.9888 | J28: =MIN(C28-I28,MAX(0,H28)) -> 0.329 | K28: =MIN(C28-I28-J28,E28) -> 3.817 | L28: =C28-I28-J28-K28 -> 113.6214 | M28: =E28-K28 -> 0
A29: 25 | B29: 12 | C29: =SUM('3. Raw PV per load'!AA5:AA74) -> 140.2819 | D29: =SUMIF('4. Raw load per load'!$B$5:$B$74,"prosumer",'4. Raw load per load'!AA5:AA74) -> 11.9531 | E29: =SUMIF('4. Raw load per load'!$B$5:$B$74,"customer",'4. Raw load per load'!AA5:AA74) -> 9.3623 | F29: =SUM('5. Raw batt charge'!C29:AY29) -> 0.481 | G29: =SUM('6. Raw batt discharge'!C29:AY29) -> 0 | H29: =F29-G29 -> 0.481 | I29: =MIN(C29,D29) -> 11.9531 | J29: =MIN(C29-I29,MAX(0,H29)) -> 0.481 | K29: =MIN(C29-I29-J29,E29) -> 9.3623 | L29: =C29-I29-J29-K29 -> 118.4855 | M29: =E29-K29 -> 0
A30: 26 | B30: 12.5 | C30: =SUM('3. Raw PV per load'!AB5:AB74) -> 139.2961 | D30: =SUMIF('4. Raw load per load'!$B$5:$B$74,"prosumer",'4. Raw load per load'!AB5:AB74) -> 12.7509 | E30: =SUMIF('4. Raw load per load'!$B$5:$B$74,"customer",'4. Raw load per load'!AB5:AB74) -> 9.5228 | F30: =SUM('5. Raw batt charge'!C30:AY30) -> 0 | G30: =SUM('6. Raw batt discharge'!C30:AY30) -> 0 | H30: =F30-G30 -> 0 | I30: =MIN(C30,D30) -> 12.7509 | J30: =MIN(C30-I30,MAX(0,H30)) -> 0 | K30: =MIN(C30-I30-J30,E30) -> 9.5228 | L30: =C30-I30-J30-K30 -> 117.0224 | M30: =E30-K30 -> 0
A31: 27 | B31: 13 | C31: =SUM('3. Raw PV per load'!AC5:AC74) -> 135.9902 | D31: =SUMIF('4. Raw load per load'!$B$5:$B$74,"prosumer",'4. Raw load per load'!AC5:AC74) -> 18.1356 | E31: =SUMIF('4. Raw load per load'!$B$5:$B$74,"customer",'4. Raw load per load'!AC5:AC74) -> 12.3293 | F31: =SUM('5. Raw batt charge'!C31:AY31) -> 0 | G31: =SUM('6. Raw batt discharge'!C31:AY31) -> 0.789 | H31: =F31-G31 -> -0.789 | I31: =MIN(C31,D31) -> 18.1356 | J31: =MIN(C31-I31,MAX(0,H31)) -> 0 | K31: =MIN(C31-I31-J31,E31) -> 12.3293 | L31: =C31-I31-J31-K31 -> 105.5253 | M31: =E31-K31 -> 0
A32: 28 | B32: 13.5 | C32: =SUM('3. Raw PV per load'!AD5:AD74) -> 130.9429 | D32: =SUMIF('4. Raw load per load'!$B$5:$B$74,"prosumer",'4. Raw load per load'!AD5:AD74) -> 17.4091 | E32: =SUMIF('4. Raw load per load'!$B$5:$B$74,"customer",'4. Raw load per load'!AD5:AD74) -> 5.9408 | F32: =SUM('5. Raw batt charge'!C32:AY32) -> 0.682 | G32: =SUM('6. Raw batt discharge'!C32:AY32) -> 0 | H32: =F32-G32 -> 0.682 | I32: =MIN(C32,D32) -> 17.4091 | J32: =MIN(C32-I32,MAX(0,H32)) -> 0.682 | K32: =MIN(C32-I32-J32,E32) -> 5.9408 | L32: =C32-I32-J32-K32 -> 106.911 | M32: =E32-K32 -> 0
A33: 29 | B33: 14 | C33: =SUM('3. Raw PV per load'!AE5:AE74) -> 124.9191 | D33: =SUMIF('4. Raw load per load'!$B$5:$B$74,"prosumer",'4. Raw load per load'!AE5:AE74) -> 14.0843 | E33: =SUMIF('4. Raw load per load'!$B$5:$B$74,"customer",'4. Raw load per load'!AE5:AE74) -> 7.822 | F33: =SUM('5. Raw batt charge'!C33:AY33) -> 0.195 | G33: =SUM('6. Raw batt discharge'!C33:AY33) -> 0.3 | H33: =F33-G33 -> -0.105 | I33: =MIN(C33,D33) -> 14.0843 | J33: =MIN(C33-I33,MAX(0,H33)) -> 0 | K33: =MIN(C33-I33-J33,E33) -> 7.822 | L33: =C33-I33-J33-K33 -> 103.0128 | M33: =E33-K33 -> 0
A34: 30 | B34: 14.5 | C34: =SUM('3. Raw PV per load'!AF5:AF74) -> 117.2862 | D34: =SUMIF('4. Raw load per load'!$B$5:$B$74,"prosumer",'4. Raw load per load'!AF5:AF74) -> 15.6731 | E34: =SUMIF('4. Raw load per load'!$B$5:$B$74,"customer",'4. Raw load per load'!AF5:AF74) -> 9.5163 | F34: =SUM('5. Raw batt charge'!C34:AY34) -> 0.333 | G34: =SUM('6. Raw batt discharge'!C34:AY34) -> 0.216 | H34: =F34-G34 -> 0.117 | I34: =MIN(C34,D34) -> 15.6731 | J34: =MIN(C34-I34,MAX(0,H34)) -> 0.117 | K34: =MIN(C34-I34-J34,E34) -> 9.5163 | L34: =C34-I34-J34-K34 -> 91.9798 | M34: =E34-K34 -> 0
A35: 31 | B35: 15 | C35: =SUM('3. Raw PV per load'!AG5:AG74) -> 109.1737 | D35: =SUMIF('4. Raw load per load'!$B$5:$B$74,"prosumer",'4. Raw load per load'!AG5:AG74) -> 20.6182 | E35: =SUMIF('4. Raw load per load'!$B$5:$B$74,"customer",'4. Raw load per load'!AG5:AG74) -> 6.9962 | F35: =SUM('5. Raw batt charge'!C35:AY35) -> 0 | G35: =SUM('6. Raw batt discharge'!C35:AY35) -> 3.707 | H35: =F35-G35 -> -3.707 | I35: =MIN(C35,D35) -> 20.6182 | J35: =MIN(C35-I35,MAX(0,H35)) -> 0 | K35: =MIN(C35-I35-J35,E35) -> 6.9962 | L35: =C35-I35-J35-K35 -> 81.5593 | M35: =E35-K35 -> 0
A36: 32 | B36: 15.5 | C36: =SUM('3. Raw PV per load'!AH5:AH74) -> 99.413 | D36: =SUMIF('4. Raw load per load'!$B$5:$B$74,"prosumer",'4. Raw load per load'!AH5:AH74) -> 16.1785 | E36: =SUMIF('4. Raw load per load'!$B$5:$B$74,"customer",'4. Raw load per load'!AH5:AH74) -> 4.5421 | F36: =SUM('5. Raw batt charge'!C36:AY36) -> 0.416 | G36: =SUM('6. Raw batt discharge'!C36:AY36) -> 1.861 | H36: =F36-G36 -> -1.445 | I36: =MIN(C36,D36) -> 16.1785 | J36: =MIN(C36-I36,MAX(0,H36)) -> 0 | K36: =MIN(C36-I36-J36,E36) -> 4.5421 | L36: =C36-I36-J36-K36 -> 78.6924 | M36: =E36-K36 -> 0
A37: 33 | B37: 16 | C37: =SUM('3. Raw PV per load'!AI5:AI74) -> 88.4198 | D37: =SUMIF('4. Raw load per load'!$B$5:$B$74,"prosumer",'4. Raw load per load'!AI5:AI74) -> 15.9448 | E37: =SUMIF('4. Raw load per load'!$B$5:$B$74,"customer",'4. Raw load per load'!AI5:AI74) -> 6.4482 | F37: =SUM('5. Raw batt charge'!C37:AY37) -> 2.391 | G37: =SUM('6. Raw batt discharge'!C37:AY37) -> 0.288 | H37: =F37-G37 -> 2.103 | I37: =MIN(C37,D37) -> 15.9448 | J37: =MIN(C37-I37,MAX(0,H37)) -> 2.103 | K37: =MIN(C37-I37-J37,E37) -> 6.4482 | L37: =C37-I37-J37-K37 -> 63.9238 | M37: =E37-K37 -> 0
A38: 34 | B38: 16.5 | C38: =SUM('3. Raw PV per load'!AJ5:AJ74) -> 75.1467 | D38: =SUMIF('4. Raw load per load'!$B$5:$B$74,"prosumer",'4. Raw load per load'!AJ5:AJ74) -> 18.5203 | E38: =SUMIF('4. Raw load per load'!$B$5:$B$74,"customer",'4. Raw load per load'!AJ5:AJ74) -> 8.3593 | F38: =SUM('5. Raw batt charge'!C38:AY38) -> 0.854 | G38: =SUM('6. Raw batt discharge'!C38:AY38) -> 2.968 | H38: =F38-G38 -> -2.114 | I38: =MIN(C38,D38) -> 18.5203 | J38: =MIN(C38-I38,MAX(0,H38)) -> 0 | K38: =MIN(C38-I38-J38,E38) -> 8.3593 | L38: =C38-I38-J38-K38 -> 48.2671 | M38: =E38-K38 -> 0
