Workbook

Sheet 1. Overview
B2: TR2 — Where does the PV energy go?
B3: Prosumers vs. pure customers — every kWh traced from the raw model inputs
B5: Purpose
B6: This workbook accounts for every kWh of PV generated on transformer TR2 over one representative day, and it is fully auditable: nothing is hand-typed except the raw model outputs. Follow the data chain below — each step is a live formula, so changing any raw number updates everything.
B10: The data chain (how each number is built)
B11: Sheet 3 · Raw PV per load | C11: The PV profile of every connection, 48 half-hours. Copied verbatim from TR2_load_PV_48periods.xlsx (sheet PV_generation_kW). Customers = 0.
B12: Sheet 4 · Raw load per load | C12: The load profile of every connection, 48 half-hours, tagged prosumer / customer. Copied from TR2_load_PV_48periods.xlsx (sheet Load_P_kW).
B13: Sheet 5 · Raw batt charge | C13: Charging power of every battery, 48 half-hours. Copied from the rolling dispatch TR2_analysis_data.xlsx (sheet Charge_kW).
B14: Sheet 6 · Raw batt discharge | C14: Discharging power of every battery. Copied from the same run (Discharge_kW).
B15: Sheet 7 · PV allocation | C15: Per half-hour: the five blue inputs are AGGREGATED from sheets 3–6 by SUM / SUMIF; the amber columns then split the PV by the priority rule.
B16: Sheets 1 & 8 · Results | C16: Daily totals (Σ×0.5 h) and shares. Every headline cell links to sheet 7.
B18: The aggregation formulas (sheet 7, per half-hour)
B19: PV (all) | C19: =SUM over every row of sheet 3 for that half-hour → total PV that instant
B20: prosumer load | C20: =SUMIF(type = "prosumer") over sheet 4 → load of the 95 PV owners
B21: customer load | C21: =SUMIF(type = "customer") over sheet 4 → load of the 82 pure customers
B22: battery charge | C22: =SUM of all 95 battery columns of sheet 5 for that half-hour
B23: battery discharge | C23: =SUM of all 95 battery columns of sheet 6 for that half-hour
B25: Headline results (all linked live to sheet 7)
B26: Quantity | C26: Value | D26: Unit
B27: Prosumers (PV + battery) | C27: 95 | D27: connections
B28: Pure customers (load only) | C28: 82 | D28: connections
B29: PV generated | C29: ='7. PV allocation (per period)'!C53 | D29: kWh/day
B30: PV → prosumers' own load (direct) | C30: ='7. PV allocation (per period)'!I53 | D30: kWh/day
B31: PV → battery storage | C31: ='7. PV allocation (per period)'!J53 | D31: kWh/day
B32: PV → customers | C32: ='7. PV allocation (per period)'!K53 | D32: kWh/day
B33: PV → export to grid | C33: ='7. PV allocation (per period)'!L53 | D33: kWh/day
B34: PV share reaching customers | C34: ='7. PV allocation (per period)'!K53/'7. PV allocation (per period)'!C53 | D34: % of PV
B35: Customer load covered by PV | C35: ='7. PV allocation (per period)'!K53/'7. PV allocation (per period)'!E53 | D35: % of customer load
B36: Customer load covered by grid | C36: ='7. PV allocation (per period)'!M53/'7. PV allocation (per period)'!E53 | D36: % of customer load
B39: Colour key & provenance
B40: • LIGHT-BLUE cell = data belonging to a prosumer (its rooftop PV, load, or battery). WHITE = a pure customer (load only). On sheet 7: VIOLET = value aggregated live from the raw sheets (SUM/SUMIF); AMBER = allocation formula; GREEN = daily total (Σ × 0.5 h).
B41: • Per-load PV & load profiles: results/tables/TR2_load_PV_48periods.xlsx (built from OpData.xls).
B42: • Per-battery charge/discharge: TR2_analysis/01_DAILY_ROLLING_DISPATCH/TR2_analysis_data.xlsx (exact-QCP rolling dispatch, RunFOR_Rolling, CPLEX).
B43: • Load classification (PV size > 0 = prosumer): sheet 'Customers' of the load/PV workbook.
B44: • Method note: priority energy allocation per half-hour; downstream network + battery round-trip losses (~3–4% of PV) are not separated out in the per-period disposition.

Sheet 2. Load classification
A1: TR2 load classification — 177 connections
A2: 95 prosumers (PV + battery) · 82 pure customers (load only)
A4: ID | B4: Load name | C4: Bus | D4: Phase | E4: PV size (kW) | F4: Type
A5: 133 | B5: Load_TR2_F3_1 | C5: TR2_three64 | D5: 1 | E5: 0 | F5: customer
A6: 134 | B6: Load_TR2_F3_10 | C6: TR2_three193 | D6: 1 | E6: 0 | F6: customer
A7: 135 | B7: Load_TR2_F3_11 | C7: TR2_three204 | D7: 2 | E7: 0 | F7: customer
A8: 136 | B8: Load_TR2_F3_12 | C8: TR2_three210 | D8: 2 | E8: 0 | F8: customer
A9: 137 | B9: Load_TR2_F3_13 | C9: TR2_three232 | D9: 3 | E9: 0 | F9: customer
A10: 138 | B10: Load_TR2_F3_14 | C10: TR2_three233 | D10: 1 | E10: 0 | F10: customer
A11: 139 | B11: Load_TR2_F3_15 | C11: TR2_three248 | D11: 3 | E11: 0 | F11: customer
A12: 140 | B12: Load_TR2_F3_16 | C12: TR2_three252 | D12: 2 | E12: 0 | F12: customer
A13: 141 | B13: Load_TR2_F3_17 | C13: TR2_three253 | D13: 3 | E13: 0 | F13: customer
A14: 142 | B14: Load_TR2_F3_18 | C14: TR2_three260 | D14: 3 | E14: 0 | F14: customer
A15: 143 | B15: Load_TR2_F3_19 | C15: TR2_three284 | D15: 2 | E15: 0 | F15: customer
A16: 144 | B16: Load_TR2_F3_2 | C16: TR2_three66 | D16: 3 | E16: 0 | F16: customer
... A181: 306 | B181: Load_TR2_F6_81 | C181: TR2_six1020 | D181: 1 | E181: 2 | F181: prosumer

Sheet 3. Raw PV per load
A1: Raw PV per load
A2: Verbatim copy of PV_generation_kW (TR2_load_PV_48periods.xlsx). One row per connection, 48 half-hours (kW).
A4: Load name | B4: Type | C4: p1 | D4: p2 | E4: p3 | F4: p4 | G4: p5 | H4: p6 | I4: p7 | J4: p8 | K4: p9 | L4: p10 | M4: p11 | N4: p12 | O4: p13 | P4: p14 | Q4: p15 | R4: p16 | S4: p17 | T4: p18 | U4: p19 | V4: p20 | W4: p21 | X4: p22 | Y4: p23 | Z4: p24 | AA4: p25 | AB4: p26 | AC4: p27 | AD4: p28 | AE4: p29 | AF4: p30 | AG4: p31 | AH4: p32 | AI4: p33 | AJ4: p34 | AK4: p35 | AL4: p36 | AM4: p37 | AN4: p38 | AO4: p39 | AP4: p40 | AQ4: p41 | AR4: p42 | AS4: p43 | AT4: p44 | AU4: p45 | AV4: p46 | AW4: p47 | AX4: p48
A5: Load_TR2_F3_1 | B5: customer | C5: 0 | D5: 0 | E5: 0 | F5: 0 | G5: 0 | H5: 0 | I5: 0 | J5: 0 | K5: 0 | L5: 0 | M5: 0 | N5: 0 | O5: 0 | P5: 0 | Q5: 0 | R5: 0 | S5: 0 | T5: 0 | U5: 0 | V5: 0 | W5: 0 | X5: 0 | Y5: 0 | Z5: 0 | AA5: 0 | AB5: 0 | AC5: 0 | AD5: 0 | AE5: 0 | AF5: 0 | AG5: 0 | AH5: 0 | AI5: 0 | AJ5: 0 | AK5: 0 | AL5: 0 | AM5: 0 | AN5: 0 | AO5: 0 | AP5: 0 | AQ5: 0 | AR5: 0 | AS5: 0 | AT5: 0 | AU5: 0 | AV5: 0 | AW5: 0 | AX5: 0
A6: Load_TR2_F3_10 | B6: customer | C6: 0 | D6: 0 | E6: 0 | F6: 0 | G6: 0 | H6: 0 | I6: 0 | J6: 0 | K6: 0 | L6: 0 | M6: 0 | N6: 0 | O6: 0 | P6: 0 | Q6: 0 | R6: 0 | S6: 0 | T6: 0 | U6: 0 | V6: 0 | W6: 0 | X6: 0 | Y6: 0 | Z6: 0 | AA6: 0 | AB6: 0 | AC6: 0 | AD6: 0 | AE6: 0 | AF6: 0 | AG6: 0 | AH6: 0 | AI6: 0 | AJ6: 0 | AK6: 0 | AL6: 0 | AM6: 0 | AN6: 0 | AO6: 0 | AP6: 0 | AQ6: 0 | AR6: 0 | AS6: 0 | AT6: 0 | AU6: 0 | AV6: 0 | AW6: 0 | AX6: 0
A7: Load_TR2_F3_11 | B7: customer | C7: 0 | D7: 0 | E7: 0 | F7: 0 | G7: 0 | H7: 0 | I7: 0 | J7: 0 | K7: 0 | L7: 0 | M7: 0 | N7: 0 | O7: 0 | P7: 0 | Q7: 0 | R7: 0 | S7: 0 | T7: 0 | U7: 0 | V7: 0 | W7: 0 | X7: 0 | Y7: 0 | Z7: 0 | AA7: 0 | AB7: 0 | AC7: 0 | AD7: 0 | AE7: 0 | AF7: 0 | AG7: 0 | AH7: 0 | AI7: 0 | AJ7: 0 | AK7: 0 | AL7: 0 | AM7: 0 | AN7: 0 | AO7: 0 | AP7: 0 | AQ7: 0 | AR7: 0 | AS7: 0 | AT7: 0 | AU7: 0 | AV7: 0 | AW7: 0 | AX7: 0
A8: Load_TR2_F3_12 | B8: customer | C8: 0 | D8: 0 | E8: 0 | F8: 0 | G8: 0 | H8: 0 | I8: 0 | J8: 0 | K8: 0 | L8: 0 | M8: 0 | N8: 0 | O8: 0 | P8: 0 | Q8: 0 | R8: 0 | S8: 0 | T8: 0 | U8: 0 | V8: 0 | W8: 0 | X8: 0 | Y8: 0 | Z8: 0 | AA8: 0 | AB8: 0 | AC8: 0 | AD8: 0 | AE8: 0 | AF8: 0 | AG8: 0 | AH8: 0 | AI8: 0 | AJ8: 0 | AK8: 0 | AL8: 0 | AM8: 0 | AN8: 0 | AO8: 0 | AP8: 0 | AQ8: 0 | AR8: 0 | AS8: 0 | AT8: 0 | AU8: 0 | AV8: 0 | AW8: 0 | AX8: 0
A9: Load_TR2_F3_13 | B9: customer | C9: 0 | D9: 0 | E9: 0 | F9: 0 | G9: 0 | H9: 0 | I9: 0 | J9: 0 | K9: 0 | L9: 0 | M9: 0 | N9: 0 | O9: 0 | P9: 0 | Q9: 0 | R9: 0 | S9: 0 | T9: 0 | U9: 0 | V9: 0 | W9: 0 | X9: 0 | Y9: 0 | Z9: 0 | AA9: 0 | AB9: 0 | AC9: 0 | AD9: 0 | AE9: 0 | AF9: 0 | AG9: 0 | AH9: 0 | AI9: 0 | AJ9: 0 | AK9: 0 | AL9: 0 | AM9: 0 | AN9: 0 | AO9: 0 | AP9: 0 | AQ9: 0 | AR9: 0 | AS9: 0 | AT9: 0 | AU9: 0 | AV9: 0 | AW9: 0 | AX9: 0
A10: Load_TR2_F3_14 | B10: customer | C10: 0 | D10: 0 | E10: 0 | F10: 0 | G10: 0 | H10: 0 | I10: 0 | J10: 0 | K10: 0 | L10: 0 | M10: 0 | N10: 0 | O10: 0 | P10: 0 | Q10: 0 | R10: 0 | S10: 0 | T10: 0 | U10: 0 | V10: 0 | W10: 0 | X10: 0 | Y10: 0 | Z10: 0 | AA10: 0 | AB10: 0 | AC10: 0 | AD10: 0 | AE10: 0 | AF10: 0 | AG10: 0 | AH10: 0 | AI10: 0 | AJ10: 0 | AK10: 0 | AL10: 0 | AM10: 0 | AN10: 0 | AO10: 0 | AP10: 0 | AQ10: 0 | AR10: 0 | AS10: 0 | AT10: 0 | AU10: 0 | AV10: 0 | AW10: 0 | AX10: 0
A11: Load_TR2_F3_15 | B11: customer | C11: 0 | D11: 0 | E11: 0 | F11: 0 | G11: 0 | H11: 0 | I11: 0 | J11: 0 | K11: 0 | L11: 0 | M11: 0 | N11: 0 | O11: 0 | P11: 0 | Q11: 0 | R11: 0 | S11: 0 | T11: 0 | U11: 0 | V11: 0 | W11: 0 | X11: 0 | Y11: 0 | Z11: 0 | AA11: 0 | AB11: 0 | AC11: 0 | AD11: 0 | AE11: 0 | AF11: 0 | AG11: 0 | AH11: 0 | AI11: 0 | AJ11: 0 | AK11: 0 | AL11: 0 | AM11: 0 | AN11: 0 | AO11: 0 | AP11: 0 | AQ11: 0 | AR11: 0 | AS11: 0 | AT11: 0 | AU11: 0 | AV11: 0 | AW11: 0 | AX11: 0
A12: Load_TR2_F3_16 | B12: customer | C12: 0 | D12: 0 | E12: 0 | F12: 0 | G12: 0 | H12: 0 | I12: 0 | J12: 0 | K12: 0 | L12: 0 | M12: 0 | N12: 0 | O12: 0 | P12: 0 | Q12: 0 | R12: 0 | S12: 0 | T12: 0 | U12: 0 | V12: 0 | W12: 0 | X12: 0 | Y12: 0 | Z12: 0 | AA12: 0 | AB12: 0 | AC12: 0 | AD12: 0 | AE12: 0 | AF12: 0 | AG12: 0 | AH12: 0 | AI12: 0 | AJ12: 0 | AK12: 0 | AL12: 0 | AM12: 0 | AN12: 0 | AO12: 0 | AP12: 0 | AQ12: 0 | AR12: 0 | AS12: 0 | AT12: 0 | AU12: 0 | AV12: 0 | AW12: 0 | AX12: 0
A13: Load_TR2_F3_17 | B13: customer | C13: 0 | D13: 0 | E13: 0 | F13: 0 | G13: 0 | H13: 0 | I13: 0 | J13: 0 | K13: 0 | L13: 0 | M13: 0 | N13: 0 | O13: 0 | P13: 0 | Q13: 0 | R13: 0 | S13: 0 | T13: 0 | U13: 0 | V13: 0 | W13: 0 | X13: 0 | Y13: 0 | Z13: 0 | AA13: 0 | AB13: 0 | AC13: 0 | AD13: 0 | AE13: 0 | AF13: 0 | AG13: 0 | AH13: 0 | AI13: 0 | AJ13: 0 | AK13: 0 | AL13: 0 | AM13: 0 | AN13: 0 | AO13: 0 | AP13: 0 | AQ13: 0 | AR13: 0 | AS13: 0 | AT13: 0 | AU13: 0 | AV13: 0 | AW13: 0 | AX13: 0
A14: Load_TR2_F3_18 | B14: customer | C14: 0 | D14: 0 | E14: 0 | F14: 0 | G14: 0 | H14: 0 | I14: 0 | J14: 0 | K14: 0 | L14: 0 | M14: 0 | N14: 0 | O14: 0 | P14: 0 | Q14: 0 | R14: 0 | S14: 0 | T14: 0 | U14: 0 | V14: 0 | W14: 0 | X14: 0 | Y14: 0 | Z14: 0 | AA14: 0 | AB14: 0 | AC14: 0 | AD14: 0 | AE14: 0 | AF14: 0 | AG14: 0 | AH14: 0 | AI14: 0 | AJ14: 0 | AK14: 0 | AL14: 0 | AM14: 0 | AN14: 0 | AO14: 0 | AP14: 0 | AQ14: 0 | AR14: 0 | AS14: 0 | AT14: 0 | AU14: 0 | AV14: 0 | AW14: 0 | AX14: 0
A15: Load_TR2_F3_19 | B15: customer | C15: 0 | D15: 0 | E15: 0 | F15: 0 | G15: 0 | H15: 0 | I15: 0 | J15: 0 | K15: 0 | L15: 0 | M15: 0 | N15: 0 | O15: 0 | P15: 0 | Q15: 0 | R15: 0 | S15: 0 | T15: 0 | U15: 0 | V15: 0 | W15: 0 | X15: 0 | Y15: 0 | Z15: 0 | AA15: 0 | AB15: 0 | AC15: 0 | AD15: 0 | AE15: 0 | AF15: 0 | AG15: 0 | AH15: 0 | AI15: 0 | AJ15: 0 | AK15: 0 | AL15: 0 | AM15: 0 | AN15: 0 | AO15: 0 | AP15: 0 | AQ15: 0 | AR15: 0 | AS15: 0 | AT15: 0 | AU15: 0 | AV15: 0 | AW15: 0 | AX15: 0
A16: Load_TR2_F3_2 | B16: customer | C16: 0 | D16: 0 | E16: 0 | F16: 0 | G16: 0 | H16: 0 | I16: 0 | J16: 0 | K16: 0 | L16: 0 | M16: 0 | N16: 0 | O16: 0 | P16: 0 | Q16: 0 | R16: 0 | S16: 0 | T16: 0 | U16: 0 | V16: 0 | W16: 0 | X16: 0 | Y16: 0 | Z16: 0 | AA16: 0 | AB16: 0 | AC16: 0 | AD16: 0 | AE16: 0 | AF16: 0 | AG16: 0 | AH16: 0 | AI16: 0 | AJ16: 0 | AK16: 0 | AL16: 0 | AM16: 0 | AN16: 0 | AO16: 0 | AP16: 0 | AQ16: 0 | AR16: 0 | AS16: 0 | AT16: 0 | AU16: 0 | AV16: 0 | AW16: 0 | AX16: 0
... A181: Load_TR2_F6_9 | B181: customer | C181: 0 | D181: 0 | E181: 0 | F181: 0 | G181: 0 | H181: 0 | I181: 0 | J181: 0 | K181: 0 | L181: 0 | M181: 0 | N181: 0 | O181: 0 | P181: 0 | Q181: 0 | R181: 0 | S181: 0 | T181: 0 | U181: 0 | V181: 0 | W181: 0 | X181: 0 | Y181: 0 | Z181: 0 | AA181: 0 | AB181: 0 | AC181: 0 | AD181: 0 | AE181: 0 | AF181: 0 | AG181: 0 | AH181: 0 | AI181: 0 | AJ181: 0 | AK181: 0 | AL181: 0 | AM181: 0 | AN181: 0 | AO181: 0 | AP181: 0 | AQ181: 0 | AR181: 0 | AS181: 0 | AT181: 0 | AU181: 0 | AV181: 0 | AW181: 0 | AX181: 0

Sheet 4. Raw load per load
A1: Raw load per load
A2: Verbatim copy of Load_P_kW (TR2_load_PV_48periods.xlsx), tagged by type. One row per connection, 48 half-hours (kW).
A4: Load name | B4: Type | C4: p1 | D4: p2 | E4: p3 | F4: p4 | G4: p5 | H4: p6 | I4: p7 | J4: p8 | K4: p9 | L4: p10 | M4: p11 | N4: p12 | O4: p13 | P4: p14 | Q4: p15 | R4: p16 | S4: p17 | T4: p18 | U4: p19 | V4: p20 | W4: p21 | X4: p22 | Y4: p23 | Z4: p24 | AA4: p25 | AB4: p26 | AC4: p27 | AD4: p28 | AE4: p29 | AF4: p30 | AG4: p31 | AH4: p32 | AI4: p33 | AJ4: p34 | AK4: p35 | AL4: p36 | AM4: p37 | AN4: p38 | AO4: p39 | AP4: p40 | AQ4: p41 | AR4: p42 | AS4: p43 | AT4: p44 | AU4: p45 | AV4: p46 | AW4: p47 | AX4: p48
A5: Load_TR2_F3_1 | B5: customer | C5: 0.048 | D5: 0.1549 | E5: 0.048 | F5: 0.048 | G5: 0.1549 | H5: 0.048 | I5: 0.048 | J5: 0.1549 | K5: 0.048 | L5: 0.1549 | M5: 0.048 | N5: 0.048 | O5: 0.1549 | P5: 0.1086 | Q5: 0.229 | R5: 0.2045 | S5: 0.3574 | T5: 0.2536 | U5: 0.242 | V5: 0.1343 | W5: 0.1623 | X5: 0.8564 | Y5: 0.1565 | Z5: 0.048 | AA5: 0.1549 | AB5: 0.0572 | AC5: 0.7935 | AD5: 0.5391 | AE5: 0.048 | AF5: 0.1549 | AG5: 0.048 | AH5: 0.048 | AI5: 0.327 | AJ5: 0.048 | AK5: 0.0487 | AL5: 1.0719 | AM5: 0.283 | AN5: 0.0893 | AO5: 0.1549 | AP5: 0.048 | AQ5: 0.1091 | AR5: 0.0938 | AS5: 0.048 | AT5: 0.0556 | AU5: 0.1473 | AV5: 0.048 | AW5: 0.048 | AX5: 0.0862
A6: Load_TR2_F3_10 | B6: customer | C6: 0.1726 | D6: 0.1003 | E6: 0.057 | F6: 0.2159 | G6: 0.057 | H6: 0.057 | I6: 0.1653 | J6: 0.1076 | K6: 0.057 | L6: 0.057 | M6: 0.2087 | N6: 0.0642 | O6: 0.0787 | P6: 1.2415 | Q6: 0.097 | R6: 0.1993 | S6: 1.3792 | T6: 1.0353 | U6: 1.3393 | V6: 0.9763 | W6: 2.497 | X6: 0.3245 | Y6: 0.2334 | Z6: 1.6163 | AA6: 0.3725 | AB6: 1.4164 | AC6: 0.057 | AD6: 0.9998 | AE6: 0.8418 | AF6: 1.623 | AG6: 0.3558 | AH6: 0.2091 | AI6: 0.2035 | AJ6: 0.2833 | AK6: 0.5547 | AL6: 1.5895 | AM6: 0.2121 | AN6: 0.5087 | AO6: 0.2669 | AP6: 0.7303 | AQ6: 0.543 | AR6: 0.7202 | AS6: 2.1174 | AT6: 0.6897 | AU6: 0.3038 | AV6: 0.3734 | AW6: 0.3972 | AX6: 0.3092
A7: Load_TR2_F3_11 | B7: customer | C7: 0.2667 | D7: 0.053 | E7: 0.0589 | F7: 0.207 | G7: 0.1069 | H7: 0.1 | I7: 0.2197 | J7: 0.053 | K7: 0.2667 | L7: 0.053 | M7: 0.094 | N7: 0.2257 | O7: 0.1116 | P7: 1.9659 | Q7: 0.8412 | R7: 1.3094 | S7: 0.2877 | T7: 0.1727 | U7: 0.3508 | V7: 0.4026 | W7: 1.3043 | X7: 0.193 | Y7: 0.1351 | Z7: 0.053 | AA7: 0.2331 | AB7: 0.1259 | AC7: 0.1205 | AD7: 0.3801 | AE7: 0.2548 | AF7: 0.2657 | AG7: 0.094 | AH7: 0.3154 | AI7: 0.1869 | AJ7: 0.1706 | AK7: 0.2199 | AL7: 0.3245 | AM7: 0.3902 | AN7: 0.2385 | AO7: 0.9998 | AP7: 0.804 | AQ7: 0.3483 | AR7: 0.278 | AS7: 0.2454 | AT7: 0.5865 | AU7: 0.4732 | AV7: 0.1273 | AW7: 0.1175 | AX7: 0.1424
A8: Load_TR2_F3_12 | B8: customer | C8: 0.8069 | D8: 0.4644 | E8: 0.4347 | F8: 0.3725 | G8: 0.4447 | H8: 0.0887 | I8: 0.2177 | J8: 0.1146 | K8: 0.1786 | L8: 0.1742 | M8: 0.0739 | N8: 0.2193 | O8: 0.1411 | P8: 0.7522 | Q8: 1.055 | R8: 0.237 | S8: 0.1874 | T8: 0.055 | U8: 0.1224 | V8: 0.2436 | W8: 0.1136 | X8: 0.3147 | Y8: 1.2415 | Z8: 2.3482 | AA8: 0.3344 | AB8: 0.2378 | AC8: 0.3921 | AD8: 0.5304 | AE8: 0.6396 | AF8: 0.7573 | AG8: 0.1964 | AH8: 0.0822 | AI8: 0.232 | AJ8: 1.2149 | AK8: 0.485 | AL8: 2.4083 | AM8: 1.3988 | AN8: 0.4145 | AO8: 0.7633 | AP8: 0.6336 | AQ8: 0.5807 | AR8: 0.5176 | AS8: 0.4835 | AT8: 0.6368 | AU8: 0.7579 | AV8: 0.6555 | AW8: 0.5817 | AX8: 0.3233
A9: Load_TR2_F3_13 | B9: customer | C9: 0.0734 | D9: 0.1549 | E9: 0.056 | F9: 0.056 | G9: 0.1374 | H9: 0.0909 | I9: 0.056 | J9: 0.1607 | K9: 0.0676 | L9: 0.1642 | M9: 0.1374 | N9: 0.056 | O9: 0.1723 | P9: 0.056 | Q9: 0.1723 | R9: 0.056 | S9: 0.1549 | T9: 0.0734 | U9: 0.056 | V9: 0.1723 | W9: 0.056 | X9: 0.056 | Y9: 0.1723 | Z9: 0.056 | AA9: 0.2327 | AB9: 0.2876 | AC9: 0.2331 | AD9: 0.5264 | AE9: 0.2321 | AF9: 0.5089 | AG9: 0.4379 | AH9: 0.5267 | AI9: 0.2319 | AJ9: 0.0721 | AK9: 0.1142 | AL9: 0.1142 | AM9: 0.056 | AN9: 0.1723 | AO9: 0.1315 | AP9: 0.2103 | AQ9: 0.6784 | AR9: 0.4258 | AS9: 0.5984 | AT9: 0.6139 | AU9: 0.1491 | AV9: 0.0793 | AW9: 0.0676 | AX9: 0.1607
A10: Load_TR2_F3_14 | B10: customer | C10: 0.1154 | D10: 0.05 | E10: 0.3316 | F10: 0.0745 | G10: 0.209 | H10: 0.1971 | I10: 0.05 | J10: 0.3561 | K10: 0.05 | L10: 0.2744 | M10: 0.1317 | N10: 0.05 | O10: 0.1399 | P10: 0.1715 | Q10: 0.1447 | R10: 0.2551 | S10: 0.1511 | T10: 0.1733 | U10: 0.5874 | V10: 0.6525 | W10: 0.3772 | X10: 0.3213 | Y10: 0.2424 | Z10: 0.05 | AA10: 0.2499 | AB10: 0.1562 | AC10: 0.0891 | AD10: 0.6733 | AE10: 0.1535 | AF10: 0.2995 | AG10: 0.2165 | AH10: 0.355 | AI10: 0.258 | AJ10: 0.2025 | AK10: 0.6346 | AL10: 0.6913 | AM10: 0.1674 | AN10: 0.3399 | AO10: 0.1808 | AP10: 0.1622 | AQ10: 0.1132 | AR10: 0.05 | AS10: 0.2926 | AT10: 0.1135 | AU10: 0.1648 | AV10: 0.2413 | AW10: 0.05 | AX10: 0.1098
A11: Load_TR2_F3_15 | B11: customer | C11: 0.4363 | D11: 0.4532 | E11: 0.0295 | F11: 0.1874 | G11: 0.0465 | H11: 0.1453 | I11: 0.0931 | J11: 0.025 | K11: 0.1469 | L11: 0.0915 | M11: 0.025 | N11: 0.1109 | O11: 0.0465 | P11: 0.0465 | Q11: 0.1919 | R11: 0.0304 | S11: 0.1636 | T11: 0.1335 | U11: 0.0401 | V11: 0.0565 | W11: 0.1819 | X11: 0.079 | Y11: 0.1594 | Z11: 0.025 | AA11: 0.1382 | AB11: 0.1002 | AC11: 0.052 | AD11: 0.079 | AE11: 0.025 | AF11: 0.165 | AG11: 0.0733 | AH11: 0.0519 | AI11: 0.1056 | AJ11: 0.106 | AK11: 0.0895 | AL11: 0.2177 | AM11: 0.1102 | AN11: 0.2273 | AO11: 0.0884 | AP11: 0.2069 | AQ11: 0.3915 | AR11: 0.4668 | AS11: 0.4359 | AT11: 0.446 | AU11: 0.7716 | AV11: 0.8114 | AW11: 0.4869 | AX11: 0.1324
A12: Load_TR2_F3_16 | B12: customer | C12: 0.1684 | D12: 0.2135 | E12: 0.065 | F12: 0.3097 | G12: 0.0853 | H12: 0.1009 | I12: 0.3167 | J12: 0.097 | K12: 0.236 | L12: 0.1474 | M12: 0.1233 | N12: 0.0853 | O12: 0.3439 | P12: 0.1009 | Q12: 0.058 | R12: 0.3124 | S12: 0.1324 | T12: 0.7032 | U12: 2.315 | V12: 0.5179 | W12: 0.2474 | X12: 0.5992 | Y12: 0.3827 | Z12: 0.7663 | AA12: 2.1706 | AB12: 2.5795 | AC12: 2.2937 | AD12: 0.2468 | AE12: 0.3021 | AF12: 0.1566 | AG12: 0.1863 | AH12: 0.1404 | AI12: 0.1086 | AJ12: 0.2048 | AK12: 0.2705 | AL12: 0.7733 | AM12: 0.1069 | AN12: 0.1629 | AO12: 0.2819 | AP12: 0.1554 | AQ12: 0.2195 | AR12: 0.1279 | AS12: 0.1629 | AT12: 0.1768 | AU12: 0.1631 | AV12: 0.1838 | AW12: 0.2609 | AX12: 0.1479
A13: Load_TR2_F3_17 | B13: customer | C13: 0.2762 | D13: 0.1562 | E13: 0.1224 | F13: 0.1519 | G13: 0.1961 | H13: 0.142 | I13: 0.4171 | J13: 0.5411 | K13: 0.1522 | L13: 0.1415 | M13: 0.2762 | N13: 0.1656 | O13: 0.128 | P13: 0.2213 | Q13: 0.2112 | R13: 0.0808 | S13: 0.2673 | T13: 0.0671 | U13: 0.1858 | V13: 0.2326 | W13: 0.1374 | X13: 0.1918 | Y13: 0.0992 | Z13: 0.2638 | AA13: 0.1459 | AB13: 0.114 | AC13: 0.0899 | AD13: 0.3426 | AE13: 0.0675 | AF13: 0.4327 | AG13: 0.1649 | AH13: 0.3367 | AI13: 0.188 | AJ13: 0.2391 | AK13: 0.1656 | AL13: 0.1327 | AM13: 0.1293 | AN13: 0.2235 | AO13: 0.1374 | AP13: 0.295 | AQ13: 0.053 | AR13: 0.0751 | AS13: 0.2776 | AT13: 0.1327 | AU13: 0.112 | AV13: 0.2454 | AW13: 0.3517 | AX13: 0.2673
A14: Load_TR2_F3_18 | B14: customer | C14: 0.1474 | D14: 0.046 | E14: 0.1334 | F14: 0.2709 | G14: 0.0802 | H14: 0.1237 | I14: 0.3148 | J14: 0.046 | K14: 0.2215 | L14: 0.217 | M14: 0.1043 | N14: 0.3342 | O14: 0.0897 | P14: 0.0994 | Q14: 0.2954 | R14: 0.1043 | S14: 0.0848 | T14: 0.3099 | U14: 0.1456 | V14: 0.2234 | W14: 0.2236 | X14: 0.0973 | Y14: 0.2526 | Z14: 0.181 | AA14: 0.0744 | AB14: 0.3204 | AC14: 0.0946 | AD14: 0.2184 | AE14: 0.123 | AF14: 0.198 | AG14: 0.1892 | AH14: 0.1944 | AI14: 0.2526 | AJ14: 0.1033 | AK14: 0.2696 | AL14: 0.1822 | AM14: 0.0998 | AN14: 0.548 | AO14: 0.1323 | AP14: 0.3742 | AQ14: 0.7361 | AR14: 0.6087 | AS14: 0.731 | AT14: 1.0361 | AU14: 0.7173 | AV14: 0.5039 | AW14: 0.6304 | AX14: 0.311
A15: Load_TR2_F3_19 | B15: customer | C15: 0.1256 | D15: 0.051 | E15: 0.0551 | F15: 0.1215 | G15: 0.051 | H15: 0.051 | I15: 0.0966 | J15: 0.08 | K15: 0.051 | L15: 0.0759 | M15: 0.1008 | N15: 0.051 | O15: 0.051 | P15: 0.051 | Q15: 0.051 | R15: 0.1256 | S15: 0.2975 | T15: 0.4056 | U15: 0.2806 | V15: 0.2372 | W15: 0.0605 | X15: 0.0634 | Y15: 0.1132 | Z15: 0.051 | AA15: 0.2041 | AB15: 0.2141 | AC15: 0.1276 | AD15: 0.051 | AE15: 0.0717 | AF15: 0.1049 | AG15: 0.051 | AH15: 0.051 | AI15: 0.1256 | AJ15: 0.051 | AK15: 0.1091 | AL15: 0.0676 | AM15: 0.0966 | AN15: 0.08 | AO15: 0.051 | AP15: 0.051 | AQ15: 0.0883 | AR15: 0.0883 | AS15: 0.051 | AT15: 0.1256 | AU15: 0.051 | AV15: 0.1256 | AW15: 0.051 | AX15: 0.051
A16: Load_TR2_F3_2 | B16: customer | C16: 0.1823 | D16: 0.048 | E16: 0.1512 | F16: 0.1567 | G16: 0.1192 | H16: 0.1887 | I16: 0.048 | J16: 0.1192 | K16: 0.048 | L16: 0.2441 | M16: 0.0638 | N16: 0.1113 | O16: 0.1966 | P16: 0.048 | Q16: 0.048 | R16: 0.1247 | S16: 0.1119 | T16: 1.0913 | U16: 0.3151 | V16: 0.3174 | W16: 0.3007 | X16: 0.3775 | Y16: 0.207 | Z16: 0.3627 | AA16: 0.2224 | AB16: 0.2714 | AC16: 0.3776 | AD16: 0.2642 | AE16: 0.4403 | AF16: 0.5407 | AG16: 1.2901 | AH16: 0.4804 | AI16: 0.3614 | AJ16: 0.2332 | AK16: 0.3552 | AL16: 0.3398 | AM16: 0.2082 | AN16: 0.0762 | AO16: 0.3634 | AP16: 0.4132 | AQ16: 0.7189 | AR16: 0.7294 | AS16: 0.5619 | AT16: 0.7093 | AU16: 0.863 | AV16: 0.6242 | AW16: 0.224 | AX16: 0.0839
... A181: Load_TR2_F6_9 | B181: customer | C181: 0.049 | D181: 0.2777 | E181: 0.0925 | F181: 0.0997 | G181: 0.2084 | H181: 0.1111 | I181: 0.2083 | J181: 0.1619 | K181: 0.049 | L181: 0.1078 | M181: 0.2624 | N181: 0.049 | O181: 0.2535 | P181: 0.1167 | Q181: 0.0997 | R181: 0.1576 | S181: 0.1054 | T181: 0.1706 | U181: 0.1488 | V181: 0.1562 | W181: 0.1576 | X181: 0.2126 | Y181: 0.049 | Z181: 0.1975 | AA181: 0.223 | AB181: 0.2025 | AC181: 0.1794 | AD181: 0.078 | AE181: 0.049 | AF181: 0.0772 | AG181: 0.293 | AH181: 0.049 | AI181: 0.3212 | AJ181: 0.049 | AK181: 0.1651 | AL181: 0.3932 | AM181: 0.0772 | AN181: 0.1337 | AO181: 0.2586 | AP181: 0.6139 | AQ181: 0.5827 | AR181: 0.7466 | AS181: 0.6861 | AT181: 0.8749 | AU181: 1.2018 | AV181: 0.3003 | AW181: 0.1167 | AX181: 0.2535

Sheet 5. Raw batt charge
A1: Raw batt charge
A2: Verbatim copy of Charge_kW (TR2_analysis_data.xlsx). One row per half-hour, one column per battery (kW).
A4: period | B4: hour | C4: BES_TR2_three312_A | D4: BES_TR2_three321_B | E4: BES_TR2_three368_A | F4: BES_TR2_three388_A | G4: BES_TR2_three409_C | H4: BES_TR2_three478_B | I4: BES_TR2_three97_B | J4: BES_TR2_three133_C | K4: BES_TR2_three160_C | L4: BES_TR2_five58_C | M4: BES_TR2_five147_C | N4: BES_TR2_five149_A | O4: BES_TR2_five160_C | P4: BES_TR2_five170_A | Q4: BES_TR2_five177_A | R4: BES_TR2_five67_C | S4: BES_TR2_five243_B | T4: BES_TR2_five284_C | U4: BES_TR2_five285_B | V4: BES_TR2_five303_B | W4: BES_TR2_five324_B | X4: BES_TR2_five355_A | Y4: BES_TR2_five394_C | Z4: BES_TR2_five451_A | AA4: BES_TR2_five466_A | AB4: BES_TR2_five494_B | AC4: BES_TR2_five512_A | AD4: BES_TR2_five520_C | AE4: BES_TR2_five540_A | AF4: BES_TR2_five588_A | AG4: BES_TR2_five649_A | AH4: BES_TR2_five663_C | AI4: BES_TR2_five685_B | AJ4: BES_TR2_five695_A | AK4: BES_TR2_five704_A | AL4: BES_TR2_five733_C | AM4: BES_TR2_five117_B | AN4: BES_TR2_five778_B | AO4: BES_TR2_five799_C | AP4: BES_TR2_five801_C | AQ4: BES_TR2_five831_C | AR4: BES_TR2_five881_C | AS4: BES_TR2_five118_B | AT4: BES_TR2_six64_A | AU4: BES_TR2_six154_C | AV4: BES_TR2_six173_C | AW4: BES_TR2_six186_A | AX4: BES_TR2_six191_B | AY4: BES_TR2_six203_A | AZ4: BES_TR2_six232_C | BA4: BES_TR2_six238_A | BB4: BES_TR2_six249_B | BC4: BES_TR2_six254_B | BD4: BES_TR2_six269_C | BE4: BES_TR2_six289_C | BF4: BES_TR2_six317_C | BG4: BES_TR2_six326_A | BH4: BES_TR2_six329_A | BI4: BES_TR2_six342_A | BJ4: BES_TR2_six349_A | BK4: BES_TR2_six350_B | BL4: BES_TR2_six362_C | BM4: BES_TR2_six365_C | BN4: BES_TR2_six378_A | BO4: BES_TR2_six385_B | BP4: BES_TR2_six387_A | BQ4: BES_TR2_six392_C | BR4: BES_TR2_six410_A | BS4: BES_TR2_six431_C | BT4: BES_TR2_six484_B | BU4: BES_TR2_six512_B | BV4: BES_TR2_six518_B | BW4: BES_TR2_six523_C | BX4: BES_TR2_six571_C | BY4: BES_TR2_six583_A | BZ4: BES_TR2_six625_A | CA4: BES_TR2_six646_B | CB4: BES_TR2_six87_A | CC4: BES_TR2_six652_A | CD4: BES_TR2_six665_B | CE4: BES_TR2_six667_A | CF4: BES_TR2_six721_A | CG4: BES_TR2_six740_A | CH4: BES_TR2_six758_B | CI4: BES_TR2_six784_B | CJ4: BES_TR2_six799_B | CK4: BES_TR2_six807_A | CL4: BES_TR2_six885_A | CM4: BES_TR2_six894_B | CN4: BES_TR2_six914_A | CO4: BES_TR2_six921_B | CP4: BES_TR2_six929_A | CQ4: BES_TR2_six938_A | CR4: BES_TR2_six990_B | CS4: BES_TR2_six1020_A
A5: 1 | B5: 0 | C5: 0 | D5: 0 | E5: 0 | F5: 0 | G5: 0 | H5: 0 | I5: 0 | J5: 0 | K5: 0 | L5: 0 | M5: 0 | N5: 0 | O5: 0 | P5: 0 | Q5: 0 | R5: 0 | S5: 0 | T5: 0 | U5: 0 | V5: 0 | W5: 0 | X5: 0 | Y5: 0 | Z5: 0 | AA5: 0 | AB5: 0 | AC5: 0 | AD5: 0 | AE5: 0 | AF5: 0 | AG5: 0 | AH5: 0 | AI5: 0 | AJ5: 0 | AK5: 0 | AL5: 0 | AM5: 0 | AN5: 0 | AO5: 0 | AP5: 0 | AQ5: 0 | AR5: 0 | AS5: 0 | AT5: 0 | AU5: 0 | AV5: 0 | AW5: 0 | AX5: 0 | AY5: 0 | AZ5: 0 | BA5: 0 | BB5: 0 | BC5: 0 | BD5: 0 | BE5: 0 | BF5: 0 | BG5: 0 | BH5: 0 | BI5: 0 | BJ5: 0 | BK5: 0 | BL5: 0 | BM5: 0 | BN5: 0 | BO5: 0 | BP5: 0 | BQ5: 0 | BR5: 0 | BS5: 0 | BT5: 0 | BU5: 0 | BV5: 0 | BW5: 0 | BX5: 0 | BY5: 0 | BZ5: 0 | CA5: 0 | CB5: 0 | CC5: 0 | CD5: 0 | CE5: 0 | CF5: 0 | CG5: 0 | CH5: 0 | CI5: 0 | CJ5: 0 | CK5: 0 | CL5: 0 | CM5: 0 | CN5: 0 | CO5: 0 | CP5: 0 | CQ5: 0 | CR5: 0 | CS5: 0
A6: 2 | B6: 0.5 | C6: 0 | D6: 0 | E6: 0 | F6: 0 | G6: 0 | H6: 0 | I6: 0 | J6: 0 | K6: 0 | L6: 0 | M6: 0 | N6: 0 | O6: 0 | P6: 0 | Q6: 0 | R6: 0 | S6: 0 | T6: 0 | U6: 0 | V6: 0 | W6: 0 | X6: 0 | Y6: 0 | Z6: 0 | AA6: 0 | AB6: 0 | AC6: 0 | AD6: 0 | AE6: 0 | AF6: 0 | AG6: 0 | AH6: 0 | AI6: 0 | AJ6: 0 | AK6: 0 | AL6: 0 | AM6: 0 | AN6: 0 | AO6: 0 | AP6: 0 | AQ6: 0 | AR6: 0 | AS6: 0 | AT6: 0 | AU6: 0 | AV6: 0 | AW6: 0 | AX6: 0 | AY6: 0 | AZ6: 0 | BA6: 0 | BB6: 0 | BC6: 0 | BD6: 0 | BE6: 0 | BF6: 0 | BG6: 0 | BH6: 0 | BI6: 0 | BJ6: 0 | BK6: 0 | BL6: 0 | BM6: 0 | BN6: 0 | BO6: 0 | BP6: 0 | BQ6: 0 | BR6: 0 | BS6: 0 | BT6: 0 | BU6: 0 | BV6: 0 | BW6: 0 | BX6: 0 | BY6: 0 | BZ6: 0 | CA6: 0 | CB6: 0 | CC6: 0 | CD6: 0 | CE6: 0 | CF6: 0 | CG6: 0 | CH6: 0 | CI6: 0 | CJ6: 0 | CK6: 0 | CL6: 0 | CM6: 0 | CN6: 0 | CO6: 0 | CP6: 0 | CQ6: 0 | CR6: 0 | CS6: 0
A7: 3 | B7: 1 | C7: 0 | D7: 0 | E7: 0 | F7: 0 | G7: 0 | H7: 0 | I7: 0 | J7: 0 | K7: 0 | L7: 0 | M7: 0 | N7: 0 | O7: 0 | P7: 0 | Q7: 0 | R7: 0 | S7: 0 | T7: 0 | U7: 0 | V7: 0 | W7: 0 | X7: 0 | Y7: 0 | Z7: 0 | AA7: 0 | AB7: 0 | AC7: 0 | AD7: 0 | AE7: 0 | AF7: 0 | AG7: 0 | AH7: 0 | AI7: 0 | AJ7: 0 | AK7: 0 | AL7: 0 | AM7: 0 | AN7: 0 | AO7: 0 | AP7: 0 | AQ7: 0 | AR7: 0 | AS7: 0 | AT7: 0 | AU7: 0 | AV7: 0 | AW7: 0 | AX7: 0 | AY7: 0 | AZ7: 0 | BA7: 0 | BB7: 0 | BC7: 0 | BD7: 0 | BE7: 0 | BF7: 0 | BG7: 0 | BH7: 0 | BI7: 0 | BJ7: 0 | BK7: 0 | BL7: 0 | BM7: 0 | BN7: 0 | BO7: 0 | BP7: 0 | BQ7: 0 | BR7: 0 | BS7: 0 | BT7: 0 | BU7: 0 | BV7: 0 | BW7: 0 | BX7: 0 | BY7: 0 | BZ7: 0 | CA7: 0 | CB7: 0 | CC7: 0 | CD7: 0 | CE7: 0 | CF7: 0 | CG7: 0 | CH7: 0 | CI7: 0 | CJ7: 0 | CK7: 0 | CL7: 0 | CM7: 0 | CN7: 0 | CO7: 0 | CP7: 0 | CQ7: 0 | CR7: 0 | CS7: 0
A8: 4 | B8: 1.5 | C8: 0 | D8: 0 | E8: 0 | F8: 0 | G8: 0 | H8: 0 | I8: 0 | J8: 0 | K8: 0 | L8: 0 | M8: 0 | N8: 0 | O8: 0 | P8: 0 | Q8: 0 | R8: 0 | S8: 0 | T8: 0 | U8: 0 | V8: 0 | W8: 0 | X8: 0 | Y8: 0 | Z8: 0 | AA8: 0 | AB8: 0 | AC8: 0 | AD8: 0 | AE8: 0 | AF8: 0 | AG8: 0 | AH8: 0 | AI8: 0 | AJ8: 0 | AK8: 0 | AL8: 0 | AM8: 0 | AN8: 0 | AO8: 0 | AP8: 0 | AQ8: 0 | AR8: 0 | AS8: 0 | AT8: 0 | AU8: 0 | AV8: 0 | AW8: 0 | AX8: 0 | AY8: 0 | AZ8: 0 | BA8: 0 | BB8: 0 | BC8: 0 | BD8: 0 | BE8: 0 | BF8: 0 | BG8: 0 | BH8: 0 | BI8: 0 | BJ8: 0 | BK8: 0 | BL8: 0 | BM8: 0 | BN8: 0 | BO8: 0 | BP8: 0 | BQ8: 0 | BR8: 0 | BS8: 0 | BT8: 0 | BU8: 0 | BV8: 0 | BW8: 0 | BX8: 0 | BY8: 0 | BZ8: 0 | CA8: 0 | CB8: 0 | CC8: 0 | CD8: 0 | CE8: 0 | CF8: 0 | CG8: 0 | CH8: 0 | CI8: 0 | CJ8: 0 | CK8: 0 | CL8: 0 | CM8: 0 | CN8: 0 | CO8: 0 | CP8: 0 | CQ8: 0 | CR8: 0 | CS8: 0
A9: 5 | B9: 2 | C9: 0 | D9: 0 | E9: 0 | F9: 0 | G9: 0 | H9: 0 | I9: 0 | J9: 0 | K9: 0 | L9: 0 | M9: 0 | N9: 0 | O9: 0 | P9: 0 | Q9: 0 | R9: 0 | S9: 0 | T9: 0 | U9: 0 | V9: 0 | W9: 0 | X9: 0 | Y9: 0 | Z9: 0 | AA9: 0 | AB9: 0 | AC9: 0 | AD9: 0 | AE9: 0 | AF9: 0 | AG9: 0 | AH9: 0 | AI9: 0 | AJ9: 0 | AK9: 0 | AL9: 0 | AM9: 0 | AN9: 0 | AO9: 0 | AP9: 0 | AQ9: 0 | AR9: 0 | AS9: 0 | AT9: 0 | AU9: 0 | AV9: 0 | AW9: 0 | AX9: 0 | AY9: 0 | AZ9: 0 | BA9: 0 | BB9: 0 | BC9: 0 | BD9: 0 | BE9: 0 | BF9: 0 | BG9: 0 | BH9: 0 | BI9: 0 | BJ9: 0 | BK9: 0 | BL9: 0 | BM9: 0 | BN9: 0 | BO9: 0 | BP9: 0 | BQ9: 0 | BR9: 0 | BS9: 0 | BT9: 0 | BU9: 0 | BV9: 0 | BW9: 0 | BX9: 0 | BY9: 0 | BZ9: 0 | CA9: 0 | CB9: 0 | CC9: 0 | CD9: 0 | CE9: 0 | CF9: 0 | CG9: 0 | CH9: 0 | CI9: 0 | CJ9: 0 | CK9: 0 | CL9: 0 | CM9: 0 | CN9: 0 | CO9: 0 | CP9: 0 | CQ9: 0 | CR9: 0 | CS9: 0
A10: 6 | B10: 2.5 | C10: 0 | D10: 0 | E10: 0 | F10: 0 | G10: 0 | H10: 0 | I10: 0 | J10: 0 | K10: 0 | L10: 0 | M10: 0 | N10: 0 | O10: 0 | P10: 0 | Q10: 0 | R10: 0 | S10: 0 | T10: 0 | U10: 0 | V10: 0 | W10: 0 | X10: 0 | Y10: 0 | Z10: 0 | AA10: 0 | AB10: 0 | AC10: 0 | AD10: 0 | AE10: 0 | AF10: 0 | AG10: 0 | AH10: 0 | AI10: 0 | AJ10: 0 | AK10: 0 | AL10: 0 | AM10: 0 | AN10: 0 | AO10: 0 | AP10: 0 | AQ10: 0 | AR10: 0 | AS10: 0 | AT10: 0 | AU10: 0 | AV10: 0 | AW10: 0 | AX10: 0 | AY10: 0 | AZ10: 0 | BA10: 0 | BB10: 0 | BC10: 0 | BD10: 0 | BE10: 0 | BF10: 0 | BG10: 0 | BH10: 0 | BI10: 0 | BJ10: 0 | BK10: 0 | BL10: 0 | BM10: 0 | BN10: 0 | BO10: 0 | BP10: 0 | BQ10: 0 | BR10: 0 | BS10: 0 | BT10: 0 | BU10: 0 | BV10: 0 | BW10: 0 | BX10: 0 | BY10: 0 | BZ10: 0 | CA10: 0 | CB10: 0 | CC10: 0 | CD10: 0 | CE10: 0 | CF10: 0 | CG10: 0 | CH10: 0 | CI10: 0 | CJ10: 0 | CK10: 0 | CL10: 0 | CM10: 0 | CN10: 0 | CO10: 0 | CP10: 0 | CQ10: 0 | CR10: 0 | CS10: 0
A11: 7 | B11: 3 | C11: 0 | D11: 0 | E11: 0 | F11: 0 | G11: 0 | H11: 0 | I11: 0 | J11: 0 | K11: 0 | L11: 0 | M11: 0 | N11: 0 | O11: 0 | P11: 0 | Q11: 0 | R11: 0 | S11: 0 | T11: 0 | U11: 0 | V11: 0 | W11: 0 | X11: 0 | Y11: 0 | Z11: 0 | AA11: 0 | AB11: 0 | AC11: 0 | AD11: 0 | AE11: 0 | AF11: 0 | AG11: 0 | AH11: 0 | AI11: 0 | AJ11: 0 | AK11: 0 | AL11: 0 | AM11: 0 | AN11: 0 | AO11: 0 | AP11: 0 | AQ11: 0 | AR11: 0 | AS11: 0 | AT11: 0 | AU11: 0 | AV11: 0 | AW11: 0 | AX11: 0 | AY11: 0 | AZ11: 0 | BA11: 0 | BB11: 0 | BC11: 0 | BD11: 0 | BE11: 0 | BF11: 0 | BG11: 0 | BH11: 0 | BI11: 0 | BJ11: 0 | BK11: 0 | BL11: 0 | BM11: 0 | BN11: 0 | BO11: 0 | BP11: 0 | BQ11: 0 | BR11: 0 | BS11: 0 | BT11: 0 | BU11: 0 | BV11: 0 | BW11: 0 | BX11: 0 | BY11: 0 | BZ11: 0 | CA11: 0 | CB11: 0 | CC11: 0 | CD11: 0 | CE11: 0 | CF11: 0 | CG11: 0 | CH11: 0 | CI11: 0 | CJ11: 0 | CK11: 0 | CL11: 0 | CM11: 0 | CN11: 0 | CO11: 0 | CP11: 0 | CQ11: 0 | CR11: 0 | CS11: 0
A12: 8 | B12: 3.5 | C12: 0 | D12: 0 | E12: 0 | F12: 0 | G12: 0 | H12: 0 | I12: 0 | J12: 0 | K12: 0 | L12: 0 | M12: 0 | N12: 0 | O12: 0 | P12: 0 | Q12: 0 | R12: 0 | S12: 0 | T12: 0 | U12: 0 | V12: 0 | W12: 0 | X12: 0 | Y12: 0 | Z12: 0 | AA12: 0 | AB12: 0 | AC12: 0 | AD12: 0 | AE12: 0 | AF12: 0 | AG12: 0 | AH12: 0 | AI12: 0 | AJ12: 0 | AK12: 0 | AL12: 0 | AM12: 0 | AN12: 0 | AO12: 0 | AP12: 0 | AQ12: 0 | AR12: 0 | AS12: 0 | AT12: 0 | AU12: 0 | AV12: 0 | AW12: 0 | AX12: 0 | AY12: 0 | AZ12: 0 | BA12: 0 | BB12: 0 | BC12: 0 | BD12: 0 | BE12: 0 | BF12: 0 | BG12: 0 | BH12: 0 | BI12: 0 | BJ12: 0 | BK12: 0 | BL12: 0 | BM12: 0 | BN12: 0 | BO12: 0 | BP12: 0 | BQ12: 0 | BR12: 0 | BS12: 0 | BT12: 0 | BU12: 0 | BV12: 0 | BW12: 0 | BX12: 0 | BY12: 0 | BZ12: 0 | CA12: 0 | CB12: 0 | CC12: 0 | CD12: 0 | CE12: 0 | CF12: 0 | CG12: 0 | CH12: 0 | CI12: 0 | CJ12: 0 | CK12: 0 | CL12: 0 | CM12: 0 | CN12: 0 | CO12: 0 | CP12: 0 | CQ12: 0 | CR12: 0 | CS12: 0
A13: 9 | B13: 4 | C13: 0 | D13: 0 | E13: 0 | F13: 0 | G13: 0 | H13: 0 | I13: 0.004 | J13: 0 | K13: 0 | L13: 0 | M13: 0 | N13: 0 | O13: 0 | P13: 0 | Q13: 0 | R13: 0 | S13: 0 | T13: 0 | U13: 0 | V13: 0 | W13: 0.001 | X13: 0 | Y13: 0 | Z13: 0 | AA13: 0 | AB13: 0 | AC13: 0 | AD13: 0 | AE13: 0 | AF13: 0 | AG13: 0.014 | AH13: 0 | AI13: 0 | AJ13: 0.001 | AK13: 0 | AL13: 0 | AM13: 0.002 | AN13: 0.004 | AO13: 0 | AP13: 0 | AQ13: 0 | AR13: 0 | AS13: 0 | AT13: 0 | AU13: 0 | AV13: 0 | AW13: 0 | AX13: 0 | AY13: 0 | AZ13: 0 | BA13: 0 | BB13: 0 | BC13: 0 | BD13: 0 | BE13: 0 | BF13: 0.002 | BG13: 0 | BH13: 0.021 | BI13: 0 | BJ13: 0 | BK13: 0 | BL13: 0 | BM13: 0.002 | BN13: 0 | BO13: 0 | BP13: 0 | BQ13: 0 | BR13: 0 | BS13: 0 | BT13: 0 | BU13: 0 | BV13: 0 | BW13: 0 | BX13: 0 | BY13: 0 | BZ13: 0 | CA13: 0 | CB13: 0 | CC13: 0 | CD13: 0 | CE13: 0 | CF13: 0 | CG13: 0 | CH13: 0 | CI13: 0 | CJ13: 0 | CK13: 0 | CL13: 0 | CM13: 0 | CN13: 0 | CO13: 0 | CP13: 0 | CQ13: 0 | CR13: 0 | CS13: 0
A14: 10 | B14: 4.5 | C14: 0.119 | D14: 0.19 | E14: 0.06 | F14: 0.176 | G14: 0.078 | H14: 0 | I14: 0.187 | J14: 0.119 | K14: 0.168 | L14: 0.192 | M14: 0.179 | N14: 0.092 | O14: 0 | P14: 0.101 | Q14: 0.033 | R14: 0 | S14: 0.183 | T14: 0.016 | U14: 0.177 | V14: 0.171 | W14: 0.123 | X14: 0.091 | Y14: 0.146 | Z14: 0.017 | AA14: 0 | AB14: 0.033 | AC14: 0.06 | AD14: 0 | AE14: 0.147 | AF14: 0 | AG14: 0.08 | AH14: 0 | AI14: 0.181 | AJ14: 0.184 | AK14: 0 | AL14: 0.064 | AM14: 0.005 | AN14: 0.072 | AO14: 0.186 | AP14: 0.142 | AQ14: 0 | AR14: 0 | AS14: 0 | AT14: 0 | AU14: 0.007 | AV14: 0.165 | AW14: 0.132 | AX14: 0.114 | AY14: 0.03 | AZ14: 0 | BA14: 0.123 | BB14: 0.115 | BC14: 0.13 | BD14: 0.089 | BE14: 0.139 | BF14: 0.185 | BG14: 0.157 | BH14: 0.204 | BI14: 0.097 | BJ14: 0 | BK14: 0.12 | BL14: 0.04 | BM14: 0.078 | BN14: 0 | BO14: 0.098 | BP14: 0.102 | BQ14: 0.154 | BR14: 0.197 | BS14: 0.097 | BT14: 0.107 | BU14: 0.193 | BV14: 0.062 | BW14: 0.068 | BX14: 0.015 | BY14: 0.085 | BZ14: 0 | CA14: 0.158 | CB14: 0 | CC14: 0.111 | CD14: 0.106 | CE14: 0 | CF14: 0 | CG14: 0.172 | CH14: 0 | CI14: 0.067 | CJ14: 0.035 | CK14: 0.098 | CL14: 0.113 | CM14: 0.039 | CN14: 0 | CO14: 0.154 | CP14: 0 | CQ14: 0.182 | CR14: 0.113 | CS14: 0
A15: 11 | B15: 5 | C15: 0.169 | D15: 0.326 | E15: 0 | F15: 0.404 | G15: 0.196 | H15: 0.303 | I15: 0.415 | J15: 0.282 | K15: 0.291 | L15: 0.42 | M15: 0.286 | N15: 0.376 | O15: 0.177 | P15: 0.182 | Q15: 0.041 | R15: 0.341 | S15: 0.411 | T15: 0 | U15: 0.405 | V15: 0.42 | W15: 0.412 | X15: 0.188 | Y15: 0.187 | Z15: 0.241 | AA15: 0.106 | AB15: 0.119 | AC15: 0.065 | AD15: 0.128 | AE15: 0.32 | AF15: 0.125 | AG15: 0.425 | AH15: 0.009 | AI15: 0.277 | AJ15: 0.205 | AK15: 0.275 | AL15: 0.179 | AM15: 0.413 | AN15: 0.362 | AO15: 0.328 | AP15: 0.378 | AQ15: 0.169 | AR15: 0.163 | AS15: 0.306 | AT15: 0.226 | AU15: 0.177 | AV15: 0.417 | AW15: 0.382 | AX15: 0.286 | AY15: 0.297 | AZ15: 0.176 | BA15: 0.245 | BB15: 0.186 | BC15: 0.413 | BD15: 0.328 | BE15: 0.357 | BF15: 0.413 | BG15: 0.357 | BH15: 0.432 | BI15: 0.088 | BJ15: 0.089 | BK15: 0.245 | BL15: 0.126 | BM15: 0.382 | BN15: 0.146 | BO15: 0.148 | BP15: 0.406 | BQ15: 0.033 | BR15: 0.376 | BS15: 0.409 | BT15: 0.25 | BU15: 0.421 | BV15: 0.156 | BW15: 0 | BX15: 0.107 | BY15: 0.305 | BZ15: 0.135 | CA15: 0.247 | CB15: 0.005 | CC15: 0.199 | CD15: 0.408 | CE15: 0.207 | CF15: 0.088 | CG15: 0.314 | CH15: 0.207 | CI15: 0.182 | CJ15: 0.179 | CK15: 0.356 | CL15: 0.194 | CM15: 0.047 | CN15: 0.087 | CO15: 0.354 | CP15: 0 | CQ15: 0.229 | CR15: 0.272 | CS15: 0.094
A16: 12 | B16: 5.5 | C16: 0.466 | D16: 0.622 | E16: 0.232 | F16: 0.685 | G16: 0.609 | H16: 0.312 | I16: 0.696 | J16: 0.439 | K16: 0.596 | L16: 0.687 | M16: 0.688 | N16: 0.472 | O16: 0.317 | P16: 0.509 | Q16: 0.224 | R16: 0.695 | S16: 0.692 | T16: 0.314 | U16: 0.686 | V16: 0.701 | W16: 0.693 | X16: 0.517 | Y16: 0.591 | Z16: 0.226 | AA16: 0.224 | AB16: 0.224 | AC16: 0.224 | AD16: 0.081 | AE16: 0.69 | AF16: 0.387 | AG16: 0.636 | AH16: 0.146 | AI16: 0.577 | AJ16: 0.693 | AK16: 0.41 | AL16: 0.319 | AM16: 0.515 | AN16: 0.696 | AO16: 0.498 | AP16: 0.572 | AQ16: 0.406 | AR16: 0.322 | AS16: 0.524 | AT16: 0.499 | AU16: 0.207 | AV16: 0.535 | AW16: 0.448 | AX16: 0.496 | AY16: 0.263 | AZ16: 0.33 | BA16: 0.615 | BB16: 0.372 | BC16: 0.646 | BD16: 0.403 | BE16: 0.441 | BF16: 0.694 | BG16: 0.513 | BH16: 0.713 | BI16: 0.416 | BJ16: 0.332 | BK16: 0.403 | BL16: 0.231 | BM16: 0.694 | BN16: 0.452 | BO16: 0.339 | BP16: 0.612 | BQ16: 0.585 | BR16: 0.615 | BS16: 0.69 | BT16: 0.325 | BU16: 0.687 | BV16: 0.186 | BW16: 0.011 | BX16: 0.395 | BY16: 0.517 | BZ16: 0.41 | CA16: 0.4 | CB16: 0.404 | CC16: 0.597 | CD16: 0.615 | CE16: 0.408 | CF16: 0.178 | CG16: 0.51 | CH16: 0.406 | CI16: 0.306 | CJ16: 0.07 | CK16: 0.512 | CL16: 0.416 | CM16: 0.23 | CN16: 0.234 | CO16: 0.599 | CP16: 0.241 | CQ16: 0.691 | CR16: 0.267 | CS16: 0.222
... A52: 48 | B52: 23.5 | C52: 0 | D52: 0 | E52: 0 | F52: 0 | G52: 0 | H52: 0 | I52: 0 | J52: 0 | K52: 0 | L52: 0 | M52: 0 | N52: 0 | O52: 0 | P52: 0 | Q52: 0 | R52: 0 | S52: 0 | T52: 0 | U52: 0 | V52: 0 | W52: 0 | X52: 0 | Y52: 0 | Z52: 0 | AA52: 0 | AB52: 0 | AC52: 0 | AD52: 0 | AE52: 0 | AF52: 0 | AG52: 0 | AH52: 0 | AI52: 0 | AJ52: 0 | AK52: 0 | AL52: 0 | AM52: 0 | AN52: 0 | AO52: 0 | AP52: 0 | AQ52: 0 | AR52: 0 | AS52: 0 | AT52: 0 | AU52: 0 | AV52: 0 | AW52: 0 | AX52: 0 | AY52: 0 | AZ52: 0 | BA52: 0 | BB52: 0 | BC52: 0 | BD52: 0 | BE52: 0 | BF52: 0 | BG52: 0 | BH52: 0 | BI52: 0 | BJ52: 0 | BK52: 0 | BL52: 0 | BM52: 0 | BN52: 0 | BO52: 0 | BP52: 0 | BQ52: 0 | BR52: 0 | BS52: 0 | BT52: 0 | BU52: 0 | BV52: 0 | BW52: 0 | BX52: 0 | BY52: 0 | BZ52: 0 | CA52: 0 | CB52: 0 | CC52: 0 | CD52: 0 | CE52: 0 | CF52: 0 | CG52: 0 | CH52: 0 | CI52: 0 | CJ52: 0 | CK52: 0 | CL52: 0 | CM52: 0 | CN52: 0 | CO52: 0 | CP52: 0 | CQ52: 0 | CR52: 0 | CS52: 0

Sheet 6. Raw batt discharge
A1: Raw batt discharge
A2: Verbatim copy of Discharge_kW (TR2_analysis_data.xlsx). One row per half-hour, one column per battery (kW).
A4: period | B4: hour | C4: BES_TR2_three312_A | D4: BES_TR2_three321_B | E4: BES_TR2_three368_A | F4: BES_TR2_three388_A | G4: BES_TR2_three409_C | H4: BES_TR2_three478_B | I4: BES_TR2_three97_B | J4: BES_TR2_three133_C | K4: BES_TR2_three160_C | L4: BES_TR2_five58_C | M4: BES_TR2_five147_C | N4: BES_TR2_five149_A | O4: BES_TR2_five160_C | P4: BES_TR2_five170_A | Q4: BES_TR2_five177_A | R4: BES_TR2_five67_C | S4: BES_TR2_five243_B | T4: BES_TR2_five284_C | U4: BES_TR2_five285_B | V4: BES_TR2_five303_B | W4: BES_TR2_five324_B | X4: BES_TR2_five355_A | Y4: BES_TR2_five394_C | Z4: BES_TR2_five451_A | AA4: BES_TR2_five466_A | AB4: BES_TR2_five494_B | AC4: BES_TR2_five512_A | AD4: BES_TR2_five520_C | AE4: BES_TR2_five540_A | AF4: BES_TR2_five588_A | AG4: BES_TR2_five649_A | AH4: BES_TR2_five663_C | AI4: BES_TR2_five685_B | AJ4: BES_TR2_five695_A | AK4: BES_TR2_five704_A | AL4: BES_TR2_five733_C | AM4: BES_TR2_five117_B | AN4: BES_TR2_five778_B | AO4: BES_TR2_five799_C | AP4: BES_TR2_five801_C | AQ4: BES_TR2_five831_C | AR4: BES_TR2_five881_C | AS4: BES_TR2_five118_B | AT4: BES_TR2_six64_A | AU4: BES_TR2_six154_C | AV4: BES_TR2_six173_C | AW4: BES_TR2_six186_A | AX4: BES_TR2_six191_B | AY4: BES_TR2_six203_A | AZ4: BES_TR2_six232_C | BA4: BES_TR2_six238_A | BB4: BES_TR2_six249_B | BC4: BES_TR2_six254_B | BD4: BES_TR2_six269_C | BE4: BES_TR2_six289_C | BF4: BES_TR2_six317_C | BG4: BES_TR2_six326_A | BH4: BES_TR2_six329_A | BI4: BES_TR2_six342_A | BJ4: BES_TR2_six349_A | BK4: BES_TR2_six350_B | BL4: BES_TR2_six362_C | BM4: BES_TR2_six365_C | BN4: BES_TR2_six378_A | BO4: BES_TR2_six385_B | BP4: BES_TR2_six387_A | BQ4: BES_TR2_six392_C | BR4: BES_TR2_six410_A | BS4: BES_TR2_six431_C | BT4: BES_TR2_six484_B | BU4: BES_TR2_six512_B | BV4: BES_TR2_six518_B | BW4: BES_TR2_six523_C | BX4: BES_TR2_six571_C | BY4: BES_TR2_six583_A | BZ4: BES_TR2_six625_A | CA4: BES_TR2_six646_B | CB4: BES_TR2_six87_A | CC4: BES_TR2_six652_A | CD4: BES_TR2_six665_B | CE4: BES_TR2_six667_A | CF4: BES_TR2_six721_A | CG4: BES_TR2_six740_A | CH4: BES_TR2_six758_B | CI4: BES_TR2_six784_B | CJ4: BES_TR2_six799_B | CK4: BES_TR2_six807_A | CL4: BES_TR2_six885_A | CM4: BES_TR2_six894_B | CN4: BES_TR2_six914_A | CO4: BES_TR2_six921_B | CP4: BES_TR2_six929_A | CQ4: BES_TR2_six938_A | CR4: BES_TR2_six990_B | CS4: BES_TR2_six1020_A
A5: 1 | B5: 0 | C5: 0.271 | D5: 0.043 | E5: 0.206 | F5: 0.057 | G5: 0.054 | H5: 0.162 | I5: 0.046 | J5: 0.055 | K5: 0.678 | L5: 0.213 | M5: 0.142 | N5: 0.119 | O5: 0.139 | P5: 0.19 | Q5: 0.054 | R5: 0.094 | S5: 0.05 | T5: 0.05 | U5: 0.41 | V5: 0.149 | W5: 0.049 | X5: 0.185 | Y5: 1.565 | Z5: 0.182 | AA5: 0.054 | AB5: 0.054 | AC5: 0.257 | AD5: 0.086 | AE5: 0.124 | AF5: 0.282 | AG5: 0.036 | AH5: 0.209 | AI5: 0.272 | AJ5: 0.158 | AK5: 0.709 | AL5: 0.052 | AM5: 0.048 | AN5: 0.214 | AO5: 0.86 | AP5: 0.053 | AQ5: 0.058 | AR5: 0.049 | AS5: 0.235 | AT5: 0.273 | AU5: 0.156 | AV5: 0.53 | AW5: 0.192 | AX5: 0.167 | AY5: 0.144 | AZ5: 0.167 | BA5: 0.034 | BB5: 0.038 | BC5: 0.401 | BD5: 0.178 | BE5: 0.61 | BF5: 0.048 | BG5: 0.145 | BH5: 0.029 | BI5: 0.367 | BJ5: 0.431 | BK5: 0.062 | BL5: 0.047 | BM5: 0.048 | BN5: 0.16 | BO5: 0.455 | BP5: 0.901 | BQ5: 0.313 | BR5: 0.757 | BS5: 0.178 | BT5: 0.038 | BU5: 0.409 | BV5: 0.116 | BW5: 0.048 | BX5: 0.384 | BY5: 0.054 | BZ5: 0.594 | CA5: 0.211 | CB5: 0.145 | CC5: 0.156 | CD5: 0.053 | CE5: 0.056 | CF5: 0.706 | CG5: 0.135 | CH5: 0.05 | CI5: 0.049 | CJ5: 1.071 | CK5: 0.57 | CL5: 0.046 | CM5: 0.061 | CN5: 0.086 | CO5: 0.082 | CP5: 0.778 | CQ5: 0.201 | CR5: 0.164 | CS5: 0.475
A6: 2 | B6: 0.5 | C6: 0.084 | D6: 0.211 | E6: 0.056 | F6: 0.057 | G6: 0.172 | H6: 0.14 | I6: 0.046 | J6: 0.116 | K6: 0.297 | L6: 0.284 | M6: 0.087 | N6: 0.1 | O6: 0.054 | P6: 0.047 | Q6: 0.132 | R6: 0.15 | S6: 0.05 | T6: 0.129 | U6: 0.486 | V6: 0.143 | W6: 0.11 | X6: 0.128 | Y6: 0.058 | Z6: 0.161 | AA6: 0.186 | AB6: 0.188 | AC6: 0.056 | AD6: 0.156 | AE6: 0.102 | AF6: 0.203 | AG6: 0.153 | AH6: 0.103 | AI6: 0.052 | AJ6: 0.049 | AK6: 0.856 | AL6: 0.052 | AM6: 0.227 | AN6: 0.046 | AO6: 0.639 | AP6: 0.121 | AQ6: 0.058 | AR6: 0.049 | AS6: 0.203 | AT6: 0.25 | AU6: 0.054 | AV6: 0.363 | AW6: 0.174 | AX6: 0.262 | AY6: 0.049 | AZ6: 0.129 | BA6: 0.034 | BB6: 0.138 | BC6: 0.562 | BD6: 0.101 | BE6: 0.23 | BF6: 0.048 | BG6: 0.047 | BH6: 0.029 | BI6: 0.447 | BJ6: 0.437 | BK6: 0.192 | BL6: 0.047 | BM6: 0.048 | BN6: 0.25 | BO6: 0.477 | BP6: 0.795 | BQ6: 0.05 | BR6: 1.634 | BS6: 0.052 | BT6: 0.038 | BU6: 0.357 | BV6: 0.144 | BW6: 0.1 | BX6: 0.054 | BY6: 0.215 | BZ6: 0.572 | CA6: 0.046 | CB6: 0.198 | CC6: 0.293 | CD6: 0.061 | CE6: 0.241 | CF6: 0.136 | CG6: 0.132 | CH6: 0.222 | CI6: 0.049 | CJ6: 1.043 | CK6: 0.713 | CL6: 0.159 | CM6: 0.052 | CN6: 0.156 | CO6: 0.125 | CP6: 0.668 | CQ6: 0.051 | CR6: 0.048 | CS6: 0.397
A7: 3 | B7: 1 | C7: 0.184 | D7: 0.043 | E7: 0.196 | F7: 0.057 | G7: 0.213 | H7: 0.193 | I7: 0.046 | J7: 0.131 | K7: 0.133 | L7: 0.135 | M7: 0.071 | N7: 0.198 | O7: 0.101 | P7: 0.177 | Q7: 0.054 | R7: 0.193 | S7: 0.05 | T7: 0.195 | U7: 0.583 | V7: 0.041 | W7: 0.049 | X7: 0.275 | Y7: 0.101 | Z7: 0.047 | AA7: 0.06 | AB7: 0.054 | AC7: 0.056 | AD7: 0.045 | AE7: 0.052 | AF7: 0.129 | AG7: 0.036 | AH7: 0.222 | AI7: 0.179 | AJ7: 0.225 | AK7: 0.679 | AL7: 0.052 | AM7: 0.048 | AN7: 0.183 | AO7: 0.387 | AP7: 0.053 | AQ7: 0.161 | AR7: 0.148 | AS7: 0.1 | AT7: 0.167 | AU7: 0.054 | AV7: 0.871 | AW7: 0.079 | AX7: 0.188 | AY7: 0.144 | AZ7: 0.05 | BA7: 0.151 | BB7: 0.084 | BC7: 0.048 | BD7: 0.128 | BE7: 0.104 | BF7: 0.048 | BG7: 0.114 | BH7: 0.029 | BI7: 0.172 | BJ7: 0.039 | BK7: 0.038 | BL7: 0.047 | BM7: 0.212 | BN7: 0.208 | BO7: 0.223 | BP7: 0.695 | BQ7: 0.273 | BR7: 0 | BS7: 0.206 | BT7: 0.139 | BU7: 0.066 | BV7: 0.054 | BW7: 0.304 | BX7: 0.346 | BY7: 0.058 | BZ7: 0.563 | CA7: 0.316 | CB7: 0.171 | CC7: 0.121 | CD7: 0.119 | CE7: 0.056 | CF7: 0.149 | CG7: 0.054 | CH7: 0.05 | CI7: 0.049 | CJ7: 0.058 | CK7: 0.093 | CL7: 0.119 | CM7: 0.121 | CN7: 0.044 | CO7: 0.055 | CP7: 0.17 | CQ7: 0.208 | CR7: 0.309 | CS7: 0.17
A8: 4 | B8: 1.5 | C8: 0.055 | D8: 0.166 | E8: 0.206 | F8: 0.057 | G8: 0.054 | H8: 0.156 | I8: 0.046 | J8: 0.051 | K8: 0.203 | L8: 0.041 | M8: 0.159 | N8: 0.112 | O8: 0.092 | P8: 0.06 | Q8: 0.123 | R8: 0.182 | S8: 0.05 | T8: 0.104 | U8: 0.638 | V8: 0.082 | W8: 0.11 | X8: 0.084 | Y8: 0.173 | Z8: 0.129 | AA8: 0.054 | AB8: 0.188 | AC8: 0.056 | AD8: 0.197 | AE8: 0.091 | AF8: 0.103 | AG8: 0.036 | AH8: 0.103 | AI8: 0.12 | AJ8: 0.081 | AK8: 0.147 | AL8: 0.052 | AM8: 0.048 | AN8: 0.077 | AO8: 0.192 | AP8: 0.083 | AQ8: 0.106 | AR8: 0.074 | AS8: 0.203 | AT8: 0.076 | AU8: 0.164 | AV8: 0.309 | AW8: 0.229 | AX8: 0.237 | AY8: 0.049 | AZ8: 0.109 | BA8: 0.089 | BB8: 0.261 | BC8: 0.082 | BD8: 0.225 | BE8: 0.164 | BF8: 0.048 | BG8: 0.183 | BH8: 0.029 | BI8: 0.544 | BJ8: 0.142 | BK8: 0.153 | BL8: 0.047 | BM8: 0.457 | BN8: 0.057 | BO8: 0.047 | BP8: 0 | BQ8: 0.131 | BR8: 0 | BS8: 0.052 | BT8: 0.038 | BU8: 0.19 | BV8: 0.157 | BW8: 0.077 | BX8: 0.074 | BY8: 0.054 | BZ8: 0.058 | CA8: 0.089 | CB8: 0.348 | CC8: 0.222 | CD8: 0.061 | CE8: 0.132 | CF8: 0.186 | CG8: 0.088 | CH8: 0.16 | CI8: 0.049 | CJ8: 0.219 | CK8: 0.171 | CL8: 0.288 | CM8: 0.048 | CN8: 0.198 | CO8: 0.152 | CP8: 0.037 | CQ8: 0.076 | CR8: 0.069 | CS8: 0.05
A9: 5 | B9: 2 | C9: 0.141 | D9: 0.089 | E9: 0.056 | F9: 0.057 | G9: 0.154 | H9: 0.125 | I9: 0.046 | J9: 0.117 | K9: 0.039 | L9: 0.259 | M9: 0.054 | N9: 0.22 | O9: 0.106 | P9: 0.138 | Q9: 0.063 | R9: 0.12 | S9: 0.05 | T9: 0.098 | U9: 0.173 | V9: 0.15 | W9: 0.049 | X9: 0.247 | Y9: 0.058 | Z9: 0.108 | AA9: 0.186 | AB9: 0.054 | AC9: 0.093 | AD9: 0.045 | AE9: 0.135 | AF9: 0.21 | AG9: 0.112 | AH9: 0.154 | AI9: 0.101 | AJ9: 0.174 | AK9: 0 | AL9: 0.052 | AM9: 0.227 | AN9: 0.115 | AO9: 0.18 | AP9: 0.091 | AQ9: 0.092 | AR9: 0.049 | AS9: 0.271 | AT9: 0.392 | AU9: 0.054 | AV9: 0.044 | AW9: 0.104 | AX9: 0.06 | AY9: 0.111 | AZ9: 0.188 | BA9: 0.034 | BB9: 0.038 | BC9: 0.163 | BD9: 0.063 | BE9: 0.17 | BF9: 0.048 | BG9: 0.083 | BH9: 0.029 | BI9: 0.231 | BJ9: 0.194 | BK9: 0.101 | BL9: 0.047 | BM9: 0.936 | BN9: 0.29 | BO9: 0.109 | BP9: 0 | BQ9: 0.189 | BR9: 0 | BS9: 0.108 | BT9: 0.038 | BU9: 0.134 | BV9: 0.102 | BW9: 0.12 | BX9: 0.341 | BY9: 0.131 | BZ9: 0.291 | CA9: 0.089 | CB9: 0.154 | CC9: 0.083 | CD9: 0.119 | CE9: 0.165 | CF9: 0.174 | CG9: 0.072 | CH9: 0.113 | CI9: 0.049 | CJ9: 0 | CK9: 0.142 | CL9: 0.057 | CM9: 0.126 | CN9: 0.044 | CO9: 0.05 | CP9: 0.277 | CQ9: 0.051 | CR9: 0.048 | CS9: 0.318
A10: 6 | B10: 2.5 | C10: 0.127 | D10: 0.058 | E10: 0.346 | F10: 0.057 | G10: 0.231 | H10: 0.176 | I10: 0.046 | J10: 0.064 | K10: 0.152 | L10: 0.041 | M10: 0.115 | N10: 0.106 | O10: 0.087 | P10: 0.099 | Q10: 0.11 | R10: 0.135 | S10: 0.05 | T10: 0.28 | U10: 0.056 | V10: 0.041 | W10: 0.086 | X10: 0.112 | Y10: 0.217 | Z10: 0.153 | AA10: 0.06 | AB10: 0.155 | AC10: 0.221 | AD10: 0.045 | AE10: 0.052 | AF10: 0.172 | AG10: 0.077 | AH10: 0.216 | AI10: 0.208 | AJ10: 0.132 | AK10: 0 | AL10: 0.052 | AM10: 0.048 | AN10: 0.145 | AO10: 0.064 | AP10: 0.053 | AQ10: 0.174 | AR10: 0.049 | AS10: 0.248 | AT10: 0.13 | AU10: 0.164 | AV10: 0.192 | AW10: 0.198 | AX10: 0.06 | AY10: 0.082 | AZ10: 0.065 | BA10: 0.034 | BB10: 0.207 | BC10: 0.048 | BD10: 0.12 | BE10: 0.091 | BF10: 0.048 | BG10: 0.214 | BH10: 0.029 | BI10: 0.333 | BJ10: 0.039 | BK10: 0.038 | BL10: 0.047 | BM10: 0.69 | BN10: 0.16 | BO10: 0.156 | BP10: 0 | BQ10: 0.136 | BR10: 0 | BS10: 0.15 | BT10: 0.139 | BU10: 0.13 | BV10: 0.054 | BW10: 0.269 | BX10: 0.114 | BY10: 0.142 | BZ10: 0.13 | CA10: 0.304 | CB10: 0.184 | CC10: 0.287 | CD10: 0.053 | CE10: 0.056 | CF10: 0.047 | CG10: 0.187 | CH10: 0.074 | CI10: 0.049 | CJ10: 0 | CK10: 0.048 | CL10: 0.046 | CM10: 0.052 | CN10: 0.044 | CO10: 0.147 | CP10: 0.037 | CQ10: 0.117 | CR10: 0.247 | CS10: 0.063
A11: 7 | B11: 3 | C11: 0.055 | D11: 0.196 | E11: 0.056 | F11: 0.057 | G11: 0.104 | H11: 0.105 | I11: 0.046 | J11: 0.109 | K11: 0.039 | L11: 0.041 | M11: 0.115 | N11: 0.211 | O11: 0.068 | P11: 0.047 | Q11: 0.076 | R11: 0.135 | S11: 0.05 | T11: 0.05 | U11: 0.044 | V11: 0.191 | W11: 0.073 | X11: 0.039 | Y11: 0.058 | Z11: 0.111 | AA11: 0.067 | AB11: 0.088 | AC11: 0.056 | AD11: 0.197 | AE11: 0.052 | AF11: 0.076 | AG11: 0.048 | AH11: 0.087 | AI11: 0.097 | AJ11: 0.116 | AK11: 0 | AL11: 0.052 | AM11: 0.154 | AN11: 0.046 | AO11: 0.069 | AP11: 0.121 | AQ11: 0.058 | AR11: 0.173 | AS11: 0.062 | AT11: 0.123 | AU11: 0.054 | AV11: 0.067 | AW11: 0.169 | AX11: 0.06 | AY11: 0.049 | AZ11: 0.119 | BA11: 0.034 | BB11: 0.138 | BC11: 0.184 | BD11: 0.245 | BE11: 0.217 | BF11: 0.048 | BG11: 0.047 | BH11: 0.029 | BI11: 0.295 | BJ11: 0.105 | BK11: 0.16 | BL11: 0.047 | BM11: 0 | BN11: 0.21 | BO11: 0.047 | BP11: 0 | BQ11: 0.22 | BR11: 0 | BS11: 0.052 | BT11: 0.038 | BU11: 0.194 | BV11: 0.054 | BW11: 0.106 | BX11: 0.309 | BY11: 0.054 | BZ11: 0.101 | CA11: 0.058 | CB11: 0.235 | CC11: 0.167 | CD11: 0.086 | CE11: 0.157 | CF11: 0.18 | CG11: 0.041 | CH11: 0.199 | CI11: 0.049 | CJ11: 0 | CK11: 0.265 | CL11: 0.231 | CM11: 0.121 | CN11: 0.044 | CO11: 0.061 | CP11: 0.037 | CQ11: 0.166 | CR11: 0.13 | CS11: 0.09
A12: 8 | B12: 3.5 | C12: 0.131 | D12: 0.04 | E12: 0.196 | F12: 0.054 | G12: 0.245 | H12: 0.177 | I12: 0.043 | J12: 0.071 | K12: 0.175 | L12: 0.038 | M12: 0.078 | N12: 0.089 | O12: 0.123 | P12: 0.188 | Q12: 0.083 | R12: 0.252 | S12: 0.047 | T12: 0.193 | U12: 0 | V12: 0.038 | W12: 0.046 | X12: 0.148 | Y12: 0.16 | Z12: 0.078 | AA12: 0.179 | AB12: 0.106 | AC12: 0.255 | AD12: 0.044 | AE12: 0.115 | AF12: 0.292 | AG12: 0.138 | AH12: 0.181 | AI12: 0.1 | AJ12: 0.186 | AK12: 0 | AL12: 0.05 | AM12: 0.118 | AN12: 0.21 | AO12: 0 | AP12: 0.05 | AQ12: 0.2 | AR12: 0.047 | AS12: 0.324 | AT12: 0.268 | AU12: 0.052 | AV12: 0.014 | AW12: 0.043 | AX12: 0.057 | AY12: 0.141 | AZ12: 0.111 | BA12: 0.179 | BB12: 0.174 | BC12: 0.058 | BD12: 0.105 | BE12: 0.07 | BF12: 0.045 | BG12: 0.1 | BH12: 0.026 | BI12: 0 | BJ12: 0.23 | BK12: 0.091 | BL12: 0.046 | BM12: 0 | BN12: 0.214 | BO12: 0.216 | BP12: 0 | BQ12: 0.176 | BR12: 0 | BS12: 0.049 | BT12: 0.036 | BU12: 0.037 | BV12: 0.114 | BW12: 0.238 | BX12: 0.18 | BY12: 0.051 | BZ12: 0.082 | CA12: 0.139 | CB12: 0.169 | CC12: 0.226 | CD12: 0.091 | CE12: 0.138 | CF12: 0.121 | CG12: 0.168 | CH12: 0.048 | CI12: 0.047 | CJ12: 0 | CK12: 0.045 | CL12: 0.185 | CM12: 0.051 | CN12: 0.043 | CO12: 0.047 | CP12: 0.237 | CQ12: 0.048 | CR12: 0.045 | CS12: 0.289
A13: 9 | B13: 4 | C13: 0.096 | D13: 0.162 | E13: 0.179 | F13: 0.007 | G13: 0.036 | H13: 0.03 | I13: 0 | J13: 0.089 | K13: 0.103 | L13: 0.085 | M13: 0.098 | N13: 0.168 | O13: 0.029 | P13: 0.01 | Q13: 0.083 | R13: 0.024 | S13: 0.0003 | T13: 0.158 | U13: 0 | V13: 0.121 | W13: 0 | X13: 0.216 | Y13: 0 | Z13: 0.168 | AA13: 0.035 | AB13: 0.116 | AC13: 0.031 | AD13: 0.095 | AE13: 0.058 | AF13: 0.034 | AG13: 0 | AH13: 0.034 | AI13: 0.151 | AJ13: 0 | AK13: 0 | AL13: 0.027 | AM13: 0 | AN13: 0 | AO13: 0 | AP13: 0.003 | AQ13: 0.034 | AR13: 0.024 | AS13: 0.115 | AT13: 0.149 | AU13: 0.084 | AV13: 0 | AW13: 0.264 | AX13: 0.023 | AY13: 0.012 | AZ13: 0.011 | BA13: 0.014 | BB13: 0.11 | BC13: 0.093 | BD13: 0.195 | BE13: 0.227 | BF13: 0 | BG13: 0.151 | BH13: 0 | BI13: 0 | BJ13: 0.014 | BK13: 0.1 | BL13: 0.028 | BM13: 0 | BN13: 0.071 | BO13: 0.016 | BP13: 0 | BQ13: 0.183 | BR13: 0 | BS13: 0.072 | BT13: 0.108 | BU13: 0.235 | BV13: 0.119 | BW13: 0.154 | BX13: 0.122 | BY13: 0.099 | BZ13: 0 | CA13: 0.098 | CB13: 0.181 | CC13: 0.171 | CD13: 0.003 | CE13: 0.025 | CF13: 0.168 | CG13: 0.053 | CH13: 0.019 | CI13: 0.024 | CJ13: 0 | CK13: 0.164 | CL13: 0.114 | CM13: 0.103 | CN13: 0.025 | CO13: 0.114 | CP13: 0.057 | CQ13: 0.001 | CR13: 0.278 | CS13: 0.018
A14: 10 | B14: 4.5 | C14: 0 | D14: 0 | E14: 0 | F14: 0 | G14: 0 | H14: 0.107 | I14: 0 | J14: 0 | K14: 0 | L14: 0 | M14: 0 | N14: 0 | O14: 0.022 | P14: 0 | Q14: 0 | R14: 0.01 | S14: 0 | T14: 0 | U14: 0 | V14: 0 | W14: 0 | X14: 0 | Y14: 0 | Z14: 0 | AA14: 0.093 | AB14: 0 | AC14: 0 | AD14: 0.041 | AE14: 0 | AF14: 0.073 | AG14: 0 | AH14: 0.124 | AI14: 0 | AJ14: 0 | AK14: 0 | AL14: 0 | AM14: 0 | AN14: 0 | AO14: 0 | AP14: 0 | AQ14: 0.002 | AR14: 0.038 | AS14: 0.012 | AT14: 0.099 | AU14: 0 | AV14: 0 | AW14: 0 | AX14: 0 | AY14: 0 | AZ14: 0.065 | BA14: 0 | BB14: 0 | BC14: 0 | BD14: 0 | BE14: 0 | BF14: 0 | BG14: 0 | BH14: 0 | BI14: 0 | BJ14: 0.078 | BK14: 0 | BL14: 0 | BM14: 0 | BN14: 0.072 | BO14: 0 | BP14: 0 | BQ14: 0 | BR14: 0 | BS14: 0 | BT14: 0 | BU14: 0 | BV14: 0 | BW14: 0 | BX14: 0 | BY14: 0 | BZ14: 0 | CA14: 0 | CB14: 0.045 | CC14: 0 | CD14: 0 | CE14: 0.07 | CF14: 0.013 | CG14: 0 | CH14: 0.046 | CI14: 0 | CJ14: 0 | CK14: 0 | CL14: 0 | CM14: 0 | CN14: 0.069 | CO14: 0 | CP14: 0.049 | CQ14: 0 | CR14: 0 | CS14: 0.081
A15: 11 | B15: 5 | C15: 0 | D15: 0 | E15: 0.032 | F15: 0 | G15: 0 | H15: 0 | I15: 0 | J15: 0 | K15: 0 | L15: 0 | M15: 0 | N15: 0 | O15: 0 | P15: 0 | Q15: 0 | R15: 0 | S15: 0 | T15: 0.047 | U15: 0 | V15: 0 | W15: 0 | X15: 0 | Y15: 0 | Z15: 0 | AA15: 0 | AB15: 0 | AC15: 0 | AD15: 0 | AE15: 0 | AF15: 0 | AG15: 0 | AH15: 0 | AI15: 0 | AJ15: 0 | AK15: 0 | AL15: 0 | AM15: 0 | AN15: 0 | AO15: 0 | AP15: 0 | AQ15: 0 | AR15: 0 | AS15: 0 | AT15: 0 | AU15: 0 | AV15: 0 | AW15: 0 | AX15: 0 | AY15: 0 | AZ15: 0 | BA15: 0 | BB15: 0 | BC15: 0 | BD15: 0 | BE15: 0 | BF15: 0 | BG15: 0 | BH15: 0 | BI15: 0 | BJ15: 0 | BK15: 0 | BL15: 0 | BM15: 0 | BN15: 0 | BO15: 0 | BP15: 0 | BQ15: 0 | BR15: 0 | BS15: 0 | BT15: 0 | BU15: 0 | BV15: 0 | BW15: 0.031 | BX15: 0 | BY15: 0 | BZ15: 0 | CA15: 0 | CB15: 0 | CC15: 0 | CD15: 0 | CE15: 0 | CF15: 0 | CG15: 0 | CH15: 0 | CI15: 0 | CJ15: 0 | CK15: 0 | CL15: 0 | CM15: 0 | CN15: 0 | CO15: 0 | CP15: 0.005 | CQ15: 0 | CR15: 0 | CS15: 0
A16: 12 | B16: 5.5 | C16: 0 | D16: 0 | E16: 0 | F16: 0 | G16: 0 | H16: 0 | I16: 0 | J16: 0 | K16: 0 | L16: 0 | M16: 0 | N16: 0 | O16: 0 | P16: 0 | Q16: 0 | R16: 0 | S16: 0 | T16: 0 | U16: 0 | V16: 0 | W16: 0 | X16: 0 | Y16: 0 | Z16: 0 | AA16: 0 | AB16: 0 | AC16: 0 | AD16: 0 | AE16: 0 | AF16: 0 | AG16: 0 | AH16: 0 | AI16: 0 | AJ16: 0 | AK16: 0 | AL16: 0 | AM16: 0 | AN16: 0 | AO16: 0 | AP16: 0 | AQ16: 0 | AR16: 0 | AS16: 0 | AT16: 0 | AU16: 0 | AV16: 0 | AW16: 0 | AX16: 0 | AY16: 0 | AZ16: 0 | BA16: 0 | BB16: 0 | BC16: 0 | BD16: 0 | BE16: 0 | BF16: 0 | BG16: 0 | BH16: 0 | BI16: 0 | BJ16: 0 | BK16: 0 | BL16: 0 | BM16: 0 | BN16: 0 | BO16: 0 | BP16: 0 | BQ16: 0 | BR16: 0 | BS16: 0 | BT16: 0 | BU16: 0 | BV16: 0 | BW16: 0 | BX16: 0 | BY16: 0 | BZ16: 0 | CA16: 0 | CB16: 0 | CC16: 0 | CD16: 0 | CE16: 0 | CF16: 0 | CG16: 0 | CH16: 0 | CI16: 0 | CJ16: 0 | CK16: 0 | CL16: 0 | CM16: 0 | CN16: 0 | CO16: 0 | CP16: 0 | CQ16: 0 | CR16: 0 | CS16: 0
... A52: 48 | B52: 23.5 | C52: 0.447 | D52: 0.043 | E52: 0.346 | F52: 0.057 | G52: 0.054 | H52: 0.194 | I52: 0.081 | J52: 0.055 | K52: 0 | L52: 0.041 | M52: 0.117 | N52: 0.055 | O52: 0.424 | P52: 0.047 | Q52: 0.054 | R52: 0.343 | S52: 0.05 | T52: 0.328 | U52: 0.486 | V52: 0.041 | W52: 0 | X52: 0.088 | Y52: 0.058 | Z52: 0.478 | AA52: 0.174 | AB52: 0.192 | AC52: 0.129 | AD52: 0.548 | AE52: 0.409 | AF52: 0.32 | AG52: 0.048 | AH52: 0.179 | AI52: 0.151 | AJ52: 0.743 | AK52: 0 | AL52: 0.159 | AM52: 0.162 | AN52: 0.725 | AO52: 0.063 | AP52: 0.321 | AQ52: 0.058 | AR52: 0.068 | AS52: 0.685 | AT52: 0.213 | AU52: 0 | AV52: 0.609 | AW52: 0.164 | AX52: 0.623 | AY52: 0.049 | AZ52: 0.113 | BA52: 0.337 | BB52: 0.207 | BC52: 0.394 | BD52: 0.22 | BE52: 0 | BF52: 0.048 | BG52: 0.047 | BH52: 0.029 | BI52: 0.253 | BJ52: 0.145 | BK52: 0.153 | BL52: 0.347 | BM52: 0.505 | BN52: 0.23 | BO52: 0.047 | BP52: 0.063 | BQ52: 0.055 | BR52: 0.09 | BS52: 0 | BT52: 0.038 | BU52: 0.171 | BV52: 0.151 | BW52: 0.501 | BX52: 0.066 | BY52: 0.743 | BZ52: 0.058 | CA52: 0.046 | CB52: 0 | CC52: 0.193 | CD52: 0.053 | CE52: 0 | CF52: 0.218 | CG52: 0.137 | CH52: 0.05 | CI52: 0.004 | CJ52: 0 | CK52: 0.075 | CL52: 0.235 | CM52: 0.078 | CN52: 0.072 | CO52: 0.088 | CP52: 0.142 | CQ52: 0.117 | CR52: 0.225 | CS52: 0.218

Sheet 7. PV allocation (per period)
A1: TR2 PV allocation — per half-hour
A2: VIOLET = aggregated live from the raw sheets 3–6 (SUM / SUMIF). AMBER = priority split (MIN formulas): PV → prosumer load → battery → customer load → export.
A4: period | B4: hour (h) | C4: PV (kW) | D4: prosumer load (kW) | E4: customer load (kW) | F4: batt charge (kW) | G4: batt discharge (kW) | H4: batt net =chg−dis | I4: PV→ prosumer | J4: PV→ battery | K4: PV→ customer | L4: PV→ export | M4: customer ←grid
A5: 1 | B5: 0 | C5: =SUM('3. Raw PV per load'!C5:C181) | D5: =SUMIF('4. Raw load per load'!$B$5:$B$181,"prosumer",'4. Raw load per load'!C5:C181) | E5: =SUMIF('4. Raw load per load'!$B$5:$B$181,"customer",'4. Raw load per load'!C5:C181) | F5: =SUM('5. Raw batt charge'!C5:CS5) | G5: =SUM('6. Raw batt discharge'!C5:CS5) | H5: =F5-G5 | I5: =MIN(C5,D5) | J5: =MIN(C5-I5,MAX(0,H5)) | K5: =MIN(C5-I5-J5,E5) | L5: =C5-I5-J5-K5 | M5: =E5-K5
A6: 2 | B6: 0.5 | C6: =SUM('3. Raw PV per load'!D5:D181) | D6: =SUMIF('4. Raw load per load'!$B$5:$B$181,"prosumer",'4. Raw load per load'!D5:D181) | E6: =SUMIF('4. Raw load per load'!$B$5:$B$181,"customer",'4. Raw load per load'!D5:D181) | F6: =SUM('5. Raw batt charge'!C6:CS6) | G6: =SUM('6. Raw batt discharge'!C6:CS6) | H6: =F6-G6 | I6: =MIN(C6,D6) | J6: =MIN(C6-I6,MAX(0,H6)) | K6: =MIN(C6-I6-J6,E6) | L6: =C6-I6-J6-K6 | M6: =E6-K6
A7: 3 | B7: 1 | C7: =SUM('3. Raw PV per load'!E5:E181) | D7: =SUMIF('4. Raw load per load'!$B$5:$B$181,"prosumer",'4. Raw load per load'!E5:E181) | E7: =SUMIF('4. Raw load per load'!$B$5:$B$181,"customer",'4. Raw load per load'!E5:E181) | F7: =SUM('5. Raw batt charge'!C7:CS7) | G7: =SUM('6. Raw batt discharge'!C7:CS7) | H7: =F7-G7 | I7: =MIN(C7,D7) | J7: =MIN(C7-I7,MAX(0,H7)) | K7: =MIN(C7-I7-J7,E7) | L7: =C7-I7-J7-K7 | M7: =E7-K7
A8: 4 | B8: 1.5 | C8: =SUM('3. Raw PV per load'!F5:F181) | D8: =SUMIF('4. Raw load per load'!$B$5:$B$181,"prosumer",'4. Raw load per load'!F5:F181) | E8: =SUMIF('4. Raw load per load'!$B$5:$B$181,"customer",'4. Raw load per load'!F5:F181) | F8: =SUM('5. Raw batt charge'!C8:CS8) | G8: =SUM('6. Raw batt discharge'!C8:CS8) | H8: =F8-G8 | I8: =MIN(C8,D8) | J8: =MIN(C8-I8,MAX(0,H8)) | K8: =MIN(C8-I8-J8,E8) | L8: =C8-I8-J8-K8 | M8: =E8-K8
A9: 5 | B9: 2 | C9: =SUM('3. Raw PV per load'!G5:G181) | D9: =SUMIF('4. Raw load per load'!$B$5:$B$181,"prosumer",'4. Raw load per load'!G5:G181) | E9: =SUMIF('4. Raw load per load'!$B$5:$B$181,"customer",'4. Raw load per load'!G5:G181) | F9: =SUM('5. Raw batt charge'!C9:CS9) | G9: =SUM('6. Raw batt discharge'!C9:CS9) | H9: =F9-G9 | I9: =MIN(C9,D9) | J9: =MIN(C9-I9,MAX(0,H9)) | K9: =MIN(C9-I9-J9,E9) | L9: =C9-I9-J9-K9 | M9: =E9-K9
A10: 6 | B10: 2.5 | C10: =SUM('3. Raw PV per load'!H5:H181) | D10: =SUMIF('4. Raw load per load'!$B$5:$B$181,"prosumer",'4. Raw load per load'!H5:H181) | E10: =SUMIF('4. Raw load per load'!$B$5:$B$181,"customer",'4. Raw load per load'!H5:H181) | F10: =SUM('5. Raw batt charge'!C10:CS10) | G10: =SUM('6. Raw batt discharge'!C10:CS10) | H10: =F10-G10 | I10: =MIN(C10,D10) | J10: =MIN(C10-I10,MAX(0,H10)) | K10: =MIN(C10-I10-J10,E10) | L10: =C10-I10-J10-K10 | M10: =E10-K10
A11: 7 | B11: 3 | C11: =SUM('3. Raw PV per load'!I5:I181) | D11: =SUMIF('4. Raw load per load'!$B$5:$B$181,"prosumer",'4. Raw load per load'!I5:I181) | E11: =SUMIF('4. Raw load per load'!$B$5:$B$181,"customer",'4. Raw load per load'!I5:I181) | F11: =SUM('5. Raw batt charge'!C11:CS11) | G11: =SUM('6. Raw batt discharge'!C11:CS11) | H11: =F11-G11 | I11: =MIN(C11,D11) | J11: =MIN(C11-I11,MAX(0,H11)) | K11: =MIN(C11-I11-J11,E11) | L11: =C11-I11-J11-K11 | M11: =E11-K11
A12: 8 | B12: 3.5 | C12: =SUM('3. Raw PV per load'!J5:J181) | D12: =SUMIF('4. Raw load per load'!$B$5:$B$181,"prosumer",'4. Raw load per load'!J5:J181) | E12: =SUMIF('4. Raw load per load'!$B$5:$B$181,"customer",'4. Raw load per load'!J5:J181) | F12: =SUM('5. Raw batt charge'!C12:CS12) | G12: =SUM('6. Raw batt discharge'!C12:CS12) | H12: =F12-G12 | I12: =MIN(C12,D12) | J12: =MIN(C12-I12,MAX(0,H12)) | K12: =MIN(C12-I12-J12,E12) | L12: =C12-I12-J12-K12 | M12: =E12-K12
A13: 9 | B13: 4 | C13: =SUM('3. Raw PV per load'!K5:K181) | D13: =SUMIF('4. Raw load per load'!$B$5:$B$181,"prosumer",'4. Raw load per load'!K5:K181) | E13: =SUMIF('4. Raw load per load'!$B$5:$B$181,"customer",'4. Raw load per load'!K5:K181) | F13: =SUM('5. Raw batt charge'!C13:CS13) | G13: =SUM('6. Raw batt discharge'!C13:CS13) | H13: =F13-G13 | I13: =MIN(C13,D13) | J13: =MIN(C13-I13,MAX(0,H13)) | K13: =MIN(C13-I13-J13,E13) | L13: =C13-I13-J13-K13 | M13: =E13-K13
