Workbook

Sheet 1. Overview
B2: TR9 — Where does the PV energy go?
B3: Prosumers vs. pure customers — every kWh traced from the raw model inputs
B5: Purpose
B6: This workbook accounts for every kWh of PV generated on transformer TR9 over one representative day, and it is fully auditable: nothing is hand-typed except the raw model outputs. Follow the data chain below — each step is a live formula, so changing any raw number updates everything.
B10: The data chain (how each number is built)
B11: Sheet 3 · Raw PV per load | C11: The PV profile of every connection, 48 half-hours. Copied verbatim from TR9_load_PV_48periods.xlsx (sheet PV_generation_kW). Customers = 0.
B12: Sheet 4 · Raw load per load | C12: The load profile of every connection, 48 half-hours, tagged prosumer / customer. Copied from TR9_load_PV_48periods.xlsx (sheet Load_P_kW).
B13: Sheet 5 · Raw batt charge | C13: Charging power of every battery, 48 half-hours. Copied from the rolling dispatch TR9_analysis_data.xlsx (sheet Charge_kW).
B14: Sheet 6 · Raw batt discharge | C14: Discharging power of every battery. Copied from the same run (Discharge_kW).
B15: Sheet 7 · PV allocation | C15: Per half-hour: the five blue inputs are AGGREGATED from sheets 3–6 by SUM / SUMIF; the amber columns then split the PV by the priority rule.
B16: Sheets 1 & 8 · Results | C16: Daily totals (Σ×0.5 h) and shares. Every headline cell links to sheet 7.
B18: The aggregation formulas (sheet 7, per half-hour)
B19: PV (all)
B20: prosumer load
B21: customer load
B22: battery charge
B23: battery discharge
B25: Headline results (all linked live to sheet 7)
B26: Quantity | C26: Value | D26: Unit
B27: Prosumers (PV + battery) | C27: 90 | D27: connections
B28: Pure customers (load only) | C28: 82 | D28: connections
B29: PV generated | C29: ='7. PV allocation (per period)'!C53 -> 2241.1862 | D29: kWh/day
B30: PV → prosumers' own load (direct) | C30: ='7. PV allocation (per period)'!I53 -> 399.9009 | D30: kWh/day
B31: PV → battery storage | C31: ='7. PV allocation (per period)'!J53 -> 306.73605 | D31: kWh/day
B32: PV → customers | C32: ='7. PV allocation (per period)'!K53 -> 319.0854 | D32: kWh/day
B33: PV → export to grid | C33: ='7. PV allocation (per period)'!L53 -> 1215.4639 | D33: kWh/day
B34: PV share reaching customers | C34: ='7. PV allocation (per period)'!K53/'7. PV allocation (per period)'!C53 -> 0.14237344 | D34: % of PV
B35: Customer load covered by PV | C35: ='7. PV allocation (per period)'!K53/'7. PV allocation (per period)'!E53 -> 0.52734633 | D35: % of customer load
B36: Customer load covered by grid | C36: ='7. PV allocation (per period)'!M53/'7. PV allocation (per period)'!E53 -> 0.47265367 | D36: % of customer load
B39: Colour key & provenance
B40: • LIGHT-BLUE cell = data belonging to a prosumer (its rooftop PV, load, or battery). WHITE = a pure customer (load only). On sheet 7: VIOLET = value aggregated live from the raw sheets (SUM/SUMIF); AMBER = allocation formula; GREEN = daily total (Σ × 0.5 h).
B41: • Per-load PV & load profiles: results/tables/TR9_load_PV_48periods.xlsx (built from OpData.xls).
B42: • Per-battery charge/discharge: TR9_analysis/01_DAILY_ROLLING_DISPATCH/TR9_analysis_data.xlsx (exact-QCP rolling dispatch, RunFOR_Rolling, CPLEX).
B43: • Load classification (PV size > 0 = prosumer): sheet 'Customers' of the load/PV workbook.
B44: • Method note: priority energy allocation per half-hour; downstream network + battery round-trip losses (~3–4% of PV) are not separated out in the per-period disposition.

Sheet 2. Load classification
A1: TR9 load classification — 172 connections
A2: 90 prosumers (PV + battery) · 82 pure customers (load only)
A4: ID | B4: Load name | C4: Bus | D4: Phase | E4: PV size (kW) | F4: Type
A5: 2259 | B5: Load_TR9_F2_1 | C5: TR9_two130 | D5: 3 | E5: 0 | F5: customer
A6: 2260 | B6: Load_TR9_F2_10 | C6: TR9_two249 | D6: 1 | E6: 0 | F6: customer
A7: 2263 | B7: Load_TR9_F2_13 | C7: TR9_two283 | D7: 2 | E7: 0 | F7: customer
A8: 2270 | B8: Load_TR9_F2_2 | C8: TR9_two137 | D8: 2 | E8: 0 | F8: customer
A9: 2273 | B9: Load_TR9_F2_3 | C9: TR9_two149 | D9: 2 | E9: 0 | F9: customer
A10: 2274 | B10: Load_TR9_F2_4 | C10: TR9_two217 | D10: 1 | E10: 0 | F10: customer
A11: 2276 | B11: Load_TR9_F2_6 | C11: TR9_two229 | D11: 1 | E11: 0 | F11: customer
A12: 2278 | B12: Load_TR9_F2_8 | C12: TR9_two238 | D12: 3 | E12: 0 | F12: customer
A13: 2279 | B13: Load_TR9_F2_9 | C13: TR9_two242 | D13: 2 | E13: 0 | F13: customer
A14: 2280 | B14: Load_TR9_F5_1 | C14: TR9_five58 | D14: 3 | E14: 0 | F14: customer
A15: 2284 | B15: Load_TR9_F5_13 | C15: TR9_five168 | D15: 1 | E15: 0 | F15: customer
A16: 2287 | B16: Load_TR9_F5_16 | C16: TR9_five186 | D16: 3 | E16: 0 | F16: customer
... A176: 2430 | B176: Load_TR9_F6_9 | C176: TR9_six128 | D176: 2 | E176: 4 | F176: prosumer

Sheet 3. Raw PV per load
A1: Raw PV per load
A2: Verbatim copy of PV_generation_kW (TR9_load_PV_48periods.xlsx). One row per connection, 48 half-hours (kW).
A4: Load name | B4: Type | C4: p1 | D4: p2 | E4: p3 | F4: p4 | G4: p5 | H4: p6 | I4: p7 | J4: p8 | K4: p9 | L4: p10 | M4: p11 | N4: p12 | O4: p13 | P4: p14 | Q4: p15 | R4: p16 | S4: p17 | T4: p18 | U4: p19 | V4: p20 | W4: p21 | X4: p22 | Y4: p23 | Z4: p24 | AA4: p25 | AB4: p26 | AC4: p27 | AD4: p28 | AE4: p29 | AF4: p30 | AG4: p31 | AH4: p32 | AI4: p33 | AJ4: p34 | AK4: p35 | AL4: p36 | AM4: p37 | AN4: p38 | AO4: p39 | AP4: p40 | AQ4: p41 | AR4: p42 | AS4: p43 | AT4: p44 | AU4: p45 | AV4: p46 | AW4: p47 | AX4: p48
A5: Load_TR9_F2_1 | B5: customer | C5: 0 | D5: 0 | E5: 0 | F5: 0 | G5: 0 | H5: 0 | I5: 0 | J5: 0 | K5: 0 | L5: 0 | M5: 0 | N5: 0 | O5: 0 | P5: 0 | Q5: 0 | R5: 0 | S5: 0 | T5: 0 | U5: 0 | V5: 0 | W5: 0 | X5: 0 | Y5: 0 | Z5: 0 | AA5: 0 | AB5: 0 | AC5: 0 | AD5: 0 | AE5: 0 | AF5: 0 | AG5: 0 | AH5: 0 | AI5: 0 | AJ5: 0 | AK5: 0 | AL5: 0 | AM5: 0 | AN5: 0 | AO5: 0 | AP5: 0 | AQ5: 0 | AR5: 0 | AS5: 0 | AT5: 0 | AU5: 0 | AV5: 0 | AW5: 0 | AX5: 0
A6: Load_TR9_F2_10 | B6: customer | C6: 0 | D6: 0 | E6: 0 | F6: 0 | G6: 0 | H6: 0 | I6: 0 | J6: 0 | K6: 0 | L6: 0 | M6: 0 | N6: 0 | O6: 0 | P6: 0 | Q6: 0 | R6: 0 | S6: 0 | T6: 0 | U6: 0 | V6: 0 | W6: 0 | X6: 0 | Y6: 0 | Z6: 0 | AA6: 0 | AB6: 0 | AC6: 0 | AD6: 0 | AE6: 0 | AF6: 0 | AG6: 0 | AH6: 0 | AI6: 0 | AJ6: 0 | AK6: 0 | AL6: 0 | AM6: 0 | AN6: 0 | AO6: 0 | AP6: 0 | AQ6: 0 | AR6: 0 | AS6: 0 | AT6: 0 | AU6: 0 | AV6: 0 | AW6: 0 | AX6: 0
A7: Load_TR9_F2_11 | B7: prosumer | C7: 0 | D7: 0 | E7: 0 | F7: 0 | G7: 0 | H7: 0 | I7: 0 | J7: 0.0026 | K7: 0.0373 | L7: 0.1744 | M7: 0.346 | N7: 0.5564 | O7: 0.7859 | P7: 1.0183 | Q7: 1.2495 | R7: 1.481 | S7: 1.6982 | T7: 1.9025 | U7: 2.0764 | V7: 2.2248 | W7: 2.355 | X7: 2.4625 | Y7: 2.5387 | Z7: 2.5722 | AA7: 2.5819 | AB7: 2.5637 | AC7: 2.5029 | AD7: 2.41 | AE7: 2.2991 | AF7: 2.1586 | AG7: 2.0093 | AH7: 1.8297 | AI7: 1.6274 | AJ7: 1.3831 | AK7: 1.1544 | AL7: 0.9195 | AM7: 0.6922 | AN7: 0.4731 | AO7: 0.2762 | AP7: 0.0804 | AQ7: 0.0148 | AR7: 0 | AS7: 0 | AT7: 0 | AU7: 0 | AV7: 0 | AW7: 0 | AX7: 0
A8: Load_TR9_F2_12 | B8: prosumer | C8: 0 | D8: 0 | E8: 0 | F8: 0 | G8: 0 | H8: 0 | I8: 0 | J8: 0.0034 | K8: 0.0497 | L8: 0.2326 | M8: 0.4613 | N8: 0.7419 | O8: 1.0479 | P8: 1.3577 | Q8: 1.666 | R8: 1.9746 | S8: 2.2643 | T8: 2.5367 | U8: 2.7686 | V8: 2.9664 | W8: 3.14 | X8: 3.2833 | Y8: 3.385 | Z8: 3.4296 | AA8: 3.4425 | AB8: 3.4183 | AC8: 3.3372 | AD8: 3.2133 | AE8: 3.0655 | AF8: 2.8782 | AG8: 2.6791 | AH8: 2.4396 | AI8: 2.1698 | AJ8: 1.8441 | AK8: 1.5392 | AL8: 1.2259 | AM8: 0.9229 | AN8: 0.6308 | AO8: 0.3683 | AP8: 0.1072 | AQ8: 0.0198 | AR8: 0 | AS8: 0 | AT8: 0 | AU8: 0 | AV8: 0 | AW8: 0 | AX8: 0
A9: Load_TR9_F2_13 | B9: customer | C9: 0 | D9: 0 | E9: 0 | F9: 0 | G9: 0 | H9: 0 | I9: 0 | J9: 0 | K9: 0 | L9: 0 | M9: 0 | N9: 0 | O9: 0 | P9: 0 | Q9: 0 | R9: 0 | S9: 0 | T9: 0 | U9: 0 | V9: 0 | W9: 0 | X9: 0 | Y9: 0 | Z9: 0 | AA9: 0 | AB9: 0 | AC9: 0 | AD9: 0 | AE9: 0 | AF9: 0 | AG9: 0 | AH9: 0 | AI9: 0 | AJ9: 0 | AK9: 0 | AL9: 0 | AM9: 0 | AN9: 0 | AO9: 0 | AP9: 0 | AQ9: 0 | AR9: 0 | AS9: 0 | AT9: 0 | AU9: 0 | AV9: 0 | AW9: 0 | AX9: 0
A10: Load_TR9_F2_14 | B10: prosumer | C10: 0 | D10: 0 | E10: 0 | F10: 0 | G10: 0 | H10: 0 | I10: 0 | J10: 0.0034 | K10: 0.0497 | L10: 0.2326 | M10: 0.4613 | N10: 0.7419 | O10: 1.0479 | P10: 1.3577 | Q10: 1.666 | R10: 1.9746 | S10: 2.2643 | T10: 2.5367 | U10: 2.7686 | V10: 2.9664 | W10: 3.14 | X10: 3.2833 | Y10: 3.385 | Z10: 3.4296 | AA10: 3.4425 | AB10: 3.4183 | AC10: 3.3372 | AD10: 3.2133 | AE10: 3.0655 | AF10: 2.8782 | AG10: 2.6791 | AH10: 2.4396 | AI10: 2.1698 | AJ10: 1.8441 | AK10: 1.5392 | AL10: 1.2259 | AM10: 0.9229 | AN10: 0.6308 | AO10: 0.3683 | AP10: 0.1072 | AQ10: 0.0198 | AR10: 0 | AS10: 0 | AT10: 0 | AU10: 0 | AV10: 0 | AW10: 0 | AX10: 0
A11: Load_TR9_F2_15 | B11: prosumer | C11: 0 | D11: 0 | E11: 0 | F11: 0 | G11: 0 | H11: 0 | I11: 0 | J11: 0.0034 | K11: 0.0497 | L11: 0.2326 | M11: 0.4613 | N11: 0.7419 | O11: 1.0479 | P11: 1.3577 | Q11: 1.666 | R11: 1.9746 | S11: 2.2643 | T11: 2.5367 | U11: 2.7686 | V11: 2.9664 | W11: 3.14 | X11: 3.2833 | Y11: 3.385 | Z11: 3.4296 | AA11: 3.4425 | AB11: 3.4183 | AC11: 3.3372 | AD11: 3.2133 | AE11: 3.0655 | AF11: 2.8782 | AG11: 2.6791 | AH11: 2.4396 | AI11: 2.1698 | AJ11: 1.8441 | AK11: 1.5392 | AL11: 1.2259 | AM11: 0.9229 | AN11: 0.6308 | AO11: 0.3683 | AP11: 0.1072 | AQ11: 0.0198 | AR11: 0 | AS11: 0 | AT11: 0 | AU11: 0 | AV11: 0 | AW11: 0 | AX11: 0
A12: Load_TR9_F2_16 | B12: prosumer | C12: 0 | D12: 0 | E12: 0 | F12: 0 | G12: 0 | H12: 0 | I12: 0 | J12: 0.0034 | K12: 0.0497 | L12: 0.2326 | M12: 0.4613 | N12: 0.7419 | O12: 1.0479 | P12: 1.3577 | Q12: 1.666 | R12: 1.9746 | S12: 2.2643 | T12: 2.5367 | U12: 2.7686 | V12: 2.9664 | W12: 3.14 | X12: 3.2833 | Y12: 3.385 | Z12: 3.4296 | AA12: 3.4425 | AB12: 3.4183 | AC12: 3.3372 | AD12: 3.2133 | AE12: 3.0655 | AF12: 2.8782 | AG12: 2.6791 | AH12: 2.4396 | AI12: 2.1698 | AJ12: 1.8441 | AK12: 1.5392 | AL12: 1.2259 | AM12: 0.9229 | AN12: 0.6308 | AO12: 0.3683 | AP12: 0.1072 | AQ12: 0.0198 | AR12: 0 | AS12: 0 | AT12: 0 | AU12: 0 | AV12: 0 | AW12: 0 | AX12: 0
A13: Load_TR9_F2_17 | B13: prosumer | C13: 0 | D13: 0 | E13: 0 | F13: 0 | G13: 0 | H13: 0 | I13: 0 | J13: 0.003 | K13: 0.0435 | L13: 0.2035 | M13: 0.4037 | N13: 0.6491 | O13: 0.9169 | P13: 1.188 | Q13: 1.4577 | R13: 1.7278 | S13: 1.9813 | T13: 2.2196 | U13: 2.4225 | V13: 2.5956 | W13: 2.7475 | X13: 2.8729 | Y13: 2.9619 | Z13: 3.0009 | AA13: 3.0122 | AB13: 2.991 | AC13: 2.92 | AD13: 2.8117 | AE13: 2.6823 | AF13: 2.5184 | AG13: 2.3442 | AH13: 2.1346 | AI13: 1.8986 | AJ13: 1.6136 | AK13: 1.3468 | AL13: 1.0727 | AM13: 0.8076 | AN13: 0.5519 | AO13: 0.3223 | AP13: 0.0938 | AQ13: 0.0173 | AR13: 0 | AS13: 0 | AT13: 0 | AU13: 0 | AV13: 0 | AW13: 0 | AX13: 0
A14: Load_TR9_F2_18 | B14: prosumer | C14: 0 | D14: 0 | E14: 0 | F14: 0 | G14: 0 | H14: 0 | I14: 0 | J14: 0.0034 | K14: 0.0497 | L14: 0.2326 | M14: 0.4613 | N14: 0.7419 | O14: 1.0479 | P14: 1.3577 | Q14: 1.666 | R14: 1.9746 | S14: 2.2643 | T14: 2.5367 | U14: 2.7686 | V14: 2.9664 | W14: 3.14 | X14: 3.2833 | Y14: 3.385 | Z14: 3.4296 | AA14: 3.4425 | AB14: 3.4183 | AC14: 3.3372 | AD14: 3.2133 | AE14: 3.0655 | AF14: 2.8782 | AG14: 2.6791 | AH14: 2.4396 | AI14: 2.1698 | AJ14: 1.8441 | AK14: 1.5392 | AL14: 1.2259 | AM14: 0.9229 | AN14: 0.6308 | AO14: 0.3683 | AP14: 0.1072 | AQ14: 0.0198 | AR14: 0 | AS14: 0 | AT14: 0 | AU14: 0 | AV14: 0 | AW14: 0 | AX14: 0
A15: Load_TR9_F2_19 | B15: prosumer | C15: 0 | D15: 0 | E15: 0 | F15: 0 | G15: 0 | H15: 0 | I15: 0 | J15: 0.003 | K15: 0.0435 | L15: 0.2035 | M15: 0.4037 | N15: 0.6491 | O15: 0.9169 | P15: 1.188 | Q15: 1.4577 | R15: 1.7278 | S15: 1.9813 | T15: 2.2196 | U15: 2.4225 | V15: 2.5956 | W15: 2.7475 | X15: 2.8729 | Y15: 2.9619 | Z15: 3.0009 | AA15: 3.0122 | AB15: 2.991 | AC15: 2.92 | AD15: 2.8117 | AE15: 2.6823 | AF15: 2.5184 | AG15: 2.3442 | AH15: 2.1346 | AI15: 1.8986 | AJ15: 1.6136 | AK15: 1.3468 | AL15: 1.0727 | AM15: 0.8076 | AN15: 0.5519 | AO15: 0.3223 | AP15: 0.0938 | AQ15: 0.0173 | AR15: 0 | AS15: 0 | AT15: 0 | AU15: 0 | AV15: 0 | AW15: 0 | AX15: 0
A16: Load_TR9_F2_2 | B16: customer | C16: 0 | D16: 0 | E16: 0 | F16: 0 | G16: 0 | H16: 0 | I16: 0 | J16: 0 | K16: 0 | L16: 0 | M16: 0 | N16: 0 | O16: 0 | P16: 0 | Q16: 0 | R16: 0 | S16: 0 | T16: 0 | U16: 0 | V16: 0 | W16: 0 | X16: 0 | Y16: 0 | Z16: 0 | AA16: 0 | AB16: 0 | AC16: 0 | AD16: 0 | AE16: 0 | AF16: 0 | AG16: 0 | AH16: 0 | AI16: 0 | AJ16: 0 | AK16: 0 | AL16: 0 | AM16: 0 | AN16: 0 | AO16: 0 | AP16: 0 | AQ16: 0 | AR16: 0 | AS16: 0 | AT16: 0 | AU16: 0 | AV16: 0 | AW16: 0 | AX16: 0
... A176: Load_TR9_F6_9 | B176: prosumer | C176: 0 | D176: 0 | E176: 0 | F176: 0 | G176: 0 | H176: 0 | I176: 0 | J176: 0.0034 | K176: 0.0497 | L176: 0.2326 | M176: 0.4613 | N176: 0.7419 | O176: 1.0479 | P176: 1.3577 | Q176: 1.666 | R176: 1.9746 | S176: 2.2643 | T176: 2.5367 | U176: 2.7686 | V176: 2.9664 | W176: 3.14 | X176: 3.2833 | Y176: 3.385 | Z176: 3.4296 | AA176: 3.4425 | AB176: 3.4183 | AC176: 3.3372 | AD176: 3.2133 | AE176: 3.0655 | AF176: 2.8782 | AG176: 2.6791 | AH176: 2.4396 | AI176: 2.1698 | AJ176: 1.8441 | AK176: 1.5392 | AL176: 1.2259 | AM176: 0.9229 | AN176: 0.6308 | AO176: 0.3683 | AP176: 0.1072 | AQ176: 0.0198 | AR176: 0 | AS176: 0 | AT176: 0 | AU176: 0 | AV176: 0 | AW176: 0 | AX176: 0

Sheet 4. Raw load per load
A1: Raw load per load
A2: Verbatim copy of Load_P_kW (TR9_load_PV_48periods.xlsx), tagged by type. One row per connection, 48 half-hours (kW).
A4: Load name | B4: Type | C4: p1 | D4: p2 | E4: p3 | F4: p4 | G4: p5 | H4: p6 | I4: p7 | J4: p8 | K4: p9 | L4: p10 | M4: p11 | N4: p12 | O4: p13 | P4: p14 | Q4: p15 | R4: p16 | S4: p17 | T4: p18 | U4: p19 | V4: p20 | W4: p21 | X4: p22 | Y4: p23 | Z4: p24 | AA4: p25 | AB4: p26 | AC4: p27 | AD4: p28 | AE4: p29 | AF4: p30 | AG4: p31 | AH4: p32 | AI4: p33 | AJ4: p34 | AK4: p35 | AL4: p36 | AM4: p37 | AN4: p38 | AO4: p39 | AP4: p40 | AQ4: p41 | AR4: p42 | AS4: p43 | AT4: p44 | AU4: p45 | AV4: p46 | AW4: p47 | AX4: p48
A5: Load_TR9_F2_1 | B5: customer | C5: 0.116 | D5: 0.1435 | E5: 0.054 | F5: 0.1573 | G5: 0.1022 | H5: 0.054 | I5: 0.054 | J5: 0.116 | K5: 0.1435 | L5: 0.054 | M5: 0.0747 | N5: 0.1848 | O5: 0.054 | P5: 0.1917 | Q5: 0.0678 | R5: 0.054 | S5: 0.054 | T5: 0.1435 | U5: 2.0585 | V5: 0.6477 | W5: 0.101 | X5: 0.2546 | Y5: 0.188 | Z5: 0.3354 | AA5: 0.413 | AB5: 0.054 | AC5: 0.1642 | AD5: 0.0953 | AE5: 0.054 | AF5: 0.2055 | AG5: 0.054 | AH5: 0.054 | AI5: 0.216 | AJ5: 0.1039 | AK5: 0.3041 | AL5: 0.054 | AM5: 0.1229 | AN5: 0.4397 | AO5: 0.3222 | AP5: 0.5606 | AQ5: 0.4578 | AR5: 1.3998 | AS5: 0.4976 | AT5: 0.3628 | AU5: 0.5337 | AV5: 0.284 | AW5: 0.4844 | AX5: 0.1515
A6: Load_TR9_F2_10 | B6: customer | C6: 0.1295 | D6: 0.0823 | E6: 0.1106 | F6: 0.1012 | G6: 0.0917 | H6: 0.054 | I6: 0.087 | J6: 0.1059 | K6: 0.054 | L6: 0.054 | M6: 0.054 | N6: 0.0634 | O6: 0.1295 | P6: 0.054 | Q6: 0.1698 | R6: 2.0509 | S6: 1.8305 | T6: 1.1694 | U6: 0.4114 | V6: 1.3354 | W6: 0.054 | X6: 0.054 | Y6: 0.054 | Z6: 0.1579 | AA6: 0.054 | AB6: 0.1389 | AC6: 0.054 | AD6: 0.1389 | AE6: 0.054 | AF6: 0.1648 | AG6: 0.376 | AH6: 0.1453 | AI6: 0.0864 | AJ6: 0.4269 | AK6: 0.4964 | AL6: 0.0666 | AM6: 0.2591 | AN6: 0.2307 | AO6: 0.2955 | AP6: 0.054 | AQ6: 0.054 | AR6: 0.054 | AS6: 0.3601 | AT6: 0.4062 | AU6: 0.4366 | AV6: 0.445 | AW6: 0.2895 | AX6: 0.1248
A7: Load_TR9_F2_11 | B7: prosumer | C7: 0.048 | D7: 0.1005 | E7: 0.3037 | F7: 0.0769 | G7: 0.1203 | H7: 0.269 | I7: 0.1062 | J7: 0.2394 | K7: 0.1792 | L7: 0.048 | M7: 0.2621 | N7: 0.3604 | O7: 0.2161 | P7: 1.5606 | Q7: 0.2934 | R7: 1.4221 | S7: 0.5454 | T7: 0.3273 | U7: 0.5762 | V7: 0.5385 | W7: 0.2503 | X7: 0.3974 | Y7: 0.0572 | Z7: 0.048 | AA7: 0.3147 | AB7: 0.5124 | AC7: 0.048 | AD7: 0.2838 | AE7: 0.1493 | AF7: 0.048 | AG7: 0.3634 | AH7: 0.0697 | AI7: 0.048 | AJ7: 0.1615 | AK7: 0.3194 | AL7: 0.0943 | AM7: 1.3534 | AN7: 0.2009 | AO7: 0.3023 | AP7: 0.5735 | AQ7: 0.2367 | AR7: 0.4093 | AS7: 0.5228 | AT7: 1.2307 | AU7: 0.6806 | AV7: 0.7499 | AW7: 0.5675 | AX7: 0.5005
A8: Load_TR9_F2_12 | B8: prosumer | C8: 0.049 | D8: 0.049 | E8: 0.049 | F8: 0.049 | G8: 0.049 | H8: 0.049 | I8: 0.049 | J8: 0.049 | K8: 0.049 | L8: 0.049 | M8: 0.049 | N8: 0.049 | O8: 0.049 | P8: 0.049 | Q8: 0.1063 | R8: 0.1116 | S8: 0.1449 | T8: 1.0046 | U8: 0.1016 | V8: 0.0924 | W8: 0.0736 | X8: 0.049 | Y8: 0.0716 | Z8: 0.1202 | AA8: 0.1803 | AB8: 0.1701 | AC8: 0.9349 | AD8: 0.2773 | AE8: 0.4947 | AF8: 0.133 | AG8: 0.049 | AH8: 0.5026 | AI8: 1.3947 | AJ8: 0.4174 | AK8: 0.1025 | AL8: 0.4385 | AM8: 0.2115 | AN8: 0.3798 | AO8: 0.049 | AP8: 0.049 | AQ8: 0.049 | AR8: 0.049 | AS8: 0.049 | AT8: 0.049 | AU8: 0.049 | AV8: 0.049 | AW8: 0.3964 | AX8: 0.1651
A9: Load_TR9_F2_13 | B9: customer | C9: 0.384 | D9: 0.054 | E9: 0.3461 | F9: 0.0739 | G9: 0.3415 | H9: 0.1144 | I9: 0.3091 | J9: 0.1827 | K9: 0.1592 | L9: 0.1598 | M9: 0.2388 | N9: 0.1618 | O9: 0.2782 | P9: 0.1879 | Q9: 0.26 | R9: 0.1622 | S9: 0.1635 | T9: 0.2891 | U9: 0.3101 | V9: 0.3613 | W9: 0.447 | X9: 2.2095 | Y9: 2.5968 | Z9: 1.951 | AA9: 0.209 | AB9: 0.2639 | AC9: 0.2398 | AD9: 1.1335 | AE9: 0.6056 | AF9: 0.3996 | AG9: 0.246 | AH9: 0.1427 | AI9: 0.1418 | AJ9: 0.7082 | AK9: 0.706 | AL9: 0.7192 | AM9: 0.8493 | AN9: 0.4953 | AO9: 0.7129 | AP9: 0.3661 | AQ9: 0.2241 | AR9: 0.1353 | AS9: 0.2887 | AT9: 0.0849 | AU9: 0.2096 | AV9: 0.054 | AW9: 0.4059 | AX9: 0.066
A10: Load_TR9_F2_14 | B10: prosumer | C10: 0.054 | D10: 0.2155 | E10: 0.0583 | F10: 0.054 | G10: 0.1315 | H10: 0.1423 | I10: 0.054 | J10: 0.054 | K10: 0.1423 | L10: 0.1185 | M10: 0.0985 | N10: 0.1323 | O10: 0.1099 | P10: 0.054 | Q10: 0.1423 | R10: 0.054 | S10: 0.1315 | T10: 0.1942 | U10: 1.6659 | V10: 1.4541 | W10: 1.1433 | X10: 0.1974 | Y10: 0.2347 | Z10: 0.6195 | AA10: 0.5548 | AB10: 0.7274 | AC10: 0.4009 | AD10: 0.1089 | AE10: 0.1653 | AF10: 0.1021 | AG10: 0.302 | AH10: 0.7193 | AI10: 0.1569 | AJ10: 0.144 | AK10: 0.2498 | AL10: 0.054 | AM10: 0.2855 | AN10: 0.054 | AO10: 0.1423 | AP10: 0.1315 | AQ10: 0.0729 | AR10: 0.2008 | AS10: 0.0583 | AT10: 0.3604 | AU10: 0.4995 | AV10: 0.436 | AW10: 0.5956 | AX10: 0.7427
A11: Load_TR9_F2_15 | B11: prosumer | C11: 0.1166 | D11: 0.0852 | E11: 0.0544 | F11: 0.2229 | G11: 0.067 | H11: 0.1005 | I11: 0.046 | J11: 0.1558 | K11: 0.1214 | L11: 0.046 | M11: 0.1558 | N11: 0.046 | O11: 0.2312 | P11: 0.046 | Q11: 0.1763 | R11: 0.1009 | S11: 0.046 | T11: 0.1214 | U11: 0.046 | V11: 0.2312 | W11: 0.0604 | X11: 0.1989 | Y11: 0.0623 | Z11: 0.124 | AA11: 0.1558 | AB11: 0.046 | AC11: 0.046 | AD11: 0.2312 | AE11: 1.849 | AF11: 0.191 | AG11: 0.4265 | AH11: 0.1383 | AI11: 0.2033 | AJ11: 0.1474 | AK11: 0.4352 | AL11: 0.1387 | AM11: 0.1366 | AN11: 0.0931 | AO11: 0.0921 | AP11: 0.1851 | AQ11: 0.1005 | AR11: 0.1781 | AS11: 0.1206 | AT11: 0.2679 | AU11: 0.4704 | AV11: 0.107 | AW11: 0.1692 | AX11: 0.601
A12: Load_TR9_F2_16 | B12: prosumer | C12: 0.5774 | D12: 0.4897 | E12: 0.2732 | F12: 0.0848 | G12: 0.2881 | H12: 0.1433 | I12: 0.1995 | J12: 0.2392 | K12: 0.042 | L12: 0.2687 | M12: 0.17 | N12: 0.042 | O12: 0.1823 | P12: 0.2564 | Q12: 0.2729 | R12: 0.2576 | S12: 0.3535 | T12: 0.489 | U12: 0.0572 | V12: 0.2406 | W12: 0.3179 | X12: 0.4507 | Y12: 0.4016 | Z12: 1.0075 | AA12: 3.0598 | AB12: 1.9052 | AC12: 0.4365 | AD12: 0.335 | AE12: 0.1935 | AF12: 0.3789 | AG12: 0.1551 | AH12: 0.302 | AI12: 0.3234 | AJ12: 1.2339 | AK12: 1.1878 | AL12: 1.8042 | AM12: 0.3548 | AN12: 0.5796 | AO12: 0.5944 | AP12: 0.7312 | AQ12: 0.9048 | AR12: 1.0234 | AS12: 0.6867 | AT12: 0.6497 | AU12: 0.1805 | AV12: 0.1955 | AW12: 0.2362 | AX12: 0.413
A13: Load_TR9_F2_17 | B13: prosumer | C13: 0.5937 | D13: 0.5725 | E13: 0.5629 | F13: 0.058 | G13: 0.2905 | H13: 0.13 | I13: 0.1013 | J13: 0.3193 | K13: 0.058 | L13: 0.21 | M13: 0.2105 | N13: 0.146 | O13: 0.1781 | P13: 0.1544 | Q13: 0.058 | R13: 0.3626 | S13: 1.9124 | T13: 0.3362 | U13: 0.2499 | V13: 0.295 | W13: 0.066 | X13: 0.3546 | Y13: 0.058 | Z13: 0.135 | AA13: 0.2856 | AB13: 0.058 | AC13: 0.3417 | AD13: 0.1236 | AE13: 0.2912 | AF13: 0.3686 | AG13: 0.1963 | AH13: 0.4052 | AI13: 0.2604 | AJ13: 0.3942 | AK13: 0.2771 | AL13: 0.2002 | AM13: 0.138 | AN13: 0.6411 | AO13: 1.6412 | AP13: 0.4917 | AQ13: 0.5626 | AR13: 0.6514 | AS13: 0.4957 | AT13: 0.17 | AU13: 0.058 | AV13: 0.2726 | AW13: 0.148 | AX13: 0.058
A14: Load_TR9_F2_18 | B14: prosumer | C14: 0.045 | D14: 0.1388 | E14: 0.045 | F14: 0.1388 | G14: 0.045 | H14: 0.1388 | I14: 0.045 | J14: 0.045 | K14: 0.1388 | L14: 0.045 | M14: 0.1388 | N14: 0.045 | O14: 0.1013 | P14: 0.0825 | Q14: 0.045 | R14: 0.0563 | S14: 0.1013 | T14: 0.2916 | U14: 2.0625 | V14: 0.8015 | W14: 1.0392 | X14: 0.5931 | Y14: 0.1832 | Z14: 1.1805 | AA14: 0.4183 | AB14: 0.1354 | AC14: 0.202 | AD14: 0.0892 | AE14: 0.0988 | AF14: 0.1668 | AG14: 0.0591 | AH14: 0.1247 | AI14: 0.045 | AJ14: 0.0825 | AK14: 0.1013 | AL14: 0.1005 | AM14: 0.1478 | AN14: 0.0753 | AO14: 0.2416 | AP14: 0.2031 | AQ14: 0.3022 | AR14: 0.3942 | AS14: 0.5067 | AT14: 0.4655 | AU14: 0.4839 | AV14: 0.5486 | AW14: 0.4088 | AX14: 1.1005
A15: Load_TR9_F2_19 | B15: prosumer | C15: 0.211 | D15: 0.046 | E15: 0.3164 | F15: 0.0894 | G15: 0.0894 | H15: 0.3041 | I15: 0.0583 | J15: 0.1415 | K15: 0.1415 | L15: 0.046 | M15: 0.1564 | N15: 0.2493 | O15: 0.046 | P15: 0.2493 | Q15: 0.1564 | R15: 0.1502 | S15: 0.2003 | T15: 0.1167 | U15: 0.2446 | V15: 0.2148 | W15: 1.1337 | X15: 0.9164 | Y15: 0.2137 | Z15: 1.0145 | AA15: 1.3613 | AB15: 0.4072 | AC15: 0.3297 | AD15: 0.5557 | AE15: 0.1819 | AF15: 0.1962 | AG15: 0.3147 | AH15: 1.2989 | AI15: 0.4413 | AJ15: 0.24 | AK15: 0.4094 | AL15: 0.2716 | AM15: 1.4863 | AN15: 0.4278 | AO15: 0.0828 | AP15: 0.046 | AQ15: 0.2371 | AR15: 0.0644 | AS15: 0.2024 | AT15: 0.2034 | AU15: 0.1503 | AV15: 0.0721 | AW15: 0.3337 | AX15: 0.046
A16: Load_TR9_F2_2 | B16: customer | C16: 0.1157 | D16: 0.053 | E16: 0.053 | F16: 0.1336 | G16: 0.053 | H16: 0.1023 | I16: 0.0843 | J16: 0.053 | K16: 0.053 | L16: 0.1202 | M16: 0.0664 | N16: 0.1291 | O16: 0.0575 | P16: 0.1247 | Q16: 0.062 | R16: 0.1336 | S16: 0.1672 | T16: 0.1479 | U16: 0.0936 | V16: 0.1381 | W16: 0.0897 | X16: 0.907 | Y16: 0.1905 | Z16: 0.1347 | AA16: 0.0575 | AB16: 0.2927 | AC16: 0.053 | AD16: 0.3139 | AE16: 0.053 | AF16: 0.1336 | AG16: 0.053 | AH16: 0.1336 | AI16: 0.053 | AJ16: 0.0754 | AK16: 0.1112 | AL16: 0.053 | AM16: 0.1336 | AN16: 0.053 | AO16: 0.0799 | AP16: 0.1771 | AQ16: 0.437 | AR16: 0.4265 | AS16: 0.8826 | AT16: 1.131 | AU16: 0.298 | AV16: 0.2241 | AW16: 0.053 | AX16: 0.0799
... A176: Load_TR9_F6_9 | B176: prosumer | C176: 0.1401 | D176: 0.2123 | E176: 0.0781 | F176: 0.1955 | G176: 0.1714 | H176: 0.1022 | I176: 0.1932 | J176: 0.1593 | K176: 0.1263 | L176: 0.2261 | M176: 0.0926 | N176: 0.224 | O176: 0.0898 | P176: 0.0627 | Q176: 0.9496 | R176: 0.1998 | S176: 0.0926 | T176: 0.138 | U176: 0.2378 | V176: 0.1209 | W176: 0.2473 | X176: 0.1239 | Y176: 0.993 | Z176: 0.7035 | AA176: 0.2721 | AB176: 0.3141 | AC176: 0.4246 | AD176: 0.0742 | AE176: 0.2203 | AF176: 0.054 | AG176: 0.191 | AH176: 0.1615 | AI176: 0.1408 | AJ176: 0.054 | AK176: 0.1615 | AL176: 0.191 | AM176: 0.054 | AN176: 0.054 | AO176: 0.0781 | AP176: 0.1167 | AQ176: 0.0755 | AR176: 0.2769 | AS176: 0.054 | AT176: 0.2984 | AU176: 0.054 | AV176: 0.1901 | AW176: 0.1623 | AX176: 0.1041

Sheet 5. Raw batt charge
A1: Raw batt charge
A2: Verbatim copy of Charge_kW (TR9_analysis_data.xlsx). One row per half-hour, one column per battery (kW).
A4: period | B4: hour | C4: BES_TR9_two267_C | D4: BES_TR9_two275_C | E4: BES_TR9_two292_B | F4: BES_TR9_two306_A | G4: BES_TR9_two308_A | H4: BES_TR9_two312_C | I4: BES_TR9_two313_C | J4: BES_TR9_two315_A | K4: BES_TR9_two316_A | L4: BES_TR9_two339_A | M4: BES_TR9_two225_C | N4: BES_TR9_two233_A | O4: BES_TR9_five147_C | P4: BES_TR9_five149_A | Q4: BES_TR9_five160_C | R4: BES_TR9_five170_A | S4: BES_TR9_five177_A | T4: BES_TR9_five220_C | U4: BES_TR9_five67_C | V4: BES_TR9_five284_C | W4: BES_TR9_five345_A | X4: BES_TR9_five355_A | Y4: BES_TR9_five78_A | Z4: BES_TR9_five394_C | AA4: BES_TR9_five445_C | AB4: BES_TR9_five499_B | AC4: BES_TR9_five92_A | AD4: BES_TR9_five520_C | AE4: BES_TR9_five545_B | AF4: BES_TR9_five588_A | AG4: BES_TR9_five670_C | AH4: BES_TR9_five685_B | AI4: BES_TR9_five704_A | AJ4: BES_TR9_five719_A | AK4: BES_TR9_five748_B | AL4: BES_TR9_five117_B | AM4: BES_TR9_five778_B | AN4: BES_TR9_five799_C | AO4: BES_TR9_five801_C | AP4: BES_TR9_five881_C | AQ4: BES_TR9_five123_B | AR4: BES_TR9_six186_A | AS4: BES_TR9_six191_B | AT4: BES_TR9_six203_A | AU4: BES_TR9_six232_C | AV4: BES_TR9_six238_A | AW4: BES_TR9_six249_B | AX4: BES_TR9_six269_C | AY4: BES_TR9_six289_C | AZ4: BES_TR9_six326_A | BA4: BES_TR9_six349_A | BB4: BES_TR9_six362_C | BC4: BES_TR9_six365_C | BD4: BES_TR9_six385_B | BE4: BES_TR9_six387_A | BF4: BES_TR9_six431_C | BG4: BES_TR9_six441_A | BH4: BES_TR9_six501_A | BI4: BES_TR9_six512_B | BJ4: BES_TR9_six82_A | BK4: BES_TR9_six523_C | BL4: BES_TR9_six534_B | BM4: BES_TR9_six583_A | BN4: BES_TR9_six625_A | BO4: BES_TR9_six646_B | BP4: BES_TR9_six651_C | BQ4: BES_TR9_six718_C | BR4: BES_TR9_six721_A | BS4: BES_TR9_six740_A | BT4: BES_TR9_six758_B | BU4: BES_TR9_six784_B | BV4: BES_TR9_six90_B | BW4: BES_TR9_six799_B | BX4: BES_TR9_six801_C | BY4: BES_TR9_six807_A | BZ4: BES_TR9_six844_C | CA4: BES_TR9_six852_B | CB4: BES_TR9_six860_C | CC4: BES_TR9_six885_A | CD4: BES_TR9_six914_A | CE4: BES_TR9_six921_B | CF4: BES_TR9_six938_A | CG4: BES_TR9_six967_B | CH4: BES_TR9_six974_C | CI4: BES_TR9_six990_B | CJ4: BES_TR9_six111_C | CK4: BES_TR9_six1006_C | CL4: BES_TR9_six1025_B | CM4: BES_TR9_six1064_C | CN4: BES_TR9_six128_B
A5: 1 | B5: 0 | C5: 0 | D5: 0 | E5: 0 | F5: 0 | G5: 0 | H5: 0 | I5: 0 | J5: 0 | K5: 0 | L5: 0 | M5: 0 | N5: 0 | O5: 0 | P5: 0 | Q5: 0 | R5: 0 | S5: 0 | T5: 0 | U5: 0 | V5: 0 | W5: 0 | X5: 0 | Y5: 0 | Z5: 0 | AA5: 0 | AB5: 0 | AC5: 0 | AD5: 0 | AE5: 0 | AF5: 0 | AG5: 0 | AH5: 0 | AI5: 0 | AJ5: 0 | AK5: 0 | AL5: 0 | AM5: 0 | AN5: 0 | AO5: 0 | AP5: 0 | AQ5: 0 | AR5: 0 | AS5: 0 | AT5: 0 | AU5: 0 | AV5: 0 | AW5: 0 | AX5: 0 | AY5: 0 | AZ5: 0 | BA5: 0 | BB5: 0 | BC5: 0 | BD5: 0 | BE5: 0 | BF5: 0 | BG5: 0 | BH5: 0 | BI5: 0 | BJ5: 0 | BK5: 0 | BL5: 0 | BM5: 0 | BN5: 0 | BO5: 0 | BP5: 0 | BQ5: 0 | BR5: 0 | BS5: 0 | BT5: 0 | BU5: 0 | BV5: 0 | BW5: 0 | BX5: 0 | BY5: 0 | BZ5: 0 | CA5: 0 | CB5: 0 | CC5: 0 | CD5: 0 | CE5: 0 | CF5: 0 | CG5: 0 | CH5: 0 | CI5: 0 | CJ5: 0 | CK5: 0 | CL5: 0 | CM5: 0 | CN5: 0
A6: 2 | B6: 0.5 | C6: 0 | D6: 0 | E6: 0 | F6: 0 | G6: 0 | H6: 0 | I6: 0 | J6: 0 | K6: 0 | L6: 0 | M6: 0 | N6: 0 | O6: 0 | P6: 0 | Q6: 0 | R6: 0 | S6: 0 | T6: 0 | U6: 0 | V6: 0 | W6: 0 | X6: 0 | Y6: 0 | Z6: 0 | AA6: 0 | AB6: 0 | AC6: 0 | AD6: 0 | AE6: 0 | AF6: 0 | AG6: 0 | AH6: 0 | AI6: 0 | AJ6: 0 | AK6: 0 | AL6: 0 | AM6: 0 | AN6: 0 | AO6: 0 | AP6: 0 | AQ6: 0 | AR6: 0 | AS6: 0 | AT6: 0 | AU6: 0 | AV6: 0 | AW6: 0 | AX6: 0 | AY6: 0 | AZ6: 0 | BA6: 0 | BB6: 0 | BC6: 0 | BD6: 0 | BE6: 0 | BF6: 0 | BG6: 0 | BH6: 0 | BI6: 0 | BJ6: 0 | BK6: 0 | BL6: 0 | BM6: 0 | BN6: 0 | BO6: 0 | BP6: 0 | BQ6: 0 | BR6: 0 | BS6: 0 | BT6: 0 | BU6: 0 | BV6: 0 | BW6: 0 | BX6: 0 | BY6: 0 | BZ6: 0 | CA6: 0 | CB6: 0 | CC6: 0 | CD6: 0 | CE6: 0 | CF6: 0 | CG6: 0 | CH6: 0 | CI6: 0 | CJ6: 0 | CK6: 0 | CL6: 0 | CM6: 0 | CN6: 0
A7: 3 | B7: 1 | C7: 0 | D7: 0 | E7: 0 | F7: 0 | G7: 0 | H7: 0 | I7: 0 | J7: 0 | K7: 0 | L7: 0 | M7: 0 | N7: 0 | O7: 0 | P7: 0 | Q7: 0 | R7: 0 | S7: 0 | T7: 0 | U7: 0 | V7: 0 | W7: 0 | X7: 0 | Y7: 0 | Z7: 0 | AA7: 0 | AB7: 0 | AC7: 0 | AD7: 0 | AE7: 0 | AF7: 0 | AG7: 0 | AH7: 0 | AI7: 0 | AJ7: 0 | AK7: 0 | AL7: 0 | AM7: 0 | AN7: 0 | AO7: 0 | AP7: 0 | AQ7: 0 | AR7: 0 | AS7: 0 | AT7: 0 | AU7: 0 | AV7: 0 | AW7: 0 | AX7: 0 | AY7: 0 | AZ7: 0 | BA7: 0 | BB7: 0 | BC7: 0 | BD7: 0 | BE7: 0 | BF7: 0 | BG7: 0 | BH7: 0 | BI7: 0 | BJ7: 0 | BK7: 0 | BL7: 0 | BM7: 0 | BN7: 0 | BO7: 0 | BP7: 0 | BQ7: 0 | BR7: 0 | BS7: 0 | BT7: 0 | BU7: 0 | BV7: 0 | BW7: 0 | BX7: 0 | BY7: 0 | BZ7: 0 | CA7: 0 | CB7: 0 | CC7: 0 | CD7: 0 | CE7: 0 | CF7: 0 | CG7: 0 | CH7: 0 | CI7: 0 | CJ7: 0 | CK7: 0 | CL7: 0 | CM7: 0 | CN7: 0
A8: 4 | B8: 1.5 | C8: 0 | D8: 0 | E8: 0 | F8: 0 | G8: 0 | H8: 0 | I8: 0 | J8: 0 | K8: 0 | L8: 0 | M8: 0 | N8: 0 | O8: 0 | P8: 0 | Q8: 0 | R8: 0 | S8: 0 | T8: 0 | U8: 0 | V8: 0 | W8: 0 | X8: 0 | Y8: 0 | Z8: 0 | AA8: 0 | AB8: 0 | AC8: 0 | AD8: 0 | AE8: 0 | AF8: 0 | AG8: 0 | AH8: 0 | AI8: 0 | AJ8: 0 | AK8: 0 | AL8: 0 | AM8: 0 | AN8: 0 | AO8: 0 | AP8: 0 | AQ8: 0 | AR8: 0 | AS8: 0 | AT8: 0 | AU8: 0 | AV8: 0 | AW8: 0 | AX8: 0 | AY8: 0 | AZ8: 0 | BA8: 0 | BB8: 0 | BC8: 0 | BD8: 0 | BE8: 0 | BF8: 0 | BG8: 0 | BH8: 0 | BI8: 0 | BJ8: 0 | BK8: 0 | BL8: 0 | BM8: 0 | BN8: 0 | BO8: 0 | BP8: 0 | BQ8: 0 | BR8: 0 | BS8: 0 | BT8: 0 | BU8: 0 | BV8: 0 | BW8: 0 | BX8: 0 | BY8: 0 | BZ8: 0 | CA8: 0 | CB8: 0 | CC8: 0 | CD8: 0 | CE8: 0 | CF8: 0 | CG8: 0 | CH8: 0 | CI8: 0 | CJ8: 0 | CK8: 0 | CL8: 0 | CM8: 0 | CN8: 0
A9: 5 | B9: 2 | C9: 0 | D9: 0 | E9: 0 | F9: 0 | G9: 0 | H9: 0 | I9: 0 | J9: 0 | K9: 0 | L9: 0 | M9: 0 | N9: 0 | O9: 0 | P9: 0 | Q9: 0 | R9: 0 | S9: 0 | T9: 0 | U9: 0 | V9: 0 | W9: 0 | X9: 0 | Y9: 0 | Z9: 0 | AA9: 0 | AB9: 0 | AC9: 0 | AD9: 0 | AE9: 0 | AF9: 0 | AG9: 0 | AH9: 0 | AI9: 0 | AJ9: 0 | AK9: 0 | AL9: 0 | AM9: 0 | AN9: 0 | AO9: 0 | AP9: 0 | AQ9: 0 | AR9: 0 | AS9: 0 | AT9: 0 | AU9: 0 | AV9: 0 | AW9: 0 | AX9: 0 | AY9: 0 | AZ9: 0 | BA9: 0 | BB9: 0 | BC9: 0 | BD9: 0 | BE9: 0 | BF9: 0 | BG9: 0 | BH9: 0 | BI9: 0 | BJ9: 0 | BK9: 0 | BL9: 0 | BM9: 0 | BN9: 0 | BO9: 0 | BP9: 0 | BQ9: 0 | BR9: 0 | BS9: 0 | BT9: 0 | BU9: 0 | BV9: 0 | BW9: 0 | BX9: 0 | BY9: 0 | BZ9: 0 | CA9: 0 | CB9: 0 | CC9: 0 | CD9: 0 | CE9: 0 | CF9: 0 | CG9: 0 | CH9: 0 | CI9: 0 | CJ9: 0 | CK9: 0 | CL9: 0 | CM9: 0 | CN9: 0
A10: 6 | B10: 2.5 | C10: 0 | D10: 0 | E10: 0 | F10: 0 | G10: 0 | H10: 0 | I10: 0 | J10: 0 | K10: 0 | L10: 0 | M10: 0 | N10: 0 | O10: 0 | P10: 0 | Q10: 0 | R10: 0 | S10: 0 | T10: 0 | U10: 0 | V10: 0 | W10: 0 | X10: 0 | Y10: 0 | Z10: 0 | AA10: 0 | AB10: 0 | AC10: 0 | AD10: 0 | AE10: 0 | AF10: 0 | AG10: 0 | AH10: 0 | AI10: 0 | AJ10: 0 | AK10: 0 | AL10: 0 | AM10: 0 | AN10: 0 | AO10: 0 | AP10: 0 | AQ10: 0 | AR10: 0 | AS10: 0 | AT10: 0 | AU10: 0 | AV10: 0 | AW10: 0 | AX10: 0 | AY10: 0 | AZ10: 0 | BA10: 0 | BB10: 0 | BC10: 0 | BD10: 0 | BE10: 0 | BF10: 0 | BG10: 0 | BH10: 0 | BI10: 0 | BJ10: 0 | BK10: 0 | BL10: 0 | BM10: 0 | BN10: 0 | BO10: 0 | BP10: 0 | BQ10: 0 | BR10: 0 | BS10: 0 | BT10: 0 | BU10: 0 | BV10: 0 | BW10: 0 | BX10: 0 | BY10: 0 | BZ10: 0 | CA10: 0 | CB10: 0 | CC10: 0 | CD10: 0 | CE10: 0 | CF10: 0 | CG10: 0 | CH10: 0 | CI10: 0 | CJ10: 0 | CK10: 0 | CL10: 0 | CM10: 0 | CN10: 0
A11: 7 | B11: 3 | C11: 0 | D11: 0 | E11: 0 | F11: 0 | G11: 0 | H11: 0 | I11: 0 | J11: 0 | K11: 0 | L11: 0 | M11: 0 | N11: 0 | O11: 0 | P11: 0 | Q11: 0 | R11: 0 | S11: 0 | T11: 0 | U11: 0 | V11: 0 | W11: 0 | X11: 0 | Y11: 0 | Z11: 0 | AA11: 0 | AB11: 0 | AC11: 0 | AD11: 0 | AE11: 0 | AF11: 0 | AG11: 0 | AH11: 0 | AI11: 0 | AJ11: 0 | AK11: 0 | AL11: 0 | AM11: 0 | AN11: 0 | AO11: 0 | AP11: 0 | AQ11: 0 | AR11: 0 | AS11: 0 | AT11: 0 | AU11: 0 | AV11: 0 | AW11: 0 | AX11: 0 | AY11: 0 | AZ11: 0 | BA11: 0 | BB11: 0 | BC11: 0 | BD11: 0 | BE11: 0 | BF11: 0 | BG11: 0 | BH11: 0 | BI11: 0 | BJ11: 0 | BK11: 0 | BL11: 0 | BM11: 0 | BN11: 0 | BO11: 0 | BP11: 0 | BQ11: 0 | BR11: 0 | BS11: 0 | BT11: 0 | BU11: 0 | BV11: 0 | BW11: 0 | BX11: 0 | BY11: 0 | BZ11: 0 | CA11: 0 | CB11: 0 | CC11: 0 | CD11: 0 | CE11: 0 | CF11: 0 | CG11: 0 | CH11: 0 | CI11: 0 | CJ11: 0 | CK11: 0 | CL11: 0 | CM11: 0 | CN11: 0
A12: 8 | B12: 3.5 | C12: 0 | D12: 0 | E12: 0 | F12: 0 | G12: 0 | H12: 0 | I12: 0 | J12: 0 | K12: 0 | L12: 0 | M12: 0 | N12: 0 | O12: 0 | P12: 0 | Q12: 0 | R12: 0 | S12: 0 | T12: 0 | U12: 0 | V12: 0 | W12: 0 | X12: 0 | Y12: 0 | Z12: 0 | AA12: 0 | AB12: 0 | AC12: 0 | AD12: 0 | AE12: 0 | AF12: 0 | AG12: 0 | AH12: 0 | AI12: 0 | AJ12: 0 | AK12: 0 | AL12: 0 | AM12: 0 | AN12: 0 | AO12: 0 | AP12: 0 | AQ12: 0 | AR12: 0 | AS12: 0 | AT12: 0 | AU12: 0 | AV12: 0 | AW12: 0 | AX12: 0 | AY12: 0 | AZ12: 0 | BA12: 0 | BB12: 0 | BC12: 0 | BD12: 0 | BE12: 0 | BF12: 0 | BG12: 0 | BH12: 0 | BI12: 0 | BJ12: 0 | BK12: 0 | BL12: 0 | BM12: 0 | BN12: 0 | BO12: 0 | BP12: 0 | BQ12: 0 | BR12: 0 | BS12: 0 | BT12: 0 | BU12: 0 | BV12: 0 | BW12: 0 | BX12: 0 | BY12: 0 | BZ12: 0 | CA12: 0 | CB12: 0 | CC12: 0 | CD12: 0 | CE12: 0 | CF12: 0 | CG12: 0 | CH12: 0 | CI12: 0 | CJ12: 0 | CK12: 0 | CL12: 0 | CM12: 0 | CN12: 0
A13: 9 | B13: 4 | C13: 0 | D13: 0.001 | E13: 0 | F13: 0 | G13: 0.008 | H13: 0 | I13: 0 | J13: 0 | K13: 0 | L13: 0 | M13: 0 | N13: 0 | O13: 0 | P13: 0 | Q13: 0 | R13: 0 | S13: 0 | T13: 0 | U13: 0 | V13: 0 | W13: 0 | X13: 0 | Y13: 0 | Z13: 0 | AA13: 0 | AB13: 0 | AC13: 0 | AD13: 0.002 | AE13: 0 | AF13: 0 | AG13: 0 | AH13: 0 | AI13: 0 | AJ13: 0 | AK13: 0 | AL13: 0 | AM13: 0 | AN13: 0 | AO13: 0 | AP13: 0 | AQ13: 0 | AR13: 0 | AS13: 0 | AT13: 0 | AU13: 0 | AV13: 0 | AW13: 0 | AX13: 0 | AY13: 0 | AZ13: 0 | BA13: 0 | BB13: 0 | BC13: 0 | BD13: 0 | BE13: 0 | BF13: 0 | BG13: 0 | BH13: 0 | BI13: 0 | BJ13: 0 | BK13: 0 | BL13: 0 | BM13: 0 | BN13: 0 | BO13: 0.006 | BP13: 0 | BQ13: 0 | BR13: 0 | BS13: 0 | BT13: 0 | BU13: 0.007 | BV13: 0 | BW13: 0 | BX13: 0 | BY13: 0 | BZ13: 0 | CA13: 0 | CB13: 0 | CC13: 0 | CD13: 0 | CE13: 0 | CF13: 0 | CG13: 0 | CH13: 0 | CI13: 0 | CJ13: 0 | CK13: 0 | CL13: 0 | CM13: 0 | CN13: 0
A14: 10 | B14: 4.5 | C14: 0.126 | D14: 0.184 | E14: 0.114 | F14: 0.187 | G14: 0 | H14: 0 | I14: 0.188 | J14: 0.158 | K14: 0.013 | L14: 0 | M14: 0.122 | N14: 0.103 | O14: 0.125 | P14: 0.064 | Q14: 0.093 | R14: 0.127 | S14: 0 | T14: 0.113 | U14: 0.068 | V14: 0.154 | W14: 0.133 | X14: 0.021 | Y14: 0.101 | Z14: 0.084 | AA14: 0 | AB14: 0.101 | AC14: 0 | AD14: 0.065 | AE14: 0 | AF14: 0.124 | AG14: 0.091 | AH14: 0 | AI14: 0 | AJ14: 0 | AK14: 0 | AL14: 0.114 | AM14: 0.153 | AN14: 0.151 | AO14: 0 | AP14: 0.035 | AQ14: 0 | AR14: 0.063 | AS14: 0.117 | AT14: 0 | AU14: 0.06 | AV14: 0.019 | AW14: 0.07 | AX14: 0 | AY14: 0 | AZ14: 0.028 | BA14: 0 | BB14: 0.095 | BC14: 0.092 | BD14: 0.12 | BE14: 0 | BF14: 0 | BG14: 0 | BH14: 0.038 | BI14: 0 | BJ14: 0.107 | BK14: 0.149 | BL14: 0.037 | BM14: 0.178 | BN14: 0 | BO14: 0.075 | BP14: 0.13 | BQ14: 0.098 | BR14: 0.017 | BS14: 0 | BT14: 0 | BU14: 0.128 | BV14: 0.064 | BW14: 0.074 | BX14: 0 | BY14: 0.088 | BZ14: 0.078 | CA14: 0.018 | CB14: 0.181 | CC14: 0.181 | CD14: 0 | CE14: 0.008 | CF14: 0.065 | CG14: 0 | CH14: 0 | CI14: 0.138 | CJ14: 0.125 | CK14: 0.146 | CL14: 0.179 | CM14: 0.112 | CN14: 0.007
A15: 11 | B15: 5 | C15: 0.084 | D15: 0.412 | E15: 0.363 | F15: 0.306 | G15: 0.291 | H15: 0.193 | I15: 0.323 | J15: 0.247 | K15: 0.121 | L15: 0 | M15: 0.294 | N15: 0.319 | O15: 0.297 | P15: 0.062 | Q15: 0.294 | R15: 0.413 | S15: 0.116 | T15: 0.194 | U15: 0.105 | V15: 0.354 | W15: 0.348 | X15: 0.237 | Y15: 0.248 | Z15: 0.214 | AA15: 0.21 | AB15: 0.415 | AC15: 0.393 | AD15: 0.413 | AE15: 0.086 | AF15: 0.415 | AG15: 0.171 | AH15: 0.224 | AI15: 0.277 | AJ15: 0.046 | AK15: 0.163 | AL15: 0.126 | AM15: 0.273 | AN15: 0.243 | AO15: 0.354 | AP15: 0.299 | AQ15: 0.142 | AR15: 0.178 | AS15: 0.222 | AT15: 0.252 | AU15: 0.292 | AV15: 0.14 | AW15: 0.309 | AX15: 0.131 | AY15: 0.085 | AZ15: 0.395 | BA15: 0.236 | BB15: 0.146 | BC15: 0.235 | BD15: 0.203 | BE15: 0.067 | BF15: 0.171 | BG15: 0.029 | BH15: 0.407 | BI15: 0.288 | BJ15: 0.321 | BK15: 0.107 | BL15: 0.099 | BM15: 0.406 | BN15: 0.306 | BO15: 0.384 | BP15: 0.212 | BQ15: 0.356 | BR15: 0.198 | BS15: 0.104 | BT15: 0.068 | BU15: 0.354 | BV15: 0.179 | BW15: 0.116 | BX15: 0.174 | BY15: 0.336 | BZ15: 0.193 | CA15: 0.187 | CB15: 0.155 | CC15: 0.255 | CD15: 0.201 | CE15: 0.06 | CF15: 0.18 | CG15: 0 | CH15: 0.019 | CI15: 0.202 | CJ15: 0.17 | CK15: 0.346 | CL15: 0.431 | CM15: 0.41 | CN15: 0.369
A16: 12 | B16: 5.5 | C16: 0.196 | D16: 0.693 | E16: 0.61 | F16: 0.696 | G16: 0.7 | H16: 0.503 | I16: 0.697 | J16: 0.4 | K16: 0.589 | L16: 0.226 | M16: 0.504 | N16: 0.549 | O16: 0.491 | P16: 0.219 | Q16: 0.256 | R16: 0.605 | S16: 0.113 | T16: 0.416 | U16: 0.323 | V16: 0.599 | W16: 0.422 | X16: 0 | Y16: 0.623 | Z16: 0.174 | AA16: 0.534 | AB16: 0.538 | AC16: 0.486 | AD16: 0.628 | AE16: 0.318 | AF16: 0.696 | AG16: 0.41 | AH16: 0.406 | AI16: 0.548 | AJ16: 0.058 | AK16: 0.189 | AL16: 0.45 | AM16: 0.593 | AN16: 0.596 | AO16: 0.445 | AP16: 0.61 | AQ16: 0.496 | AR16: 0.316 | AS16: 0.59 | AT16: 0.428 | AU16: 0.458 | AV16: 0.177 | AW16: 0.519 | AX16: 0.129 | AY16: 0.414 | AZ16: 0.619 | BA16: 0.336 | BB16: 0.199 | BC16: 0.411 | BD16: 0.502 | BE16: 0.126 | BF16: 0.242 | BG16: 0.168 | BH16: 0.486 | BI16: 0.447 | BJ16: 0.561 | BK16: 0.589 | BL16: 0.075 | BM16: 0.687 | BN16: 0.624 | BO16: 0.698 | BP16: 0.382 | BQ16: 0.674 | BR16: 0.531 | BS16: 0.184 | BT16: 0.234 | BU16: 0.316 | BV16: 0.319 | BW16: 0.501 | BX16: 0.314 | BY16: 0.696 | BZ16: 0.258 | CA16: 0.437 | CB16: 0.69 | CC16: 0.69 | CD16: 0.414 | CE16: 0.265 | CF16: 0.045 | CG16: 0.12 | CH16: 0.077 | CI16: 0.686 | CJ16: 0.489 | CK16: 0.591 | CL16: 0.594 | CM16: 0.559 | CN16: 0.518
... A52: 48 | B52: 23.5 | C52: 0 | D52: 0 | E52: 0 | F52: 0 | G52: 0 | H52: 0 | I52: 0 | J52: 0 | K52: 0 | L52: 0 | M52: 0 | N52: 0 | O52: 0 | P52: 0 | Q52: 0 | R52: 0 | S52: 0 | T52: 0 | U52: 0 | V52: 0 | W52: 0 | X52: 0 | Y52: 0 | Z52: 0 | AA52: 0 | AB52: 0 | AC52: 0 | AD52: 0 | AE52: 0 | AF52: 0 | AG52: 0 | AH52: 0 | AI52: 0 | AJ52: 0 | AK52: 0 | AL52: 0 | AM52: 0 | AN52: 0 | AO52: 0 | AP52: 0 | AQ52: 0 | AR52: 0 | AS52: 0 | AT52: 0 | AU52: 0 | AV52: 0 | AW52: 0 | AX52: 0 | AY52: 0 | AZ52: 0 | BA52: 0 | BB52: 0 | BC52: 0 | BD52: 0 | BE52: 0 | BF52: 0 | BG52: 0 | BH52: 0 | BI52: 0 | BJ52: 0 | BK52: 0 | BL52: 0 | BM52: 0 | BN52: 0 | BO52: 0 | BP52: 0 | BQ52: 0 | BR52: 0 | BS52: 0 | BT52: 0 | BU52: 0 | BV52: 0 | BW52: 0 | BX52: 0 | BY52: 0 | BZ52: 0 | CA52: 0 | CB52: 0 | CC52: 0 | CD52: 0 | CE52: 0 | CF52: 0 | CG52: 0 | CH52: 0 | CI52: 0 | CJ52: 0 | CK52: 0 | CL52: 0 | CM52: 0 | CN52: 0

Sheet 6. Raw batt discharge
A1: Raw batt discharge
A2: Verbatim copy of Discharge_kW (TR9_analysis_data.xlsx). One row per half-hour, one column per battery (kW).
A4: period | B4: hour | C4: BES_TR9_two267_C | D4: BES_TR9_two275_C | E4: BES_TR9_two292_B | F4: BES_TR9_two306_A | G4: BES_TR9_two308_A | H4: BES_TR9_two312_C | I4: BES_TR9_two313_C | J4: BES_TR9_two315_A | K4: BES_TR9_two316_A | L4: BES_TR9_two339_A | M4: BES_TR9_two225_C | N4: BES_TR9_two233_A | O4: BES_TR9_five147_C | P4: BES_TR9_five149_A | Q4: BES_TR9_five160_C | R4: BES_TR9_five170_A | S4: BES_TR9_five177_A | T4: BES_TR9_five220_C | U4: BES_TR9_five67_C | V4: BES_TR9_five284_C | W4: BES_TR9_five345_A | X4: BES_TR9_five355_A | Y4: BES_TR9_five78_A | Z4: BES_TR9_five394_C | AA4: BES_TR9_five445_C | AB4: BES_TR9_five499_B | AC4: BES_TR9_five92_A | AD4: BES_TR9_five520_C | AE4: BES_TR9_five545_B | AF4: BES_TR9_five588_A | AG4: BES_TR9_five670_C | AH4: BES_TR9_five685_B | AI4: BES_TR9_five704_A | AJ4: BES_TR9_five719_A | AK4: BES_TR9_five748_B | AL4: BES_TR9_five117_B | AM4: BES_TR9_five778_B | AN4: BES_TR9_five799_C | AO4: BES_TR9_five801_C | AP4: BES_TR9_five881_C | AQ4: BES_TR9_five123_B | AR4: BES_TR9_six186_A | AS4: BES_TR9_six191_B | AT4: BES_TR9_six203_A | AU4: BES_TR9_six232_C | AV4: BES_TR9_six238_A | AW4: BES_TR9_six249_B | AX4: BES_TR9_six269_C | AY4: BES_TR9_six289_C | AZ4: BES_TR9_six326_A | BA4: BES_TR9_six349_A | BB4: BES_TR9_six362_C | BC4: BES_TR9_six365_C | BD4: BES_TR9_six385_B | BE4: BES_TR9_six387_A | BF4: BES_TR9_six431_C | BG4: BES_TR9_six441_A | BH4: BES_TR9_six501_A | BI4: BES_TR9_six512_B | BJ4: BES_TR9_six82_A | BK4: BES_TR9_six523_C | BL4: BES_TR9_six534_B | BM4: BES_TR9_six583_A | BN4: BES_TR9_six625_A | BO4: BES_TR9_six646_B | BP4: BES_TR9_six651_C | BQ4: BES_TR9_six718_C | BR4: BES_TR9_six721_A | BS4: BES_TR9_six740_A | BT4: BES_TR9_six758_B | BU4: BES_TR9_six784_B | BV4: BES_TR9_six90_B | BW4: BES_TR9_six799_B | BX4: BES_TR9_six801_C | BY4: BES_TR9_six807_A | BZ4: BES_TR9_six844_C | CA4: BES_TR9_six852_B | CB4: BES_TR9_six860_C | CC4: BES_TR9_six885_A | CD4: BES_TR9_six914_A | CE4: BES_TR9_six921_B | CF4: BES_TR9_six938_A | CG4: BES_TR9_six967_B | CH4: BES_TR9_six974_C | CI4: BES_TR9_six990_B | CJ4: BES_TR9_six111_C | CK4: BES_TR9_six1006_C | CL4: BES_TR9_six1025_B | CM4: BES_TR9_six1064_C | CN4: BES_TR9_six128_B
A5: 1 | B5: 0 | C5: 0.048 | D5: 0.049 | E5: 0.054 | F5: 0.117 | G5: 0.577 | H5: 0.594 | I5: 0.045 | J5: 0.211 | K5: 0.145 | L5: 0.156 | M5: 0.052 | N5: 0.706 | O5: 0.049 | P5: 1.047 | Q5: 1.071 | R5: 0.57 | S5: 0.1 | T5: 0.046 | U5: 0.061 | V5: 0.082 | W5: 0.288 | X5: 0.045 | Y5: 0.055 | Z5: 0.164 | AA5: 0.75 | AB5: 0.103 | AC5: 0.046 | AD5: 0.048 | AE5: 0.104 | AF5: 0.046 | AG5: 0.054 | AH5: 0.599 | AI5: 0.144 | AJ5: 0.165 | AK5: 0.131 | AL5: 0.149 | AM5: 0.149 | AN5: 0.053 | AO5: 0.148 | AP5: 0.081 | AQ5: 0.06 | AR5: 0.053 | AS5: 0.059 | AT5: 0.111 | AU5: 0.499 | AV5: 0.152 | AW5: 0.055 | AX5: 0.149 | AY5: 0.079 | AZ5: 0.156 | BA5: 0.11 | BB5: 0.127 | BC5: 0.053 | BD5: 0.683 | BE5: 0.734 | BF5: 0.16 | BG5: 0.133 | BH5: 0.168 | BI5: 0.769 | BJ5: 0.37 | BK5: 0.201 | BL5: 0.163 | BM5: 0.243 | BN5: 0.308 | BO5: 0.084 | BP5: 0.129 | BQ5: 0.187 | BR5: 0.21 | BS5: 0.585 | BT5: 0.316 | BU5: 0.061 | BV5: 0.052 | BW5: 0.206 | BX5: 0.252 | BY5: 0.412 | BZ5: 0.109 | CA5: 0.105 | CB5: 0.111 | CC5: 0.428 | CD5: 0.08 | CE5: 0.409 | CF5: 0.268 | CG5: 0.696 | CH5: 0.183 | CI5: 0.838 | CJ5: 0.122 | CK5: 0.207 | CL5: 0.03 | CM5: 0.066 | CN5: 0.14
A6: 2 | B6: 0.5 | C6: 0.1 | D6: 0.049 | E6: 0.215 | F6: 0.085 | G6: 0.49 | H6: 0.572 | I6: 0.139 | J6: 0.046 | K6: 0.198 | L6: 0.293 | M6: 0.114 | N6: 0.136 | O6: 0.049 | P6: 0.574 | Q6: 1.043 | R6: 0.713 | S6: 0.122 | T6: 0.159 | U6: 0.052 | V6: 0.125 | W6: 0.375 | X6: 0.305 | Y6: 0.127 | Z6: 0.048 | AA6: 0.257 | AB6: 0.089 | AC6: 0.107 | AD6: 0.21 | AE6: 0.171 | AF6: 0.199 | AG6: 0.172 | AH6: 0.544 | AI6: 0.23 | AJ6: 0.047 | AK6: 0.055 | AL6: 0.17 | AM6: 0.139 | AN6: 0.053 | AO6: 0.106 | AP6: 0.28 | AQ6: 0.243 | AR6: 0.053 | AS6: 0.148 | AT6: 0.141 | AU6: 0.621 | AV6: 0.041 | AW6: 0.32 | AX6: 0.082 | AY6: 0.196 | AZ6: 0.242 | BA6: 0.095 | BB6: 0.05 | BC6: 0.053 | BD6: 0.149 | BE6: 0.438 | BF6: 0.146 | BG6: 0.173 | BH6: 0.202 | BI6: 0.109 | BJ6: 0.049 | BK6: 0.044 | BL6: 0.05 | BM6: 0.329 | BN6: 0.613 | BO6: 0.151 | BP6: 0.153 | BQ6: 0.183 | BR6: 0.177 | BS6: 0.618 | BT6: 0.148 | BU6: 0.185 | BV6: 0.052 | BW6: 0.124 | BX6: 0.057 | BY6: 0.227 | BZ6: 0.042 | CA6: 0.286 | CB6: 0.247 | CC6: 0.052 | CD6: 0.184 | CE6: 0.054 | CF6: 0.391 | CG6: 0.322 | CH6: 0.213 | CI6: 0.802 | CJ6: 0.084 | CK6: 0.093 | CL6: 0.159 | CM6: 0.206 | CN6: 0.212
A7: 3 | B7: 1 | C7: 0.304 | D7: 0.049 | E7: 0.058 | F7: 0.054 | G7: 0.273 | H7: 0.563 | I7: 0.045 | J7: 0.316 | K7: 0.171 | L7: 0.121 | M7: 0.118 | N7: 0.149 | O7: 0.049 | P7: 0.77 | Q7: 0.058 | R7: 0.093 | S7: 0.116 | T7: 0.119 | U7: 0.121 | V7: 0.055 | W7: 0.216 | X7: 0.088 | Y7: 0.218 | Z7: 0.309 | AA7: 0.054 | AB7: 0.208 | AC7: 0.191 | AD7: 0.048 | AE7: 0.098 | AF7: 0.046 | AG7: 0.079 | AH7: 0.548 | AI7: 0.161 | AJ7: 0.221 | AK7: 0.087 | AL7: 0.22 | AM7: 0.083 | AN7: 0.161 | AO7: 0.05 | AP7: 0.049 | AQ7: 0.152 | AR7: 0.053 | AS7: 0.12 | AT7: 0.036 | AU7: 0.268 | AV7: 0.243 | AW7: 0.062 | AX7: 0.042 | AY7: 0.137 | AZ7: 0.059 | BA7: 0.218 | BB7: 0.05 | BC7: 0.053 | BD7: 0.143 | BE7: 0.831 | BF7: 0.099 | BG7: 0.104 | BH7: 0.054 | BI7: 0.217 | BJ7: 0.12 | BK7: 0.044 | BL7: 0.228 | BM7: 0.328 | BN7: 0.131 | BO7: 0.044 | BP7: 0.155 | BQ7: 0.05 | BR7: 0.211 | BS7: 0.048 | BT7: 0.046 | BU7: 0.135 | BV7: 0.052 | BW7: 0.158 | BX7: 0.226 | BY7: 0.174 | BZ7: 0.038 | CA7: 0.04 | CB7: 0.052 | CC7: 0.206 | CD7: 0.05 | CE7: 0.373 | CF7: 0.051 | CG7: 0.317 | CH7: 0.194 | CI7: 0.751 | CJ7: 0.332 | CK7: 0.058 | CL7: 0.03 | CM7: 0.051 | CN7: 0.078
A8: 4 | B8: 1.5 | C8: 0.077 | D8: 0.049 | E8: 0.054 | F8: 0.223 | G8: 0.085 | H8: 0.058 | I8: 0.139 | J8: 0.089 | K8: 0.348 | L8: 0.222 | M8: 0.052 | N8: 0.186 | O8: 0.049 | P8: 0 | Q8: 0.219 | R8: 0.171 | S8: 0.16 | T8: 0.288 | U8: 0.048 | V8: 0.152 | W8: 0.056 | X8: 0.051 | Y8: 0.055 | Z8: 0.069 | AA8: 0.26 | AB8: 0.241 | AC8: 0.073 | AD8: 0.048 | AE8: 0.059 | AF8: 0.158 | AG8: 0.082 | AH8: 0.656 | AI8: 0.153 | AJ8: 0.122 | AK8: 0.163 | AL8: 0.177 | AM8: 0.034 | AN8: 0.053 | AO8: 0.05 | AP8: 0.203 | AQ8: 0.19 | AR8: 0.053 | AS8: 0.079 | AT8: 0.066 | AU8: 0.176 | AV8: 0.041 | AW8: 0.126 | AX8: 0.189 | AY8: 0.185 | AZ8: 0.184 | BA8: 0.076 | BB8: 0.158 | BC8: 0.053 | BD8: 0.054 | BE8: 0.387 | BF8: 0.246 | BG8: 0.09 | BH8: 0.262 | BI8: 0.109 | BJ8: 0.178 | BK8: 0.183 | BL8: 0.05 | BM8: 0.231 | BN8: 0.123 | BO8: 0.137 | BP8: 0.108 | BQ8: 0.294 | BR8: 0.126 | BS8: 0.114 | BT8: 0.128 | BU8: 0.161 | BV8: 0.052 | BW8: 0.142 | BX8: 0.084 | BY8: 0.106 | BZ8: 0.084 | CA8: 0.273 | CB8: 0.06 | CC8: 0.052 | CD8: 0.132 | CE8: 0.054 | CF8: 0.316 | CG8: 0.107 | CH8: 0.169 | CI8: 0 | CJ8: 0.049 | CK8: 0.084 | CL8: 0.118 | CM8: 0.159 | CN8: 0.195
A9: 5 | B9: 2 | C9: 0.12 | D9: 0.049 | E9: 0.131 | F9: 0.067 | G9: 0.288 | H9: 0.291 | I9: 0.045 | J9: 0.089 | K9: 0.154 | L9: 0.083 | M9: 0.052 | N9: 0.174 | O9: 0.049 | P9: 0 | Q9: 0 | R9: 0.142 | S9: 0.057 | T9: 0.057 | U9: 0.126 | V9: 0.05 | W9: 0.056 | X9: 0.342 | Y9: 0.177 | Z9: 0.048 | AA9: 0.054 | AB9: 0.277 | AC9: 0.199 | AD9: 0.072 | AE9: 0.26 | AF9: 0.088 | AG9: 0.089 | AH9: 0.043 | AI9: 0.096 | AJ9: 0.082 | AK9: 0.055 | AL9: 0.048 | AM9: 0.191 | AN9: 0.145 | AO9: 0.204 | AP9: 0.158 | AQ9: 0.185 | AR9: 0.053 | AS9: 0.188 | AT9: 0.17 | AU9: 0.187 | AV9: 0.041 | AW9: 0.351 | AX9: 0.042 | AY9: 0.177 | AZ9: 0.087 | BA9: 0.113 | BB9: 0.05 | BC9: 0.053 | BD9: 0.054 | BE9: 0 | BF9: 0.149 | BG9: 0.209 | BH9: 0.086 | BI9: 0.033 | BJ9: 0.087 | BK9: 0.174 | BL9: 0.203 | BM9: 0.055 | BN9: 0.22 | BO9: 0.097 | BP9: 0.159 | BQ9: 0.543 | BR9: 0.292 | BS9: 0.044 | BT9: 0.232 | BU9: 0.149 | BV9: 0.052 | BW9: 0.134 | BX9: 0.128 | BY9: 0.046 | BZ9: 0.067 | CA9: 0.117 | CB9: 0.222 | CC9: 0.136 | CD9: 0.132 | CE9: 0.054 | CF9: 0.051 | CG9: 0.23 | CH9: 0.173 | CI9: 0 | CJ9: 0.213 | CK9: 0.111 | CL9: 0.071 | CM9: 0.113 | CN9: 0.171
A10: 6 | B10: 2.5 | C10: 0.269 | D10: 0.049 | E10: 0.142 | F10: 0.1 | G10: 0.143 | H10: 0.13 | I10: 0.139 | J10: 0.304 | K10: 0.184 | L10: 0.287 | M10: 0.052 | N10: 0.047 | O10: 0.049 | P10: 0 | Q10: 0 | R10: 0.048 | S10: 0.079 | T10: 0.046 | U10: 0.052 | V10: 0.147 | W10: 0.142 | X10: 0.051 | Y10: 0.167 | Z10: 0.247 | AA10: 0.08 | AB10: 0.046 | AC10: 0.046 | AD10: 0.143 | AE10: 0.053 | AF10: 0.046 | AG10: 0.054 | AH10: 0 | AI10: 0.304 | AJ10: 0.091 | AK10: 0.055 | AL10: 0.22 | AM10: 0.146 | AN10: 0.068 | AO10: 0.05 | AP10: 0.049 | AQ10: 0.21 | AR10: 0.053 | AS10: 0.059 | AT10: 0.036 | AU10: 0.272 | AV10: 0.213 | AW10: 0.28 | AX10: 0.042 | AY10: 0.061 | AZ10: 0.168 | BA10: 0.135 | BB10: 0.142 | BC10: 0.053 | BD10: 0.143 | BE10: 0 | BF10: 0.246 | BG10: 0.144 | BH10: 0.501 | BI10: 0.109 | BJ10: 0.211 | BK10: 0.044 | BL10: 0.074 | BM10: 0.055 | BN10: 0.164 | BO10: 0.044 | BP10: 0.072 | BQ10: 0.152 | BR10: 0.116 | BS10: 0.119 | BT10: 0.046 | BU10: 0.227 | BV10: 0.052 | BW10: 0.174 | BX10: 0.181 | BY10: 0.09 | BZ10: 0.075 | CA10: 0.072 | CB10: 0.052 | CC10: 0.122 | CD10: 0.05 | CE10: 0.273 | CF10: 0.186 | CG10: 0.227 | CH10: 0.192 | CI10: 0 | CJ10: 0.075 | CK10: 0.102 | CL10: 0.03 | CM10: 0.051 | CN10: 0.102
A11: 7 | B11: 3 | C11: 0.106 | D11: 0.049 | E11: 0.054 | F11: 0.046 | G11: 0.199 | H11: 0.101 | I11: 0.045 | J11: 0.058 | K11: 0.235 | L11: 0.167 | M11: 0.052 | N11: 0.18 | O11: 0.049 | P11: 0 | Q11: 0 | R11: 0.265 | S11: 0.276 | T11: 0.231 | U11: 0.121 | V11: 0.061 | W11: 0.198 | X11: 0.159 | Y11: 0.105 | Z11: 0.13 | AA11: 0.206 | AB11: 0.175 | AC11: 0.243 | AD11: 0.048 | AE11: 0.132 | AF11: 0.199 | AG11: 0.054 | AH11: 0 | AI11: 0.094 | AJ11: 0.192 | AK11: 0.195 | AL11: 0.177 | AM11: 0.034 | AN11: 0.053 | AO11: 0.127 | AP11: 0.136 | AQ11: 0.06 | AR11: 0.053 | AS11: 0.059 | AT11: 0.2 | AU11: 0.179 | AV11: 0.071 | AW11: 0.373 | AX11: 0.122 | AY11: 0.254 | AZ11: 0.168 | BA11: 0.172 | BB11: 0.065 | BC11: 0.053 | BD11: 0.054 | BE11: 0 | BF11: 0.05 | BG11: 0.049 | BH11: 0.503 | BI11: 0.058 | BJ11: 0.124 | BK11: 0.233 | BL11: 0.082 | BM11: 0.055 | BN11: 0.147 | BO11: 0.111 | BP11: 0.236 | BQ11: 0.21 | BR11: 0.068 | BS11: 0.044 | BT11: 0.129 | BU11: 0.069 | BV11: 0.052 | BW11: 0.109 | BX11: 0.075 | BY11: 0.191 | BZ11: 0.075 | CA11: 0.212 | CB11: 0.128 | CC11: 0.052 | CD11: 0.191 | CE11: 0.154 | CF11: 0.072 | CG11: 0.063 | CH11: 0.239 | CI11: 0 | CJ11: 0.049 | CK11: 0.093 | CL11: 0.159 | CM11: 0.221 | CN11: 0.193
A12: 8 | B12: 3.5 | C12: 0.237 | D12: 0.046 | E12: 0.051 | F12: 0.152 | G12: 0.236 | H12: 0.082 | I12: 0.042 | J12: 0.139 | K12: 0.168 | L12: 0.228 | M12: 0.049 | N12: 0.12 | O12: 0.046 | P12: 0 | Q12: 0 | R12: 0.045 | S12: 0.085 | T12: 0.185 | U12: 0.051 | V12: 0.047 | W12: 0.053 | X12: 0.042 | Y12: 0.236 | Z12: 0.046 | AA12: 0.078 | AB12: 0.071 | AC12: 0.078 | AD12: 0.045 | AE12: 0.185 | AF12: 0.043 | AG12: 0.115 | AH12: 0 | AI12: 0.18 | AJ12: 0.082 | AK12: 0.053 | AL12: 0.132 | AM12: 0.185 | AN12: 0.15 | AO12: 0.124 | AP12: 0.198 | AQ12: 0.332 | AR12: 0.051 | AS12: 0.206 | AT12: 0.034 | AU12: 0.188 | AV12: 0.051 | AW12: 0.824 | AX12: 0.108 | AY12: 0.095 | AZ12: 0.169 | BA12: 0.099 | BB12: 0.048 | BC12: 0.051 | BD12: 0.096 | BE12: 0 | BF12: 0.087 | BG12: 0.179 | BH12: 0.226 | BI12: 0.19 | BJ12: 0.144 | BK12: 0.12 | BL12: 0.194 | BM12: 0.052 | BN12: 0.317 | BO12: 0.121 | BP12: 0.059 | BQ12: 0.075 | BR12: 0.362 | BS12: 0.117 | BT12: 0.229 | BU12: 0.205 | BV12: 0.05 | BW12: 0.239 | BX12: 0.233 | BY12: 0.1 | BZ12: 0.099 | CA12: 0.037 | CB12: 0.227 | CC12: 0.049 | CD12: 0.07 | CE12: 0.052 | CF12: 0.065 | CG12: 0.271 | CH12: 0.037 | CI12: 0 | CJ12: 0.338 | CK12: 0.055 | CL12: 0.027 | CM12: 0.048 | CN12: 0.156
A13: 9 | B13: 4 | C13: 0.142 | D13: 0 | E13: 0.093 | F13: 0.072 | G13: 0 | H13: 0 | I13: 0.089 | J13: 0.098 | K13: 0.168 | L13: 0.196 | M13: 0.015 | N13: 0.143 | O13: 0.012 | P13: 0 | Q13: 0 | R13: 0.158 | S13: 0.075 | T13: 0.114 | U13: 0.097 | V13: 0.114 | W13: 0.226 | X13: 0.202 | Y13: 0.005 | Z13: 0.285 | AA13: 0.004 | AB13: 0.068 | AC13: 0.036 | AD13: 0 | AE13: 0.028 | AF13: 0.087 | AG13: 0.023 | AH13: 0 | AI13: 0.141 | AJ13: 0.187 | AK13: 0.094 | AL13: 0.213 | AM13: 0.053 | AN13: 0.017 | AO13: 0.006 | AP13: 0.023 | AQ13: 0.023 | AR13: 0.028 | AS13: 0.015 | AT13: 0.005 | AU13: 0 | AV13: 0.15 | AW13: 0 | AX13: 0.05 | AY13: 0.019 | AZ13: 0.086 | BA13: 0.104 | BB13: 0.127 | BC13: 0.022 | BD13: 0.061 | BE13: 0 | BF13: 0.148 | BG13: 0.155 | BH13: 0.104 | BI13: 0.055 | BJ13: 0.068 | BK13: 0.099 | BL13: 0.031 | BM13: 0.005 | BN13: 0.068 | BO13: 0 | BP13: 0.196 | BQ13: 0.137 | BR13: 0.017 | BS13: 0.025 | BT13: 0.021 | BU13: 0 | BV13: 0.027 | BW13: 0.052 | BX13: 0.032 | BY13: 0.029 | BZ13: 0.026 | CA13: 0.095 | CB13: 0.078 | CC13: 0.002 | CD13: 0.019 | CE13: 0.258 | CF13: 0.276 | CG13: 0.158 | CH13: 0.299 | CI13: 0 | CJ13: 0.038 | CK13: 0.094 | CL13: 0.086 | CM13: 0.102 | CN13: 0.077
A14: 10 | B14: 4.5 | C14: 0 | D14: 0 | E14: 0 | F14: 0 | G14: 0.036 | H14: 0 | I14: 0 | J14: 0 | K14: 0 | L14: 0.005 | M14: 0 | N14: 0 | O14: 0 | P14: 0 | Q14: 0 | R14: 0 | S14: 0.095 | T14: 0 | U14: 0 | V14: 0 | W14: 0 | X14: 0 | Y14: 0 | Z14: 0 | AA14: 0.033 | AB14: 0 | AC14: 0.006 | AD14: 0 | AE14: 0.058 | AF14: 0 | AG14: 0 | AH14: 0 | AI14: 0.015 | AJ14: 0.036 | AK14: 0.015 | AL14: 0 | AM14: 0 | AN14: 0 | AO14: 0.0002 | AP14: 0 | AQ14: 0.016 | AR14: 0 | AS14: 0 | AT14: 0.055 | AU14: 0 | AV14: 0 | AW14: 0 | AX14: 0.075 | AY14: 0.014 | AZ14: 0 | BA14: 0.075 | BB14: 0 | BC14: 0 | BD14: 0 | BE14: 0 | BF14: 0.031 | BG14: 0.027 | BH14: 0 | BI14: 0.035 | BJ14: 0 | BK14: 0 | BL14: 0 | BM14: 0 | BN14: 0.002 | BO14: 0 | BP14: 0 | BQ14: 0 | BR14: 0 | BS14: 0.007 | BT14: 0.082 | BU14: 0 | BV14: 0 | BW14: 0 | BX14: 0.136 | BY14: 0 | BZ14: 0 | CA14: 0 | CB14: 0 | CC14: 0 | CD14: 0.031 | CE14: 0 | CF14: 0 | CG14: 0 | CH14: 0.026 | CI14: 0 | CJ14: 0 | CK14: 0 | CL14: 0 | CM14: 0 | CN14: 0
A15: 11 | B15: 5 | C15: 0 | D15: 0 | E15: 0 | F15: 0 | G15: 0 | H15: 0 | I15: 0 | J15: 0 | K15: 0 | L15: 0.031 | M15: 0 | N15: 0 | O15: 0 | P15: 0 | Q15: 0 | R15: 0 | S15: 0 | T15: 0 | U15: 0 | V15: 0 | W15: 0 | X15: 0 | Y15: 0 | Z15: 0 | AA15: 0 | AB15: 0 | AC15: 0 | AD15: 0 | AE15: 0 | AF15: 0 | AG15: 0 | AH15: 0 | AI15: 0 | AJ15: 0 | AK15: 0 | AL15: 0 | AM15: 0 | AN15: 0 | AO15: 0 | AP15: 0 | AQ15: 0 | AR15: 0 | AS15: 0 | AT15: 0 | AU15: 0 | AV15: 0 | AW15: 0 | AX15: 0 | AY15: 0 | AZ15: 0 | BA15: 0 | BB15: 0 | BC15: 0 | BD15: 0 | BE15: 0 | BF15: 0 | BG15: 0 | BH15: 0 | BI15: 0 | BJ15: 0 | BK15: 0 | BL15: 0 | BM15: 0 | BN15: 0 | BO15: 0 | BP15: 0 | BQ15: 0 | BR15: 0 | BS15: 0 | BT15: 0 | BU15: 0 | BV15: 0 | BW15: 0 | BX15: 0 | BY15: 0 | BZ15: 0 | CA15: 0 | CB15: 0 | CC15: 0 | CD15: 0 | CE15: 0 | CF15: 0 | CG15: 0 | CH15: 0 | CI15: 0 | CJ15: 0 | CK15: 0 | CL15: 0 | CM15: 0 | CN15: 0
A16: 12 | B16: 5.5 | C16: 0 | D16: 0 | E16: 0 | F16: 0 | G16: 0 | H16: 0 | I16: 0 | J16: 0 | K16: 0 | L16: 0 | M16: 0 | N16: 0 | O16: 0 | P16: 0 | Q16: 0 | R16: 0 | S16: 0 | T16: 0 | U16: 0 | V16: 0 | W16: 0 | X16: 1.128 | Y16: 0 | Z16: 0 | AA16: 0 | AB16: 0 | AC16: 0 | AD16: 0 | AE16: 0 | AF16: 0 | AG16: 0 | AH16: 0 | AI16: 0 | AJ16: 0 | AK16: 0 | AL16: 0 | AM16: 0 | AN16: 0 | AO16: 0 | AP16: 0 | AQ16: 0 | AR16: 0 | AS16: 0 | AT16: 0 | AU16: 0 | AV16: 0 | AW16: 0 | AX16: 0 | AY16: 0 | AZ16: 0 | BA16: 0 | BB16: 0 | BC16: 0 | BD16: 0 | BE16: 0 | BF16: 0 | BG16: 0 | BH16: 0 | BI16: 0 | BJ16: 0 | BK16: 0 | BL16: 0 | BM16: 0 | BN16: 0 | BO16: 0 | BP16: 0 | BQ16: 0 | BR16: 0 | BS16: 0 | BT16: 0 | BU16: 0 | BV16: 0 | BW16: 0 | BX16: 0 | BY16: 0 | BZ16: 0 | CA16: 0 | CB16: 0 | CC16: 0 | CD16: 0 | CE16: 0 | CF16: 0 | CG16: 0 | CH16: 0 | CI16: 0 | CJ16: 0 | CK16: 0 | CL16: 0 | CM16: 0 | CN16: 0
... A52: 48 | B52: 23.5 | C52: 0.501 | D52: 0.165 | E52: 0.743 | F52: 0.601 | G52: 0.413 | H52: 0.058 | I52: 1.1 | J52: 0.046 | K52: 0 | L52: 0.193 | M52: 0.395 | N52: 0.218 | O52: 0.049 | P52: 0 | Q52: 0 | R52: 0.075 | S52: 0.322 | T52: 0.235 | U52: 0.078 | V52: 0.088 | W52: 0.056 | X52: 0.244 | Y52: 0.069 | Z52: 0.225 | AA52: 0.054 | AB52: 1.44 | AC52: 0.176 | AD52: 0.167 | AE52: 0.171 | AF52: 0.224 | AG52: 0.089 | AH52: 0.074 | AI52: 0.149 | AJ52: 1.405 | AK52: 0.171 | AL52: 0.991 | AM52: 0 | AN52: 0.153 | AO52: 0.572 | AP52: 0.193 | AQ52: 0 | AR52: 0.161 | AS52: 0 | AT52: 0.305 | AU52: 0.236 | AV52: 0.473 | AW52: 0 | AX52: 0.169 | AY52: 0.794 | AZ52: 0.135 | BA52: 0.203 | BB52: 0.142 | BC52: 0.063 | BD52: 0.646 | BE52: 0.162 | BF52: 0.05 | BG52: 0.056 | BH52: 0.13 | BI52: 0.168 | BJ52: 0.049 | BK52: 0.187 | BL52: 0.123 | BM52: 0.055 | BN52: 0.126 | BO52: 0.171 | BP52: 0.342 | BQ52: 0.113 | BR52: 0.244 | BS52: 0.044 | BT52: 0.46 | BU52: 0.052 | BV52: 0.477 | BW52: 0.784 | BX52: 0.306 | BY52: 0.317 | BZ52: 0.113 | CA52: 0.16 | CB52: 0.231 | CC52: 0.301 | CD52: 0.303 | CE52: 0.305 | CF52: 0.382 | CG52: 0 | CH52: 0.12 | CI52: 0.718 | CJ52: 0.11 | CK52: 0.649 | CL52: 0.03 | CM52: 0.405 | CN52: 0.104

Sheet 7. PV allocation (per period)
A1: TR9 PV allocation — per half-hour
A2: VIOLET = aggregated live from the raw sheets 3–6 (SUM / SUMIF). AMBER = priority split (MIN formulas): PV → prosumer load → battery → customer load → export.
A4: period | B4: hour (h) | C4: PV (kW) | D4: prosumer load (kW) | E4: customer load (kW) | F4: batt charge (kW) | G4: batt discharge (kW) | H4: batt net =chg−dis | I4: PV→ prosumer | J4: PV→ battery | K4: PV→ customer | L4: PV→ export | M4: customer ←grid
A5: 1 | B5: 0 | C5: =SUM('3. Raw PV per load'!C5:C176) -> 0 | D5: =SUMIF('4. Raw load per load'!$B$5:$B$176,"prosumer",'4. Raw load per load'!C5:C176) -> 20.9812 | E5: =SUMIF('4. Raw load per load'!$B$5:$B$176,"customer",'4. Raw load per load'!C5:C176) -> 19.519 | F5: =SUM('5. Raw batt charge'!C5:CN5) -> 0 | G5: =SUM('6. Raw batt discharge'!C5:CN5) -> 20.983 | H5: =F5-G5 -> -20.983 | I5: =MIN(C5,D5) -> 0 | J5: =MIN(C5-I5,MAX(0,H5)) -> 0 | K5: =MIN(C5-I5-J5,E5) -> 0 | L5: =C5-I5-J5-K5 -> 0 | M5: =E5-K5 -> 19.519
A6: 2 | B6: 0.5 | C6: =SUM('3. Raw PV per load'!D5:D176) -> 0 | D6: =SUMIF('4. Raw load per load'!$B$5:$B$176,"prosumer",'4. Raw load per load'!D5:D176) -> 18.9665 | E6: =SUMIF('4. Raw load per load'!$B$5:$B$176,"customer",'4. Raw load per load'!D5:D176) -> 16.3714 | F6: =SUM('5. Raw batt charge'!C6:CN6) -> 0 | G6: =SUM('6. Raw batt discharge'!C6:CN6) -> 18.967 | H6: =F6-G6 -> -18.967 | I6: =MIN(C6,D6) -> 0 | J6: =MIN(C6-I6,MAX(0,H6)) -> 0 | K6: =MIN(C6-I6-J6,E6) -> 0 | L6: =C6-I6-J6-K6 -> 0 | M6: =E6-K6 -> 16.3714
A7: 3 | B7: 1 | C7: =SUM('3. Raw PV per load'!E5:E176) -> 0 | D7: =SUMIF('4. Raw load per load'!$B$5:$B$176,"prosumer",'4. Raw load per load'!E5:E176) -> 14.6159 | E7: =SUMIF('4. Raw load per load'!$B$5:$B$176,"customer",'4. Raw load per load'!E5:E176) -> 13.4279 | F7: =SUM('5. Raw batt charge'!C7:CN7) -> 0 | G7: =SUM('6. Raw batt discharge'!C7:CN7) -> 14.449 | H7: =F7-G7 -> -14.449 | I7: =MIN(C7,D7) -> 0 | J7: =MIN(C7-I7,MAX(0,H7)) -> 0 | K7: =MIN(C7-I7-J7,E7) -> 0 | L7: =C7-I7-J7-K7 -> 0 | M7: =E7-K7 -> 13.4279
A8: 4 | B8: 1.5 | C8: =SUM('3. Raw PV per load'!F5:F176) -> 0 | D8: =SUMIF('4. Raw load per load'!$B$5:$B$176,"prosumer",'4. Raw load per load'!F5:F176) -> 13.148 | E8: =SUMIF('4. Raw load per load'!$B$5:$B$176,"customer",'4. Raw load per load'!F5:F176) -> 11.0852 | F8: =SUM('5. Raw batt charge'!C8:CN8) -> 0 | G8: =SUM('6. Raw batt discharge'!C8:CN8) -> 12.225 | H8: =F8-G8 -> -12.225 | I8: =MIN(C8,D8) -> 0 | J8: =MIN(C8-I8,MAX(0,H8)) -> 0 | K8: =MIN(C8-I8-J8,E8) -> 0 | L8: =C8-I8-J8-K8 -> 0 | M8: =E8-K8 -> 11.0852
A9: 5 | B9: 2 | C9: =SUM('3. Raw PV per load'!G5:G176) -> 0 | D9: =SUMIF('4. Raw load per load'!$B$5:$B$176,"prosumer",'4. Raw load per load'!G5:G176) -> 12.762 | E9: =SUMIF('4. Raw load per load'!$B$5:$B$176,"customer",'4. Raw load per load'!G5:G176) -> 11.2356 | F9: =SUM('5. Raw batt charge'!C9:CN9) -> 0 | G9: =SUM('6. Raw batt discharge'!C9:CN9) -> 11.412 | H9: =F9-G9 -> -11.412 | I9: =MIN(C9,D9) -> 0 | J9: =MIN(C9-I9,MAX(0,H9)) -> 0 | K9: =MIN(C9-I9-J9,E9) -> 0 | L9: =C9-I9-J9-K9 -> 0 | M9: =E9-K9 -> 11.2356
A10: 6 | B10: 2.5 | C10: =SUM('3. Raw PV per load'!H5:H176) -> 0 | D10: =SUMIF('4. Raw load per load'!$B$5:$B$176,"prosumer",'4. Raw load per load'!H5:H176) -> 11.8935 | E10: =SUMIF('4. Raw load per load'!$B$5:$B$176,"customer",'4. Raw load per load'!H5:H176) -> 10.2205 | F10: =SUM('5. Raw batt charge'!C10:CN10) -> 0 | G10: =SUM('6. Raw batt discharge'!C10:CN10) -> 10.622 | H10: =F10-G10 -> -10.622 | I10: =MIN(C10,D10) -> 0 | J10: =MIN(C10-I10,MAX(0,H10)) -> 0 | K10: =MIN(C10-I10-J10,E10) -> 0 | L10: =C10-I10-J10-K10 -> 0 | M10: =E10-K10 -> 10.2205
A11: 7 | B11: 3 | C11: =SUM('3. Raw PV per load'!I5:I176) -> 0 | D11: =SUMIF('4. Raw load per load'!$B$5:$B$176,"prosumer",'4. Raw load per load'!I5:I176) -> 11.9806 | E11: =SUMIF('4. Raw load per load'!$B$5:$B$176,"customer",'4. Raw load per load'!I5:I176) -> 9.6378 | F11: =SUM('5. Raw batt charge'!C11:CN11) -> 0 | G11: =SUM('6. Raw batt discharge'!C11:CN11) -> 11.331 | H11: =F11-G11 -> -11.331 | I11: =MIN(C11,D11) -> 0 | J11: =MIN(C11-I11,MAX(0,H11)) -> 0 | K11: =MIN(C11-I11-J11,E11) -> 0 | L11: =C11-I11-J11-K11 -> 0 | M11: =E11-K11 -> 9.6378
A12: 8 | B12: 3.5 | C12: =SUM('3. Raw PV per load'!J5:J176) -> 0.2379 | D12: =SUMIF('4. Raw load per load'!$B$5:$B$176,"prosumer",'4. Raw load per load'!J5:J176) -> 13.0479 | E12: =SUMIF('4. Raw load per load'!$B$5:$B$176,"customer",'4. Raw load per load'!J5:J176) -> 10.5542 | F12: =SUM('5. Raw batt charge'!C12:CN12) -> 0 | G12: =SUM('6. Raw batt discharge'!C12:CN12) -> 11.287 | H12: =F12-G12 -> -11.287 | I12: =MIN(C12,D12) -> 0.2379 | J12: =MIN(C12-I12,MAX(0,H12)) -> 0 | K12: =MIN(C12-I12-J12,E12) -> 0 | L12: =C12-I12-J12-K12 -> 0 | M12: =E12-K12 -> 10.5542
A13: 9 | B13: 4 | C13: =SUM('3. Raw PV per load'!K5:K176) -> 3.45 | D13: =SUMIF('4. Raw load per load'!$B$5:$B$176,"prosumer",'4. Raw load per load'!K5:K176) -> 11.0102 | E13: =SUMIF('4. Raw load per load'!$B$5:$B$176,"customer",'4. Raw load per load'!K5:K176) -> 9.1705 | F13: =SUM('5. Raw batt charge'!C13:CN13) -> 0.024 | G13: =SUM('6. Raw batt discharge'!C13:CN13) -> 6.851 | H13: =F13-G13 -> -6.827 | I13: =MIN(C13,D13) -> 3.45 | J13: =MIN(C13-I13,MAX(0,H13)) -> 0 | K13: =MIN(C13-I13-J13,E13) -> 0 | L13: =C13-I13-J13-K13 -> 0 | M13: =E13-K13 -> 9.1705
