Workbook

Sheet 1. Overview
B2: TR1 — Where does the PV energy go?
B3: Prosumers vs. pure customers — every kWh traced from the raw model inputs
B5: Purpose
B6: This workbook accounts for every kWh of PV generated on transformer TR1 over one representative day, and it is fully auditable: nothing is hand-typed except the raw model outputs. Follow the data chain below — each step is a live formula, so changing any raw number updates everything.
B10: The data chain (how each number is built)
B11: Sheet 3 · Raw PV per load | C11: The PV profile of every connection, 48 half-hours. Copied verbatim from TR1_load_PV_48periods.xlsx (sheet PV_generation_kW). Customers = 0.
B12: Sheet 4 · Raw load per load | C12: The load profile of every connection, 48 half-hours, tagged prosumer / customer. Copied from TR1_load_PV_48periods.xlsx (sheet Load_P_kW).
B13: Sheet 5 · Raw batt charge | C13: Charging power of every battery, 48 half-hours. Copied from the rolling dispatch TR1_analysis_data.xlsx (sheet Charge_kW).
B14: Sheet 6 · Raw batt discharge | C14: Discharging power of every battery. Copied from the same run (Discharge_kW).
B15: Sheet 7 · PV allocation | C15: Per half-hour: the five blue inputs are AGGREGATED from sheets 3–6 by SUM / SUMIF; the amber columns then split the PV by the priority rule.
B16: Sheets 1 & 8 · Results | C16: Daily totals (Σ×0.5 h) and shares. Every headline cell links to sheet 7.
B18: The aggregation formulas (sheet 7, per half-hour)
B19: PV (all)
B20: prosumer load
B21: customer load
B22: battery charge
B23: battery discharge
B25: Headline results (all linked live to sheet 7)
B26: Quantity | C26: Value | D26: Unit
B27: Prosumers (PV + battery) | C27: 77 | D27: connections
B28: Pure customers (load only) | C28: 55 | D28: connections
B29: PV generated | C29: ='7. PV allocation (per period)'!C53 -> 1796.988 | D29: kWh/day
B30: PV → prosumers' own load (direct) | C30: ='7. PV allocation (per period)'!I53 -> 357.82515 | D30: kWh/day
B31: PV → battery storage | C31: ='7. PV allocation (per period)'!J53 -> 258.7837 | D31: kWh/day
B32: PV → customers | C32: ='7. PV allocation (per period)'!K53 -> 193.7687 | D32: kWh/day
B33: PV → export to grid | C33: ='7. PV allocation (per period)'!L53 -> 986.6104 | D33: kWh/day
B34: PV share reaching customers | C34: ='7. PV allocation (per period)'!K53/'7. PV allocation (per period)'!C53 -> 0.10782972 | D34: % of PV
B35: Customer load covered by PV | C35: ='7. PV allocation (per period)'!K53/'7. PV allocation (per period)'!E53 -> 0.53780755 | D35: % of customer load
B36: Customer load covered by grid | C36: ='7. PV allocation (per period)'!M53/'7. PV allocation (per period)'!E53 -> 0.46219245 | D36: % of customer load
B39: Colour key & provenance
B40: • LIGHT-BLUE cell = data belonging to a prosumer (its rooftop PV, load, or battery). WHITE = a pure customer (load only). On sheet 7: VIOLET = value aggregated live from the raw sheets (SUM/SUMIF); AMBER = allocation formula; GREEN = daily total (Σ × 0.5 h).
B41: • Per-load PV & load profiles: results/tables/TR1_load_PV_48periods.xlsx (built from OpData.xls).
B42: • Per-battery charge/discharge: TR1_analysis/01_DAILY_ROLLING_DISPATCH/TR1_analysis_data.xlsx (exact-QCP rolling dispatch, RunFOR_Rolling, CPLEX).
B43: • Load classification (PV size > 0 = prosumer): sheet 'Customers' of the load/PV workbook.
B44: • Method note: priority energy allocation per half-hour; downstream network + battery round-trip losses (~3–4% of PV) are not separated out in the per-period disposition.

Sheet 2. Load classification
A1: TR1 load classification — 132 connections
A2: 77 prosumers (PV + battery) · 55 pure customers (load only)
A4: ID | B4: Load name | C4: Bus | D4: Phase | E4: PV size (kW) | F4: Type
A5: 1 | B5: Load_TR1_F1_1 | C5: TR1_one38 | D5: 2 | E5: 0 | F5: customer
A6: 2 | B6: Load_TR1_F1_10 | C6: TR1_one195 | D6: 3 | E6: 0 | F6: customer
A7: 4 | B7: Load_TR1_F1_12 | C7: TR1_one235 | D7: 1 | E7: 0 | F7: customer
A8: 5 | B8: Load_TR1_F1_13 | C8: TR1_one242 | D8: 2 | E8: 0 | F8: customer
A9: 6 | B9: Load_TR1_F1_14 | C9: TR1_one252 | D9: 3 | E9: 0 | F9: customer
A10: 7 | B10: Load_TR1_F1_15 | C10: TR1_one260 | D10: 3 | E10: 0 | F10: customer
A11: 8 | B11: Load_TR1_F1_16 | C11: TR1_one280 | D11: 1 | E11: 0 | F11: customer
A12: 9 | B12: Load_TR1_F1_17 | C12: TR1_one287 | D12: 2 | E12: 0 | F12: customer
A13: 10 | B13: Load_TR1_F1_18 | C13: TR1_one299 | D13: 2 | E13: 0 | F13: customer
A14: 12 | B14: Load_TR1_F1_2 | C14: TR1_one42 | D14: 2 | E14: 0 | F14: customer
A15: 15 | B15: Load_TR1_F1_22 | C15: TR1_one328 | D15: 1 | E15: 0 | F15: customer
A16: 16 | B16: Load_TR1_F1_23 | C16: TR1_one345 | D16: 1 | E16: 0 | F16: customer
... A136: 132 | B136: Load_TR1_F6_9 | C136: TR1_six128 | D136: 2 | E136: 3 | F136: prosumer

Sheet 3. Raw PV per load
A1: Raw PV per load
A2: Verbatim copy of PV_generation_kW (TR1_load_PV_48periods.xlsx). One row per connection, 48 half-hours (kW).
A4: Load name | B4: Type | C4: p1 | D4: p2 | E4: p3 | F4: p4 | G4: p5 | H4: p6 | I4: p7 | J4: p8 | K4: p9 | L4: p10 | M4: p11 | N4: p12 | O4: p13 | P4: p14 | Q4: p15 | R4: p16 | S4: p17 | T4: p18 | U4: p19 | V4: p20 | W4: p21 | X4: p22 | Y4: p23 | Z4: p24 | AA4: p25 | AB4: p26 | AC4: p27 | AD4: p28 | AE4: p29 | AF4: p30 | AG4: p31 | AH4: p32 | AI4: p33 | AJ4: p34 | AK4: p35 | AL4: p36 | AM4: p37 | AN4: p38 | AO4: p39 | AP4: p40 | AQ4: p41 | AR4: p42 | AS4: p43 | AT4: p44 | AU4: p45 | AV4: p46 | AW4: p47 | AX4: p48
A5: Load_TR1_F1_1 | B5: customer | C5: 0 | D5: 0 | E5: 0 | F5: 0 | G5: 0 | H5: 0 | I5: 0 | J5: 0 | K5: 0 | L5: 0 | M5: 0 | N5: 0 | O5: 0 | P5: 0 | Q5: 0 | R5: 0 | S5: 0 | T5: 0 | U5: 0 | V5: 0 | W5: 0 | X5: 0 | Y5: 0 | Z5: 0 | AA5: 0 | AB5: 0 | AC5: 0 | AD5: 0 | AE5: 0 | AF5: 0 | AG5: 0 | AH5: 0 | AI5: 0 | AJ5: 0 | AK5: 0 | AL5: 0 | AM5: 0 | AN5: 0 | AO5: 0 | AP5: 0 | AQ5: 0 | AR5: 0 | AS5: 0 | AT5: 0 | AU5: 0 | AV5: 0 | AW5: 0 | AX5: 0
A6: Load_TR1_F1_10 | B6: customer | C6: 0 | D6: 0 | E6: 0 | F6: 0 | G6: 0 | H6: 0 | I6: 0 | J6: 0 | K6: 0 | L6: 0 | M6: 0 | N6: 0 | O6: 0 | P6: 0 | Q6: 0 | R6: 0 | S6: 0 | T6: 0 | U6: 0 | V6: 0 | W6: 0 | X6: 0 | Y6: 0 | Z6: 0 | AA6: 0 | AB6: 0 | AC6: 0 | AD6: 0 | AE6: 0 | AF6: 0 | AG6: 0 | AH6: 0 | AI6: 0 | AJ6: 0 | AK6: 0 | AL6: 0 | AM6: 0 | AN6: 0 | AO6: 0 | AP6: 0 | AQ6: 0 | AR6: 0 | AS6: 0 | AT6: 0 | AU6: 0 | AV6: 0 | AW6: 0 | AX6: 0
A7: Load_TR1_F1_11 | B7: prosumer | C7: 0 | D7: 0 | E7: 0 | F7: 0 | G7: 0 | H7: 0 | I7: 0 | J7: 0.0034 | K7: 0.0497 | L7: 0.2326 | M7: 0.4613 | N7: 0.7419 | O7: 1.0479 | P7: 1.3577 | Q7: 1.666 | R7: 1.9746 | S7: 2.2643 | T7: 2.5367 | U7: 2.7686 | V7: 2.9664 | W7: 3.14 | X7: 3.2833 | Y7: 3.385 | Z7: 3.4296 | AA7: 3.4425 | AB7: 3.4183 | AC7: 3.3372 | AD7: 3.2133 | AE7: 3.0655 | AF7: 2.8782 | AG7: 2.6791 | AH7: 2.4396 | AI7: 2.1698 | AJ7: 1.8441 | AK7: 1.5392 | AL7: 1.2259 | AM7: 0.9229 | AN7: 0.6308 | AO7: 0.3683 | AP7: 0.1072 | AQ7: 0.0198 | AR7: 0 | AS7: 0 | AT7: 0 | AU7: 0 | AV7: 0 | AW7: 0 | AX7: 0
A8: Load_TR1_F1_12 | B8: customer | C8: 0 | D8: 0 | E8: 0 | F8: 0 | G8: 0 | H8: 0 | I8: 0 | J8: 0 | K8: 0 | L8: 0 | M8: 0 | N8: 0 | O8: 0 | P8: 0 | Q8: 0 | R8: 0 | S8: 0 | T8: 0 | U8: 0 | V8: 0 | W8: 0 | X8: 0 | Y8: 0 | Z8: 0 | AA8: 0 | AB8: 0 | AC8: 0 | AD8: 0 | AE8: 0 | AF8: 0 | AG8: 0 | AH8: 0 | AI8: 0 | AJ8: 0 | AK8: 0 | AL8: 0 | AM8: 0 | AN8: 0 | AO8: 0 | AP8: 0 | AQ8: 0 | AR8: 0 | AS8: 0 | AT8: 0 | AU8: 0 | AV8: 0 | AW8: 0 | AX8: 0
A9: Load_TR1_F1_13 | B9: customer | C9: 0 | D9: 0 | E9: 0 | F9: 0 | G9: 0 | H9: 0 | I9: 0 | J9: 0 | K9: 0 | L9: 0 | M9: 0 | N9: 0 | O9: 0 | P9: 0 | Q9: 0 | R9: 0 | S9: 0 | T9: 0 | U9: 0 | V9: 0 | W9: 0 | X9: 0 | Y9: 0 | Z9: 0 | AA9: 0 | AB9: 0 | AC9: 0 | AD9: 0 | AE9: 0 | AF9: 0 | AG9: 0 | AH9: 0 | AI9: 0 | AJ9: 0 | AK9: 0 | AL9: 0 | AM9: 0 | AN9: 0 | AO9: 0 | AP9: 0 | AQ9: 0 | AR9: 0 | AS9: 0 | AT9: 0 | AU9: 0 | AV9: 0 | AW9: 0 | AX9: 0
A10: Load_TR1_F1_14 | B10: customer | C10: 0 | D10: 0 | E10: 0 | F10: 0 | G10: 0 | H10: 0 | I10: 0 | J10: 0 | K10: 0 | L10: 0 | M10: 0 | N10: 0 | O10: 0 | P10: 0 | Q10: 0 | R10: 0 | S10: 0 | T10: 0 | U10: 0 | V10: 0 | W10: 0 | X10: 0 | Y10: 0 | Z10: 0 | AA10: 0 | AB10: 0 | AC10: 0 | AD10: 0 | AE10: 0 | AF10: 0 | AG10: 0 | AH10: 0 | AI10: 0 | AJ10: 0 | AK10: 0 | AL10: 0 | AM10: 0 | AN10: 0 | AO10: 0 | AP10: 0 | AQ10: 0 | AR10: 0 | AS10: 0 | AT10: 0 | AU10: 0 | AV10: 0 | AW10: 0 | AX10: 0
A11: Load_TR1_F1_15 | B11: customer | C11: 0 | D11: 0 | E11: 0 | F11: 0 | G11: 0 | H11: 0 | I11: 0 | J11: 0 | K11: 0 | L11: 0 | M11: 0 | N11: 0 | O11: 0 | P11: 0 | Q11: 0 | R11: 0 | S11: 0 | T11: 0 | U11: 0 | V11: 0 | W11: 0 | X11: 0 | Y11: 0 | Z11: 0 | AA11: 0 | AB11: 0 | AC11: 0 | AD11: 0 | AE11: 0 | AF11: 0 | AG11: 0 | AH11: 0 | AI11: 0 | AJ11: 0 | AK11: 0 | AL11: 0 | AM11: 0 | AN11: 0 | AO11: 0 | AP11: 0 | AQ11: 0 | AR11: 0 | AS11: 0 | AT11: 0 | AU11: 0 | AV11: 0 | AW11: 0 | AX11: 0
A12: Load_TR1_F1_16 | B12: customer | C12: 0 | D12: 0 | E12: 0 | F12: 0 | G12: 0 | H12: 0 | I12: 0 | J12: 0 | K12: 0 | L12: 0 | M12: 0 | N12: 0 | O12: 0 | P12: 0 | Q12: 0 | R12: 0 | S12: 0 | T12: 0 | U12: 0 | V12: 0 | W12: 0 | X12: 0 | Y12: 0 | Z12: 0 | AA12: 0 | AB12: 0 | AC12: 0 | AD12: 0 | AE12: 0 | AF12: 0 | AG12: 0 | AH12: 0 | AI12: 0 | AJ12: 0 | AK12: 0 | AL12: 0 | AM12: 0 | AN12: 0 | AO12: 0 | AP12: 0 | AQ12: 0 | AR12: 0 | AS12: 0 | AT12: 0 | AU12: 0 | AV12: 0 | AW12: 0 | AX12: 0
A13: Load_TR1_F1_17 | B13: customer | C13: 0 | D13: 0 | E13: 0 | F13: 0 | G13: 0 | H13: 0 | I13: 0 | J13: 0 | K13: 0 | L13: 0 | M13: 0 | N13: 0 | O13: 0 | P13: 0 | Q13: 0 | R13: 0 | S13: 0 | T13: 0 | U13: 0 | V13: 0 | W13: 0 | X13: 0 | Y13: 0 | Z13: 0 | AA13: 0 | AB13: 0 | AC13: 0 | AD13: 0 | AE13: 0 | AF13: 0 | AG13: 0 | AH13: 0 | AI13: 0 | AJ13: 0 | AK13: 0 | AL13: 0 | AM13: 0 | AN13: 0 | AO13: 0 | AP13: 0 | AQ13: 0 | AR13: 0 | AS13: 0 | AT13: 0 | AU13: 0 | AV13: 0 | AW13: 0 | AX13: 0
A14: Load_TR1_F1_18 | B14: customer | C14: 0 | D14: 0 | E14: 0 | F14: 0 | G14: 0 | H14: 0 | I14: 0 | J14: 0 | K14: 0 | L14: 0 | M14: 0 | N14: 0 | O14: 0 | P14: 0 | Q14: 0 | R14: 0 | S14: 0 | T14: 0 | U14: 0 | V14: 0 | W14: 0 | X14: 0 | Y14: 0 | Z14: 0 | AA14: 0 | AB14: 0 | AC14: 0 | AD14: 0 | AE14: 0 | AF14: 0 | AG14: 0 | AH14: 0 | AI14: 0 | AJ14: 0 | AK14: 0 | AL14: 0 | AM14: 0 | AN14: 0 | AO14: 0 | AP14: 0 | AQ14: 0 | AR14: 0 | AS14: 0 | AT14: 0 | AU14: 0 | AV14: 0 | AW14: 0 | AX14: 0
A15: Load_TR1_F1_19 | B15: prosumer | C15: 0 | D15: 0 | E15: 0 | F15: 0 | G15: 0 | H15: 0 | I15: 0 | J15: 0.0034 | K15: 0.0497 | L15: 0.2326 | M15: 0.4613 | N15: 0.7419 | O15: 1.0479 | P15: 1.3577 | Q15: 1.666 | R15: 1.9746 | S15: 2.2643 | T15: 2.5367 | U15: 2.7686 | V15: 2.9664 | W15: 3.14 | X15: 3.2833 | Y15: 3.385 | Z15: 3.4296 | AA15: 3.4425 | AB15: 3.4183 | AC15: 3.3372 | AD15: 3.2133 | AE15: 3.0655 | AF15: 2.8782 | AG15: 2.6791 | AH15: 2.4396 | AI15: 2.1698 | AJ15: 1.8441 | AK15: 1.5392 | AL15: 1.2259 | AM15: 0.9229 | AN15: 0.6308 | AO15: 0.3683 | AP15: 0.1072 | AQ15: 0.0198 | AR15: 0 | AS15: 0 | AT15: 0 | AU15: 0 | AV15: 0 | AW15: 0 | AX15: 0
A16: Load_TR1_F1_2 | B16: customer | C16: 0 | D16: 0 | E16: 0 | F16: 0 | G16: 0 | H16: 0 | I16: 0 | J16: 0 | K16: 0 | L16: 0 | M16: 0 | N16: 0 | O16: 0 | P16: 0 | Q16: 0 | R16: 0 | S16: 0 | T16: 0 | U16: 0 | V16: 0 | W16: 0 | X16: 0 | Y16: 0 | Z16: 0 | AA16: 0 | AB16: 0 | AC16: 0 | AD16: 0 | AE16: 0 | AF16: 0 | AG16: 0 | AH16: 0 | AI16: 0 | AJ16: 0 | AK16: 0 | AL16: 0 | AM16: 0 | AN16: 0 | AO16: 0 | AP16: 0 | AQ16: 0 | AR16: 0 | AS16: 0 | AT16: 0 | AU16: 0 | AV16: 0 | AW16: 0 | AX16: 0
... A136: Load_TR1_F6_9 | B136: prosumer | C136: 0 | D136: 0 | E136: 0 | F136: 0 | G136: 0 | H136: 0 | I136: 0 | J136: 0.0026 | K136: 0.0373 | L136: 0.1744 | M136: 0.346 | N136: 0.5564 | O136: 0.7859 | P136: 1.0183 | Q136: 1.2495 | R136: 1.481 | S136: 1.6982 | T136: 1.9025 | U136: 2.0764 | V136: 2.2248 | W136: 2.355 | X136: 2.4625 | Y136: 2.5387 | Z136: 2.5722 | AA136: 2.5819 | AB136: 2.5637 | AC136: 2.5029 | AD136: 2.41 | AE136: 2.2991 | AF136: 2.1586 | AG136: 2.0093 | AH136: 1.8297 | AI136: 1.6274 | AJ136: 1.3831 | AK136: 1.1544 | AL136: 0.9195 | AM136: 0.6922 | AN136: 0.4731 | AO136: 0.2762 | AP136: 0.0804 | AQ136: 0.0148 | AR136: 0 | AS136: 0 | AT136: 0 | AU136: 0 | AV136: 0 | AW136: 0 | AX136: 0

Sheet 4. Raw load per load
A1: Raw load per load
A2: Verbatim copy of Load_P_kW (TR1_load_PV_48periods.xlsx), tagged by type. One row per connection, 48 half-hours (kW).
A4: Load name | B4: Type | C4: p1 | D4: p2 | E4: p3 | F4: p4 | G4: p5 | H4: p6 | I4: p7 | J4: p8 | K4: p9 | L4: p10 | M4: p11 | N4: p12 | O4: p13 | P4: p14 | Q4: p15 | R4: p16 | S4: p17 | T4: p18 | U4: p19 | V4: p20 | W4: p21 | X4: p22 | Y4: p23 | Z4: p24 | AA4: p25 | AB4: p26 | AC4: p27 | AD4: p28 | AE4: p29 | AF4: p30 | AG4: p31 | AH4: p32 | AI4: p33 | AJ4: p34 | AK4: p35 | AL4: p36 | AM4: p37 | AN4: p38 | AO4: p39 | AP4: p40 | AQ4: p41 | AR4: p42 | AS4: p43 | AT4: p44 | AU4: p45 | AV4: p46 | AW4: p47 | AX4: p48
A5: Load_TR1_F1_1 | B5: customer | C5: 0.1728 | D5: 0.1488 | E5: 0.1515 | F5: 0.2622 | G5: 0.1579 | H5: 0.1852 | I5: 0.1683 | J5: 0.053 | K5: 0.1215 | L5: 0.1709 | M5: 0.1807 | N5: 0.1728 | O5: 0.2473 | P5: 0.053 | Q5: 0.3006 | R5: 0.3354 | S5: 1.2371 | T5: 0.3016 | U5: 0.3932 | V5: 0.3972 | W5: 0.3368 | X5: 1.0621 | Y5: 0.6625 | Z5: 0.3886 | AA5: 0.0929 | AB5: 0.232 | AC5: 0.1743 | AD5: 0.3792 | AE5: 0.1691 | AF5: 0.3555 | AG5: 0.1618 | AH5: 0.2703 | AI5: 0.3229 | AJ5: 0.2858 | AK5: 0.3273 | AL5: 0.1983 | AM5: 1.6876 | AN5: 0.2883 | AO5: 0.2392 | AP5: 0.7353 | AQ5: 1.6555 | AR5: 2.2482 | AS5: 0.915 | AT5: 0.6569 | AU5: 1.542 | AV5: 0.7453 | AW5: 0.6293 | AX5: 0.6921
A6: Load_TR1_F1_10 | B6: customer | C6: 0.2614 | D6: 0.1504 | E6: 0.0916 | F6: 0.3191 | G6: 0.0588 | H6: 0.347 | I6: 0.0685 | J6: 0.2293 | K6: 0.1861 | L6: 0.124 | M6: 0.2538 | N6: 0.1279 | O6: 0.1937 | P6: 0.1854 | Q6: 0.2156 | R6: 1.0153 | S6: 0.3903 | T6: 0.146 | U6: 0.1504 | V6: 0.054 | W6: 0.1675 | X6: 0.2953 | Y6: 0.1856 | Z6: 0.4612 | AA6: 0.119 | AB6: 0.1229 | AC6: 0.3951 | AD6: 0.054 | AE6: 0.2549 | AF6: 0.5166 | AG6: 0.6905 | AH6: 0.3861 | AI6: 0.7 | AJ6: 0.6783 | AK6: 1.6196 | AL6: 4.291 | AM6: 2.5453 | AN6: 0.1406 | AO6: 0.4521 | AP6: 0.7723 | AQ6: 0.5788 | AR6: 1.4949 | AS6: 0.5698 | AT6: 0.2831 | AU6: 0.1677 | AV6: 0.0948 | AW6: 0.3207 | AX6: 0.054
A7: Load_TR1_F1_11 | B7: prosumer | C7: 0.1833 | D7: 0.2404 | E7: 0.1517 | F7: 0.223 | G7: 0.1409 | H7: 0.1484 | I7: 0.2789 | J7: 0.046 | K7: 0.1445 | L7: 0.2129 | M7: 0.0693 | N7: 0.2821 | O7: 0.1218 | P7: 0.1522 | Q7: 0.2674 | R7: 0.3476 | S7: 0.4452 | T7: 1.1229 | U7: 0.3797 | V7: 0.3114 | W7: 0.4319 | X7: 1.1413 | Y7: 0.4484 | Z7: 0.0771 | AA7: 0.2982 | AB7: 0.098 | AC7: 0.0536 | AD7: 0.3154 | AE7: 0.1042 | AF7: 0.1311 | AG7: 0.2961 | AH7: 0.046 | AI7: 0.4704 | AJ7: 0.1786 | AK7: 0.1123 | AL7: 0.249 | AM7: 0.2829 | AN7: 0.1967 | AO7: 0.2577 | AP7: 0.4576 | AQ7: 1.0054 | AR7: 0.7273 | AS7: 0.9693 | AT7: 0.5957 | AU7: 1.725 | AV7: 0.708 | AW7: 0.5263 | AX7: 0.5321
A8: Load_TR1_F1_12 | B8: customer | C8: 0.1863 | D8: 0.1472 | E8: 0.1732 | F8: 0.2747 | G8: 0.052 | H8: 0.0857 | I8: 0.2497 | J8: 0.0877 | K8: 0.2684 | L8: 0.1795 | M8: 0.1597 | N8: 0.1607 | O8: 0.1795 | P8: 0.2257 | Q8: 0.1568 | R8: 0.1444 | S8: 0.25 | T8: 0.052 | U8: 0.2001 | V8: 0.0639 | W8: 0.3198 | X8: 0.1162 | Y8: 0.171 | Z8: 0.1866 | AA8: 0.1785 | AB8: 0.058 | AC8: 0.266 | AD8: 0.1819 | AE8: 0.052 | AF8: 0.3959 | AG8: 1.2573 | AH8: 0.6164 | AI8: 0.9556 | AJ8: 1.5565 | AK8: 1.9744 | AL8: 1.5019 | AM8: 0.437 | AN8: 0.2018 | AO8: 0.1848 | AP8: 0.2093 | AQ8: 0.1866 | AR8: 0.1966 | AS8: 0.2513 | AT8: 0.0904 | AU8: 0.2094 | AV8: 0.2262 | AW8: 0.1027 | AX8: 0.0563
A9: Load_TR1_F1_13 | B9: customer | C9: 0.6131 | D9: 0.2 | E9: 0.047 | F9: 0.2566 | G9: 0.0612 | H9: 0.115 | I9: 0.047 | J9: 0.1717 | K9: 0.1461 | L9: 0.1075 | M9: 0.1395 | N9: 0.1858 | O9: 0.047 | P9: 0.1929 | Q9: 0.1249 | R9: 0.047 | S9: 0.2304 | T9: 0.3872 | U9: 0.2434 | V9: 0.2359 | W9: 0.3124 | X9: 0.2529 | Y9: 0.1873 | Z9: 0.1787 | AA9: 0.0966 | AB9: 0.2446 | AC9: 1.2986 | AD9: 0.2547 | AE9: 0.1046 | AF9: 0.2979 | AG9: 0.2664 | AH9: 0.047 | AI9: 0.1292 | AJ9: 0.1886 | AK9: 0.0699 | AL9: 0.121 | AM9: 0.0651 | AN9: 0.349 | AO9: 0.1189 | AP9: 0.3787 | AQ9: 0.2406 | AR9: 0.6588 | AS9: 0.3029 | AT9: 0.3207 | AU9: 0.1461 | AV9: 0.047 | AW9: 0.1075 | AX9: 0.0546
A10: Load_TR1_F1_14 | B10: customer | C10: 0.0727 | D10: 0.1196 | E10: 0.0915 | F10: 0.1683 | G10: 0.1515 | H10: 0.1383 | I10: 0.204 | J10: 0.1346 | K10: 0.1702 | L10: 0.1215 | M10: 0.1065 | N10: 0.1665 | O10: 0.054 | P10: 0.2115 | Q10: 0.0615 | R10: 0.0727 | S10: 0.2958 | T10: 0.4877 | U10: 0.2519 | V10: 0.2744 | W10: 0.3749 | X10: 1.6141 | Y10: 0.3934 | Z10: 0.5864 | AA10: 1.4142 | AB10: 0.8744 | AC10: 0.4191 | AD10: 0.3119 | AE10: 0.2326 | AF10: 0.3471 | AG10: 0.1149 | AH10: 0.2377 | AI10: 0.2125 | AJ10: 0.2375 | AK10: 0.19 | AL10: 0.1365 | AM10: 0.1149 | AN10: 0.2124 | AO10: 0.8871 | AP10: 0.4017 | AQ10: 0.4929 | AR10: 0.4979 | AS10: 0.5161 | AT10: 0.4558 | AU10: 0.7765 | AV10: 2.1796 | AW10: 0.4599 | AX10: 0.1324
A11: Load_TR1_F1_15 | B11: customer | C11: 0.1648 | D11: 0.0568 | E11: 0.026 | F11: 0.2317 | G11: 0.0672 | H11: 0.026 | I11: 0.026 | J11: 0.2343 | K11: 0.0646 | L11: 0.026 | M11: 0.026 | N11: 0.1879 | O11: 0.111 | P11: 0.1262 | Q11: 0.4975 | R11: 0.146 | S11: 0.6465 | T11: 0.5299 | U11: 0.5584 | V11: 0.7484 | W11: 0.5453 | X11: 0.4157 | Y11: 0.234 | Z11: 0.3272 | AA11: 0.2128 | AB11: 0.3512 | AC11: 1.7433 | AD11: 1.2534 | AE11: 0.1956 | AF11: 0.026 | AG11: 0.1872 | AH11: 0.1117 | AI11: 0.099 | AJ11: 0.1999 | AK11: 0.026 | AL11: 0.122 | AM11: 0.1769 | AN11: 0.0475 | AO11: 0.2514 | AP11: 0.0732 | AQ11: 0.056 | AR11: 0.2437 | AS11: 0.1697 | AT11: 0.2222 | AU11: 1.3685 | AV11: 0.6312 | AW11: 0.4549 | AX11: 0.142
A12: Load_TR1_F1_16 | B12: customer | C12: 0.2336 | D12: 0.1361 | E12: 0.059 | F12: 0.2004 | G12: 0.059 | H12: 0.1104 | I12: 0.149 | J12: 0.059 | K12: 0.2004 | L12: 0.059 | M12: 0.1875 | N12: 0.0719 | O12: 0.059 | P12: 0.059 | Q12: 0.2443 | R12: 0.2996 | S12: 0.2433 | T12: 0.3589 | U12: 0.2322 | V12: 0.2923 | W12: 0.9015 | X12: 0.5465 | Y12: 0.1683 | Z12: 0.0911 | AA12: 0.1297 | AB12: 0.1297 | AC12: 0.059 | AD12: 0.059 | AE12: 0.2329 | AF12: 0.2898 | AG12: 0.0738 | AH12: 0.3493 | AI12: 0.3378 | AJ12: 0.1805 | AK12: 0.2218 | AL12: 0.4635 | AM12: 0.4438 | AN12: 1.4101 | AO12: 0.5824 | AP12: 0.6825 | AQ12: 0.4531 | AR12: 0.3283 | AS12: 0.6732 | AT12: 0.9685 | AU12: 0.1757 | AV12: 0.3037 | AW12: 0.0847 | AX12: 0.1747
A13: Load_TR1_F1_17 | B13: customer | C13: 0.1091 | D13: 0.1519 | E13: 0.052 | F13: 0.209 | G13: 0.052 | H13: 0.052 | I13: 0.052 | J13: 0.2019 | K13: 0.0591 | L13: 0.1519 | M13: 0.1091 | N13: 0.1091 | O13: 0.1519 | P13: 0.052 | Q13: 0.2068 | R13: 0.3638 | S13: 0.2762 | T13: 0.1131 | U13: 0.455 | V13: 0.0882 | W13: 0.2776 | X13: 1.0528 | Y13: 1.5006 | Z13: 0.2141 | AA13: 0.4982 | AB13: 0.0597 | AC13: 0.5093 | AD13: 0.1108 | AE13: 0.2361 | AF13: 0.0892 | AG13: 0.236 | AH13: 0.0966 | AI13: 0.1608 | AJ13: 0.3327 | AK13: 0.1347 | AL13: 0.3078 | AM13: 0.052 | AN13: 0.209 | AO13: 0.052 | AP13: 0.052 | AQ13: 0.5694 | AR13: 0.4466 | AS13: 1.0521 | AT13: 1.1626 | AU13: 0.9625 | AV13: 0.6937 | AW13: 0.0591 | AX13: 0.2019
A14: Load_TR1_F1_18 | B14: customer | C14: 0.05 | D14: 0.2314 | E14: 0.05 | F14: 0.1489 | G14: 0.1324 | H14: 0.083 | I14: 0.1984 | J14: 0.05 | K14: 0.2314 | L14: 0.05 | M14: 0.05 | N14: 0.05 | O14: 0.1902 | P14: 0.0912 | Q14: 0.05 | R14: 0.0747 | S14: 0.4134 | T14: 0.2076 | U14: 0.2184 | V14: 0.1162 | W14: 0.1394 | X14: 0.1823 | Y14: 0.2149 | Z14: 0.05 | AA14: 0.1984 | AB14: 0.083 | AC14: 0.1491 | AD14: 0.2584 | AE14: 0.4931 | AF14: 0.3075 | AG14: 0.3458 | AH14: 0.3415 | AI14: 0.3189 | AJ14: 0.6418 | AK14: 0.2928 | AL14: 0.4345 | AM14: 0.2397 | AN14: 0.1353 | AO14: 0.4797 | AP14: 0.1718 | AQ14: 0.3206 | AR14: 0.572 | AS14: 0.3459 | AT14: 0.6346 | AU14: 0.3421 | AV14: 0.4153 | AW14: 0.4146 | AX14: 0.5358
A15: Load_TR1_F1_19 | B15: prosumer | C15: 0.0944 | D15: 0.04 | E15: 0.04 | F15: 0.0944 | G15: 0.1352 | H15: 0.04 | I15: 0.1897 | J15: 0.04 | K15: 0.1216 | L15: 0.108 | M15: 0.0468 | N15: 0.1829 | O15: 0.04 | P15: 0.04 | Q15: 0.2704 | R15: 0.2957 | S15: 0.04 | T15: 0.2431 | U15: 0.27 | V15: 0.2536 | W15: 0.4267 | X15: 0.2479 | Y15: 0.2079 | Z15: 0.4306 | AA15: 0.0902 | AB15: 0.1352 | AC15: 0.0944 | AD15: 0.074 | AE15: 0.1557 | AF15: 0.04 | AG15: 0.1625 | AH15: 0.0672 | AI15: 0.074 | AJ15: 0.1557 | AK15: 0.04 | AL15: 0.04 | AM15: 0.04 | AN15: 0.1897 | AO15: 0.04 | AP15: 0.04 | AQ15: 0.1897 | AR15: 0.04 | AS15: 0.04 | AT15: 0.0604 | AU15: 0.1693 | AV15: 0.04 | AW15: 0.1216 | AX15: 0.108
A16: Load_TR1_F1_2 | B16: customer | C16: 0.2276 | D16: 0.048 | E16: 0.2272 | F16: 0.1704 | G16: 0.1701 | H16: 0.2276 | I16: 0.048 | J16: 0.3089 | K16: 0.0888 | L16: 0.1133 | M16: 0.2844 | N16: 0.048 | O16: 0.0643 | P16: 0.315 | Q16: 0.0663 | R16: 0.1906 | S16: 0.2071 | T16: 0.1029 | U16: 0.2621 | V16: 0.0807 | W16: 2.9241 | X16: 2.9344 | Y16: 0.4729 | Z16: 0.3192 | AA16: 0.0725 | AB16: 0.048 | AC16: 0.2276 | AD16: 0.1701 | AE16: 0.0888 | AF16: 0.1868 | AG16: 0.1701 | AH16: 0.2276 | AI16: 0.0602 | AJ16: 0.3698 | AK16: 0.1464 | AL16: 0.1781 | AM16: 0.2289 | AN16: 0.1796 | AO16: 0.0863 | AP16: 0.445 | AQ16: 0.586 | AR16: 0.3306 | AS16: 0.4188 | AT16: 0.696 | AU16: 0.2925 | AV16: 0.1051 | AW16: 0.048 | AX16: 0.1112
... A136: Load_TR1_F6_9 | B136: prosumer | C136: 0.048 | D136: 0.048 | E136: 0.048 | F136: 0.048 | G136: 0.048 | H136: 0.048 | I136: 0.048 | J136: 0.048 | K136: 0.048 | L136: 0.048 | M136: 0.048 | N136: 0.048 | O136: 0.048 | P136: 0.048 | Q136: 0.048 | R136: 0.048 | S136: 0.048 | T136: 0.048 | U136: 0.3374 | V136: 0.3999 | W136: 0.0501 | X136: 0.048 | Y136: 0.048 | Z136: 0.048 | AA136: 0.048 | AB136: 0.048 | AC136: 0.048 | AD136: 0.0782 | AE136: 0.2179 | AF136: 0.5089 | AG136: 0.5147 | AH136: 0.0601 | AI136: 0.0644 | AJ136: 0.0595 | AK136: 0.0733 | AL136: 0.1322 | AM136: 0.545 | AN136: 0.4611 | AO136: 0.5946 | AP136: 0.4912 | AQ136: 0.5498 | AR136: 0.4401 | AS136: 0.6002 | AT136: 0.3867 | AU136: 0.5132 | AV136: 0.4941 | AW136: 0.6733 | AX136: 0.5128

Sheet 5. Raw batt charge
A1: Raw batt charge
A2: Verbatim copy of Charge_kW (TR1_analysis_data.xlsx). One row per half-hour, one column per battery (kW).
A4: period | B4: hour | C4: BES_TR1_one223_B | D4: BES_TR1_one313_A | E4: BES_TR1_one320_B | F4: BES_TR1_one321_C | G4: BES_TR1_one346_C | H4: BES_TR1_one366_B | I4: BES_TR1_one375_C | J4: BES_TR1_one410_B | K4: BES_TR1_one50_A | L4: BES_TR1_one423_B | M4: BES_TR1_one469_A | N4: BES_TR1_one480_A | O4: BES_TR1_one482_B | P4: BES_TR1_one521_C | Q4: BES_TR1_one528_C | R4: BES_TR1_one537_A | S4: BES_TR1_one61_A | T4: BES_TR1_one544_A | U4: BES_TR1_one552_B | V4: BES_TR1_one559_C | W4: BES_TR1_one560_C | X4: BES_TR1_one605_A | Y4: BES_TR1_one617_A | Z4: BES_TR1_one73_A | AA4: BES_TR1_one76_A | AB4: BES_TR1_six64_A | AC4: BES_TR1_six154_C | AD4: BES_TR1_six173_C | AE4: BES_TR1_six186_A | AF4: BES_TR1_six191_B | AG4: BES_TR1_six249_B | AH4: BES_TR1_six254_B | AI4: BES_TR1_six269_C | AJ4: BES_TR1_six68_C | AK4: BES_TR1_six289_C | AL4: BES_TR1_six317_C | AM4: BES_TR1_six326_A | AN4: BES_TR1_six329_A | AO4: BES_TR1_six342_A | AP4: BES_TR1_six349_A | AQ4: BES_TR1_six350_B | AR4: BES_TR1_six378_A | AS4: BES_TR1_six75_A | AT4: BES_TR1_six385_B | AU4: BES_TR1_six387_A | AV4: BES_TR1_six410_A | AW4: BES_TR1_six431_C | AX4: BES_TR1_six441_A | AY4: BES_TR1_six484_B | AZ4: BES_TR1_six501_A | BA4: BES_TR1_six512_B | BB4: BES_TR1_six518_B | BC4: BES_TR1_six595_B | BD4: BES_TR1_six646_B | BE4: BES_TR1_six699_C | BF4: BES_TR1_six718_C | BG4: BES_TR1_six721_A | BH4: BES_TR1_six723_B | BI4: BES_TR1_six784_B | BJ4: BES_TR1_six90_B | BK4: BES_TR1_six807_A | BL4: BES_TR1_six852_B | BM4: BES_TR1_six860_C | BN4: BES_TR1_six869_C | BO4: BES_TR1_six885_A | BP4: BES_TR1_six909_C | BQ4: BES_TR1_six105_A | BR4: BES_TR1_six914_A | BS4: BES_TR1_six945_C | BT4: BES_TR1_six952_A | BU4: BES_TR1_six967_B | BV4: BES_TR1_six990_B | BW4: BES_TR1_six1006_C | BX4: BES_TR1_six1020_A | BY4: BES_TR1_six1025_B | BZ4: BES_TR1_six1064_C | CA4: BES_TR1_six128_B
A5: 1 | B5: 0 | C5: 0 | D5: 0 | E5: 0 | F5: 0 | G5: 0 | H5: 0 | I5: 0 | J5: 0 | K5: 0 | L5: 0 | M5: 0 | N5: 0 | O5: 0 | P5: 0 | Q5: 0 | R5: 0 | S5: 0 | T5: 0 | U5: 0 | V5: 0 | W5: 0 | X5: 0 | Y5: 0 | Z5: 0 | AA5: 0 | AB5: 0 | AC5: 0 | AD5: 0 | AE5: 0 | AF5: 0 | AG5: 0 | AH5: 0 | AI5: 0 | AJ5: 0 | AK5: 0 | AL5: 0 | AM5: 0 | AN5: 0 | AO5: 0 | AP5: 0 | AQ5: 0 | AR5: 0 | AS5: 0 | AT5: 0 | AU5: 0 | AV5: 0 | AW5: 0 | AX5: 0 | AY5: 0 | AZ5: 0 | BA5: 0 | BB5: 0 | BC5: 0 | BD5: 0 | BE5: 0 | BF5: 0 | BG5: 0 | BH5: 0 | BI5: 0 | BJ5: 0 | BK5: 0 | BL5: 0 | BM5: 0 | BN5: 0 | BO5: 0 | BP5: 0 | BQ5: 0 | BR5: 0 | BS5: 0 | BT5: 0 | BU5: 0 | BV5: 0 | BW5: 0 | BX5: 0 | BY5: 0 | BZ5: 0 | CA5: 0
A6: 2 | B6: 0.5 | C6: 0 | D6: 0 | E6: 0 | F6: 0 | G6: 0 | H6: 0 | I6: 0 | J6: 0 | K6: 0 | L6: 0 | M6: 0 | N6: 0 | O6: 0 | P6: 0 | Q6: 0 | R6: 0 | S6: 0 | T6: 0 | U6: 0 | V6: 0 | W6: 0 | X6: 0 | Y6: 0 | Z6: 0 | AA6: 0 | AB6: 0 | AC6: 0 | AD6: 0 | AE6: 0 | AF6: 0 | AG6: 0 | AH6: 0 | AI6: 0 | AJ6: 0 | AK6: 0 | AL6: 0 | AM6: 0 | AN6: 0 | AO6: 0 | AP6: 0 | AQ6: 0 | AR6: 0 | AS6: 0 | AT6: 0 | AU6: 0 | AV6: 0 | AW6: 0 | AX6: 0 | AY6: 0 | AZ6: 0 | BA6: 0 | BB6: 0 | BC6: 0 | BD6: 0 | BE6: 0 | BF6: 0 | BG6: 0 | BH6: 0 | BI6: 0 | BJ6: 0 | BK6: 0 | BL6: 0 | BM6: 0 | BN6: 0 | BO6: 0 | BP6: 0 | BQ6: 0 | BR6: 0 | BS6: 0 | BT6: 0 | BU6: 0 | BV6: 0 | BW6: 0 | BX6: 0 | BY6: 0 | BZ6: 0 | CA6: 0
A7: 3 | B7: 1 | C7: 0 | D7: 0 | E7: 0 | F7: 0 | G7: 0 | H7: 0 | I7: 0 | J7: 0 | K7: 0 | L7: 0 | M7: 0 | N7: 0 | O7: 0 | P7: 0 | Q7: 0 | R7: 0 | S7: 0 | T7: 0 | U7: 0 | V7: 0 | W7: 0 | X7: 0 | Y7: 0 | Z7: 0 | AA7: 0 | AB7: 0 | AC7: 0 | AD7: 0 | AE7: 0 | AF7: 0 | AG7: 0 | AH7: 0 | AI7: 0 | AJ7: 0 | AK7: 0 | AL7: 0 | AM7: 0 | AN7: 0 | AO7: 0 | AP7: 0 | AQ7: 0 | AR7: 0 | AS7: 0 | AT7: 0 | AU7: 0 | AV7: 0 | AW7: 0 | AX7: 0 | AY7: 0 | AZ7: 0 | BA7: 0 | BB7: 0 | BC7: 0 | BD7: 0 | BE7: 0 | BF7: 0 | BG7: 0 | BH7: 0 | BI7: 0 | BJ7: 0 | BK7: 0 | BL7: 0 | BM7: 0 | BN7: 0 | BO7: 0 | BP7: 0 | BQ7: 0 | BR7: 0 | BS7: 0 | BT7: 0 | BU7: 0 | BV7: 0 | BW7: 0 | BX7: 0 | BY7: 0 | BZ7: 0 | CA7: 0
A8: 4 | B8: 1.5 | C8: 0 | D8: 0 | E8: 0 | F8: 0 | G8: 0 | H8: 0 | I8: 0 | J8: 0 | K8: 0 | L8: 0 | M8: 0 | N8: 0 | O8: 0 | P8: 0 | Q8: 0 | R8: 0 | S8: 0 | T8: 0 | U8: 0 | V8: 0 | W8: 0 | X8: 0 | Y8: 0 | Z8: 0 | AA8: 0 | AB8: 0 | AC8: 0 | AD8: 0 | AE8: 0 | AF8: 0 | AG8: 0 | AH8: 0 | AI8: 0 | AJ8: 0 | AK8: 0 | AL8: 0 | AM8: 0 | AN8: 0 | AO8: 0 | AP8: 0 | AQ8: 0 | AR8: 0 | AS8: 0 | AT8: 0 | AU8: 0 | AV8: 0 | AW8: 0 | AX8: 0 | AY8: 0 | AZ8: 0 | BA8: 0 | BB8: 0 | BC8: 0 | BD8: 0 | BE8: 0 | BF8: 0 | BG8: 0 | BH8: 0 | BI8: 0 | BJ8: 0 | BK8: 0 | BL8: 0 | BM8: 0 | BN8: 0 | BO8: 0 | BP8: 0 | BQ8: 0 | BR8: 0 | BS8: 0 | BT8: 0 | BU8: 0 | BV8: 0 | BW8: 0 | BX8: 0 | BY8: 0 | BZ8: 0 | CA8: 0
A9: 5 | B9: 2 | C9: 0 | D9: 0 | E9: 0 | F9: 0 | G9: 0 | H9: 0 | I9: 0 | J9: 0 | K9: 0 | L9: 0 | M9: 0 | N9: 0 | O9: 0 | P9: 0 | Q9: 0 | R9: 0 | S9: 0 | T9: 0 | U9: 0 | V9: 0 | W9: 0 | X9: 0 | Y9: 0 | Z9: 0 | AA9: 0 | AB9: 0 | AC9: 0 | AD9: 0 | AE9: 0 | AF9: 0 | AG9: 0 | AH9: 0 | AI9: 0 | AJ9: 0 | AK9: 0 | AL9: 0 | AM9: 0 | AN9: 0 | AO9: 0 | AP9: 0 | AQ9: 0 | AR9: 0 | AS9: 0 | AT9: 0 | AU9: 0 | AV9: 0 | AW9: 0 | AX9: 0 | AY9: 0 | AZ9: 0 | BA9: 0 | BB9: 0 | BC9: 0 | BD9: 0 | BE9: 0 | BF9: 0 | BG9: 0 | BH9: 0 | BI9: 0 | BJ9: 0 | BK9: 0 | BL9: 0 | BM9: 0 | BN9: 0 | BO9: 0 | BP9: 0 | BQ9: 0 | BR9: 0 | BS9: 0 | BT9: 0 | BU9: 0 | BV9: 0 | BW9: 0 | BX9: 0 | BY9: 0 | BZ9: 0 | CA9: 0
A10: 6 | B10: 2.5 | C10: 0 | D10: 0 | E10: 0 | F10: 0 | G10: 0 | H10: 0 | I10: 0 | J10: 0 | K10: 0 | L10: 0 | M10: 0 | N10: 0 | O10: 0 | P10: 0 | Q10: 0 | R10: 0 | S10: 0 | T10: 0 | U10: 0 | V10: 0 | W10: 0 | X10: 0 | Y10: 0 | Z10: 0 | AA10: 0 | AB10: 0 | AC10: 0 | AD10: 0 | AE10: 0 | AF10: 0 | AG10: 0 | AH10: 0 | AI10: 0 | AJ10: 0 | AK10: 0 | AL10: 0 | AM10: 0 | AN10: 0 | AO10: 0 | AP10: 0 | AQ10: 0 | AR10: 0 | AS10: 0 | AT10: 0 | AU10: 0 | AV10: 0 | AW10: 0 | AX10: 0 | AY10: 0 | AZ10: 0 | BA10: 0 | BB10: 0 | BC10: 0 | BD10: 0 | BE10: 0 | BF10: 0 | BG10: 0 | BH10: 0 | BI10: 0 | BJ10: 0 | BK10: 0 | BL10: 0 | BM10: 0 | BN10: 0 | BO10: 0 | BP10: 0 | BQ10: 0 | BR10: 0 | BS10: 0 | BT10: 0 | BU10: 0 | BV10: 0 | BW10: 0 | BX10: 0 | BY10: 0 | BZ10: 0 | CA10: 0
A11: 7 | B11: 3 | C11: 0 | D11: 0 | E11: 0 | F11: 0 | G11: 0 | H11: 0 | I11: 0 | J11: 0 | K11: 0 | L11: 0 | M11: 0 | N11: 0 | O11: 0 | P11: 0 | Q11: 0 | R11: 0 | S11: 0 | T11: 0 | U11: 0 | V11: 0 | W11: 0 | X11: 0 | Y11: 0 | Z11: 0 | AA11: 0 | AB11: 0 | AC11: 0 | AD11: 0 | AE11: 0 | AF11: 0 | AG11: 0 | AH11: 0 | AI11: 0 | AJ11: 0 | AK11: 0 | AL11: 0 | AM11: 0 | AN11: 0 | AO11: 0 | AP11: 0 | AQ11: 0 | AR11: 0 | AS11: 0 | AT11: 0 | AU11: 0 | AV11: 0 | AW11: 0 | AX11: 0 | AY11: 0 | AZ11: 0 | BA11: 0 | BB11: 0 | BC11: 0 | BD11: 0 | BE11: 0 | BF11: 0 | BG11: 0 | BH11: 0 | BI11: 0 | BJ11: 0 | BK11: 0 | BL11: 0 | BM11: 0 | BN11: 0 | BO11: 0 | BP11: 0 | BQ11: 0 | BR11: 0 | BS11: 0 | BT11: 0 | BU11: 0 | BV11: 0 | BW11: 0 | BX11: 0 | BY11: 0 | BZ11: 0 | CA11: 0
A12: 8 | B12: 3.5 | C12: 0 | D12: 0 | E12: 0 | F12: 0 | G12: 0 | H12: 0 | I12: 0 | J12: 0 | K12: 0 | L12: 0 | M12: 0 | N12: 0 | O12: 0 | P12: 0 | Q12: 0 | R12: 0 | S12: 0 | T12: 0 | U12: 0 | V12: 0 | W12: 0 | X12: 0 | Y12: 0 | Z12: 0 | AA12: 0 | AB12: 0 | AC12: 0 | AD12: 0 | AE12: 0 | AF12: 0 | AG12: 0 | AH12: 0 | AI12: 0 | AJ12: 0 | AK12: 0 | AL12: 0 | AM12: 0 | AN12: 0 | AO12: 0 | AP12: 0 | AQ12: 0 | AR12: 0 | AS12: 0 | AT12: 0 | AU12: 0 | AV12: 0 | AW12: 0 | AX12: 0 | AY12: 0 | AZ12: 0 | BA12: 0 | BB12: 0 | BC12: 0 | BD12: 0 | BE12: 0 | BF12: 0 | BG12: 0 | BH12: 0 | BI12: 0 | BJ12: 0 | BK12: 0 | BL12: 0 | BM12: 0 | BN12: 0 | BO12: 0 | BP12: 0 | BQ12: 0 | BR12: 0 | BS12: 0 | BT12: 0 | BU12: 0 | BV12: 0 | BW12: 0 | BX12: 0 | BY12: 0 | BZ12: 0 | CA12: 0
A13: 9 | B13: 4 | C13: 0 | D13: 0 | E13: 0 | F13: 0 | G13: 0 | H13: 0 | I13: 0 | J13: 0 | K13: 0 | L13: 0 | M13: 0 | N13: 0 | O13: 0 | P13: 0 | Q13: 0 | R13: 0 | S13: 0 | T13: 0 | U13: 0 | V13: 0 | W13: 0 | X13: 0 | Y13: 0 | Z13: 0 | AA13: 0 | AB13: 0 | AC13: 0 | AD13: 0 | AE13: 0 | AF13: 0 | AG13: 0 | AH13: 0 | AI13: 0 | AJ13: 0 | AK13: 0 | AL13: 0 | AM13: 0 | AN13: 0 | AO13: 0 | AP13: 0 | AQ13: 0 | AR13: 0.004 | AS13: 0 | AT13: 0 | AU13: 0 | AV13: 0 | AW13: 0 | AX13: 0 | AY13: 0 | AZ13: 0 | BA13: 0 | BB13: 0 | BC13: 0 | BD13: 0 | BE13: 0 | BF13: 0 | BG13: 0 | BH13: 0 | BI13: 0 | BJ13: 0 | BK13: 0 | BL13: 0 | BM13: 0 | BN13: 0 | BO13: 0 | BP13: 0 | BQ13: 0 | BR13: 0 | BS13: 0 | BT13: 0 | BU13: 0 | BV13: 0 | BW13: 0 | BX13: 0 | BY13: 0 | BZ13: 0 | CA13: 0
A14: 10 | B14: 4.5 | C14: 0.02 | D14: 0.125 | E14: 0.066 | F14: 0.069 | G14: 0.119 | H14: 0 | I14: 0 | J14: 0.025 | K14: 0.061 | L14: 0 | M14: 0.128 | N14: 0.059 | O14: 0.182 | P14: 0 | Q14: 0 | R14: 0.1 | S14: 0.075 | T14: 0.105 | U14: 0.157 | V14: 0.013 | W14: 0.034 | X14: 0.044 | Y14: 0.124 | Z14: 0.119 | AA14: 0.146 | AB14: 0.088 | AC14: 0.183 | AD14: 0.166 | AE14: 0.008 | AF14: 0.179 | AG14: 0.174 | AH14: 0.044 | AI14: 0.114 | AJ14: 0 | AK14: 0.058 | AL14: 0 | AM14: 0.097 | AN14: 0 | AO14: 0.127 | AP14: 0.093 | AQ14: 0.158 | AR14: 0.187 | AS14: 0.061 | AT14: 0.05 | AU14: 0 | AV14: 0 | AW14: 0 | AX14: 0 | AY14: 0 | AZ14: 0.113 | BA14: 0.002 | BB14: 0.162 | BC14: 0.102 | BD14: 0 | BE14: 0.08 | BF14: 0.031 | BG14: 0 | BH14: 0.118 | BI14: 0.109 | BJ14: 0.005 | BK14: 0.061 | BL14: 0.103 | BM14: 0.13 | BN14: 0.085 | BO14: 0.075 | BP14: 0.095 | BQ14: 0.108 | BR14: 0.156 | BS14: 0.116 | BT14: 0.061 | BU14: 0.003 | BV14: 0.129 | BW14: 0.036 | BX14: 0.132 | BY14: 0 | BZ14: 0.014 | CA14: 0.126
A15: 11 | B15: 5 | C15: 0.392 | D15: 0.415 | E15: 0.181 | F15: 0.392 | G15: 0.291 | H15: 0.177 | I15: 0.188 | J15: 0.139 | K15: 0.176 | L15: 0.17 | M15: 0.3 | N15: 0 | O15: 0.286 | P15: 0.073 | Q15: 0.225 | R15: 0.243 | S15: 0.253 | T15: 0.37 | U15: 0.312 | V15: 0 | W15: 0.301 | X15: 0.225 | Y15: 0.296 | Z15: 0.291 | AA15: 0.346 | AB15: 0.158 | AC15: 0.396 | AD15: 0.339 | AE15: 0.103 | AF15: 0.407 | AG15: 0.295 | AH15: 0.157 | AI15: 0.286 | AJ15: 0.051 | AK15: 0.011 | AL15: 0.078 | AM15: 0.143 | AN15: 0.21 | AO15: 0.268 | AP15: 0.236 | AQ15: 0.352 | AR15: 0.415 | AS15: 0.245 | AT15: 0 | AU15: 0.091 | AV15: 0.093 | AW15: 0.182 | AX15: 0.218 | AY15: 0.199 | AZ15: 0.218 | BA15: 0.286 | BB15: 0.403 | BC15: 0.171 | BD15: 0.215 | BE15: 0.346 | BF15: 0 | BG15: 0.123 | BH15: 0.264 | BI15: 0.246 | BJ15: 0.105 | BK15: 0.176 | BL15: 0.335 | BM15: 0.283 | BN15: 0.4 | BO15: 0.031 | BP15: 0.238 | BQ15: 0.244 | BR15: 0.356 | BS15: 0.411 | BT15: 0.176 | BU15: 0.06 | BV15: 0.41 | BW15: 0.348 | BX15: 0.28 | BY15: 0.204 | BZ15: 0.071 | CA15: 0.298
A16: 12 | B16: 5.5 | C16: 0.46 | D16: 0.559 | E16: 0.238 | F16: 0.685 | G16: 0.415 | H16: 0.111 | I16: 0.22 | J16: 0.307 | K16: 0.316 | L16: 0.31 | M16: 0.51 | N16: 0.306 | O16: 0.644 | P16: 0.383 | Q16: 0.416 | R16: 0.252 | S16: 0.646 | T16: 0.444 | U16: 0.482 | V16: 0.322 | W16: 0.618 | X16: 0.362 | Y16: 0.506 | Z16: 0.459 | AA16: 0.591 | AB16: 0.367 | AC16: 0.604 | AD16: 0.523 | AE16: 0.321 | AF16: 0.672 | AG16: 0.683 | AH16: 0.1 | AI16: 0.288 | AJ16: 0.142 | AK16: 0.18 | AL16: 0.361 | AM16: 0.416 | AN16: 0.297 | AO16: 0.46 | AP16: 0.412 | AQ16: 0.689 | AR16: 0.696 | AS16: 0.514 | AT16: 0.166 | AU16: 0.102 | AV16: 0.307 | AW16: 0.38 | AX16: 0.712 | AY16: 0.328 | AZ16: 0.254 | BA16: 0.509 | BB16: 0.684 | BC16: 0.421 | BD16: 0.428 | BE16: 0.54 | BF16: 0.222 | BG16: 0 | BH16: 0.687 | BI16: 0.478 | BJ16: 0.158 | BK16: 0.174 | BL16: 0.584 | BM16: 0.685 | BN16: 0.507 | BO16: 0.33 | BP16: 0.414 | BQ16: 0.264 | BR16: 0.601 | BS16: 0.53 | BT16: 0.216 | BU16: 0 | BV16: 0.474 | BW16: 0.593 | BX16: 0.69 | BY16: 0.25 | BZ16: 0.141 | CA16: 0.508
... A52: 48 | B52: 23.5 | C52: 0 | D52: 0 | E52: 0 | F52: 0 | G52: 0 | H52: 0 | I52: 0 | J52: 0 | K52: 0 | L52: 0 | M52: 0 | N52: 0 | O52: 0 | P52: 0 | Q52: 0 | R52: 0 | S52: 0 | T52: 0 | U52: 0 | V52: 0 | W52: 0 | X52: 0 | Y52: 0 | Z52: 0 | AA52: 0 | AB52: 0 | AC52: 0 | AD52: 0 | AE52: 0 | AF52: 0 | AG52: 0 | AH52: 0 | AI52: 0 | AJ52: 0 | AK52: 0 | AL52: 0 | AM52: 0 | AN52: 0 | AO52: 0 | AP52: 0 | AQ52: 0 | AR52: 0 | AS52: 0 | AT52: 0 | AU52: 0 | AV52: 0 | AW52: 0 | AX52: 0 | AY52: 0 | AZ52: 0 | BA52: 0 | BB52: 0 | BC52: 0 | BD52: 0 | BE52: 0 | BF52: 0 | BG52: 0 | BH52: 0 | BI52: 0 | BJ52: 0 | BK52: 0 | BL52: 0 | BM52: 0 | BN52: 0 | BO52: 0 | BP52: 0 | BQ52: 0 | BR52: 0 | BS52: 0 | BT52: 0 | BU52: 0 | BV52: 0 | BW52: 0 | BX52: 0 | BY52: 0 | BZ52: 0 | CA52: 0

Sheet 6. Raw batt discharge
A1: Raw batt discharge
A2: Verbatim copy of Discharge_kW (TR1_analysis_data.xlsx). One row per half-hour, one column per battery (kW).
A4: period | B4: hour | C4: BES_TR1_one223_B | D4: BES_TR1_one313_A | E4: BES_TR1_one320_B | F4: BES_TR1_one321_C | G4: BES_TR1_one346_C | H4: BES_TR1_one366_B | I4: BES_TR1_one375_C | J4: BES_TR1_one410_B | K4: BES_TR1_one50_A | L4: BES_TR1_one423_B | M4: BES_TR1_one469_A | N4: BES_TR1_one480_A | O4: BES_TR1_one482_B | P4: BES_TR1_one521_C | Q4: BES_TR1_one528_C | R4: BES_TR1_one537_A | S4: BES_TR1_one61_A | T4: BES_TR1_one544_A | U4: BES_TR1_one552_B | V4: BES_TR1_one559_C | W4: BES_TR1_one560_C | X4: BES_TR1_one605_A | Y4: BES_TR1_one617_A | Z4: BES_TR1_one73_A | AA4: BES_TR1_one76_A | AB4: BES_TR1_six64_A | AC4: BES_TR1_six154_C | AD4: BES_TR1_six173_C | AE4: BES_TR1_six186_A | AF4: BES_TR1_six191_B | AG4: BES_TR1_six249_B | AH4: BES_TR1_six254_B | AI4: BES_TR1_six269_C | AJ4: BES_TR1_six68_C | AK4: BES_TR1_six289_C | AL4: BES_TR1_six317_C | AM4: BES_TR1_six326_A | AN4: BES_TR1_six329_A | AO4: BES_TR1_six342_A | AP4: BES_TR1_six349_A | AQ4: BES_TR1_six350_B | AR4: BES_TR1_six378_A | AS4: BES_TR1_six75_A | AT4: BES_TR1_six385_B | AU4: BES_TR1_six387_A | AV4: BES_TR1_six410_A | AW4: BES_TR1_six431_C | AX4: BES_TR1_six441_A | AY4: BES_TR1_six484_B | AZ4: BES_TR1_six501_A | BA4: BES_TR1_six512_B | BB4: BES_TR1_six518_B | BC4: BES_TR1_six595_B | BD4: BES_TR1_six646_B | BE4: BES_TR1_six699_C | BF4: BES_TR1_six718_C | BG4: BES_TR1_six721_A | BH4: BES_TR1_six723_B | BI4: BES_TR1_six784_B | BJ4: BES_TR1_six90_B | BK4: BES_TR1_six807_A | BL4: BES_TR1_six852_B | BM4: BES_TR1_six860_C | BN4: BES_TR1_six869_C | BO4: BES_TR1_six885_A | BP4: BES_TR1_six909_C | BQ4: BES_TR1_six105_A | BR4: BES_TR1_six914_A | BS4: BES_TR1_six945_C | BT4: BES_TR1_six952_A | BU4: BES_TR1_six967_B | BV4: BES_TR1_six990_B | BW4: BES_TR1_six1006_C | BX4: BES_TR1_six1020_A | BY4: BES_TR1_six1025_B | BZ4: BES_TR1_six1064_C | CA4: BES_TR1_six128_B
A5: 1 | B5: 0 | C5: 0.183 | D5: 0.094 | E5: 0.05 | F5: 0.057 | G5: 0.055 | H5: 0.192 | I5: 0.229 | J5: 0.256 | K5: 0.56 | L5: 0.378 | M5: 0.484 | N5: 0.353 | O5: 0.183 | P5: 0.229 | Q5: 0.13 | R5: 0.045 | S5: 0.079 | T5: 0.378 | U5: 0.107 | V5: 0.22 | W5: 0.1 | X5: 0.051 | Y5: 0.05 | Z5: 2.391 | AA5: 0.095 | AB5: 0.522 | AC5: 0.133 | AD5: 0.197 | AE5: 0.655 | AF5: 0.245 | AG5: 0.059 | AH5: 0.147 | AI5: 0.168 | AJ5: 0.07 | AK5: 0.073 | AL5: 0.269 | AM5: 0.112 | AN5: 0.059 | AO5: 0.391 | AP5: 0.526 | AQ5: 0.053 | AR5: 0.142 | AS5: 0.042 | AT5: 0.197 | AU5: 0.116 | AV5: 0.218 | AW5: 0.313 | AX5: 0.03 | AY5: 0.16 | AZ5: 0.293 | BA5: 0.124 | BB5: 0.095 | BC5: 0.089 | BD5: 0.401 | BE5: 0.058 | BF5: 0.153 | BG5: 0.187 | BH5: 0.184 | BI5: 0.359 | BJ5: 0.719 | BK5: 0.219 | BL5: 0.285 | BM5: 1.792 | BN5: 1.946 | BO5: 0.168 | BP5: 0.05 | BQ5: 0.363 | BR5: 0.048 | BS5: 0.102 | BT5: 0.055 | BU5: 0.214 | BV5: 0.146 | BW5: 0.168 | BX5: 0.76 | BY5: 0.107 | BZ5: 0.044 | CA5: 0.048
A6: 2 | B6: 0.5 | C6: 0.24 | D6: 0.04 | E6: 0.133 | F6: 0.057 | G6: 0.055 | H6: 0.218 | I6: 0.108 | J6: 0.095 | K6: 0.534 | L6: 0.382 | M6: 0.506 | N6: 0.503 | O6: 0.051 | P6: 0.084 | Q6: 0.13 | R6: 0.045 | S6: 0.288 | T6: 0.216 | U6: 0.047 | V6: 0.104 | W6: 0.331 | X6: 0.168 | Y6: 0.05 | Z6: 0 | AA6: 0.104 | AB6: 0.097 | AC6: 0.05 | AD6: 0.055 | AE6: 0.693 | AF6: 0.388 | AG6: 0.173 | AH6: 0.198 | AI6: 0.117 | AJ6: 0.372 | AK6: 0.298 | AL6: 0.225 | AM6: 0.082 | AN6: 0.293 | AO6: 0.047 | AP6: 0.447 | AQ6: 0.131 | AR6: 0.046 | AS6: 0.127 | AT6: 0.037 | AU6: 0.248 | AV6: 0.081 | AW6: 0.081 | AX6: 0.161 | AY6: 0.242 | AZ6: 0.088 | BA6: 0.14 | BB6: 0.095 | BC6: 0.08 | BD6: 0.091 | BE6: 0.058 | BF6: 0.168 | BG6: 0.166 | BH6: 0.068 | BI6: 0.948 | BJ6: 0.094 | BK6: 0.055 | BL6: 0.237 | BM6: 0.37 | BN6: 0.445 | BO6: 0.084 | BP6: 0.05 | BQ6: 0.037 | BR6: 0.048 | BS6: 0.16 | BT6: 0.191 | BU6: 0.055 | BV6: 0.181 | BW6: 0.056 | BX6: 0.052 | BY6: 0.265 | BZ6: 0.044 | CA6: 0.048
A7: 3 | B7: 1 | C7: 0.152 | D7: 0.04 | E7: 0.05 | F7: 0.057 | G7: 0.214 | H7: 0.08 | I7: 0.111 | J7: 0.051 | K7: 0.055 | L7: 0.061 | M7: 0.384 | N7: 0.71 | O7: 0.067 | P7: 0.319 | Q7: 0.112 | R7: 0.06 | S7: 0.05 | T7: 0.054 | U7: 0.16 | V7: 0.289 | W7: 0.058 | X7: 0.108 | Y7: 0.05 | Z7: 0 | AA7: 0.058 | AB7: 0.13 | AC7: 0.086 | AD7: 0.388 | AE7: 0.479 | AF7: 0.269 | AG7: 0.166 | AH7: 0.096 | AI7: 0.161 | AJ7: 0.161 | AK7: 0.15 | AL7: 0.181 | AM7: 0.048 | AN7: 0.059 | AO7: 0.047 | AP7: 0.052 | AQ7: 0.053 | AR7: 0.046 | AS7: 0.139 | AT7: 0.037 | AU7: 0.04 | AV7: 0.128 | AW7: 0.26 | AX7: 0.03 | AY7: 0.147 | AZ7: 0.198 | BA7: 0.18 | BB7: 0.058 | BC7: 0.08 | BD7: 0.254 | BE7: 0.058 | BF7: 0.085 | BG7: 0.088 | BH7: 0.244 | BI7: 0.044 | BJ7: 0.06 | BK7: 0.055 | BL7: 0.198 | BM7: 0.118 | BN7: 0 | BO7: 0.157 | BP7: 0.05 | BQ7: 0.037 | BR7: 0.048 | BS7: 0.05 | BT7: 0.105 | BU7: 0.055 | BV7: 0.132 | BW7: 0.056 | BX7: 0.157 | BY7: 0.126 | BZ7: 0.105 | CA7: 0.048
A8: 4 | B8: 1.5 | C8: 0.223 | D8: 0.094 | E8: 0.133 | F8: 0.175 | G8: 0.055 | H8: 0.306 | I8: 0.222 | J8: 0.3 | K8: 0.055 | L8: 0.225 | M8: 0.167 | N8: 0.369 | O8: 0.207 | P8: 0.052 | Q8: 0.107 | R8: 0.196 | S8: 0.05 | T8: 0.054 | U8: 0.1 | V8: 0.074 | W8: 0.226 | X8: 0.051 | Y8: 0.05 | Z8: 0 | AA8: 0.132 | AB8: 0.057 | AC8: 0.117 | AD8: 0.07 | AE8: 0.091 | AF8: 0.054 | AG8: 0.173 | AH8: 0.096 | AI8: 0.161 | AJ8: 0.05 | AK8: 0.166 | AL8: 0.131 | AM8: 0.119 | AN8: 0.208 | AO8: 0.047 | AP8: 0.052 | AQ8: 0.053 | AR8: 0.046 | AS8: 0.351 | AT8: 0.205 | AU8: 0.183 | AV8: 0.174 | AW8: 0.055 | AX8: 0.161 | AY8: 0.187 | AZ8: 0.058 | BA8: 0.14 | BB8: 0.133 | BC8: 0.101 | BD8: 0.036 | BE8: 0.124 | BF8: 0.295 | BG8: 0.273 | BH8: 0.055 | BI8: 0.113 | BJ8: 0.279 | BK8: 0.219 | BL8: 0.23 | BM8: 0.11 | BN8: 0 | BO8: 0.084 | BP8: 0.05 | BQ8: 0.207 | BR8: 0.048 | BS8: 0.124 | BT8: 0.084 | BU8: 0.214 | BV8: 0.18 | BW8: 0.168 | BX8: 0.125 | BY8: 0.443 | BZ8: 0.151 | CA8: 0.048
A9: 5 | B9: 2 | C9: 0.141 | D9: 0.135 | E9: 0.05 | F9: 0.057 | G9: 0.164 | H9: 0.151 | I9: 0.075 | J9: 0.051 | K9: 0.055 | L9: 0.061 | M9: 0.046 | N9: 0.235 | O9: 0.051 | P9: 0.064 | Q9: 0.152 | R9: 0.045 | S9: 0.295 | T9: 0.054 | U9: 0.051 | V9: 0.132 | W9: 0.155 | X9: 0.184 | Y9: 0.05 | Z9: 0 | AA9: 0.067 | AB9: 0.057 | AC9: 0.05 | AD9: 0.107 | AE9: 0.16 | AF9: 0.054 | AG9: 0.059 | AH9: 0.044 | AI9: 0.135 | AJ9: 0.208 | AK9: 0.256 | AL9: 0.184 | AM9: 0.048 | AN9: 0.144 | AO9: 0.128 | AP9: 0.052 | AQ9: 0.131 | AR9: 0.046 | AS9: 0.463 | AT9: 0.054 | AU9: 0.181 | AV9: 0.068 | AW9: 0.18 | AX9: 0.03 | AY9: 0.159 | AZ9: 0.091 | BA9: 0.18 | BB9: 0.058 | BC9: 0.06 | BD9: 0.247 | BE9: 0.058 | BF9: 0.065 | BG9: 0.05 | BH9: 0.171 | BI9: 0.053 | BJ9: 0.053 | BK9: 0.055 | BL9: 0.149 | BM9: 0.002 | BN9: 0 | BO9: 0.05 | BP9: 0.05 | BQ9: 0.037 | BR9: 0.048 | BS9: 0.138 | BT9: 0.113 | BU9: 0.055 | BV9: 0.215 | BW9: 0.056 | BX9: 0.068 | BY9: 0.089 | BZ9: 0.044 | CA9: 0.048
A10: 6 | B10: 2.5 | C10: 0.148 | D10: 0.04 | E10: 0.064 | F10: 0.175 | G10: 0.106 | H10: 0.149 | I10: 0.147 | J10: 0.102 | K10: 0.055 | L10: 0.061 | M10: 0.046 | N10: 0.139 | O10: 0.207 | P10: 0.331 | Q10: 0.048 | R10: 0.075 | S10: 0.072 | T10: 0.12 | U10: 0.194 | V10: 0.223 | W10: 0.174 | X10: 0.092 | Y10: 0.05 | Z10: 0 | AA10: 0.1 | AB10: 0.068 | AC10: 0.154 | AD10: 0.234 | AE10: 0.05 | AF10: 0.054 | AG10: 0.268 | AH10: 0.175 | AI10: 0.168 | AJ10: 0.05 | AK10: 0.1 | AL10: 0.257 | AM10: 0.119 | AN10: 0.059 | AO10: 0.047 | AP10: 0.052 | AQ10: 0.053 | AR10: 0.046 | AS10: 0.542 | AT10: 0.045 | AU10: 0.04 | AV10: 0.118 | AW10: 0.157 | AX10: 0.115 | AY10: 0.14 | AZ10: 0.339 | BA10: 0.112 | BB10: 0.133 | BC10: 0.043 | BD10: 0.064 | BE10: 0.058 | BF10: 0.177 | BG10: 0.05 | BH10: 0.141 | BI10: 0.044 | BJ10: 0.184 | BK10: 0.212 | BL10: 0.155 | BM10: 0 | BN10: 0 | BO10: 0.163 | BP10: 0.05 | BQ10: 0.13 | BR10: 0.048 | BS10: 0.05 | BT10: 0.164 | BU10: 0.098 | BV10: 0.051 | BW10: 0.168 | BX10: 0.213 | BY10: 0.366 | BZ10: 0.044 | CA10: 0.048
A11: 7 | B11: 3 | C11: 0.279 | D11: 0.19 | E11: 0.119 | F11: 0.057 | G11: 0.077 | H11: 0.315 | I11: 0.197 | J11: 0.249 | K11: 0.055 | L11: 0.21 | M11: 0.046 | N11: 0.048 | O11: 0.067 | P11: 0.06 | Q11: 0.063 | R11: 0.181 | S11: 0.127 | T11: 0.268 | U11: 0.16 | V11: 0.108 | W11: 0.209 | X11: 0.051 | Y11: 0.05 | Z11: 0 | AA11: 0.1 | AB11: 0.159 | AC11: 0.05 | AD11: 0.1 | AE11: 0.208 | AF11: 0.054 | AG11: 0.07 | AH11: 0.17 | AI11: 0.161 | AJ11: 0.208 | AK11: 0.319 | AL11: 0.223 | AM11: 0.146 | AN11: 0.185 | AO11: 0.047 | AP11: 0.052 | AQ11: 0.105 | AR11: 0.046 | AS11: 0.21 | AT11: 0.213 | AU11: 0.191 | AV11: 0.156 | AW11: 0.132 | AX11: 0.076 | AY11: 0.213 | AZ11: 0.041 | BA11: 0.084 | BB11: 0.058 | BC11: 0.043 | BD11: 0.148 | BE11: 0.124 | BF11: 0.212 | BG11: 0.153 | BH11: 0.112 | BI11: 0.066 | BJ11: 0.082 | BK11: 0.062 | BL11: 0.193 | BM11: 0 | BN11: 0 | BO11: 0.078 | BP11: 0.05 | BQ11: 0.114 | BR11: 0.048 | BS11: 0.212 | BT11: 0.132 | BU11: 0.17 | BV11: 0.351 | BW11: 0.056 | BX11: 0.052 | BY11: 0.223 | BZ11: 0.044 | CA11: 0.048
A12: 8 | B12: 3.5 | C12: 0.043 | D12: 0.037 | E12: 0.048 | F12: 0.16 | G12: 0.19 | H12: 0.093 | I12: 0.051 | J12: 0.094 | K12: 0.053 | L12: 0.074 | M12: 0.043 | N12: 0.033 | O12: 0.048 | P12: 0.173 | Q12: 0.195 | R12: 0.043 | S12: 0.222 | T12: 0.051 | U12: 0.044 | V12: 0.279 | W12: 0.244 | X12: 0.077 | Y12: 0.047 | Z12: 0 | AA12: 0.055 | AB12: 0.055 | AC12: 0.047 | AD12: 0.163 | AE12: 0.054 | AF12: 0.051 | AG12: 0.078 | AH12: 0.05 | AI12: 0.121 | AJ12: 0.049 | AK12: 0.143 | AL12: 0.152 | AM12: 0.05 | AN12: 0.057 | AO12: 0.044 | AP12: 0.05 | AQ12: 0.076 | AR12: 0.043 | AS12: 0.137 | AT12: 0.036 | AU12: 0.054 | AV12: 0.096 | AW12: 0.208 | AX12: 0.079 | AY12: 0.222 | AZ12: 0.219 | BA12: 0.133 | BB12: 0.055 | BC12: 0.115 | BD12: 0.161 | BE12: 0.055 | BF12: 0.079 | BG12: 0.134 | BH12: 0.151 | BI12: 0.098 | BJ12: 0.124 | BK12: 0.184 | BL12: 0.232 | BM12: 0 | BN12: 0 | BO12: 0.062 | BP12: 0.048 | BQ12: 0.035 | BR12: 0.045 | BS12: 0.047 | BT12: 0.153 | BU12: 0.054 | BV12: 0.048 | BW12: 0.053 | BX12: 0.153 | BY12: 0.232 | BZ12: 0.043 | CA12: 0.045
A13: 9 | B13: 4 | C13: 0.095 | D13: 0.072 | E13: 0.025 | F13: 0.019 | G13: 0.018 | H13: 0.182 | I13: 0.147 | J13: 0.199 | K13: 0.03 | L13: 0.036 | M13: 0.009 | N13: 0 | O13: 0.172 | P13: 0.021 | Q13: 0.017 | R13: 0.18 | S13: 0.015 | T13: 0.211 | U13: 0.169 | V13: 0.141 | W13: 0.134 | X13: 0.159 | Y13: 0.013 | Z13: 0 | AA13: 0.098 | AB13: 0.139 | AC13: 0.0003 | AD13: 0.136 | AE13: 0 | AF13: 0.004 | AG13: 0.1 | AH13: 0.241 | AI13: 0.167 | AJ13: 0.147 | AK13: 0.141 | AL13: 0.094 | AM13: 0.182 | AN13: 0.142 | AO13: 0.01 | AP13: 0.021 | AQ13: 0.003 | AR13: 0 | AS13: 0.037 | AT13: 0.203 | AU13: 0.127 | AV13: 0.071 | AW13: 0.093 | AX13: 0.059 | AY13: 0.045 | AZ13: 0.151 | BA13: 0.056 | BB13: 0.071 | BC13: 0.012 | BD13: 0.033 | BE13: 0.014 | BF13: 0.1 | BG13: 0.079 | BH13: 0.052 | BI13: 0.007 | BJ13: 0.13 | BK13: 0.127 | BL13: 0.162 | BM13: 0 | BN13: 0 | BO13: 0.1 | BP13: 0.019 | BQ13: 0.176 | BR13: 0.032 | BS13: 0.103 | BT13: 0.117 | BU13: 0.201 | BV13: 0.249 | BW13: 0.012 | BX13: 0.075 | BY13: 0.297 | BZ13: 0.032 | CA13: 0.011
A14: 10 | B14: 4.5 | C14: 0 | D14: 0 | E14: 0 | F14: 0 | G14: 0 | H14: 0.099 | I14: 0.02 | J14: 0 | K14: 0 | L14: 0.109 | M14: 0 | N14: 0 | O14: 0 | P14: 0.071 | Q14: 0.051 | R14: 0 | S14: 0 | T14: 0 | U14: 0 | V14: 0 | W14: 0 | X14: 0 | Y14: 0 | Z14: 0 | AA14: 0 | AB14: 0 | AC14: 0 | AD14: 0 | AE14: 0 | AF14: 0 | AG14: 0 | AH14: 0 | AI14: 0 | AJ14: 0.006 | AK14: 0 | AL14: 0.078 | AM14: 0 | AN14: 0.034 | AO14: 0 | AP14: 0 | AQ14: 0 | AR14: 0 | AS14: 0 | AT14: 0 | AU14: 0.119 | AV14: 0.032 | AW14: 0.057 | AX14: 0.755 | AY14: 0.082 | AZ14: 0 | BA14: 0 | BB14: 0 | BC14: 0 | BD14: 0.064 | BE14: 0 | BF14: 0 | BG14: 0.172 | BH14: 0 | BI14: 0 | BJ14: 0 | BK14: 0 | BL14: 0 | BM14: 0 | BN14: 0 | BO14: 0 | BP14: 0 | BQ14: 0 | BR14: 0 | BS14: 0 | BT14: 0 | BU14: 0 | BV14: 0 | BW14: 0 | BX14: 0 | BY14: 0.015 | BZ14: 0 | CA14: 0
A15: 11 | B15: 5 | C15: 0 | D15: 0 | E15: 0 | F15: 0 | G15: 0 | H15: 0 | I15: 0 | J15: 0 | K15: 0 | L15: 0 | M15: 0 | N15: 0.053 | O15: 0 | P15: 0 | Q15: 0 | R15: 0 | S15: 0 | T15: 0 | U15: 0 | V15: 0.105 | W15: 0 | X15: 0 | Y15: 0 | Z15: 0 | AA15: 0 | AB15: 0 | AC15: 0 | AD15: 0 | AE15: 0 | AF15: 0 | AG15: 0 | AH15: 0 | AI15: 0 | AJ15: 0 | AK15: 0 | AL15: 0 | AM15: 0 | AN15: 0 | AO15: 0 | AP15: 0 | AQ15: 0 | AR15: 0 | AS15: 0 | AT15: 0.002 | AU15: 0 | AV15: 0 | AW15: 0 | AX15: 0 | AY15: 0 | AZ15: 0 | BA15: 0 | BB15: 0 | BC15: 0 | BD15: 0 | BE15: 0 | BF15: 0.16 | BG15: 0 | BH15: 0 | BI15: 0 | BJ15: 0 | BK15: 0 | BL15: 0 | BM15: 0 | BN15: 0 | BO15: 0 | BP15: 0 | BQ15: 0 | BR15: 0 | BS15: 0 | BT15: 0 | BU15: 0 | BV15: 0 | BW15: 0 | BX15: 0 | BY15: 0 | BZ15: 0 | CA15: 0
A16: 12 | B16: 5.5 | C16: 0 | D16: 0 | E16: 0 | F16: 0 | G16: 0 | H16: 0 | I16: 0 | J16: 0 | K16: 0 | L16: 0 | M16: 0 | N16: 0 | O16: 0 | P16: 0 | Q16: 0 | R16: 0 | S16: 0 | T16: 0 | U16: 0 | V16: 0 | W16: 0 | X16: 0 | Y16: 0 | Z16: 0 | AA16: 0 | AB16: 0 | AC16: 0 | AD16: 0 | AE16: 0 | AF16: 0 | AG16: 0 | AH16: 0 | AI16: 0 | AJ16: 0 | AK16: 0 | AL16: 0 | AM16: 0 | AN16: 0 | AO16: 0 | AP16: 0 | AQ16: 0 | AR16: 0 | AS16: 0 | AT16: 0 | AU16: 0 | AV16: 0 | AW16: 0 | AX16: 0 | AY16: 0 | AZ16: 0 | BA16: 0 | BB16: 0 | BC16: 0 | BD16: 0 | BE16: 0 | BF16: 0 | BG16: 0.02 | BH16: 0 | BI16: 0 | BJ16: 0 | BK16: 0 | BL16: 0 | BM16: 0 | BN16: 0 | BO16: 0 | BP16: 0 | BQ16: 0 | BR16: 0 | BS16: 0 | BT16: 0 | BU16: 0.007 | BV16: 0 | BW16: 0 | BX16: 0 | BY16: 0 | BZ16: 0 | CA16: 0
... A52: 48 | B52: 23.5 | C52: 0.532 | D52: 0.108 | E52: 0.311 | F52: 0.14 | G52: 0.185 | H52: 0 | I52: 0.128 | J52: 0.231 | K52: 0.055 | L52: 0 | M52: 0.504 | N52: 0.03 | O52: 0.434 | P52: 0.068 | Q52: 0 | R52: 0 | S52: 0.616 | T52: 0.647 | U52: 0.557 | V52: 0.187 | W52: 0.062 | X52: 0.167 | Y52: 0.341 | Z52: 0.055 | AA52: 0.058 | AB52: 0.704 | AC52: 0.138 | AD52: 0 | AE52: 0 | AF52: 0.054 | AG52: 0.165 | AH52: 0.118 | AI52: 0.142 | AJ52: 0.102 | AK52: 0 | AL52: 0.048 | AM52: 0 | AN52: 0.059 | AO52: 0.442 | AP52: 0 | AQ52: 0.131 | AR52: 0.046 | AS52: 0.337 | AT52: 0.037 | AU52: 0.285 | AV52: 0.162 | AW52: 0.092 | AX52: 0.03 | AY52: 0.814 | AZ52: 0.191 | BA52: 0.07 | BB52: 1.433 | BC52: 0.289 | BD52: 0.275 | BE52: 0.124 | BF52: 0.099 | BG52: 0.076 | BH52: 0.118 | BI52: 0.044 | BJ52: 0.249 | BK52: 0 | BL52: 0.223 | BM52: 0.057 | BN52: 0.095 | BO52: 0.151 | BP52: 0 | BQ52: 0.757 | BR52: 0.206 | BS52: 0.205 | BT52: 0.423 | BU52: 0 | BV52: 0.407 | BW52: 0.624 | BX52: 0.052 | BY52: 0.678 | BZ52: 0.044 | CA52: 0.513

Sheet 7. PV allocation (per period)
A1: TR1 PV allocation — per half-hour
A2: VIOLET = aggregated live from the raw sheets 3–6 (SUM / SUMIF). AMBER = priority split (MIN formulas): PV → prosumer load → battery → customer load → export.
A4: period | B4: hour (h) | C4: PV (kW) | D4: prosumer load (kW) | E4: customer load (kW) | F4: batt charge (kW) | G4: batt discharge (kW) | H4: batt net =chg−dis | I4: PV→ prosumer | J4: PV→ battery | K4: PV→ customer | L4: PV→ export | M4: customer ←grid
A5: 1 | B5: 0 | C5: =SUM('3. Raw PV per load'!C5:C136) -> 0 | D5: =SUMIF('4. Raw load per load'!$B$5:$B$136,"prosumer",'4. Raw load per load'!C5:C136) -> 21.0715 | E5: =SUMIF('4. Raw load per load'!$B$5:$B$136,"customer",'4. Raw load per load'!C5:C136) -> 7.851 | F5: =SUM('5. Raw batt charge'!C5:CA5) -> 0 | G5: =SUM('6. Raw batt discharge'!C5:CA5) -> 21.023 | H5: =F5-G5 -> -21.023 | I5: =MIN(C5,D5) -> 0 | J5: =MIN(C5-I5,MAX(0,H5)) -> 0 | K5: =MIN(C5-I5-J5,E5) -> 0 | L5: =C5-I5-J5-K5 -> 0 | M5: =E5-K5 -> 7.851
A6: 2 | B6: 0.5 | C6: =SUM('3. Raw PV per load'!D5:D136) -> 0 | D6: =SUMIF('4. Raw load per load'!$B$5:$B$136,"prosumer",'4. Raw load per load'!D5:D136) -> 13.7 | E6: =SUMIF('4. Raw load per load'!$B$5:$B$136,"customer",'4. Raw load per load'!D5:D136) -> 6.5979 | F6: =SUM('5. Raw batt charge'!C6:CA6) -> 0 | G6: =SUM('6. Raw batt discharge'!C6:CA6) -> 13.552 | H6: =F6-G6 -> -13.552 | I6: =MIN(C6,D6) -> 0 | J6: =MIN(C6-I6,MAX(0,H6)) -> 0 | K6: =MIN(C6-I6-J6,E6) -> 0 | L6: =C6-I6-J6-K6 -> 0 | M6: =E6-K6 -> 6.5979
A7: 3 | B7: 1 | C7: =SUM('3. Raw PV per load'!E5:E136) -> 0 | D7: =SUMIF('4. Raw load per load'!$B$5:$B$136,"prosumer",'4. Raw load per load'!E5:E136) -> 9.6827 | E7: =SUMIF('4. Raw load per load'!$B$5:$B$136,"customer",'4. Raw load per load'!E5:E136) -> 5.4129 | F7: =SUM('5. Raw batt charge'!C7:CA7) -> 0 | G7: =SUM('6. Raw batt discharge'!C7:CA7) -> 9.549 | H7: =F7-G7 -> -9.549 | I7: =MIN(C7,D7) -> 0 | J7: =MIN(C7-I7,MAX(0,H7)) -> 0 | K7: =MIN(C7-I7-J7,E7) -> 0 | L7: =C7-I7-J7-K7 -> 0 | M7: =E7-K7 -> 5.4129
A8: 4 | B8: 1.5 | C8: =SUM('3. Raw PV per load'!F5:F136) -> 0 | D8: =SUMIF('4. Raw load per load'!$B$5:$B$136,"prosumer",'4. Raw load per load'!F5:F136) -> 10.9238 | E8: =SUMIF('4. Raw load per load'!$B$5:$B$136,"customer",'4. Raw load per load'!F5:F136) -> 7.0902 | F8: =SUM('5. Raw batt charge'!C8:CA8) -> 0 | G8: =SUM('6. Raw batt discharge'!C8:CA8) -> 10.722 | H8: =F8-G8 -> -10.722 | I8: =MIN(C8,D8) -> 0 | J8: =MIN(C8-I8,MAX(0,H8)) -> 0 | K8: =MIN(C8-I8-J8,E8) -> 0 | L8: =C8-I8-J8-K8 -> 0 | M8: =E8-K8 -> 7.0902
A9: 5 | B9: 2 | C9: =SUM('3. Raw PV per load'!G5:G136) -> 0 | D9: =SUMIF('4. Raw load per load'!$B$5:$B$136,"prosumer",'4. Raw load per load'!G5:G136) -> 8.1915 | E9: =SUMIF('4. Raw load per load'!$B$5:$B$136,"customer",'4. Raw load per load'!G5:G136) -> 5.8701 | F9: =SUM('5. Raw batt charge'!C9:CA9) -> 0 | G9: =SUM('6. Raw batt discharge'!C9:CA9) -> 7.822 | H9: =F9-G9 -> -7.822 | I9: =MIN(C9,D9) -> 0 | J9: =MIN(C9-I9,MAX(0,H9)) -> 0 | K9: =MIN(C9-I9-J9,E9) -> 0 | L9: =C9-I9-J9-K9 -> 0 | M9: =E9-K9 -> 5.8701
A10: 6 | B10: 2.5 | C10: =SUM('3. Raw PV per load'!H5:H136) -> 0 | D10: =SUMIF('4. Raw load per load'!$B$5:$B$136,"prosumer",'4. Raw load per load'!H5:H136) -> 9.5869 | E10: =SUMIF('4. Raw load per load'!$B$5:$B$136,"customer",'4. Raw load per load'!H5:H136) -> 5.9723 | F10: =SUM('5. Raw batt charge'!C10:CA10) -> 0 | G10: =SUM('6. Raw batt discharge'!C10:CA10) -> 9.334 | H10: =F10-G10 -> -9.334 | I10: =MIN(C10,D10) -> 0 | J10: =MIN(C10-I10,MAX(0,H10)) -> 0 | K10: =MIN(C10-I10-J10,E10) -> 0 | L10: =C10-I10-J10-K10 -> 0 | M10: =E10-K10 -> 5.9723
A11: 7 | B11: 3 | C11: =SUM('3. Raw PV per load'!I5:I136) -> 0 | D11: =SUMIF('4. Raw load per load'!$B$5:$B$136,"prosumer",'4. Raw load per load'!I5:I136) -> 10.1676 | E11: =SUMIF('4. Raw load per load'!$B$5:$B$136,"customer",'4. Raw load per load'!I5:I136) -> 6.1997 | F11: =SUM('5. Raw batt charge'!C11:CA11) -> 0 | G11: =SUM('6. Raw batt discharge'!C11:CA11) -> 9.736 | H11: =F11-G11 -> -9.736 | I11: =MIN(C11,D11) -> 0 | J11: =MIN(C11-I11,MAX(0,H11)) -> 0 | K11: =MIN(C11-I11-J11,E11) -> 0 | L11: =C11-I11-J11-K11 -> 0 | M11: =E11-K11 -> 6.1997
A12: 8 | B12: 3.5 | C12: =SUM('3. Raw PV per load'!J5:J136) -> 0.1913 | D12: =SUMIF('4. Raw load per load'!$B$5:$B$136,"prosumer",'4. Raw load per load'!J5:J136) -> 7.875 | E12: =SUMIF('4. Raw load per load'!$B$5:$B$136,"customer",'4. Raw load per load'!J5:J136) -> 6.9557 | F12: =SUM('5. Raw batt charge'!C12:CA12) -> 0 | G12: =SUM('6. Raw batt discharge'!C12:CA12) -> 7.27 | H12: =F12-G12 -> -7.27 | I12: =MIN(C12,D12) -> 0.1913 | J12: =MIN(C12-I12,MAX(0,H12)) -> 0 | K12: =MIN(C12-I12-J12,E12) -> 0 | L12: =C12-I12-J12-K12 -> 0 | M12: =E12-K12 -> 6.9557
A13: 9 | B13: 4 | C13: =SUM('3. Raw PV per load'!K5:K136) -> 2.7665 | D13: =SUMIF('4. Raw load per load'!$B$5:$B$136,"prosumer",'4. Raw load per load'!K5:K136) -> 10.0019 | E13: =SUMIF('4. Raw load per load'!$B$5:$B$136,"customer",'4. Raw load per load'!K5:K136) -> 5.9338 | F13: =SUM('5. Raw batt charge'!C13:CA13) -> 0.004 | G13: =SUM('6. Raw batt discharge'!C13:CA13) -> 6.7423 | H13: =F13-G13 -> -6.7383 | I13: =MIN(C13,D13) -> 2.7665 | J13: =MIN(C13-I13,MAX(0,H13)) -> 0 | K13: =MIN(C13-I13-J13,E13) -> 0 | L13: =C13-I13-J13-K13 -> 0 | M13: =E13-K13 -> 5.9338
A14: 10 | B14: 4.5 | C14: =SUM('3. Raw PV per load'!L5:L136) -> 12.9378 | D14: =SUMIF('4. Raw load per load'!$B$5:$B$136,"prosumer",'4. Raw load per load'!L5:L136) -> 8.9887 | E14: =SUMIF('4. Raw load per load'!$B$5:$B$136,"customer",'4. Raw load per load'!L5:L136) -> 6.8415 | F14: =SUM('5. Raw batt charge'!C14:CA14) -> 5.71 | G14: =SUM('6. Raw batt discharge'!C14:CA14) -> 1.764 | H14: =F14-G14 -> 3.946 | I14: =MIN(C14,D14) -> 8.9887 | J14: =MIN(C14-I14,MAX(0,H14)) -> 3.946 | K14: =MIN(C14-I14-J14,E14) -> 0.0031 | L14: =C14-I14-J14-K14 -> 0 | M14: =E14-K14 -> 6.8384
A15: 11 | B15: 5 | C15: =SUM('3. Raw PV per load'!M5:M136) -> 25.661 | D15: =SUMIF('4. Raw load per load'!$B$5:$B$136,"prosumer",'4. Raw load per load'!M5:M136) -> 8.3604 | E15: =SUMIF('4. Raw load per load'!$B$5:$B$136,"customer",'4. Raw load per load'!M5:M136) -> 6.1488 | F15: =SUM('5. Raw batt charge'!C15:CA15) -> 17.673 | G15: =SUM('6. Raw batt discharge'!C15:CA15) -> 0.32 | H15: =F15-G15 -> 17.353 | I15: =MIN(C15,D15) -> 8.3604 | J15: =MIN(C15-I15,MAX(0,H15)) -> 17.3006 | K15: =MIN(C15-I15-J15,E15) -> 0 | L15: =C15-I15-J15-K15 -> 0 | M15: =E15-K15 -> 6.1488
A16: 12 | B16: 5.5 | C16: =SUM('3. Raw PV per load'!N5:N136) -> 41.267 | D16: =SUMIF('4. Raw load per load'!$B$5:$B$136,"prosumer",'4. Raw load per load'!N5:N136) -> 9.6716 | E16: =SUMIF('4. Raw load per load'!$B$5:$B$136,"customer",'4. Raw load per load'!N5:N136) -> 6.5477 | F16: =SUM('5. Raw batt charge'!C16:CA16) -> 31.624 | G16: =SUM('6. Raw batt discharge'!C16:CA16) -> 0.027 | H16: =F16-G16 -> 31.597 | I16: =MIN(C16,D16) -> 9.6716 | J16: =MIN(C16-I16,MAX(0,H16)) -> 31.5954 | K16: =MIN(C16-I16-J16,E16) -> 0 | L16: =C16-I16-J16-K16 -> 0 | M16: =E16-K16 -> 6.5477
A17: 13 | B17: 6 | C17: =SUM('3. Raw PV per load'!O5:O136) -> 58.2894 | D17: =SUMIF('4. Raw load per load'!$B$5:$B$136,"prosumer",'4. Raw load per load'!O5:O136) -> 9.6461 | E17: =SUMIF('4. Raw load per load'!$B$5:$B$136,"customer",'4. Raw load per load'!O5:O136) -> 7.045 | F17: =SUM('5. Raw batt charge'!C17:CA17) -> 48.648 | G17: =SUM('6. Raw batt discharge'!C17:CA17) -> 0 | H17: =F17-G17 -> 48.648 | I17: =MIN(C17,D17) -> 9.6461 | J17: =MIN(C17-I17,MAX(0,H17)) -> 48.6433 | K17: =MIN(C17-I17-J17,E17) -> 0 | L17: =C17-I17-J17-K17 -> 0 | M17: =E17-K17 -> 7.045
A18: 14 | B18: 6.5 | C18: =SUM('3. Raw PV per load'!P5:P136) -> 75.524 | D18: =SUMIF('4. Raw load per load'!$B$5:$B$136,"prosumer",'4. Raw load per load'!P5:P136) -> 13.654 | E18: =SUMIF('4. Raw load per load'!$B$5:$B$136,"customer",'4. Raw load per load'!P5:P136) -> 7.6288 | F18: =SUM('5. Raw batt charge'!C18:CA18) -> 63.153 | G18: =SUM('6. Raw batt discharge'!C18:CA18) -> 1.279 | H18: =F18-G18 -> 61.874 | I18: =MIN(C18,D18) -> 13.654 | J18: =MIN(C18-I18,MAX(0,H18)) -> 61.87 | K18: =MIN(C18-I18-J18,E18) -> 0 | L18: =C18-I18-J18-K18 -> 0 | M18: =E18-K18 -> 7.6288
A19: 15 | B19: 7 | C19: =SUM('3. Raw PV per load'!Q5:Q136) -> 92.6699 | D19: =SUMIF('4. Raw load per load'!$B$5:$B$136,"prosumer",'4. Raw load per load'!Q5:Q136) -> 11.7598 | E19: =SUMIF('4. Raw load per load'!$B$5:$B$136,"customer",'4. Raw load per load'!Q5:Q136) -> 11.2833 | F19: =SUM('5. Raw batt charge'!C19:CA19) -> 82.028 | G19: =SUM('6. Raw batt discharge'!C19:CA19) -> 1.117 | H19: =F19-G19 -> 80.911 | I19: =MIN(C19,D19) -> 11.7598 | J19: =MIN(C19-I19,MAX(0,H19)) -> 80.9101 | K19: =MIN(C19-I19-J19,E19) -> 0 | L19: =C19-I19-J19-K19 -> 0 | M19: =E19-K19 -> 11.2833
A20: 16 | B20: 7.5 | C20: =SUM('3. Raw PV per load'!R5:R136) -> 109.8377 | D20: =SUMIF('4. Raw load per load'!$B$5:$B$136,"prosumer",'4. Raw load per load'!R5:R136) -> 15.6407 | E20: =SUMIF('4. Raw load per load'!$B$5:$B$136,"customer",'4. Raw load per load'!R5:R136) -> 10.4029 | F20: =SUM('5. Raw batt charge'!C20:CA20) -> 89.354 | G20: =SUM('6. Raw batt discharge'!C20:CA20) -> 0.659 | H20: =F20-G20 -> 88.695 | I20: =MIN(C20,D20) -> 15.6407 | J20: =MIN(C20-I20,MAX(0,H20)) -> 88.695 | K20: =MIN(C20-I20-J20,E20) -> 5.502 | L20: =C20-I20-J20-K20 -> 0 | M20: =E20-K20 -> 4.9009
A21: 17 | B21: 8 | C21: =SUM('3. Raw PV per load'!S5:S136) -> 125.9525 | D21: =SUMIF('4. Raw load per load'!$B$5:$B$136,"prosumer",'4. Raw load per load'!S5:S136) -> 18.5108 | E21: =SUMIF('4. Raw load per load'!$B$5:$B$136,"customer",'4. Raw load per load'!S5:S136) -> 13.5521 | F21: =SUM('5. Raw batt charge'!C21:CA21) -> 63.118 | G21: =SUM('6. Raw batt discharge'!C21:CA21) -> 0 | H21: =F21-G21 -> 63.118 | I21: =MIN(C21,D21) -> 18.5108 | J21: =MIN(C21-I21,MAX(0,H21)) -> 63.118 | K21: =MIN(C21-I21-J21,E21) -> 13.5521 | L21: =C21-I21-J21-K21 -> 30.7716 | M21: =E21-K21 -> 0
A22: 18 | B22: 8.5 | C22: =SUM('3. Raw PV per load'!T5:T136) -> 141.102 | D22: =SUMIF('4. Raw load per load'!$B$5:$B$136,"prosumer",'4. Raw load per load'!T5:T136) -> 32.9066 | E22: =SUMIF('4. Raw load per load'!$B$5:$B$136,"customer",'4. Raw load per load'!T5:T136) -> 12.7291 | F22: =SUM('5. Raw batt charge'!C22:CA22) -> 39.159 | G22: =SUM('6. Raw batt discharge'!C22:CA22) -> 2.901 | H22: =F22-G22 -> 36.258 | I22: =MIN(C22,D22) -> 32.9066 | J22: =MIN(C22-I22,MAX(0,H22)) -> 36.258 | K22: =MIN(C22-I22-J22,E22) -> 12.7291 | L22: =C22-I22-J22-K22 -> 59.2083 | M22: =E22-K22 -> 0
A23: 19 | B23: 9 | C23: =SUM('3. Raw PV per load'!U5:U136) -> 154.0028 | D23: =SUMIF('4. Raw load per load'!$B$5:$B$136,"prosumer",'4. Raw load per load'!U5:U136) -> 29.6883 | E23: =SUMIF('4. Raw load per load'!$B$5:$B$136,"customer",'4. Raw load per load'!U5:U136) -> 15.5878 | F23: =SUM('5. Raw batt charge'!C23:CA23) -> 26.747 | G23: =SUM('6. Raw batt discharge'!C23:CA23) -> 1.019 | H23: =F23-G23 -> 25.728 | I23: =MIN(C23,D23) -> 29.6883 | J23: =MIN(C23-I23,MAX(0,H23)) -> 25.728 | K23: =MIN(C23-I23-J23,E23) -> 15.5878 | L23: =C23-I23-J23-K23 -> 82.9987 | M23: =E23-K23 -> 0
