Workbook

Sheet 1. Overview
B2: TR8 — Where does the PV energy go?
B3: Prosumers vs. pure customers — every kWh traced from the raw model inputs
B5: Purpose
B6: This workbook accounts for every kWh of PV generated on transformer TR8 over one representative day, and it is fully auditable: nothing is hand-typed except the raw model outputs. Follow the data chain below — each step is a live formula, so changing any raw number updates everything.
B10: The data chain (how each number is built)
B11: Sheet 3 · Raw PV per load | C11: The PV profile of every connection, 48 half-hours. Copied verbatim from TR8_load_PV_48periods.xlsx (sheet PV_generation_kW). Customers = 0.
B12: Sheet 4 · Raw load per load | C12: The load profile of every connection, 48 half-hours, tagged prosumer / customer. Copied from TR8_load_PV_48periods.xlsx (sheet Load_P_kW).
B13: Sheet 5 · Raw batt charge | C13: Charging power of every battery, 48 half-hours. Copied from the rolling dispatch TR8_analysis_data.xlsx (sheet Charge_kW).
B14: Sheet 6 · Raw batt discharge | C14: Discharging power of every battery. Copied from the same run (Discharge_kW).
B15: Sheet 7 · PV allocation | C15: Per half-hour: the five blue inputs are AGGREGATED from sheets 3–6 by SUM / SUMIF; the amber columns then split the PV by the priority rule.
B16: Sheets 1 & 8 · Results | C16: Daily totals (Σ×0.5 h) and shares. Every headline cell links to sheet 7.
B18: The aggregation formulas (sheet 7, per half-hour)
B19: PV (all)
B20: prosumer load
B21: customer load
B22: battery charge
B23: battery discharge
B25: Headline results (all linked live to sheet 7)
B26: Quantity | C26: Value | D26: Unit
B27: Prosumers (PV + battery) | C27: 124 | D27: connections
B28: Pure customers (load only) | C28: 176 | D28: connections
B29: PV generated | C29: ='7. PV allocation (per period)'!C53 -> 3081.1269 | D29: kWh/day
B30: PV → prosumers' own load (direct) | C30: ='7. PV allocation (per period)'!I53 -> 529.65205 | D30: kWh/day
B31: PV → battery storage | C31: ='7. PV allocation (per period)'!J53 -> 407.26565 | D31: kWh/day
B32: PV → customers | C32: ='7. PV allocation (per period)'!K53 -> 641.9556 | D32: kWh/day
B33: PV → export to grid | C33: ='7. PV allocation (per period)'!L53 -> 1502.2536 | D33: kWh/day
B34: PV share reaching customers | C34: ='7. PV allocation (per period)'!K53/'7. PV allocation (per period)'!C53 -> 0.20835091 | D34: % of PV
B35: Customer load covered by PV | C35: ='7. PV allocation (per period)'!K53/'7. PV allocation (per period)'!E53 -> 0.51442041 | D35: % of customer load
B36: Customer load covered by grid | C36: ='7. PV allocation (per period)'!M53/'7. PV allocation (per period)'!E53 -> 0.48557959 | D36: % of customer load
B39: Colour key & provenance
B40: • LIGHT-BLUE cell = data belonging to a prosumer (its rooftop PV, load, or battery). WHITE = a pure customer (load only). On sheet 7: VIOLET = value aggregated live from the raw sheets (SUM/SUMIF); AMBER = allocation formula; GREEN = daily total (Σ × 0.5 h).
B41: • Per-load PV & load profiles: results/tables/TR8_load_PV_48periods.xlsx (built from OpData.xls).
B42: • Per-battery charge/discharge: TR8_analysis/01_DAILY_ROLLING_DISPATCH/TR8_analysis_data.xlsx (exact-QCP rolling dispatch, RunFOR_Rolling, CPLEX).
B43: • Load classification (PV size > 0 = prosumer): sheet 'Customers' of the load/PV workbook.
B44: • Method note: priority energy allocation per half-hour; downstream network + battery round-trip losses (~3–4% of PV) are not separated out in the per-period disposition.

Sheet 2. Load classification
A1: TR8 load classification — 300 connections
A2: 124 prosumers (PV + battery) · 176 pure customers (load only)
A4: ID | B4: Load name | C4: Bus | D4: Phase | E4: PV size (kW) | F4: Type
A5: 1959 | B5: Load_TR8_F1_1 | C5: TR8_one38 | D5: 2 | E5: 0 | F5: customer
A6: 1960 | B6: Load_TR8_F1_10 | C6: TR8_one195 | D6: 3 | E6: 0 | F6: customer
A7: 1962 | B7: Load_TR8_F1_12 | C7: TR8_one235 | D7: 1 | E7: 0 | F7: customer
A8: 1963 | B8: Load_TR8_F1_13 | C8: TR8_one242 | D8: 2 | E8: 0 | F8: customer
A9: 1965 | B9: Load_TR8_F1_15 | C9: TR8_one260 | D9: 3 | E9: 0 | F9: customer
A10: 1967 | B10: Load_TR8_F1_17 | C10: TR8_one287 | D10: 2 | E10: 0 | F10: customer
A11: 1968 | B11: Load_TR8_F1_18 | C11: TR8_one299 | D11: 2 | E11: 0 | F11: customer
A12: 1970 | B12: Load_TR8_F1_2 | C12: TR8_one42 | D12: 2 | E12: 0 | F12: customer
A13: 1971 | B13: Load_TR8_F1_20 | C13: TR8_one320 | D13: 2 | E13: 0 | F13: customer
A14: 1973 | B14: Load_TR8_F1_22 | C14: TR8_one328 | D14: 1 | E14: 0 | F14: customer
A15: 1975 | B15: Load_TR8_F1_24 | C15: TR8_one346 | D15: 3 | E15: 0 | F15: customer
A16: 1976 | B16: Load_TR8_F1_25 | C16: TR8_one363 | D16: 3 | E16: 0 | F16: customer
... A304: 2257 | B304: Load_TR8_F6_83 | C304: TR8_six1064 | D304: 3 | E304: 1 | F304: prosumer

Sheet 3. Raw PV per load
A1: Raw PV per load
A2: Verbatim copy of PV_generation_kW (TR8_load_PV_48periods.xlsx). One row per connection, 48 half-hours (kW).
A4: Load name | B4: Type | C4: p1 | D4: p2 | E4: p3 | F4: p4 | G4: p5 | H4: p6 | I4: p7 | J4: p8 | K4: p9 | L4: p10 | M4: p11 | N4: p12 | O4: p13 | P4: p14 | Q4: p15 | R4: p16 | S4: p17 | T4: p18 | U4: p19 | V4: p20 | W4: p21 | X4: p22 | Y4: p23 | Z4: p24 | AA4: p25 | AB4: p26 | AC4: p27 | AD4: p28 | AE4: p29 | AF4: p30 | AG4: p31 | AH4: p32 | AI4: p33 | AJ4: p34 | AK4: p35 | AL4: p36 | AM4: p37 | AN4: p38 | AO4: p39 | AP4: p40 | AQ4: p41 | AR4: p42 | AS4: p43 | AT4: p44 | AU4: p45 | AV4: p46 | AW4: p47 | AX4: p48
A5: Load_TR8_F1_1 | B5: customer | C5: 0 | D5: 0 | E5: 0 | F5: 0 | G5: 0 | H5: 0 | I5: 0 | J5: 0 | K5: 0 | L5: 0 | M5: 0 | N5: 0 | O5: 0 | P5: 0 | Q5: 0 | R5: 0 | S5: 0 | T5: 0 | U5: 0 | V5: 0 | W5: 0 | X5: 0 | Y5: 0 | Z5: 0 | AA5: 0 | AB5: 0 | AC5: 0 | AD5: 0 | AE5: 0 | AF5: 0 | AG5: 0 | AH5: 0 | AI5: 0 | AJ5: 0 | AK5: 0 | AL5: 0 | AM5: 0 | AN5: 0 | AO5: 0 | AP5: 0 | AQ5: 0 | AR5: 0 | AS5: 0 | AT5: 0 | AU5: 0 | AV5: 0 | AW5: 0 | AX5: 0
A6: Load_TR8_F1_10 | B6: customer | C6: 0 | D6: 0 | E6: 0 | F6: 0 | G6: 0 | H6: 0 | I6: 0 | J6: 0 | K6: 0 | L6: 0 | M6: 0 | N6: 0 | O6: 0 | P6: 0 | Q6: 0 | R6: 0 | S6: 0 | T6: 0 | U6: 0 | V6: 0 | W6: 0 | X6: 0 | Y6: 0 | Z6: 0 | AA6: 0 | AB6: 0 | AC6: 0 | AD6: 0 | AE6: 0 | AF6: 0 | AG6: 0 | AH6: 0 | AI6: 0 | AJ6: 0 | AK6: 0 | AL6: 0 | AM6: 0 | AN6: 0 | AO6: 0 | AP6: 0 | AQ6: 0 | AR6: 0 | AS6: 0 | AT6: 0 | AU6: 0 | AV6: 0 | AW6: 0 | AX6: 0
A7: Load_TR8_F1_11 | B7: prosumer | C7: 0 | D7: 0 | E7: 0 | F7: 0 | G7: 0 | H7: 0 | I7: 0 | J7: 0.0017 | K7: 0.0249 | L7: 0.1163 | M7: 0.2307 | N7: 0.3709 | O7: 0.524 | P7: 0.6789 | Q7: 0.833 | R7: 0.9873 | S7: 1.1322 | T7: 1.2683 | U7: 1.3843 | V7: 1.4832 | W7: 1.57 | X7: 1.6417 | Y7: 1.6925 | Z7: 1.7148 | AA7: 1.7212 | AB7: 1.7092 | AC7: 1.6686 | AD7: 1.6067 | AE7: 1.5328 | AF7: 1.4391 | AG7: 1.3396 | AH7: 1.2198 | AI7: 1.0849 | AJ7: 0.922 | AK7: 0.7696 | AL7: 0.613 | AM7: 0.4615 | AN7: 0.3154 | AO7: 0.1842 | AP7: 0.0536 | AQ7: 0.0099 | AR7: 0 | AS7: 0 | AT7: 0 | AU7: 0 | AV7: 0 | AW7: 0 | AX7: 0
A8: Load_TR8_F1_12 | B8: customer | C8: 0 | D8: 0 | E8: 0 | F8: 0 | G8: 0 | H8: 0 | I8: 0 | J8: 0 | K8: 0 | L8: 0 | M8: 0 | N8: 0 | O8: 0 | P8: 0 | Q8: 0 | R8: 0 | S8: 0 | T8: 0 | U8: 0 | V8: 0 | W8: 0 | X8: 0 | Y8: 0 | Z8: 0 | AA8: 0 | AB8: 0 | AC8: 0 | AD8: 0 | AE8: 0 | AF8: 0 | AG8: 0 | AH8: 0 | AI8: 0 | AJ8: 0 | AK8: 0 | AL8: 0 | AM8: 0 | AN8: 0 | AO8: 0 | AP8: 0 | AQ8: 0 | AR8: 0 | AS8: 0 | AT8: 0 | AU8: 0 | AV8: 0 | AW8: 0 | AX8: 0
A9: Load_TR8_F1_13 | B9: customer | C9: 0 | D9: 0 | E9: 0 | F9: 0 | G9: 0 | H9: 0 | I9: 0 | J9: 0 | K9: 0 | L9: 0 | M9: 0 | N9: 0 | O9: 0 | P9: 0 | Q9: 0 | R9: 0 | S9: 0 | T9: 0 | U9: 0 | V9: 0 | W9: 0 | X9: 0 | Y9: 0 | Z9: 0 | AA9: 0 | AB9: 0 | AC9: 0 | AD9: 0 | AE9: 0 | AF9: 0 | AG9: 0 | AH9: 0 | AI9: 0 | AJ9: 0 | AK9: 0 | AL9: 0 | AM9: 0 | AN9: 0 | AO9: 0 | AP9: 0 | AQ9: 0 | AR9: 0 | AS9: 0 | AT9: 0 | AU9: 0 | AV9: 0 | AW9: 0 | AX9: 0
A10: Load_TR8_F1_14 | B10: prosumer | C10: 0 | D10: 0 | E10: 0 | F10: 0 | G10: 0 | H10: 0 | I10: 0 | J10: 0.0022 | K10: 0.0311 | L10: 0.1454 | M10: 0.2883 | N10: 0.4637 | O10: 0.6549 | P10: 0.8486 | Q10: 1.0412 | R10: 1.2341 | S10: 1.4152 | T10: 1.5854 | U10: 1.7304 | V10: 1.854 | W10: 1.9625 | X10: 2.0521 | Y10: 2.1156 | Z10: 2.1435 | AA10: 2.1516 | AB10: 2.1365 | AC10: 2.0857 | AD10: 2.0083 | AE10: 1.9159 | AF10: 1.7989 | AG10: 1.6745 | AH10: 1.5247 | AI10: 1.3561 | AJ10: 1.1525 | AK10: 0.962 | AL10: 0.7662 | AM10: 0.5768 | AN10: 0.3942 | AO10: 0.2302 | AP10: 0.067 | AQ10: 0.0124 | AR10: 0 | AS10: 0 | AT10: 0 | AU10: 0 | AV10: 0 | AW10: 0 | AX10: 0
A11: Load_TR8_F1_15 | B11: customer | C11: 0 | D11: 0 | E11: 0 | F11: 0 | G11: 0 | H11: 0 | I11: 0 | J11: 0 | K11: 0 | L11: 0 | M11: 0 | N11: 0 | O11: 0 | P11: 0 | Q11: 0 | R11: 0 | S11: 0 | T11: 0 | U11: 0 | V11: 0 | W11: 0 | X11: 0 | Y11: 0 | Z11: 0 | AA11: 0 | AB11: 0 | AC11: 0 | AD11: 0 | AE11: 0 | AF11: 0 | AG11: 0 | AH11: 0 | AI11: 0 | AJ11: 0 | AK11: 0 | AL11: 0 | AM11: 0 | AN11: 0 | AO11: 0 | AP11: 0 | AQ11: 0 | AR11: 0 | AS11: 0 | AT11: 0 | AU11: 0 | AV11: 0 | AW11: 0 | AX11: 0
A12: Load_TR8_F1_16 | B12: prosumer | C12: 0 | D12: 0 | E12: 0 | F12: 0 | G12: 0 | H12: 0 | I12: 0 | J12: 0.0022 | K12: 0.0311 | L12: 0.1454 | M12: 0.2883 | N12: 0.4637 | O12: 0.6549 | P12: 0.8486 | Q12: 1.0412 | R12: 1.2341 | S12: 1.4152 | T12: 1.5854 | U12: 1.7304 | V12: 1.854 | W12: 1.9625 | X12: 2.0521 | Y12: 2.1156 | Z12: 2.1435 | AA12: 2.1516 | AB12: 2.1365 | AC12: 2.0857 | AD12: 2.0083 | AE12: 1.9159 | AF12: 1.7989 | AG12: 1.6745 | AH12: 1.5247 | AI12: 1.3561 | AJ12: 1.1525 | AK12: 0.962 | AL12: 0.7662 | AM12: 0.5768 | AN12: 0.3942 | AO12: 0.2302 | AP12: 0.067 | AQ12: 0.0124 | AR12: 0 | AS12: 0 | AT12: 0 | AU12: 0 | AV12: 0 | AW12: 0 | AX12: 0
A13: Load_TR8_F1_17 | B13: customer | C13: 0 | D13: 0 | E13: 0 | F13: 0 | G13: 0 | H13: 0 | I13: 0 | J13: 0 | K13: 0 | L13: 0 | M13: 0 | N13: 0 | O13: 0 | P13: 0 | Q13: 0 | R13: 0 | S13: 0 | T13: 0 | U13: 0 | V13: 0 | W13: 0 | X13: 0 | Y13: 0 | Z13: 0 | AA13: 0 | AB13: 0 | AC13: 0 | AD13: 0 | AE13: 0 | AF13: 0 | AG13: 0 | AH13: 0 | AI13: 0 | AJ13: 0 | AK13: 0 | AL13: 0 | AM13: 0 | AN13: 0 | AO13: 0 | AP13: 0 | AQ13: 0 | AR13: 0 | AS13: 0 | AT13: 0 | AU13: 0 | AV13: 0 | AW13: 0 | AX13: 0
A14: Load_TR8_F1_18 | B14: customer | C14: 0 | D14: 0 | E14: 0 | F14: 0 | G14: 0 | H14: 0 | I14: 0 | J14: 0 | K14: 0 | L14: 0 | M14: 0 | N14: 0 | O14: 0 | P14: 0 | Q14: 0 | R14: 0 | S14: 0 | T14: 0 | U14: 0 | V14: 0 | W14: 0 | X14: 0 | Y14: 0 | Z14: 0 | AA14: 0 | AB14: 0 | AC14: 0 | AD14: 0 | AE14: 0 | AF14: 0 | AG14: 0 | AH14: 0 | AI14: 0 | AJ14: 0 | AK14: 0 | AL14: 0 | AM14: 0 | AN14: 0 | AO14: 0 | AP14: 0 | AQ14: 0 | AR14: 0 | AS14: 0 | AT14: 0 | AU14: 0 | AV14: 0 | AW14: 0 | AX14: 0
A15: Load_TR8_F1_19 | B15: prosumer | C15: 0 | D15: 0 | E15: 0 | F15: 0 | G15: 0 | H15: 0 | I15: 0 | J15: 0.0017 | K15: 0.0249 | L15: 0.1163 | M15: 0.2307 | N15: 0.3709 | O15: 0.524 | P15: 0.6789 | Q15: 0.833 | R15: 0.9873 | S15: 1.1322 | T15: 1.2683 | U15: 1.3843 | V15: 1.4832 | W15: 1.57 | X15: 1.6417 | Y15: 1.6925 | Z15: 1.7148 | AA15: 1.7212 | AB15: 1.7092 | AC15: 1.6686 | AD15: 1.6067 | AE15: 1.5328 | AF15: 1.4391 | AG15: 1.3396 | AH15: 1.2198 | AI15: 1.0849 | AJ15: 0.922 | AK15: 0.7696 | AL15: 0.613 | AM15: 0.4615 | AN15: 0.3154 | AO15: 0.1842 | AP15: 0.0536 | AQ15: 0.0099 | AR15: 0 | AS15: 0 | AT15: 0 | AU15: 0 | AV15: 0 | AW15: 0 | AX15: 0
A16: Load_TR8_F1_2 | B16: customer | C16: 0 | D16: 0 | E16: 0 | F16: 0 | G16: 0 | H16: 0 | I16: 0 | J16: 0 | K16: 0 | L16: 0 | M16: 0 | N16: 0 | O16: 0 | P16: 0 | Q16: 0 | R16: 0 | S16: 0 | T16: 0 | U16: 0 | V16: 0 | W16: 0 | X16: 0 | Y16: 0 | Z16: 0 | AA16: 0 | AB16: 0 | AC16: 0 | AD16: 0 | AE16: 0 | AF16: 0 | AG16: 0 | AH16: 0 | AI16: 0 | AJ16: 0 | AK16: 0 | AL16: 0 | AM16: 0 | AN16: 0 | AO16: 0 | AP16: 0 | AQ16: 0 | AR16: 0 | AS16: 0 | AT16: 0 | AU16: 0 | AV16: 0 | AW16: 0 | AX16: 0
... A304: Load_TR8_F6_9 | B304: customer | C304: 0 | D304: 0 | E304: 0 | F304: 0 | G304: 0 | H304: 0 | I304: 0 | J304: 0 | K304: 0 | L304: 0 | M304: 0 | N304: 0 | O304: 0 | P304: 0 | Q304: 0 | R304: 0 | S304: 0 | T304: 0 | U304: 0 | V304: 0 | W304: 0 | X304: 0 | Y304: 0 | Z304: 0 | AA304: 0 | AB304: 0 | AC304: 0 | AD304: 0 | AE304: 0 | AF304: 0 | AG304: 0 | AH304: 0 | AI304: 0 | AJ304: 0 | AK304: 0 | AL304: 0 | AM304: 0 | AN304: 0 | AO304: 0 | AP304: 0 | AQ304: 0 | AR304: 0 | AS304: 0 | AT304: 0 | AU304: 0 | AV304: 0 | AW304: 0 | AX304: 0

Sheet 4. Raw load per load
A1: Raw load per load
A2: Verbatim copy of Load_P_kW (TR8_load_PV_48periods.xlsx), tagged by type. One row per connection, 48 half-hours (kW).
A4: Load name | B4: Type | C4: p1 | D4: p2 | E4: p3 | F4: p4 | G4: p5 | H4: p6 | I4: p7 | J4: p8 | K4: p9 | L4: p10 | M4: p11 | N4: p12 | O4: p13 | P4: p14 | Q4: p15 | R4: p16 | S4: p17 | T4: p18 | U4: p19 | V4: p20 | W4: p21 | X4: p22 | Y4: p23 | Z4: p24 | AA4: p25 | AB4: p26 | AC4: p27 | AD4: p28 | AE4: p29 | AF4: p30 | AG4: p31 | AH4: p32 | AI4: p33 | AJ4: p34 | AK4: p35 | AL4: p36 | AM4: p37 | AN4: p38 | AO4: p39 | AP4: p40 | AQ4: p41 | AR4: p42 | AS4: p43 | AT4: p44 | AU4: p45 | AV4: p46 | AW4: p47 | AX4: p48
A5: Load_TR8_F1_1 | B5: customer | C5: 0.5221 | D5: 0.6788 | E5: 0.3255 | F5: 0.2989 | G5: 0.1786 | H5: 0.0911 | I5: 0.3005 | J5: 0.0655 | K5: 0.05 | L5: 0.3493 | M5: 0.0577 | N5: 0.05 | O5: 0.22 | P5: 0.058 | Q5: 1.5404 | R5: 1.3141 | S5: 0.7346 | T5: 0.2566 | U5: 0.3473 | V5: 1.4907 | W5: 1.36 | X5: 0.1973 | Y5: 0.2303 | Z5: 0.232 | AA5: 0.1477 | AB5: 0.1048 | AC5: 0.0964 | AD5: 0.5944 | AE5: 1.2544 | AF5: 1.6393 | AG5: 0.3507 | AH5: 2.3126 | AI5: 0.3858 | AJ5: 0.3496 | AK5: 0.119 | AL5: 0.3746 | AM5: 1.3128 | AN5: 0.9198 | AO5: 1.7773 | AP5: 0.607 | AQ5: 0.4781 | AR5: 0.7327 | AS5: 0.7341 | AT5: 0.6956 | AU5: 0.8601 | AV5: 0.8683 | AW5: 0.7639 | AX5: 0.7654
A6: Load_TR8_F1_10 | B6: customer | C6: 0.6385 | D6: 0.3275 | E6: 0.2823 | F6: 0.1154 | G6: 0.2907 | H6: 0.1384 | I6: 0.1907 | J6: 0.1899 | K6: 0.2204 | L6: 0.1972 | M6: 0.0975 | N6: 0.2176 | O6: 0.2617 | P6: 0.059 | Q6: 0.1969 | R6: 0.2823 | S6: 0.129 | T6: 0.176 | U6: 0.1808 | V6: 0.3198 | W6: 1.4824 | X6: 1.2659 | Y6: 0.2828 | Z6: 0.3679 | AA6: 0.6184 | AB6: 1.0152 | AC6: 1.8356 | AD6: 0.4508 | AE6: 0.3539 | AF6: 0.3678 | AG6: 0.4275 | AH6: 0.6463 | AI6: 0.2173 | AJ6: 0.26 | AK6: 0.2569 | AL6: 0.3253 | AM6: 0.5054 | AN6: 0.2656 | AO6: 0.3581 | AP6: 0.8877 | AQ6: 0.3803 | AR6: 0.2534 | AS6: 0.7062 | AT6: 0.6699 | AU6: 0.8827 | AV6: 1.0927 | AW6: 0.3681 | AX6: 0.1822
A7: Load_TR8_F1_11 | B7: prosumer | C7: 0.0979 | D7: 0.043 | E7: 0.1803 | F7: 0.043 | G7: 0.0499 | H7: 0.1735 | I7: 0.043 | J7: 0.1185 | K7: 0.1048 | L7: 0.043 | M7: 0.043 | N7: 0.1803 | O7: 0.043 | P7: 0.043 | Q7: 0.043 | R7: 0.043 | S7: 0.043 | T7: 0.1597 | U7: 0.0748 | V7: 0.1709 | W7: 0.0636 | X7: 0.043 | Y7: 0.1185 | Z7: 0.1048 | AA7: 0.0979 | AB7: 0.1254 | AC7: 0.0705 | AD7: 0.1529 | AE7: 0.043 | AF7: 0.043 | AG7: 0.043 | AH7: 0.043 | AI7: 0.1323 | AJ7: 0.0911 | AK7: 0.043 | AL7: 0.1803 | AM7: 0.043 | AN7: 0.0773 | AO7: 0.146 | AP7: 0.043 | AQ7: 0.1803 | AR7: 0.043 | AS7: 0.1666 | AT7: 0.0567 | AU7: 0.2834 | AV7: 1.8167 | AW7: 0.5643 | AX7: 0.693
A8: Load_TR8_F1_12 | B8: customer | C8: 0.3848 | D8: 0.686 | E8: 0.6559 | F8: 0.2426 | G8: 0.1181 | H8: 0.056 | I8: 0.056 | J8: 0.1181 | K8: 0.056 | L8: 0.1181 | M8: 0.056 | N8: 0.1181 | O8: 0.056 | P8: 0.0801 | Q8: 0.0939 | R8: 0.0974 | S8: 0.1392 | T8: 0.2239 | U8: 0.2366 | V8: 0.2438 | W8: 0.2135 | X8: 0.1992 | Y8: 0.3855 | Z8: 0.4846 | AA8: 0.2153 | AB8: 0.2531 | AC8: 0.3075 | AD8: 1.1973 | AE8: 0.0685 | AF8: 0.1256 | AG8: 0.1411 | AH8: 0.2444 | AI8: 0.212 | AJ8: 0.3949 | AK8: 0.3715 | AL8: 0.4396 | AM8: 0.6372 | AN8: 0.3588 | AO8: 0.5049 | AP8: 0.6015 | AQ8: 0.7672 | AR8: 0.842 | AS8: 0.8197 | AT8: 0.6168 | AU8: 0.5187 | AV8: 1.0013 | AW8: 1.6087 | AX8: 0.056
A9: Load_TR8_F1_13 | B9: customer | C9: 0.6492 | D9: 0.2578 | E9: 0.048 | F9: 0.1323 | G9: 0.1765 | H9: 0.0714 | I9: 0.1089 | J9: 0.1906 | K9: 0.1182 | L9: 0.1874 | M9: 0.1617 | N9: 0.246 | O9: 0.048 | P9: 0.1451 | Q9: 0.1637 | R9: 0.1323 | S9: 0.048 | T9: 0.1701 | U9: 0.0919 | V9: 0.1374 | W9: 0.138 | X9: 0.048 | Y9: 0.1387 | Z9: 0.2165 | AA9: 0.7474 | AB9: 0.9249 | AC9: 0.2259 | AD9: 0.2645 | AE9: 0.0907 | AF9: 0.2561 | AG9: 0.0527 | AH9: 0.295 | AI9: 0.048 | AJ9: 0.0579 | AK9: 0.44 | AL9: 0.3594 | AM9: 1.5254 | AN9: 0.4058 | AO9: 0.3801 | AP9: 0.4612 | AQ9: 0.3404 | AR9: 0.6095 | AS9: 0.3957 | AT9: 0.6477 | AU9: 0.5799 | AV9: 0.4556 | AW9: 0.1323 | AX9: 0.048
A10: Load_TR8_F1_14 | B10: prosumer | C10: 0.049 | D10: 0.2386 | E10: 0.049 | F10: 0.2041 | G10: 0.0835 | H10: 0.049 | I10: 0.1352 | J10: 0.1524 | K10: 0.049 | L10: 0.2386 | M10: 0.049 | N10: 0.1266 | O10: 0.161 | P10: 0.049 | Q10: 0.1869 | R10: 0.1007 | S10: 0.1179 | T10: 0.1697 | U10: 0.049 | V10: 0.0835 | W10: 0.2041 | X10: 0.049 | Y10: 0.2386 | Z10: 0.049 | AA10: 0.0921 | AB10: 0.1998 | AC10: 0.4071 | AD10: 0.7305 | AE10: 0.1793 | AF10: 0.1018 | AG10: 0.3206 | AH10: 0.149 | AI10: 0.648 | AJ10: 0.0662 | AK10: 0.2125 | AL10: 0.3044 | AM10: 0.0662 | AN10: 0.2214 | AO10: 0.049 | AP10: 0.0576 | AQ10: 0.23 | AR10: 0.049 | AS10: 0.2041 | AT10: 0.0835 | AU10: 0.049 | AV10: 0.049 | AW10: 0.2386 | AX10: 0.049
A11: Load_TR8_F1_15 | B11: customer | C11: 0.059 | D11: 0.0908 | E11: 0.1864 | F11: 0.051 | G11: 0.2262 | H11: 0.051 | I11: 0.051 | J11: 0.2262 | K11: 0.051 | L11: 0.051 | M11: 0.1227 | N11: 0.1545 | O11: 0.051 | P11: 0.051 | Q11: 0.1784 | R11: 0.0988 | S11: 0.0908 | T11: 0.2603 | U11: 0.0836 | V11: 0.1882 | W11: 1.2359 | X11: 4.996 | Y11: 2.6535 | Z11: 0.7891 | AA11: 0.051 | AB11: 0.1147 | AC11: 0.1625 | AD11: 0.051 | AE11: 0.0765 | AF11: 0.2222 | AG11: 0.3101 | AH11: 0.3166 | AI11: 0.3343 | AJ11: 0.1354 | AK11: 0.4772 | AL11: 0.1398 | AM11: 0.1057 | AN11: 0.1944 | AO11: 0.1213 | AP11: 0.7084 | AQ11: 0.7746 | AR11: 0.809 | AS11: 0.842 | AT11: 0.8902 | AU11: 1.321 | AV11: 1.3209 | AW11: 2.8959 | AX11: 3.5458
A12: Load_TR8_F1_16 | B12: prosumer | C12: 0.0546 | D12: 0.1263 | E12: 0.063 | F12: 0.051 | G12: 0.051 | H12: 0.051 | I12: 0.051 | J12: 0.051 | K12: 0.051 | L12: 0.051 | M12: 0.051 | N12: 0.051 | O12: 0.051 | P12: 0.051 | Q12: 0.051 | R12: 0.051 | S12: 0.051 | T12: 0.051 | U12: 0.0643 | V12: 0.0606 | W12: 0.0555 | X12: 0.066 | Y12: 0.051 | Z12: 0.051 | AA12: 0.051 | AB12: 0.051 | AC12: 0.9924 | AD12: 0.1175 | AE12: 0.051 | AF12: 0.051 | AG12: 0.0546 | AH12: 0.0546 | AI12: 0.051 | AJ12: 0.051 | AK12: 0.051 | AL12: 0.051 | AM12: 0.051 | AN12: 0.051 | AO12: 0.051 | AP12: 0.051 | AQ12: 0.051 | AR12: 0.051 | AS12: 0.051 | AT12: 0.1022 | AU12: 0.051 | AV12: 0.051 | AW12: 0.051 | AX12: 0.051
A13: Load_TR8_F1_17 | B13: customer | C13: 0.043 | D13: 0.2252 | E13: 0.043 | F13: 0.0844 | G13: 0.1838 | H13: 0.043 | I13: 0.1589 | J13: 0.1092 | K13: 0.0761 | L13: 0.192 | M13: 0.043 | N13: 0.1506 | O13: 0.1175 | P13: 0.2137 | Q13: 0.0981 | R13: 0.2086 | S13: 0.0596 | T13: 0.1341 | U13: 0.2985 | V13: 0.446 | W13: 0.3738 | X13: 0.0538 | Y13: 0.2334 | Z13: 0.2711 | AA13: 0.4528 | AB13: 0.2305 | AC13: 0.214 | AD13: 0.2252 | AE13: 0.043 | AF13: 0.1755 | AG13: 0.5208 | AH13: 0.3695 | AI13: 0.4531 | AJ13: 0.214 | AK13: 0.4202 | AL13: 0.3303 | AM13: 0.2642 | AN13: 0.2626 | AO13: 0.3386 | AP13: 0.6433 | AQ13: 0.4406 | AR13: 0.5417 | AS13: 0.765 | AT13: 0.4494 | AU13: 0.5387 | AV13: 0.5744 | AW13: 0.043 | AX13: 0.1424
A14: Load_TR8_F1_18 | B14: customer | C14: 0.051 | D14: 0.051 | E14: 0.051 | F14: 0.051 | G14: 0.051 | H14: 0.051 | I14: 0.051 | J14: 0.051 | K14: 0.051 | L14: 0.051 | M14: 0.051 | N14: 0.051 | O14: 0.051 | P14: 0.051 | Q14: 0.051 | R14: 0.114 | S14: 0.2521 | T14: 0.8453 | U14: 0.4833 | V14: 0.051 | W14: 0.051 | X14: 0.051 | Y14: 0.051 | Z14: 0.051 | AA14: 0.051 | AB14: 0.051 | AC14: 0.051 | AD14: 0.051 | AE14: 0.051 | AF14: 0.1081 | AG14: 0.1428 | AH14: 0.0689 | AI14: 0.0852 | AJ14: 0.0622 | AK14: 0.051 | AL14: 0.051 | AM14: 0.0748 | AN14: 0.2926 | AO14: 0.4251 | AP14: 0.8624 | AQ14: 1.013 | AR14: 0.8493 | AS14: 0.8506 | AT14: 0.8378 | AU14: 0.943 | AV14: 0.7243 | AW14: 0.5742 | AX14: 0.5885
A15: Load_TR8_F1_19 | B15: prosumer | C15: 0.059 | D15: 0.059 | E15: 0.059 | F15: 0.059 | G15: 0.059 | H15: 0.059 | I15: 0.059 | J15: 0.059 | K15: 0.059 | L15: 0.059 | M15: 0.059 | N15: 0.059 | O15: 0.059 | P15: 0.059 | Q15: 0.059 | R15: 0.059 | S15: 0.5567 | T15: 0.5627 | U15: 1.7257 | V15: 0.452 | W15: 1.1208 | X15: 0.0688 | Y15: 2.0651 | Z15: 4.6403 | AA15: 0.5566 | AB15: 0.059 | AC15: 0.059 | AD15: 0.059 | AE15: 0.059 | AF15: 0.059 | AG15: 0.059 | AH15: 0.059 | AI15: 0.059 | AJ15: 0.059 | AK15: 0.059 | AL15: 0.059 | AM15: 0.059 | AN15: 0.059 | AO15: 0.063 | AP15: 0.2246 | AQ15: 0.6629 | AR15: 0.6212 | AS15: 0.5872 | AT15: 0.551 | AU15: 0.059 | AV15: 0.059 | AW15: 0.059 | AX15: 0.059
A16: Load_TR8_F1_2 | B16: customer | C16: 0.0827 | D16: 0.1832 | E16: 0.054 | F16: 0.054 | G16: 0.054 | H16: 0.1473 | I16: 0.1186 | J16: 0.0684 | K16: 0.1976 | L16: 0.054 | M16: 0.0755 | N16: 0.1904 | O16: 0.054 | P16: 0.2119 | Q16: 0.054 | R16: 0.0971 | S16: 0.1688 | T16: 0.3106 | U16: 0.4862 | V16: 0.2434 | W16: 1.7953 | X16: 0.2356 | Y16: 0.2627 | Z16: 0.2833 | AA16: 1.1008 | AB16: 0.3436 | AC16: 0.2584 | AD16: 0.2143 | AE16: 0.1942 | AF16: 0.2929 | AG16: 0.4988 | AH16: 0.2229 | AI16: 0.1831 | AJ16: 0.2064 | AK16: 0.1997 | AL16: 0.0863 | AM16: 0.1831 | AN16: 0.3724 | AO16: 0.183 | AP16: 0.2462 | AQ16: 0.3063 | AR16: 0.4221 | AS16: 0.5006 | AT16: 0.422 | AU16: 0.5368 | AV16: 0.3342 | AW16: 0.9358 | AX16: 0.6568
... A304: Load_TR8_F6_9 | B304: customer | C304: 0.4092 | D304: 0.3567 | E304: 0.0664 | F304: 0.1901 | G304: 0.1344 | H304: 0.1301 | I304: 0.1944 | J304: 0.04 | K304: 0.2845 | L304: 0.04 | M304: 0.04 | N304: 0.055 | O304: 0.1901 | P304: 0.0929 | Q304: 0.0815 | R304: 0.1901 | S304: 0.0474 | T304: 0.2066 | U304: 0.0885 | V304: 0.1609 | W304: 0.1297 | X304: 0.7581 | Y304: 2.5229 | Z304: 1.7852 | AA304: 0.162 | AB304: 0.2914 | AC304: 0.0515 | AD304: 0.1751 | AE304: 0.07 | AF304: 0.1226 | AG304: 0.1358 | AH304: 0.1061 | AI304: 0.1901 | AJ304: 0.0884 | AK304: 0.1874 | AL304: 0.3237 | AM304: 1.1118 | AN304: 0.2097 | AO304: 0.1879 | AP304: 0.2355 | AQ304: 0.3561 | AR304: 0.1861 | AS304: 0.2826 | AT304: 0.3114 | AU304: 0.3199 | AV304: 0.3961 | AW304: 0.3583 | AX304: 0.1706

Sheet 5. Raw batt charge
A1: Raw batt charge
A2: Verbatim copy of Charge_kW (TR8_analysis_data.xlsx). One row per half-hour, one column per battery (kW).
A4: period | B4: hour | C4: BES_TR8_one223_B | D4: BES_TR8_one252_C | E4: BES_TR8_one280_A | F4: BES_TR8_one313_A | G4: BES_TR8_one321_C | H4: BES_TR8_one345_A | I4: BES_TR8_one375_C | J4: BES_TR8_one410_B | K4: BES_TR8_one416_C | L4: BES_TR8_one423_B | M4: BES_TR8_one446_B | N4: BES_TR8_one469_A | O4: BES_TR8_one477_A | P4: BES_TR8_one482_B | Q4: BES_TR8_one61_A | R4: BES_TR8_one552_B | S4: BES_TR8_one560_C | T4: BES_TR8_one73_A | U4: BES_TR8_one137_A | V4: BES_TR8_four50_C | W4: BES_TR8_four171_A | X4: BES_TR8_four180_A | Y4: BES_TR8_four200_A | Z4: BES_TR8_four239_A | AA4: BES_TR8_four259_B | AB4: BES_TR8_four265_C | AC4: BES_TR8_four54_C | AD4: BES_TR8_four288_B | AE4: BES_TR8_four289_B | AF4: BES_TR8_four292_C | AG4: BES_TR8_four301_C | AH4: BES_TR8_four326_A | AI4: BES_TR8_four352_A | AJ4: BES_TR8_four358_C | AK4: BES_TR8_four368_C | AL4: BES_TR8_four372_C | AM4: BES_TR8_four381_A | AN4: BES_TR8_four385_A | AO4: BES_TR8_four423_C | AP4: BES_TR8_four437_A | AQ4: BES_TR8_four446_B | AR4: BES_TR8_four466_C | AS4: BES_TR8_four467_C | AT4: BES_TR8_four548_B | AU4: BES_TR8_four558_C | AV4: BES_TR8_four562_C | AW4: BES_TR8_four590_A | AX4: BES_TR8_four604_A | AY4: BES_TR8_four78_B | AZ4: BES_TR8_four734_A | BA4: BES_TR8_four797_C | BB4: BES_TR8_four846_C | BC4: BES_TR8_four854_A | BD4: BES_TR8_four936_C | BE4: BES_TR8_four950_B | BF4: BES_TR8_four978_A | BG4: BES_TR8_four104_A | BH4: BES_TR8_four988_A | BI4: BES_TR8_four1013_B | BJ4: BES_TR8_four1027_A | BK4: BES_TR8_four1132_C | BL4: BES_TR8_four126_A | BM4: BES_TR8_four1187_A | BN4: BES_TR8_four1207_B | BO4: BES_TR8_five168_A | BP4: BES_TR8_five186_C | BQ4: BES_TR8_five194_C | BR4: BES_TR8_five223_A | BS4: BES_TR8_five303_B | BT4: BES_TR8_five324_B | BU4: BES_TR8_five345_A | BV4: BES_TR8_five421_A | BW4: BES_TR8_five488_B | BX4: BES_TR8_five513_B | BY4: BES_TR8_five537_C | BZ4: BES_TR8_five540_A | CA4: BES_TR8_five551_C | CB4: BES_TR8_five631_B | CC4: BES_TR8_five649_A | CD4: BES_TR8_five663_C | CE4: BES_TR8_five670_C | CF4: BES_TR8_five704_A | CG4: BES_TR8_five719_A | CH4: BES_TR8_five750_B | CI4: BES_TR8_five793_A | CJ4: BES_TR8_five801_C | CK4: BES_TR8_five905_B | CL4: BES_TR8_five118_B | CM4: BES_TR8_five123_B | CN4: BES_TR8_six64_A | CO4: BES_TR8_six154_C | CP4: BES_TR8_six173_C | CQ4: BES_TR8_six232_C | CR4: BES_TR8_six238_A | CS4: BES_TR8_six269_C | CT4: BES_TR8_six289_C | CU4: BES_TR8_six317_C | CV4: BES_TR8_six326_A | CW4: BES_TR8_six329_A | CX4: BES_TR8_six342_A | CY4: BES_TR8_six350_B | CZ4: BES_TR8_six365_C | DA4: BES_TR8_six75_A | DB4: BES_TR8_six385_B | DC4: BES_TR8_six431_C | DD4: BES_TR8_six571_C | DE4: BES_TR8_six595_B | DF4: BES_TR8_six643_A | DG4: BES_TR8_six652_A | DH4: BES_TR8_six667_A | DI4: BES_TR8_six699_C | DJ4: BES_TR8_six723_B | DK4: BES_TR8_six740_A | DL4: BES_TR8_six90_B | DM4: BES_TR8_six801_C | DN4: BES_TR8_six807_A | DO4: BES_TR8_six844_C | DP4: BES_TR8_six860_C | DQ4: BES_TR8_six909_C | DR4: BES_TR8_six914_A | DS4: BES_TR8_six111_C | DT4: BES_TR8_six1006_C | DU4: BES_TR8_six1020_A | DV4: BES_TR8_six1064_C
A5: 1 | B5: 0 | C5: 0 | D5: 0 | E5: 0 | F5: 0 | G5: 0 | H5: 0 | I5: 0 | J5: 0 | K5: 0 | L5: 0 | M5: 0 | N5: 0 | O5: 0 | P5: 0 | Q5: 0 | R5: 0 | S5: 0 | T5: 0 | U5: 0 | V5: 0 | W5: 0 | X5: 0 | Y5: 0 | Z5: 0 | AA5: 0 | AB5: 0 | AC5: 0 | AD5: 0 | AE5: 0 | AF5: 0 | AG5: 0 | AH5: 0 | AI5: 0 | AJ5: 0 | AK5: 0 | AL5: 0 | AM5: 0 | AN5: 0 | AO5: 0 | AP5: 0 | AQ5: 0 | AR5: 0 | AS5: 0 | AT5: 0 | AU5: 0 | AV5: 0 | AW5: 0 | AX5: 0 | AY5: 0 | AZ5: 0 | BA5: 0 | BB5: 0 | BC5: 0 | BD5: 0 | BE5: 0 | BF5: 0 | BG5: 0 | BH5: 0 | BI5: 0 | BJ5: 0 | BK5: 0 | BL5: 0 | BM5: 0 | BN5: 0 | BO5: 0 | BP5: 0 | BQ5: 0 | BR5: 0 | BS5: 0 | BT5: 0 | BU5: 0 | BV5: 0 | BW5: 0 | BX5: 0 | BY5: 0 | BZ5: 0 | CA5: 0 | CB5: 0 | CC5: 0 | CD5: 0 | CE5: 0 | CF5: 0 | CG5: 0 | CH5: 0 | CI5: 0 | CJ5: 0 | CK5: 0 | CL5: 0 | CM5: 0 | CN5: 0 | CO5: 0 | CP5: 0 | CQ5: 0 | CR5: 0 | CS5: 0 | CT5: 0 | CU5: 0 | CV5: 0 | CW5: 0 | CX5: 0 | CY5: 0 | CZ5: 0 | DA5: 0 | DB5: 0 | DC5: 0 | DD5: 0 | DE5: 0 | DF5: 0 | DG5: 0 | DH5: 0 | DI5: 0 | DJ5: 0 | DK5: 0 | DL5: 0 | DM5: 0 | DN5: 0 | DO5: 0 | DP5: 0 | DQ5: 0 | DR5: 0 | DS5: 0 | DT5: 0 | DU5: 0 | DV5: 0
A6: 2 | B6: 0.5 | C6: 0 | D6: 0 | E6: 0 | F6: 0 | G6: 0 | H6: 0 | I6: 0 | J6: 0 | K6: 0 | L6: 0 | M6: 0 | N6: 0 | O6: 0 | P6: 0 | Q6: 0 | R6: 0 | S6: 0 | T6: 0 | U6: 0 | V6: 0 | W6: 0 | X6: 0 | Y6: 0 | Z6: 0 | AA6: 0 | AB6: 0 | AC6: 0 | AD6: 0 | AE6: 0 | AF6: 0 | AG6: 0 | AH6: 0 | AI6: 0 | AJ6: 0 | AK6: 0 | AL6: 0 | AM6: 0 | AN6: 0 | AO6: 0 | AP6: 0 | AQ6: 0 | AR6: 0 | AS6: 0 | AT6: 0 | AU6: 0 | AV6: 0 | AW6: 0 | AX6: 0 | AY6: 0 | AZ6: 0 | BA6: 0 | BB6: 0 | BC6: 0 | BD6: 0 | BE6: 0 | BF6: 0 | BG6: 0 | BH6: 0 | BI6: 0 | BJ6: 0 | BK6: 0 | BL6: 0 | BM6: 0 | BN6: 0 | BO6: 0 | BP6: 0 | BQ6: 0 | BR6: 0 | BS6: 0 | BT6: 0 | BU6: 0 | BV6: 0 | BW6: 0 | BX6: 0 | BY6: 0 | BZ6: 0 | CA6: 0 | CB6: 0 | CC6: 0 | CD6: 0 | CE6: 0 | CF6: 0 | CG6: 0 | CH6: 0 | CI6: 0 | CJ6: 0 | CK6: 0 | CL6: 0 | CM6: 0 | CN6: 0 | CO6: 0 | CP6: 0 | CQ6: 0 | CR6: 0 | CS6: 0 | CT6: 0 | CU6: 0 | CV6: 0 | CW6: 0 | CX6: 0 | CY6: 0 | CZ6: 0 | DA6: 0 | DB6: 0 | DC6: 0 | DD6: 0 | DE6: 0 | DF6: 0 | DG6: 0 | DH6: 0 | DI6: 0 | DJ6: 0 | DK6: 0 | DL6: 0 | DM6: 0 | DN6: 0 | DO6: 0 | DP6: 0 | DQ6: 0 | DR6: 0 | DS6: 0 | DT6: 0 | DU6: 0 | DV6: 0
A7: 3 | B7: 1 | C7: 0 | D7: 0 | E7: 0 | F7: 0 | G7: 0 | H7: 0 | I7: 0 | J7: 0 | K7: 0 | L7: 0 | M7: 0 | N7: 0 | O7: 0 | P7: 0 | Q7: 0 | R7: 0 | S7: 0 | T7: 0 | U7: 0 | V7: 0 | W7: 0 | X7: 0 | Y7: 0 | Z7: 0 | AA7: 0 | AB7: 0 | AC7: 0 | AD7: 0 | AE7: 0 | AF7: 0 | AG7: 0 | AH7: 0 | AI7: 0 | AJ7: 0 | AK7: 0 | AL7: 0 | AM7: 0 | AN7: 0 | AO7: 0 | AP7: 0 | AQ7: 0 | AR7: 0 | AS7: 0 | AT7: 0 | AU7: 0 | AV7: 0 | AW7: 0 | AX7: 0 | AY7: 0 | AZ7: 0 | BA7: 0 | BB7: 0 | BC7: 0 | BD7: 0 | BE7: 0 | BF7: 0 | BG7: 0 | BH7: 0 | BI7: 0 | BJ7: 0 | BK7: 0 | BL7: 0 | BM7: 0 | BN7: 0 | BO7: 0 | BP7: 0 | BQ7: 0 | BR7: 0 | BS7: 0 | BT7: 0 | BU7: 0 | BV7: 0 | BW7: 0 | BX7: 0 | BY7: 0 | BZ7: 0 | CA7: 0 | CB7: 0 | CC7: 0 | CD7: 0 | CE7: 0 | CF7: 0 | CG7: 0 | CH7: 0 | CI7: 0 | CJ7: 0 | CK7: 0 | CL7: 0 | CM7: 0 | CN7: 0 | CO7: 0 | CP7: 0 | CQ7: 0 | CR7: 0 | CS7: 0 | CT7: 0 | CU7: 0 | CV7: 0 | CW7: 0 | CX7: 0 | CY7: 0 | CZ7: 0 | DA7: 0 | DB7: 0 | DC7: 0 | DD7: 0 | DE7: 0 | DF7: 0 | DG7: 0 | DH7: 0 | DI7: 0 | DJ7: 0 | DK7: 0 | DL7: 0 | DM7: 0 | DN7: 0 | DO7: 0 | DP7: 0 | DQ7: 0 | DR7: 0 | DS7: 0 | DT7: 0 | DU7: 0 | DV7: 0
A8: 4 | B8: 1.5 | C8: 0 | D8: 0 | E8: 0 | F8: 0 | G8: 0 | H8: 0 | I8: 0 | J8: 0 | K8: 0 | L8: 0 | M8: 0 | N8: 0 | O8: 0 | P8: 0 | Q8: 0 | R8: 0 | S8: 0 | T8: 0 | U8: 0 | V8: 0 | W8: 0 | X8: 0 | Y8: 0 | Z8: 0 | AA8: 0 | AB8: 0 | AC8: 0 | AD8: 0 | AE8: 0 | AF8: 0 | AG8: 0 | AH8: 0 | AI8: 0 | AJ8: 0 | AK8: 0 | AL8: 0 | AM8: 0 | AN8: 0 | AO8: 0 | AP8: 0 | AQ8: 0 | AR8: 0 | AS8: 0 | AT8: 0 | AU8: 0 | AV8: 0 | AW8: 0 | AX8: 0 | AY8: 0 | AZ8: 0 | BA8: 0 | BB8: 0 | BC8: 0 | BD8: 0 | BE8: 0 | BF8: 0 | BG8: 0 | BH8: 0 | BI8: 0 | BJ8: 0 | BK8: 0 | BL8: 0 | BM8: 0 | BN8: 0 | BO8: 0 | BP8: 0 | BQ8: 0 | BR8: 0 | BS8: 0 | BT8: 0 | BU8: 0 | BV8: 0 | BW8: 0 | BX8: 0 | BY8: 0 | BZ8: 0 | CA8: 0 | CB8: 0 | CC8: 0 | CD8: 0 | CE8: 0 | CF8: 0 | CG8: 0 | CH8: 0 | CI8: 0 | CJ8: 0 | CK8: 0 | CL8: 0 | CM8: 0 | CN8: 0 | CO8: 0 | CP8: 0 | CQ8: 0 | CR8: 0 | CS8: 0 | CT8: 0 | CU8: 0 | CV8: 0 | CW8: 0 | CX8: 0 | CY8: 0 | CZ8: 0 | DA8: 0 | DB8: 0 | DC8: 0 | DD8: 0 | DE8: 0 | DF8: 0 | DG8: 0 | DH8: 0 | DI8: 0 | DJ8: 0 | DK8: 0 | DL8: 0 | DM8: 0 | DN8: 0 | DO8: 0 | DP8: 0 | DQ8: 0 | DR8: 0 | DS8: 0 | DT8: 0 | DU8: 0 | DV8: 0
A9: 5 | B9: 2 | C9: 0 | D9: 0 | E9: 0 | F9: 0 | G9: 0 | H9: 0 | I9: 0 | J9: 0 | K9: 0 | L9: 0 | M9: 0 | N9: 0 | O9: 0 | P9: 0 | Q9: 0 | R9: 0 | S9: 0 | T9: 0 | U9: 0 | V9: 0 | W9: 0 | X9: 0 | Y9: 0 | Z9: 0 | AA9: 0 | AB9: 0 | AC9: 0 | AD9: 0 | AE9: 0 | AF9: 0 | AG9: 0 | AH9: 0 | AI9: 0 | AJ9: 0 | AK9: 0 | AL9: 0 | AM9: 0 | AN9: 0 | AO9: 0 | AP9: 0 | AQ9: 0 | AR9: 0 | AS9: 0 | AT9: 0 | AU9: 0 | AV9: 0 | AW9: 0 | AX9: 0 | AY9: 0 | AZ9: 0 | BA9: 0 | BB9: 0 | BC9: 0 | BD9: 0 | BE9: 0 | BF9: 0 | BG9: 0 | BH9: 0 | BI9: 0 | BJ9: 0 | BK9: 0 | BL9: 0 | BM9: 0 | BN9: 0 | BO9: 0 | BP9: 0 | BQ9: 0 | BR9: 0 | BS9: 0 | BT9: 0 | BU9: 0 | BV9: 0 | BW9: 0 | BX9: 0 | BY9: 0 | BZ9: 0 | CA9: 0 | CB9: 0 | CC9: 0 | CD9: 0 | CE9: 0 | CF9: 0 | CG9: 0 | CH9: 0 | CI9: 0 | CJ9: 0 | CK9: 0 | CL9: 0 | CM9: 0 | CN9: 0 | CO9: 0 | CP9: 0 | CQ9: 0 | CR9: 0 | CS9: 0 | CT9: 0 | CU9: 0 | CV9: 0 | CW9: 0 | CX9: 0 | CY9: 0 | CZ9: 0 | DA9: 0 | DB9: 0 | DC9: 0 | DD9: 0 | DE9: 0 | DF9: 0 | DG9: 0 | DH9: 0 | DI9: 0 | DJ9: 0 | DK9: 0 | DL9: 0 | DM9: 0 | DN9: 0 | DO9: 0 | DP9: 0 | DQ9: 0 | DR9: 0 | DS9: 0 | DT9: 0 | DU9: 0 | DV9: 0
A10: 6 | B10: 2.5 | C10: 0 | D10: 0 | E10: 0 | F10: 0 | G10: 0 | H10: 0 | I10: 0 | J10: 0 | K10: 0 | L10: 0 | M10: 0 | N10: 0 | O10: 0 | P10: 0 | Q10: 0 | R10: 0 | S10: 0 | T10: 0 | U10: 0 | V10: 0 | W10: 0 | X10: 0 | Y10: 0 | Z10: 0 | AA10: 0 | AB10: 0 | AC10: 0 | AD10: 0 | AE10: 0 | AF10: 0 | AG10: 0 | AH10: 0 | AI10: 0 | AJ10: 0 | AK10: 0 | AL10: 0 | AM10: 0 | AN10: 0 | AO10: 0 | AP10: 0 | AQ10: 0 | AR10: 0 | AS10: 0 | AT10: 0 | AU10: 0 | AV10: 0 | AW10: 0 | AX10: 0 | AY10: 0 | AZ10: 0 | BA10: 0 | BB10: 0 | BC10: 0 | BD10: 0 | BE10: 0 | BF10: 0 | BG10: 0 | BH10: 0 | BI10: 0 | BJ10: 0 | BK10: 0 | BL10: 0 | BM10: 0 | BN10: 0 | BO10: 0 | BP10: 0 | BQ10: 0 | BR10: 0 | BS10: 0 | BT10: 0 | BU10: 0 | BV10: 0 | BW10: 0 | BX10: 0 | BY10: 0 | BZ10: 0 | CA10: 0 | CB10: 0 | CC10: 0 | CD10: 0 | CE10: 0 | CF10: 0 | CG10: 0 | CH10: 0 | CI10: 0 | CJ10: 0 | CK10: 0 | CL10: 0 | CM10: 0 | CN10: 0 | CO10: 0 | CP10: 0 | CQ10: 0 | CR10: 0 | CS10: 0 | CT10: 0 | CU10: 0 | CV10: 0 | CW10: 0 | CX10: 0 | CY10: 0 | CZ10: 0 | DA10: 0 | DB10: 0 | DC10: 0 | DD10: 0 | DE10: 0 | DF10: 0 | DG10: 0 | DH10: 0 | DI10: 0 | DJ10: 0 | DK10: 0 | DL10: 0 | DM10: 0 | DN10: 0 | DO10: 0 | DP10: 0 | DQ10: 0 | DR10: 0 | DS10: 0 | DT10: 0 | DU10: 0 | DV10: 0
A11: 7 | B11: 3 | C11: 0 | D11: 0 | E11: 0 | F11: 0 | G11: 0 | H11: 0 | I11: 0 | J11: 0 | K11: 0 | L11: 0 | M11: 0 | N11: 0 | O11: 0 | P11: 0 | Q11: 0 | R11: 0 | S11: 0 | T11: 0 | U11: 0 | V11: 0 | W11: 0 | X11: 0 | Y11: 0 | Z11: 0 | AA11: 0 | AB11: 0 | AC11: 0 | AD11: 0 | AE11: 0 | AF11: 0 | AG11: 0 | AH11: 0 | AI11: 0 | AJ11: 0 | AK11: 0 | AL11: 0 | AM11: 0 | AN11: 0 | AO11: 0 | AP11: 0 | AQ11: 0 | AR11: 0 | AS11: 0 | AT11: 0 | AU11: 0 | AV11: 0 | AW11: 0 | AX11: 0 | AY11: 0 | AZ11: 0 | BA11: 0 | BB11: 0 | BC11: 0 | BD11: 0 | BE11: 0 | BF11: 0 | BG11: 0 | BH11: 0 | BI11: 0 | BJ11: 0 | BK11: 0 | BL11: 0 | BM11: 0 | BN11: 0 | BO11: 0 | BP11: 0 | BQ11: 0 | BR11: 0 | BS11: 0 | BT11: 0 | BU11: 0 | BV11: 0 | BW11: 0 | BX11: 0 | BY11: 0 | BZ11: 0 | CA11: 0 | CB11: 0 | CC11: 0 | CD11: 0 | CE11: 0 | CF11: 0 | CG11: 0 | CH11: 0 | CI11: 0 | CJ11: 0 | CK11: 0 | CL11: 0 | CM11: 0 | CN11: 0 | CO11: 0 | CP11: 0 | CQ11: 0 | CR11: 0 | CS11: 0 | CT11: 0 | CU11: 0 | CV11: 0 | CW11: 0 | CX11: 0 | CY11: 0 | CZ11: 0 | DA11: 0 | DB11: 0 | DC11: 0 | DD11: 0 | DE11: 0 | DF11: 0 | DG11: 0 | DH11: 0 | DI11: 0 | DJ11: 0 | DK11: 0 | DL11: 0 | DM11: 0 | DN11: 0 | DO11: 0 | DP11: 0 | DQ11: 0 | DR11: 0 | DS11: 0 | DT11: 0 | DU11: 0 | DV11: 0
A12: 8 | B12: 3.5 | C12: 0 | D12: 0 | E12: 0 | F12: 0 | G12: 0 | H12: 0 | I12: 0 | J12: 0 | K12: 0 | L12: 0 | M12: 0 | N12: 0 | O12: 0 | P12: 0 | Q12: 0 | R12: 0 | S12: 0 | T12: 0 | U12: 0 | V12: 0 | W12: 0 | X12: 0 | Y12: 0 | Z12: 0 | AA12: 0 | AB12: 0 | AC12: 0 | AD12: 0 | AE12: 0 | AF12: 0 | AG12: 0 | AH12: 0 | AI12: 0 | AJ12: 0 | AK12: 0 | AL12: 0 | AM12: 0 | AN12: 0 | AO12: 0 | AP12: 0 | AQ12: 0 | AR12: 0 | AS12: 0 | AT12: 0 | AU12: 0 | AV12: 0 | AW12: 0 | AX12: 0 | AY12: 0 | AZ12: 0 | BA12: 0 | BB12: 0 | BC12: 0 | BD12: 0 | BE12: 0 | BF12: 0 | BG12: 0 | BH12: 0 | BI12: 0 | BJ12: 0 | BK12: 0 | BL12: 0 | BM12: 0 | BN12: 0 | BO12: 0 | BP12: 0 | BQ12: 0 | BR12: 0 | BS12: 0 | BT12: 0 | BU12: 0 | BV12: 0 | BW12: 0 | BX12: 0 | BY12: 0 | BZ12: 0 | CA12: 0 | CB12: 0 | CC12: 0 | CD12: 0 | CE12: 0 | CF12: 0 | CG12: 0 | CH12: 0 | CI12: 0 | CJ12: 0 | CK12: 0 | CL12: 0 | CM12: 0 | CN12: 0 | CO12: 0 | CP12: 0 | CQ12: 0 | CR12: 0 | CS12: 0 | CT12: 0 | CU12: 0 | CV12: 0 | CW12: 0 | CX12: 0 | CY12: 0 | CZ12: 0 | DA12: 0 | DB12: 0 | DC12: 0 | DD12: 0 | DE12: 0 | DF12: 0 | DG12: 0 | DH12: 0 | DI12: 0 | DJ12: 0 | DK12: 0 | DL12: 0 | DM12: 0 | DN12: 0 | DO12: 0 | DP12: 0 | DQ12: 0 | DR12: 0 | DS12: 0 | DT12: 0 | DU12: 0 | DV12: 0
A13: 9 | B13: 4 | C13: 0 | D13: 0 | E13: 0 | F13: 0 | G13: 0.003 | H13: 0 | I13: 0 | J13: 0 | K13: 0 | L13: 0 | M13: 0.002 | N13: 0 | O13: 0 | P13: 0 | Q13: 0 | R13: 0 | S13: 0 | T13: 0 | U13: 0 | V13: 0 | W13: 0 | X13: 0 | Y13: 0 | Z13: 0 | AA13: 0 | AB13: 0 | AC13: 0 | AD13: 0 | AE13: 0 | AF13: 0 | AG13: 0 | AH13: 0.004 | AI13: 0 | AJ13: 0 | AK13: 0 | AL13: 0 | AM13: 0 | AN13: 0 | AO13: 0 | AP13: 0 | AQ13: 0 | AR13: 0 | AS13: 0 | AT13: 0 | AU13: 0 | AV13: 0 | AW13: 0 | AX13: 0 | AY13: 0 | AZ13: 0 | BA13: 0 | BB13: 0 | BC13: 0 | BD13: 0 | BE13: 0 | BF13: 0 | BG13: 0 | BH13: 0 | BI13: 0 | BJ13: 0 | BK13: 0 | BL13: 0 | BM13: 0 | BN13: 0 | BO13: 0 | BP13: 0 | BQ13: 0 | BR13: 0 | BS13: 0 | BT13: 0 | BU13: 0 | BV13: 0 | BW13: 0 | BX13: 0 | BY13: 0 | BZ13: 0 | CA13: 0 | CB13: 0 | CC13: 0 | CD13: 0 | CE13: 0 | CF13: 0 | CG13: 0 | CH13: 0.003 | CI13: 0 | CJ13: 0 | CK13: 0 | CL13: 0 | CM13: 0 | CN13: 0 | CO13: 0 | CP13: 0.001 | CQ13: 0 | CR13: 0 | CS13: 0 | CT13: 0 | CU13: 0 | CV13: 0 | CW13: 0 | CX13: 0 | CY13: 0.016 | CZ13: 0 | DA13: 0 | DB13: 0 | DC13: 0 | DD13: 0 | DE13: 0 | DF13: 0 | DG13: 0 | DH13: 0 | DI13: 0 | DJ13: 0 | DK13: 0 | DL13: 0 | DM13: 0.008 | DN13: 0 | DO13: 0 | DP13: 0 | DQ13: 0 | DR13: 0.002 | DS13: 0 | DT13: 0 | DU13: 0 | DV13: 0
A14: 10 | B14: 4.5 | C14: 0.073 | D14: 0 | E14: 0.094 | F14: 0.057 | G14: 0.186 | H14: 0.078 | I14: 0.032 | J14: 0 | K14: 0.062 | L14: 0 | M14: 0.185 | N14: 0.186 | O14: 0.129 | P14: 0.095 | Q14: 0.068 | R14: 0 | S14: 0.062 | T14: 0 | U14: 0.111 | V14: 0.174 | W14: 0.003 | X14: 0 | Y14: 0.143 | Z14: 0.178 | AA14: 0.037 | AB14: 0 | AC14: 0.105 | AD14: 0.112 | AE14: 0.178 | AF14: 0 | AG14: 0 | AH14: 0.187 | AI14: 0 | AJ14: 0.153 | AK14: 0 | AL14: 0.1 | AM14: 0 | AN14: 0.186 | AO14: 0.034 | AP14: 0.158 | AQ14: 0.151 | AR14: 0.178 | AS14: 0.175 | AT14: 0 | AU14: 0.183 | AV14: 0.137 | AW14: 0.173 | AX14: 0.086 | AY14: 0.185 | AZ14: 0.122 | BA14: 0.135 | BB14: 0.084 | BC14: 0 | BD14: 0.026 | BE14: 0.031 | BF14: 0.011 | BG14: 0 | BH14: 0.066 | BI14: 0.155 | BJ14: 0.073 | BK14: 0.144 | BL14: 0 | BM14: 0.06 | BN14: 0 | BO14: 0.056 | BP14: 0.124 | BQ14: 0.196 | BR14: 0.064 | BS14: 0 | BT14: 0 | BU14: 0.065 | BV14: 0.126 | BW14: 0 | BX14: 0.128 | BY14: 0.178 | BZ14: 0.131 | CA14: 0.176 | CB14: 0 | CC14: 0.074 | CD14: 0.037 | CE14: 0.099 | CF14: 0.168 | CG14: 0.192 | CH14: 0.16 | CI14: 0.036 | CJ14: 0.155 | CK14: 0.096 | CL14: 0.124 | CM14: 0.074 | CN14: 0.055 | CO14: 0.069 | CP14: 0.123 | CQ14: 0.058 | CR14: 0 | CS14: 0.105 | CT14: 0.068 | CU14: 0.04 | CV14: 0.15 | CW14: 0.047 | CX14: 0 | CY14: 0.151 | CZ14: 0.064 | DA14: 0.176 | DB14: 0 | DC14: 0 | DD14: 0.074 | DE14: 0.06 | DF14: 0.045 | DG14: 0.086 | DH14: 0.167 | DI14: 0 | DJ14: 0 | DK14: 0.094 | DL14: 0.114 | DM14: 0.022 | DN14: 0.152 | DO14: 0.173 | DP14: 0.031 | DQ14: 0.098 | DR14: 0.185 | DS14: 0.08 | DT14: 0 | DU14: 0.061 | DV14: 0
A15: 11 | B15: 5 | C15: 0.188 | D15: 0.239 | E15: 0.237 | F15: 0.172 | G15: 0.414 | H15: 0.403 | I15: 0.287 | J15: 0.315 | K15: 0 | L15: 0.295 | M15: 0.331 | N15: 0.246 | O15: 0.241 | P15: 0.346 | Q15: 0 | R15: 0.023 | S15: 0.115 | T15: 0.046 | U15: 0.355 | V15: 0.274 | W15: 0 | X15: 0.219 | Y15: 0.202 | Z15: 0.406 | AA15: 0.351 | AB15: 0.234 | AC15: 0.411 | AD15: 0.312 | AE15: 0.406 | AF15: 0.257 | AG15: 0.227 | AH15: 0.415 | AI15: 0.212 | AJ15: 0.228 | AK15: 0.283 | AL15: 0.243 | AM15: 0.022 | AN15: 0.369 | AO15: 0.301 | AP15: 0.11 | AQ15: 0.275 | AR15: 0.406 | AS15: 0.403 | AT15: 0.191 | AU15: 0.396 | AV15: 0.281 | AW15: 0.401 | AX15: 0.122 | AY15: 0.316 | AZ15: 0.294 | BA15: 0.307 | BB15: 0.324 | BC15: 0.218 | BD15: 0.045 | BE15: 0.343 | BF15: 0.231 | BG15: 0.029 | BH15: 0.181 | BI15: 0.289 | BJ15: 0.113 | BK15: 0.31 | BL15: 0.353 | BM15: 0 | BN15: 0 | BO15: 0.342 | BP15: 0.296 | BQ15: 0.417 | BR15: 0.351 | BS15: 0 | BT15: 0.293 | BU15: 0.405 | BV15: 0.298 | BW15: 0.33 | BX15: 0.303 | BY15: 0.285 | BZ15: 0.211 | CA15: 0.404 | CB15: 0.303 | CC15: 0.365 | CD15: 0.124 | CE15: 0.242 | CF15: 0.291 | CG15: 0.42 | CH15: 0.297 | CI15: 0 | CJ15: 0.258 | CK15: 0.114 | CL15: 0.296 | CM15: 0.068 | CN15: 0.19 | CO15: 0.142 | CP15: 0.412 | CQ15: 0.014 | CR15: 0.075 | CS15: 0.404 | CT15: 0.357 | CU15: 0.183 | CV15: 0.35 | CW15: 0.133 | CX15: 0.115 | CY15: 0.397 | CZ15: 0.179 | DA15: 0.404 | DB15: 0.249 | DC15: 0 | DD15: 0.12 | DE15: 0.175 | DF15: 0.255 | DG15: 0.342 | DH15: 0.356 | DI15: 0.249 | DJ15: 0.341 | DK15: 0.35 | DL15: 0.286 | DM15: 0.349 | DN15: 0.303 | DO15: 0.301 | DP15: 0.213 | DQ15: 0.241 | DR15: 0.261 | DS15: 0.146 | DT15: 0.179 | DU15: 0.113 | DV15: 0
A16: 12 | B16: 5.5 | C16: 0.191 | D16: 0.337 | E16: 0.413 | F16: 0.312 | G16: 0.65 | H16: 0.542 | I16: 0.689 | J16: 0.389 | K16: 0.317 | L16: 0.505 | M16: 0.659 | N16: 0.695 | O16: 0.69 | P16: 0.604 | Q16: 0.309 | R16: 0.159 | S16: 0.305 | T16: 0 | U16: 0.575 | V16: 0.67 | W16: 0.323 | X16: 0.407 | Y16: 0.525 | Z16: 0.6 | AA16: 0.505 | AB16: 0.203 | AC16: 0.503 | AD16: 0.585 | AE16: 0.687 | AF16: 0.429 | AG16: 0.403 | AH16: 0.696 | AI16: 0.501 | AJ16: 0.551 | AK16: 0.508 | AL16: 0.252 | AM16: 0.275 | AN16: 0.575 | AO16: 0.618 | AP16: 0.603 | AQ16: 0.596 | AR16: 0.645 | AS16: 0.684 | AT16: 0.137 | AU16: 0.604 | AV16: 0.43 | AW16: 0.682 | AX16: 0.405 | AY16: 0.694 | AZ16: 0.504 | BA16: 0.517 | BB16: 0.678 | BC16: 0.712 | BD16: 0 | BE16: 0.602 | BF16: 0.291 | BG16: 0.226 | BH16: 0.163 | BI16: 0.617 | BJ16: 0.328 | BK16: 0.38 | BL16: 0.537 | BM16: 0.315 | BN16: 0.223 | BO16: 0.414 | BP16: 0.506 | BQ16: 0.542 | BR16: 0.464 | BS16: 0.312 | BT16: 0.331 | BU16: 0.686 | BV16: 0.508 | BW16: 0.692 | BX16: 0.598 | BY16: 0.651 | BZ16: 0.437 | CA16: 0.685 | CB16: 0.312 | CC16: 0.519 | CD16: 0.503 | CE16: 0.418 | CF16: 0.596 | CG16: 0.687 | CH16: 0.695 | CI16: 0.227 | CJ16: 0.564 | CK16: 0.326 | CL16: 0.506 | CM16: 0.499 | CN16: 0.33 | CO16: 0.41 | CP16: 0.693 | CQ16: 0.313 | CR16: 0.185 | CS16: 0.685 | CT16: 0.602 | CU16: 0.46 | CV16: 0.595 | CW16: 0.238 | CX16: 0.001 | CY16: 0.708 | CZ16: 0.319 | DA16: 0.685 | DB16: 0.346 | DC16: 0.155 | DD16: 0.325 | DE16: 0.103 | DF16: 0.413 | DG16: 0.684 | DH16: 0.692 | DI16: 0.431 | DJ16: 0.685 | DK16: 0.485 | DL16: 0.496 | DM16: 0.608 | DN16: 0.708 | DO16: 0.557 | DP16: 0.217 | DQ16: 0.327 | DR16: 0.694 | DS16: 0.244 | DT16: 0.319 | DU16: 0.253 | DV16: 0.011
... A52: 48 | B52: 23.5 | C52: 0 | D52: 0 | E52: 0 | F52: 0 | G52: 0 | H52: 0 | I52: 0 | J52: 0 | K52: 0 | L52: 0 | M52: 0 | N52: 0 | O52: 0 | P52: 0 | Q52: 0 | R52: 0 | S52: 0 | T52: 0 | U52: 0 | V52: 0 | W52: 0 | X52: 0 | Y52: 0 | Z52: 0 | AA52: 0 | AB52: 0 | AC52: 0 | AD52: 0 | AE52: 0 | AF52: 0 | AG52: 0 | AH52: 0 | AI52: 0 | AJ52: 0 | AK52: 0 | AL52: 0 | AM52: 0 | AN52: 0 | AO52: 0 | AP52: 0 | AQ52: 0 | AR52: 0 | AS52: 0 | AT52: 0 | AU52: 0 | AV52: 0 | AW52: 0 | AX52: 0 | AY52: 0 | AZ52: 0 | BA52: 0 | BB52: 0 | BC52: 0 | BD52: 0 | BE52: 0 | BF52: 0 | BG52: 0 | BH52: 0 | BI52: 0 | BJ52: 0 | BK52: 0 | BL52: 0 | BM52: 0 | BN52: 0 | BO52: 0 | BP52: 0 | BQ52: 0 | BR52: 0 | BS52: 0 | BT52: 0 | BU52: 0 | BV52: 0 | BW52: 0 | BX52: 0 | BY52: 0 | BZ52: 0 | CA52: 0 | CB52: 0 | CC52: 0 | CD52: 0 | CE52: 0 | CF52: 0 | CG52: 0 | CH52: 0 | CI52: 0 | CJ52: 0 | CK52: 0 | CL52: 0 | CM52: 0 | CN52: 0 | CO52: 0 | CP52: 0 | CQ52: 0 | CR52: 0 | CS52: 0 | CT52: 0 | CU52: 0 | CV52: 0 | CW52: 0 | CX52: 0 | CY52: 0 | CZ52: 0 | DA52: 0 | DB52: 0 | DC52: 0 | DD52: 0 | DE52: 0 | DF52: 0 | DG52: 0 | DH52: 0 | DI52: 0 | DJ52: 0 | DK52: 0 | DL52: 0 | DM52: 0 | DN52: 0 | DO52: 0 | DP52: 0 | DQ52: 0 | DR52: 0 | DS52: 0 | DT52: 0 | DU52: 0 | DV52: 0

Sheet 6. Raw batt discharge
A1: Raw batt discharge
A2: Verbatim copy of Discharge_kW (TR8_analysis_data.xlsx). One row per half-hour, one column per battery (kW).
A4: period | B4: hour | C4: BES_TR8_one223_B | D4: BES_TR8_one252_C | E4: BES_TR8_one280_A | F4: BES_TR8_one313_A | G4: BES_TR8_one321_C | H4: BES_TR8_one345_A | I4: BES_TR8_one375_C | J4: BES_TR8_one410_B | K4: BES_TR8_one416_C | L4: BES_TR8_one423_B | M4: BES_TR8_one446_B | N4: BES_TR8_one469_A | O4: BES_TR8_one477_A | P4: BES_TR8_one482_B | Q4: BES_TR8_one61_A | R4: BES_TR8_one552_B | S4: BES_TR8_one560_C | T4: BES_TR8_one73_A | U4: BES_TR8_one137_A | V4: BES_TR8_four50_C | W4: BES_TR8_four171_A | X4: BES_TR8_four180_A | Y4: BES_TR8_four200_A | Z4: BES_TR8_four239_A | AA4: BES_TR8_four259_B | AB4: BES_TR8_four265_C | AC4: BES_TR8_four54_C | AD4: BES_TR8_four288_B | AE4: BES_TR8_four289_B | AF4: BES_TR8_four292_C | AG4: BES_TR8_four301_C | AH4: BES_TR8_four326_A | AI4: BES_TR8_four352_A | AJ4: BES_TR8_four358_C | AK4: BES_TR8_four368_C | AL4: BES_TR8_four372_C | AM4: BES_TR8_four381_A | AN4: BES_TR8_four385_A | AO4: BES_TR8_four423_C | AP4: BES_TR8_four437_A | AQ4: BES_TR8_four446_B | AR4: BES_TR8_four466_C | AS4: BES_TR8_four467_C | AT4: BES_TR8_four548_B | AU4: BES_TR8_four558_C | AV4: BES_TR8_four562_C | AW4: BES_TR8_four590_A | AX4: BES_TR8_four604_A | AY4: BES_TR8_four78_B | AZ4: BES_TR8_four734_A | BA4: BES_TR8_four797_C | BB4: BES_TR8_four846_C | BC4: BES_TR8_four854_A | BD4: BES_TR8_four936_C | BE4: BES_TR8_four950_B | BF4: BES_TR8_four978_A | BG4: BES_TR8_four104_A | BH4: BES_TR8_four988_A | BI4: BES_TR8_four1013_B | BJ4: BES_TR8_four1027_A | BK4: BES_TR8_four1132_C | BL4: BES_TR8_four126_A | BM4: BES_TR8_four1187_A | BN4: BES_TR8_four1207_B | BO4: BES_TR8_five168_A | BP4: BES_TR8_five186_C | BQ4: BES_TR8_five194_C | BR4: BES_TR8_five223_A | BS4: BES_TR8_five303_B | BT4: BES_TR8_five324_B | BU4: BES_TR8_five345_A | BV4: BES_TR8_five421_A | BW4: BES_TR8_five488_B | BX4: BES_TR8_five513_B | BY4: BES_TR8_five537_C | BZ4: BES_TR8_five540_A | CA4: BES_TR8_five551_C | CB4: BES_TR8_five631_B | CC4: BES_TR8_five649_A | CD4: BES_TR8_five663_C | CE4: BES_TR8_five670_C | CF4: BES_TR8_five704_A | CG4: BES_TR8_five719_A | CH4: BES_TR8_five750_B | CI4: BES_TR8_five793_A | CJ4: BES_TR8_five801_C | CK4: BES_TR8_five905_B | CL4: BES_TR8_five118_B | CM4: BES_TR8_five123_B | CN4: BES_TR8_six64_A | CO4: BES_TR8_six154_C | CP4: BES_TR8_six173_C | CQ4: BES_TR8_six232_C | CR4: BES_TR8_six238_A | CS4: BES_TR8_six269_C | CT4: BES_TR8_six289_C | CU4: BES_TR8_six317_C | CV4: BES_TR8_six326_A | CW4: BES_TR8_six329_A | CX4: BES_TR8_six342_A | CY4: BES_TR8_six350_B | CZ4: BES_TR8_six365_C | DA4: BES_TR8_six75_A | DB4: BES_TR8_six385_B | DC4: BES_TR8_six431_C | DD4: BES_TR8_six571_C | DE4: BES_TR8_six595_B | DF4: BES_TR8_six643_A | DG4: BES_TR8_six652_A | DH4: BES_TR8_six667_A | DI4: BES_TR8_six699_C | DJ4: BES_TR8_six723_B | DK4: BES_TR8_six740_A | DL4: BES_TR8_six90_B | DM4: BES_TR8_six801_C | DN4: BES_TR8_six807_A | DO4: BES_TR8_six844_C | DP4: BES_TR8_six860_C | DQ4: BES_TR8_six909_C | DR4: BES_TR8_six914_A | DS4: BES_TR8_six111_C | DT4: BES_TR8_six1006_C | DU4: BES_TR8_six1020_A | DV4: BES_TR8_six1064_C
A5: 1 | B5: 0 | C5: 0.098 | D5: 0.049 | E5: 0.055 | F5: 0.059 | G5: 0.047 | H5: 0.15 | I5: 0.132 | J5: 0.255 | K5: 0.178 | L5: 0.159 | M5: 0.166 | N5: 0.223 | O5: 0.53 | P5: 0.18 | Q5: 0.075 | R5: 0.593 | S5: 0.961 | T5: 0.183 | U5: 0.073 | V5: 0.234 | W5: 0.228 | X5: 0.057 | Y5: 0.031 | Z5: 0.055 | AA5: 0.064 | AB5: 0.192 | AC5: 0.186 | AD5: 0.256 | AE5: 0.56 | AF5: 0.221 | AG5: 0.378 | AH5: 0.484 | AI5: 0.06 | AJ5: 0.183 | AK5: 0.13 | AL5: 0.045 | AM5: 0.079 | AN5: 0.107 | AO5: 0.1 | AP5: 0.046 | AQ5: 0.129 | AR5: 2.391 | AS5: 0.095 | AT5: 0.04 | AU5: 0.133 | AV5: 0.197 | AW5: 0.06 | AX5: 0.059 | AY5: 0.112 | AZ5: 0.526 | BA5: 0.365 | BB5: 0.218 | BC5: 0.03 | BD5: 0.293 | BE5: 0.124 | BF5: 0.553 | BG5: 0.263 | BH5: 0.179 | BI5: 0.227 | BJ5: 0.089 | BK5: 0.123 | BL5: 0.078 | BM5: 0.153 | BN5: 0.184 | BO5: 1.946 | BP5: 0.05 | BQ5: 0.363 | BR5: 0.067 | BS5: 0.426 | BT5: 0.226 | BU5: 0.168 | BV5: 0.048 | BW5: 0.115 | BX5: 0.126 | BY5: 0.271 | BZ5: 0.043 | CA5: 0.057 | CB5: 0.162 | CC5: 0.205 | CD5: 0.119 | CE5: 0.046 | CF5: 0.678 | CG5: 0.213 | CH5: 0.19 | CI5: 0.118 | CJ5: 0.307 | CK5: 0.217 | CL5: 0.05 | CM5: 0.05 | CN5: 0.149 | CO5: 0.195 | CP5: 0.049 | CQ5: 1.565 | CR5: 0.041 | CS5: 0.451 | CT5: 0.155 | CU5: 1.492 | CV5: 0.054 | CW5: 0.04 | CX5: 0.058 | CY5: 0.09 | CZ5: 0.125 | DA5: 0.057 | DB5: 0.1 | DC5: 0.315 | DD5: 0.042 | DE5: 0.155 | DF5: 0.719 | DG5: 0.058 | DH5: 0.05 | DI5: 0.235 | DJ5: 0.273 | DK5: 0.156 | DL5: 0.167 | DM5: 0.167 | DN5: 0.034 | DO5: 0.038 | DP5: 0.178 | DQ5: 0.145 | DR5: 0.367 | DS5: 0.757 | DT5: 0.178 | DU5: 0.167 | DV5: 0.09
A6: 2 | B6: 0.5 | C6: 0.043 | D6: 0.239 | E6: 0.126 | F6: 0.059 | G6: 0.047 | H6: 0.108 | I6: 0.244 | J6: 0.031 | K6: 0.177 | L6: 0.051 | M6: 0.048 | N6: 0.185 | O6: 0.727 | P6: 0.045 | Q6: 0.131 | R6: 0.383 | S6: 0.819 | T6: 0.24 | U6: 0.12 | V6: 0.136 | W6: 0.048 | X6: 0.057 | Y6: 0.127 | Z6: 0.055 | AA6: 0.155 | AB6: 0.218 | AC6: 0.127 | AD6: 0.095 | AE6: 0.534 | AF6: 0.05 | AG6: 0.382 | AH6: 0.506 | AI6: 0.303 | AJ6: 0.051 | AK6: 0.13 | AL6: 0.045 | AM6: 0.288 | AN6: 0.047 | AO6: 0.331 | AP6: 0.046 | AQ6: 0.053 | AR6: 0 | AS6: 0.104 | AT6: 0.109 | AU6: 0.05 | AV6: 0.055 | AW6: 0.06 | AX6: 0.173 | AY6: 0.082 | AZ6: 0.447 | BA6: 0.039 | BB6: 0.081 | BC6: 0.161 | BD6: 0.088 | BE6: 0.14 | BF6: 0.135 | BG6: 0.055 | BH6: 0.079 | BI6: 0.07 | BJ6: 0.08 | BK6: 0.232 | BL6: 0.123 | BM6: 0.168 | BN6: 0.068 | BO6: 0.445 | BP6: 0.05 | BQ6: 0.037 | BR6: 0.292 | BS6: 0.059 | BT6: 0.053 | BU6: 0.056 | BV6: 0.048 | BW6: 0.05 | BX6: 0.051 | BY6: 0.084 | BZ6: 0.211 | CA6: 0.057 | CB6: 0.14 | CC6: 0.052 | CD6: 0.053 | CE6: 0.046 | CF6: 0.297 | CG6: 0.284 | CH6: 0.047 | CI6: 0.227 | CJ6: 0.049 | CK6: 0.189 | CL6: 0.05 | CM6: 0.129 | CN6: 0.143 | CO6: 0.155 | CP6: 0.11 | CQ6: 0.058 | CR6: 0.229 | CS6: 0.323 | CT6: 0.047 | CU6: 0.198 | CV6: 0.188 | CW6: 0.096 | CX6: 0.303 | CY6: 0.034 | CZ6: 0.052 | DA6: 0.057 | DB6: 0.039 | DC6: 0.093 | DD6: 0.115 | DE6: 0.183 | DF6: 0.508 | DG6: 0.058 | DH6: 0.121 | DI6: 0.203 | DJ6: 0.25 | DK6: 0.054 | DL6: 0.262 | DM6: 0.129 | DN6: 0.034 | DO6: 0.138 | DP6: 0.101 | DQ6: 0.047 | DR6: 0.447 | DS6: 1.634 | DT6: 0.052 | DU6: 0.067 | DV6: 0.049
A7: 3 | B7: 1 | C7: 0.18 | D7: 0.049 | E7: 0.063 | F7: 0.059 | G7: 0.047 | H7: 0.098 | I7: 0.053 | J7: 0.031 | K7: 0.081 | L7: 0.178 | M7: 0.166 | N7: 0.047 | O7: 0.129 | P7: 0.22 | Q7: 0.174 | R7: 0.559 | S7: 0.611 | T7: 0.152 | U7: 0.091 | V7: 0.059 | W7: 0.227 | X7: 0.057 | Y7: 0.048 | Z7: 0.214 | AA7: 0.053 | AB7: 0.08 | AC7: 0.05 | AD7: 0.051 | AE7: 0.055 | AF7: 0.213 | AG7: 0.061 | AH7: 0.384 | AI7: 0.101 | AJ7: 0.067 | AK7: 0.112 | AL7: 0.06 | AM7: 0.05 | AN7: 0.16 | AO7: 0.058 | AP7: 0.046 | AQ7: 0.12 | AR7: 0 | AS7: 0.058 | AT7: 0.165 | AU7: 0.086 | AV7: 0.388 | AW7: 0.06 | AX7: 0.166 | AY7: 0.048 | AZ7: 0.052 | BA7: 0.039 | BB7: 0.128 | BC7: 0.03 | BD7: 0.198 | BE7: 0.18 | BF7: 0.18 | BG7: 0.245 | BH7: 0.057 | BI7: 0.148 | BJ7: 0.08 | BK7: 0.056 | BL7: 0.051 | BM7: 0.085 | BN7: 0.244 | BO7: 0 | BP7: 0.05 | BQ7: 0.037 | BR7: 0.053 | BS7: 0.219 | BT7: 0.123 | BU7: 0.056 | BV7: 0.048 | BW7: 0.332 | BX7: 0.055 | BY7: 0.184 | BZ7: 0.043 | CA7: 0.057 | CB7: 0.193 | CC7: 0.198 | CD7: 0.306 | CE7: 0.046 | CF7: 0.133 | CG7: 0.135 | CH7: 0.177 | CI7: 0.051 | CJ7: 0.182 | CK7: 0.049 | CL7: 0.05 | CM7: 0.195 | CN7: 0.041 | CO7: 0.052 | CP7: 0.049 | CQ7: 0.101 | CR7: 0.073 | CS7: 0.273 | CT7: 0.047 | CU7: 0.054 | CV7: 0.054 | CW7: 0.159 | CX7: 0.1 | CY7: 0.034 | CZ7: 0.125 | DA7: 0.057 | DB7: 0.161 | DC7: 0.093 | DD7: 0.042 | DE7: 0.056 | DF7: 0.506 | DG7: 0.161 | DH7: 0.103 | DI7: 0.1 | DJ7: 0.167 | DK7: 0.054 | DL7: 0.188 | DM7: 0.05 | DN7: 0.151 | DO7: 0.084 | DP7: 0.128 | DQ7: 0.114 | DR7: 0.172 | DS7: 0 | DT7: 0.206 | DU7: 0.055 | DV7: 0.221
A8: 4 | B8: 1.5 | C8: 0.043 | D8: 0.204 | E8: 0.051 | F8: 0.059 | G8: 0.047 | H8: 0.108 | I8: 0.181 | J8: 0.168 | K8: 0.178 | L8: 0.051 | M8: 0.048 | N8: 0.093 | O8: 0.152 | P8: 0.121 | Q8: 0.13 | R8: 0.262 | S8: 0 | T8: 0.223 | U8: 0.168 | V8: 0.2 | W8: 0.17 | X8: 0.175 | Y8: 0.082 | Z8: 0.055 | AA8: 0.053 | AB8: 0.306 | AC8: 0.149 | AD8: 0.3 | AE8: 0.055 | AF8: 0.058 | AG8: 0.225 | AH8: 0.167 | AI8: 0.126 | AJ8: 0.207 | AK8: 0.107 | AL8: 0.196 | AM8: 0.05 | AN8: 0.1 | AO8: 0.226 | AP8: 0.046 | AQ8: 0.061 | AR8: 0 | AS8: 0.132 | AT8: 0.063 | AU8: 0.117 | AV8: 0.07 | AW8: 0.06 | AX8: 0.173 | AY8: 0.119 | AZ8: 0.052 | BA8: 0.039 | BB8: 0.174 | BC8: 0.161 | BD8: 0.058 | BE8: 0.14 | BF8: 0.181 | BG8: 0.065 | BH8: 0.201 | BI8: 0.148 | BJ8: 0.101 | BK8: 0.113 | BL8: 0.231 | BM8: 0.295 | BN8: 0.055 | BO8: 0 | BP8: 0.05 | BQ8: 0.207 | BR8: 0.053 | BS8: 0.316 | BT8: 0.153 | BU8: 0.168 | BV8: 0.048 | BW8: 0.075 | BX8: 0.121 | BY8: 0.055 | BZ8: 0.166 | CA8: 0.057 | CB8: 0.156 | CC8: 0.121 | CD8: 0.053 | CE8: 0.046 | CF8: 0.203 | CG8: 0.041 | CH8: 0.06 | CI8: 0.118 | CJ8: 0.049 | CK8: 0.088 | CL8: 0.05 | CM8: 0.104 | CN8: 0.082 | CO8: 0.298 | CP8: 0.11 | CQ8: 0.173 | CR8: 0.104 | CS8: 0.136 | CT8: 0.155 | CU8: 0.269 | CV8: 0.188 | CW8: 0.04 | CX8: 0.219 | CY8: 0.098 | CZ8: 0.052 | DA8: 0.057 | DB8: 0.039 | DC8: 0.243 | DD8: 0.042 | DE8: 0.056 | DF8: 0.483 | DG8: 0.106 | DH8: 0.086 | DI8: 0.203 | DJ8: 0.076 | DK8: 0.164 | DL8: 0.237 | DM8: 0.109 | DN8: 0.089 | DO8: 0.261 | DP8: 0.225 | DQ8: 0.183 | DR8: 0.544 | DS8: 0 | DT8: 0.052 | DU8: 0.055 | DV8: 0.154
A9: 5 | B9: 2 | C9: 0.05 | D9: 0.083 | E9: 0.051 | F9: 0.059 | G9: 0.047 | H9: 0.156 | I9: 0.194 | J9: 0.142 | K9: 0.054 | L9: 0.076 | M9: 0.048 | N9: 0.169 | O9: 0.198 | P9: 0.045 | Q9: 0.167 | R9: 0.094 | S9: 0 | T9: 0.141 | U9: 0.152 | V9: 0.059 | W9: 0.17 | X9: 0.057 | Y9: 0.093 | Z9: 0.164 | AA9: 0.166 | AB9: 0.151 | AC9: 0.104 | AD9: 0.051 | AE9: 0.055 | AF9: 0.089 | AG9: 0.061 | AH9: 0.046 | AI9: 0.3 | AJ9: 0.051 | AK9: 0.152 | AL9: 0.045 | AM9: 0.295 | AN9: 0.051 | AO9: 0.155 | AP9: 0.046 | AQ9: 0.095 | AR9: 0 | AS9: 0.067 | AT9: 0.117 | AU9: 0.05 | AV9: 0.107 | AW9: 0.06 | AX9: 0.059 | AY9: 0.048 | AZ9: 0.052 | BA9: 0.039 | BB9: 0.068 | BC9: 0.03 | BD9: 0.091 | BE9: 0.18 | BF9: 0.057 | BG9: 0.169 | BH9: 0.05 | BI9: 0.062 | BJ9: 0.06 | BK9: 0.048 | BL9: 0.089 | BM9: 0.065 | BN9: 0.171 | BO9: 0 | BP9: 0.05 | BQ9: 0.037 | BR9: 0.246 | BS9: 0.059 | BT9: 0.214 | BU9: 0.056 | BV9: 0.048 | BW9: 0.209 | BX9: 0.051 | BY9: 0.141 | BZ9: 0.089 | CA9: 0.057 | CB9: 0.125 | CC9: 0.133 | CD9: 0.053 | CE9: 0.046 | CF9: 0.039 | CG9: 0.259 | CH9: 0.138 | CI9: 0.075 | CJ9: 0.133 | CK9: 0.172 | CL9: 0.05 | CM9: 0.098 | CN9: 0.15 | CO9: 0.052 | CP9: 0.049 | CQ9: 0.058 | CR9: 0.198 | CS9: 0.057 | CT9: 0.066 | CU9: 0.187 | CV9: 0.054 | CW9: 0.175 | CX9: 0.199 | CY9: 0.047 | CZ9: 0.125 | DA9: 0.057 | DB9: 0.039 | DC9: 0.144 | DD9: 0.042 | DE9: 0.259 | DF9: 0.143 | DG9: 0.092 | DH9: 0.086 | DI9: 0.271 | DJ9: 0.392 | DK9: 0.054 | DL9: 0.06 | DM9: 0.188 | DN9: 0.034 | DO9: 0.038 | DP9: 0.063 | DQ9: 0.083 | DR9: 0.231 | DS9: 0 | DT9: 0.108 | DU9: 0.18 | DV9: 0.094
A10: 6 | B10: 2.5 | C10: 0.173 | D10: 0.049 | E10: 0.051 | F10: 0.059 | G10: 0.047 | H10: 0.206 | I10: 0.057 | J10: 0.106 | K10: 0.291 | L10: 0.153 | M10: 0.048 | N10: 0.047 | O10: 0.129 | P10: 0.148 | Q10: 0.133 | R10: 0.244 | S10: 0 | T10: 0.148 | U10: 0.138 | V10: 0.11 | W10: 0.228 | X10: 0.175 | Y10: 0.031 | Z10: 0.106 | AA10: 0.053 | AB10: 0.149 | AC10: 0.172 | AD10: 0.102 | AE10: 0.055 | AF10: 0.182 | AG10: 0.061 | AH10: 0.046 | AI10: 0.038 | AJ10: 0.207 | AK10: 0.048 | AL10: 0.075 | AM10: 0.072 | AN10: 0.194 | AO10: 0.174 | AP10: 0.046 | AQ10: 0.087 | AR10: 0 | AS10: 0.1 | AT10: 0.141 | AU10: 0.154 | AV10: 0.234 | AW10: 0.06 | AX10: 0.268 | AY10: 0.119 | AZ10: 0.052 | BA10: 0.039 | BB10: 0.118 | BC10: 0.115 | BD10: 0.339 | BE10: 0.112 | BF10: 0.266 | BG10: 0.157 | BH10: 0.136 | BI10: 0.117 | BJ10: 0.043 | BK10: 0.259 | BL10: 0.051 | BM10: 0.177 | BN10: 0.141 | BO10: 0 | BP10: 0.05 | BQ10: 0.13 | BR10: 0.114 | BS10: 0.059 | BT10: 0.062 | BU10: 0.168 | BV10: 0.048 | BW10: 0.197 | BX10: 0.051 | BY10: 0.127 | BZ10: 0.058 | CA10: 0.057 | CB10: 0.176 | CC10: 0.187 | CD10: 0.306 | CE10: 0.046 | CF10: 0.152 | CG10: 0.041 | CH10: 0.099 | CI10: 0.27 | CJ10: 0.097 | CK10: 0.265 | CL10: 0.05 | CM10: 0.28 | CN10: 0.041 | CO10: 0.244 | CP10: 0.086 | CQ10: 0.217 | CR10: 0.041 | CS10: 0.136 | CT10: 0.079 | CU10: 0.054 | CV10: 0.155 | CW10: 0.08 | CX10: 0.141 | CY10: 0.082 | CZ10: 0.052 | DA10: 0.057 | DB10: 0.039 | DC10: 0.278 | DD10: 0.111 | DE10: 0.079 | DF10: 0.031 | DG10: 0.174 | DH10: 0.05 | DI10: 0.248 | DJ10: 0.13 | DK10: 0.164 | DL10: 0.06 | DM10: 0.065 | DN10: 0.034 | DO10: 0.207 | DP10: 0.12 | DQ10: 0.214 | DR10: 0.333 | DS10: 0 | DT10: 0.15 | DU10: 0.055 | DV10: 0.281
A11: 7 | B11: 3 | C11: 0.043 | D11: 0.135 | E11: 0.051 | F11: 0.059 | G11: 0.047 | H11: 0.051 | I11: 0.119 | J11: 0.125 | K11: 0.092 | L11: 0.057 | M11: 0.166 | N11: 0.047 | O11: 0.373 | P11: 0.116 | Q11: 0.08 | R11: 0.046 | S11: 0 | T11: 0.279 | U11: 0.204 | V11: 0.149 | W11: 0.048 | X11: 0.057 | Y11: 0.031 | Z11: 0.077 | AA11: 0.104 | AB11: 0.315 | AC11: 0.141 | AD11: 0.249 | AE11: 0.055 | AF11: 0.05 | AG11: 0.21 | AH11: 0.046 | AI11: 0.301 | AJ11: 0.067 | AK11: 0.063 | AL11: 0.181 | AM11: 0.127 | AN11: 0.16 | AO11: 0.209 | AP11: 0.046 | AQ11: 0.053 | AR11: 0 | AS11: 0.1 | AT11: 0.12 | AU11: 0.05 | AV11: 0.1 | AW11: 0.06 | AX11: 0.07 | AY11: 0.146 | AZ11: 0.052 | BA11: 0.039 | BB11: 0.156 | BC11: 0.076 | BD11: 0.041 | BE11: 0.084 | BF11: 0.108 | BG11: 0.182 | BH11: 0.122 | BI11: 0.18 | BJ11: 0.043 | BK11: 0.105 | BL11: 0.19 | BM11: 0.212 | BN11: 0.112 | BO11: 0 | BP11: 0.05 | BQ11: 0.114 | BR11: 0.053 | BS11: 0.234 | BT11: 0.186 | BU11: 0.056 | BV11: 0.048 | BW11: 0.05 | BX11: 0.097 | BY11: 0.055 | BZ11: 0.196 | CA11: 0.057 | CB11: 0.105 | CC11: 0.052 | CD11: 0.053 | CE11: 0.046 | CF11: 0.039 | CG11: 0.041 | CH11: 0.047 | CI11: 0.051 | CJ11: 0.085 | CK11: 0.123 | CL11: 0.05 | CM11: 0.05 | CN11: 0.191 | CO11: 0.106 | CP11: 0.073 | CQ11: 0.058 | CR11: 0.054 | CS11: 0.057 | CT11: 0.142 | CU11: 0.137 | CV11: 0.088 | CW11: 0.04 | CX11: 0.244 | CY11: 0.068 | CZ11: 0.072 | DA11: 0.057 | DB11: 0.161 | DC11: 0.119 | DD11: 0.046 | DE11: 0.07 | DF11: 0 | DG11: 0.058 | DH11: 0.121 | DI11: 0.062 | DJ11: 0.123 | DK11: 0.054 | DL11: 0.06 | DM11: 0.119 | DN11: 0.034 | DO11: 0.138 | DP11: 0.245 | DQ11: 0.047 | DR11: 0.295 | DS11: 0 | DT11: 0.052 | DU11: 0.174 | DV11: 0.049
A12: 8 | B12: 3.5 | C12: 0.117 | D12: 0.15 | E12: 0.049 | F12: 0.057 | G12: 1.33 | H12: 0.307 | I12: 0.249 | J12: 0.108 | K12: 0.198 | L12: 0.169 | M12: 0.045 | N12: 0.093 | O12: 0.154 | P12: 0.149 | Q12: 0.187 | R12: 0.21 | S12: 0 | T12: 0.045 | U12: 0.131 | V12: 0.056 | W12: 0.307 | X12: 0.161 | Y12: 0.079 | Z12: 0.189 | AA12: 0.112 | AB12: 0.092 | AC12: 0.107 | AD12: 0.092 | AE12: 0.052 | AF12: 0.218 | AG12: 0.074 | AH12: 0.043 | AI12: 0.086 | AJ12: 0.048 | AK12: 0.194 | AL12: 0.043 | AM12: 0.223 | AN12: 0.044 | AO12: 0.244 | AP12: 0.043 | AQ12: 0.126 | AR12: 0 | AS12: 0.055 | AT12: 0.144 | AU12: 0.047 | AV12: 0.164 | AW12: 0.057 | AX12: 0.08 | AY12: 0.049 | AZ12: 0.049 | BA12: 0.036 | BB12: 0.094 | BC12: 0.079 | BD12: 0.22 | BE12: 0.133 | BF12: 0.12 | BG12: 0.077 | BH12: 0.077 | BI12: 0.059 | BJ12: 0.116 | BK12: 0.066 | BL12: 0.127 | BM12: 0.078 | BN12: 0.153 | BO12: 0 | BP12: 0.047 | BQ12: 0.034 | BR12: 0.303 | BS12: 0.3 | BT12: 0.174 | BU12: 0.053 | BV12: 0.045 | BW12: 0.353 | BX12: 0.077 | BY12: 0.13 | BZ12: 0.04 | CA12: 0.054 | CB12: 0.177 | CC12: 0.049 | CD12: 0.207 | CE12: 0.044 | CF12: 0.175 | CG12: 0.038 | CH12: 0.187 | CI12: 0.242 | CJ12: 0.143 | CK12: 0.047 | CL12: 0.047 | CM12: 0.192 | CN12: 0.039 | CO12: 0.105 | CP12: 0.046 | CQ12: 0.16 | CR12: 0.18 | CS12: 0.054 | CT12: 0.044 | CU12: 0 | CV12: 0.105 | CW12: 0.102 | CX12: 0.207 | CY12: 0.073 | CZ12: 0.103 | DA12: 0.054 | DB12: 0.037 | DC12: 0.147 | DD12: 0.04 | DE12: 0.266 | DF12: 0 | DG12: 0.198 | DH12: 0.054 | DI12: 0.324 | DJ12: 0.267 | DK12: 0.051 | DL12: 0.057 | DM12: 0.109 | DN12: 0.179 | DO12: 0.173 | DP12: 0.105 | DQ12: 0.1 | DR12: 0 | DS12: 0 | DT12: 0.05 | DU12: 0.06 | DV12: 0.291
A13: 9 | B13: 4 | C13: 0.08 | D13: 0.018 | E13: 0.02 | F13: 0.034 | G13: 0 | H13: 0.001 | I13: 0.003 | J13: 0.068 | K13: 0.158 | L13: 0.014 | M13: 0 | N13: 0.127 | O13: 0 | P13: 0.145 | Q13: 0.119 | R13: 0 | S13: 0 | T13: 0.132 | U13: 0.121 | V13: 0.151 | W13: 0.064 | X13: 0.038 | Y13: 0.056 | Z13: 0.005 | AA13: 0.009 | AB13: 0.176 | AC13: 0.136 | AD13: 0.18 | AE13: 0.005 | AF13: 0.302 | AG13: 0.03 | AH13: 0 | AI13: 0.029 | AJ13: 0.179 | AK13: 0.011 | AL13: 0.18 | AM13: 0.04 | AN13: 0.162 | AO13: 0.134 | AP13: 0.002 | AQ13: 0.009 | AR13: 0 | AS13: 0.092 | AT13: 0.083 | AU13: 0.0003 | AV13: 0.142 | AW13: 0.01 | AX13: 0.119 | AY13: 0.163 | AZ13: 0.015 | BA13: 0.002 | BB13: 0.046 | BC13: 0.059 | BD13: 0.169 | BE13: 0.05 | BF13: 0.118 | BG13: 0.099 | BH13: 0.154 | BI13: 0.169 | BJ13: 0.018 | BK13: 0.166 | BL13: 0.042 | BM13: 0.094 | BN13: 0.083 | BO13: 0 | BP13: 0.013 | BQ13: 0.158 | BR13: 0.009 | BS13: 0.034 | BT13: 0.056 | BU13: 0.006 | BV13: 0.011 | BW13: 0.0003 | BX13: 0.007 | BY13: 0.084 | BZ13: 0.174 | CA13: 0.007 | CB13: 0.03 | CC13: 0.111 | CD13: 0.112 | CE13: 0.015 | CF13: 0.103 | CG13: 0.085 | CH13: 0 | CI13: 0.083 | CJ13: 0.005 | CK13: 0.232 | CL13: 0.013 | CM13: 0.146 | CN13: 0.145 | CO13: 0.152 | CP13: 0 | CQ13: 0 | CR13: 0.089 | CS13: 0.016 | CT13: 0.041 | CU13: 0 | CV13: 0.091 | CW13: 0.133 | CX13: 0.113 | CY13: 0 | CZ13: 0.027 | DA13: 0.007 | DB13: 0.008 | DC13: 0.125 | DD13: 0.017 | DE13: 0.031 | DF13: 0 | DG13: 0.015 | DH13: 0.064 | DI13: 0.122 | DJ13: 0.137 | DK13: 0.065 | DL13: 0.023 | DM13: 0 | DN13: 0.008 | DO13: 0.098 | DP13: 0.207 | DQ13: 0.164 | DR13: 0 | DS13: 0 | DT13: 0.097 | DU13: 0.03 | DV13: 0.071
