Workbook

Sheet 1. Overview
B2: TR5 — Where does the PV energy go?
B3: Prosumers vs. pure customers — every kWh traced from the raw model inputs
B5: Purpose
B6: This workbook accounts for every kWh of PV generated on transformer TR5 over one representative day, and it is fully auditable: nothing is hand-typed except the raw model outputs. Follow the data chain below — each step is a live formula, so changing any raw number updates everything.
B10: The data chain (how each number is built)
B11: Sheet 3 · Raw PV per load | C11: The PV profile of every connection, 48 half-hours. Copied verbatim from TR5_load_PV_48periods.xlsx (sheet PV_generation_kW). Customers = 0.
B12: Sheet 4 · Raw load per load | C12: The load profile of every connection, 48 half-hours, tagged prosumer / customer. Copied from TR5_load_PV_48periods.xlsx (sheet Load_P_kW).
B13: Sheet 5 · Raw batt charge | C13: Charging power of every battery, 48 half-hours. Copied from the rolling dispatch TR5_analysis_data.xlsx (sheet Charge_kW).
B14: Sheet 6 · Raw batt discharge | C14: Discharging power of every battery. Copied from the same run (Discharge_kW).
B15: Sheet 7 · PV allocation | C15: Per half-hour: the five blue inputs are AGGREGATED from sheets 3–6 by SUM / SUMIF; the amber columns then split the PV by the priority rule.
B16: Sheets 1 & 8 · Results | C16: Daily totals (Σ×0.5 h) and shares. Every headline cell links to sheet 7.
B18: The aggregation formulas (sheet 7, per half-hour)
B19: PV (all)
B20: prosumer load
B21: customer load
B22: battery charge
B23: battery discharge
B25: Headline results (all linked live to sheet 7)
B26: Quantity | C26: Value | D26: Unit
B27: Prosumers (PV + battery) | C27: 214 | D27: connections
B28: Pure customers (load only) | C28: 203 | D28: connections
B29: PV generated | C29: ='7. PV allocation (per period)'!C53 -> 5100.2134 | D29: kWh/day
B30: PV → prosumers' own load (direct) | C30: ='7. PV allocation (per period)'!I53 -> 1049.137 | D30: kWh/day
B31: PV → battery storage | C31: ='7. PV allocation (per period)'!J53 -> 709.867 | D31: kWh/day
B32: PV → customers | C32: ='7. PV allocation (per period)'!K53 -> 725.16655 | D32: kWh/day
B33: PV → export to grid | C33: ='7. PV allocation (per period)'!L53 -> 2616.0428 | D33: kWh/day
B34: PV share reaching customers | C34: ='7. PV allocation (per period)'!K53/'7. PV allocation (per period)'!C53 -> 0.14218357 | D34: % of PV
B35: Customer load covered by PV | C35: ='7. PV allocation (per period)'!K53/'7. PV allocation (per period)'!E53 -> 0.50366927 | D35: % of customer load
B36: Customer load covered by grid | C36: ='7. PV allocation (per period)'!M53/'7. PV allocation (per period)'!E53 -> 0.49633073 | D36: % of customer load
B39: Colour key & provenance
B40: • LIGHT-BLUE cell = data belonging to a prosumer (its rooftop PV, load, or battery). WHITE = a pure customer (load only). On sheet 7: VIOLET = value aggregated live from the raw sheets (SUM/SUMIF); AMBER = allocation formula; GREEN = daily total (Σ × 0.5 h).
B41: • Per-load PV & load profiles: results/tables/TR5_load_PV_48periods.xlsx (built from OpData.xls).
B42: • Per-battery charge/discharge: TR5_analysis/01_DAILY_ROLLING_DISPATCH/TR5_analysis_data.xlsx (exact-QCP rolling dispatch, RunFOR_Rolling, CPLEX).
B43: • Load classification (PV size > 0 = prosumer): sheet 'Customers' of the load/PV workbook.
B44: • Method note: priority energy allocation per half-hour; downstream network + battery round-trip losses (~3–4% of PV) are not separated out in the per-period disposition.

Sheet 2. Load classification
A1: TR5 load classification — 417 connections
A2: 214 prosumers (PV + battery) · 203 pure customers (load only)
A4: ID | B4: Load name | C4: Bus | D4: Phase | E4: PV size (kW) | F4: Type
A5: 459 | B5: Load_TR5_F1_11 | C5: TR5_one223 | D5: 2 | E5: 0 | F5: customer
A6: 460 | B6: Load_TR5_F1_11_dup | C6: TR5_one223_dup | D6: 2 | E6: 0 | F6: customer
A7: 463 | B7: Load_TR5_F1_13 | C7: TR5_one242 | D7: 2 | E7: 0 | F7: customer
A8: 467 | B8: Load_TR5_F1_15 | C8: TR5_one260 | D8: 3 | E8: 0 | F8: customer
A9: 470 | B9: Load_TR5_F1_16_dup | C9: TR5_one280_dup | D9: 1 | E9: 0 | F9: customer
A10: 472 | B10: Load_TR5_F1_17_dup | C10: TR5_one287_dup | D10: 2 | E10: 0 | F10: customer
A11: 456 | B11: Load_TR5_F1_1_dup | C11: TR5_one38_dup | D11: 2 | E11: 0 | F11: customer
A12: 480 | B12: Load_TR5_F1_20_dup | C12: TR5_one320_dup | D12: 2 | E12: 0 | F12: customer
A13: 482 | B13: Load_TR5_F1_21_dup | C13: TR5_one321_dup | D13: 3 | E13: 0 | F13: customer
A14: 484 | B14: Load_TR5_F1_22_dup | C14: TR5_one328_dup | D14: 1 | E14: 0 | F14: customer
A15: 485 | B15: Load_TR5_F1_23 | C15: TR5_one345 | D15: 1 | E15: 0 | F15: customer
A16: 488 | B16: Load_TR5_F1_24_dup | C16: TR5_one346_dup | D16: 3 | E16: 0 | F16: customer
... A421: 867 | B421: Load_TR5_F6_80 | C421: TR5_six1006 | D421: 3 | E421: 3 | F421: prosumer

Sheet 3. Raw PV per load
A1: Raw PV per load
A2: Verbatim copy of PV_generation_kW (TR5_load_PV_48periods.xlsx). One row per connection, 48 half-hours (kW).
A4: Load name | B4: Type | C4: p1 | D4: p2 | E4: p3 | F4: p4 | G4: p5 | H4: p6 | I4: p7 | J4: p8 | K4: p9 | L4: p10 | M4: p11 | N4: p12 | O4: p13 | P4: p14 | Q4: p15 | R4: p16 | S4: p17 | T4: p18 | U4: p19 | V4: p20 | W4: p21 | X4: p22 | Y4: p23 | Z4: p24 | AA4: p25 | AB4: p26 | AC4: p27 | AD4: p28 | AE4: p29 | AF4: p30 | AG4: p31 | AH4: p32 | AI4: p33 | AJ4: p34 | AK4: p35 | AL4: p36 | AM4: p37 | AN4: p38 | AO4: p39 | AP4: p40 | AQ4: p41 | AR4: p42 | AS4: p43 | AT4: p44 | AU4: p45 | AV4: p46 | AW4: p47 | AX4: p48
A5: Load_TR5_F1_1 | B5: prosumer | C5: 0 | D5: 0 | E5: 0 | F5: 0 | G5: 0 | H5: 0 | I5: 0 | J5: 0.0022 | K5: 0.0311 | L5: 0.1454 | M5: 0.2883 | N5: 0.4637 | O5: 0.6549 | P5: 0.8486 | Q5: 1.0412 | R5: 1.2341 | S5: 1.4152 | T5: 1.5854 | U5: 1.7304 | V5: 1.854 | W5: 1.9625 | X5: 2.0521 | Y5: 2.1156 | Z5: 2.1435 | AA5: 2.1516 | AB5: 2.1365 | AC5: 2.0857 | AD5: 2.0083 | AE5: 1.9159 | AF5: 1.7989 | AG5: 1.6745 | AH5: 1.5247 | AI5: 1.3561 | AJ5: 1.1525 | AK5: 0.962 | AL5: 0.7662 | AM5: 0.5768 | AN5: 0.3942 | AO5: 0.2302 | AP5: 0.067 | AQ5: 0.0124 | AR5: 0 | AS5: 0 | AT5: 0 | AU5: 0 | AV5: 0 | AW5: 0 | AX5: 0
A6: Load_TR5_F1_10 | B6: prosumer | C6: 0 | D6: 0 | E6: 0 | F6: 0 | G6: 0 | H6: 0 | I6: 0 | J6: 0.0034 | K6: 0.0497 | L6: 0.2326 | M6: 0.4613 | N6: 0.7419 | O6: 1.0479 | P6: 1.3577 | Q6: 1.666 | R6: 1.9746 | S6: 2.2643 | T6: 2.5367 | U6: 2.7686 | V6: 2.9664 | W6: 3.14 | X6: 3.2833 | Y6: 3.385 | Z6: 3.4296 | AA6: 3.4425 | AB6: 3.4183 | AC6: 3.3372 | AD6: 3.2133 | AE6: 3.0655 | AF6: 2.8782 | AG6: 2.6791 | AH6: 2.4396 | AI6: 2.1698 | AJ6: 1.8441 | AK6: 1.5392 | AL6: 1.2259 | AM6: 0.9229 | AN6: 0.6308 | AO6: 0.3683 | AP6: 0.1072 | AQ6: 0.0198 | AR6: 0 | AS6: 0 | AT6: 0 | AU6: 0 | AV6: 0 | AW6: 0 | AX6: 0
A7: Load_TR5_F1_10_dup | B7: prosumer | C7: 0 | D7: 0 | E7: 0 | F7: 0 | G7: 0 | H7: 0 | I7: 0 | J7: 0.0034 | K7: 0.0497 | L7: 0.2326 | M7: 0.4613 | N7: 0.7419 | O7: 1.0479 | P7: 1.3577 | Q7: 1.666 | R7: 1.9746 | S7: 2.2643 | T7: 2.5367 | U7: 2.7686 | V7: 2.9664 | W7: 3.14 | X7: 3.2833 | Y7: 3.385 | Z7: 3.4296 | AA7: 3.4425 | AB7: 3.4183 | AC7: 3.3372 | AD7: 3.2133 | AE7: 3.0655 | AF7: 2.8782 | AG7: 2.6791 | AH7: 2.4396 | AI7: 2.1698 | AJ7: 1.8441 | AK7: 1.5392 | AL7: 1.2259 | AM7: 0.9229 | AN7: 0.6308 | AO7: 0.3683 | AP7: 0.1072 | AQ7: 0.0198 | AR7: 0 | AS7: 0 | AT7: 0 | AU7: 0 | AV7: 0 | AW7: 0 | AX7: 0
A8: Load_TR5_F1_11 | B8: customer | C8: 0 | D8: 0 | E8: 0 | F8: 0 | G8: 0 | H8: 0 | I8: 0 | J8: 0 | K8: 0 | L8: 0 | M8: 0 | N8: 0 | O8: 0 | P8: 0 | Q8: 0 | R8: 0 | S8: 0 | T8: 0 | U8: 0 | V8: 0 | W8: 0 | X8: 0 | Y8: 0 | Z8: 0 | AA8: 0 | AB8: 0 | AC8: 0 | AD8: 0 | AE8: 0 | AF8: 0 | AG8: 0 | AH8: 0 | AI8: 0 | AJ8: 0 | AK8: 0 | AL8: 0 | AM8: 0 | AN8: 0 | AO8: 0 | AP8: 0 | AQ8: 0 | AR8: 0 | AS8: 0 | AT8: 0 | AU8: 0 | AV8: 0 | AW8: 0 | AX8: 0
A9: Load_TR5_F1_11_dup | B9: customer | C9: 0 | D9: 0 | E9: 0 | F9: 0 | G9: 0 | H9: 0 | I9: 0 | J9: 0 | K9: 0 | L9: 0 | M9: 0 | N9: 0 | O9: 0 | P9: 0 | Q9: 0 | R9: 0 | S9: 0 | T9: 0 | U9: 0 | V9: 0 | W9: 0 | X9: 0 | Y9: 0 | Z9: 0 | AA9: 0 | AB9: 0 | AC9: 0 | AD9: 0 | AE9: 0 | AF9: 0 | AG9: 0 | AH9: 0 | AI9: 0 | AJ9: 0 | AK9: 0 | AL9: 0 | AM9: 0 | AN9: 0 | AO9: 0 | AP9: 0 | AQ9: 0 | AR9: 0 | AS9: 0 | AT9: 0 | AU9: 0 | AV9: 0 | AW9: 0 | AX9: 0
A10: Load_TR5_F1_12 | B10: prosumer | C10: 0 | D10: 0 | E10: 0 | F10: 0 | G10: 0 | H10: 0 | I10: 0 | J10: 0.0022 | K10: 0.0311 | L10: 0.1454 | M10: 0.2883 | N10: 0.4637 | O10: 0.6549 | P10: 0.8486 | Q10: 1.0412 | R10: 1.2341 | S10: 1.4152 | T10: 1.5854 | U10: 1.7304 | V10: 1.854 | W10: 1.9625 | X10: 2.0521 | Y10: 2.1156 | Z10: 2.1435 | AA10: 2.1516 | AB10: 2.1365 | AC10: 2.0857 | AD10: 2.0083 | AE10: 1.9159 | AF10: 1.7989 | AG10: 1.6745 | AH10: 1.5247 | AI10: 1.3561 | AJ10: 1.1525 | AK10: 0.962 | AL10: 0.7662 | AM10: 0.5768 | AN10: 0.3942 | AO10: 0.2302 | AP10: 0.067 | AQ10: 0.0124 | AR10: 0 | AS10: 0 | AT10: 0 | AU10: 0 | AV10: 0 | AW10: 0 | AX10: 0
A11: Load_TR5_F1_12_dup | B11: prosumer | C11: 0 | D11: 0 | E11: 0 | F11: 0 | G11: 0 | H11: 0 | I11: 0 | J11: 0.0017 | K11: 0.0249 | L11: 0.1163 | M11: 0.2307 | N11: 0.3709 | O11: 0.524 | P11: 0.6789 | Q11: 0.833 | R11: 0.9873 | S11: 1.1322 | T11: 1.2683 | U11: 1.3843 | V11: 1.4832 | W11: 1.57 | X11: 1.6417 | Y11: 1.6925 | Z11: 1.7148 | AA11: 1.7212 | AB11: 1.7092 | AC11: 1.6686 | AD11: 1.6067 | AE11: 1.5328 | AF11: 1.4391 | AG11: 1.3396 | AH11: 1.2198 | AI11: 1.0849 | AJ11: 0.922 | AK11: 0.7696 | AL11: 0.613 | AM11: 0.4615 | AN11: 0.3154 | AO11: 0.1842 | AP11: 0.0536 | AQ11: 0.0099 | AR11: 0 | AS11: 0 | AT11: 0 | AU11: 0 | AV11: 0 | AW11: 0 | AX11: 0
A12: Load_TR5_F1_13 | B12: customer | C12: 0 | D12: 0 | E12: 0 | F12: 0 | G12: 0 | H12: 0 | I12: 0 | J12: 0 | K12: 0 | L12: 0 | M12: 0 | N12: 0 | O12: 0 | P12: 0 | Q12: 0 | R12: 0 | S12: 0 | T12: 0 | U12: 0 | V12: 0 | W12: 0 | X12: 0 | Y12: 0 | Z12: 0 | AA12: 0 | AB12: 0 | AC12: 0 | AD12: 0 | AE12: 0 | AF12: 0 | AG12: 0 | AH12: 0 | AI12: 0 | AJ12: 0 | AK12: 0 | AL12: 0 | AM12: 0 | AN12: 0 | AO12: 0 | AP12: 0 | AQ12: 0 | AR12: 0 | AS12: 0 | AT12: 0 | AU12: 0 | AV12: 0 | AW12: 0 | AX12: 0
A13: Load_TR5_F1_13_dup | B13: prosumer | C13: 0 | D13: 0 | E13: 0 | F13: 0 | G13: 0 | H13: 0 | I13: 0 | J13: 0.0013 | K13: 0.0187 | L13: 0.0872 | M13: 0.173 | N13: 0.2782 | O13: 0.393 | P13: 0.5092 | Q13: 0.6247 | R13: 0.7405 | S13: 0.8491 | T13: 0.9512 | U13: 1.0382 | V13: 1.1124 | W13: 1.1775 | X13: 1.2312 | Y13: 1.2694 | Z13: 1.2861 | AA13: 1.2909 | AB13: 1.2819 | AC13: 1.2514 | AD13: 1.205 | AE13: 1.1496 | AF13: 1.0793 | AG13: 1.0047 | AH13: 0.9148 | AI13: 0.8137 | AJ13: 0.6915 | AK13: 0.5772 | AL13: 0.4597 | AM13: 0.3461 | AN13: 0.2365 | AO13: 0.1381 | AP13: 0.0402 | AQ13: 0.0074 | AR13: 0 | AS13: 0 | AT13: 0 | AU13: 0 | AV13: 0 | AW13: 0 | AX13: 0
A14: Load_TR5_F1_14 | B14: prosumer | C14: 0 | D14: 0 | E14: 0 | F14: 0 | G14: 0 | H14: 0 | I14: 0 | J14: 0.0026 | K14: 0.0373 | L14: 0.1744 | M14: 0.346 | N14: 0.5564 | O14: 0.7859 | P14: 1.0183 | Q14: 1.2495 | R14: 1.481 | S14: 1.6982 | T14: 1.9025 | U14: 2.0764 | V14: 2.2248 | W14: 2.355 | X14: 2.4625 | Y14: 2.5387 | Z14: 2.5722 | AA14: 2.5819 | AB14: 2.5637 | AC14: 2.5029 | AD14: 2.41 | AE14: 2.2991 | AF14: 2.1586 | AG14: 2.0093 | AH14: 1.8297 | AI14: 1.6274 | AJ14: 1.3831 | AK14: 1.1544 | AL14: 0.9195 | AM14: 0.6922 | AN14: 0.4731 | AO14: 0.2762 | AP14: 0.0804 | AQ14: 0.0148 | AR14: 0 | AS14: 0 | AT14: 0 | AU14: 0 | AV14: 0 | AW14: 0 | AX14: 0
A15: Load_TR5_F1_14_dup | B15: prosumer | C15: 0 | D15: 0 | E15: 0 | F15: 0 | G15: 0 | H15: 0 | I15: 0 | J15: 0.0017 | K15: 0.0249 | L15: 0.1163 | M15: 0.2307 | N15: 0.3709 | O15: 0.524 | P15: 0.6789 | Q15: 0.833 | R15: 0.9873 | S15: 1.1322 | T15: 1.2683 | U15: 1.3843 | V15: 1.4832 | W15: 1.57 | X15: 1.6417 | Y15: 1.6925 | Z15: 1.7148 | AA15: 1.7212 | AB15: 1.7092 | AC15: 1.6686 | AD15: 1.6067 | AE15: 1.5328 | AF15: 1.4391 | AG15: 1.3396 | AH15: 1.2198 | AI15: 1.0849 | AJ15: 0.922 | AK15: 0.7696 | AL15: 0.613 | AM15: 0.4615 | AN15: 0.3154 | AO15: 0.1842 | AP15: 0.0536 | AQ15: 0.0099 | AR15: 0 | AS15: 0 | AT15: 0 | AU15: 0 | AV15: 0 | AW15: 0 | AX15: 0
A16: Load_TR5_F1_15 | B16: customer | C16: 0 | D16: 0 | E16: 0 | F16: 0 | G16: 0 | H16: 0 | I16: 0 | J16: 0 | K16: 0 | L16: 0 | M16: 0 | N16: 0 | O16: 0 | P16: 0 | Q16: 0 | R16: 0 | S16: 0 | T16: 0 | U16: 0 | V16: 0 | W16: 0 | X16: 0 | Y16: 0 | Z16: 0 | AA16: 0 | AB16: 0 | AC16: 0 | AD16: 0 | AE16: 0 | AF16: 0 | AG16: 0 | AH16: 0 | AI16: 0 | AJ16: 0 | AK16: 0 | AL16: 0 | AM16: 0 | AN16: 0 | AO16: 0 | AP16: 0 | AQ16: 0 | AR16: 0 | AS16: 0 | AT16: 0 | AU16: 0 | AV16: 0 | AW16: 0 | AX16: 0
... A421: Load_TR5_F6_9 | B421: customer | C421: 0 | D421: 0 | E421: 0 | F421: 0 | G421: 0 | H421: 0 | I421: 0 | J421: 0 | K421: 0 | L421: 0 | M421: 0 | N421: 0 | O421: 0 | P421: 0 | Q421: 0 | R421: 0 | S421: 0 | T421: 0 | U421: 0 | V421: 0 | W421: 0 | X421: 0 | Y421: 0 | Z421: 0 | AA421: 0 | AB421: 0 | AC421: 0 | AD421: 0 | AE421: 0 | AF421: 0 | AG421: 0 | AH421: 0 | AI421: 0 | AJ421: 0 | AK421: 0 | AL421: 0 | AM421: 0 | AN421: 0 | AO421: 0 | AP421: 0 | AQ421: 0 | AR421: 0 | AS421: 0 | AT421: 0 | AU421: 0 | AV421: 0 | AW421: 0 | AX421: 0

Sheet 4. Raw load per load
A1: Raw load per load
A2: Verbatim copy of Load_P_kW (TR5_load_PV_48periods.xlsx), tagged by type. One row per connection, 48 half-hours (kW).
A4: Load name | B4: Type | C4: p1 | D4: p2 | E4: p3 | F4: p4 | G4: p5 | H4: p6 | I4: p7 | J4: p8 | K4: p9 | L4: p10 | M4: p11 | N4: p12 | O4: p13 | P4: p14 | Q4: p15 | R4: p16 | S4: p17 | T4: p18 | U4: p19 | V4: p20 | W4: p21 | X4: p22 | Y4: p23 | Z4: p24 | AA4: p25 | AB4: p26 | AC4: p27 | AD4: p28 | AE4: p29 | AF4: p30 | AG4: p31 | AH4: p32 | AI4: p33 | AJ4: p34 | AK4: p35 | AL4: p36 | AM4: p37 | AN4: p38 | AO4: p39 | AP4: p40 | AQ4: p41 | AR4: p42 | AS4: p43 | AT4: p44 | AU4: p45 | AV4: p46 | AW4: p47 | AX4: p48
A5: Load_TR5_F1_1 | B5: prosumer | C5: 0.2355 | D5: 0.052 | E5: 0.1604 | F5: 0.1271 | G5: 0.052 | H5: 0.0937 | I5: 0.1938 | J5: 0.052 | K5: 0.052 | L5: 0.2355 | M5: 0.052 | N5: 0.052 | O5: 0.2272 | P5: 0.0603 | Q5: 0.245 | R5: 1.0888 | S5: 0.226 | T5: 0.3653 | U5: 0.3936 | V5: 0.2921 | W5: 0.473 | X5: 0.434 | Y5: 0.2129 | Z5: 0.6047 | AA5: 0.2452 | AB5: 2.0194 | AC5: 0.5818 | AD5: 0.4188 | AE5: 0.3091 | AF5: 0.1 | AG5: 0.3997 | AH5: 0.1665 | AI5: 0.9459 | AJ5: 2.1714 | AK5: 1.8219 | AL5: 0.2806 | AM5: 0.3835 | AN5: 0.5267 | AO5: 0.561 | AP5: 0.3291 | AQ5: 0.0806 | AR5: 0.1354 | AS5: 0.1521 | AT5: 0.052 | AU5: 0.3605 | AV5: 0.5645 | AW5: 0.6776 | AX5: 0.6844
A6: Load_TR5_F1_10 | B6: prosumer | C6: 0.758 | D6: 0.6276 | E6: 0.7769 | F6: 0.2312 | G6: 0.2664 | H6: 0.1746 | I6: 0.1344 | J6: 0.2158 | K6: 0.1482 | L6: 0.2665 | M6: 0.0707 | N6: 0.1503 | O6: 0.1745 | P6: 0.1606 | Q6: 0.2358 | R6: 0.1997 | S6: 0.0908 | T6: 0.1713 | U6: 1.6537 | V6: 0.3993 | W6: 0.2852 | X6: 0.2294 | Y6: 0.4271 | Z6: 0.3119 | AA6: 1.5015 | AB6: 0.266 | AC6: 1.319 | AD6: 0.4272 | AE6: 0.1881 | AF6: 0.2232 | AG6: 0.2116 | AH6: 0.103 | AI6: 0.1951 | AJ6: 0.235 | AK6: 0.1281 | AL6: 0.1745 | AM6: 0.2287 | AN6: 0.355 | AO6: 0.2729 | AP6: 0.474 | AQ6: 0.2731 | AR6: 0.3914 | AS6: 0.1678 | AT6: 0.052 | AU6: 0.6142 | AV6: 0.1519 | AW6: 0.1658 | AX6: 0.2155
A7: Load_TR5_F1_10_dup | B7: prosumer | C7: 0.1706 | D7: 0.1882 | E7: 0.1154 | F7: 0.1154 | G7: 0.1759 | H7: 0.048 | I7: 0.3108 | J7: 0.048 | K7: 0.048 | L7: 0.3108 | M7: 0.048 | N7: 0.1631 | O7: 0.1956 | P7: 0.048 | Q7: 0.048 | R7: 0.048 | S7: 0.1399 | T7: 0.0909 | U7: 1.7715 | V7: 0.7763 | W7: 0.1759 | X7: 0.1461 | Y7: 0.1551 | Z7: 1.0046 | AA7: 0.7356 | AB7: 1.2214 | AC7: 0.1972 | AD7: 0.5909 | AE7: 1.2306 | AF7: 0.4185 | AG7: 0.2622 | AH7: 0.3783 | AI7: 0.1215 | AJ7: 0.048 | AK7: 0.1706 | AL7: 0.1882 | AM7: 0.1928 | AN7: 0.5361 | AO7: 0.3973 | AP7: 0.4698 | AQ7: 0.4529 | AR7: 0.5694 | AS7: 0.1338 | AT7: 0.2249 | AU7: 0.048 | AV7: 0.1828 | AW7: 0.0672 | AX7: 0.2425
A8: Load_TR5_F1_11 | B8: customer | C8: 0.051 | D8: 0.051 | E8: 0.051 | F8: 0.051 | G8: 0.051 | H8: 0.0641 | I8: 0.2546 | J8: 0.294 | K8: 0.051 | L8: 0.051 | M8: 0.051 | N8: 0.051 | O8: 0.051 | P8: 0.051 | Q8: 0.051 | R8: 0.0561 | S8: 0.0649 | T8: 0.0598 | U8: 0.1873 | V8: 0.2812 | W8: 0.2812 | X8: 0.4227 | Y8: 0.2999 | Z8: 0.3755 | AA8: 0.3572 | AB8: 1.0994 | AC8: 0.3182 | AD8: 0.4934 | AE8: 0.311 | AF8: 0.1325 | AG8: 0.325 | AH8: 0.0544 | AI8: 0.0649 | AJ8: 0.0635 | AK8: 1.2496 | AL8: 1.2152 | AM8: 2.6869 | AN8: 2.8111 | AO8: 0.5266 | AP8: 0.3656 | AQ8: 0.4151 | AR8: 0.051 | AS8: 0.2036 | AT8: 0.3702 | AU8: 0.051 | AV8: 0.051 | AW8: 0.051 | AX8: 0.051
A9: Load_TR5_F1_11_dup | B9: customer | C9: 0.1972 | D9: 0.051 | E9: 0.0975 | F9: 0.1507 | G9: 0.051 | H9: 0.051 | I9: 0.1972 | J9: 0.051 | K9: 0.1706 | L9: 0.0776 | M9: 0.0709 | N9: 0.1773 | O9: 0.051 | P9: 0.1174 | Q9: 0.1307 | R9: 1.4152 | S9: 0.8483 | T9: 0.2132 | U9: 0.0831 | V9: 1.8108 | W9: 0.0644 | X9: 1.1724 | Y9: 0.4082 | Z9: 0.2748 | AA9: 0.2748 | AB9: 0.2515 | AC9: 0.0842 | AD9: 0.1108 | AE9: 0.1374 | AF9: 0.715 | AG9: 0.9264 | AH9: 0.2347 | AI9: 1.4662 | AJ9: 0.9256 | AK9: 0.2762 | AL9: 0.5929 | AM9: 0.9281 | AN9: 2.2632 | AO9: 0.9636 | AP9: 0.815 | AQ9: 0.3145 | AR9: 1.2264 | AS9: 0.7165 | AT9: 0.5151 | AU9: 0.2296 | AV9: 0.1212 | AW9: 0.1144 | AX9: 0.1507
A10: Load_TR5_F1_12 | B10: prosumer | C10: 0.2899 | D10: 0.0602 | E10: 0.3614 | F10: 0.039 | G10: 0.1025 | H10: 0.2661 | I10: 0.092 | J10: 0.289 | K10: 0.1326 | L10: 0.088 | M10: 0.0989 | N10: 0.2737 | O10: 0.039 | P10: 0.0836 | Q10: 0.2585 | R10: 0.1185 | S10: 0.4194 | T10: 0.2456 | U10: 0.7224 | V10: 0.5236 | W10: 0.2177 | X10: 0.3442 | Y10: 0.4102 | Z10: 1.2541 | AA10: 0.8142 | AB10: 0.606 | AC10: 0.3093 | AD10: 0.5979 | AE10: 0.2799 | AF10: 0.4289 | AG10: 0.2918 | AH10: 0.1169 | AI10: 0.5903 | AJ10: 0.2261 | AK10: 0.5713 | AL10: 0.9097 | AM10: 0.1434 | AN10: 0.3561 | AO10: 0.3366 | AP10: 0.4829 | AQ10: 0.4011 | AR10: 0.4444 | AS10: 0.6638 | AT10: 0.4451 | AU10: 0.3604 | AV10: 0.2301 | AW10: 0.1863 | AX10: 0.1364
A11: Load_TR5_F1_12_dup | B11: prosumer | C11: 0.122 | D11: 0.048 | E11: 0.122 | F11: 0.048 | G11: 0.048 | H11: 0.0768 | I11: 0.0932 | J11: 0.048 | K11: 0.122 | L11: 0.048 | M11: 0.048 | N11: 0.048 | O11: 0.048 | P11: 0.048 | Q11: 0.316 | R11: 0.225 | S11: 0.0764 | T11: 0.5118 | U11: 1.306 | V11: 0.3729 | W11: 1.1359 | X11: 0.1101 | Y11: 0.0691 | Z11: 0.1708 | AA11: 0.7349 | AB11: 0.5906 | AC11: 0.2529 | AD11: 0.1075 | AE11: 0.3266 | AF11: 0.1116 | AG11: 0.1028 | AH11: 0.1211 | AI11: 0.5659 | AJ11: 1.3082 | AK11: 0.9414 | AL11: 1.8842 | AM11: 0.9342 | AN11: 1.1448 | AO11: 0.5917 | AP11: 0.5434 | AQ11: 0.58 | AR11: 0.5728 | AS11: 1.1421 | AT11: 0.7017 | AU11: 0.5034 | AV11: 0.4419 | AW11: 0.3884 | AX11: 0.1056
A12: Load_TR5_F1_13 | B12: customer | C12: 0.044 | D12: 0.183 | E12: 0.0749 | F12: 0.044 | G12: 0.1135 | H12: 0.1444 | I12: 0.0594 | J12: 0.1985 | K12: 0.044 | L12: 0.0517 | M12: 0.2062 | N12: 0.044 | O12: 0.044 | P12: 0.2139 | Q12: 0.044 | R12: 0.1095 | S12: 0.1768 | T12: 0.0826 | U12: 0.05 | V12: 0.1847 | W12: 0.0749 | X12: 0.044 | Y12: 0.0517 | Z12: 0.2062 | AA12: 0.044 | AB12: 0.1907 | AC12: 0.1572 | AD12: 0.1404 | AE12: 0.2636 | AF12: 0.1979 | AG12: 0.1494 | AH12: 0.2795 | AI12: 0.044 | AJ12: 0.2139 | AK12: 0.0778 | AL12: 0.2509 | AM12: 0.4005 | AN12: 0.044 | AO12: 0.2279 | AP12: 0.1478 | AQ12: 0.4657 | AR12: 0.4239 | AS12: 0.2572 | AT12: 0.512 | AU12: 0.3218 | AV12: 0.4828 | AW12: 0.044 | AX12: 0.044
A13: Load_TR5_F1_13_dup | B13: prosumer | C13: 0.3803 | D13: 0.037 | E13: 0.037 | F13: 0.037 | G13: 0.037 | H13: 0.037 | I13: 0.037 | J13: 0.037 | K13: 0.037 | L13: 0.037 | M13: 0.037 | N13: 0.037 | O13: 0.037 | P13: 0.037 | Q13: 0.037 | R13: 0.037 | S13: 0.037 | T13: 0.5405 | U13: 2.1166 | V13: 0.1561 | W13: 0.1397 | X13: 0.1464 | Y13: 0.1316 | Z13: 0.1404 | AA13: 0.127 | AB13: 0.097 | AC13: 0.051 | AD13: 0.2688 | AE13: 0.0852 | AF13: 0.2907 | AG13: 0.272 | AH13: 0.0888 | AI13: 0.09 | AJ13: 0.0577 | AK13: 0.161 | AL13: 0.1341 | AM13: 0.0767 | AN13: 0.1529 | AO13: 0.1429 | AP13: 0.2573 | AQ13: 0.547 | AR13: 0.3214 | AS13: 0.3497 | AT13: 0.4519 | AU13: 0.5201 | AV13: 0.5684 | AW13: 0.6572 | AX13: 0.7238
A14: Load_TR5_F1_14 | B14: prosumer | C14: 0.056 | D14: 0.2911 | E14: 0.056 | F14: 0.056 | G14: 0.1711 | H14: 0.0899 | I14: 0.1421 | J14: 0.056 | K14: 0.2289 | L14: 0.1182 | M14: 0.1373 | N14: 0.2098 | O14: 0.056 | P14: 0.1421 | Q14: 0.1237 | R14: 0.4634 | S14: 1.0527 | T14: 1.3246 | U14: 0.207 | V14: 0.1381 | W14: 0.3002 | X14: 0.1881 | Y14: 0.1465 | Z14: 0.2209 | AA14: 0.1485 | AB14: 0.1196 | AC14: 1.5255 | AD14: 0.056 | AE14: 0.1628 | AF14: 0.6044 | AG14: 0.3416 | AH14: 0.298 | AI14: 0.702 | AJ14: 0.5982 | AK14: 0.8035 | AL14: 1.0931 | AM14: 0.056 | AN14: 0.2911 | AO14: 0.9082 | AP14: 0.5387 | AQ14: 0.8105 | AR14: 0.5564 | AS14: 0.8802 | AT14: 0.7122 | AU14: 0.9926 | AV14: 0.8564 | AW14: 1.1063 | AX14: 1.2063
A15: Load_TR5_F1_14_dup | B15: prosumer | C15: 0.1622 | D15: 0.1946 | E15: 0.056 | F15: 0.2618 | G15: 0.095 | H15: 0.1524 | I15: 0.2044 | J15: 0.0863 | K15: 0.2488 | L15: 0.0776 | M15: 0.1394 | N15: 0.2174 | O15: 0.056 | P15: 0.056 | Q15: 0.4011 | R15: 0.0788 | S15: 0.1167 | T15: 0.6113 | U15: 0.105 | V15: 0.5137 | W15: 0.2682 | X15: 0.2322 | Y15: 0.3002 | Z15: 0.3331 | AA15: 0.2001 | AB15: 0.056 | AC15: 0.0776 | AD15: 0.1123 | AE15: 0.2532 | AF15: 0.1036 | AG15: 0.1383 | AH15: 0.2185 | AI15: 0.0776 | AJ15: 0.1123 | AK15: 0.2001 | AL15: 0.2588 | AM15: 0.8421 | AN15: 0.6877 | AO15: 0.5445 | AP15: 0.6727 | AQ15: 1.1172 | AR15: 0.9799 | AS15: 0.1774 | AT15: 0.1795 | AU15: 0.0788 | AV15: 0.2521 | AW15: 0.082 | AX15: 0.2466
A16: Load_TR5_F1_15 | B16: customer | C16: 0.0638 | D16: 0.1059 | E16: 0.047 | F16: 0.068 | G16: 0.1017 | H16: 0.047 | I16: 0.047 | J16: 0.1143 | K16: 0.0554 | L16: 0.1227 | M16: 0.047 | N16: 0.047 | O16: 0.047 | P16: 0.2145 | Q16: 1.3606 | R16: 0.9558 | S16: 0.0998 | T16: 0.0731 | U16: 0.1271 | V16: 0.2825 | W16: 0.1962 | X16: 0.047 | Y16: 0.1143 | Z16: 0.0554 | AA16: 0.0652 | AB16: 0.0874 | AC16: 0.2563 | AD16: 0.0701 | AE16: 0.247 | AF16: 0.3139 | AG16: 1.5973 | AH16: 3.0872 | AI16: 1.5225 | AJ16: 0.2828 | AK16: 0.1511 | AL16: 0.2064 | AM16: 0.1545 | AN16: 0.2216 | AO16: 0.1766 | AP16: 0.4659 | AQ16: 0.3416 | AR16: 0.3703 | AS16: 0.4644 | AT16: 0.4696 | AU16: 0.047 | AV16: 0.0849 | AW16: 0.1873 | AX16: 0.1099
... A421: Load_TR5_F6_9 | B421: customer | C421: 0.355 | D421: 0.047 | E421: 0.0522 | F421: 0.3033 | G421: 0.1144 | H421: 0.047 | I421: 0.3651 | J421: 0.0579 | K421: 0.2334 | L421: 0.1896 | M421: 0.0522 | N421: 0.3137 | O421: 0.104 | P421: 0.0545 | Q421: 0.2615 | R421: 0.1539 | S421: 0.1308 | T421: 0.4246 | U421: 0.2639 | V421: 0.3151 | W421: 0.5501 | X421: 0.1765 | Y421: 0.4663 | Z421: 0.2602 | AA421: 0.162 | AB421: 0.2752 | AC421: 0.047 | AD421: 0.1851 | AE421: 0.2379 | AF421: 0.0582 | AG421: 0.3505 | AH421: 0.0837 | AI421: 0.1711 | AJ421: 0.382 | AK421: 0.3423 | AL421: 0.377 | AM421: 0.3121 | AN421: 0.1502 | AO421: 0.516 | AP421: 0.3792 | AQ421: 0.6393 | AR421: 0.6386 | AS421: 0.8143 | AT421: 0.711 | AU421: 0.7843 | AV421: 0.8469 | AW421: 0.7927 | AX421: 0.2547

Sheet 5. Raw batt charge
A1: Raw batt charge
A2: Verbatim copy of Charge_kW (TR5_analysis_data.xlsx). One row per half-hour, one column per battery (kW).
A4: period | B4: hour | C4: BES_TR5_one38_B | D4: BES_TR5_one195_C | E4: BES_TR5_one195_dup_C | F4: BES_TR5_one235_A | G4: BES_TR5_one235_dup_A | H4: BES_TR5_one242_dup_B | I4: BES_TR5_one252_C | J4: BES_TR5_one252_dup_C | K4: BES_TR5_one260_dup_C | L4: BES_TR5_one280_A | M4: BES_TR5_one287_B | N4: BES_TR5_one299_B | O4: BES_TR5_one299_dup_B | P4: BES_TR5_one313_A | Q4: BES_TR5_one313_dup_A | R4: BES_TR5_one42_B | S4: BES_TR5_one320_B | T4: BES_TR5_one321_C | U4: BES_TR5_one328_A | V4: BES_TR5_one345_dup_A | W4: BES_TR5_one346_C | X4: BES_TR5_one366_dup_B | Y4: BES_TR5_one375_C | Z4: BES_TR5_one375_dup_C | AA4: BES_TR5_one410_B | AB4: BES_TR5_one410_dup_B | AC4: BES_TR5_one50_A | AD4: BES_TR5_one416_C | AE4: BES_TR5_one416_dup_C | AF4: BES_TR5_one423_dup_B | AG4: BES_TR5_one446_dup_B | AH4: BES_TR5_one469_A | AI4: BES_TR5_one477_A | AJ4: BES_TR5_one477_dup_A | AK4: BES_TR5_one480_A | AL4: BES_TR5_one480_dup_A | AM4: BES_TR5_one521_dup_C | AN4: BES_TR5_one528_C | AO4: BES_TR5_one528_dup_C | AP4: BES_TR5_one61_dup_A | AQ4: BES_TR5_one544_A | AR4: BES_TR5_one544_dup_A | AS4: BES_TR5_one559_C | AT4: BES_TR5_one590_A | AU4: BES_TR5_one590_dup_A | AV4: BES_TR5_one605_A | AW4: BES_TR5_one605_dup_A | AX4: BES_TR5_one614_B | AY4: BES_TR5_one617_dup_A | AZ4: BES_TR5_one73_A | BA4: BES_TR5_one73_dup_A | BB4: BES_TR5_one76_A | BC4: BES_TR5_one133_A | BD4: BES_TR5_one137_A | BE4: BES_TR5_one176_A | BF4: BES_TR5_four1252_C | BG4: BES_TR5_four171_A | BH4: BES_TR5_four180_A | BI4: BES_TR5_four184_B | BJ4: BES_TR5_four200_A | BK4: BES_TR5_four239_A | BL4: BES_TR5_four259_B | BM4: BES_TR5_four54_C | BN4: BES_TR5_four279_B | BO4: BES_TR5_four288_B | BP4: BES_TR5_four301_C | BQ4: BES_TR5_four326_A | BR4: BES_TR5_four352_A | BS4: BES_TR5_four354_B | BT4: BES_TR5_four358_C | BU4: BES_TR5_four381_A | BV4: BES_TR5_four385_A | BW4: BES_TR5_four396_B | BX4: BES_TR5_four423_C | BY4: BES_TR5_four446_B | BZ4: BES_TR5_four451_C | CA4: BES_TR5_four532_A | CB4: BES_TR5_four548_B | CC4: BES_TR5_four553_B | CD4: BES_TR5_four562_C | CE4: BES_TR5_four70_B | CF4: BES_TR5_four659_B | CG4: BES_TR5_four675_C | CH4: BES_TR5_four704_B | CI4: BES_TR5_four710_C | CJ4: BES_TR5_four734_A | CK4: BES_TR5_four763_A | CL4: BES_TR5_four797_C | CM4: BES_TR5_four840_A | CN4: BES_TR5_four854_A | CO4: BES_TR5_four926_B | CP4: BES_TR5_four958_C | CQ4: BES_TR5_four1027_A | CR4: BES_TR5_four1063_C | CS4: BES_TR5_four1091_B | CT4: BES_TR5_four1103_C | CU4: BES_TR5_four1132_C | CV4: BES_TR5_four1140_A | CW4: BES_TR5_four126_A | CX4: BES_TR5_four1187_A | CY4: BES_TR5_four1207_B | CZ4: BES_TR5_four1216_C | DA4: BES_TR5_four1220_C | DB4: BES_TR5_four1226_A | DC4: BES_TR5_four1244_B | DD4: BES_TR5_five58_dup_C | DE4: BES_TR5_five147_dup_C | DF4: BES_TR5_five149_A | DG4: BES_TR5_five149_dup_A | DH4: BES_TR5_five160_C | DI4: BES_TR5_five160_dup_C | DJ4: BES_TR5_five168_A | DK4: BES_TR5_five170_A | DL4: BES_TR5_five177_A | DM4: BES_TR5_five194_C | DN4: BES_TR5_five194_dup_C | DO4: BES_TR5_five220_C | DP4: BES_TR5_five220_dup_C | DQ4: BES_TR5_five223_dup_A | DR4: BES_TR5_five242_dup_A | DS4: BES_TR5_five243_dup_B | DT4: BES_TR5_five284_C | DU4: BES_TR5_five284_dup_C | DV4: BES_TR5_five285_B | DW4: BES_TR5_five309_C | DX4: BES_TR5_five324_B | DY4: BES_TR5_five345_A | DZ4: BES_TR5_five355_A | EA4: BES_TR5_five78_dup_A | EB4: BES_TR5_five394_C | EC4: BES_TR5_five421_A | ED4: BES_TR5_five421_dup_A | EE4: BES_TR5_five457_B | EF4: BES_TR5_five457_dup_B | EG4: BES_TR5_five466_A | EH4: BES_TR5_five472_dup_A | EI4: BES_TR5_five488_B | EJ4: BES_TR5_five488_dup_B | EK4: BES_TR5_five494_dup_B | EL4: BES_TR5_five512_A | EM4: BES_TR5_five513_dup_B | EN4: BES_TR5_five537_C | EO4: BES_TR5_five537_dup_C | EP4: BES_TR5_five540_A | EQ4: BES_TR5_five545_dup_B | ER4: BES_TR5_five585_dup_A | ES4: BES_TR5_five588_dup_A | ET4: BES_TR5_five108_B | EU4: BES_TR5_five108_dup_B | EV4: BES_TR5_five663_C | EW4: BES_TR5_five663_dup_C | EX4: BES_TR5_five670_C | EY4: BES_TR5_five670_dup_C | EZ4: BES_TR5_five685_dup_B | FA4: BES_TR5_five695_dup_A | FB4: BES_TR5_five704_dup_A | FC4: BES_TR5_five719_A | FD4: BES_TR5_five719_dup_A | FE4: BES_TR5_five735_A | FF4: BES_TR5_five748_dup_B | FG4: BES_TR5_five117_dup_B | FH4: BES_TR5_five750_B | FI4: BES_TR5_five750_dup_B | FJ4: BES_TR5_five778_dup_B | FK4: BES_TR5_five793_A | FL4: BES_TR5_five793_dup_A | FM4: BES_TR5_five799_dup_C | FN4: BES_TR5_five801_dup_C | FO4: BES_TR5_five118_B | FP4: BES_TR5_six64_A | FQ4: BES_TR5_six173_C | FR4: BES_TR5_six186_A | FS4: BES_TR5_six203_A | FT4: BES_TR5_six238_A | FU4: BES_TR5_six249_B | FV4: BES_TR5_six254_B | FW4: BES_TR5_six68_C | FX4: BES_TR5_six317_C | FY4: BES_TR5_six326_A | FZ4: BES_TR5_six342_A | GA4: BES_TR5_six350_B | GB4: BES_TR5_six75_A | GC4: BES_TR5_six385_B | GD4: BES_TR5_six387_A | GE4: BES_TR5_six392_C | GF4: BES_TR5_six431_C | GG4: BES_TR5_six441_A | GH4: BES_TR5_six512_B | GI4: BES_TR5_six518_B | GJ4: BES_TR5_six523_C | GK4: BES_TR5_six534_B | GL4: BES_TR5_six591_C | GM4: BES_TR5_six595_B | GN4: BES_TR5_six643_A | GO4: BES_TR5_six646_B | GP4: BES_TR5_six651_C | GQ4: BES_TR5_six87_A | GR4: BES_TR5_six665_B | GS4: BES_TR5_six718_C | GT4: BES_TR5_six721_A | GU4: BES_TR5_six723_B | GV4: BES_TR5_six740_A | GW4: BES_TR5_six799_B | GX4: BES_TR5_six807_A | GY4: BES_TR5_six852_B | GZ4: BES_TR5_six860_C | HA4: BES_TR5_six885_A | HB4: BES_TR5_six909_C | HC4: BES_TR5_six921_B | HD4: BES_TR5_six929_A | HE4: BES_TR5_six952_A | HF4: BES_TR5_six967_B | HG4: BES_TR5_six111_C | HH4: BES_TR5_six1006_C
A5: 1 | B5: 0 | C5: 0 | D5: 0 | E5: 0 | F5: 0 | G5: 0 | H5: 0 | I5: 0 | J5: 0 | K5: 0 | L5: 0 | M5: 0 | N5: 0 | O5: 0 | P5: 0 | Q5: 0 | R5: 0 | S5: 0 | T5: 0 | U5: 0 | V5: 0 | W5: 0 | X5: 0 | Y5: 0 | Z5: 0 | AA5: 0 | AB5: 0 | AC5: 0 | AD5: 0 | AE5: 0 | AF5: 0 | AG5: 0 | AH5: 0 | AI5: 0 | AJ5: 0 | AK5: 0 | AL5: 0 | AM5: 0 | AN5: 0 | AO5: 0 | AP5: 0 | AQ5: 0 | AR5: 0 | AS5: 0 | AT5: 0 | AU5: 0 | AV5: 0 | AW5: 0 | AX5: 0 | AY5: 0 | AZ5: 0 | BA5: 0 | BB5: 0 | BC5: 0 | BD5: 0 | BE5: 0 | BF5: 0 | BG5: 0 | BH5: 0 | BI5: 0 | BJ5: 0 | BK5: 0 | BL5: 0 | BM5: 0 | BN5: 0 | BO5: 0 | BP5: 0 | BQ5: 0 | BR5: 0 | BS5: 0 | BT5: 0 | BU5: 0 | BV5: 0 | BW5: 0 | BX5: 0 | BY5: 0 | BZ5: 0 | CA5: 0 | CB5: 0 | CC5: 0 | CD5: 0 | CE5: 0 | CF5: 0 | CG5: 0 | CH5: 0 | CI5: 0 | CJ5: 0 | CK5: 0 | CL5: 0 | CM5: 0 | CN5: 0 | CO5: 0 | CP5: 0 | CQ5: 0 | CR5: 0 | CS5: 0 | CT5: 0 | CU5: 0 | CV5: 0 | CW5: 0 | CX5: 0 | CY5: 0 | CZ5: 0 | DA5: 0 | DB5: 0 | DC5: 0 | DD5: 0 | DE5: 0 | DF5: 0 | DG5: 0 | DH5: 0 | DI5: 0 | DJ5: 0 | DK5: 0 | DL5: 0 | DM5: 0 | DN5: 0 | DO5: 0 | DP5: 0 | DQ5: 0 | DR5: 0 | DS5: 0 | DT5: 0 | DU5: 0 | DV5: 0 | DW5: 0 | DX5: 0 | DY5: 0 | DZ5: 0 | EA5: 0 | EB5: 0 | EC5: 0 | ED5: 0 | EE5: 0 | EF5: 0 | EG5: 0 | EH5: 0 | EI5: 0 | EJ5: 0 | EK5: 0 | EL5: 0 | EM5: 0 | EN5: 0 | EO5: 0 | EP5: 0 | EQ5: 0 | ER5: 0 | ES5: 0 | ET5: 0 | EU5: 0 | EV5: 0 | EW5: 0 | EX5: 0 | EY5: 0 | EZ5: 0 | FA5: 0 | FB5: 0 | FC5: 0 | FD5: 0 | FE5: 0 | FF5: 0 | FG5: 0 | FH5: 0 | FI5: 0 | FJ5: 0 | FK5: 0 | FL5: 0 | FM5: 0 | FN5: 0 | FO5: 0 | FP5: 0 | FQ5: 0 | FR5: 0 | FS5: 0 | FT5: 0 | FU5: 0 | FV5: 0 | FW5: 0 | FX5: 0 | FY5: 0 | FZ5: 0 | GA5: 0 | GB5: 0 | GC5: 0 | GD5: 0 | GE5: 0 | GF5: 0 | GG5: 0 | GH5: 0 | GI5: 0 | GJ5: 0 | GK5: 0 | GL5: 0 | GM5: 0 | GN5: 0 | GO5: 0 | GP5: 0 | GQ5: 0 | GR5: 0 | GS5: 0 | GT5: 0 | GU5: 0 | GV5: 0 | GW5: 0 | GX5: 0 | GY5: 0 | GZ5: 0 | HA5: 0 | HB5: 0 | HC5: 0 | HD5: 0 | HE5: 0 | HF5: 0 | HG5: 0 | HH5: 0
A6: 2 | B6: 0.5 | C6: 0 | D6: 0 | E6: 0 | F6: 0 | G6: 0 | H6: 0 | I6: 0 | J6: 0 | K6: 0 | L6: 0 | M6: 0 | N6: 0 | O6: 0 | P6: 0 | Q6: 0 | R6: 0 | S6: 0 | T6: 0 | U6: 0 | V6: 0 | W6: 0 | X6: 0 | Y6: 0 | Z6: 0 | AA6: 0 | AB6: 0 | AC6: 0 | AD6: 0 | AE6: 0 | AF6: 0 | AG6: 0 | AH6: 0 | AI6: 0 | AJ6: 0 | AK6: 0 | AL6: 0 | AM6: 0 | AN6: 0 | AO6: 0 | AP6: 0 | AQ6: 0 | AR6: 0 | AS6: 0 | AT6: 0 | AU6: 0 | AV6: 0 | AW6: 0 | AX6: 0 | AY6: 0 | AZ6: 0 | BA6: 0 | BB6: 0 | BC6: 0 | BD6: 0 | BE6: 0 | BF6: 0 | BG6: 0 | BH6: 0 | BI6: 0 | BJ6: 0 | BK6: 0 | BL6: 0 | BM6: 0 | BN6: 0 | BO6: 0 | BP6: 0 | BQ6: 0 | BR6: 0 | BS6: 0 | BT6: 0 | BU6: 0 | BV6: 0 | BW6: 0 | BX6: 0 | BY6: 0 | BZ6: 0 | CA6: 0 | CB6: 0 | CC6: 0 | CD6: 0 | CE6: 0 | CF6: 0 | CG6: 0 | CH6: 0 | CI6: 0 | CJ6: 0 | CK6: 0 | CL6: 0 | CM6: 0 | CN6: 0 | CO6: 0 | CP6: 0 | CQ6: 0 | CR6: 0 | CS6: 0 | CT6: 0 | CU6: 0 | CV6: 0 | CW6: 0 | CX6: 0 | CY6: 0 | CZ6: 0 | DA6: 0 | DB6: 0 | DC6: 0 | DD6: 0 | DE6: 0 | DF6: 0 | DG6: 0 | DH6: 0 | DI6: 0 | DJ6: 0 | DK6: 0 | DL6: 0 | DM6: 0 | DN6: 0 | DO6: 0 | DP6: 0 | DQ6: 0 | DR6: 0 | DS6: 0 | DT6: 0 | DU6: 0 | DV6: 0 | DW6: 0 | DX6: 0 | DY6: 0 | DZ6: 0 | EA6: 0 | EB6: 0 | EC6: 0 | ED6: 0 | EE6: 0 | EF6: 0 | EG6: 0 | EH6: 0 | EI6: 0 | EJ6: 0 | EK6: 0 | EL6: 0 | EM6: 0 | EN6: 0 | EO6: 0 | EP6: 0 | EQ6: 0 | ER6: 0 | ES6: 0 | ET6: 0 | EU6: 0 | EV6: 0 | EW6: 0 | EX6: 0 | EY6: 0 | EZ6: 0 | FA6: 0 | FB6: 0 | FC6: 0 | FD6: 0 | FE6: 0 | FF6: 0 | FG6: 0 | FH6: 0 | FI6: 0 | FJ6: 0 | FK6: 0 | FL6: 0 | FM6: 0 | FN6: 0 | FO6: 0 | FP6: 0 | FQ6: 0 | FR6: 0 | FS6: 0 | FT6: 0 | FU6: 0 | FV6: 0 | FW6: 0 | FX6: 0 | FY6: 0 | FZ6: 0 | GA6: 0 | GB6: 0 | GC6: 0 | GD6: 0 | GE6: 0 | GF6: 0 | GG6: 0 | GH6: 0 | GI6: 0 | GJ6: 0 | GK6: 0 | GL6: 0 | GM6: 0 | GN6: 0 | GO6: 0 | GP6: 0 | GQ6: 0 | GR6: 0 | GS6: 0 | GT6: 0 | GU6: 0 | GV6: 0 | GW6: 0 | GX6: 0 | GY6: 0 | GZ6: 0 | HA6: 0 | HB6: 0 | HC6: 0 | HD6: 0 | HE6: 0 | HF6: 0 | HG6: 0 | HH6: 0
A7: 3 | B7: 1 | C7: 0 | D7: 0 | E7: 0 | F7: 0 | G7: 0 | H7: 0 | I7: 0 | J7: 0 | K7: 0 | L7: 0 | M7: 0 | N7: 0 | O7: 0 | P7: 0 | Q7: 0 | R7: 0 | S7: 0 | T7: 0 | U7: 0 | V7: 0 | W7: 0 | X7: 0 | Y7: 0 | Z7: 0 | AA7: 0 | AB7: 0 | AC7: 0 | AD7: 0 | AE7: 0 | AF7: 0 | AG7: 0 | AH7: 0 | AI7: 0 | AJ7: 0 | AK7: 0 | AL7: 0 | AM7: 0 | AN7: 0 | AO7: 0 | AP7: 0 | AQ7: 0 | AR7: 0 | AS7: 0 | AT7: 0 | AU7: 0 | AV7: 0 | AW7: 0 | AX7: 0 | AY7: 0 | AZ7: 0 | BA7: 0 | BB7: 0 | BC7: 0 | BD7: 0 | BE7: 0 | BF7: 0 | BG7: 0 | BH7: 0 | BI7: 0 | BJ7: 0 | BK7: 0 | BL7: 0 | BM7: 0 | BN7: 0 | BO7: 0 | BP7: 0 | BQ7: 0 | BR7: 0 | BS7: 0 | BT7: 0 | BU7: 0 | BV7: 0 | BW7: 0 | BX7: 0 | BY7: 0 | BZ7: 0 | CA7: 0 | CB7: 0 | CC7: 0 | CD7: 0 | CE7: 0 | CF7: 0 | CG7: 0 | CH7: 0 | CI7: 0 | CJ7: 0 | CK7: 0 | CL7: 0 | CM7: 0 | CN7: 0 | CO7: 0 | CP7: 0 | CQ7: 0 | CR7: 0 | CS7: 0 | CT7: 0 | CU7: 0 | CV7: 0 | CW7: 0 | CX7: 0 | CY7: 0 | CZ7: 0 | DA7: 0 | DB7: 0 | DC7: 0 | DD7: 0 | DE7: 0 | DF7: 0 | DG7: 0 | DH7: 0 | DI7: 0 | DJ7: 0 | DK7: 0 | DL7: 0 | DM7: 0 | DN7: 0 | DO7: 0 | DP7: 0 | DQ7: 0 | DR7: 0 | DS7: 0 | DT7: 0 | DU7: 0 | DV7: 0 | DW7: 0 | DX7: 0 | DY7: 0 | DZ7: 0 | EA7: 0 | EB7: 0 | EC7: 0 | ED7: 0 | EE7: 0 | EF7: 0 | EG7: 0 | EH7: 0 | EI7: 0 | EJ7: 0 | EK7: 0 | EL7: 0 | EM7: 0 | EN7: 0 | EO7: 0 | EP7: 0 | EQ7: 0 | ER7: 0 | ES7: 0 | ET7: 0 | EU7: 0 | EV7: 0 | EW7: 0 | EX7: 0 | EY7: 0 | EZ7: 0 | FA7: 0 | FB7: 0 | FC7: 0 | FD7: 0 | FE7: 0 | FF7: 0 | FG7: 0 | FH7: 0 | FI7: 0 | FJ7: 0 | FK7: 0 | FL7: 0 | FM7: 0 | FN7: 0 | FO7: 0 | FP7: 0 | FQ7: 0 | FR7: 0 | FS7: 0 | FT7: 0 | FU7: 0 | FV7: 0 | FW7: 0 | FX7: 0 | FY7: 0 | FZ7: 0 | GA7: 0 | GB7: 0 | GC7: 0 | GD7: 0 | GE7: 0 | GF7: 0 | GG7: 0 | GH7: 0 | GI7: 0 | GJ7: 0 | GK7: 0 | GL7: 0 | GM7: 0 | GN7: 0 | GO7: 0 | GP7: 0 | GQ7: 0 | GR7: 0 | GS7: 0 | GT7: 0 | GU7: 0 | GV7: 0 | GW7: 0 | GX7: 0 | GY7: 0 | GZ7: 0 | HA7: 0 | HB7: 0 | HC7: 0 | HD7: 0 | HE7: 0 | HF7: 0 | HG7: 0 | HH7: 0
A8: 4 | B8: 1.5 | C8: 0 | D8: 0 | E8: 0 | F8: 0 | G8: 0 | H8: 0 | I8: 0 | J8: 0 | K8: 0 | L8: 0 | M8: 0 | N8: 0 | O8: 0 | P8: 0 | Q8: 0 | R8: 0 | S8: 0 | T8: 0 | U8: 0 | V8: 0 | W8: 0 | X8: 0 | Y8: 0 | Z8: 0 | AA8: 0 | AB8: 0 | AC8: 0 | AD8: 0 | AE8: 0 | AF8: 0 | AG8: 0 | AH8: 0 | AI8: 0 | AJ8: 0 | AK8: 0 | AL8: 0 | AM8: 0 | AN8: 0 | AO8: 0 | AP8: 0 | AQ8: 0 | AR8: 0 | AS8: 0 | AT8: 0 | AU8: 0 | AV8: 0 | AW8: 0 | AX8: 0 | AY8: 0 | AZ8: 0 | BA8: 0 | BB8: 0 | BC8: 0 | BD8: 0 | BE8: 0 | BF8: 0 | BG8: 0 | BH8: 0 | BI8: 0 | BJ8: 0 | BK8: 0 | BL8: 0 | BM8: 0 | BN8: 0 | BO8: 0 | BP8: 0 | BQ8: 0 | BR8: 0 | BS8: 0 | BT8: 0 | BU8: 0 | BV8: 0 | BW8: 0 | BX8: 0 | BY8: 0 | BZ8: 0 | CA8: 0 | CB8: 0 | CC8: 0 | CD8: 0 | CE8: 0 | CF8: 0 | CG8: 0 | CH8: 0 | CI8: 0 | CJ8: 0 | CK8: 0 | CL8: 0 | CM8: 0 | CN8: 0 | CO8: 0 | CP8: 0 | CQ8: 0 | CR8: 0 | CS8: 0 | CT8: 0 | CU8: 0 | CV8: 0 | CW8: 0 | CX8: 0 | CY8: 0 | CZ8: 0 | DA8: 0 | DB8: 0 | DC8: 0 | DD8: 0 | DE8: 0 | DF8: 0 | DG8: 0 | DH8: 0 | DI8: 0 | DJ8: 0 | DK8: 0 | DL8: 0 | DM8: 0 | DN8: 0 | DO8: 0 | DP8: 0 | DQ8: 0 | DR8: 0 | DS8: 0 | DT8: 0 | DU8: 0 | DV8: 0 | DW8: 0 | DX8: 0 | DY8: 0 | DZ8: 0 | EA8: 0 | EB8: 0 | EC8: 0 | ED8: 0 | EE8: 0 | EF8: 0 | EG8: 0 | EH8: 0 | EI8: 0 | EJ8: 0 | EK8: 0 | EL8: 0 | EM8: 0 | EN8: 0 | EO8: 0 | EP8: 0 | EQ8: 0 | ER8: 0 | ES8: 0 | ET8: 0 | EU8: 0 | EV8: 0 | EW8: 0 | EX8: 0 | EY8: 0 | EZ8: 0 | FA8: 0 | FB8: 0 | FC8: 0 | FD8: 0 | FE8: 0 | FF8: 0 | FG8: 0 | FH8: 0 | FI8: 0 | FJ8: 0 | FK8: 0 | FL8: 0 | FM8: 0 | FN8: 0 | FO8: 0 | FP8: 0 | FQ8: 0 | FR8: 0 | FS8: 0 | FT8: 0 | FU8: 0 | FV8: 0 | FW8: 0 | FX8: 0 | FY8: 0 | FZ8: 0 | GA8: 0 | GB8: 0 | GC8: 0 | GD8: 0 | GE8: 0 | GF8: 0 | GG8: 0 | GH8: 0 | GI8: 0 | GJ8: 0 | GK8: 0 | GL8: 0 | GM8: 0 | GN8: 0 | GO8: 0 | GP8: 0 | GQ8: 0 | GR8: 0 | GS8: 0 | GT8: 0 | GU8: 0 | GV8: 0 | GW8: 0 | GX8: 0 | GY8: 0 | GZ8: 0 | HA8: 0 | HB8: 0 | HC8: 0 | HD8: 0 | HE8: 0 | HF8: 0 | HG8: 0 | HH8: 0
A9: 5 | B9: 2 | C9: 0 | D9: 0 | E9: 0 | F9: 0 | G9: 0 | H9: 0 | I9: 0 | J9: 0 | K9: 0 | L9: 0 | M9: 0 | N9: 0 | O9: 0 | P9: 0 | Q9: 0 | R9: 0 | S9: 0 | T9: 0 | U9: 0 | V9: 0 | W9: 0 | X9: 0 | Y9: 0 | Z9: 0 | AA9: 0 | AB9: 0 | AC9: 0 | AD9: 0 | AE9: 0 | AF9: 0 | AG9: 0 | AH9: 0 | AI9: 0 | AJ9: 0 | AK9: 0 | AL9: 0 | AM9: 0 | AN9: 0 | AO9: 0 | AP9: 0 | AQ9: 0 | AR9: 0 | AS9: 0 | AT9: 0 | AU9: 0 | AV9: 0 | AW9: 0 | AX9: 0 | AY9: 0 | AZ9: 0 | BA9: 0 | BB9: 0 | BC9: 0 | BD9: 0 | BE9: 0 | BF9: 0 | BG9: 0 | BH9: 0 | BI9: 0 | BJ9: 0 | BK9: 0 | BL9: 0 | BM9: 0 | BN9: 0 | BO9: 0 | BP9: 0 | BQ9: 0 | BR9: 0 | BS9: 0 | BT9: 0 | BU9: 0 | BV9: 0 | BW9: 0 | BX9: 0 | BY9: 0 | BZ9: 0 | CA9: 0 | CB9: 0 | CC9: 0 | CD9: 0 | CE9: 0 | CF9: 0 | CG9: 0 | CH9: 0 | CI9: 0 | CJ9: 0 | CK9: 0 | CL9: 0 | CM9: 0 | CN9: 0 | CO9: 0 | CP9: 0 | CQ9: 0 | CR9: 0 | CS9: 0 | CT9: 0 | CU9: 0 | CV9: 0 | CW9: 0 | CX9: 0 | CY9: 0 | CZ9: 0 | DA9: 0 | DB9: 0 | DC9: 0 | DD9: 0 | DE9: 0 | DF9: 0 | DG9: 0 | DH9: 0 | DI9: 0 | DJ9: 0 | DK9: 0 | DL9: 0 | DM9: 0 | DN9: 0 | DO9: 0 | DP9: 0 | DQ9: 0 | DR9: 0 | DS9: 0 | DT9: 0 | DU9: 0 | DV9: 0 | DW9: 0 | DX9: 0 | DY9: 0 | DZ9: 0 | EA9: 0 | EB9: 0 | EC9: 0 | ED9: 0 | EE9: 0 | EF9: 0 | EG9: 0 | EH9: 0 | EI9: 0 | EJ9: 0 | EK9: 0 | EL9: 0 | EM9: 0 | EN9: 0 | EO9: 0 | EP9: 0 | EQ9: 0 | ER9: 0 | ES9: 0 | ET9: 0 | EU9: 0 | EV9: 0 | EW9: 0 | EX9: 0 | EY9: 0 | EZ9: 0 | FA9: 0 | FB9: 0 | FC9: 0 | FD9: 0 | FE9: 0 | FF9: 0 | FG9: 0 | FH9: 0 | FI9: 0 | FJ9: 0 | FK9: 0 | FL9: 0 | FM9: 0 | FN9: 0 | FO9: 0 | FP9: 0 | FQ9: 0 | FR9: 0 | FS9: 0 | FT9: 0 | FU9: 0 | FV9: 0 | FW9: 0 | FX9: 0 | FY9: 0 | FZ9: 0 | GA9: 0 | GB9: 0 | GC9: 0 | GD9: 0 | GE9: 0 | GF9: 0 | GG9: 0 | GH9: 0 | GI9: 0 | GJ9: 0 | GK9: 0 | GL9: 0 | GM9: 0 | GN9: 0 | GO9: 0 | GP9: 0 | GQ9: 0 | GR9: 0 | GS9: 0 | GT9: 0 | GU9: 0 | GV9: 0 | GW9: 0 | GX9: 0 | GY9: 0 | GZ9: 0 | HA9: 0 | HB9: 0 | HC9: 0 | HD9: 0 | HE9: 0 | HF9: 0 | HG9: 0 | HH9: 0
A10: 6 | B10: 2.5 | C10: 0 | D10: 0 | E10: 0 | F10: 0 | G10: 0 | H10: 0 | I10: 0 | J10: 0 | K10: 0 | L10: 0 | M10: 0 | N10: 0 | O10: 0 | P10: 0 | Q10: 0 | R10: 0 | S10: 0 | T10: 0 | U10: 0 | V10: 0 | W10: 0 | X10: 0 | Y10: 0 | Z10: 0 | AA10: 0 | AB10: 0 | AC10: 0 | AD10: 0 | AE10: 0 | AF10: 0 | AG10: 0 | AH10: 0 | AI10: 0 | AJ10: 0 | AK10: 0 | AL10: 0 | AM10: 0 | AN10: 0 | AO10: 0 | AP10: 0 | AQ10: 0 | AR10: 0 | AS10: 0 | AT10: 0 | AU10: 0 | AV10: 0 | AW10: 0 | AX10: 0 | AY10: 0 | AZ10: 0 | BA10: 0 | BB10: 0 | BC10: 0 | BD10: 0 | BE10: 0 | BF10: 0 | BG10: 0 | BH10: 0 | BI10: 0 | BJ10: 0 | BK10: 0 | BL10: 0 | BM10: 0 | BN10: 0 | BO10: 0 | BP10: 0 | BQ10: 0 | BR10: 0 | BS10: 0 | BT10: 0 | BU10: 0 | BV10: 0 | BW10: 0 | BX10: 0 | BY10: 0 | BZ10: 0 | CA10: 0 | CB10: 0 | CC10: 0 | CD10: 0 | CE10: 0 | CF10: 0 | CG10: 0 | CH10: 0 | CI10: 0 | CJ10: 0 | CK10: 0 | CL10: 0 | CM10: 0 | CN10: 0 | CO10: 0 | CP10: 0 | CQ10: 0 | CR10: 0 | CS10: 0 | CT10: 0 | CU10: 0 | CV10: 0 | CW10: 0 | CX10: 0 | CY10: 0 | CZ10: 0 | DA10: 0 | DB10: 0 | DC10: 0 | DD10: 0 | DE10: 0 | DF10: 0 | DG10: 0 | DH10: 0 | DI10: 0 | DJ10: 0 | DK10: 0 | DL10: 0 | DM10: 0 | DN10: 0 | DO10: 0 | DP10: 0 | DQ10: 0 | DR10: 0 | DS10: 0 | DT10: 0 | DU10: 0 | DV10: 0 | DW10: 0 | DX10: 0 | DY10: 0 | DZ10: 0 | EA10: 0 | EB10: 0 | EC10: 0 | ED10: 0 | EE10: 0 | EF10: 0 | EG10: 0 | EH10: 0 | EI10: 0 | EJ10: 0 | EK10: 0 | EL10: 0 | EM10: 0 | EN10: 0 | EO10: 0 | EP10: 0 | EQ10: 0 | ER10: 0 | ES10: 0 | ET10: 0 | EU10: 0 | EV10: 0 | EW10: 0 | EX10: 0 | EY10: 0 | EZ10: 0 | FA10: 0 | FB10: 0 | FC10: 0 | FD10: 0 | FE10: 0 | FF10: 0 | FG10: 0 | FH10: 0 | FI10: 0 | FJ10: 0 | FK10: 0 | FL10: 0 | FM10: 0 | FN10: 0 | FO10: 0 | FP10: 0 | FQ10: 0 | FR10: 0 | FS10: 0 | FT10: 0 | FU10: 0 | FV10: 0 | FW10: 0 | FX10: 0 | FY10: 0 | FZ10: 0 | GA10: 0 | GB10: 0 | GC10: 0 | GD10: 0 | GE10: 0 | GF10: 0 | GG10: 0 | GH10: 0 | GI10: 0 | GJ10: 0 | GK10: 0 | GL10: 0 | GM10: 0 | GN10: 0 | GO10: 0 | GP10: 0 | GQ10: 0 | GR10: 0 | GS10: 0 | GT10: 0 | GU10: 0 | GV10: 0 | GW10: 0 | GX10: 0 | GY10: 0 | GZ10: 0 | HA10: 0 | HB10: 0 | HC10: 0 | HD10: 0 | HE10: 0 | HF10: 0 | HG10: 0 | HH10: 0
A11: 7 | B11: 3 | C11: 0 | D11: 0 | E11: 0 | F11: 0 | G11: 0 | H11: 0 | I11: 0 | J11: 0 | K11: 0 | L11: 0 | M11: 0 | N11: 0 | O11: 0 | P11: 0 | Q11: 0 | R11: 0 | S11: 0 | T11: 0 | U11: 0 | V11: 0 | W11: 0 | X11: 0 | Y11: 0 | Z11: 0 | AA11: 0 | AB11: 0 | AC11: 0 | AD11: 0 | AE11: 0 | AF11: 0 | AG11: 0 | AH11: 0 | AI11: 0 | AJ11: 0 | AK11: 0 | AL11: 0 | AM11: 0 | AN11: 0 | AO11: 0 | AP11: 0 | AQ11: 0 | AR11: 0 | AS11: 0 | AT11: 0 | AU11: 0 | AV11: 0 | AW11: 0 | AX11: 0 | AY11: 0 | AZ11: 0 | BA11: 0 | BB11: 0 | BC11: 0 | BD11: 0 | BE11: 0 | BF11: 0 | BG11: 0 | BH11: 0 | BI11: 0 | BJ11: 0 | BK11: 0 | BL11: 0 | BM11: 0 | BN11: 0 | BO11: 0 | BP11: 0 | BQ11: 0 | BR11: 0 | BS11: 0 | BT11: 0 | BU11: 0 | BV11: 0 | BW11: 0 | BX11: 0 | BY11: 0 | BZ11: 0 | CA11: 0 | CB11: 0 | CC11: 0 | CD11: 0 | CE11: 0 | CF11: 0 | CG11: 0 | CH11: 0 | CI11: 0 | CJ11: 0 | CK11: 0 | CL11: 0 | CM11: 0 | CN11: 0 | CO11: 0 | CP11: 0 | CQ11: 0 | CR11: 0 | CS11: 0 | CT11: 0 | CU11: 0 | CV11: 0 | CW11: 0 | CX11: 0 | CY11: 0 | CZ11: 0 | DA11: 0 | DB11: 0 | DC11: 0 | DD11: 0 | DE11: 0 | DF11: 0 | DG11: 0 | DH11: 0 | DI11: 0 | DJ11: 0 | DK11: 0 | DL11: 0 | DM11: 0 | DN11: 0 | DO11: 0 | DP11: 0 | DQ11: 0 | DR11: 0 | DS11: 0 | DT11: 0 | DU11: 0 | DV11: 0 | DW11: 0 | DX11: 0 | DY11: 0 | DZ11: 0 | EA11: 0 | EB11: 0 | EC11: 0 | ED11: 0 | EE11: 0 | EF11: 0 | EG11: 0 | EH11: 0 | EI11: 0 | EJ11: 0 | EK11: 0 | EL11: 0 | EM11: 0 | EN11: 0 | EO11: 0 | EP11: 0 | EQ11: 0 | ER11: 0 | ES11: 0 | ET11: 0 | EU11: 0 | EV11: 0 | EW11: 0 | EX11: 0 | EY11: 0 | EZ11: 0 | FA11: 0 | FB11: 0 | FC11: 0 | FD11: 0 | FE11: 0 | FF11: 0 | FG11: 0 | FH11: 0 | FI11: 0 | FJ11: 0 | FK11: 0 | FL11: 0 | FM11: 0 | FN11: 0 | FO11: 0 | FP11: 0 | FQ11: 0 | FR11: 0 | FS11: 0 | FT11: 0 | FU11: 0 | FV11: 0 | FW11: 0 | FX11: 0 | FY11: 0 | FZ11: 0 | GA11: 0 | GB11: 0 | GC11: 0 | GD11: 0 | GE11: 0 | GF11: 0 | GG11: 0 | GH11: 0 | GI11: 0 | GJ11: 0 | GK11: 0 | GL11: 0 | GM11: 0 | GN11: 0 | GO11: 0 | GP11: 0 | GQ11: 0 | GR11: 0 | GS11: 0 | GT11: 0 | GU11: 0 | GV11: 0 | GW11: 0 | GX11: 0 | GY11: 0 | GZ11: 0 | HA11: 0 | HB11: 0 | HC11: 0 | HD11: 0 | HE11: 0 | HF11: 0 | HG11: 0 | HH11: 0
A12: 8 | B12: 3.5 | C12: 0 | D12: 0 | E12: 0 | F12: 0 | G12: 0 | H12: 0 | I12: 0 | J12: 0 | K12: 0 | L12: 0 | M12: 0 | N12: 0 | O12: 0 | P12: 0 | Q12: 0 | R12: 0 | S12: 0 | T12: 0 | U12: 0 | V12: 0 | W12: 0 | X12: 0 | Y12: 0 | Z12: 0 | AA12: 0 | AB12: 0 | AC12: 0 | AD12: 0 | AE12: 0 | AF12: 0 | AG12: 0 | AH12: 0 | AI12: 0 | AJ12: 0 | AK12: 0 | AL12: 0 | AM12: 0 | AN12: 0 | AO12: 0 | AP12: 0 | AQ12: 0 | AR12: 0 | AS12: 0 | AT12: 0 | AU12: 0 | AV12: 0 | AW12: 0 | AX12: 0 | AY12: 0 | AZ12: 0 | BA12: 0 | BB12: 0 | BC12: 0 | BD12: 0 | BE12: 0 | BF12: 0 | BG12: 0 | BH12: 0 | BI12: 0 | BJ12: 0 | BK12: 0 | BL12: 0 | BM12: 0 | BN12: 0 | BO12: 0 | BP12: 0 | BQ12: 0 | BR12: 0 | BS12: 0 | BT12: 0 | BU12: 0 | BV12: 0 | BW12: 0 | BX12: 0 | BY12: 0 | BZ12: 0 | CA12: 0 | CB12: 0 | CC12: 0 | CD12: 0 | CE12: 0 | CF12: 0 | CG12: 0 | CH12: 0 | CI12: 0 | CJ12: 0 | CK12: 0 | CL12: 0 | CM12: 0 | CN12: 0 | CO12: 0 | CP12: 0 | CQ12: 0 | CR12: 0 | CS12: 0 | CT12: 0 | CU12: 0 | CV12: 0 | CW12: 0 | CX12: 0 | CY12: 0 | CZ12: 0 | DA12: 0 | DB12: 0 | DC12: 0 | DD12: 0 | DE12: 0 | DF12: 0 | DG12: 0 | DH12: 0 | DI12: 0 | DJ12: 0 | DK12: 0 | DL12: 0 | DM12: 0 | DN12: 0 | DO12: 0 | DP12: 0 | DQ12: 0 | DR12: 0 | DS12: 0 | DT12: 0 | DU12: 0 | DV12: 0 | DW12: 0 | DX12: 0 | DY12: 0 | DZ12: 0 | EA12: 0 | EB12: 0 | EC12: 0 | ED12: 0 | EE12: 0 | EF12: 0 | EG12: 0 | EH12: 0 | EI12: 0 | EJ12: 0 | EK12: 0 | EL12: 0 | EM12: 0 | EN12: 0 | EO12: 0 | EP12: 0 | EQ12: 0 | ER12: 0 | ES12: 0 | ET12: 0 | EU12: 0 | EV12: 0 | EW12: 0 | EX12: 0 | EY12: 0 | EZ12: 0 | FA12: 0 | FB12: 0 | FC12: 0 | FD12: 0 | FE12: 0 | FF12: 0 | FG12: 0 | FH12: 0 | FI12: 0 | FJ12: 0 | FK12: 0 | FL12: 0 | FM12: 0 | FN12: 0 | FO12: 0 | FP12: 0 | FQ12: 0 | FR12: 0 | FS12: 0 | FT12: 0 | FU12: 0 | FV12: 0 | FW12: 0 | FX12: 0 | FY12: 0 | FZ12: 0 | GA12: 0 | GB12: 0 | GC12: 0 | GD12: 0 | GE12: 0 | GF12: 0 | GG12: 0 | GH12: 0 | GI12: 0 | GJ12: 0 | GK12: 0 | GL12: 0 | GM12: 0 | GN12: 0 | GO12: 0 | GP12: 0 | GQ12: 0 | GR12: 0 | GS12: 0 | GT12: 0 | GU12: 0 | GV12: 0 | GW12: 0 | GX12: 0 | GY12: 0 | GZ12: 0 | HA12: 0 | HB12: 0 | HC12: 0 | HD12: 0 | HE12: 0 | HF12: 0 | HG12: 0 | HH12: 0
A13: 9 | B13: 4 | C13: 0 | D13: 0 | E13: 0.002 | F13: 0 | G13: 0 | H13: 0 | I13: 0 | J13: 0 | K13: 0 | L13: 0 | M13: 0 | N13: 0 | O13: 0 | P13: 0 | Q13: 0 | R13: 0.014 | S13: 0 | T13: 0 | U13: 0 | V13: 0 | W13: 0 | X13: 0 | Y13: 0 | Z13: 0 | AA13: 0 | AB13: 0 | AC13: 0 | AD13: 0 | AE13: 0 | AF13: 0 | AG13: 0.006 | AH13: 0 | AI13: 0 | AJ13: 0 | AK13: 0 | AL13: 0 | AM13: 0.001 | AN13: 0.008 | AO13: 0 | AP13: 0 | AQ13: 0 | AR13: 0 | AS13: 0 | AT13: 0 | AU13: 0 | AV13: 0 | AW13: 0 | AX13: 0 | AY13: 0 | AZ13: 0 | BA13: 0 | BB13: 0 | BC13: 0 | BD13: 0 | BE13: 0 | BF13: 0 | BG13: 0 | BH13: 0 | BI13: 0 | BJ13: 0 | BK13: 0 | BL13: 0 | BM13: 0 | BN13: 0 | BO13: 0 | BP13: 0 | BQ13: 0 | BR13: 0 | BS13: 0 | BT13: 0 | BU13: 0 | BV13: 0.006 | BW13: 0 | BX13: 0 | BY13: 0 | BZ13: 0 | CA13: 0 | CB13: 0 | CC13: 0 | CD13: 0 | CE13: 0 | CF13: 0 | CG13: 0 | CH13: 0 | CI13: 0 | CJ13: 0 | CK13: 0 | CL13: 0 | CM13: 0 | CN13: 0 | CO13: 0 | CP13: 0 | CQ13: 0 | CR13: 0 | CS13: 0 | CT13: 0 | CU13: 0.002 | CV13: 0 | CW13: 0 | CX13: 0 | CY13: 0 | CZ13: 0 | DA13: 0 | DB13: 0 | DC13: 0 | DD13: 0 | DE13: 0 | DF13: 0 | DG13: 0 | DH13: 0 | DI13: 0 | DJ13: 0 | DK13: 0 | DL13: 0 | DM13: 0 | DN13: 0 | DO13: 0 | DP13: 0 | DQ13: 0 | DR13: 0 | DS13: 0 | DT13: 0 | DU13: 0 | DV13: 0 | DW13: 0 | DX13: 0 | DY13: 0 | DZ13: 0 | EA13: 0 | EB13: 0.004 | EC13: 0 | ED13: 0 | EE13: 0 | EF13: 0 | EG13: 0 | EH13: 0 | EI13: 0 | EJ13: 0 | EK13: 0 | EL13: 0 | EM13: 0 | EN13: 0 | EO13: 0.014 | EP13: 0 | EQ13: 0 | ER13: 0 | ES13: 0 | ET13: 0 | EU13: 0 | EV13: 0 | EW13: 0 | EX13: 0 | EY13: 0 | EZ13: 0 | FA13: 0 | FB13: 0 | FC13: 0 | FD13: 0 | FE13: 0 | FF13: 0 | FG13: 0 | FH13: 0 | FI13: 0 | FJ13: 0 | FK13: 0 | FL13: 0 | FM13: 0 | FN13: 0 | FO13: 0 | FP13: 0 | FQ13: 0 | FR13: 0 | FS13: 0 | FT13: 0 | FU13: 0 | FV13: 0 | FW13: 0 | FX13: 0 | FY13: 0 | FZ13: 0 | GA13: 0 | GB13: 0 | GC13: 0 | GD13: 0 | GE13: 0 | GF13: 0 | GG13: 0 | GH13: 0 | GI13: 0 | GJ13: 0 | GK13: 0 | GL13: 0 | GM13: 0 | GN13: 0 | GO13: 0 | GP13: 0 | GQ13: 0 | GR13: 0 | GS13: 0 | GT13: 0 | GU13: 0 | GV13: 0 | GW13: 0 | GX13: 0 | GY13: 0 | GZ13: 0.009 | HA13: 0 | HB13: 0 | HC13: 0 | HD13: 0 | HE13: 0 | HF13: 0 | HG13: 0.008 | HH13: 0
A14: 10 | B14: 4.5 | C14: 0 | D14: 0 | E14: 0 | F14: 0.057 | G14: 0.068 | H14: 0.05 | I14: 0.056 | J14: 0.039 | K14: 0 | L14: 0.04 | M14: 0.023 | N14: 0.127 | O14: 0.036 | P14: 0.182 | Q14: 0 | R14: 0.016 | S14: 0.143 | T14: 0.017 | U14: 0.093 | V14: 0 | W14: 0.093 | X14: 0.073 | Y14: 0.123 | Z14: 0.052 | AA14: 0.158 | AB14: 0.038 | AC14: 0.09 | AD14: 0.063 | AE14: 0 | AF14: 0.074 | AG14: 0.189 | AH14: 0.118 | AI14: 0.123 | AJ14: 0.035 | AK14: 0 | AL14: 0.182 | AM14: 0.184 | AN14: 0.145 | AO14: 0.09 | AP14: 0 | AQ14: 0.181 | AR14: 0.067 | AS14: 0.039 | AT14: 0 | AU14: 0.149 | AV14: 0.068 | AW14: 0.027 | AX14: 0.044 | AY14: 0 | AZ14: 0 | BA14: 0.087 | BB14: 0 | BC14: 0 | BD14: 0.153 | BE14: 0.185 | BF14: 0.028 | BG14: 0.007 | BH14: 0.027 | BI14: 0.049 | BJ14: 0.088 | BK14: 0.068 | BL14: 0 | BM14: 0 | BN14: 0.026 | BO14: 0 | BP14: 0.008 | BQ14: 0.011 | BR14: 0.176 | BS14: 0 | BT14: 0.088 | BU14: 0.032 | BV14: 0.189 | BW14: 0.01 | BX14: 0.086 | BY14: 0 | BZ14: 0.183 | CA14: 0.032 | CB14: 0.12 | CC14: 0.181 | CD14: 0.066 | CE14: 0.051 | CF14: 0.003 | CG14: 0.156 | CH14: 0.046 | CI14: 0.127 | CJ14: 0 | CK14: 0.002 | CL14: 0.12 | CM14: 0 | CN14: 0.091 | CO14: 0 | CP14: 0.121 | CQ14: 0 | CR14: 0.016 | CS14: 0.156 | CT14: 0.181 | CU14: 0.185 | CV14: 0 | CW14: 0 | CX14: 0.177 | CY14: 0.102 | CZ14: 0 | DA14: 0.005 | DB14: 0.02 | DC14: 0.069 | DD14: 0.044 | DE14: 0.086 | DF14: 0 | DG14: 0 | DH14: 0.003 | DI14: 0.073 | DJ14: 0.091 | DK14: 0.003 | DL14: 0 | DM14: 0 | DN14: 0.001 | DO14: 0 | DP14: 0.041 | DQ14: 0.157 | DR14: 0 | DS14: 0 | DT14: 0.004 | DU14: 0 | DV14: 0.023 | DW14: 0.03 | DX14: 0.104 | DY14: 0.085 | DZ14: 0 | EA14: 0.053 | EB14: 0.187 | EC14: 0 | ED14: 0.109 | EE14: 0 | EF14: 0.088 | EG14: 0.088 | EH14: 0.112 | EI14: 0 | EJ14: 0.156 | EK14: 0 | EL14: 0.034 | EM14: 0.014 | EN14: 0 | EO14: 0.054 | EP14: 0.066 | EQ14: 0.046 | ER14: 0.192 | ES14: 0.061 | ET14: 0.119 | EU14: 0 | EV14: 0 | EW14: 0.175 | EX14: 0.083 | EY14: 0.069 | EZ14: 0.102 | FA14: 0.02 | FB14: 0 | FC14: 0 | FD14: 0.124 | FE14: 0.177 | FF14: 0.064 | FG14: 0.176 | FH14: 0.079 | FI14: 0.183 | FJ14: 0.082 | FK14: 0 | FL14: 0.007 | FM14: 0 | FN14: 0.123 | FO14: 0.069 | FP14: 0.109 | FQ14: 0.008 | FR14: 0.089 | FS14: 0.064 | FT14: 0.086 | FU14: 0.022 | FV14: 0 | FW14: 0.116 | FX14: 0.09 | FY14: 0.038 | FZ14: 0.075 | GA14: 0.013 | GB14: 0.039 | GC14: 0.147 | GD14: 0.105 | GE14: 0.173 | GF14: 0 | GG14: 0 | GH14: 0.08 | GI14: 0.181 | GJ14: 0.07 | GK14: 0.015 | GL14: 0 | GM14: 0 | GN14: 0.185 | GO14: 0.058 | GP14: 0.116 | GQ14: 0.025 | GR14: 0.18 | GS14: 0 | GT14: 0.092 | GU14: 0.041 | GV14: 0.041 | GW14: 0.156 | GX14: 0.087 | GY14: 0.018 | GZ14: 0.032 | HA14: 0.081 | HB14: 0 | HC14: 0 | HD14: 0 | HE14: 0.012 | HF14: 0.084 | HG14: 0.161 | HH14: 0.125
A15: 11 | B15: 5 | C15: 0.236 | D15: 0.391 | E15: 0.413 | F15: 0.189 | G15: 0.183 | H15: 0.136 | I15: 0.209 | J15: 0.091 | K15: 0 | L15: 0.332 | M15: 0.288 | N15: 0.164 | O15: 0.122 | P15: 0.41 | Q15: 0.128 | R15: 0.43 | S15: 0.308 | T15: 0 | U15: 0.236 | V15: 0.27 | W15: 0.183 | X15: 0.023 | Y15: 0.295 | Z15: 0.291 | AA15: 0.358 | AB15: 0.124 | AC15: 0.233 | AD15: 0.034 | AE15: 0.369 | AF15: 0.344 | AG15: 0.417 | AH15: 0.29 | AI15: 0.168 | AJ15: 0.343 | AK15: 0 | AL15: 0.278 | AM15: 0.412 | AN15: 0.297 | AO15: 0.233 | AP15: 0.074 | AQ15: 0.257 | AR15: 0.184 | AS15: 0.087 | AT15: 0.408 | AU15: 0.349 | AV15: 0.37 | AW15: 0.199 | AX15: 0.158 | AY15: 0.156 | AZ15: 0.127 | BA15: 0.356 | BB15: 0.067 | BC15: 0 | BD15: 0.319 | BE15: 0.203 | BF15: 0.406 | BG15: 0.399 | BH15: 0.343 | BI15: 0.287 | BJ15: 0.231 | BK15: 0.183 | BL15: 0.12 | BM15: 0.216 | BN15: 0.082 | BO15: 0.118 | BP15: 0 | BQ15: 0.389 | BR15: 0.404 | BS15: 0.061 | BT15: 0.231 | BU15: 0.018 | BV15: 0.417 | BW15: 0.135 | BX15: 0.411 | BY15: 0.061 | BZ15: 0.411 | CA15: 0.09 | CB15: 0.252 | CC15: 0.409 | CD15: 0.181 | CE15: 0.218 | CF15: 0.18 | CG15: 0.281 | CH15: 0.29 | CI15: 0.192 | CJ15: 0.125 | CK15: 0.29 | CL15: 0.209 | CM15: 0.101 | CN15: 0.306 | CO15: 0 | CP15: 0.19 | CQ15: 0.352 | CR15: 0 | CS15: 0.349 | CT15: 0.261 | CU15: 0.413 | CV15: 0.417 | CW15: 0.124 | CX15: 0.405 | CY15: 0.148 | CZ15: 0.268 | DA15: 0.295 | DB15: 0.239 | DC15: 0.316 | DD15: 0 | DE15: 0.353 | DF15: 0 | DG15: 0.235 | DH15: 0.387 | DI15: 0.355 | DJ15: 0.115 | DK15: 0.226 | DL15: 0.177 | DM15: 0.41 | DN15: 0.209 | DO15: 0.057 | DP15: 0.296 | DQ15: 0.287 | DR15: 0.176 | DS15: 0.296 | DT15: 0.385 | DU15: 0 | DV15: 0 | DW15: 0.412 | DX15: 0.144 | DY15: 0.256 | DZ15: 0 | EA15: 0.18 | EB15: 0.415 | EC15: 0.256 | ED15: 0.241 | EE15: 0.346 | EF15: 0.303 | EG15: 0.421 | EH15: 0.409 | EI15: 0.226 | EJ15: 0.356 | EK15: 0.086 | EL15: 0.353 | EM15: 0.006 | EN15: 0.111 | EO15: 0.419 | EP15: 0.162 | EQ15: 0.132 | ER15: 0.307 | ES15: 0.176 | ET15: 0.298 | EU15: 0.281 | EV15: 0.152 | EW15: 0.261 | EX15: 0.23 | EY15: 0.178 | EZ15: 0.29 | FA15: 0.061 | FB15: 0.082 | FC15: 0.342 | FD15: 0.081 | FE15: 0.405 | FF15: 0.179 | FG15: 0.257 | FH15: 0.194 | FI15: 0.368 | FJ15: 0.297 | FK15: 0.29 | FL15: 0.21 | FM15: 0.149 | FN15: 0.173 | FO15: 0 | FP15: 0.252 | FQ15: 0.296 | FR15: 0.232 | FS15: 0 | FT15: 0.229 | FU15: 0.061 | FV15: 0 | FW15: 0.288 | FX15: 0.356 | FY15: 0.044 | FZ15: 0.351 | GA15: 0.169 | GB15: 0.414 | GC15: 0.241 | GD15: 0.189 | GE15: 0.401 | GF15: 0.018 | GG15: 0.086 | GH15: 0.237 | GI15: 0.409 | GJ15: 0.017 | GK15: 0.086 | GL15: 0.16 | GM15: 0.054 | GN15: 0.413 | GO15: 0.403 | GP15: 0.23 | GQ15: 0.31 | GR15: 0.408 | GS15: 0.182 | GT15: 0.235 | GU15: 0.195 | GV15: 0.241 | GW15: 0.154 | GX15: 0.258 | GY15: 0.22 | GZ15: 0.42 | HA15: 0.242 | HB15: 0.158 | HC15: 0.156 | HD15: 0.393 | HE15: 0.189 | HF15: 0.356 | HG15: 0.218 | HH15: 0.297
A16: 12 | B16: 5.5 | C16: 0.412 | D16: 0.592 | E16: 0.579 | F16: 0.19 | G16: 0.323 | H16: 0.241 | I16: 0.347 | J16: 0.154 | K16: 0 | L16: 0.687 | M16: 0.503 | N16: 0.509 | O16: 0.227 | P16: 0.691 | Q16: 0 | R16: 0.595 | S16: 0.562 | T16: 0.231 | U16: 0.272 | V16: 0.501 | W16: 0.332 | X16: 0.232 | Y16: 0.362 | Z16: 0.476 | AA16: 0.603 | AB16: 0.229 | AC16: 0.409 | AD16: 0.311 | AE16: 0.596 | AF16: 0.554 | AG16: 0.698 | AH16: 0.5 | AI16: 0.572 | AJ16: 0.634 | AK16: 0.106 | AL16: 0.691 | AM16: 0.693 | AN16: 0.7 | AO16: 0.409 | AP16: 0.229 | AQ16: 0.589 | AR16: 0.19 | AS16: 0.153 | AT16: 0.511 | AU16: 0.594 | AV16: 0.573 | AW16: 0.497 | AX16: 0.17 | AY16: 0.192 | AZ16: 0.351 | BA16: 0.601 | BB16: 0.327 | BC16: 0.124 | BD16: 0.556 | BE16: 0.62 | BF16: 0.687 | BG16: 0.639 | BH16: 0.639 | BI16: 0.497 | BJ16: 0.407 | BK16: 0.323 | BL16: 0.23 | BM16: 0.693 | BN16: 0.042 | BO16: 0.122 | BP16: 0.226 | BQ16: 0.565 | BR16: 0.685 | BS16: 0.252 | BT16: 0.407 | BU16: 0.223 | BV16: 0.582 | BW16: 0.321 | BX16: 0.671 | BY16: 0.129 | BZ16: 0.611 | CA16: 0.291 | CB16: 0.453 | CC16: 0.69 | CD16: 0.172 | CE16: 0.406 | CF16: 0.07 | CG16: 0.662 | CH16: 0.605 | CI16: 0.322 | CJ16: 0.073 | CK16: 0.492 | CL16: 0.458 | CM16: 0.216 | CN16: 0.597 | CO16: 0.077 | CP16: 0.444 | CQ16: 0.597 | CR16: 0.029 | CS16: 0.6 | CT16: 0.69 | CU16: 0.694 | CV16: 0.585 | CW16: 0.04 | CX16: 0.686 | CY16: 0.489 | CZ16: 0.549 | DA16: 0.353 | DB16: 0.415 | DC16: 0.51 | DD16: 0.149 | DE16: 0.692 | DF16: 0.148 | DG16: 0.503 | DH16: 0.393 | DI16: 0.6 | DJ16: 0.505 | DK16: 0.257 | DL16: 0.27 | DM16: 0.659 | DN16: 0.372 | DO16: 0.414 | DP16: 0.442 | DQ16: 0.422 | DR16: 0.138 | DS16: 0.448 | DT16: 0.52 | DU16: 0.23 | DV16: 0.227 | DW16: 0.597 | DX16: 0.375 | DY16: 0.597 | DZ16: 0.143 | EA16: 0.448 | EB16: 0.696 | EC16: 0.511 | ED16: 0.596 | EE16: 0.584 | EF16: 0.593 | EG16: 0.499 | EH16: 0.587 | EI16: 0.496 | EJ16: 0.439 | EK16: 0.14 | EL16: 0.52 | EM16: 0.375 | EN16: 0.326 | EO16: 0.611 | EP16: 0.205 | EQ16: 0.237 | ER16: 0.676 | ES16: 0.068 | ET16: 0.632 | EU16: 0.266 | EV16: 0.506 | EW16: 0.613 | EX16: 0.406 | EY16: 0.326 | EZ16: 0.46 | FA16: 0.228 | FB16: 0.299 | FC16: 0.505 | FD16: 0.506 | FE16: 0.686 | FF16: 0.319 | FG16: 0.684 | FH16: 0.334 | FI16: 0.566 | FJ16: 0.42 | FK16: 0.264 | FL16: 0.145 | FM16: 0.411 | FN16: 0.448 | FO16: 0 | FP16: 0.428 | FQ16: 0.372 | FR16: 0.356 | FS16: 0.344 | FT16: 0.405 | FU16: 0.244 | FV16: 0.133 | FW16: 0.498 | FX16: 0.355 | FY16: 0.195 | FZ16: 0.526 | GA16: 0.397 | GB16: 0.6 | GC16: 0.587 | GD16: 0.4 | GE16: 0.574 | GF16: 0.039 | GG16: 0.321 | GH16: 0.413 | GI16: 0.69 | GJ16: 0.316 | GK16: 0.32 | GL16: 0.137 | GM16: 0.235 | GN16: 0.525 | GO16: 0.616 | GP16: 0.605 | GQ16: 0.343 | GR16: 0.566 | GS16: 0.602 | GT16: 0.411 | GU16: 0.322 | GV16: 0.365 | GW16: 0.693 | GX16: 0.499 | GY16: 0.5 | GZ16: 0.607 | HA16: 0.509 | HB16: 0.455 | HC16: 0.241 | HD16: 0.44 | HE16: 0.364 | HF16: 0.528 | HG16: 0.7 | HH16: 0.507
... A52: 48 | B52: 23.5 | C52: 0 | D52: 0 | E52: 0 | F52: 0 | G52: 0 | H52: 0 | I52: 0 | J52: 0 | K52: 0 | L52: 0 | M52: 0 | N52: 0 | O52: 0 | P52: 0 | Q52: 0 | R52: 0 | S52: 0 | T52: 0 | U52: 0 | V52: 0 | W52: 0 | X52: 0 | Y52: 0 | Z52: 0 | AA52: 0 | AB52: 0 | AC52: 0 | AD52: 0 | AE52: 0 | AF52: 0 | AG52: 0 | AH52: 0 | AI52: 0 | AJ52: 0 | AK52: 0 | AL52: 0 | AM52: 0 | AN52: 0 | AO52: 0 | AP52: 0 | AQ52: 0 | AR52: 0 | AS52: 0 | AT52: 0 | AU52: 0 | AV52: 0 | AW52: 0 | AX52: 0 | AY52: 0 | AZ52: 0 | BA52: 0 | BB52: 0 | BC52: 0 | BD52: 0 | BE52: 0 | BF52: 0 | BG52: 0 | BH52: 0 | BI52: 0 | BJ52: 0 | BK52: 0 | BL52: 0 | BM52: 0 | BN52: 0 | BO52: 0 | BP52: 0 | BQ52: 0 | BR52: 0 | BS52: 0 | BT52: 0 | BU52: 0 | BV52: 0 | BW52: 0 | BX52: 0 | BY52: 0 | BZ52: 0 | CA52: 0 | CB52: 0 | CC52: 0 | CD52: 0 | CE52: 0 | CF52: 0 | CG52: 0 | CH52: 0 | CI52: 0 | CJ52: 0 | CK52: 0 | CL52: 0 | CM52: 0 | CN52: 0 | CO52: 0 | CP52: 0 | CQ52: 0 | CR52: 0 | CS52: 0 | CT52: 0 | CU52: 0 | CV52: 0 | CW52: 0 | CX52: 0 | CY52: 0 | CZ52: 0 | DA52: 0 | DB52: 0 | DC52: 0 | DD52: 0 | DE52: 0 | DF52: 0 | DG52: 0 | DH52: 0 | DI52: 0 | DJ52: 0 | DK52: 0 | DL52: 0 | DM52: 0 | DN52: 0 | DO52: 0 | DP52: 0 | DQ52: 0 | DR52: 0 | DS52: 0 | DT52: 0 | DU52: 0 | DV52: 0 | DW52: 0 | DX52: 0 | DY52: 0 | DZ52: 0 | EA52: 0 | EB52: 0 | EC52: 0 | ED52: 0 | EE52: 0 | EF52: 0 | EG52: 0 | EH52: 0 | EI52: 0 | EJ52: 0 | EK52: 0 | EL52: 0 | EM52: 0 | EN52: 0 | EO52: 0 | EP52: 0 | EQ52: 0 | ER52: 0 | ES52: 0 | ET52: 0 | EU52: 0 | EV52: 0 | EW52: 0 | EX52: 0 | EY52: 0 | EZ52: 0 | FA52: 0 | FB52: 0 | FC52: 0 | FD52: 0 | FE52: 0 | FF52: 0 | FG52: 0 | FH52: 0 | FI52: 0 | FJ52: 0 | FK52: 0 | FL52: 0 | FM52: 0 | FN52: 0 | FO52: 0 | FP52: 0 | FQ52: 0 | FR52: 0 | FS52: 0 | FT52: 0 | FU52: 0 | FV52: 0 | FW52: 0 | FX52: 0 | FY52: 0 | FZ52: 0 | GA52: 0 | GB52: 0 | GC52: 0 | GD52: 0 | GE52: 0 | GF52: 0 | GG52: 0 | GH52: 0 | GI52: 0 | GJ52: 0 | GK52: 0 | GL52: 0 | GM52: 0 | GN52: 0 | GO52: 0 | GP52: 0 | GQ52: 0 | GR52: 0 | GS52: 0 | GT52: 0 | GU52: 0 | GV52: 0 | GW52: 0 | GX52: 0 | GY52: 0 | GZ52: 0 | HA52: 0 | HB52: 0 | HC52: 0 | HD52: 0 | HE52: 0 | HF52: 0 | HG52: 0 | HH52: 0

Sheet 6. Raw batt discharge
A1: Raw batt discharge
A2: Verbatim copy of Discharge_kW (TR5_analysis_data.xlsx). One row per half-hour, one column per battery (kW).
