Workbook

Sheet ReadMe
A1: README
A2: Data behind the TR1 rolling-dispatch figures (SOC, demand/PV/dispatch, net, self-consumption, metrics histogram).
A3: Each quantity sheet: rows = 48 half-hour periods (with hour of day), columns = prosumers, plus fleet_average / fleet_total.
A4: Dispatch is the committed slot-1 execution of the rolling horizon (self-consumption baseline, Term 2 + Term 3).
A5: SOC is the realised state at the START of each step (fraction of capacity).
A6: net_kW = (demand - PV) + (charge - discharge); positive = import, negative = export.
A7: Regenerate: python build_workbook.py --force (see README.md for other transformers).

Sheet Summary
A1: quantity | B1: value
A2: run | B2: TR1 exact-QCP rolling (FOR_PolyS=0, FOR_LinearizeVmax=0), 48 steps, all Optimal
A3: source dispatch | B3: FOR_rolling_soc_TR1.csv
A4: source load/PV | B4: TR1_load_PV_48periods.xlsx
A5: prosumers | B5: 77
A6: PV generated kWh/day | B6: 1797
A7: demand kWh/day | B7: 572.8
A8: exported kWh/day | B8: 1201.3
A9: imported kWh/day | B9: 22.6
A10: SCR % (PV used locally) | B10: 33.1
A11: SSR % (demand met locally) | B11: 96
A12: prosumer-periods |net|<50W % | B12: 58.2
A13: SOC min/max over day | B13: 0.10 / 1.00
A14: simultaneous chg+dis rows | B14: 0

Sheet FleetAverage
A1: period | B1: hour | C1: demand_avg_kW | D1: PV_avg_kW | E1: charge_avg_kW | F1: discharge_avg_kW | G1: net_avg_kW | H1: SOC_avg_pct | I1: demand_total_kW | J1: PV_total_kW | K1: net_total_kW
A2: =Demand_kW!A2 -> 1 | B2: =Demand_kW!B2 -> 0 | C2: =AVERAGE(Demand_kW!$C2:$CA2) -> 0.27365084 | D2: =AVERAGE(PV_kW!$C2:$CA2) -> 0 | E2: =AVERAGE(Charge_kW!$C2:$CA2) -> 0 | F2: =AVERAGE(Discharge_kW!$C2:$CA2) -> 0.27302597 | G2: =C2-D2+E2-F2 -> 0.00062486364 | H2: =AVERAGE(SOC_pct!$C2:$CA2) -> 40 | I2: =SUM(Demand_kW!$C2:$CA2) -> 21.071115 | J2: =SUM(PV_kW!$C2:$CA2) -> 0 | K2: =I2-J2+SUM(Charge_kW!$C2:$CA2)-SUM(Discharge_kW!$C2:$CA2) -> 0.0481145
A3: =Demand_kW!A3 -> 2 | B3: =Demand_kW!B3 -> 0.5 | C3: =AVERAGE(Demand_kW!$C3:$CA3) -> 0.17791698 | D3: =AVERAGE(PV_kW!$C3:$CA3) -> 0 | E3: =AVERAGE(Charge_kW!$C3:$CA3) -> 0 | F3: =AVERAGE(Discharge_kW!$C3:$CA3) -> 0.176 | G3: =C3-D3+E3-F3 -> 0.0019169775 | H3: =AVERAGE(SOC_pct!$C3:$CA3) -> 36.573881 | I3: =SUM(Demand_kW!$C3:$CA3) -> 13.699607 | J3: =SUM(PV_kW!$C3:$CA3) -> 0 | K3: =I3-J3+SUM(Charge_kW!$C3:$CA3)-SUM(Discharge_kW!$C3:$CA3) -> 0.14760727
A4: =Demand_kW!A4 -> 3 | B4: =Demand_kW!B4 -> 1 | C4: =AVERAGE(Demand_kW!$C4:$CA4) -> 0.1257483 | D4: =AVERAGE(PV_kW!$C4:$CA4) -> 0 | E4: =AVERAGE(Charge_kW!$C4:$CA4) -> 0 | F4: =AVERAGE(Discharge_kW!$C4:$CA4) -> 0.12401299 | G4: =C4-D4+E4-F4 -> 0.0017353117 | H4: =AVERAGE(SOC_pct!$C4:$CA4) -> 34.364817 | I4: =SUM(Demand_kW!$C4:$CA4) -> 9.682619 | J4: =SUM(PV_kW!$C4:$CA4) -> 0 | K4: =I4-J4+SUM(Charge_kW!$C4:$CA4)-SUM(Discharge_kW!$C4:$CA4) -> 0.133619
A5: =Demand_kW!A5 -> 4 | B5: =Demand_kW!B5 -> 1.5 | C5: =AVERAGE(Demand_kW!$C5:$CA5) -> 0.14186491 | D5: =AVERAGE(PV_kW!$C5:$CA5) -> 0 | E5: =AVERAGE(Charge_kW!$C5:$CA5) -> 0 | F5: =AVERAGE(Discharge_kW!$C5:$CA5) -> 0.13924675 | G5: =C5-D5+E5-F5 -> 0.002618155 | H5: =AVERAGE(SOC_pct!$C5:$CA5) -> 32.808425 | I5: =SUM(Demand_kW!$C5:$CA5) -> 10.923598 | J5: =SUM(PV_kW!$C5:$CA5) -> 0 | K5: =I5-J5+SUM(Charge_kW!$C5:$CA5)-SUM(Discharge_kW!$C5:$CA5) -> 0.20159793
A6: =Demand_kW!A6 -> 5 | B6: =Demand_kW!B6 -> 2 | C6: =AVERAGE(Demand_kW!$C6:$CA6) -> 0.10638473 | D6: =AVERAGE(PV_kW!$C6:$CA6) -> 0 | E6: =AVERAGE(Charge_kW!$C6:$CA6) -> 0 | F6: =AVERAGE(Discharge_kW!$C6:$CA6) -> 0.10158442 | G6: =C6-D6+E6-F6 -> 0.004800316 | H6: =AVERAGE(SOC_pct!$C6:$CA6) -> 31.061217 | I6: =SUM(Demand_kW!$C6:$CA6) -> 8.1916243 | J6: =SUM(PV_kW!$C6:$CA6) -> 0 | K6: =I6-J6+SUM(Charge_kW!$C6:$CA6)-SUM(Discharge_kW!$C6:$CA6) -> 0.36962433
A7: =Demand_kW!A7 -> 6 | B7: =Demand_kW!B7 -> 2.5 | C7: =AVERAGE(Demand_kW!$C7:$CA7) -> 0.12450446 | D7: =AVERAGE(PV_kW!$C7:$CA7) -> 0 | E7: =AVERAGE(Charge_kW!$C7:$CA7) -> 0 | F7: =AVERAGE(Discharge_kW!$C7:$CA7) -> 0.12122078 | G7: =C7-D7+E7-F7 -> 0.0032836788 | H7: =AVERAGE(SOC_pct!$C7:$CA7) -> 29.786691 | I7: =SUM(Demand_kW!$C7:$CA7) -> 9.5868433 | J7: =SUM(PV_kW!$C7:$CA7) -> 0 | K7: =I7-J7+SUM(Charge_kW!$C7:$CA7)-SUM(Discharge_kW!$C7:$CA7) -> 0.25284327
A8: =Demand_kW!A8 -> 7 | B8: =Demand_kW!B8 -> 3 | C8: =AVERAGE(Demand_kW!$C8:$CA8) -> 0.1320434 | D8: =AVERAGE(PV_kW!$C8:$CA8) -> 0 | E8: =AVERAGE(Charge_kW!$C8:$CA8) -> 0 | F8: =AVERAGE(Discharge_kW!$C8:$CA8) -> 0.12644156 | G8: =C8-D8+E8-F8 -> 0.0056018442 | H8: =AVERAGE(SOC_pct!$C8:$CA8) -> 28.265666 | I8: =SUM(Demand_kW!$C8:$CA8) -> 10.167342 | J8: =SUM(PV_kW!$C8:$CA8) -> 0 | K8: =I8-J8+SUM(Charge_kW!$C8:$CA8)-SUM(Discharge_kW!$C8:$CA8) -> 0.431342
A9: =Demand_kW!A9 -> 8 | B9: =Demand_kW!B9 -> 3.5 | C9: =AVERAGE(Demand_kW!$C9:$CA9) -> 0.10227013 | D9: =AVERAGE(PV_kW!$C9:$CA9) -> 0.0024856454 | E9: =AVERAGE(Charge_kW!$C9:$CA9) -> 0 | F9: =AVERAGE(Discharge_kW!$C9:$CA9) -> 0.094415584 | G9: =C9-D9+E9-F9 -> 0.0053688958 | H9: =AVERAGE(SOC_pct!$C9:$CA9) -> 26.679017 | I9: =SUM(Demand_kW!$C9:$CA9) -> 7.8747997 | J9: =SUM(PV_kW!$C9:$CA9) -> 0.19139469 | K9: =I9-J9+SUM(Charge_kW!$C9:$CA9)-SUM(Discharge_kW!$C9:$CA9) -> 0.41340497
A10: =Demand_kW!A10 -> 9 | B10: =Demand_kW!B10 -> 4 | C10: =AVERAGE(Demand_kW!$C10:$CA10) -> 0.12989528 | D10: =AVERAGE(PV_kW!$C10:$CA10) -> 0.035928327 | E10: =AVERAGE(Charge_kW!$C10:$CA10) -> 5.1948052e-05 | F10: =AVERAGE(Discharge_kW!$C10:$CA10) -> 0.08756189 | G10: =C10-D10+E10-F10 -> 0.0064570078 | H10: =AVERAGE(SOC_pct!$C10:$CA10) -> 25.494478 | I10: =SUM(Demand_kW!$C10:$CA10) -> 10.001936 | J10: =SUM(PV_kW!$C10:$CA10) -> 2.7664811 | K10: =I10-J10+SUM(Charge_kW!$C10:$CA10)-SUM(Discharge_kW!$C10:$CA10) -> 0.4971896
A11: =Demand_kW!A11 -> 10 | B11: =Demand_kW!B11 -> 4.5 | C11: =AVERAGE(Demand_kW!$C11:$CA11) -> 0.11673562 | D11: =AVERAGE(PV_kW!$C11:$CA11) -> 0.16801174 | E11: =AVERAGE(Charge_kW!$C11:$CA11) -> 0.074155844 | F11: =AVERAGE(Discharge_kW!$C11:$CA11) -> 0.022909091 | G11: =C11-D11+E11-F11 -> -2.9369514e-05 | H11: =AVERAGE(SOC_pct!$C11:$CA11) -> 24.39647 | I11: =SUM(Demand_kW!$C11:$CA11) -> 8.9886427 | J11: =SUM(PV_kW!$C11:$CA11) -> 12.936904 | K11: =I11-J11+SUM(Charge_kW!$C11:$CA11)-SUM(Discharge_kW!$C11:$CA11) -> -0.0022614526
A12: =Demand_kW!A12 -> 11 | B12: =Demand_kW!B12 -> 5 | C12: =AVERAGE(Demand_kW!$C12:$CA12) -> 0.10857823 | D12: =AVERAGE(PV_kW!$C12:$CA12) -> 0.33327342 | E12: =AVERAGE(Charge_kW!$C12:$CA12) -> 0.22951948 | F12: =AVERAGE(Discharge_kW!$C12:$CA12) -> 0.0041558442 | G12: =C12-D12+E12-F12 -> 0.00066844847 | H12: =AVERAGE(SOC_pct!$C12:$CA12) -> 24.946829 | I12: =SUM(Demand_kW!$C12:$CA12) -> 8.3605241 | J12: =SUM(PV_kW!$C12:$CA12) -> 25.662054 | K12: =I12-J12+SUM(Charge_kW!$C12:$CA12)-SUM(Discharge_kW!$C12:$CA12) -> 0.051470532
A13: =Demand_kW!A13 -> 12 | B13: =Demand_kW!B13 -> 5.5 | C13: =AVERAGE(Demand_kW!$C13:$CA13) -> 0.12560554 | D13: =AVERAGE(PV_kW!$C13:$CA13) -> 0.53592013 | E13: =AVERAGE(Charge_kW!$C13:$CA13) -> 0.4107013 | F13: =AVERAGE(Discharge_kW!$C13:$CA13) -> 0.00035064935 | G13: =C13-D13+E13-F13 -> 3.6063922e-05 | H13: =AVERAGE(SOC_pct!$C13:$CA13) -> 27.486579 | I13: =SUM(Demand_kW!$C13:$CA13) -> 9.6716269 | J13: =SUM(PV_kW!$C13:$CA13) -> 41.26585 | K13: =I13-J13+SUM(Charge_kW!$C13:$CA13)-SUM(Discharge_kW!$C13:$CA13) -> 0.002776922
... A49: =Demand_kW!A49 -> 48 | B49: =Demand_kW!B49 -> 23.5 | C49: =AVERAGE(Demand_kW!$C49:$CA49) -> 0.28430934 | D49: =AVERAGE(PV_kW!$C49:$CA49) -> 0 | E49: =AVERAGE(Charge_kW!$C49:$CA49) -> 0 | F49: =AVERAGE(Discharge_kW!$C49:$CA49) -> 0.21720779 | G49: =C49-D49+E49-F49 -> 0.067101552 | H49: =AVERAGE(SOC_pct!$C49:$CA49) -> 48.559494 | I49: =SUM(Demand_kW!$C49:$CA49) -> 21.891819 | J49: =SUM(PV_kW!$C49:$CA49) -> 0 | K49: =I49-J49+SUM(Charge_kW!$C49:$CA49)-SUM(Discharge_kW!$C49:$CA49) -> 5.1668195

Sheet SOC_pct
A1: period | B1: hour | C1: BES_TR1_one223_B | D1: BES_TR1_one313_A | E1: BES_TR1_one320_B | F1: BES_TR1_one321_C | G1: BES_TR1_one346_C | H1: BES_TR1_one366_B | I1: BES_TR1_one375_C | J1: BES_TR1_one410_B | K1: BES_TR1_one50_A | L1: BES_TR1_one423_B | M1: BES_TR1_one469_A | N1: BES_TR1_one480_A | O1: BES_TR1_one482_B | P1: BES_TR1_one521_C | Q1: BES_TR1_one528_C | R1: BES_TR1_one537_A | S1: BES_TR1_one61_A | T1: BES_TR1_one544_A | U1: BES_TR1_one552_B | V1: BES_TR1_one559_C | W1: BES_TR1_one560_C | X1: BES_TR1_one605_A | Y1: BES_TR1_one617_A | Z1: BES_TR1_one73_A | AA1: BES_TR1_one76_A | AB1: BES_TR1_six64_A | AC1: BES_TR1_six154_C | AD1: BES_TR1_six173_C | AE1: BES_TR1_six186_A | AF1: BES_TR1_six191_B | AG1: BES_TR1_six249_B | AH1: BES_TR1_six254_B | AI1: BES_TR1_six269_C | AJ1: BES_TR1_six68_C | AK1: BES_TR1_six289_C | AL1: BES_TR1_six317_C | AM1: BES_TR1_six326_A | AN1: BES_TR1_six329_A | AO1: BES_TR1_six342_A | AP1: BES_TR1_six349_A | AQ1: BES_TR1_six350_B | AR1: BES_TR1_six378_A | AS1: BES_TR1_six75_A | AT1: BES_TR1_six385_B | AU1: BES_TR1_six387_A | AV1: BES_TR1_six410_A | AW1: BES_TR1_six431_C | AX1: BES_TR1_six441_A | AY1: BES_TR1_six484_B | AZ1: BES_TR1_six501_A | BA1: BES_TR1_six512_B | BB1: BES_TR1_six518_B | BC1: BES_TR1_six595_B | BD1: BES_TR1_six646_B | BE1: BES_TR1_six699_C | BF1: BES_TR1_six718_C | BG1: BES_TR1_six721_A | BH1: BES_TR1_six723_B | BI1: BES_TR1_six784_B | BJ1: BES_TR1_six90_B | BK1: BES_TR1_six807_A | BL1: BES_TR1_six852_B | BM1: BES_TR1_six860_C | BN1: BES_TR1_six869_C | BO1: BES_TR1_six885_A | BP1: BES_TR1_six909_C | BQ1: BES_TR1_six105_A | BR1: BES_TR1_six914_A | BS1: BES_TR1_six945_C | BT1: BES_TR1_six952_A | BU1: BES_TR1_six967_B | BV1: BES_TR1_six990_B | BW1: BES_TR1_six1006_C | BX1: BES_TR1_six1020_A | BY1: BES_TR1_six1025_B | BZ1: BES_TR1_six1064_C | CA1: BES_TR1_six128_B | CB1: fleet_average | CC1: fleet_total
A2: 1 | B2: 0 | C2: 40 | D2: 40 | E2: 40 | F2: 40 | G2: 40 | H2: 40 | I2: 40 | J2: 40 | K2: 40 | L2: 40 | M2: 40 | N2: 40 | O2: 40 | P2: 40 | Q2: 40 | R2: 40 | S2: 40 | T2: 40 | U2: 40 | V2: 40 | W2: 40 | X2: 40 | Y2: 40 | Z2: 40 | AA2: 40 | AB2: 40 | AC2: 40 | AD2: 40 | AE2: 40 | AF2: 40 | AG2: 40 | AH2: 40 | AI2: 40 | AJ2: 40 | AK2: 40 | AL2: 40 | AM2: 40 | AN2: 40 | AO2: 40 | AP2: 40 | AQ2: 40 | AR2: 40 | AS2: 40 | AT2: 40 | AU2: 40 | AV2: 40 | AW2: 40 | AX2: 40 | AY2: 40 | AZ2: 40 | BA2: 40 | BB2: 40 | BC2: 40 | BD2: 40 | BE2: 40 | BF2: 40 | BG2: 40 | BH2: 40 | BI2: 40 | BJ2: 40 | BK2: 40 | BL2: 40 | BM2: 40 | BN2: 40 | BO2: 40 | BP2: 40 | BQ2: 40 | BR2: 40 | BS2: 40 | BT2: 40 | BU2: 40 | BV2: 40 | BW2: 40 | BX2: 40 | BY2: 40 | BZ2: 40 | CA2: 40 | CB2: 40 | CC2: 3080
A3: 2 | B3: 0.5 | C3: 37.6999 | D3: 38.8151 | E3: 39.3726 | F3: 39.2847 | G3: 39.3098 | H3: 37.5954 | I3: 37.1264 | J3: 36.7855 | K3: 32.9732 | L3: 35.253 | M3: 33.9218 | N3: 35.5687 | O3: 37.7004 | P3: 37.1295 | Q3: 38.3716 | R3: 39.4353 | S3: 39.0108 | T3: 35.2519 | U3: 38.6564 | V3: 37.2409 | W3: 38.7427 | X3: 39.36 | Y3: 39.3726 | Z3: 10 | AA3: 38.8061 | AB3: 33.4458 | AC3: 38.3303 | AD3: 37.5324 | AE3: 31.7818 | AF3: 36.924 | AG3: 39.2596 | AH3: 38.155 | AI3: 37.8981 | AJ3: 39.1243 | AK3: 39.0792 | AL3: 36.6217 | AM3: 38.6002 | AN3: 39.2596 | AO3: 35.0878 | AP3: 33.399 | AQ3: 39.3349 | AR3: 38.2194 | AS3: 39.473 | AT3: 37.534 | AU3: 38.5488 | AV3: 37.266 | AW3: 36.069 | AX3: 39.6235 | AY3: 37.9875 | AZ3: 36.3203 | BA3: 38.4427 | BB3: 38.803 | BC3: 38.8886 | BD3: 34.9732 | BE3: 39.2722 | BF3: 38.0791 | BG3: 37.6538 | BH3: 37.6874 | BI3: 35.4943 | BJ3: 30.9777 | BK3: 37.2519 | BL3: 36.4255 | BM3: 17.5159 | BN3: 15.5794 | BO3: 37.8865 | BP3: 39.3726 | BQ3: 35.4453 | BR3: 39.3977 | BS3: 38.7262 | BT3: 39.3098 | BU3: 37.318 | BV3: 38.1631 | BW3: 37.8954 | BX3: 30.4645 | BY3: 38.6599 | BZ3: 39.4479 | CA3: 39.3977 | CB3: 36.573881 | CC3: 2816.1888
A4: 3 | B4: 1 | C4: 34.6832 | D4: 38.3131 | E4: 37.7009 | F4: 38.5695 | G4: 38.6197 | H4: 34.8614 | I4: 35.7733 | J4: 35.5979 | K4: 26.278 | L4: 30.4581 | M4: 27.5684 | N4: 29.254 | O4: 37.0604 | P4: 36.0748 | Q4: 36.7432 | R4: 38.8706 | S4: 35.4005 | T4: 32.5399 | U4: 38.0666 | V4: 35.9362 | W4: 34.5887 | X4: 37.255 | Y4: 38.7451 | Z4: 10 | AA4: 37.4957 | AB4: 32.2339 | AC4: 37.7029 | AD4: 36.8423 | AE4: 23.0833 | AF4: 32.0516 | AG4: 37.0908 | AH4: 35.6731 | AI4: 36.4353 | AJ4: 34.455 | AK4: 35.3366 | AL4: 33.7936 | AM4: 37.5684 | AN4: 35.5823 | AO4: 34.4981 | AP4: 27.794 | AQ4: 37.6874 | AR4: 37.6421 | AS4: 37.8818 | AT4: 37.0697 | AU4: 35.4373 | AV4: 36.2472 | AW4: 35.0494 | AX4: 37.5977 | AY4: 34.9472 | AZ4: 35.2104 | BA4: 36.6855 | BB4: 37.606 | BC4: 37.8812 | BD4: 33.8306 | BE4: 38.5444 | BF4: 35.9654 | BG4: 35.5686 | BH4: 36.8313 | BI4: 23.5964 | BJ4: 29.8036 | BK4: 36.5618 | BL4: 33.4545 | BM4: 12.8768 | BN4: 10 | BO4: 36.8302 | BP4: 38.7451 | BQ4: 34.981 | BR4: 38.7953 | BS4: 36.7136 | BT4: 36.9083 | BU4: 36.6278 | BV4: 35.8874 | BW4: 37.1927 | BX4: 29.812 | BY4: 35.3348 | BZ4: 38.8957 | CA4: 38.7953 | CB4: 34.364817 | CC4: 2646.0909
A5: 4 | B5: 1.5 | C5: 32.7801 | D5: 37.8112 | E5: 37.0734 | F5: 37.8542 | G5: 35.931 | H5: 33.8558 | I5: 34.3809 | J5: 34.9579 | K5: 25.5878 | L5: 29.6926 | M5: 22.7464 | N5: 20.3386 | O5: 36.2252 | P5: 32.0696 | Q5: 35.3348 | R5: 38.116 | S5: 34.773 | T5: 31.8623 | U5: 36.0634 | V5: 32.3051 | W5: 33.8652 | X5: 35.8963 | Y5: 38.1177 | Z5: 10 | AA5: 36.7679 | AB5: 30.5964 | AC5: 36.6194 | AD5: 31.9703 | AE5: 17.067 | AF5: 28.6746 | AG5: 35.0087 | AH5: 34.4746 | AI5: 34.4128 | AJ5: 32.4341 | AK5: 33.4523 | AL5: 31.5268 | AM5: 36.9661 | AN5: 34.8419 | AO5: 33.9083 | AP5: 27.1415 | AQ5: 37.0223 | AR5: 37.0649 | AS5: 36.1327 | AT5: 36.6054 | AU5: 34.9354 | AV5: 34.6442 | AW5: 31.7857 | AX5: 37.2213 | AY5: 33.1018 | AZ5: 32.7277 | BA5: 34.429 | BB5: 36.8782 | BC5: 36.8738 | BD5: 30.6442 | BE5: 37.8166 | BF5: 34.9007 | BG5: 34.4636 | BH5: 33.772 | BI5: 23.0443 | BJ5: 29.0474 | BK5: 35.8716 | BL5: 30.9728 | BM5: 11.4012 | BN5: 10 | BO5: 34.8612 | BP5: 38.1177 | BQ5: 34.5167 | BR5: 38.193 | BS5: 36.0861 | BT5: 35.5919 | BU5: 35.9377 | BV5: 34.2262 | BW5: 36.49 | BX5: 27.8437 | BY5: 33.7587 | BZ5: 37.5748 | CA5: 38.193 | CB5: 32.808425 | CC5: 2526.2487
A6: 5 | B6: 2 | C6: 29.9816 | D6: 36.6263 | E6: 35.4017 | F6: 35.6525 | G6: 35.2409 | H6: 30.021 | I6: 31.5925 | J6: 31.1958 | K6: 24.8976 | L6: 26.8705 | M6: 20.6526 | N6: 15.7113 | O6: 33.6326 | P6: 31.4171 | Q6: 33.9863 | R6: 35.6518 | S6: 34.1456 | T6: 31.1847 | U6: 34.8141 | V6: 31.3767 | W6: 31.0283 | X6: 35.2564 | Y6: 37.4903 | Z6: 10 | AA6: 35.108 | AB6: 29.8811 | AC6: 35.1451 | AD6: 31.0933 | AE6: 15.9211 | AF6: 27.9969 | AG6: 32.8398 | AH6: 33.276 | AI6: 32.3973 | AJ6: 31.8067 | AK6: 31.3737 | AL6: 29.8772 | AM6: 35.4711 | AN6: 32.237 | AO6: 33.3185 | AP6: 26.489 | AQ6: 36.3572 | AR6: 36.4877 | AS6: 31.7325 | AT6: 34.0341 | AU6: 32.6419 | AV6: 32.4559 | AW6: 31.0949 | AX6: 35.1954 | AY6: 30.7551 | AZ6: 31.9974 | BA6: 32.6718 | BB6: 35.212 | BC6: 35.6065 | BD6: 30.1925 | BE6: 36.2607 | BF6: 31.1947 | BG6: 31.0415 | BH6: 33.0818 | BI6: 21.6231 | BJ6: 25.5518 | BK6: 33.1235 | BL6: 28.0846 | BM6: 10.0207 | BN6: 10 | BO6: 33.8049 | BP6: 37.4903 | BQ6: 31.9158 | BR6: 37.5907 | BS6: 34.5353 | BT6: 34.54 | BU6: 33.2557 | BV6: 31.9618 | BW6: 34.3854 | BX6: 26.2803 | BY6: 28.2007 | BZ6: 35.6848 | CA6: 37.5907 | CB6: 31.061217 | CC6: 2391.7137
A7: 6 | B7: 2.5 | C7: 28.2135 | D7: 34.9292 | E7: 34.7743 | F7: 34.9373 | G7: 33.1881 | H7: 28.1281 | I7: 30.6523 | J7: 30.5558 | K7: 24.2075 | L7: 26.1051 | M7: 20.0753 | N7: 12.7654 | O7: 32.9927 | P7: 30.6103 | Q7: 32.078 | R7: 35.0871 | S7: 30.4448 | T7: 30.507 | U7: 34.168 | V7: 29.7244 | W7: 29.0832 | X7: 32.9517 | Y7: 36.8629 | Z7: 10 | AA7: 34.2636 | AB7: 29.1658 | AC7: 34.5177 | AD7: 29.7469 | AE7: 13.911 | AF7: 27.3193 | AG7: 32.0994 | AH7: 32.7239 | AI7: 30.6978 | AJ7: 29.1915 | AK7: 28.1651 | AL7: 27.5743 | AM7: 34.8687 | AN7: 30.4242 | AO7: 31.7185 | AP7: 25.8365 | AQ7: 34.7097 | AR7: 35.9104 | AS7: 25.9205 | AT7: 33.3591 | AU7: 30.3727 | AV7: 31.6034 | AW7: 28.8312 | AX7: 34.819 | AY7: 28.7594 | AZ7: 30.8512 | BA7: 30.4153 | BB7: 34.4842 | BC7: 34.859 | BD7: 27.0983 | BE7: 35.5329 | BF7: 30.3834 | BG7: 30.414 | BH7: 30.9351 | BI7: 20.9623 | BJ7: 24.8867 | BK7: 32.4334 | BL7: 26.2189 | BM7: 10 | BN7: 10 | BO7: 33.182 | BP7: 36.8629 | BQ7: 31.4515 | BR7: 36.9884 | BS7: 32.7997 | BT7: 33.1264 | BU7: 32.5655 | BV7: 29.2633 | BW7: 33.6827 | BX7: 25.4254 | BY7: 27.08 | BZ7: 35.1327 | CA7: 36.9884 | CB7: 29.786691 | CC7: 2293.5752
A8: 7 | B8: 3 | C8: 26.3518 | D8: 34.4272 | E8: 33.9728 | F8: 32.7356 | G8: 31.8621 | H8: 26.2622 | I8: 28.8076 | J8: 29.2771 | K8: 23.5173 | L8: 25.3396 | M8: 19.4981 | N8: 11.0219 | O8: 30.4001 | P8: 26.4578 | Q8: 31.4757 | R8: 34.1425 | S8: 29.5461 | T8: 28.9972 | U8: 31.736 | V8: 26.9298 | W8: 26.904 | X8: 31.7927 | Y8: 36.2354 | Z8: 10 | AA8: 33.0115 | AB8: 28.3087 | AC8: 32.5874 | AD8: 26.8144 | AE8: 13.2835 | AF8: 26.6417 | AG8: 28.7317 | AH8: 30.528 | AI8: 28.596 | AJ8: 28.5641 | AK8: 26.9046 | AL8: 24.3478 | AM8: 33.3737 | AN8: 29.6838 | AO8: 31.1287 | AP8: 25.1839 | AQ8: 34.0446 | AR8: 35.3332 | AS8: 19.1183 | AT8: 32.7894 | AU8: 29.8708 | AV8: 30.1255 | AW8: 26.8625 | AX8: 33.3704 | AY8: 27.0028 | AZ8: 26.6012 | BA8: 29.0096 | BB8: 32.8181 | BC8: 34.3194 | BD8: 26.291 | BE8: 34.8051 | BF8: 28.1606 | BG8: 29.7866 | BH8: 29.1664 | BI8: 20.4102 | BJ8: 22.5809 | BK8: 29.7788 | BL8: 24.2747 | BM8: 10 | BN8: 10 | BO8: 31.1408 | BP8: 36.2354 | BQ8: 29.8218 | BR8: 36.386 | BS8: 32.1723 | BT8: 31.0633 | BU8: 31.3321 | BV8: 28.6234 | BW8: 31.5781 | BX8: 22.7487 | BY8: 22.4876 | BZ8: 34.5806 | CA8: 36.386 | CB8: 28.265666 | CC8: 2176.4563
A9: 8 | B9: 3.5 | C9: 22.8525 | D9: 32.0471 | E9: 32.4752 | F9: 32.0203 | G9: 30.8994 | H9: 22.3155 | I9: 26.3339 | J9: 26.1537 | K9: 22.8271 | L9: 22.7045 | M9: 18.9209 | N9: 10.4195 | O9: 29.5649 | P9: 25.7047 | Q9: 30.6868 | R9: 31.8683 | S9: 27.9507 | T9: 25.6283 | U9: 29.7328 | V9: 25.5751 | W9: 24.2776 | X9: 31.1527 | Y9: 35.608 | Z9: 10 | AA9: 31.7593 | AB9: 26.3164 | AC9: 31.96 | AD9: 25.5617 | AE9: 10.6736 | AF9: 25.9641 | AG9: 27.8485 | AH9: 28.397 | AI9: 26.581 | AJ9: 25.949 | AK9: 22.9067 | AL9: 21.5447 | AM9: 31.5444 | AN9: 27.3591 | AO9: 30.5389 | AP9: 24.5314 | AQ9: 32.7246 | AR9: 34.756 | AS9: 16.4799 | AT9: 30.1127 | AU9: 27.4702 | AV9: 28.1634 | AW9: 25.2123 | AX9: 32.4167 | AY9: 24.3292 | AZ9: 26.0868 | BA9: 27.9553 | BB9: 32.0903 | BC9: 33.7798 | BD9: 24.4346 | BE9: 33.2492 | BF9: 25.5042 | BG9: 27.8701 | BH9: 27.7664 | BI9: 19.5865 | BJ9: 21.5512 | BK9: 28.9951 | BL9: 21.859 | BM9: 10 | BN9: 10 | BO9: 30.1567 | BP9: 35.608 | BQ9: 28.3863 | BR9: 35.7837 | BS9: 29.5133 | BT9: 29.4085 | BU9: 29.1934 | BV9: 24.215 | BW9: 30.8754 | BX9: 22.0962 | BY9: 19.6869 | BZ9: 34.0284 | CA9: 35.7837 | CB9: 26.679017 | CC9: 2054.2843
A10: 9 | B10: 4 | C10: 22.3184 | D10: 31.5883 | E10: 31.8693 | F10: 30.0105 | G10: 28.5157 | H10: 21.1502 | I10: 25.6958 | J10: 24.9802 | K10: 22.1585 | L10: 21.7737 | M10: 18.376 | N10: 10 | O10: 28.9681 | P10: 23.5363 | Q10: 28.2458 | R10: 31.3306 | S10: 25.1706 | T10: 24.9938 | U10: 29.1808 | V10: 22.0684 | W10: 21.2101 | X10: 30.1804 | Y10: 35.013 | Z10: 10 | AA10: 31.0693 | AB10: 25.6281 | AC10: 31.3757 | AD10: 23.5127 | AE10: 10 | AF10: 25.3296 | AG10: 26.8656 | AH10: 27.7741 | AI10: 25.0567 | AJ10: 25.3378 | AK10: 21.1064 | AL10: 19.6406 | AM10: 30.9195 | AN10: 26.6458 | AO10: 29.9815 | AP10: 23.9059 | AQ10: 31.7752 | AR10: 34.2219 | AS10: 14.7574 | AT10: 29.6646 | AU10: 26.7946 | AV10: 26.9572 | AW10: 22.6063 | AX10: 31.4237 | AY10: 21.5384 | AZ10: 23.3437 | BA10: 26.2805 | BB10: 31.4056 | BC10: 32.3316 | BD10: 22.4165 | BE10: 32.5592 | BF10: 24.516 | BG10: 26.1846 | BH10: 25.8749 | BI10: 18.3606 | BJ10: 19.9915 | BK10: 26.6867 | BL10: 18.9449 | BM10: 10 | BN10: 10 | BO10: 29.3754 | BP10: 35.0076 | BQ10: 27.949 | BR10: 35.2192 | BS10: 28.929 | BT10: 27.4875 | BU10: 28.514 | BV10: 23.6182 | BW10: 30.2105 | BX10: 20.1712 | BY10: 16.7729 | BZ10: 33.4871 | CA10: 35.2138 | CB10: 25.494478 | CC10: 1963.0748
A11: 10 | B11: 4.5 | C11: 21.1295 | D11: 30.686 | E11: 31.554 | F11: 29.7707 | G11: 28.2936 | H11: 18.8603 | I11: 23.848 | J11: 22.4815 | K11: 21.7804 | L11: 21.3203 | M11: 18.2668 | N11: 10 | O11: 26.8044 | P11: 23.2739 | Q11: 28.0335 | R11: 29.0665 | S11: 24.9864 | T11: 22.3415 | U11: 27.0641 | V11: 20.2973 | W11: 19.5344 | X11: 28.1793 | Y11: 34.8536 | Z11: 10 | AA11: 29.8389 | AB11: 23.884 | AC11: 31.3724 | AD11: 21.8095 | AE11: 10 | AF11: 25.2761 | AG11: 25.6065 | AH11: 24.7546 | AI11: 22.9646 | AJ11: 23.4988 | AK11: 19.3398 | AL11: 18.4603 | AM11: 28.6372 | AN11: 24.8696 | AO11: 29.8598 | AP11: 23.6434 | AQ11: 31.7342 | AR11: 34.2641 | AS11: 14.2892 | AT11: 27.1166 | AU11: 25.1977 | AV11: 26.0694 | AW11: 21.441 | AX11: 30.6817 | AY11: 20.9764 | AZ11: 21.451 | BA11: 25.58 | BB11: 30.5199 | BC11: 32.1821 | BD11: 22.0036 | BE11: 32.3774 | BF11: 23.263 | BG11: 25.1937 | BH11: 25.2281 | BI11: 18.2765 | BJ11: 18.3623 | BK11: 25.0926 | BL11: 16.9142 | BM11: 10 | BN11: 10 | BO11: 28.1153 | BP11: 34.7702 | BQ11: 25.7382 | BR11: 34.8184 | BS11: 27.6326 | BT11: 26.0242 | BU11: 25.988 | BV11: 20.4889 | BW11: 30.0538 | BX11: 19.2319 | BY11: 13.04 | BZ11: 33.091 | CA11: 35.0795 | CB11: 24.39647 | CC11: 1878.5282
A12: 11 | B12: 5 | C12: 21.352 | D12: 32.0926 | E12: 32.3026 | F12: 30.5496 | G12: 29.6424 | H12: 17.6182 | I12: 23.5915 | J12: 22.7611 | K12: 22.4726 | L12: 19.9574 | M12: 19.7173 | N12: 10.6685 | O12: 28.8551 | P12: 22.3834 | Q12: 27.3896 | R12: 30.2 | S12: 25.8288 | T12: 23.5261 | U12: 28.8317 | V12: 20.446 | W12: 19.9219 | X12: 28.676 | Y12: 36.2589 | Z12: 11.3489 | AA12: 31.4822 | AB12: 24.8819 | AC12: 33.4344 | AD12: 23.6884 | AE12: 10.0856 | AF12: 27.2929 | AG12: 27.5668 | AH12: 25.2553 | AI12: 24.257 | AJ12: 23.4237 | AK12: 19.9981 | AL12: 17.4813 | AM12: 29.7368 | AN12: 24.4421 | AO12: 31.299 | AP12: 24.6978 | AQ12: 33.5167 | AR12: 36.3713 | AS12: 14.9745 | AT12: 27.6837 | AU12: 23.7074 | AV12: 25.6637 | AW12: 20.7269 | AX12: 21.2067 | AY12: 19.9417 | AZ12: 22.724 | BA12: 25.5976 | BB12: 32.3508 | BC12: 33.3381 | BD12: 21.2031 | BE12: 33.2755 | BF12: 23.6156 | BG12: 23.0338 | BH12: 26.5615 | BI12: 19.5051 | BJ12: 18.4207 | BK12: 25.7847 | BL12: 18.0796 | BM12: 11.4697 | BN12: 10.9623 | BO12: 28.9656 | BP12: 35.8472 | BQ12: 26.962 | BR12: 36.5746 | BS12: 28.9466 | BT12: 26.7164 | BU12: 26.0235 | BV12: 21.9501 | BW12: 30.458 | BX12: 20.7247 | BY12: 12.8488 | BZ12: 33.2507 | CA12: 36.5074 | CB12: 24.946829 | CC12: 1920.9058
A13: 12 | B13: 5.5 | C13: 25.7798 | D13: 36.7744 | E13: 34.3431 | F13: 34.9824 | G13: 32.9291 | H13: 19.6135 | I13: 25.7185 | J13: 24.333 | K13: 24.4566 | L13: 21.8737 | M13: 23.1056 | N13: 10 | O13: 32.0837 | P13: 23.2096 | Q13: 29.9361 | R13: 32.9482 | S13: 28.6838 | T13: 27.7104 | U13: 32.3511 | V13: 19.1344 | W13: 23.3163 | X13: 31.2128 | Y13: 39.602 | Z13: 14.6355 | AA13: 35.3863 | AB13: 26.6646 | AC13: 37.9042 | AD13: 27.5183 | AE13: 11.2482 | AF13: 31.8934 | AG13: 30.9033 | AH13: 27.0311 | AI13: 27.4871 | AJ13: 23.9997 | AK13: 20.1237 | AL13: 18.3643 | AM13: 31.3469 | AN13: 26.8184 | AO13: 34.3224 | AP13: 27.367 | AQ13: 37.4899 | AR13: 41.0621 | AS13: 17.7449 | AT13: 27.6619 | AU13: 24.7355 | AV13: 26.7135 | AW13: 22.7789 | AX13: 23.6639 | AY13: 22.1886 | AZ13: 25.1863 | BA13: 28.825 | BB13: 36.9062 | BC13: 35.2669 | BD13: 23.6264 | BE13: 37.1795 | BF13: 21.61 | BG13: 24.423 | BH13: 29.5412 | BI13: 22.2805 | BJ13: 19.6027 | BK13: 27.7688 | BL13: 21.8641 | BM13: 14.6678 | BN13: 15.4755 | BO13: 29.311 | BP13: 38.539 | BQ13: 29.7132 | BR13: 40.5916 | BS13: 33.5923 | BT13: 28.7004 | BU13: 26.7049 | BV13: 26.5845 | BW13: 34.3846 | BX13: 23.8904 | BY13: 15.1496 | BZ13: 34.0564 | CA13: 39.8731 | CB13: 27.486579 | CC13: 2116.4666
... A49: 48 | B49: 23.5 | C49: 17.3325 | D49: 91.9536 | E49: 43.3267 | F49: 91.4113 | G49: 89.9503 | H49: 10 | I49: 11.6036 | J49: 84.5332 | K49: 33.9026 | L49: 10 | M49: 59.1603 | N49: 10.3772 | O49: 52.3853 | P49: 82.2766 | Q49: 10 | R49: 10 | S49: 22.2173 | T49: 36.614 | U49: 76.6006 | V49: 51.3277 | W49: 68.282 | X49: 67.303 | Y49: 62.6764 | Z49: 85.7666 | AA49: 31.7518 | AB49: 25.3453 | AC49: 91.7885 | AD49: 10 | AE49: 10 | AF49: 67.439 | AG49: 49.3021 | AH49: 54.0161 | AI49: 65.6195 | AJ49: 31.852 | AK49: 10 | AL49: 62.8967 | AM49: 10 | AN49: 87.8458 | AO49: 69.5688 | AP49: 10 | AQ49: 59.3471 | AR49: 45.4377 | AS49: 49.515 | AT49: 56.4191 | AU49: 42.7072 | AV49: 66.0032 | AW49: 56.5508 | AX49: 80.1825 | AY49: 20.2123 | AZ49: 41.4402 | BA49: 51.7651 | BB49: 36.5554 | BC49: 56.8065 | BD49: 57.0425 | BE49: 93.4662 | BF49: 28.9825 | BG49: 39.6203 | BH49: 67.6373 | BI49: 53.9867 | BJ49: 87.1689 | BK49: 10 | BL49: 12.7945 | BM49: 61.57 | BN49: 40.3985 | BO49: 60.7474 | BP49: 10 | BQ49: 73.6531 | BR49: 42.4525 | BS49: 31.6657 | BT49: 77.5075 | BU49: 10 | BV49: 69.1267 | BW49: 72.8023 | BX49: 63.3629 | BY49: 33.8092 | BZ49: 66.7763 | CA49: 45.1415 | CB49: 48.559494 | CC49: 3739.081

Sheet Demand_kW
A1: period | B1: hour | C1: BES_TR1_one223_B | D1: BES_TR1_one313_A | E1: BES_TR1_one320_B | F1: BES_TR1_one321_C | G1: BES_TR1_one346_C | H1: BES_TR1_one366_B | I1: BES_TR1_one375_C | J1: BES_TR1_one410_B | K1: BES_TR1_one50_A | L1: BES_TR1_one423_B | M1: BES_TR1_one469_A | N1: BES_TR1_one480_A | O1: BES_TR1_one482_B | P1: BES_TR1_one521_C | Q1: BES_TR1_one528_C | R1: BES_TR1_one537_A | S1: BES_TR1_one61_A | T1: BES_TR1_one544_A | U1: BES_TR1_one552_B | V1: BES_TR1_one559_C | W1: BES_TR1_one560_C | X1: BES_TR1_one605_A | Y1: BES_TR1_one617_A | Z1: BES_TR1_one73_A | AA1: BES_TR1_one76_A | AB1: BES_TR1_six64_A | AC1: BES_TR1_six154_C | AD1: BES_TR1_six173_C | AE1: BES_TR1_six186_A | AF1: BES_TR1_six191_B | AG1: BES_TR1_six249_B | AH1: BES_TR1_six254_B | AI1: BES_TR1_six269_C | AJ1: BES_TR1_six68_C | AK1: BES_TR1_six289_C | AL1: BES_TR1_six317_C | AM1: BES_TR1_six326_A | AN1: BES_TR1_six329_A | AO1: BES_TR1_six342_A | AP1: BES_TR1_six349_A | AQ1: BES_TR1_six350_B | AR1: BES_TR1_six378_A | AS1: BES_TR1_six75_A | AT1: BES_TR1_six385_B | AU1: BES_TR1_six387_A | AV1: BES_TR1_six410_A | AW1: BES_TR1_six431_C | AX1: BES_TR1_six441_A | AY1: BES_TR1_six484_B | AZ1: BES_TR1_six501_A | BA1: BES_TR1_six512_B | BB1: BES_TR1_six518_B | BC1: BES_TR1_six595_B | BD1: BES_TR1_six646_B | BE1: BES_TR1_six699_C | BF1: BES_TR1_six718_C | BG1: BES_TR1_six721_A | BH1: BES_TR1_six723_B | BI1: BES_TR1_six784_B | BJ1: BES_TR1_six90_B | BK1: BES_TR1_six807_A | BL1: BES_TR1_six852_B | BM1: BES_TR1_six860_C | BN1: BES_TR1_six869_C | BO1: BES_TR1_six885_A | BP1: BES_TR1_six909_C | BQ1: BES_TR1_six105_A | BR1: BES_TR1_six914_A | BS1: BES_TR1_six945_C | BT1: BES_TR1_six952_A | BU1: BES_TR1_six967_B | BV1: BES_TR1_six990_B | BW1: BES_TR1_six1006_C | BX1: BES_TR1_six1020_A | BY1: BES_TR1_six1025_B | BZ1: BES_TR1_six1064_C | CA1: BES_TR1_six128_B | CB1: fleet_average | CC1: fleet_total
A2: 1 | B2: 0 | C2: 0.18330067 | D2: 0.094426667 | E2: 0.05 | F2: 0.057 | G2: 0.055 | H2: 0.19162733 | I2: 0.228996 | J2: 0.25616833 | K2: 0.55997167 | L2: 0.37828833 | M2: 0.484378 | N2: 0.353135 | O2: 0.18326 | P2: 0.22875467 | Q2: 0.12977033 | R2: 0.045 | S2: 0.078828 | T2: 0.378376 | U2: 0.107072 | V2: 0.21987567 | W2: 0.10019833 | X2: 0.051 | Y2: 0.05 | Z2: 2.4385167 | AA2: 0.095141333 | AB2: 0.52231033 | AC2: 0.13306133 | AD2: 0.196642 | AE2: 0.65491333 | AF2: 0.24512833 | AG2: 0.059 | AH2: 0.14703067 | AI2: 0.1675 | AJ2: 0.069782167 | AK2: 0.073378 | AL2: 0.26922133 | AM2: 0.11155267 | AN2: 0.059 | AO2: 0.39145467 | AP2: 0.52604 | AQ2: 0.053 | AR2: 0.1419 | AS2: 0.042 | AT2: 0.19651767 | AU2: 0.11565 | AV2: 0.21787367 | AW2: 0.313266 | AX2: 0.03 | AY2: 0.16038067 | AZ2: 0.29324033 | BA2: 0.124101 | BB2: 0.095389 | BC2: 0.088565667 | BD2: 0.40058767 | BE2: 0.058 | BF2: 0.15307767 | BG2: 0.18697067 | BH2: 0.18429467 | BI2: 0.359062 | BJ2: 0.71899433 | BK2: 0.21899533 | BL2: 0.28485467 | BM2: 1.791776 | BN2: 1.9461 | BO2: 0.16842333 | BP2: 0.05 | BQ2: 0.36297033 | BR2: 0.048 | BS2: 0.101513 | BT2: 0.055 | BU2: 0.21373 | BV2: 0.146382 | BW2: 0.16771533 | BX2: 0.75989333 | BY2: 0.10679033 | BZ2: 0.044 | CA2: 0.048 | CB2: 0.27365084 | CC2: 21.071115
A3: 2 | B3: 0.5 | C3: 0.240402 | D3: 0.04 | E3: 0.13322 | F3: 0.057 | G3: 0.055 | H3: 0.21787233 | I3: 0.10783 | J3: 0.094640333 | K3: 0.53354867 | L3: 0.382116 | M3: 0.506309 | N3: 0.50322467 | O3: 0.051 | P3: 0.084050667 | Q3: 0.12977033 | R3: 0.045 | S3: 0.28771267 | T3: 0.21612533 | U3: 0.047 | V3: 0.10397433 | W3: 0.33103167 | X3: 0.16775333 | Y3: 0.05 | Z3: 0.055 | AA3: 0.10442667 | AB3: 0.096575667 | AC3: 0.05 | AD3: 0.055 | AE3: 0.69319167 | AF3: 0.388283 | AG3: 0.17284 | AH3: 0.19778 | AI3: 0.116574 | AJ3: 0.3721036 | AK3: 0.298254 | AL3: 0.22536867 | AM3: 0.082220667 | AN3: 0.29305333 | AO3: 0.047 | AP3: 0.44666333 | AQ3: 0.131294 | AR3: 0.046 | AS3: 0.126799 | AT3: 0.037 | AU3: 0.24795333 | AV3: 0.081188667 | AW3: 0.081253333 | AX3: 0.16144 | AY3: 0.24227733 | AZ3: 0.08845 | BA3: 0.140036 | BB3: 0.095389 | BC3: 0.080281 | BD3: 0.091054667 | BE3: 0.058 | BF3: 0.16844567 | BG3: 0.16617367 | BH3: 0.068223333 | BI3: 0.94815067 | BJ3: 0.093563333 | BK3: 0.055 | BL3: 0.23675967 | BM3: 0.36969467 | BN3: 0.53397667 | BO3: 0.08418 | BP3: 0.05 | BQ3: 0.037 | BR3: 0.048 | BS3: 0.160385 | BT3: 0.191381 | BU3: 0.055 | BV3: 0.181358 | BW3: 0.056 | BX3: 0.052 | BY3: 0.26498333 | BZ3: 0.044 | CA3: 0.048 | CB3: 0.17791698 | CC3: 13.699607
A4: 3 | B4: 1 | C4: 0.151653 | D4: 0.04 | E4: 0.05 | F4: 0.057 | G4: 0.214258 | H4: 0.080133333 | I4: 0.110968 | J4: 0.051 | K4: 0.055 | L4: 0.061 | M4: 0.38427 | N4: 0.71047133 | O4: 0.06656 | P4: 0.31917467 | Q4: 0.11222933 | R4: 0.060137333 | S4: 0.05 | T4: 0.054 | U4: 0.159635 | V4: 0.28936133 | W4: 0.057654667 | X4: 0.10827 | Y4: 0.05 | Z4: 0.055 | AA4: 0.058 | AB4: 0.13049767 | AC4: 0.086339333 | AD4: 0.388255 | AE4: 0.47944433 | AF4: 0.26912267 | AG4: 0.16592267 | AH4: 0.095515333 | AI4: 0.16117333 | AJ4: 0.16104867 | AK4: 0.150158 | AL4: 0.180644 | AM4: 0.048 | AN4: 0.059 | AO4: 0.047 | AP4: 0.052 | AQ4: 0.053 | AR4: 0.046 | AS4: 0.139391 | AT4: 0.037 | AU4: 0.04 | AV4: 0.12774933 | AW4: 0.260082 | AX4: 0.03 | AY4: 0.147064 | AZ4: 0.197847 | BA4: 0.17982 | BB4: 0.058 | BC4: 0.080281 | BD4: 0.253926 | BE4: 0.058 | BF4: 0.084846 | BG4: 0.088055 | BH4: 0.24379633 | BI4: 0.044 | BJ4: 0.060264333 | BK4: 0.055 | BL4: 0.19776667 | BM4: 0.11758667 | BN4: 0.077342667 | BO4: 0.15690867 | BP4: 0.05 | BQ4: 0.037 | BR4: 0.048 | BS4: 0.05 | BT4: 0.104903 | BU4: 0.055 | BV4: 0.13237967 | BW4: 0.056 | BX4: 0.15684933 | BY4: 0.12559667 | BZ4: 0.10526667 | CA4: 0.048 | CB4: 0.1257483 | CC4: 9.682619
A5: 4 | B5: 1.5 | C5: 0.22301567 | D5: 0.094426667 | E5: 0.13322 | F5: 0.17545333 | G5: 0.055 | H5: 0.30560067 | I5: 0.22220267 | J5: 0.29980867 | K5: 0.055 | L5: 0.22489267 | M5: 0.16685667 | N5: 0.368758 | O5: 0.2066 | P5: 0.052 | Q5: 0.10746933 | R5: 0.19637333 | S5: 0.05 | T5: 0.054 | U5: 0.099563 | V5: 0.073988333 | W5: 0.226074 | X5: 0.051 | Y5: 0.05 | Z5: 0.055 | AA5: 0.13228267 | AB5: 0.057 | AC5: 0.11748733 | AD5: 0.069886667 | AE5: 0.09132 | AF5: 0.054 | AG5: 0.17284 | AH5: 0.095515333 | AI5: 0.16061667 | AJ5: 0.05 | AK5: 0.165646 | AL5: 0.13146133 | AM5: 0.119142 | AN5: 0.20759 | AO5: 0.047 | AP5: 0.052 | AQ5: 0.053 | AR5: 0.046 | AS5: 0.35065667 | AT5: 0.20491333 | AU5: 0.18276833 | AV5: 0.17438093 | AW5: 0.055052333 | AX5: 0.16144 | AY5: 0.18700967 | AZ5: 0.058193333 | BA5: 0.140036 | BB5: 0.132778 | BC5: 0.10099267 | BD5: 0.036 | BE5: 0.123988 | BF5: 0.295335 | BG5: 0.272714 | BH5: 0.055 | BI5: 0.11325867 | BJ5: 0.278565 | BK5: 0.21899533 | BL5: 0.230163 | BM5: 0.11001333 | BN5: 0.14737067 | BO5: 0.08418 | BP5: 0.05 | BQ5: 0.20726533 | BR5: 0.048 | BS5: 0.12359 | BT5: 0.083826 | BU5: 0.21373 | BV5: 0.180447 | BW5: 0.16771533 | BX5: 0.124588 | BY5: 0.44292767 | BZ5: 0.15061333 | CA5: 0.048 | CB5: 0.14186491 | CC5: 10.923598
A6: 5 | B6: 2 | C6: 0.140902 | D6: 0.13524667 | E6: 0.05 | F6: 0.057 | G6: 0.163585 | H6: 0.150845 | I6: 0.074932 | J6: 0.051 | K6: 0.055 | L6: 0.061 | M6: 0.046 | N6: 0.23475733 | O6: 0.051 | P6: 0.064294667 | Q6: 0.15207133 | R6: 0.045 | S6: 0.29491967 | T6: 0.054 | U6: 0.051489667 | V6: 0.131675 | W6: 0.155007 | X6: 0.18366167 | Y6: 0.05 | Z6: 0.055 | AA6: 0.067285333 | AB6: 0.057 | AC6: 0.05 | AD6: 0.10729467 | AE6: 0.16018667 | AF6: 0.054 | AG6: 0.059 | AH6: 0.044 | AI6: 0.135432 | AJ6: 0.2084 | AK6: 0.255698 | AL6: 0.18351833 | AM6: 0.048 | AN6: 0.14446333 | AO6: 0.127508 | AP6: 0.052 | AQ6: 0.131294 | AR6: 0.046 | AS6: 0.46315667 | AT6: 0.053791333 | AU6: 0.180835 | AV6: 0.067937333 | AW6: 0.18039633 | AX6: 0.03 | AY6: 0.15904033 | AZ6: 0.091342333 | BA6: 0.17982 | BB6: 0.058 | BC6: 0.059569333 | BD6: 0.24658 | BE6: 0.058 | BF6: 0.064649667 | BG6: 0.05 | BH6: 0.171073 | BI6: 0.052657333 | BJ6: 0.053 | BK6: 0.055 | BL6: 0.14868367 | BM6: 0.1706 | BN6: 0.14694267 | BO6: 0.049636 | BP6: 0.05 | BQ6: 0.037 | BR6: 0.048 | BS6: 0.138308 | BT6: 0.112652 | BU6: 0.055 | BV6: 0.21504667 | BW6: 0.056 | BX6: 0.068130667 | BY6: 0.089308667 | BZ6: 0.044 | CA6: 0.048 | CB6: 0.10638473 | CC6: 8.1916243
A7: 6 | B7: 2.5 | C7: 0.14836267 | D7: 0.04 | E7: 0.06387 | F7: 0.17545333 | G7: 0.105673 | H7: 0.14870067 | I7: 0.147004 | J7: 0.10189567 | K7: 0.055 | L7: 0.061 | M7: 0.046 | N7: 0.13894333 | O7: 0.2066 | P7: 0.330918 | Q7: 0.048 | R7: 0.075274667 | S7: 0.071621 | T7: 0.120324 | U7: 0.19380393 | V7: 0.222701 | W7: 0.17366167 | X7: 0.092361667 | Y7: 0.05 | Z7: 0.055 | AA7: 0.099784 | AB7: 0.068307333 | AC7: 0.15382667 | AD7: 0.23369467 | AE7: 0.05 | AF7: 0.054 | AG7: 0.26837867 | AH7: 0.17499067 | AI7: 0.1675 | AJ7: 0.05 | AK7: 0.100446 | AL7: 0.257126 | AM7: 0.119142 | AN7: 0.059 | AO7: 0.047 | AP7: 0.052 | AQ7: 0.053 | AR7: 0.046 | AS7: 0.54207867 | AT7: 0.045395667 | AU7: 0.04 | AV7: 0.11778067 | AW7: 0.15688667 | AX7: 0.115436 | AY7: 0.139988 | AZ7: 0.33868467 | BA7: 0.112024 | BB7: 0.132778 | BC7: 0.043 | BD7: 0.064334 | BE7: 0.058 | BF7: 0.17713667 | BG7: 0.05 | BH7: 0.14095167 | BI7: 0.044 | BJ7: 0.183758 | BK7: 0.211541 | BL7: 0.15493667 | BM7: 0.057 | BN7: 0.141535 | BO7: 0.162666 | BP7: 0.05 | BQ7: 0.129872 | BR7: 0.048 | BS7: 0.05 | BT7: 0.16441467 | BU7: 0.09829 | BV7: 0.051 | BW7: 0.16771533 | BX7: 0.21330667 | BY7: 0.36596867 | BZ7: 0.044 | CA7: 0.048 | CB7: 0.12450446 | CC7: 9.5868433
A8: 7 | B8: 3 | C8: 0.278864 | D8: 0.18967333 | E8: 0.11935 | F8: 0.057 | G8: 0.076717 | H8: 0.31450933 | I8: 0.19713267 | J8: 0.248913 | K8: 0.055 | L8: 0.20999333 | M8: 0.046 | N8: 0.048 | O8: 0.06656 | P8: 0.060012667 | Q8: 0.062867333 | R8: 0.181236 | S8: 0.12713333 | T8: 0.268468 | U8: 0.159635 | V8: 0.107955 | W8: 0.20930133 | X8: 0.051 | Y8: 0.05 | Z8: 0.055 | AA8: 0.099784 | AB8: 0.158766 | AC8: 0.05 | AD8: 0.099824 | AE8: 0.20798433 | AF8: 0.054 | AG8: 0.070384 | AH8: 0.16982 | AI8: 0.160576 | AJ8: 0.2084 | AK8: 0.318598 | AL8: 0.22337667 | AM8: 0.14577333 | AN8: 0.18525333 | AO8: 0.047 | AP8: 0.052 | AQ8: 0.105196 | AR8: 0.046 | AS8: 0.21025333 | AT8: 0.213309 | AU8: 0.1913 | AV8: 0.15636 | AW8: 0.13150533 | AX8: 0.076004 | AY8: 0.21305933 | AZ8: 0.041 | BA8: 0.084012 | BB8: 0.058 | BC8: 0.043 | BD8: 0.147936 | BE8: 0.123988 | BF8: 0.211694 | BG8: 0.152728 | BH8: 0.111568 | BI8: 0.065643333 | BJ8: 0.082057333 | BK8: 0.062454333 | BL8: 0.19250267 | BM8: 0.22361333 | BN8: 0.15277833 | BO8: 0.078422667 | BP8: 0.05 | BQ8: 0.11439333 | BR8: 0.048 | BS8: 0.211898 | BT8: 0.13186933 | BU8: 0.17044 | BV8: 0.35130667 | BW8: 0.056 | BX8: 0.052 | BY8: 0.22318867 | BZ8: 0.044 | CA8: 0.048 | CB8: 0.1320434 | CC8: 10.167342
A9: 8 | B9: 3.5 | C9: 0.046 | D9: 0.04 | E9: 0.05 | F9: 0.163608 | G9: 0.192541 | H9: 0.094586 | I9: 0.053 | J9: 0.095661333 | K9: 0.055 | L9: 0.075899333 | M9: 0.046 | N9: 0.175761 | O9: 0.051 | P9: 0.17494667 | Q9: 0.19667333 | R9: 0.045 | S9: 0.22499333 | T9: 0.054 | U9: 0.047 | V9: 0.28117467 | W9: 0.247892 | X9: 0.079635 | Y9: 0.05 | Z9: 0.055 | AA9: 0.058 | AB9: 0.057 | AC9: 0.05 | AD9: 0.166732 | AE9: 0.17307567 | AF9: 0.054 | AG9: 0.081768 | AH9: 0.051359333 | AI9: 0.12405467 | AJ9: 0.05 | AK9: 0.145192 | AL9: 0.153893 | AM9: 0.051952333 | AN9: 0.059 | AO9: 0.047 | AP9: 0.052 | AQ9: 0.079098 | AR9: 0.046 | AS9: 0.139845 | AT9: 0.037 | AU9: 0.05513 | AV9: 0.097843333 | AW9: 0.20983 | AX9: 0.082576 | AY9: 0.22497867 | AZ9: 0.22117833 | BA9: 0.136483 | BB9: 0.058 | BC9: 0.117562 | BD9: 0.162978 | BE9: 0.058 | BF9: 0.080038333 | BG9: 0.13560667 | BH9: 0.154175 | BI9: 0.10027267 | BJ9: 0.126014 | BK9: 0.18568067 | BL9: 0.235668 | BM9: 0.057 | BN9: 0.054 | BO9: 0.063987 | BP9: 0.05 | BQ9: 0.037 | BR9: 0.048 | BS9: 0.05 | BT9: 0.154806 | BU9: 0.055 | BV9: 0.051 | BW9: 0.056 | BX9: 0.15684933 | BY9: 0.234801 | BZ9: 0.044 | CA9: 0.048 | CB9: 0.10227013 | CC9: 7.8747997
A10: 9 | B10: 4 | C10: 0.14448067 | D10: 0.12164 | E10: 0.05 | F10: 0.068845333 | G10: 0.055 | H10: 0.20735433 | I10: 0.17833867 | J10: 0.23021 | K10: 0.055 | L10: 0.061 | M10: 0.046 | N10: 0.23120767 | O10: 0.22216 | P10: 0.052 | Q10: 0.048 | R10: 0.21151067 | S10: 0.064414 | T10: 0.26109867 | U10: 0.212198 | V10: 0.16600533 | W10: 0.183274 | X10: 0.19055067 | Y10: 0.05 | Z10: 0.055 | AA10: 0.141568 | AB10: 0.17007333 | AC10: 0.05 | AD10: 0.18546333 | AE10: 0.19462 | AF10: 0.054 | AG10: 0.150072 | AH10: 0.26549133 | AI10: 0.20402133 | AJ10: 0.1652 | AK10: 0.165646 | AL10: 0.12513793 | AM10: 0.212963 | AN10: 0.172628 | AO10: 0.047 | AP10: 0.052 | AQ10: 0.053 | AR10: 0.046 | AS10: 0.074615 | AT10: 0.22170467 | AU10: 0.14591 | AV10: 0.095614667 | AW10: 0.123942 | AX10: 0.108864 | AY10: 0.082087667 | AZ10: 0.18813 | BA10: 0.099337 | BB10: 0.120315 | BC10: 0.043 | BD10: 0.063984 | BE10: 0.058 | BF10: 0.11849967 | BG10: 0.09762 | BH10: 0.10128167 | BI10: 0.044 | BJ10: 0.15470067 | BK10: 0.15190633 | BL10: 0.21156633 | BM10: 0.057 | BN10: 0.14694267 | BO10: 0.12528567 | BP10: 0.05 | BQ10: 0.20726533 | BR10: 0.075457667 | BS10: 0.15304567 | BT10: 0.141478 | BU10: 0.21373 | BV10: 0.29911 | BW10: 0.056 | BX10: 0.124588 | BY10: 0.33478233 | BZ10: 0.044 | CA10: 0.048 | CB10: 0.12989528 | CC10: 10.001936
A11: 10 | B11: 4.5 | C11: 0.21287 | D11: 0.10803333 | E11: 0.05 | F11: 0.163608 | G11: 0.055 | H11: 0.21526967 | I11: 0.165798 | J11: 0.12059867 | K11: 0.055 | L11: 0.22489267 | M11: 0.046 | N11: 0.057094333 | O11: 0.051 | P11: 0.216324 | Q11: 0.19667333 | R11: 0.045 | S11: 0.15798667 | T11: 0.12769333 | U11: 0.047 | V11: 0.10312 | W11: 0.19826767 | X11: 0.101381 | Y11: 0.05 | Z11: 0.055 | AA11: 0.058 | AB11: 0.057 | AC11: 0.05 | AD11: 0.066206 | AE11: 0.108708 | AF11: 0.054 | AG11: 0.059 | AH11: 0.07196 | AI11: 0.06 | AJ11: 0.0932 | AK11: 0.058 | AL11: 0.22337667 | AM11: 0.048 | AN11: 0.17942533 | AO11: 0.047 | AP11: 0.052 | AQ11: 0.074748333 | AR11: 0.046 | AS11: 0.113753 | AT11: 0.037 | AU11: 0.205976 | AV11: 0.14862 | AW11: 0.20226667 | AX11: 0.98764333 | AY11: 0.25688633 | AZ11: 0.061715 | BA11: 0.201946 | BB11: 0.070463 | BC11: 0.043 | BD11: 0.20915133 | BE11: 0.123988 | BF11: 0.056 | BG11: 0.25933667 | BH11: 0.114505 | BI11: 0.065643333 | BJ11: 0.11111467 | BK11: 0.055 | BL11: 0.12938567 | BM11: 0.10244 | BN11: 0.14737067 | BO11: 0.041 | BP11: 0.05 | BQ11: 0.037 | BR11: 0.048 | BS11: 0.116231 | BT11: 0.055 | BU11: 0.055 | BV11: 0.10319667 | BW11: 0.16771533 | BX11: 0.100392 | BY11: 0.189668 | BZ11: 0.044 | CA11: 0.048 | CB11: 0.11673562 | CC11: 8.9886427
A12: 11 | B12: 5 | C12: 0.069292 | D12: 0.046803333 | E12: 0.05 | F12: 0.068845333 | G12: 0.055 | H12: 0.054 | I12: 0.100002 | J12: 0.14916367 | K12: 0.055 | L12: 0.061 | M12: 0.046 | N12: 0.33324033 | O12: 0.17548 | P12: 0.21518247 | Q12: 0.062867333 | R12: 0.045 | S12: 0.208554 | T12: 0.090846667 | U12: 0.092054 | V12: 0.33519333 | W12: 0.16078733 | X12: 0.063726667 | Y12: 0.05 | Z12: 0.055 | AA12: 0.058 | AB12: 0.13049767 | AC12: 0.065574 | AD12: 0.122236 | AE12: 0.127732 | AF12: 0.054 | AG12: 0.16592267 | AH12: 0.073437333 | AI12: 0.06 | AJ12: 0.122 | AK12: 0.219544 | AL12: 0.210156 | AM12: 0.14577333 | AN12: 0.077938 | AO12: 0.078308667 | AP12: 0.052 | AQ12: 0.10954567 | AR12: 0.046 | AS12: 0.100707 | AT12: 0.17473927 | AU12: 0.081977333 | AV12: 0.137718 | AW12: 0.10665 | AX12: 0.24377333 | AY12: 0.147064 | AZ12: 0.12799167 | BA12: 0.11791 | BB12: 0.058 | BC12: 0.117562 | BD12: 0.073778667 | BE12: 0.058 | BF12: 0.33283067 | BG12: 0.05 | BH12: 0.19751667 | BI12: 0.10027267 | BJ12: 0.126014 | BK12: 0.055 | BL12: 0.126253 | BM12: 0.17817333 | BN12: 0.061733333 | BO12: 0.20008867 | BP12: 0.05 | BQ12: 0.044739333 | BR12: 0.048 | BS12: 0.05 | BT12: 0.055 | BU12: 0.055 | BV12: 0.051 | BW12: 0.056 | BX12: 0.18104533 | BY12: 0.142282 | BZ12: 0.044 | CA12: 0.048 | CB12: 0.10857823 | CC12: 8.3605241
A13: 12 | B13: 5.5 | C13: 0.28208833 | D13: 0.18287 | E13: 0.13322 | F13: 0.057 | G13: 0.141868 | H13: 0.26039467 | I13: 0.24413467 | J13: 0.15698367 | K13: 0.055 | L13: 0.061 | M13: 0.046 | N13: 0.064634 | O13: 0.09768 | P13: 0.080582867 | Q13: 0.048 | R13: 0.21151067 | S13: 0.09628 | T13: 0.29794533 | U13: 0.167144 | V13: 0.049 | W13: 0.12414433 | X13: 0.10190667 | Y13: 0.05 | Z13: 0.097111 | AA13: 0.058 | AB13: 0.096575667 | AC13: 0.13825267 | AD13: 0.21875333 | AE13: 0.05 | AF13: 0.069966667 | AG13: 0.059 | AH13: 0.27137333 | AI13: 0.268076 | AJ13: 0.1364 | AK13: 0.190718 | AL13: 0.10294167 | AM13: 0.048 | AN13: 0.16631533 | AO13: 0.096199333 | AP13: 0.052 | AQ13: 0.053 | AR13: 0.046 | AS13: 0.042 | AT13: 0.112561 | AU13: 0.17617 | AV13: 0.06348 | AW13: 0.083418667 | AX13: 0.03 | AY13: 0.22815733 | AZ13: 0.30203633 | BA13: 0.140036 | BB13: 0.058 | BC13: 0.043 | BD13: 0.036 | BE13: 0.109324 | BF13: 0.056 | BG13: 0.298396 | BH13: 0.055 | BI13: 0.078629333 | BJ13: 0.21281533 | BK13: 0.19663233 | BL13: 0.157921 | BM13: 0.057 | BN13: 0.234864 | BO13: 0.041 | BP13: 0.05 | BQ13: 0.199526 | BR13: 0.048 | BS13: 0.211898 | BT13: 0.154806 | BU13: 0.192085 | BV13: 0.26826333 | BW13: 0.056 | BX13: 0.052 | BY13: 0.306537 | BZ13: 0.044 | CA13: 0.048 | CB13: 0.12560554 | CC13: 9.6716269
... A49: 48 | B49: 23.5 | C49: 0.53206767 | D49: 0.10803333 | E49: 0.3110496 | F49: 0.13991733 | G49: 0.185302 | H49: 0.21694833 | I49: 0.85625733 | J49: 0.23086167 | K49: 0.055 | L49: 0.16529533 | M49: 0.50397333 | N49: 0.626335 | O49: 0.43429833 | P49: 0.068025333 | Q49: 0.048 | R49: 0.045 | S49: 0.61599767 | T49: 0.647131 | U49: 0.55700967 | V49: 0.186949 | W49: 0.061982 | X49: 0.16664667 | Y49: 0.34082667 | Z49: 0.055 | AA49: 0.058 | AB49: 0.70403333 | AC49: 0.13825267 | AD49: 0.44712333 | AE49: 0.0579092 | AF49: 0.054 | AG49: 0.16534667 | AH49: 0.11759333 | AI49: 0.142356 | AJ49: 0.10203333 | AK49: 0.28571633 | AL49: 0.048 | AM49: 0.54701067 | AN49: 0.059 | AO49: 0.44195533 | AP49: 0.27930767 | AQ49: 0.131294 | AR49: 0.046 | AS49: 0.3368 | AT49: 0.037 | AU49: 0.28540867 | AV49: 0.16162667 | AW49: 0.091523333 | AX49: 0.03 | AY49: 0.926359 | AZ49: 0.19125833 | BA49: 0.070006 | BB49: 1.433289 | BC49: 0.28870267 | BD49: 0.274914 | BE49: 0.123988 | BF49: 0.099269 | BG49: 0.075682 | BH49: 0.11817967 | BI49: 0.044 | BJ49: 0.24932233 | BK49: 0.687666 | BL49: 0.66742733 | BM49: 0.057 | BN49: 0.094849667 | BO49: 0.15115133 | BP49: 0.312858 | BQ49: 0.75672767 | BR49: 0.206104 | BS49: 0.204539 | BT49: 0.42261233 | BU49: 0.192085 | BV49: 0.40739333 | BW49: 0.62400733 | BX49: 0.052 | BY49: 0.67848033 | BZ49: 0.044 | CA49: 0.51275033 | CB49: 0.28430934 | CC49: 21.891819

Sheet PV_kW
A1: period | B1: hour | C1: BES_TR1_one223_B | D1: BES_TR1_one313_A | E1: BES_TR1_one320_B | F1: BES_TR1_one321_C | G1: BES_TR1_one346_C | H1: BES_TR1_one366_B | I1: BES_TR1_one375_C | J1: BES_TR1_one410_B | K1: BES_TR1_one50_A | L1: BES_TR1_one423_B | M1: BES_TR1_one469_A | N1: BES_TR1_one480_A | O1: BES_TR1_one482_B | P1: BES_TR1_one521_C | Q1: BES_TR1_one528_C | R1: BES_TR1_one537_A | S1: BES_TR1_one61_A | T1: BES_TR1_one544_A | U1: BES_TR1_one552_B | V1: BES_TR1_one559_C | W1: BES_TR1_one560_C | X1: BES_TR1_one605_A | Y1: BES_TR1_one617_A | Z1: BES_TR1_one73_A | AA1: BES_TR1_one76_A | AB1: BES_TR1_six64_A | AC1: BES_TR1_six154_C | AD1: BES_TR1_six173_C | AE1: BES_TR1_six186_A | AF1: BES_TR1_six191_B | AG1: BES_TR1_six249_B | AH1: BES_TR1_six254_B | AI1: BES_TR1_six269_C | AJ1: BES_TR1_six68_C | AK1: BES_TR1_six289_C | AL1: BES_TR1_six317_C | AM1: BES_TR1_six326_A | AN1: BES_TR1_six329_A | AO1: BES_TR1_six342_A | AP1: BES_TR1_six349_A | AQ1: BES_TR1_six350_B | AR1: BES_TR1_six378_A | AS1: BES_TR1_six75_A | AT1: BES_TR1_six385_B | AU1: BES_TR1_six387_A | AV1: BES_TR1_six410_A | AW1: BES_TR1_six431_C | AX1: BES_TR1_six441_A | AY1: BES_TR1_six484_B | AZ1: BES_TR1_six501_A | BA1: BES_TR1_six512_B | BB1: BES_TR1_six518_B | BC1: BES_TR1_six595_B | BD1: BES_TR1_six646_B | BE1: BES_TR1_six699_C | BF1: BES_TR1_six718_C | BG1: BES_TR1_six721_A | BH1: BES_TR1_six723_B | BI1: BES_TR1_six784_B | BJ1: BES_TR1_six90_B | BK1: BES_TR1_six807_A | BL1: BES_TR1_six852_B | BM1: BES_TR1_six860_C | BN1: BES_TR1_six869_C | BO1: BES_TR1_six885_A | BP1: BES_TR1_six909_C | BQ1: BES_TR1_six105_A | BR1: BES_TR1_six914_A | BS1: BES_TR1_six945_C | BT1: BES_TR1_six952_A | BU1: BES_TR1_six967_B | BV1: BES_TR1_six990_B | BW1: BES_TR1_six1006_C | BX1: BES_TR1_six1020_A | BY1: BES_TR1_six1025_B | BZ1: BES_TR1_six1064_C | CA1: BES_TR1_six128_B | CB1: fleet_average | CC1: fleet_total
A2: 1 | B2: 0 | C2: 0 | D2: 0 | E2: 0 | F2: 0 | G2: 0 | H2: 0 | I2: 0 | J2: 0 | K2: 0 | L2: 0 | M2: 0 | N2: 0 | O2: 0 | P2: 0 | Q2: 0 | R2: 0 | S2: 0 | T2: 0 | U2: 0 | V2: 0 | W2: 0 | X2: 0 | Y2: 0 | Z2: 0 | AA2: 0 | AB2: 0 | AC2: 0 | AD2: 0 | AE2: 0 | AF2: 0 | AG2: 0 | AH2: 0 | AI2: 0 | AJ2: 0 | AK2: 0 | AL2: 0 | AM2: 0 | AN2: 0 | AO2: 0 | AP2: 0 | AQ2: 0 | AR2: 0 | AS2: 0 | AT2: 0 | AU2: 0 | AV2: 0 | AW2: 0 | AX2: 0 | AY2: 0 | AZ2: 0 | BA2: 0 | BB2: 0 | BC2: 0 | BD2: 0 | BE2: 0 | BF2: 0 | BG2: 0 | BH2: 0 | BI2: 0 | BJ2: 0 | BK2: 0 | BL2: 0 | BM2: 0 | BN2: 0 | BO2: 0 | BP2: 0 | BQ2: 0 | BR2: 0 | BS2: 0 | BT2: 0 | BU2: 0 | BV2: 0 | BW2: 0 | BX2: 0 | BY2: 0 | BZ2: 0 | CA2: 0 | CB2: 0 | CC2: 0
A3: 2 | B3: 0.5 | C3: 0 | D3: 0 | E3: 0 | F3: 0 | G3: 0 | H3: 0 | I3: 0 | J3: 0 | K3: 0 | L3: 0 | M3: 0 | N3: 0 | O3: 0 | P3: 0 | Q3: 0 | R3: 0 | S3: 0 | T3: 0 | U3: 0 | V3: 0 | W3: 0 | X3: 0 | Y3: 0 | Z3: 0 | AA3: 0 | AB3: 0 | AC3: 0 | AD3: 0 | AE3: 0 | AF3: 0 | AG3: 0 | AH3: 0 | AI3: 0 | AJ3: 0 | AK3: 0 | AL3: 0 | AM3: 0 | AN3: 0 | AO3: 0 | AP3: 0 | AQ3: 0 | AR3: 0 | AS3: 0 | AT3: 0 | AU3: 0 | AV3: 0 | AW3: 0 | AX3: 0 | AY3: 0 | AZ3: 0 | BA3: 0 | BB3: 0 | BC3: 0 | BD3: 0 | BE3: 0 | BF3: 0 | BG3: 0 | BH3: 0 | BI3: 0 | BJ3: 0 | BK3: 0 | BL3: 0 | BM3: 0 | BN3: 0 | BO3: 0 | BP3: 0 | BQ3: 0 | BR3: 0 | BS3: 0 | BT3: 0 | BU3: 0 | BV3: 0 | BW3: 0 | BX3: 0 | BY3: 0 | BZ3: 0 | CA3: 0 | CB3: 0 | CC3: 0
A4: 3 | B4: 1 | C4: 0 | D4: 0 | E4: 0 | F4: 0 | G4: 0 | H4: 0 | I4: 0 | J4: 0 | K4: 0 | L4: 0 | M4: 0 | N4: 0 | O4: 0 | P4: 0 | Q4: 0 | R4: 0 | S4: 0 | T4: 0 | U4: 0 | V4: 0 | W4: 0 | X4: 0 | Y4: 0 | Z4: 0 | AA4: 0 | AB4: 0 | AC4: 0 | AD4: 0 | AE4: 0 | AF4: 0 | AG4: 0 | AH4: 0 | AI4: 0 | AJ4: 0 | AK4: 0 | AL4: 0 | AM4: 0 | AN4: 0 | AO4: 0 | AP4: 0 | AQ4: 0 | AR4: 0 | AS4: 0 | AT4: 0 | AU4: 0 | AV4: 0 | AW4: 0 | AX4: 0 | AY4: 0 | AZ4: 0 | BA4: 0 | BB4: 0 | BC4: 0 | BD4: 0 | BE4: 0 | BF4: 0 | BG4: 0 | BH4: 0 | BI4: 0 | BJ4: 0 | BK4: 0 | BL4: 0 | BM4: 0 | BN4: 0 | BO4: 0 | BP4: 0 | BQ4: 0 | BR4: 0 | BS4: 0 | BT4: 0 | BU4: 0 | BV4: 0 | BW4: 0 | BX4: 0 | BY4: 0 | BZ4: 0 | CA4: 0 | CB4: 0 | CC4: 0
A5: 4 | B5: 1.5 | C5: 0 | D5: 0 | E5: 0 | F5: 0 | G5: 0 | H5: 0 | I5: 0 | J5: 0 | K5: 0 | L5: 0 | M5: 0 | N5: 0 | O5: 0 | P5: 0 | Q5: 0 | R5: 0 | S5: 0 | T5: 0 | U5: 0 | V5: 0 | W5: 0 | X5: 0 | Y5: 0 | Z5: 0 | AA5: 0 | AB5: 0 | AC5: 0 | AD5: 0 | AE5: 0 | AF5: 0 | AG5: 0 | AH5: 0 | AI5: 0 | AJ5: 0 | AK5: 0 | AL5: 0 | AM5: 0 | AN5: 0 | AO5: 0 | AP5: 0 | AQ5: 0 | AR5: 0 | AS5: 0 | AT5: 0 | AU5: 0 | AV5: 0 | AW5: 0 | AX5: 0 | AY5: 0 | AZ5: 0 | BA5: 0 | BB5: 0 | BC5: 0 | BD5: 0 | BE5: 0 | BF5: 0 | BG5: 0 | BH5: 0 | BI5: 0 | BJ5: 0 | BK5: 0 | BL5: 0 | BM5: 0 | BN5: 0 | BO5: 0 | BP5: 0 | BQ5: 0 | BR5: 0 | BS5: 0 | BT5: 0 | BU5: 0 | BV5: 0 | BW5: 0 | BX5: 0 | BY5: 0 | BZ5: 0 | CA5: 0 | CB5: 0 | CC5: 0
A6: 5 | B6: 2 | C6: 0 | D6: 0 | E6: 0 | F6: 0 | G6: 0 | H6: 0 | I6: 0 | J6: 0 | K6: 0 | L6: 0 | M6: 0 | N6: 0 | O6: 0 | P6: 0 | Q6: 0 | R6: 0 | S6: 0 | T6: 0 | U6: 0 | V6: 0 | W6: 0 | X6: 0 | Y6: 0 | Z6: 0 | AA6: 0 | AB6: 0 | AC6: 0 | AD6: 0 | AE6: 0 | AF6: 0 | AG6: 0 | AH6: 0 | AI6: 0 | AJ6: 0 | AK6: 0 | AL6: 0 | AM6: 0 | AN6: 0 | AO6: 0 | AP6: 0 | AQ6: 0 | AR6: 0 | AS6: 0 | AT6: 0 | AU6: 0 | AV6: 0 | AW6: 0 | AX6: 0 | AY6: 0 | AZ6: 0 | BA6: 0 | BB6: 0 | BC6: 0 | BD6: 0 | BE6: 0 | BF6: 0 | BG6: 0 | BH6: 0 | BI6: 0 | BJ6: 0 | BK6: 0 | BL6: 0 | BM6: 0 | BN6: 0 | BO6: 0 | BP6: 0 | BQ6: 0 | BR6: 0 | BS6: 0 | BT6: 0 | BU6: 0 | BV6: 0 | BW6: 0 | BX6: 0 | BY6: 0 | BZ6: 0 | CA6: 0 | CB6: 0 | CC6: 0
A7: 6 | B7: 2.5 | C7: 0 | D7: 0 | E7: 0 | F7: 0 | G7: 0 | H7: 0 | I7: 0 | J7: 0 | K7: 0 | L7: 0 | M7: 0 | N7: 0 | O7: 0 | P7: 0 | Q7: 0 | R7: 0 | S7: 0 | T7: 0 | U7: 0 | V7: 0 | W7: 0 | X7: 0 | Y7: 0 | Z7: 0 | AA7: 0 | AB7: 0 | AC7: 0 | AD7: 0 | AE7: 0 | AF7: 0 | AG7: 0 | AH7: 0 | AI7: 0 | AJ7: 0 | AK7: 0 | AL7: 0 | AM7: 0 | AN7: 0 | AO7: 0 | AP7: 0 | AQ7: 0 | AR7: 0 | AS7: 0 | AT7: 0 | AU7: 0 | AV7: 0 | AW7: 0 | AX7: 0 | AY7: 0 | AZ7: 0 | BA7: 0 | BB7: 0 | BC7: 0 | BD7: 0 | BE7: 0 | BF7: 0 | BG7: 0 | BH7: 0 | BI7: 0 | BJ7: 0 | BK7: 0 | BL7: 0 | BM7: 0 | BN7: 0 | BO7: 0 | BP7: 0 | BQ7: 0 | BR7: 0 | BS7: 0 | BT7: 0 | BU7: 0 | BV7: 0 | BW7: 0 | BX7: 0 | BY7: 0 | BZ7: 0 | CA7: 0 | CB7: 0 | CC7: 0
A8: 7 | B8: 3 | C8: 0 | D8: 0 | E8: 0 | F8: 0 | G8: 0 | H8: 0 | I8: 0 | J8: 0 | K8: 0 | L8: 0 | M8: 0 | N8: 0 | O8: 0 | P8: 0 | Q8: 0 | R8: 0 | S8: 0 | T8: 0 | U8: 0 | V8: 0 | W8: 0 | X8: 0 | Y8: 0 | Z8: 0 | AA8: 0 | AB8: 0 | AC8: 0 | AD8: 0 | AE8: 0 | AF8: 0 | AG8: 0 | AH8: 0 | AI8: 0 | AJ8: 0 | AK8: 0 | AL8: 0 | AM8: 0 | AN8: 0 | AO8: 0 | AP8: 0 | AQ8: 0 | AR8: 0 | AS8: 0 | AT8: 0 | AU8: 0 | AV8: 0 | AW8: 0 | AX8: 0 | AY8: 0 | AZ8: 0 | BA8: 0 | BB8: 0 | BC8: 0 | BD8: 0 | BE8: 0 | BF8: 0 | BG8: 0 | BH8: 0 | BI8: 0 | BJ8: 0 | BK8: 0 | BL8: 0 | BM8: 0 | BN8: 0 | BO8: 0 | BP8: 0 | BQ8: 0 | BR8: 0 | BS8: 0 | BT8: 0 | BU8: 0 | BV8: 0 | BW8: 0 | BX8: 0 | BY8: 0 | BZ8: 0 | CA8: 0 | CB8: 0 | CC8: 0
A9: 8 | B9: 3.5 | C9: 0.0034408035 | D9: 0.0034408035 | E9: 0.0017204017 | F9: 0.0034408035 | G9: 0.0025806026 | H9: 0.0017204017 | I9: 0.0021505022 | J9: 0.0021505022 | K9: 0.0017204017 | L9: 0.0017204017 | M9: 0.0025806026 | N9: 0.0017204017 | O9: 0.0034408035 | P9: 0.0021505022 | Q9: 0.0021505022 | R9: 0.0021505022 | S9: 0.0034408035 | T9: 0.0034408035 | U9: 0.003010703 | V9: 0.0017204017 | W9: 0.0034408035 | X9: 0.0021505022 | Y9: 0.0025806026 | Z9: 0.0025806026 | AA9: 0.003010703 | AB9: 0.0021505022 | AC9: 0.0034408035 | AD9: 0.0034408035 | AE9: 0.0017204017 | AF9: 0.0034408035 | AG9: 0.0034408035 | AH9: 0.0017204017 | AI9: 0.0025806026 | AJ9: 0.0012903013 | AK9: 0.0017204017 | AL9: 0.0021505022 | AM9: 0.0021505022 | AN9: 0.0021505022 | AO9: 0.0025806026 | AP9: 0.0021505022 | AQ9: 0.0034408035 | AR9: 0.0034408035 | AS9: 0.0025806026 | AT9: 0.0012903013 | AU9: 0.0012903013 | AV9: 0.0017204017 | AW9: 0.0021505022 | AX9: 0.0034408035 | AY9: 0.0025806026 | AZ9: 0.0025806026 | BA9: 0.003010703 | BB9: 0.0034408035 | BC9: 0.0021505022 | BD9: 0.0021505022 | BE9: 0.003010703 | BF9: 0.0012903013 | BG9: 0.0012903013 | BH9: 0.0034408035 | BI9: 0.0025806026 | BJ9: 0.0017204017 | BK9: 0.0017204017 | BL9: 0.0034408035 | BM9: 0.0034408035 | BN9: 0.0034408035 | BO9: 0.0017204017 | BP9: 0.0021505022 | BQ9: 0.0021505022 | BR9: 0.003010703 | BS9: 0.0034408035 | BT9: 0.0017204017 | BU9: 0.00086020087 | BV9: 0.0034408035 | BW9: 0.003010703 | BX9: 0.0034408035 | BY9: 0.0025806026 | BZ9: 0.00086020087 | CA9: 0.0025806026 | CB9: 0.0024856454 | CC9: 0.19139469
A10: 9 | B10: 4 | C10: 0.049734493 | D10: 0.049734493 | E10: 0.024867246 | F10: 0.049734493 | G10: 0.037300869 | H10: 0.024867246 | I10: 0.031084058 | J10: 0.031084058 | K10: 0.024867246 | L10: 0.024867246 | M10: 0.037300869 | N10: 0.024867246 | O10: 0.049734493 | P10: 0.031084058 | Q10: 0.031084058 | R10: 0.031084058 | S10: 0.049734493 | T10: 0.049734493 | U10: 0.043517681 | V10: 0.024867246 | W10: 0.049734493 | X10: 0.031084058 | Y10: 0.037300869 | Z10: 0.037300869 | AA10: 0.043517681 | AB10: 0.031084058 | AC10: 0.049734493 | AD10: 0.049734493 | AE10: 0.024867246 | AF10: 0.049734493 | AG10: 0.049734493 | AH10: 0.024867246 | AI10: 0.037300869 | AJ10: 0.018650435 | AK10: 0.024867246 | AL10: 0.031084058 | AM10: 0.031084058 | AN10: 0.031084058 | AO10: 0.037300869 | AP10: 0.031084058 | AQ10: 0.049734493 | AR10: 0.049734493 | AS10: 0.037300869 | AT10: 0.018650435 | AU10: 0.018650435 | AV10: 0.024867246 | AW10: 0.031084058 | AX10: 0.049734493 | AY10: 0.037300869 | AZ10: 0.037300869 | BA10: 0.043517681 | BB10: 0.049734493 | BC10: 0.031084058 | BD10: 0.031084058 | BE10: 0.043517681 | BF10: 0.018650435 | BG10: 0.018650435 | BH10: 0.049734493 | BI10: 0.037300869 | BJ10: 0.024867246 | BK10: 0.024867246 | BL10: 0.049734493 | BM10: 0.049734493 | BN10: 0.049734493 | BO10: 0.024867246 | BP10: 0.031084058 | BQ10: 0.031084058 | BR10: 0.043517681 | BS10: 0.049734493 | BT10: 0.024867246 | BU10: 0.012433623 | BV10: 0.049734493 | BW10: 0.043517681 | BX10: 0.049734493 | BY10: 0.037300869 | BZ10: 0.012433623 | CA10: 0.037300869 | CB10: 0.035928327 | CC10: 2.7664811
A11: 10 | B11: 4.5 | C11: 0.23257356 | D11: 0.23257356 | E11: 0.11628678 | F11: 0.23257356 | G11: 0.17443017 | H11: 0.11628678 | I11: 0.14535847 | J11: 0.14535847 | K11: 0.11628678 | L11: 0.11628678 | M11: 0.17443017 | N11: 0.11628678 | O11: 0.23257356 | P11: 0.14535847 | Q11: 0.14535847 | R11: 0.14535847 | S11: 0.23257356 | T11: 0.23257356 | U11: 0.20350186 | V11: 0.11628678 | W11: 0.23257356 | X11: 0.14535847 | Y11: 0.17443017 | Z11: 0.17443017 | AA11: 0.20350186 | AB11: 0.14535847 | AC11: 0.23257356 | AD11: 0.23257356 | AE11: 0.11628678 | AF11: 0.23257356 | AG11: 0.23257356 | AH11: 0.11628678 | AI11: 0.17443017 | AJ11: 0.087215084 | AK11: 0.11628678 | AL11: 0.14535847 | AM11: 0.14535847 | AN11: 0.14535847 | AO11: 0.17443017 | AP11: 0.14535847 | AQ11: 0.23257356 | AR11: 0.23257356 | AS11: 0.17443017 | AT11: 0.087215084 | AU11: 0.087215084 | AV11: 0.11628678 | AW11: 0.14535847 | AX11: 0.23257356 | AY11: 0.17443017 | AZ11: 0.17443017 | BA11: 0.20350186 | BB11: 0.23257356 | BC11: 0.14535847 | BD11: 0.14535847 | BE11: 0.20350186 | BF11: 0.087215084 | BG11: 0.087215084 | BH11: 0.23257356 | BI11: 0.17443017 | BJ11: 0.11628678 | BK11: 0.11628678 | BL11: 0.23257356 | BM11: 0.23257356 | BN11: 0.23257356 | BO11: 0.11628678 | BP11: 0.14535847 | BQ11: 0.14535847 | BR11: 0.20350186 | BS11: 0.23257356 | BT11: 0.11628678 | BU11: 0.058143389 | BV11: 0.23257356 | BW11: 0.20350186 | BX11: 0.23257356 | BY11: 0.17443017 | BZ11: 0.058143389 | CA11: 0.17443017 | CB11: 0.16801174 | CC11: 12.936904
A12: 11 | B12: 5 | C12: 0.46134029 | D12: 0.46134029 | E12: 0.23067014 | F12: 0.46134029 | G12: 0.34600522 | H12: 0.23067014 | I12: 0.28833768 | J12: 0.28833768 | K12: 0.23067014 | L12: 0.23067014 | M12: 0.34600522 | N12: 0.23067014 | O12: 0.46134029 | P12: 0.28833768 | Q12: 0.28833768 | R12: 0.28833768 | S12: 0.46134029 | T12: 0.46134029 | U12: 0.40367275 | V12: 0.23067014 | W12: 0.46134029 | X12: 0.28833768 | Y12: 0.34600522 | Z12: 0.34600522 | AA12: 0.40367275 | AB12: 0.28833768 | AC12: 0.46134029 | AD12: 0.46134029 | AE12: 0.23067014 | AF12: 0.46134029 | AG12: 0.46134029 | AH12: 0.23067014 | AI12: 0.34600522 | AJ12: 0.17300261 | AK12: 0.23067014 | AL12: 0.28833768 | AM12: 0.28833768 | AN12: 0.28833768 | AO12: 0.34600522 | AP12: 0.28833768 | AQ12: 0.46134029 | AR12: 0.46134029 | AS12: 0.34600522 | AT12: 0.17300261 | AU12: 0.17300261 | AV12: 0.23067014 | AW12: 0.28833768 | AX12: 0.46134029 | AY12: 0.34600522 | AZ12: 0.34600522 | BA12: 0.40367275 | BB12: 0.46134029 | BC12: 0.28833768 | BD12: 0.28833768 | BE12: 0.40367275 | BF12: 0.17300261 | BG12: 0.17300261 | BH12: 0.46134029 | BI12: 0.34600522 | BJ12: 0.23067014 | BK12: 0.23067014 | BL12: 0.46134029 | BM12: 0.46134029 | BN12: 0.46134029 | BO12: 0.23067014 | BP12: 0.28833768 | BQ12: 0.28833768 | BR12: 0.40367275 | BS12: 0.46134029 | BT12: 0.23067014 | BU12: 0.11533507 | BV12: 0.46134029 | BW12: 0.40367275 | BX12: 0.46134029 | BY12: 0.34600522 | BZ12: 0.11533507 | CA12: 0.34600522 | CB12: 0.33327342 | CC12: 25.662054
A13: 12 | B13: 5.5 | C13: 0.74185798 | D13: 0.74185798 | E13: 0.37092899 | F13: 0.74185798 | G13: 0.55639348 | H13: 0.37092899 | I13: 0.46366124 | J13: 0.46366124 | K13: 0.37092899 | L13: 0.37092899 | M13: 0.55639348 | N13: 0.37092899 | O13: 0.74185798 | P13: 0.46366124 | Q13: 0.46366124 | R13: 0.46366124 | S13: 0.74185798 | T13: 0.74185798 | U13: 0.64912573 | V13: 0.37092899 | W13: 0.74185798 | X13: 0.46366124 | Y13: 0.55639348 | Z13: 0.55639348 | AA13: 0.64912573 | AB13: 0.46366124 | AC13: 0.74185798 | AD13: 0.74185798 | AE13: 0.37092899 | AF13: 0.74185798 | AG13: 0.74185798 | AH13: 0.37092899 | AI13: 0.55639348 | AJ13: 0.27819674 | AK13: 0.37092899 | AL13: 0.46366124 | AM13: 0.46366124 | AN13: 0.46366124 | AO13: 0.55639348 | AP13: 0.46366124 | AQ13: 0.74185798 | AR13: 0.74185798 | AS13: 0.55639348 | AT13: 0.27819674 | AU13: 0.27819674 | AV13: 0.37092899 | AW13: 0.46366124 | AX13: 0.74185798 | AY13: 0.55639348 | AZ13: 0.55639348 | BA13: 0.64912573 | BB13: 0.74185798 | BC13: 0.46366124 | BD13: 0.46366124 | BE13: 0.64912573 | BF13: 0.27819674 | BG13: 0.27819674 | BH13: 0.74185798 | BI13: 0.55639348 | BJ13: 0.37092899 | BK13: 0.37092899 | BL13: 0.74185798 | BM13: 0.74185798 | BN13: 0.74185798 | BO13: 0.37092899 | BP13: 0.46366124 | BQ13: 0.46366124 | BR13: 0.64912573 | BS13: 0.74185798 | BT13: 0.37092899 | BU13: 0.18546449 | BV13: 0.74185798 | BW13: 0.64912573 | BX13: 0.74185798 | BY13: 0.55639348 | BZ13: 0.18546449 | CA13: 0.55639348 | CB13: 0.53592013 | CC13: 41.26585
... A49: 48 | B49: 23.5 | C49: 0 | D49: 0 | E49: 0 | F49: 0 | G49: 0 | H49: 0 | I49: 0 | J49: 0 | K49: 0 | L49: 0 | M49: 0 | N49: 0 | O49: 0 | P49: 0 | Q49: 0 | R49: 0 | S49: 0 | T49: 0 | U49: 0 | V49: 0 | W49: 0 | X49: 0 | Y49: 0 | Z49: 0 | AA49: 0 | AB49: 0 | AC49: 0 | AD49: 0 | AE49: 0 | AF49: 0 | AG49: 0 | AH49: 0 | AI49: 0 | AJ49: 0 | AK49: 0 | AL49: 0 | AM49: 0 | AN49: 0 | AO49: 0 | AP49: 0 | AQ49: 0 | AR49: 0 | AS49: 0 | AT49: 0 | AU49: 0 | AV49: 0 | AW49: 0 | AX49: 0 | AY49: 0 | AZ49: 0 | BA49: 0 | BB49: 0 | BC49: 0 | BD49: 0 | BE49: 0 | BF49: 0 | BG49: 0 | BH49: 0 | BI49: 0 | BJ49: 0 | BK49: 0 | BL49: 0 | BM49: 0 | BN49: 0 | BO49: 0 | BP49: 0 | BQ49: 0 | BR49: 0 | BS49: 0 | BT49: 0 | BU49: 0 | BV49: 0 | BW49: 0 | BX49: 0 | BY49: 0 | BZ49: 0 | CA49: 0 | CB49: 0 | CC49: 0

Sheet Charge_kW
