Workbook

Sheet ReadMe
A1: README
A2: Data behind the TR2 rolling-dispatch figures (SOC, demand/PV/dispatch, net, self-consumption, metrics histogram).
A3: Each quantity sheet: rows = 48 half-hour periods (with hour of day), columns = prosumers, plus fleet_average / fleet_total.
A4: Dispatch is the committed slot-1 execution of the rolling horizon (self-consumption baseline, Term 2 + Term 3).
A5: SOC is the realised state at the START of each step (fraction of capacity).
A6: net_kW = (demand - PV) + (charge - discharge); positive = import, negative = export.
A7: Regenerate: python build_workbook.py --force (see README.md for other transformers).

Sheet Summary
A1: quantity | B1: value
A2: run | B2: TR2 exact-QCP rolling (FOR_PolyS=0, FOR_LinearizeVmax=0), 48 steps, all Optimal
A3: source dispatch | B3: FOR_rolling_soc_TR2.csv
A4: source load/PV | B4: TR2_load_PV_48periods.xlsx
A5: prosumers | B5: 95
A6: PV generated kWh/day | B6: 2370.4
A7: demand kWh/day | B7: 666.4
A8: exported kWh/day | B8: 1638.2
A9: imported kWh/day | B9: 16.1
A10: SCR % (PV used locally) | B10: 30.9
A11: SSR % (demand met locally) | B11: 97.6
A12: prosumer-periods |net|<50W % | B12: 56.9
A13: SOC min/max over day | B13: 0.10 / 1.00
A14: simultaneous chg+dis rows | B14: 0

Sheet FleetAverage
A1: period | B1: hour | C1: demand_avg_kW | D1: PV_avg_kW | E1: charge_avg_kW | F1: discharge_avg_kW | G1: net_avg_kW | H1: SOC_avg_pct | I1: demand_total_kW | J1: PV_total_kW | K1: net_total_kW
A2: =Demand_kW!A2 -> 1 | B2: =Demand_kW!B2 -> 0 | C2: =AVERAGE(Demand_kW!$C2:$CS2) -> 0.2372935 | D2: =AVERAGE(PV_kW!$C2:$CS2) -> 0 | E2: =AVERAGE(Charge_kW!$C2:$CS2) -> 0 | F2: =AVERAGE(Discharge_kW!$C2:$CS2) -> 0.23728421 | G2: =C2-D2+E2-F2 -> 9.2912281e-06 | H2: =AVERAGE(SOC_pct!$C2:$CS2) -> 40 | I2: =SUM(Demand_kW!$C2:$CS2) -> 22.542883 | J2: =SUM(PV_kW!$C2:$CS2) -> 0 | K2: =I2-J2+SUM(Charge_kW!$C2:$CS2)-SUM(Discharge_kW!$C2:$CS2) -> 0.00088266667
A3: =Demand_kW!A3 -> 2 | B3: =Demand_kW!B3 -> 0.5 | C3: =AVERAGE(Demand_kW!$C3:$CS3) -> 0.21140078 | D3: =AVERAGE(PV_kW!$C3:$CS3) -> 0 | E3: =AVERAGE(Charge_kW!$C3:$CS3) -> 0 | F3: =AVERAGE(Discharge_kW!$C3:$CS3) -> 0.21016842 | G3: =C3-D3+E3-F3 -> 0.0012323579 | H3: =AVERAGE(SOC_pct!$C3:$CS3) -> 37.022328 | I3: =SUM(Demand_kW!$C3:$CS3) -> 20.083074 | J3: =SUM(PV_kW!$C3:$CS3) -> 0 | K3: =I3-J3+SUM(Charge_kW!$C3:$CS3)-SUM(Discharge_kW!$C3:$CS3) -> 0.117074
A4: =Demand_kW!A4 -> 3 | B4: =Demand_kW!B4 -> 1 | C4: =AVERAGE(Demand_kW!$C4:$CS4) -> 0.15961575 | D4: =AVERAGE(PV_kW!$C4:$CS4) -> 0 | E4: =AVERAGE(Charge_kW!$C4:$CS4) -> 0 | F4: =AVERAGE(Discharge_kW!$C4:$CS4) -> 0.15441053 | G4: =C4-D4+E4-F4 -> 0.0052052284 | H4: =AVERAGE(SOC_pct!$C4:$CS4) -> 34.384641 | I4: =SUM(Demand_kW!$C4:$CS4) -> 15.163497 | J4: =SUM(PV_kW!$C4:$CS4) -> 0 | K4: =I4-J4+SUM(Charge_kW!$C4:$CS4)-SUM(Discharge_kW!$C4:$CS4) -> 0.4944967
A5: =Demand_kW!A5 -> 4 | B5: =Demand_kW!B5 -> 1.5 | C5: =AVERAGE(Demand_kW!$C5:$CS5) -> 0.13979605 | D5: =AVERAGE(PV_kW!$C5:$CS5) -> 0 | E5: =AVERAGE(Charge_kW!$C5:$CS5) -> 0 | F5: =AVERAGE(Discharge_kW!$C5:$CS5) -> 0.12967368 | G5: =C5-D5+E5-F5 -> 0.010122361 | H5: =AVERAGE(SOC_pct!$C5:$CS5) -> 32.446777 | I5: =SUM(Demand_kW!$C5:$CS5) -> 13.280624 | J5: =SUM(PV_kW!$C5:$CS5) -> 0 | K5: =I5-J5+SUM(Charge_kW!$C5:$CS5)-SUM(Discharge_kW!$C5:$CS5) -> 0.96162433
A6: =Demand_kW!A6 -> 5 | B6: =Demand_kW!B6 -> 2 | C6: =AVERAGE(Demand_kW!$C6:$CS6) -> 0.13803694 | D6: =AVERAGE(PV_kW!$C6:$CS6) -> 0 | E6: =AVERAGE(Charge_kW!$C6:$CS6) -> 0 | F6: =AVERAGE(Discharge_kW!$C6:$CS6) -> 0.12770526 | G6: =C6-D6+E6-F6 -> 0.010331677 | H6: =AVERAGE(SOC_pct!$C6:$CS6) -> 30.819591 | I6: =SUM(Demand_kW!$C6:$CS6) -> 13.113509 | J6: =SUM(PV_kW!$C6:$CS6) -> 0 | K6: =I6-J6+SUM(Charge_kW!$C6:$CS6)-SUM(Discharge_kW!$C6:$CS6) -> 0.98150933
A7: =Demand_kW!A7 -> 6 | B7: =Demand_kW!B7 -> 2.5 | C7: =AVERAGE(Demand_kW!$C7:$CS7) -> 0.13469394 | D7: =AVERAGE(PV_kW!$C7:$CS7) -> 0 | E7: =AVERAGE(Charge_kW!$C7:$CS7) -> 0 | F7: =AVERAGE(Discharge_kW!$C7:$CS7) -> 0.12175789 | G7: =C7-D7+E7-F7 -> 0.012936042 | H7: =AVERAGE(SOC_pct!$C7:$CS7) -> 29.216692 | I7: =SUM(Demand_kW!$C7:$CS7) -> 12.795924 | J7: =SUM(PV_kW!$C7:$CS7) -> 0 | K7: =I7-J7+SUM(Charge_kW!$C7:$CS7)-SUM(Discharge_kW!$C7:$CS7) -> 1.228924
A8: =Demand_kW!A8 -> 7 | B8: =Demand_kW!B8 -> 3 | C8: =AVERAGE(Demand_kW!$C8:$CS8) -> 0.13106514 | D8: =AVERAGE(PV_kW!$C8:$CS8) -> 0 | E8: =AVERAGE(Charge_kW!$C8:$CS8) -> 0 | F8: =AVERAGE(Discharge_kW!$C8:$CS8) -> 0.10091579 | G8: =C8-D8+E8-F8 -> 0.030149354 | H8: =AVERAGE(SOC_pct!$C8:$CS8) -> 27.689062 | I8: =SUM(Demand_kW!$C8:$CS8) -> 12.451189 | J8: =SUM(PV_kW!$C8:$CS8) -> 0 | K8: =I8-J8+SUM(Charge_kW!$C8:$CS8)-SUM(Discharge_kW!$C8:$CS8) -> 2.8641887
A9: =Demand_kW!A9 -> 8 | B9: =Demand_kW!B9 -> 3.5 | C9: =AVERAGE(Demand_kW!$C9:$CS9) -> 0.12422709 | D9: =AVERAGE(PV_kW!$C9:$CS9) -> 0.0026575679 | E9: =AVERAGE(Charge_kW!$C9:$CS9) -> 0 | F9: =AVERAGE(Discharge_kW!$C9:$CS9) -> 0.11187368 | G9: =C9-D9+E9-F9 -> 0.0096958426 | H9: =AVERAGE(SOC_pct!$C9:$CS9) -> 26.422723 | I9: =SUM(Demand_kW!$C9:$CS9) -> 11.801574 | J9: =SUM(PV_kW!$C9:$CS9) -> 0.25246895 | K9: =I9-J9+SUM(Charge_kW!$C9:$CS9)-SUM(Discharge_kW!$C9:$CS9) -> 0.92110505
A10: =Demand_kW!A10 -> 9 | B10: =Demand_kW!B10 -> 4 | C10: =AVERAGE(Demand_kW!$C10:$CS10) -> 0.12011074 | D10: =AVERAGE(PV_kW!$C10:$CS10) -> 0.038413351 | E10: =AVERAGE(Charge_kW!$C10:$CS10) -> 0.00053684211 | F10: =AVERAGE(Discharge_kW!$C10:$CS10) -> 0.072518584 | G10: =C10-D10+E10-F10 -> 0.0097156501 | H10: =AVERAGE(SOC_pct!$C10:$CS10) -> 25.019641 | I10: =SUM(Demand_kW!$C10:$CS10) -> 11.410521 | J10: =SUM(PV_kW!$C10:$CS10) -> 3.6492684 | K10: =I10-J10+SUM(Charge_kW!$C10:$CS10)-SUM(Discharge_kW!$C10:$CS10) -> 0.92298676
A11: =Demand_kW!A11 -> 10 | B11: =Demand_kW!B11 -> 4.5 | C11: =AVERAGE(Demand_kW!$C11:$CS11) -> 0.10826529 | D11: =AVERAGE(PV_kW!$C11:$CS11) -> 0.17963247 | E11: =AVERAGE(Charge_kW!$C11:$CS11) -> 0.086557895 | F11: =AVERAGE(Discharge_kW!$C11:$CS11) -> 0.012726316 | G11: =C11-D11+E11-F11 -> 0.0024643973 | H11: =AVERAGE(SOC_pct!$C11:$CS11) -> 24.11516 | I11: =SUM(Demand_kW!$C11:$CS11) -> 10.285203 | J11: =SUM(PV_kW!$C11:$CS11) -> 17.065085 | K11: =I11-J11+SUM(Charge_kW!$C11:$CS11)-SUM(Discharge_kW!$C11:$CS11) -> 0.23411774
A12: =Demand_kW!A12 -> 11 | B12: =Demand_kW!B12 -> 5 | C12: =AVERAGE(Demand_kW!$C12:$CS12) -> 0.11527114 | D12: =AVERAGE(PV_kW!$C12:$CS12) -> 0.35632467 | E12: =AVERAGE(Charge_kW!$C12:$CS12) -> 0.24218947 | F12: =AVERAGE(Discharge_kW!$C12:$CS12) -> 0.0012105263 | G12: =C12-D12+E12-F12 -> -7.4582297e-05 | H12: =AVERAGE(SOC_pct!$C12:$CS12) -> 24.932734 | I12: =SUM(Demand_kW!$C12:$CS12) -> 10.950758 | J12: =SUM(PV_kW!$C12:$CS12) -> 33.850844 | K12: =I12-J12+SUM(Charge_kW!$C12:$CS12)-SUM(Discharge_kW!$C12:$CS12) -> -0.0070853182
A13: =Demand_kW!A13 -> 12 | B13: =Demand_kW!B13 -> 5.5 | C13: =AVERAGE(Demand_kW!$C13:$CS13) -> 0.11836403 | D13: =AVERAGE(PV_kW!$C13:$CS13) -> 0.57298767 | E13: =AVERAGE(Charge_kW!$C13:$CS13) -> 0.45467368 | F13: =AVERAGE(Discharge_kW!$C13:$CS13) -> 0 | G13: =C13-D13+E13-F13 -> 5.0037949e-05 | H13: =AVERAGE(SOC_pct!$C13:$CS13) -> 27.653683 | I13: =SUM(Demand_kW!$C13:$CS13) -> 11.244583 | J13: =SUM(PV_kW!$C13:$CS13) -> 54.433829 | K13: =I13-J13+SUM(Charge_kW!$C13:$CS13)-SUM(Discharge_kW!$C13:$CS13) -> 0.0047536052
... A49: =Demand_kW!A49 -> 48 | B49: =Demand_kW!B49 -> 23.5 | C49: =AVERAGE(Demand_kW!$C49:$CS49) -> 0.22125744 | D49: =AVERAGE(PV_kW!$C49:$CS49) -> 0 | E49: =AVERAGE(Charge_kW!$C49:$CS49) -> 0 | F49: =AVERAGE(Discharge_kW!$C49:$CS49) -> 0.18569474 | G49: =C49-D49+E49-F49 -> 0.035562698 | H49: =AVERAGE(SOC_pct!$C49:$CS49) -> 55.061212 | I49: =SUM(Demand_kW!$C49:$CS49) -> 21.019456 | J49: =SUM(PV_kW!$C49:$CS49) -> 0 | K49: =I49-J49+SUM(Charge_kW!$C49:$CS49)-SUM(Discharge_kW!$C49:$CS49) -> 3.3784563

Sheet SOC_pct
A1: period | B1: hour | C1: BES_TR2_three312_A | D1: BES_TR2_three321_B | E1: BES_TR2_three368_A | F1: BES_TR2_three388_A | G1: BES_TR2_three409_C | H1: BES_TR2_three478_B | I1: BES_TR2_three97_B | J1: BES_TR2_three133_C | K1: BES_TR2_three160_C | L1: BES_TR2_five58_C | M1: BES_TR2_five147_C | N1: BES_TR2_five149_A | O1: BES_TR2_five160_C | P1: BES_TR2_five170_A | Q1: BES_TR2_five177_A | R1: BES_TR2_five67_C | S1: BES_TR2_five243_B | T1: BES_TR2_five284_C | U1: BES_TR2_five285_B | V1: BES_TR2_five303_B | W1: BES_TR2_five324_B | X1: BES_TR2_five355_A | Y1: BES_TR2_five394_C | Z1: BES_TR2_five451_A | AA1: BES_TR2_five466_A | AB1: BES_TR2_five494_B | AC1: BES_TR2_five512_A | AD1: BES_TR2_five520_C | AE1: BES_TR2_five540_A | AF1: BES_TR2_five588_A | AG1: BES_TR2_five649_A | AH1: BES_TR2_five663_C | AI1: BES_TR2_five685_B | AJ1: BES_TR2_five695_A | AK1: BES_TR2_five704_A | AL1: BES_TR2_five733_C | AM1: BES_TR2_five117_B | AN1: BES_TR2_five778_B | AO1: BES_TR2_five799_C | AP1: BES_TR2_five801_C | AQ1: BES_TR2_five831_C | AR1: BES_TR2_five881_C | AS1: BES_TR2_five118_B | AT1: BES_TR2_six64_A | AU1: BES_TR2_six154_C | AV1: BES_TR2_six173_C | AW1: BES_TR2_six186_A | AX1: BES_TR2_six191_B | AY1: BES_TR2_six203_A | AZ1: BES_TR2_six232_C | BA1: BES_TR2_six238_A | BB1: BES_TR2_six249_B | BC1: BES_TR2_six254_B | BD1: BES_TR2_six269_C | BE1: BES_TR2_six289_C | BF1: BES_TR2_six317_C | BG1: BES_TR2_six326_A | BH1: BES_TR2_six329_A | BI1: BES_TR2_six342_A | BJ1: BES_TR2_six349_A | BK1: BES_TR2_six350_B | BL1: BES_TR2_six362_C | BM1: BES_TR2_six365_C | BN1: BES_TR2_six378_A | BO1: BES_TR2_six385_B | BP1: BES_TR2_six387_A | BQ1: BES_TR2_six392_C | BR1: BES_TR2_six410_A | BS1: BES_TR2_six431_C | BT1: BES_TR2_six484_B | BU1: BES_TR2_six512_B | BV1: BES_TR2_six518_B | BW1: BES_TR2_six523_C | BX1: BES_TR2_six571_C | BY1: BES_TR2_six583_A | BZ1: BES_TR2_six625_A | CA1: BES_TR2_six646_B | CB1: BES_TR2_six87_A | CC1: BES_TR2_six652_A | CD1: BES_TR2_six665_B | CE1: BES_TR2_six667_A | CF1: BES_TR2_six721_A | CG1: BES_TR2_six740_A | CH1: BES_TR2_six758_B | CI1: BES_TR2_six784_B | CJ1: BES_TR2_six799_B | CK1: BES_TR2_six807_A | CL1: BES_TR2_six885_A | CM1: BES_TR2_six894_B | CN1: BES_TR2_six914_A | CO1: BES_TR2_six921_B | CP1: BES_TR2_six929_A | CQ1: BES_TR2_six938_A | CR1: BES_TR2_six990_B | CS1: BES_TR2_six1020_A | CT1: fleet_average | CU1: fleet_total
A2: 1 | B2: 0 | C2: 40 | D2: 40 | E2: 40 | F2: 40 | G2: 40 | H2: 40 | I2: 40 | J2: 40 | K2: 40 | L2: 40 | M2: 40 | N2: 40 | O2: 40 | P2: 40 | Q2: 40 | R2: 40 | S2: 40 | T2: 40 | U2: 40 | V2: 40 | W2: 40 | X2: 40 | Y2: 40 | Z2: 40 | AA2: 40 | AB2: 40 | AC2: 40 | AD2: 40 | AE2: 40 | AF2: 40 | AG2: 40 | AH2: 40 | AI2: 40 | AJ2: 40 | AK2: 40 | AL2: 40 | AM2: 40 | AN2: 40 | AO2: 40 | AP2: 40 | AQ2: 40 | AR2: 40 | AS2: 40 | AT2: 40 | AU2: 40 | AV2: 40 | AW2: 40 | AX2: 40 | AY2: 40 | AZ2: 40 | BA2: 40 | BB2: 40 | BC2: 40 | BD2: 40 | BE2: 40 | BF2: 40 | BG2: 40 | BH2: 40 | BI2: 40 | BJ2: 40 | BK2: 40 | BL2: 40 | BM2: 40 | BN2: 40 | BO2: 40 | BP2: 40 | BQ2: 40 | BR2: 40 | BS2: 40 | BT2: 40 | BU2: 40 | BV2: 40 | BW2: 40 | BX2: 40 | BY2: 40 | BZ2: 40 | CA2: 40 | CB2: 40 | CC2: 40 | CD2: 40 | CE2: 40 | CF2: 40 | CG2: 40 | CH2: 40 | CI2: 40 | CJ2: 40 | CK2: 40 | CL2: 40 | CM2: 40 | CN2: 40 | CO2: 40 | CP2: 40 | CQ2: 40 | CR2: 40 | CS2: 40 | CT2: 40 | CU2: 3800
A3: 2 | B3: 0.5 | C3: 36.5939 | D3: 39.4604 | E3: 37.4153 | F3: 39.2847 | G3: 39.3224 | H3: 37.9733 | I3: 39.4228 | J3: 39.3045 | K3: 31.4953 | L3: 37.3305 | M3: 38.2148 | N3: 38.5059 | O3: 38.2603 | P3: 37.6121 | Q3: 39.3224 | R3: 38.816 | S3: 39.3726 | T3: 39.3726 | U3: 34.8571 | V3: 38.1338 | W3: 39.3851 | X3: 37.6797 | Y3: 20.3589 | Z3: 37.7171 | AA3: 39.3224 | AB3: 39.3224 | AC3: 36.774 | AD3: 38.9151 | AE3: 38.4395 | AF3: 36.4661 | AG3: 39.5483 | AH3: 37.3751 | AI3: 36.5882 | AJ3: 38.0234 | AK3: 31.1093 | AL3: 39.3475 | AM3: 39.3977 | AN3: 37.3177 | AO3: 29.2084 | AP3: 39.3349 | AQ3: 39.2722 | AR3: 39.3851 | AS3: 37.0521 | AT3: 36.5725 | AU3: 38.0404 | AV3: 33.3485 | AW3: 37.5893 | AX3: 37.9065 | AY3: 38.1937 | AZ3: 37.9094 | BA3: 39.5734 | BB3: 39.5232 | BC3: 34.9644 | BD3: 37.7621 | BE3: 32.3426 | BF3: 39.3977 | BG3: 38.1762 | BH3: 39.6361 | BI3: 35.3921 | BJ3: 34.5945 | BK3: 39.2166 | BL3: 39.4102 | BM3: 39.3977 | BN3: 37.9985 | BO3: 34.287 | BP3: 28.6891 | BQ3: 36.0669 | BR3: 30.5027 | BS3: 37.7689 | BT3: 39.5232 | BU3: 34.8652 | BV3: 38.5446 | BW3: 39.3977 | BX3: 35.1817 | BY3: 39.3224 | BZ3: 32.5501 | CA3: 37.3522 | CB3: 38.1804 | CC3: 38.042 | CD3: 39.3349 | CE3: 39.2973 | CF3: 31.1459 | CG3: 38.3043 | CH3: 39.3726 | CI3: 39.3851 | CJ3: 26.5668 | CK3: 32.8434 | CL3: 39.4228 | CM3: 39.235 | CN3: 38.9205 | CO3: 38.9682 | CP3: 30.2424 | CQ3: 37.4719 | CR3: 37.9396 | CS3: 34.0399 | CT3: 37.022328 | CU3: 3517.1212
A4: 3 | B4: 1 | C4: 35.5444 | D4: 36.807 | E4: 36.7126 | F4: 38.5695 | G4: 37.1662 | H4: 36.2218 | I4: 38.8455 | J4: 37.8551 | K4: 27.7624 | L4: 33.7658 | M4: 37.1218 | N4: 37.2495 | O4: 37.5826 | P4: 37.0223 | Q4: 37.6666 | R4: 36.939 | S4: 38.7451 | T4: 37.7538 | U4: 28.7594 | V4: 36.3381 | W4: 38.0053 | X4: 36.0729 | Y4: 19.6311 | Z4: 35.6956 | AA4: 36.9831 | AB4: 36.9587 | AC4: 36.0713 | AD4: 36.9631 | AE4: 37.1585 | AF4: 33.9148 | AG4: 37.6323 | AH4: 36.0771 | AI4: 35.9356 | AJ4: 37.4085 | AK4: 20.3663 | AL4: 38.695 | AM4: 36.5468 | AN4: 36.7404 | AO4: 21.1864 | AP4: 37.818 | AQ4: 38.5444 | AR4: 38.7702 | AS4: 34.5082 | AT4: 33.44 | AU4: 37.3628 | AV4: 28.7894 | AW4: 35.4035 | AX4: 34.6182 | AY4: 37.5788 | AZ4: 36.2931 | BA4: 39.1467 | BB4: 37.7882 | BC4: 27.915 | BD4: 36.4916 | BE4: 29.4504 | BF4: 38.7953 | BG4: 37.5864 | BH4: 39.2722 | BI4: 29.7812 | BJ4: 29.1092 | BK4: 36.8089 | BL4: 38.8204 | BM4: 38.7953 | BN4: 34.8652 | BO4: 28.296 | BP4: 18.7189 | BQ4: 35.4395 | BR4: 10 | BS4: 37.1164 | BT4: 39.0463 | BU4: 30.3886 | BV4: 36.7436 | BW4: 38.1368 | BX4: 34.5041 | BY4: 36.6185 | BZ4: 25.3666 | CA4: 36.7749 | CB4: 35.6926 | CC4: 34.3608 | CD4: 38.567 | CE4: 36.2773 | CF4: 29.4418 | CG4: 36.6424 | CH4: 36.5823 | CI4: 38.7702 | CJ4: 13.4783 | CK4: 23.902 | CL4: 37.4295 | CM4: 38.5785 | CN4: 36.9622 | CO4: 37.3971 | CP4: 21.8612 | CQ4: 36.832 | CR4: 37.3373 | CS4: 29.0543 | CT4: 34.384641 | CU4: 3266.5409
A5: 4 | B5: 1.5 | C5: 33.2372 | D5: 36.2674 | E5: 34.2551 | F5: 37.8542 | G5: 34.4915 | H5: 33.7974 | I5: 38.2683 | J5: 36.2151 | K5: 26.0916 | L5: 32.0746 | M5: 36.2365 | N5: 34.7626 | O5: 36.3149 | P5: 34.7979 | Q5: 36.989 | R5: 34.5141 | S5: 38.1177 | T5: 35.3058 | U5: 21.4381 | V5: 35.8236 | W5: 37.3904 | X5: 32.6179 | Y5: 18.3601 | Z5: 35.1058 | AA5: 36.2264 | AB5: 36.2811 | AC5: 35.3686 | AD5: 36.3984 | AE5: 36.5059 | AF5: 32.2941 | AG5: 37.1805 | AH5: 33.2872 | AI5: 33.6864 | AJ5: 34.588 | AK5: 11.8444 | AL5: 38.0424 | AM5: 35.9444 | AN5: 34.4408 | AO5: 16.3284 | AP5: 37.1529 | AQ5: 36.5275 | AR5: 36.9146 | AS5: 33.2576 | AT5: 31.3456 | AU5: 36.6852 | AV5: 17.8606 | AW5: 34.4095 | AX5: 32.256 | AY5: 35.7725 | AZ5: 35.6595 | BA5: 37.2529 | BB5: 36.7331 | BC5: 27.3127 | BD5: 34.8872 | BE5: 28.1418 | BF5: 38.193 | BG5: 36.1522 | BH5: 38.9083 | BI5: 27.6186 | BJ5: 28.6198 | BK5: 36.332 | BL5: 38.2307 | BM5: 36.1371 | BN5: 32.2566 | BO5: 25.4928 | BP5: 10 | BQ5: 32.0197 | BR5: 10 | BS5: 34.5345 | BT5: 37.3072 | BU5: 29.5548 | BV5: 36.066 | BW5: 34.3261 | BX5: 30.1607 | BY5: 35.8869 | BZ5: 18.3028 | CA5: 32.8051 | CB5: 33.5465 | CC5: 32.8398 | CD5: 37.0786 | CE5: 35.5745 | CF5: 27.5772 | CG5: 35.9704 | CH5: 35.9549 | CI5: 38.1554 | CJ5: 12.7457 | CK5: 22.739 | CL5: 35.9323 | CM5: 37.0546 | CN5: 36.41 | CO5: 36.7023 | CP5: 19.7334 | CQ5: 34.2265 | CR5: 33.4618 | CS5: 26.923 | CT5: 32.446777 | CU5: 3082.4438
A6: 5 | B6: 2 | C6: 32.5471 | D6: 34.1905 | E6: 31.6704 | F6: 37.1389 | G6: 33.8139 | H6: 31.8439 | I6: 37.6911 | J6: 35.5752 | K6: 23.539 | L6: 31.5601 | M6: 34.2436 | N6: 33.3557 | O6: 35.1653 | P6: 34.0446 | Q6: 35.4418 | R6: 32.2264 | S6: 37.4903 | T6: 33.9998 | U6: 13.4262 | V6: 34.7967 | W6: 36.0106 | X6: 31.5698 | Y6: 16.1841 | Z6: 33.4911 | AA6: 35.5487 | AB6: 33.9175 | AC6: 34.6659 | AD6: 33.9262 | AE6: 35.3645 | AF6: 30.9983 | AG6: 36.7288 | AH6: 31.9931 | AI6: 32.1825 | AJ6: 33.5727 | AK6: 10 | AL6: 37.3899 | AM6: 35.3421 | AN6: 33.4809 | AO6: 13.92 | AP6: 36.1093 | AQ6: 35.1981 | AR6: 35.9896 | AS6: 30.715 | AT6: 30.3869 | AU6: 34.6269 | AV6: 13.9789 | AW6: 31.5308 | AX6: 29.2834 | AY6: 35.1576 | AZ6: 34.2943 | BA6: 36.1416 | BB6: 33.4562 | BC6: 26.2847 | BD6: 32.0689 | BE6: 26.0786 | BF6: 37.5907 | BG6: 33.8543 | BH6: 38.5444 | BI6: 20.7867 | BJ6: 26.8386 | BK6: 34.4061 | BL6: 37.6409 | BM6: 30.4072 | BN6: 31.5418 | BO6: 24.903 | BP6: 10 | BQ6: 30.3774 | BR6: 10 | BS6: 33.882 | BT6: 36.8304 | BU6: 27.1688 | BV6: 34.0921 | BW6: 33.3608 | BX6: 29.2331 | BY6: 35.2093 | BZ6: 17.575 | CA6: 31.683 | CB6: 29.1769 | CC6: 30.0511 | CD6: 36.3107 | CE6: 33.9238 | CF6: 25.2371 | CG6: 34.8655 | CH6: 33.9512 | CI6: 37.5405 | CJ6: 10 | CK6: 20.5935 | CL6: 32.3194 | CM6: 36.4523 | CN6: 33.9243 | CO6: 34.7942 | CP6: 19.2691 | CQ6: 33.2762 | CR6: 32.6021 | CS6: 26.2996 | CT6: 30.819591 | CU6: 2927.8611
A7: 6 | B7: 2.5 | C7: 30.7789 | D7: 33.0744 | E7: 30.9677 | F7: 36.4237 | G7: 31.8765 | H7: 30.2763 | I7: 37.1138 | J7: 34.1018 | K7: 23.0497 | L7: 28.3068 | M7: 33.566 | N7: 30.5894 | O7: 33.8386 | P7: 32.3106 | Q7: 34.6555 | R7: 30.719 | S7: 36.8629 | T7: 32.7693 | U7: 11.2606 | V7: 32.9156 | W7: 35.3957 | X7: 28.4716 | Y7: 15.4563 | Z7: 32.1377 | AA7: 33.2095 | AB7: 33.2399 | AC7: 33.5044 | AD7: 33.3615 | AE7: 33.6644 | AF7: 28.3658 | AG7: 35.3253 | AH7: 30.0623 | AI7: 30.9092 | AJ7: 31.393 | AK7: 10 | AL7: 36.7374 | AM7: 32.4912 | AN7: 32.0425 | AO7: 11.6673 | AP7: 34.971 | AQ7: 34.0407 | AR7: 35.3747 | AS7: 27.3181 | AT7: 25.4634 | AU7: 33.9493 | AV7: 13.4268 | AW7: 30.2297 | AX7: 28.5305 | AY7: 33.7683 | AZ7: 31.9371 | BA7: 35.715 | BB7: 32.9793 | BC7: 24.235 | BD7: 31.2772 | BE7: 23.941 | BF7: 36.9884 | BG7: 32.8099 | BH7: 38.1805 | BI7: 17.885 | BJ7: 24.4004 | BK7: 33.1409 | BL7: 37.0511 | BM7: 18.6564 | BN7: 27.9013 | BO7: 23.5339 | BP7: 10 | BQ7: 28.0004 | BR7: 10 | BS7: 32.5279 | BT7: 36.3535 | BU7: 25.4828 | BV7: 32.8095 | BW7: 31.8508 | BX7: 24.9478 | BY7: 33.5597 | BZ7: 13.929 | CA7: 30.5608 | CB7: 27.2406 | CC7: 29.0116 | CD7: 34.8223 | CE7: 31.8518 | CF7: 23.0538 | CG7: 33.961 | CH7: 32.5373 | CI7: 36.9256 | CJ7: 10 | CK7: 18.8073 | CL7: 31.6005 | CM7: 34.8742 | CN7: 33.3722 | CO7: 34.1668 | CP7: 15.7991 | CQ7: 32.6362 | CR7: 31.9998 | CS7: 22.3064 | CT7: 29.216692 | CU7: 2775.5857
A8: 7 | B8: 3 | C8: 29.1904 | D8: 32.3426 | E8: 26.6282 | F8: 35.7084 | G8: 28.9831 | H8: 28.072 | I8: 36.5366 | J8: 33.2952 | K8: 21.146 | L8: 27.7924 | M8: 32.1269 | N8: 29.2541 | O8: 32.7479 | P8: 31.067 | Q8: 33.2715 | R8: 29.0281 | S8: 36.2354 | T8: 29.2545 | U8: 10.5579 | V8: 32.4011 | W8: 34.3134 | X8: 27.0668 | Y8: 12.7371 | Z8: 30.2117 | AA8: 32.4527 | AB8: 31.2977 | AC8: 30.7372 | AD8: 32.7968 | AE8: 33.0119 | AF8: 26.208 | AG8: 34.361 | AH8: 27.346 | AI8: 28.3052 | AJ8: 29.7368 | AK8: 10 | AL8: 36.0849 | AM8: 31.8889 | AN8: 30.2213 | AO8: 10.8663 | AP8: 34.3059 | AQ8: 31.8519 | AR8: 34.7598 | AS8: 24.2053 | AT8: 23.8269 | AU8: 31.8911 | AV8: 11.0235 | AW8: 27.7502 | AX8: 27.7776 | AY8: 32.7364 | AZ8: 31.1234 | BA8: 35.2883 | BB8: 30.3822 | BC8: 23.6327 | BD8: 29.7744 | BE8: 22.7987 | BF8: 36.386 | BG8: 30.1223 | BH8: 37.8166 | BI8: 13.7012 | BJ8: 23.911 | BK8: 32.6641 | BL8: 36.4613 | BM8: 10 | BN8: 25.8998 | BO8: 21.5803 | BP8: 10 | BQ8: 26.2954 | BR8: 10 | BS8: 30.6476 | BT8: 34.6144 | BU8: 23.8504 | BV8: 32.1319 | BW8: 28.475 | BX8: 23.5121 | BY8: 31.7739 | BZ8: 12.2977 | CA8: 26.745 | CB8: 24.9302 | CC8: 25.4139 | CD8: 34.1573 | CE8: 31.1491 | CF8: 22.4641 | CG8: 31.6161 | CH8: 31.6149 | CI8: 36.3107 | CJ8: 10 | CK8: 18.205 | CL8: 31.0233 | CM8: 34.2176 | CN8: 32.82 | CO8: 32.3261 | CP8: 15.3348 | CQ8: 31.1687 | CR8: 28.8963 | CS8: 21.5155 | CT8: 27.689062 | CU8: 2630.4609
A9: 8 | B9: 3.5 | C9: 28.5002 | D9: 29.8814 | E9: 25.9255 | F9: 34.9931 | G9: 27.6756 | H9: 26.7551 | I9: 35.9594 | J9: 31.933 | K9: 20.6566 | L9: 27.2779 | M9: 30.6878 | N9: 26.6013 | O9: 31.8933 | P9: 30.4772 | Q9: 32.3221 | R9: 27.3347 | S9: 35.608 | T9: 28.6271 | U9: 10 | V9: 30.0075 | W9: 33.401 | X9: 26.5774 | Y9: 12.0093 | Z9: 28.8166 | AA9: 31.6168 | AB9: 30.1986 | AC9: 30.0345 | AD9: 30.3246 | AE9: 32.3594 | AF9: 25.2493 | AG9: 33.7629 | AH9: 26.2494 | AI9: 27.094 | AJ9: 28.2781 | AK9: 10 | AL9: 35.4323 | AM9: 29.9579 | AN9: 29.6441 | AO9: 10 | AP9: 32.789 | AQ9: 31.1241 | AR9: 32.594 | AS9: 23.4255 | AT9: 22.2861 | AU9: 31.2135 | AV9: 10.179 | AW9: 25.6332 | AX9: 27.0247 | AY9: 32.1215 | AZ9: 29.6261 | BA9: 34.8617 | BB9: 28.6473 | BC9: 21.3276 | BD9: 26.7022 | BE9: 20.0719 | BF9: 35.7837 | BG9: 29.5325 | BH9: 37.4527 | BI9: 10 | BJ9: 22.5986 | BK9: 30.6506 | BL9: 35.8715 | BM9: 10 | BN9: 23.2687 | BO9: 20.9905 | BP9: 10 | BQ9: 23.5345 | BR9: 10 | BS9: 29.9951 | BT9: 34.1376 | BU9: 21.4109 | BV9: 31.4543 | BW9: 27.1423 | BX9: 19.6337 | BY9: 31.0963 | BZ9: 11.0268 | CA9: 26.0138 | CB9: 21.9836 | CC9: 23.3152 | CD9: 33.0806 | CE9: 29.1824 | CF9: 20.2035 | CG9: 31.1064 | CH9: 29.1196 | CI9: 35.6959 | CJ9: 10 | CK9: 14.8757 | CL9: 28.129 | CM9: 32.6938 | CN9: 32.2679 | CO9: 31.5639 | CP9: 14.8705 | CQ9: 29.0805 | CR9: 27.2647 | CS9: 20.381 | CT9: 26.422723 | CU9: 2510.1587
A10: 9 | B10: 4 | C10: 26.8542 | D10: 29.385 | E10: 23.4615 | F10: 34.3211 | G10: 24.5983 | H10: 24.5344 | I10: 35.4253 | J10: 31.0476 | K10: 18.4633 | L10: 26.8066 | M10: 29.7072 | N10: 25.4824 | O10: 30.3521 | P10: 28.1217 | Q10: 31.2803 | R10: 24.1752 | S10: 35.0238 | T10: 26.2024 | U10: 10 | V10: 29.5362 | W10: 32.8293 | X10: 24.7236 | Y10: 10 | Z10: 27.8432 | AA10: 29.3729 | AB10: 28.8628 | AC10: 26.8301 | AD10: 29.7761 | AE10: 30.9119 | AF10: 21.5821 | AG10: 32.0365 | AH10: 23.9732 | AI10: 25.8373 | AJ10: 25.9442 | AK10: 10 | AL10: 34.8014 | AM10: 28.4789 | AN10: 27.0049 | AO10: 10 | AP10: 32.1671 | AQ10: 28.6186 | AR10: 32.0008 | AS10: 19.3596 | AT10: 18.922 | AU10: 30.5574 | AV10: 10 | AW10: 25.0991 | AX10: 26.3042 | AY10: 30.3476 | AZ10: 28.2386 | BA10: 32.6145 | BB10: 26.468 | BC10: 20.5982 | BD10: 25.3896 | BE10: 19.1882 | BF10: 35.2246 | BG10: 28.2837 | BH10: 37.1319 | BI10: 10 | BJ10: 19.7132 | BK10: 29.5053 | BL10: 35.298 | BM10: 10 | BN10: 20.5865 | BO10: 18.2846 | BP10: 10 | BQ10: 21.321 | BR10: 10 | BS10: 29.3858 | BT10: 33.6877 | BU10: 20.9521 | BV10: 30.0205 | BW10: 24.1595 | BX10: 17.3735 | BY10: 30.4564 | BZ10: 10 | CA10: 24.2755 | CB10: 19.8644 | CC10: 20.4751 | CD10: 31.9441 | CE10: 27.4533 | CF10: 18.6793 | CG10: 28.9996 | CH10: 28.5192 | CI10: 35.1026 | CJ10: 10 | CK10: 14.3111 | CL10: 25.8094 | CM10: 32.0534 | CN10: 31.732 | CO10: 30.9742 | CP10: 11.8965 | CQ10: 28.4837 | CR10: 26.6948 | CS10: 16.7529 | CT10: 25.019641 | CU10: 2376.8659
A11: 10 | B11: 4.5 | C11: 25.644 | D11: 27.3556 | E11: 21.2169 | F11: 34.2299 | G11: 24.1419 | H11: 24.1599 | I11: 35.4675 | J11: 29.9313 | K11: 17.1712 | L11: 25.7394 | M11: 28.4768 | N11: 23.3748 | O11: 29.9865 | P11: 28 | Q11: 30.2389 | R11: 23.8699 | S11: 35.0204 | T11: 24.2154 | U11: 10 | V11: 28.0229 | W11: 32.8376 | X11: 22.0161 | Y11: 10 | Z11: 25.7345 | AA11: 28.9293 | AB11: 27.4076 | AC11: 26.4394 | AD11: 28.5784 | AE11: 30.1851 | AF11: 21.1572 | AG11: 32.1916 | AH11: 23.5422 | AI11: 23.9461 | AJ11: 25.9524 | AK11: 10 | AL11: 34.4609 | AM11: 28.4984 | AN11: 27.0471 | AO11: 10 | AP11: 32.1261 | AQ11: 28.1949 | AR11: 31.6979 | AS11: 17.9107 | AT11: 17.0522 | AU11: 29.5016 | AV11: 10 | AW11: 21.7844 | AX11: 26.0193 | AY11: 30.2008 | AZ11: 28.1016 | BA11: 32.4405 | BB11: 25.0852 | BC11: 19.428 | BD11: 22.9456 | BE11: 16.3444 | BF11: 35.2441 | BG11: 26.3843 | BH11: 37.3661 | BI11: 10 | BJ11: 19.5358 | BK11: 28.2545 | BL11: 34.9422 | BM11: 10.0196 | BN11: 19.6937 | BO11: 18.0849 | BP11: 10 | BQ11: 19.0209 | BR11: 10 | BS11: 28.4804 | BT11: 32.3387 | BU11: 18.0062 | BV11: 28.5315 | BW11: 22.2229 | BX11: 15.8438 | BY11: 29.2166 | BZ11: 10 | CA11: 23.0456 | CB11: 17.5945 | CC11: 18.3305 | CD11: 31.9032 | CE11: 27.1407 | CF11: 16.5706 | CG11: 28.3326 | CH11: 28.2818 | CI11: 34.7997 | CJ11: 10 | CK11: 12.2522 | CL11: 24.3786 | CM11: 30.7636 | CN11: 31.4139 | CO11: 29.5449 | CP11: 11.1866 | CQ11: 28.4678 | CR11: 23.2015 | CS11: 16.5254 | CT11: 24.11516 | CU11: 2290.9402
A12: 11 | B12: 5 | C12: 26.9928 | D12: 29.4967 | E12: 21.8978 | F12: 36.2128 | G12: 25.0249 | H12: 22.8134 | I12: 37.5747 | J12: 31.2753 | K12: 19.0692 | L12: 27.903 | M12: 30.4936 | N12: 24.4182 | O12: 29.706 | P12: 29.1449 | Q12: 30.6141 | R12: 23.7392 | S12: 37.0824 | T12: 24.3963 | U12: 11.9942 | V12: 29.956 | W12: 34.2224 | X12: 23.0428 | Y12: 11.6433 | Z12: 25.9229 | AA12: 27.7636 | AB12: 27.7827 | AC12: 27.1203 | AD12: 28.0677 | AE12: 31.8473 | AF12: 20.2425 | AG12: 33.0938 | AH12: 21.9825 | AI12: 25.9855 | AJ12: 28.0257 | AK12: 10 | AL12: 35.187 | AM12: 28.5592 | AN12: 27.8625 | AO12: 12.0959 | AP12: 33.7283 | AQ12: 28.174 | AR12: 31.224 | AS12: 17.7585 | AT12: 15.8138 | AU12: 29.5837 | AV12: 11.8667 | AW12: 23.2707 | AX12: 27.3117 | AY12: 30.5451 | AZ12: 27.2818 | BA12: 33.8267 | BB12: 26.3834 | BC12: 20.8996 | BD12: 23.9546 | BE12: 17.9129 | BF12: 37.3287 | BG12: 28.1518 | BH12: 39.6653 | BI12: 11.0996 | BJ12: 18.5568 | BK12: 29.609 | BL12: 35.3964 | BM12: 10.8977 | BN12: 18.7955 | BO12: 19.1958 | BP12: 11.1568 | BQ12: 20.7546 | BR12: 12.22 | BS12: 29.5726 | BT12: 33.5512 | BU12: 20.1811 | BV12: 29.235 | BW12: 22.9941 | BX12: 16.0095 | BY12: 30.1761 | BZ12: 10 | CA12: 24.8244 | CB12: 17.0313 | CC12: 19.5882 | CD12: 33.0977 | CE12: 26.2607 | CF12: 16.4052 | CG12: 30.2696 | CH12: 27.7089 | CI12: 35.5597 | CJ12: 10.3992 | CK12: 13.3565 | CL12: 25.6595 | CM12: 31.2065 | CN12: 30.5499 | CO12: 31.2785 | CP12: 10.5765 | CQ12: 30.5185 | CR12: 24.475 | CS12: 15.5077 | CT12: 24.932734 | CU12: 2368.6097
A13: 12 | B13: 5.5 | C13: 28.9049 | D13: 33.1837 | E13: 21.4941 | F13: 40.7795 | G13: 27.2411 | H13: 26.2356 | I13: 42.2655 | J13: 34.4571 | K13: 22.3528 | L13: 32.6504 | M13: 33.7234 | N13: 28.6677 | O13: 31.7013 | P13: 31.1978 | Q13: 31.0777 | R13: 27.5929 | S13: 41.7281 | T13: 23.8038 | U13: 16.5722 | V13: 34.7033 | W13: 38.8794 | X13: 25.1692 | Y13: 13.7551 | Z13: 28.6486 | AA13: 28.9651 | AB13: 29.1267 | AC13: 27.8543 | AD13: 29.5134 | AE13: 35.4647 | AF13: 21.6526 | AG13: 37.8977 | AH13: 22.0798 | AI13: 29.1156 | AJ13: 30.3371 | AK13: 13.1101 | AL13: 37.2049 | AM13: 33.2275 | AN13: 31.9505 | AO13: 15.7971 | AP13: 37.9993 | AQ13: 30.0793 | AR13: 33.0664 | AS13: 21.2198 | AT13: 18.3624 | AU13: 31.5791 | AV13: 16.5801 | AW13: 27.5801 | AX13: 30.5419 | AY13: 33.8995 | AZ13: 29.2652 | BA13: 36.5933 | BB13: 28.4801 | BC13: 25.5679 | BD13: 27.664 | BE13: 21.9412 | BF13: 41.997 | BG13: 32.1801 | BH13: 44.5481 | BI13: 12.098 | BJ13: 19.5589 | BK13: 32.3781 | BL13: 36.8195 | BM13: 15.2111 | BN13: 20.4488 | BO13: 20.8694 | BP13: 15.7461 | BQ13: 21.1282 | BR13: 16.4696 | BS13: 34.1957 | BT13: 36.3785 | BU13: 24.9397 | BV13: 30.997 | BW13: 22.5994 | BX13: 17.2208 | BY13: 33.6233 | BZ13: 11.5299 | CA13: 27.6166 | CB13: 17.0912 | CC13: 21.8378 | CD13: 37.7095 | CE13: 28.6003 | CF13: 17.404 | CG13: 33.8206 | CH13: 30.0467 | CI13: 37.6115 | CJ13: 12.4171 | CK13: 17.3735 | CL13: 27.8556 | CM13: 31.74 | CN13: 31.5323 | CO13: 35.2729 | CP13: 10.5176 | CQ13: 33.1046 | CR13: 27.5449 | CS13: 16.5641 | CT13: 27.653683 | CU13: 2627.0999
... A49: 48 | B49: 23.5 | C49: 78.5297 | D49: 55.9903 | E49: 48.7484 | F49: 74.2272 | G49: 59.7929 | H49: 46.9482 | I49: 88.2554 | J49: 61.8404 | K49: 10 | L49: 68.0592 | M49: 52.689 | N49: 50.0589 | O49: 72.3991 | P49: 75.6569 | Q49: 66.3384 | R49: 80.1047 | S49: 95.1448 | T49: 48.4182 | U49: 61.0359 | V49: 30.4609 | W49: 10 | X49: 74.4442 | Y49: 51.6296 | Z49: 83.253 | AA49: 85.0519 | AB49: 39.49 | AC49: 38.8314 | AD49: 34.5277 | AE49: 80.2003 | AF49: 43.452 | AG49: 71.1295 | AH49: 84.706 | AI49: 78.6578 | AJ49: 40.9458 | AK49: 10 | AL49: 76.5196 | AM49: 56.5818 | AN49: 90.1605 | AO49: 63.9646 | AP49: 34.5149 | AQ49: 66.7492 | AR49: 54.9794 | AS49: 25.2352 | AT49: 78.433 | AU49: 10 | AV49: 27.7213 | AW49: 53.5703 | AX49: 48.928 | AY49: 30.975 | AZ49: 64.6513 | BA49: 35.2695 | BB49: 77.2705 | BC49: 57.6334 | BD49: 86.259 | BE49: 10 | BF49: 68.3524 | BG49: 74.1084 | BH49: 44.9451 | BI49: 66.0773 | BJ49: 73.1345 | BK49: 54.5988 | BL49: 69.3295 | BM49: 16.332 | BN49: 84.3781 | BO49: 61.4762 | BP49: 23.4937 | BQ49: 55.117 | BR49: 51.348 | BS49: 10 | BT49: 65.7468 | BU49: 70.8989 | BV49: 40.0251 | BW49: 27.0372 | BX49: 71.2724 | BY49: 71.8423 | BZ49: 46.1941 | CA49: 80.492 | CB49: 10 | CC49: 71.0127 | CD49: 56.8762 | CE49: 10 | CF49: 85.5385 | CG49: 53.4428 | CH49: 53.2515 | CI49: 10.0511 | CJ49: 10 | CK49: 67.9242 | CL49: 49.9855 | CM49: 81.9081 | CN49: 39.528 | CO49: 50.1545 | CP49: 37.6067 | CQ49: 89.7683 | CR49: 65.5381 | CS49: 61.5949 | CT49: 55.061212 | CU49: 5230.8151

Sheet Demand_kW
A1: period | B1: hour | C1: BES_TR2_three312_A | D1: BES_TR2_three321_B | E1: BES_TR2_three368_A | F1: BES_TR2_three388_A | G1: BES_TR2_three409_C | H1: BES_TR2_three478_B | I1: BES_TR2_three97_B | J1: BES_TR2_three133_C | K1: BES_TR2_three160_C | L1: BES_TR2_five58_C | M1: BES_TR2_five147_C | N1: BES_TR2_five149_A | O1: BES_TR2_five160_C | P1: BES_TR2_five170_A | Q1: BES_TR2_five177_A | R1: BES_TR2_five67_C | S1: BES_TR2_five243_B | T1: BES_TR2_five284_C | U1: BES_TR2_five285_B | V1: BES_TR2_five303_B | W1: BES_TR2_five324_B | X1: BES_TR2_five355_A | Y1: BES_TR2_five394_C | Z1: BES_TR2_five451_A | AA1: BES_TR2_five466_A | AB1: BES_TR2_five494_B | AC1: BES_TR2_five512_A | AD1: BES_TR2_five520_C | AE1: BES_TR2_five540_A | AF1: BES_TR2_five588_A | AG1: BES_TR2_five649_A | AH1: BES_TR2_five663_C | AI1: BES_TR2_five685_B | AJ1: BES_TR2_five695_A | AK1: BES_TR2_five704_A | AL1: BES_TR2_five733_C | AM1: BES_TR2_five117_B | AN1: BES_TR2_five778_B | AO1: BES_TR2_five799_C | AP1: BES_TR2_five801_C | AQ1: BES_TR2_five831_C | AR1: BES_TR2_five881_C | AS1: BES_TR2_five118_B | AT1: BES_TR2_six64_A | AU1: BES_TR2_six154_C | AV1: BES_TR2_six173_C | AW1: BES_TR2_six186_A | AX1: BES_TR2_six191_B | AY1: BES_TR2_six203_A | AZ1: BES_TR2_six232_C | BA1: BES_TR2_six238_A | BB1: BES_TR2_six249_B | BC1: BES_TR2_six254_B | BD1: BES_TR2_six269_C | BE1: BES_TR2_six289_C | BF1: BES_TR2_six317_C | BG1: BES_TR2_six326_A | BH1: BES_TR2_six329_A | BI1: BES_TR2_six342_A | BJ1: BES_TR2_six349_A | BK1: BES_TR2_six350_B | BL1: BES_TR2_six362_C | BM1: BES_TR2_six365_C | BN1: BES_TR2_six378_A | BO1: BES_TR2_six385_B | BP1: BES_TR2_six387_A | BQ1: BES_TR2_six392_C | BR1: BES_TR2_six410_A | BS1: BES_TR2_six431_C | BT1: BES_TR2_six484_B | BU1: BES_TR2_six512_B | BV1: BES_TR2_six518_B | BW1: BES_TR2_six523_C | BX1: BES_TR2_six571_C | BY1: BES_TR2_six583_A | BZ1: BES_TR2_six625_A | CA1: BES_TR2_six646_B | CB1: BES_TR2_six87_A | CC1: BES_TR2_six652_A | CD1: BES_TR2_six665_B | CE1: BES_TR2_six667_A | CF1: BES_TR2_six721_A | CG1: BES_TR2_six740_A | CH1: BES_TR2_six758_B | CI1: BES_TR2_six784_B | CJ1: BES_TR2_six799_B | CK1: BES_TR2_six807_A | CL1: BES_TR2_six885_A | CM1: BES_TR2_six894_B | CN1: BES_TR2_six914_A | CO1: BES_TR2_six921_B | CP1: BES_TR2_six929_A | CQ1: BES_TR2_six938_A | CR1: BES_TR2_six990_B | CS1: BES_TR2_six1020_A | CT1: fleet_average | CU1: fleet_total
A2: 1 | B2: 0 | C2: 0.27143133 | D2: 0.043 | E2: 0.20597333 | F2: 0.057 | G2: 0.054 | H2: 0.16150667 | I2: 0.046 | J2: 0.055427333 | K2: 0.67774833 | L2: 0.212737 | M2: 0.14226667 | N2: 0.119068 | O2: 0.138642 | P2: 0.19029333 | Q2: 0.054 | R2: 0.094357333 | S2: 0.05 | T2: 0.05 | U2: 0.40984133 | V2: 0.14871667 | W2: 0.049 | X2: 0.184908 | Y2: 1.565217 | Z2: 0.181925 | AA2: 0.054 | AB2: 0.054 | AC2: 0.25708 | AD2: 0.086458 | AE2: 0.12435367 | AF2: 0.281617 | AG2: 0.036 | AH2: 0.20918333 | AI2: 0.271893 | AJ2: 0.15751667 | AK2: 0.708509 | AL2: 0.052 | AM2: 0.048 | AN2: 0.21375733 | AO2: 0.85998733 | AP2: 0.053 | AQ2: 0.058 | AR2: 0.049 | AS2: 0.234921 | AT2: 0.27314067 | AU2: 0.15616267 | AV2: 0.53006033 | AW2: 0.19210933 | AX2: 0.166834 | AY2: 0.14394667 | AZ2: 0.16659933 | BA2: 0.034 | BB2: 0.038 | BC2: 0.401287 | BD2: 0.17833867 | BE2: 0.61022667 | BF2: 0.048 | BG2: 0.145344 | BH2: 0.029 | BI2: 0.36720933 | BJ2: 0.430768 | BK2: 0.062432333 | BL2: 0.047 | BM2: 0.048 | BN2: 0.159502 | BO2: 0.45527333 | BP2: 0.901374 | BQ2: 0.313432 | BR2: 0.75684533 | BS2: 0.177796 | BT2: 0.038 | BU2: 0.40919733 | BV2: 0.11598 | BW2: 0.048 | BX2: 0.38397467 | BY2: 0.054 | BZ2: 0.593688 | CA2: 0.21100867 | CB2: 0.14500933 | CC2: 0.15603567 | CD2: 0.053 | CE2: 0.056 | CF2: 0.70558933 | CG2: 0.13513033 | CH2: 0.05 | CI2: 0.049 | CJ2: 1.0705013 | CK2: 0.57031867 | CL2: 0.046 | CM2: 0.06096 | CN2: 0.086024 | CO2: 0.082228 | CP2: 0.777594 | CQ2: 0.20146367 | CR2: 0.164195 | CS2: 0.47496733 | CT2: 0.2372935 | CU2: 22.542883
A3: 2 | B3: 0.5 | C3: 0.083636 | D3: 0.211454 | E3: 0.056 | F3: 0.057 | G3: 0.171829 | H3: 0.13958 | I3: 0.046 | J3: 0.1155 | K3: 0.297479 | L3: 0.28407 | M3: 0.0871 | N3: 0.100124 | O3: 0.054 | P3: 0.047 | Q3: 0.131952 | R3: 0.149574 | S3: 0.05 | T3: 0.129002 | U3: 0.48593333 | V3: 0.1431 | W3: 0.10996 | X3: 0.128048 | Y3: 0.058 | Z3: 0.161095 | AA3: 0.186419 | AB3: 0.18836 | AC3: 0.056 | AD3: 0.15555467 | AE3: 0.102091 | AF3: 0.20332 | AG3: 0.15268667 | AH3: 0.10343267 | AI3: 0.052 | AJ3: 0.049 | AK3: 0.85611833 | AL3: 0.052 | AM3: 0.22719 | AN3: 0.046 | AO3: 0.639283 | AP3: 0.120884 | AQ3: 0.058 | AR3: 0.049 | AS3: 0.20272267 | AT3: 0.249628 | AU3: 0.054 | AV3: 0.36332167 | AW3: 0.17419333 | AX3: 0.26204667 | AY3: 0.049 | AZ3: 0.12880467 | BA3: 0.034 | BB3: 0.13825867 | BC3: 0.56177467 | BD3: 0.101252 | BE3: 0.23048233 | BF3: 0.048 | BG3: 0.047 | BH3: 0.029 | BI3: 0.44713533 | BJ3: 0.43712933 | BK3: 0.19187233 | BL3: 0.047 | BM3: 0.048 | BN3: 0.249696 | BO3: 0.47743 | BP3: 0.79453533 | BQ3: 0.05 | BR3: 1.7480433 | BS3: 0.052 | BT3: 0.038 | BU3: 0.356741 | BV3: 0.14352667 | BW3: 0.10048 | BX3: 0.054 | BY3: 0.21547233 | BZ3: 0.57246133 | CA3: 0.046 | CB3: 0.198252 | CC3: 0.29335967 | CD3: 0.061200667 | CE3: 0.240668 | CF3: 0.13580067 | CG3: 0.13243833 | CH3: 0.22235533 | CI3: 0.049 | CJ3: 1.0430317 | CK3: 0.71254667 | CL3: 0.15884667 | CM3: 0.05232 | CN3: 0.156064 | CO3: 0.12519867 | CP3: 0.667901 | CQ3: 0.051 | CR3: 0.048 | CS3: 0.39730733 | CT3: 0.21140078 | CU3: 20.083074
A4: 3 | B4: 1 | C4: 0.183862 | D4: 0.043 | E4: 0.19584267 | F4: 0.057 | G4: 0.21314433 | H4: 0.19320133 | I4: 0.046 | J4: 0.130692 | K4: 0.13314267 | L4: 0.13477667 | M4: 0.07055 | N4: 0.19817733 | O4: 0.10102333 | P4: 0.17726667 | Q4: 0.054 | R4: 0.19324667 | S4: 0.05 | T4: 0.19508633 | U4: 0.58344133 | V4: 0.041 | W4: 0.049 | X4: 0.27532667 | Y4: 0.10128 | Z4: 0.047 | AA4: 0.060305667 | AB4: 0.054 | AC4: 0.056 | AD4: 0.045 | AE4: 0.052 | AF4: 0.12914967 | AG4: 0.036 | AH4: 0.22233633 | AI4: 0.179242 | AJ4: 0.22476633 | AK4: 0.67911667 | AL4: 0.052 | AM4: 0.048 | AN4: 0.183256 | AO4: 0.38714167 | AP4: 0.053 | AQ4: 0.160725 | AR4: 0.14787467 | AS4: 0.099667333 | AT4: 0.16691067 | AU4: 0.054 | AV4: 0.87092567 | AW4: 0.079206667 | AX4: 0.18824737 | AY4: 0.14394667 | AZ4: 0.050497667 | BA4: 0.150915 | BB4: 0.084082 | BC4: 0.048 | BD4: 0.127852 | BE4: 0.10428233 | BF4: 0.048 | BG4: 0.114288 | BH4: 0.029 | BI4: 0.17234133 | BJ4: 0.039 | BK4: 0.038 | BL4: 0.047 | BM4: 0.211834 | BN4: 0.20788 | BO4: 0.22338933 | BP4: 0.92955333 | BQ4: 0.272526 | BR4: 0.257956 | BS4: 0.20575067 | BT4: 0.13859 | BU4: 0.066446 | BV4: 0.054 | BW4: 0.30367467 | BX4: 0.346128 | BY4: 0.058303 | BZ4: 0.56291767 | CA4: 0.31635933 | CB4: 0.171026 | CC4: 0.12120467 | CD4: 0.11860533 | CE4: 0.056 | CF4: 0.14858933 | CG4: 0.053556667 | CH4: 0.05 | CI4: 0.049 | CJ4: 0.058385667 | CK4: 0.092676 | CL4: 0.11931267 | CM4: 0.12144 | CN4: 0.044 | CO4: 0.055371333 | CP4: 0.16956933 | CQ4: 0.20762967 | CR4: 0.30884133 | CS4: 0.169844 | CT4: 0.15961575 | CU4: 15.163497
A5: 4 | B5: 1.5 | C5: 0.055 | D5: 0.165512 | E5: 0.20597333 | F5: 0.057 | G5: 0.054 | H5: 0.15567667 | I5: 0.046 | J5: 0.051 | K5: 0.20341667 | L5: 0.041 | M5: 0.15881667 | N5: 0.11211667 | O5: 0.091618667 | P5: 0.060026667 | Q5: 0.12329067 | R5: 0.18230667 | S5: 0.05 | T5: 0.104069 | U5: 0.63846767 | V5: 0.08184 | W5: 0.10996 | X5: 0.083524 | Y5: 0.17341333 | Z5: 0.12868067 | AA5: 0.054 | AB5: 0.18836 | AC5: 0.056 | AD5: 0.19701267 | AE5: 0.090959667 | AF5: 0.103269 | AG5: 0.036 | AH5: 0.103127 | AI5: 0.11984933 | AJ5: 0.080916667 | AK5: 0.44452767 | AL5: 0.052 | AM5: 0.048 | AN5: 0.076501333 | AO5: 0.19192433 | AP5: 0.083170667 | AQ5: 0.10593833 | AR5: 0.073718667 | AS5: 0.202619 | AT5: 0.076396 | AU5: 0.16402133 | AV5: 0.30933233 | AW5: 0.229409 | AX5: 0.23688333 | AY5: 0.049 | AZ5: 0.108793 | BA5: 0.088560333 | BB5: 0.26114233 | BC5: 0.081923333 | BD5: 0.22459067 | BE5: 0.16441867 | BF5: 0.048 | BG5: 0.183122 | BH5: 0.029 | BI5: 0.54443433 | BJ5: 0.141942 | BK5: 0.15347667 | BL5: 0.047 | BM5: 0.456623 | BN5: 0.056965333 | BO5: 0.047 | BP5: 0.130144 | BQ5: 0.130876 | BR5: 0.52382167 | BS5: 0.052 | BT5: 0.038 | BU5: 0.19014667 | BV5: 0.1573 | BW5: 0.076932 | BX5: 0.073921667 | BY5: 0.054 | BZ5: 0.058 | CA5: 0.089423333 | CB5: 0.34821467 | CC5: 0.222234 | CD5: 0.061200667 | CE5: 0.131546 | CF5: 0.18648733 | CG5: 0.088047333 | CH5: 0.15968067 | CI5: 0.049 | CJ5: 0.22906433 | CK5: 0.170976 | CL5: 0.28791533 | CM5: 0.048 | CN5: 0.198088 | CO5: 0.15205533 | CP5: 0.037 | CQ5: 0.075731 | CR5: 0.068505 | CS5: 0.049676 | CT5: 0.13979605 | CU5: 13.280624
A6: 5 | B6: 2 | C6: 0.140908 | D6: 0.088942 | E6: 0.056 | F6: 0.057 | G6: 0.154394 | H6: 0.124928 | I6: 0.046 | J6: 0.11741 | K6: 0.039 | L6: 0.25925333 | M6: 0.054 | N6: 0.22045467 | O6: 0.10572567 | P6: 0.13818667 | Q6: 0.062661333 | R6: 0.12012333 | S6: 0.05 | T6: 0.098061333 | U6: 0.17258467 | V6: 0.14990667 | W6: 0.049 | X6: 0.24689667 | Y6: 0.058 | Z6: 0.10785067 | AA6: 0.186419 | AB6: 0.054 | AC6: 0.09256 | AD6: 0.045 | AE6: 0.135485 | AF6: 0.20978467 | AG6: 0.11184633 | AH6: 0.15386533 | AI6: 0.10146667 | AJ6: 0.173698 | AK6: 0.50465167 | AL6: 0.052 | AM6: 0.22719 | AN6: 0.114628 | AO6: 0.179519 | AP6: 0.090713333 | AQ6: 0.092241667 | AR6: 0.049 | AS6: 0.27069733 | AT6: 0.39235667 | AU6: 0.054 | AV6: 0.044 | AW6: 0.103687 | AX6: 0.06 | AY6: 0.11071533 | AZ6: 0.18784733 | BA6: 0.034 | BB6: 0.038 | BC6: 0.16333933 | BD6: 0.063094667 | BE6: 0.170346 | BF6: 0.048 | BG6: 0.083232 | BH6: 0.029 | BI6: 0.23124367 | BJ6: 0.19430533 | BK6: 0.100826 | BL6: 0.047 | BM6: 0.93643467 | BN6: 0.29010867 | BO6: 0.109104 | BP6: 0.055 | BQ6: 0.18942 | BR6: 0.301805 | BS6: 0.10790933 | BT6: 0.038 | BU6: 0.13435267 | BV6: 0.10220667 | BW6: 0.12033 | BX6: 0.34149967 | BY6: 0.131454 | BZ6: 0.29054967 | CA6: 0.089423333 | CB6: 0.154308 | CC6: 0.082843 | CD6: 0.11860533 | CE6: 0.165122 | CF6: 0.17398667 | CG6: 0.072079667 | CH6: 0.11267467 | CI6: 0.049 | CJ6: 0.117112 | CK6: 0.142342 | CL6: 0.057284667 | CM6: 0.12576 | CN6: 0.044 | CO6: 0.05 | CP6: 0.27652333 | CQ6: 0.051 | CR6: 0.048 | CS6: 0.318224 | CT6: 0.13803694 | CU6: 13.113509
A7: 6 | B7: 2.5 | C7: 0.12659 | D7: 0.058314 | E7: 0.34581933 | F7: 0.057 | G7: 0.23057933 | H7: 0.17566 | I7: 0.046 | J7: 0.064282 | K7: 0.15170667 | L7: 0.041 | M7: 0.11468333 | N7: 0.106405 | O7: 0.086916333 | P7: 0.099106667 | Q7: 0.11029867 | R7: 0.134748 | S7: 0.05 | T7: 0.280096 | U7: 0.056 | V7: 0.041 | W7: 0.086253333 | X7: 0.111954 | Y7: 0.21669333 | Z7: 0.15348867 | AA7: 0.060305667 | AB7: 0.15477 | AC7: 0.22052 | AD7: 0.045 | AE7: 0.052 | AF7: 0.171954 | AG7: 0.076840333 | AH7: 0.216461 | AI7: 0.207518 | AJ7: 0.13198333 | AK7: 0.50461533 | AL7: 0.052 | AM7: 0.048 | AN7: 0.14512933 | AO7: 0.063834333 | AP7: 0.053 | AQ7: 0.17442167 | AR7: 0.049 | AS7: 0.24806567 | AT7: 0.130412 | AU7: 0.16402133 | AV7: 0.19152233 | AW7: 0.19759067 | AX7: 0.06 | AY7: 0.082231333 | AZ7: 0.064843333 | BA7: 0.034 | BB7: 0.20696733 | BC7: 0.048 | BD7: 0.11975733 | BE7: 0.091032 | BF7: 0.048 | BG7: 0.214178 | BH7: 0.029 | BI7: 0.33340967 | BJ7: 0.039 | BK7: 0.038 | BL7: 0.047 | BM7: 1.06447 | BN7: 0.159502 | BO7: 0.155682 | BP7: 0.055 | BQ7: 0.13588 | BR7: 0.155168 | BS7: 0.14984133 | BT7: 0.13859 | BU7: 0.130088 | BV7: 0.054 | BW7: 0.26902333 | BX7: 0.114409 | BY7: 0.14231667 | BZ7: 0.13 | CA7: 0.30408733 | CB7: 0.18411133 | CC7: 0.286702 | CD7: 0.053 | CE7: 0.056 | CF7: 0.047 | CG7: 0.18686633 | CH7: 0.073503 | CI7: 0.049 | CJ7: 0.14139933 | CK7: 0.048 | CL7: 0.046 | CM7: 0.05232 | CN7: 0.044 | CO7: 0.146684 | CP7: 0.037 | CQ7: 0.11694933 | CR7: 0.24732433 | CS7: 0.063028 | CT7: 0.13469394 | CU7: 12.795924
A8: 7 | B8: 3 | C8: 0.055 | D8: 0.19614 | E8: 0.056 | F8: 0.057 | G8: 0.104197 | H8: 0.10494467 | I8: 0.046 | J8: 0.10855533 | K8: 0.039 | L8: 0.041 | M8: 0.11468333 | N8: 0.21140967 | O8: 0.068107 | P8: 0.047 | Q8: 0.075653333 | R8: 0.13494933 | S8: 0.05 | T8: 0.05 | U8: 0.056 | V8: 0.19074667 | W8: 0.072706667 | X8: 0.039 | Y8: 0.058 | Z8: 0.11117767 | AA8: 0.066611333 | AB8: 0.08759 | AC8: 0.056 | AD8: 0.19701267 | AE8: 0.052 | AF8: 0.076398 | AG8: 0.047668667 | AH8: 0.087388333 | AI8: 0.09652 | AJ8: 0.116248 | AK8: 0.45461133 | AL8: 0.052 | AM8: 0.153885 | AN8: 0.046 | AO8: 0.18871033 | AP8: 0.120884 | AQ8: 0.058 | AR8: 0.17259333 | AS8: 0.062142 | AT8: 0.12278933 | AU8: 0.054 | AV8: 0.067293 | AW8: 0.168709 | AX8: 0.06 | AY8: 0.049 | AZ8: 0.11931733 | BA8: 0.034 | BB8: 0.13825867 | BC8: 0.18369333 | BD8: 0.24482733 | BE8: 0.21729467 | BF8: 0.048 | BG8: 0.047 | BH8: 0.029 | BI8: 0.52019367 | BJ8: 0.10458967 | BK8: 0.16045733 | BL8: 0.047 | BM8: 1.7299 | BN8: 0.209674 | BO8: 0.047 | BP8: 0.055 | BQ8: 0.22001333 | BR8: 0.057037333 | BS8: 0.052 | BT8: 0.038 | BU8: 0.19441133 | BV8: 0.054 | BW8: 0.10619933 | BX8: 0.309073 | BY8: 0.054 | BZ8: 0.101283 | CA8: 0.058272 | CB8: 0.23482133 | CC8: 0.167246 | CD8: 0.085802667 | CE8: 0.156728 | CF8: 0.180147 | CG8: 0.040622667 | CH8: 0.19885233 | CI8: 0.049 | CJ8: 0.21116267 | CK8: 0.265318 | CL8: 0.23064633 | CM8: 0.12144 | CN8: 0.044 | CO8: 0.060742667 | CP8: 0.037 | CQ8: 0.16641133 | CR8: 0.13002 | CS8: 0.090407333 | CT8: 0.13106514 | CU8: 12.451189
A9: 8 | B9: 3.5 | C9: 0.133749 | D9: 0.043 | E9: 0.19808 | F9: 0.057 | G9: 0.248671 | H9: 0.17954667 | I9: 0.046 | J9: 0.073136667 | K9: 0.178223 | L9: 0.041 | M9: 0.081583333 | N9: 0.092603333 | O9: 0.124535 | P9: 0.19029333 | Q9: 0.084314667 | R9: 0.25522867 | S9: 0.05 | T9: 0.19495033 | U9: 0.056 | V9: 0.041 | W9: 0.049 | X9: 0.15031 | Y9: 0.18062667 | Z9: 0.079715667 | AA9: 0.18011333 | AB9: 0.107744 | AC9: 0.25708 | AD9: 0.045 | AE9: 0.118788 | AF9: 0.294392 | AG9: 0.141018 | AH9: 0.182684 | AI9: 0.103589 | AJ9: 0.18943333 | AK9: 0.053 | AL9: 0.052 | AM9: 0.121305 | AN9: 0.21375733 | AO9: 0.09827 | AP9: 0.053 | AQ9: 0.201815 | AR9: 0.049 | AS9: 0.32745733 | AT9: 0.27067267 | AU9: 0.054 | AV9: 0.044 | AW9: 0.046 | AX9: 0.06 | AY9: 0.14394667 | AZ9: 0.112722 | BA9: 0.18209233 | BB9: 0.176246 | BC9: 0.061569333 | BD9: 0.10761533 | BE9: 0.073438 | BF9: 0.048 | BG9: 0.10252433 | BH9: 0.029 | BI9: 0.075624 | BJ9: 0.23165767 | BK9: 0.093845333 | BL9: 0.047 | BM9: 0.186248 | BN9: 0.21633 | BO9: 0.217786 | BP9: 0.12179467 | BQ9: 0.179408 | BR9: 0.029 | BS9: 0.052 | BT9: 0.038 | BU9: 0.04 | BV9: 0.11598 | BW9: 0.23942067 | BX9: 0.18269467 | BY9: 0.054 | BZ9: 0.31927033 | CA9: 0.14153133 | CB9: 0.171026 | CC9: 0.229771 | CD9: 0.094003333 | CE9: 0.13994 | CF9: 0.123183 | CG9: 0.17089867 | CH9: 0.05 | CI9: 0.049 | CJ9: 0.052 | CK9: 0.048 | CL9: 0.18786633 | CM9: 0.05232 | CN9: 0.044 | CO9: 0.05 | CP9: 0.23829033 | CQ9: 0.051 | CR9: 0.048 | CS9: 0.29084433 | CT9: 0.12422709 | CU9: 11.801574
A10: 9 | B10: 4 | C10: 0.133749 | D10: 0.211454 | E10: 0.203736 | F10: 0.057 | G10: 0.086105333 | H10: 0.067145 | I10: 0.046 | J10: 0.12626467 | K10: 0.152701 | L10: 0.13477667 | M10: 0.14778333 | N10: 0.21769067 | O10: 0.054 | P10: 0.047 | Q10: 0.10163733 | R10: 0.074061333 | S10: 0.05 | T10: 0.183207 | U10: 0.056 | V10: 0.17032667 | W10: 0.049 | X10: 0.25306467 | Y10: 0.094066667 | Z10: 0.19912667 | AA10: 0.054 | AB10: 0.134616 | AC10: 0.056 | AD10: 0.11409667 | AE10: 0.10765667 | AF10: 0.064948667 | AG10: 0.036 | AH10: 0.053 | AI10: 0.200449 | AJ10: 0.049 | AK10: 0.103047 | AL10: 0.052 | AM10: 0.048 | AN10: 0.046 | AO10: 0.27960167 | AP10: 0.053 | AQ10: 0.064848333 | AR10: 0.049 | AS10: 0.165199 | AT10: 0.18630667 | AU10: 0.10901067 | AV10: 0.19152233 | AW10: 0.313887 | AX10: 0.06 | AY10: 0.049 | AZ10: 0.042 | BA10: 0.057383 | BB10: 0.147496 | BC10: 0.14298533 | BD10: 0.23827667 | BE10: 0.27013933 | BF10: 0.048 | BG10: 0.19488567 | BH10: 0.029 | BI10: 0.048 | BJ10: 0.039 | BK10: 0.13698 | BL10: 0.047 | BM10: 0.048 | BN10: 0.10845067 | BO10: 0.047 | BP10: 0.063349333 | BQ10: 0.22681067 | BR10: 0.176196 | BS10: 0.12188667 | BT10: 0.13859 | BU10: 0.28449933 | BV10: 0.14352667 | BW10: 0.1792 | BX10: 0.15920867 | BY10: 0.14231667 | BZ10: 0.058 | CA10: 0.14153133 | CB10: 0.21197667 | CC10: 0.22063967 | CD10: 0.053 | CE10: 0.056 | CF10: 0.19290867 | CG10: 0.09667 | CH10: 0.05 | CI10: 0.049 | CJ10: 0.27162333 | CK10: 0.207592 | CL10: 0.157537 | CM10: 0.12144 | CN10: 0.044 | CO10: 0.15742667 | CP10: 0.075229333 | CQ10: 0.051 | CR10: 0.31567967 | CS10: 0.043 | CT10: 0.12011074 | CU10: 11.410521
A11: 10 | B11: 4.5 | C11: 0.055 | D11: 0.043 | E11: 0.056 | F11: 0.057 | G11: 0.154394 | H11: 0.281733 | I11: 0.046 | J11: 0.055427333 | K11: 0.064524333 | L11: 0.041 | M11: 0.054 | N11: 0.14018833 | O11: 0.138642 | P11: 0.073053333 | Q11: 0.054 | R11: 0.24299333 | S11: 0.05 | T11: 0.100274 | U11: 0.056 | V11: 0.06142 | W11: 0.10996 | X11: 0.083524 | Y11: 0.058 | Z11: 0.12868067 | AA11: 0.18011333 | AB11: 0.054 | AC11: 0.056 | AD11: 0.127916 | AE11: 0.085394 | AF11: 0.218252 | AG11: 0.15268667 | AH11: 0.21150267 | AI11: 0.052 | AJ11: 0.049 | AK11: 0.370225 | AL11: 0.052 | AM11: 0.22719 | AN11: 0.16038 | AO11: 0.047 | AP11: 0.090713333 | AQ11: 0.14702833 | AR11: 0.15405433 | AS11: 0.24469867 | AT11: 0.273114 | AU11: 0.10901067 | AV11: 0.067293 | AW11: 0.10096883 | AX11: 0.06 | AY11: 0.14394667 | AZ11: 0.21069367 | BA11: 0.080766 | BB11: 0.059484 | BC11: 0.10227733 | BD11: 0.114166 | BE11: 0.064625333 | BF11: 0.048 | BG11: 0.047 | BH11: 0.029 | BI11: 0.048 | BJ11: 0.19430533 | BK11: 0.054496667 | BL11: 0.047 | BM11: 0.154828 | BN11: 0.24600633 | BO11: 0.047 | BP11: 0.130144 | BQ11: 0.05 | BR11: 0.036009333 | BS11: 0.135864 | BT11: 0.038 | BU11: 0.04 | BV11: 0.054 | BW11: 0.048 | BX11: 0.15976067 | BY11: 0.118545 | BZ11: 0.21 | CA11: 0.046 | CB11: 0.190238 | CC11: 0.121209 | CD11: 0.126806 | CE11: 0.215486 | CF11: 0.12946933 | CG11: 0.032 | CH11: 0.191018 | CI11: 0.049 | CJ11: 0.080938667 | CK11: 0.105726 | CL11: 0.090089667 | CM11: 0.048 | CN11: 0.156064 | CO11: 0.05 | CP11: 0.13582933 | CQ11: 0.051 | CR11: 0.06167 | CS11: 0.197385 | CT11: 0.10826529 | CU11: 10.285203
A12: 11 | B12: 5 | C12: 0.176703 | D12: 0.134884 | E12: 0.262844 | F12: 0.057 | G12: 0.26510767 | H12: 0.043 | I12: 0.046 | J12: 0.064282 | K12: 0.170599 | L12: 0.041 | M12: 0.17536667 | N12: 0.085082667 | O12: 0.054 | P12: 0.16424 | Q12: 0.131952 | R12: 0.12012333 | S12: 0.05 | T12: 0.27788333 | U12: 0.056 | V12: 0.041 | W12: 0.049 | X12: 0.15773067 | Y12: 0.21669333 | Z12: 0.047 | AA12: 0.066611333 | AB12: 0.054 | AC12: 0.16568 | AD12: 0.045 | AE12: 0.14105067 | AF12: 0.16348667 | AG12: 0.036 | AH12: 0.16439333 | AI12: 0.18418867 | AJ12: 0.25668733 | AK12: 0.070628 | AL12: 0.052 | AM12: 0.048 | AN12: 0.099377333 | AO12: 0.133624 | AP12: 0.083170667 | AQ12: 0.119635 | AR12: 0.067539 | AS12: 0.15486867 | AT12: 0.120348 | AU12: 0.054 | AV12: 0.044 | AW12: 0.079782667 | AX12: 0.06 | AY12: 0.049 | AZ12: 0.112722 | BA12: 0.15870933 | BB12: 0.160366 | BC12: 0.048 | BD12: 0.075236667 | BE12: 0.047 | BF12: 0.048 | BG12: 0.047 | BH12: 0.029 | BI12: 0.199932 | BJ12: 0.141942 | BK12: 0.100826 | BL12: 0.047 | BM12: 0.07942 | BN12: 0.19962167 | BO12: 0.140156 | BP12: 0.055 | BQ12: 0.37059733 | BR12: 0.085074667 | BS12: 0.052 | BT12: 0.038 | BU12: 0.04 | BV12: 0.07466 | BW12: 0.26212567 | BX12: 0.23875133 | BY12: 0.098450667 | BZ12: 0.21054667 | CA12: 0.156448 | CB12: 0.28303733 | CC12: 0.26215667 | CD12: 0.053 | CE12: 0.081182 | CF12: 0.14224 | CG12: 0.089256667 | CH12: 0.081337333 | CI12: 0.049 | CJ12: 0.052 | CK12: 0.048 | CL12: 0.20922667 | CM12: 0.12576 | CN12: 0.086024 | CO12: 0.05 | CP12: 0.17769367 | CQ12: 0.23236067 | CR12: 0.074194667 | CS12: 0.13713967 | CT12: 0.11527114 | CU12: 10.950758
A13: 12 | B13: 5.5 | C13: 0.090795 | D13: 0.11957 | E13: 0.13897333 | F13: 0.057 | G13: 0.132881 | H13: 0.244432 | I13: 0.046 | J13: 0.11741 | K13: 0.14607133 | L13: 0.054396667 | M13: 0.054 | N13: 0.27033533 | O13: 0.054 | P13: 0.047 | Q13: 0.054 | R13: 0.047 | S13: 0.05 | T13: 0.057182 | U13: 0.056 | V13: 0.041 | W13: 0.049 | X13: 0.039 | Y13: 0.058 | Z13: 0.23767533 | AA13: 0.054 | AB13: 0.054 | AC13: 0.1474 | AD13: 0.19701267 | AE13: 0.052 | AF13: 0.076398 | AG13: 0.106012 | AH13: 0.13225133 | AI13: 0.16436933 | AJ13: 0.049 | AK13: 0.14617133 | AL13: 0.052 | AM13: 0.22719 | AN13: 0.046 | AO13: 0.24425133 | AP13: 0.16967 | AQ13: 0.058 | AR13: 0.049 | AS13: 0.21820733 | AT13: 0.057 | AU13: 0.16402133 | AV13: 0.207051 | AW13: 0.294198 | AX13: 0.06 | AY13: 0.29355343 | AZ13: 0.13337333 | BA13: 0.034 | BB13: 0.18485733 | BC13: 0.095492667 | BD13: 0.24637133 | BE13: 0.20845067 | BF13: 0.048 | BG13: 0.136538 | BH13: 0.029 | BI13: 0.048 | BJ13: 0.039 | BK13: 0.15347667 | BL13: 0.047 | BM13: 0.048 | BN13: 0.10475733 | BO13: 0.12463 | BP13: 0.130144 | BQ13: 0.064378667 | BR13: 0.12713067 | BS13: 0.052 | BT13: 0.13859 | BU13: 0.055014667 | BV13: 0.18484667 | BW13: 0.360366 | BX13: 0.161772 | BY13: 0.13229 | BZ13: 0.146 | CA13: 0.24933467 | CB13: 0.059895333 | CC13: 0.14516767 | CD13: 0.126806 | CE13: 0.056 | CF13: 0.19283667 | CG13: 0.13951 | CH13: 0.057834333 | CI13: 0.0651282 | CJ13: 0.300562 | CK13: 0.136816 | CL13: 0.23270667 | CM13: 0.048 | CN13: 0.044 | CO13: 0.05 | CP13: 0.037 | CQ13: 0.051 | CR13: 0.28948067 | CS13: 0.14854533 | CT13: 0.11836403 | CU13: 11.244583
... A49: 48 | B49: 23.5 | C49: 0.447443 | D49: 0.043 | E49: 0.34582067 | F49: 0.057 | G49: 0.054 | H49: 0.19442233 | I49: 0.080879667 | J49: 0.055427333 | K49: 0.11225933 | L49: 0.041 | M49: 0.11694 | N49: 0.055 | O49: 0.42389267 | P49: 0.047 | Q49: 0.054 | R49: 0.343178 | S49: 0.05 | T49: 0.32815733 | U49: 0.48597733 | V49: 0.041 | W49: 0.3624 | X49: 0.087636 | Y49: 0.058 | Z49: 0.47811167 | AA49: 0.17380767 | AB49: 0.191898 | AC49: 0.12912 | AD49: 0.54794 | AE49: 0.40925667 | AF49: 0.32027267 | AG49: 0.047668667 | AH49: 0.17880267 | AI49: 0.150966 | AJ49: 0.743428 | AK49: 0.93216067 | AL49: 0.159253 | AM49: 0.16203 | AN49: 0.72522333 | AO49: 0.06307 | AP49: 0.32139467 | AQ49: 0.058 | AR49: 0.067539 | AS49: 0.68506633 | AT49: 0.212794 | AU49: 0.70146533 | AV49: 0.60894667 | AW49: 0.164163 | AX49: 0.62299067 | AY49: 0.049 | AZ49: 0.112722 | BA49: 0.33706167 | BB49: 0.20696733 | BC49: 0.393736 | BD49: 0.22013133 | BE49: 0.179096 | BF49: 0.048 | BG49: 0.047 | BH49: 0.029 | BI49: 0.25321467 | BJ49: 0.14489 | BK49: 0.15347667 | BL49: 0.34678667 | BM49: 0.76375533 | BN49: 0.23036867 | BO49: 0.047 | BP49: 0.063349333 | BQ49: 0.055263333 | BR49: 0.090284667 | BS49: 0.20575067 | BT49: 0.038 | BU49: 0.17064333 | BV49: 0.15147133 | BW49: 0.500527 | BX49: 0.065953 | BY49: 0.74271167 | BZ49: 0.058 | CA49: 0.046 | CB49: 0.29528867 | CC49: 0.19280967 | CD49: 0.053 | CE49: 0.056 | CF49: 0.218369 | CG49: 0.13654467 | CH49: 0.05 | CI49: 0.049 | CJ49: 0.22821533 | CK49: 0.075328 | CL49: 0.23543867 | CM49: 0.07824 | CN49: 0.072016 | CO49: 0.087599333 | CP49: 0.14204133 | CQ49: 0.11694933 | CR49: 0.22456467 | CS49: 0.21808867 | CT49: 0.22125744 | CU49: 21.019456

Sheet PV_kW
A1: period | B1: hour | C1: BES_TR2_three312_A | D1: BES_TR2_three321_B | E1: BES_TR2_three368_A | F1: BES_TR2_three388_A | G1: BES_TR2_three409_C | H1: BES_TR2_three478_B | I1: BES_TR2_three97_B | J1: BES_TR2_three133_C | K1: BES_TR2_three160_C | L1: BES_TR2_five58_C | M1: BES_TR2_five147_C | N1: BES_TR2_five149_A | O1: BES_TR2_five160_C | P1: BES_TR2_five170_A | Q1: BES_TR2_five177_A | R1: BES_TR2_five67_C | S1: BES_TR2_five243_B | T1: BES_TR2_five284_C | U1: BES_TR2_five285_B | V1: BES_TR2_five303_B | W1: BES_TR2_five324_B | X1: BES_TR2_five355_A | Y1: BES_TR2_five394_C | Z1: BES_TR2_five451_A | AA1: BES_TR2_five466_A | AB1: BES_TR2_five494_B | AC1: BES_TR2_five512_A | AD1: BES_TR2_five520_C | AE1: BES_TR2_five540_A | AF1: BES_TR2_five588_A | AG1: BES_TR2_five649_A | AH1: BES_TR2_five663_C | AI1: BES_TR2_five685_B | AJ1: BES_TR2_five695_A | AK1: BES_TR2_five704_A | AL1: BES_TR2_five733_C | AM1: BES_TR2_five117_B | AN1: BES_TR2_five778_B | AO1: BES_TR2_five799_C | AP1: BES_TR2_five801_C | AQ1: BES_TR2_five831_C | AR1: BES_TR2_five881_C | AS1: BES_TR2_five118_B | AT1: BES_TR2_six64_A | AU1: BES_TR2_six154_C | AV1: BES_TR2_six173_C | AW1: BES_TR2_six186_A | AX1: BES_TR2_six191_B | AY1: BES_TR2_six203_A | AZ1: BES_TR2_six232_C | BA1: BES_TR2_six238_A | BB1: BES_TR2_six249_B | BC1: BES_TR2_six254_B | BD1: BES_TR2_six269_C | BE1: BES_TR2_six289_C | BF1: BES_TR2_six317_C | BG1: BES_TR2_six326_A | BH1: BES_TR2_six329_A | BI1: BES_TR2_six342_A | BJ1: BES_TR2_six349_A | BK1: BES_TR2_six350_B | BL1: BES_TR2_six362_C | BM1: BES_TR2_six365_C | BN1: BES_TR2_six378_A | BO1: BES_TR2_six385_B | BP1: BES_TR2_six387_A | BQ1: BES_TR2_six392_C | BR1: BES_TR2_six410_A | BS1: BES_TR2_six431_C | BT1: BES_TR2_six484_B | BU1: BES_TR2_six512_B | BV1: BES_TR2_six518_B | BW1: BES_TR2_six523_C | BX1: BES_TR2_six571_C | BY1: BES_TR2_six583_A | BZ1: BES_TR2_six625_A | CA1: BES_TR2_six646_B | CB1: BES_TR2_six87_A | CC1: BES_TR2_six652_A | CD1: BES_TR2_six665_B | CE1: BES_TR2_six667_A | CF1: BES_TR2_six721_A | CG1: BES_TR2_six740_A | CH1: BES_TR2_six758_B | CI1: BES_TR2_six784_B | CJ1: BES_TR2_six799_B | CK1: BES_TR2_six807_A | CL1: BES_TR2_six885_A | CM1: BES_TR2_six894_B | CN1: BES_TR2_six914_A | CO1: BES_TR2_six921_B | CP1: BES_TR2_six929_A | CQ1: BES_TR2_six938_A | CR1: BES_TR2_six990_B | CS1: BES_TR2_six1020_A | CT1: fleet_average | CU1: fleet_total
A2: 1 | B2: 0 | C2: 0 | D2: 0 | E2: 0 | F2: 0 | G2: 0 | H2: 0 | I2: 0 | J2: 0 | K2: 0 | L2: 0 | M2: 0 | N2: 0 | O2: 0 | P2: 0 | Q2: 0 | R2: 0 | S2: 0 | T2: 0 | U2: 0 | V2: 0 | W2: 0 | X2: 0 | Y2: 0 | Z2: 0 | AA2: 0 | AB2: 0 | AC2: 0 | AD2: 0 | AE2: 0 | AF2: 0 | AG2: 0 | AH2: 0 | AI2: 0 | AJ2: 0 | AK2: 0 | AL2: 0 | AM2: 0 | AN2: 0 | AO2: 0 | AP2: 0 | AQ2: 0 | AR2: 0 | AS2: 0 | AT2: 0 | AU2: 0 | AV2: 0 | AW2: 0 | AX2: 0 | AY2: 0 | AZ2: 0 | BA2: 0 | BB2: 0 | BC2: 0 | BD2: 0 | BE2: 0 | BF2: 0 | BG2: 0 | BH2: 0 | BI2: 0 | BJ2: 0 | BK2: 0 | BL2: 0 | BM2: 0 | BN2: 0 | BO2: 0 | BP2: 0 | BQ2: 0 | BR2: 0 | BS2: 0 | BT2: 0 | BU2: 0 | BV2: 0 | BW2: 0 | BX2: 0 | BY2: 0 | BZ2: 0 | CA2: 0 | CB2: 0 | CC2: 0 | CD2: 0 | CE2: 0 | CF2: 0 | CG2: 0 | CH2: 0 | CI2: 0 | CJ2: 0 | CK2: 0 | CL2: 0 | CM2: 0 | CN2: 0 | CO2: 0 | CP2: 0 | CQ2: 0 | CR2: 0 | CS2: 0 | CT2: 0 | CU2: 0
A3: 2 | B3: 0.5 | C3: 0 | D3: 0 | E3: 0 | F3: 0 | G3: 0 | H3: 0 | I3: 0 | J3: 0 | K3: 0 | L3: 0 | M3: 0 | N3: 0 | O3: 0 | P3: 0 | Q3: 0 | R3: 0 | S3: 0 | T3: 0 | U3: 0 | V3: 0 | W3: 0 | X3: 0 | Y3: 0 | Z3: 0 | AA3: 0 | AB3: 0 | AC3: 0 | AD3: 0 | AE3: 0 | AF3: 0 | AG3: 0 | AH3: 0 | AI3: 0 | AJ3: 0 | AK3: 0 | AL3: 0 | AM3: 0 | AN3: 0 | AO3: 0 | AP3: 0 | AQ3: 0 | AR3: 0 | AS3: 0 | AT3: 0 | AU3: 0 | AV3: 0 | AW3: 0 | AX3: 0 | AY3: 0 | AZ3: 0 | BA3: 0 | BB3: 0 | BC3: 0 | BD3: 0 | BE3: 0 | BF3: 0 | BG3: 0 | BH3: 0 | BI3: 0 | BJ3: 0 | BK3: 0 | BL3: 0 | BM3: 0 | BN3: 0 | BO3: 0 | BP3: 0 | BQ3: 0 | BR3: 0 | BS3: 0 | BT3: 0 | BU3: 0 | BV3: 0 | BW3: 0 | BX3: 0 | BY3: 0 | BZ3: 0 | CA3: 0 | CB3: 0 | CC3: 0 | CD3: 0 | CE3: 0 | CF3: 0 | CG3: 0 | CH3: 0 | CI3: 0 | CJ3: 0 | CK3: 0 | CL3: 0 | CM3: 0 | CN3: 0 | CO3: 0 | CP3: 0 | CQ3: 0 | CR3: 0 | CS3: 0 | CT3: 0 | CU3: 0
A4: 3 | B4: 1 | C4: 0 | D4: 0 | E4: 0 | F4: 0 | G4: 0 | H4: 0 | I4: 0 | J4: 0 | K4: 0 | L4: 0 | M4: 0 | N4: 0 | O4: 0 | P4: 0 | Q4: 0 | R4: 0 | S4: 0 | T4: 0 | U4: 0 | V4: 0 | W4: 0 | X4: 0 | Y4: 0 | Z4: 0 | AA4: 0 | AB4: 0 | AC4: 0 | AD4: 0 | AE4: 0 | AF4: 0 | AG4: 0 | AH4: 0 | AI4: 0 | AJ4: 0 | AK4: 0 | AL4: 0 | AM4: 0 | AN4: 0 | AO4: 0 | AP4: 0 | AQ4: 0 | AR4: 0 | AS4: 0 | AT4: 0 | AU4: 0 | AV4: 0 | AW4: 0 | AX4: 0 | AY4: 0 | AZ4: 0 | BA4: 0 | BB4: 0 | BC4: 0 | BD4: 0 | BE4: 0 | BF4: 0 | BG4: 0 | BH4: 0 | BI4: 0 | BJ4: 0 | BK4: 0 | BL4: 0 | BM4: 0 | BN4: 0 | BO4: 0 | BP4: 0 | BQ4: 0 | BR4: 0 | BS4: 0 | BT4: 0 | BU4: 0 | BV4: 0 | BW4: 0 | BX4: 0 | BY4: 0 | BZ4: 0 | CA4: 0 | CB4: 0 | CC4: 0 | CD4: 0 | CE4: 0 | CF4: 0 | CG4: 0 | CH4: 0 | CI4: 0 | CJ4: 0 | CK4: 0 | CL4: 0 | CM4: 0 | CN4: 0 | CO4: 0 | CP4: 0 | CQ4: 0 | CR4: 0 | CS4: 0 | CT4: 0 | CU4: 0
A5: 4 | B5: 1.5 | C5: 0 | D5: 0 | E5: 0 | F5: 0 | G5: 0 | H5: 0 | I5: 0 | J5: 0 | K5: 0 | L5: 0 | M5: 0 | N5: 0 | O5: 0 | P5: 0 | Q5: 0 | R5: 0 | S5: 0 | T5: 0 | U5: 0 | V5: 0 | W5: 0 | X5: 0 | Y5: 0 | Z5: 0 | AA5: 0 | AB5: 0 | AC5: 0 | AD5: 0 | AE5: 0 | AF5: 0 | AG5: 0 | AH5: 0 | AI5: 0 | AJ5: 0 | AK5: 0 | AL5: 0 | AM5: 0 | AN5: 0 | AO5: 0 | AP5: 0 | AQ5: 0 | AR5: 0 | AS5: 0 | AT5: 0 | AU5: 0 | AV5: 0 | AW5: 0 | AX5: 0 | AY5: 0 | AZ5: 0 | BA5: 0 | BB5: 0 | BC5: 0 | BD5: 0 | BE5: 0 | BF5: 0 | BG5: 0 | BH5: 0 | BI5: 0 | BJ5: 0 | BK5: 0 | BL5: 0 | BM5: 0 | BN5: 0 | BO5: 0 | BP5: 0 | BQ5: 0 | BR5: 0 | BS5: 0 | BT5: 0 | BU5: 0 | BV5: 0 | BW5: 0 | BX5: 0 | BY5: 0 | BZ5: 0 | CA5: 0 | CB5: 0 | CC5: 0 | CD5: 0 | CE5: 0 | CF5: 0 | CG5: 0 | CH5: 0 | CI5: 0 | CJ5: 0 | CK5: 0 | CL5: 0 | CM5: 0 | CN5: 0 | CO5: 0 | CP5: 0 | CQ5: 0 | CR5: 0 | CS5: 0 | CT5: 0 | CU5: 0
A6: 5 | B6: 2 | C6: 0 | D6: 0 | E6: 0 | F6: 0 | G6: 0 | H6: 0 | I6: 0 | J6: 0 | K6: 0 | L6: 0 | M6: 0 | N6: 0 | O6: 0 | P6: 0 | Q6: 0 | R6: 0 | S6: 0 | T6: 0 | U6: 0 | V6: 0 | W6: 0 | X6: 0 | Y6: 0 | Z6: 0 | AA6: 0 | AB6: 0 | AC6: 0 | AD6: 0 | AE6: 0 | AF6: 0 | AG6: 0 | AH6: 0 | AI6: 0 | AJ6: 0 | AK6: 0 | AL6: 0 | AM6: 0 | AN6: 0 | AO6: 0 | AP6: 0 | AQ6: 0 | AR6: 0 | AS6: 0 | AT6: 0 | AU6: 0 | AV6: 0 | AW6: 0 | AX6: 0 | AY6: 0 | AZ6: 0 | BA6: 0 | BB6: 0 | BC6: 0 | BD6: 0 | BE6: 0 | BF6: 0 | BG6: 0 | BH6: 0 | BI6: 0 | BJ6: 0 | BK6: 0 | BL6: 0 | BM6: 0 | BN6: 0 | BO6: 0 | BP6: 0 | BQ6: 0 | BR6: 0 | BS6: 0 | BT6: 0 | BU6: 0 | BV6: 0 | BW6: 0 | BX6: 0 | BY6: 0 | BZ6: 0 | CA6: 0 | CB6: 0 | CC6: 0 | CD6: 0 | CE6: 0 | CF6: 0 | CG6: 0 | CH6: 0 | CI6: 0 | CJ6: 0 | CK6: 0 | CL6: 0 | CM6: 0 | CN6: 0 | CO6: 0 | CP6: 0 | CQ6: 0 | CR6: 0 | CS6: 0 | CT6: 0 | CU6: 0
A7: 6 | B7: 2.5 | C7: 0 | D7: 0 | E7: 0 | F7: 0 | G7: 0 | H7: 0 | I7: 0 | J7: 0 | K7: 0 | L7: 0 | M7: 0 | N7: 0 | O7: 0 | P7: 0 | Q7: 0 | R7: 0 | S7: 0 | T7: 0 | U7: 0 | V7: 0 | W7: 0 | X7: 0 | Y7: 0 | Z7: 0 | AA7: 0 | AB7: 0 | AC7: 0 | AD7: 0 | AE7: 0 | AF7: 0 | AG7: 0 | AH7: 0 | AI7: 0 | AJ7: 0 | AK7: 0 | AL7: 0 | AM7: 0 | AN7: 0 | AO7: 0 | AP7: 0 | AQ7: 0 | AR7: 0 | AS7: 0 | AT7: 0 | AU7: 0 | AV7: 0 | AW7: 0 | AX7: 0 | AY7: 0 | AZ7: 0 | BA7: 0 | BB7: 0 | BC7: 0 | BD7: 0 | BE7: 0 | BF7: 0 | BG7: 0 | BH7: 0 | BI7: 0 | BJ7: 0 | BK7: 0 | BL7: 0 | BM7: 0 | BN7: 0 | BO7: 0 | BP7: 0 | BQ7: 0 | BR7: 0 | BS7: 0 | BT7: 0 | BU7: 0 | BV7: 0 | BW7: 0 | BX7: 0 | BY7: 0 | BZ7: 0 | CA7: 0 | CB7: 0 | CC7: 0 | CD7: 0 | CE7: 0 | CF7: 0 | CG7: 0 | CH7: 0 | CI7: 0 | CJ7: 0 | CK7: 0 | CL7: 0 | CM7: 0 | CN7: 0 | CO7: 0 | CP7: 0 | CQ7: 0 | CR7: 0 | CS7: 0 | CT7: 0 | CU7: 0
A8: 7 | B8: 3 | C8: 0 | D8: 0 | E8: 0 | F8: 0 | G8: 0 | H8: 0 | I8: 0 | J8: 0 | K8: 0 | L8: 0 | M8: 0 | N8: 0 | O8: 0 | P8: 0 | Q8: 0 | R8: 0 | S8: 0 | T8: 0 | U8: 0 | V8: 0 | W8: 0 | X8: 0 | Y8: 0 | Z8: 0 | AA8: 0 | AB8: 0 | AC8: 0 | AD8: 0 | AE8: 0 | AF8: 0 | AG8: 0 | AH8: 0 | AI8: 0 | AJ8: 0 | AK8: 0 | AL8: 0 | AM8: 0 | AN8: 0 | AO8: 0 | AP8: 0 | AQ8: 0 | AR8: 0 | AS8: 0 | AT8: 0 | AU8: 0 | AV8: 0 | AW8: 0 | AX8: 0 | AY8: 0 | AZ8: 0 | BA8: 0 | BB8: 0 | BC8: 0 | BD8: 0 | BE8: 0 | BF8: 0 | BG8: 0 | BH8: 0 | BI8: 0 | BJ8: 0 | BK8: 0 | BL8: 0 | BM8: 0 | BN8: 0 | BO8: 0 | BP8: 0 | BQ8: 0 | BR8: 0 | BS8: 0 | BT8: 0 | BU8: 0 | BV8: 0 | BW8: 0 | BX8: 0 | BY8: 0 | BZ8: 0 | CA8: 0 | CB8: 0 | CC8: 0 | CD8: 0 | CE8: 0 | CF8: 0 | CG8: 0 | CH8: 0 | CI8: 0 | CJ8: 0 | CK8: 0 | CL8: 0 | CM8: 0 | CN8: 0 | CO8: 0 | CP8: 0 | CQ8: 0 | CR8: 0 | CS8: 0 | CT8: 0 | CU8: 0
