Workbook

Sheet ReadMe
A1: README
A2: Data behind the TR3 rolling-dispatch figures (SOC, demand/PV/dispatch, net, self-consumption, metrics histogram).
A3: Each quantity sheet: rows = 48 half-hour periods (with hour of day), columns = prosumers, plus fleet_average / fleet_total.
A4: Dispatch is the committed slot-1 execution of the rolling horizon (self-consumption baseline, Term 2 + Term 3).
A5: SOC is the realised state at the START of each step (fraction of capacity).
A6: net_kW = (demand - PV) + (charge - discharge); positive = import, negative = export.
A7: Regenerate: python build_workbook.py --force (see README.md for other transformers).

Sheet Summary
A1: quantity | B1: value
A2: run | B2: TR3 exact-QCP rolling (FOR_PolyS=0, FOR_LinearizeVmax=0), 48 steps, all Optimal
A3: source dispatch | B3: FOR_rolling_soc_TR3.csv
A4: source load/PV | B4: TR3_load_PV_48periods.xlsx
A5: prosumers | B5: 49
A6: PV generated kWh/day | B6: 1316.4
A7: demand kWh/day | B7: 352.4
A8: exported kWh/day | B8: 942.2
A9: imported kWh/day | B9: 7
A10: SCR % (PV used locally) | B10: 28.4
A11: SSR % (demand met locally) | B11: 98
A12: prosumer-periods |net|<50W % | B12: 55.6
A13: SOC min/max over day | B13: 0.10 / 1.00
A14: simultaneous chg+dis rows | B14: 0

Sheet FleetAverage
A1: period | B1: hour | C1: demand_avg_kW | D1: PV_avg_kW | E1: charge_avg_kW | F1: discharge_avg_kW | G1: net_avg_kW | H1: SOC_avg_pct | I1: demand_total_kW | J1: PV_total_kW | K1: net_total_kW
A2: =Demand_kW!A2 -> 1 | B2: =Demand_kW!B2 -> 0 | C2: =AVERAGE(Demand_kW!$C2:$AY2) -> 0.18860562 | D2: =AVERAGE(PV_kW!$C2:$AY2) -> 0 | E2: =AVERAGE(Charge_kW!$C2:$AY2) -> 0 | F2: =AVERAGE(Discharge_kW!$C2:$AY2) -> 0.18865306 | G2: =C2-D2+E2-F2 -> -4.7442177e-05 | H2: =AVERAGE(SOC_pct!$C2:$AY2) -> 40 | I2: =SUM(Demand_kW!$C2:$AY2) -> 9.2416753 | J2: =SUM(PV_kW!$C2:$AY2) -> 0 | K2: =I2-J2+SUM(Charge_kW!$C2:$AY2)-SUM(Discharge_kW!$C2:$AY2) -> -0.0023246667
A3: =Demand_kW!A3 -> 2 | B3: =Demand_kW!B3 -> 0.5 | C3: =AVERAGE(Demand_kW!$C3:$AY3) -> 0.17969247 | D3: =AVERAGE(PV_kW!$C3:$AY3) -> 0 | E3: =AVERAGE(Charge_kW!$C3:$AY3) -> 0 | F3: =AVERAGE(Discharge_kW!$C3:$AY3) -> 0.17973469 | G3: =C3-D3+E3-F3 -> -4.222585e-05 | H3: =AVERAGE(SOC_pct!$C3:$AY3) -> 37.63328 | I3: =SUM(Demand_kW!$C3:$AY3) -> 8.8049309 | J3: =SUM(PV_kW!$C3:$AY3) -> 0 | K3: =I3-J3+SUM(Charge_kW!$C3:$AY3)-SUM(Discharge_kW!$C3:$AY3) -> -0.0020690667
A4: =Demand_kW!A4 -> 3 | B4: =Demand_kW!B4 -> 1 | C4: =AVERAGE(Demand_kW!$C4:$AY4) -> 0.14316063 | D4: =AVERAGE(PV_kW!$C4:$AY4) -> 0 | E4: =AVERAGE(Charge_kW!$C4:$AY4) -> 0 | F4: =AVERAGE(Discharge_kW!$C4:$AY4) -> 0.14316327 | G4: =C4-D4+E4-F4 -> -2.6394558e-06 | H4: =AVERAGE(SOC_pct!$C4:$AY4) -> 35.378414 | I4: =SUM(Demand_kW!$C4:$AY4) -> 7.0148707 | J4: =SUM(PV_kW!$C4:$AY4) -> 0 | K4: =I4-J4+SUM(Charge_kW!$C4:$AY4)-SUM(Discharge_kW!$C4:$AY4) -> -0.00012933333
A5: =Demand_kW!A5 -> 4 | B5: =Demand_kW!B5 -> 1.5 | C5: =AVERAGE(Demand_kW!$C5:$AY5) -> 0.13740688 | D5: =AVERAGE(PV_kW!$C5:$AY5) -> 0 | E5: =AVERAGE(Charge_kW!$C5:$AY5) -> 0 | F5: =AVERAGE(Discharge_kW!$C5:$AY5) -> 0.13173469 | G5: =C5-D5+E5-F5 -> 0.0056721905 | H5: =AVERAGE(SOC_pct!$C5:$AY5) -> 33.581959 | I5: =SUM(Demand_kW!$C5:$AY5) -> 6.7329373 | J5: =SUM(PV_kW!$C5:$AY5) -> 0 | K5: =I5-J5+SUM(Charge_kW!$C5:$AY5)-SUM(Discharge_kW!$C5:$AY5) -> 0.27793733
A6: =Demand_kW!A6 -> 5 | B6: =Demand_kW!B6 -> 2 | C6: =AVERAGE(Demand_kW!$C6:$AY6) -> 0.13301136 | D6: =AVERAGE(PV_kW!$C6:$AY6) -> 0 | E6: =AVERAGE(Charge_kW!$C6:$AY6) -> 0 | F6: =AVERAGE(Discharge_kW!$C6:$AY6) -> 0.11708163 | G6: =C6-D6+E6-F6 -> 0.015929728 | H6: =AVERAGE(SOC_pct!$C6:$AY6) -> 31.928912 | I6: =SUM(Demand_kW!$C6:$AY6) -> 6.5175567 | J6: =SUM(PV_kW!$C6:$AY6) -> 0 | K6: =I6-J6+SUM(Charge_kW!$C6:$AY6)-SUM(Discharge_kW!$C6:$AY6) -> 0.78055667
A7: =Demand_kW!A7 -> 6 | B7: =Demand_kW!B7 -> 2.5 | C7: =AVERAGE(Demand_kW!$C7:$AY7) -> 0.11409865 | D7: =AVERAGE(PV_kW!$C7:$AY7) -> 0 | E7: =AVERAGE(Charge_kW!$C7:$AY7) -> 0 | F7: =AVERAGE(Discharge_kW!$C7:$AY7) -> 0.098510204 | G7: =C7-D7+E7-F7 -> 0.015588449 | H7: =AVERAGE(SOC_pct!$C7:$AY7) -> 30.459698 | I7: =SUM(Demand_kW!$C7:$AY7) -> 5.590834 | J7: =SUM(PV_kW!$C7:$AY7) -> 0 | K7: =I7-J7+SUM(Charge_kW!$C7:$AY7)-SUM(Discharge_kW!$C7:$AY7) -> 0.763834
A8: =Demand_kW!A8 -> 7 | B8: =Demand_kW!B8 -> 3 | C8: =AVERAGE(Demand_kW!$C8:$AY8) -> 0.1089882 | D8: =AVERAGE(PV_kW!$C8:$AY8) -> 0 | E8: =AVERAGE(Charge_kW!$C8:$AY8) -> 0 | F8: =AVERAGE(Discharge_kW!$C8:$AY8) -> 0.10293878 | G8: =C8-D8+E8-F8 -> 0.0060494218 | H8: =AVERAGE(SOC_pct!$C8:$AY8) -> 29.222647 | I8: =SUM(Demand_kW!$C8:$AY8) -> 5.3404217 | J8: =SUM(PV_kW!$C8:$AY8) -> 0 | K8: =I8-J8+SUM(Charge_kW!$C8:$AY8)-SUM(Discharge_kW!$C8:$AY8) -> 0.29642167
A9: =Demand_kW!A9 -> 8 | B9: =Demand_kW!B9 -> 3.5 | C9: =AVERAGE(Demand_kW!$C9:$AY9) -> 0.12097806 | D9: =AVERAGE(PV_kW!$C9:$AY9) -> 0.0028614845 | E9: =AVERAGE(Charge_kW!$C9:$AY9) -> 0 | F9: =AVERAGE(Discharge_kW!$C9:$AY9) -> 0.10842857 | G9: =C9-D9+E9-F9 -> 0.0096880053 | H9: =AVERAGE(SOC_pct!$C9:$AY9) -> 27.930541 | I9: =SUM(Demand_kW!$C9:$AY9) -> 5.927925 | J9: =SUM(PV_kW!$C9:$AY9) -> 0.14021274 | K9: =I9-J9+SUM(Charge_kW!$C9:$AY9)-SUM(Discharge_kW!$C9:$AY9) -> 0.47471226
A10: =Demand_kW!A10 -> 9 | B10: =Demand_kW!B10 -> 4 | C10: =AVERAGE(Demand_kW!$C10:$AY10) -> 0.11632741 | D10: =AVERAGE(PV_kW!$C10:$AY10) -> 0.041360828 | E10: =AVERAGE(Charge_kW!$C10:$AY10) -> 0.00073469388 | F10: =AVERAGE(Discharge_kW!$C10:$AY10) -> 0.067138706 | G10: =C10-D10+E10-F10 -> 0.008562575 | H10: =AVERAGE(SOC_pct!$C10:$AY10) -> 26.57101 | I10: =SUM(Demand_kW!$C10:$AY10) -> 5.7000433 | J10: =SUM(PV_kW!$C10:$AY10) -> 2.0266806 | K10: =I10-J10+SUM(Charge_kW!$C10:$AY10)-SUM(Discharge_kW!$C10:$AY10) -> 0.41956618
A11: =Demand_kW!A11 -> 10 | B11: =Demand_kW!B11 -> 4.5 | C11: =AVERAGE(Demand_kW!$C11:$AY11) -> 0.14219854 | D11: =AVERAGE(PV_kW!$C11:$AY11) -> 0.19341576 | E11: =AVERAGE(Charge_kW!$C11:$AY11) -> 0.077408163 | F11: =AVERAGE(Discharge_kW!$C11:$AY11) -> 0.023081633 | G11: =C11-D11+E11-F11 -> 0.0031093104 | H11: =AVERAGE(SOC_pct!$C11:$AY11) -> 25.735639 | I11: =SUM(Demand_kW!$C11:$AY11) -> 6.9677287 | J11: =SUM(PV_kW!$C11:$AY11) -> 9.4773725 | K11: =I11-J11+SUM(Charge_kW!$C11:$AY11)-SUM(Discharge_kW!$C11:$AY11) -> 0.15235621
A12: =Demand_kW!A12 -> 11 | B12: =Demand_kW!B12 -> 5 | C12: =AVERAGE(Demand_kW!$C12:$AY12) -> 0.13029317 | D12: =AVERAGE(PV_kW!$C12:$AY12) -> 0.38366565 | E12: =AVERAGE(Charge_kW!$C12:$AY12) -> 0.25736735 | F12: =AVERAGE(Discharge_kW!$C12:$AY12) -> 0.0022653061 | G12: =C12-D12+E12-F12 -> 0.0017295664 | H12: =AVERAGE(SOC_pct!$C12:$AY12) -> 26.319592 | I12: =SUM(Demand_kW!$C12:$AY12) -> 6.3843655 | J12: =SUM(PV_kW!$C12:$AY12) -> 18.799617 | K12: =I12-J12+SUM(Charge_kW!$C12:$AY12)-SUM(Discharge_kW!$C12:$AY12) -> 0.084748753
A13: =Demand_kW!A13 -> 12 | B13: =Demand_kW!B13 -> 5.5 | C13: =AVERAGE(Demand_kW!$C13:$AY13) -> 0.11120318 | D13: =AVERAGE(PV_kW!$C13:$AY13) -> 0.61695332 | E13: =AVERAGE(Charge_kW!$C13:$AY13) -> 0.5057551 | F13: =AVERAGE(Discharge_kW!$C13:$AY13) -> 0 | G13: =C13-D13+E13-F13 -> 4.9684952e-06 | H13: =AVERAGE(SOC_pct!$C13:$AY13) -> 29.198576 | I13: =SUM(Demand_kW!$C13:$AY13) -> 5.448956 | J13: =SUM(PV_kW!$C13:$AY13) -> 30.230713 | K13: =I13-J13+SUM(Charge_kW!$C13:$AY13)-SUM(Discharge_kW!$C13:$AY13) -> 0.00024345627
... A49: =Demand_kW!A49 -> 48 | B49: =Demand_kW!B49 -> 23.5 | C49: =AVERAGE(Demand_kW!$C49:$AY49) -> 0.27882082 | D49: =AVERAGE(PV_kW!$C49:$AY49) -> 0 | E49: =AVERAGE(Charge_kW!$C49:$AY49) -> 0 | F49: =AVERAGE(Discharge_kW!$C49:$AY49) -> 0.25022449 | G49: =C49-D49+E49-F49 -> 0.028596331 | H49: =AVERAGE(SOC_pct!$C49:$AY49) -> 49.274647 | I49: =SUM(Demand_kW!$C49:$AY49) -> 13.66222 | J49: =SUM(PV_kW!$C49:$AY49) -> 0 | K49: =I49-J49+SUM(Charge_kW!$C49:$AY49)-SUM(Discharge_kW!$C49:$AY49) -> 1.4012202

Sheet SOC_pct
A1: period | B1: hour | C1: BES_TR3_one195_C | D1: BES_TR3_one235_A | E1: BES_TR3_one242_B | F1: BES_TR3_one252_C | G1: BES_TR3_one260_C | H1: BES_TR3_one299_B | I1: BES_TR3_one313_A | J1: BES_TR3_one42_B | K1: BES_TR3_one320_B | L1: BES_TR3_one346_C | M1: BES_TR3_one363_C | N1: BES_TR3_one366_B | O1: BES_TR3_one371_C | P1: BES_TR3_one375_C | Q1: BES_TR3_one410_B | R1: BES_TR3_one50_A | S1: BES_TR3_one423_B | T1: BES_TR3_one446_B | U1: BES_TR3_one469_A | V1: BES_TR3_one477_A | W1: BES_TR3_one480_A | X1: BES_TR3_one482_B | Y1: BES_TR3_one521_C | Z1: BES_TR3_one528_C | AA1: BES_TR3_one61_A | AB1: BES_TR3_one544_A | AC1: BES_TR3_one552_B | AD1: BES_TR3_one559_C | AE1: BES_TR3_one570_B | AF1: BES_TR3_one605_A | AG1: BES_TR3_one614_B | AH1: BES_TR3_one617_A | AI1: BES_TR3_one73_A | AJ1: BES_TR3_one76_A | AK1: BES_TR3_one137_A | AL1: BES_TR3_one176_A | AM1: BES_TR3_two130_C | AN1: BES_TR3_two249_A | AO1: BES_TR3_two267_C | AP1: BES_TR3_two292_B | AQ1: BES_TR3_two308_A | AR1: BES_TR3_two313_C | AS1: BES_TR3_two137_B | AT1: BES_TR3_two316_A | AU1: BES_TR3_two339_A | AV1: BES_TR3_two149_B | AW1: BES_TR3_two225_C | AX1: BES_TR3_two229_A | AY1: BES_TR3_two242_B | AZ1: fleet_average | BA1: fleet_total
A2: 1 | B2: 0 | C2: 40 | D2: 40 | E2: 40 | F2: 40 | G2: 40 | H2: 40 | I2: 40 | J2: 40 | K2: 40 | L2: 40 | M2: 40 | N2: 40 | O2: 40 | P2: 40 | Q2: 40 | R2: 40 | S2: 40 | T2: 40 | U2: 40 | V2: 40 | W2: 40 | X2: 40 | Y2: 40 | Z2: 40 | AA2: 40 | AB2: 40 | AC2: 40 | AD2: 40 | AE2: 40 | AF2: 40 | AG2: 40 | AH2: 40 | AI2: 40 | AJ2: 40 | AK2: 40 | AL2: 40 | AM2: 40 | AN2: 40 | AO2: 40 | AP2: 40 | AQ2: 40 | AR2: 40 | AS2: 40 | AT2: 40 | AU2: 40 | AV2: 40 | AW2: 40 | AX2: 40 | AY2: 40 | AZ2: 40 | BA2: 1960
A3: 2 | B3: 0.5 | C3: 37.6201 | D3: 39.4228 | E3: 39.4228 | F3: 35.2258 | G3: 39.3977 | H3: 38.7003 | I3: 35.7366 | J3: 39.5859 | K3: 39.4228 | L3: 38.7755 | M3: 39.3224 | N3: 32.4785 | O3: 39.0983 | P3: 38.1876 | Q3: 37.9289 | R3: 37.9872 | S3: 38.3509 | T3: 38.1364 | U3: 39.3977 | V3: 38.1296 | W3: 38.1189 | X3: 39.3349 | Y3: 38.1451 | Z3: 38.6251 | AA3: 38.9835 | AB3: 35.7988 | AC3: 39.3224 | AD3: 39.2471 | AE3: 39.4855 | AF3: 39.3349 | AG3: 39.2596 | AH3: 38.613 | AI3: 33.74 | AJ3: 38.0915 | AK3: 39.4604 | AL3: 38.1311 | AM3: 39.3851 | AN3: 39.0128 | AO3: 38.2699 | AP3: 39.3349 | AQ3: 31.9831 | AR3: 39.3349 | AS3: 33.0734 | AT3: 31.4304 | AU3: 30.7929 | AV3: 38.7202 | AW3: 37.9878 | AX3: 38.3305 | AY3: 30.3552 | AZ3: 37.63328 | BA3: 1844.0307
A4: 3 | B4: 1 | C4: 34.3433 | D4: 38.0782 | E4: 35.5353 | F4: 33.6607 | G4: 36.7682 | H4: 36.5592 | I4: 35.0715 | J4: 39.1718 | K4: 36.9205 | L4: 37.7945 | M4: 37.1653 | N4: 25.6494 | O4: 38.5712 | P4: 35.3034 | Q4: 37.3391 | R4: 37.2971 | S4: 37.6607 | T4: 35.998 | U4: 38.2553 | V4: 36.3846 | W4: 37.4915 | X4: 38.6699 | Y4: 36.8163 | Z4: 37.9728 | AA4: 35.4753 | AB4: 19.503 | AC4: 38.6448 | AD4: 36.2007 | AE4: 38.0805 | AF4: 38.6699 | AG4: 37.4081 | AH4: 36.8445 | AI4: 25.9432 | AJ4: 37.577 | AK4: 38.9208 | AL4: 37.1009 | AM4: 36.5907 | AN4: 36.5499 | AO4: 37.2778 | AP4: 38.6699 | AQ4: 31.3557 | AR4: 38.6699 | AS4: 26.3772 | AT4: 29.5651 | AU4: 25.2944 | AV4: 37.0442 | AW4: 36.1551 | AX4: 36.1646 | AY4: 28.9813 | AZ4: 35.378414 | BA4: 1733.5423
A5: 4 | B5: 1.5 | C5: 33.3504 | D5: 35.6844 | E5: 34.8166 | F5: 33.0584 | G5: 36.1658 | H5: 35.3347 | I5: 33.0421 | J5: 38.7577 | K5: 36.3433 | L5: 36.6187 | M5: 36.1786 | N5: 18.779 | O5: 38.0442 | P5: 33.2821 | Q5: 34.5703 | R5: 36.6069 | S5: 36.571 | T5: 33.2316 | U5: 36.2128 | V5: 35.3427 | W5: 36.864 | X5: 36.6546 | Y5: 36.1888 | Z5: 35.864 | AA5: 34.8604 | AB5: 14.178 | AC5: 35.7683 | AD5: 34.2929 | AE5: 37.566 | AF5: 38.0048 | AG5: 35.8985 | AH5: 36.3927 | AI5: 22.5816 | AJ5: 34.5266 | AK5: 34.0085 | AL5: 36.5738 | AM5: 35.9758 | AN5: 34.8301 | AO5: 36.5626 | AP5: 38.0048 | AQ5: 30.7283 | AR5: 38.0048 | AS5: 25.3849 | AT5: 27.7664 | AU5: 14.8607 | AV5: 35.1522 | AW5: 34.909 | AX5: 34.8658 | AY5: 26.2558 | AZ5: 33.581959 | BA5: 1645.516
A6: 5 | B6: 2 | C6: 30.0944 | D6: 34.7744 | E6: 33.3384 | F6: 30.9748 | G6: 35.5635 | H6: 34.5992 | I6: 29.9944 | J6: 37.8926 | K6: 34.366 | L6: 35.9787 | M6: 35.1477 | N6: 10.5436 | O6: 35.4564 | P6: 31.3623 | Q6: 33.0452 | R6: 35.2045 | S6: 34.5223 | T6: 31.0124 | U6: 34.6331 | V6: 34.9161 | W6: 35.5471 | X6: 35.9896 | Y6: 35.5614 | Z6: 34.4734 | AA6: 32.3177 | AB6: 12.8275 | AC6: 35.0906 | AD6: 31.9065 | AE6: 36.161 | AF6: 37.3397 | AG6: 34.9018 | AH6: 35.5669 | AI6: 20.3671 | AJ6: 34.0121 | AK6: 31.2576 | AL6: 34.2018 | AM6: 35.3609 | AN6: 32.5116 | AO6: 34.5556 | AP6: 37.3397 | AQ6: 30.1009 | AR6: 37.3397 | AS6: 24.316 | AT6: 27.0888 | AU6: 10 | AV6: 34.5247 | AW6: 31.8173 | AX6: 33.7379 | AY6: 24.8818 | AZ6: 31.928912 | BA6: 1564.5167
A7: 6 | B7: 2.5 | C7: 27.9588 | D7: 32.2787 | E7: 31.3133 | F7: 30.3725 | G7: 34.662 | H7: 31.3346 | I7: 28.9073 | J7: 37.0276 | K7: 33.2638 | L7: 35.3387 | M7: 34.0285 | N7: 10 | O7: 34.9294 | P7: 30.1534 | Q7: 32.0105 | R7: 32.9883 | S7: 33.8321 | T7: 30.41 | U7: 32.0505 | V7: 32.5183 | W7: 34.3555 | X7: 34.1672 | Y7: 33.0051 | Z7: 33.2714 | AA7: 30.3357 | AB7: 11.2096 | AC7: 32.514 | AD7: 29.5862 | AE7: 35.6465 | AF7: 36.6746 | AG7: 32.5374 | AH7: 33.4317 | AI7: 18.0261 | AJ7: 33.4976 | AK7: 28.4387 | AL7: 33.6747 | AM7: 32.5665 | AN7: 30.2876 | AO7: 33.8404 | AP7: 36.6746 | AQ7: 29.4734 | AR7: 36.6746 | AS7: 23.7263 | AT7: 26.4112 | AU7: 10 | AV7: 31.5842 | AW7: 29.9525 | AX7: 31.1159 | AY7: 24.4677 | AZ7: 30.459698 | BA7: 1492.5252
A8: 7 | B8: 3 | C8: 26.0227 | D8: 31.7015 | E8: 30.5239 | F8: 28.2889 | G8: 32.863 | H8: 30.6695 | I8: 27.8202 | J8: 36.6135 | K8: 32.6866 | L8: 34.6988 | M8: 33.3509 | N8: 10 | O8: 33.8403 | P8: 26.3431 | Q8: 30.8645 | R8: 32.2981 | S8: 33.142 | T8: 27.6436 | U8: 30.4709 | V8: 30.6855 | W8: 33.7281 | X8: 33.3093 | Y8: 32.3777 | Z8: 31.5153 | AA8: 29.7209 | AB8: 10 | AC8: 31.5365 | AD8: 26.9524 | AE8: 34.2414 | AF8: 36.0096 | AG8: 31.7971 | AH8: 32.98 | AI8: 14.6118 | AJ8: 30.8203 | AK8: 26.9553 | AL8: 33.1477 | AM8: 31.9516 | AN8: 29.5163 | AO8: 32.8483 | AP8: 36.0096 | AQ8: 28.846 | AR8: 36.0096 | AS8: 21.6695 | AT8: 24.6126 | AU8: 10 | AV8: 30.9567 | AW8: 26.8608 | AX8: 29.304 | AY8: 23.0938 | AZ8: 29.222647 | BA8: 1431.9097
A9: 8 | B9: 3.5 | C9: 23.4585 | D9: 28.6513 | E9: 27.5625 | F9: 27.6866 | G9: 32.2607 | H9: 29.0099 | I9: 25.3715 | J9: 36.1994 | K9: 30.1843 | L9: 33.1819 | M9: 32.6733 | N9: 10 | O9: 31.8146 | P9: 25.1637 | Q9: 28.4496 | R9: 29.3697 | S9: 30.6937 | T9: 25.4244 | U9: 29.8685 | V9: 30.2588 | W9: 32.035 | X9: 32.6442 | Y9: 30.7858 | Z9: 30.3217 | AA9: 28.0198 | AB9: 10 | AC9: 30.8589 | AD9: 26.1995 | AE9: 33.727 | AF9: 35.3445 | AG9: 31.0567 | AH9: 30.4707 | AI9: 12.3603 | AJ9: 29.9327 | AK9: 26.4157 | AL9: 31.6143 | AM9: 31.3368 | AN9: 26.3334 | AO9: 31.1182 | AP9: 35.3445 | AQ9: 28.2186 | AR9: 35.3445 | AS9: 20.2795 | AT9: 23.935 | AU9: 10 | AV9: 30.3293 | AW9: 26.2334 | AX9: 28.6891 | AY9: 22.3645 | AZ9: 27.930541 | BA9: 1368.5965
A10: 9 | B10: 4 | C10: 21.2197 | D10: 27.6735 | E10: 25.9609 | F10: 26.8204 | G10: 31.7015 | H10: 26.7125 | I10: 23.4444 | J10: 35.8231 | K10: 29.6503 | L10: 32.5851 | M10: 31.2224 | N10: 10 | O10: 31.3307 | P10: 22.9105 | Q10: 27.4264 | R10: 28.7065 | S10: 30.0413 | T10: 23.7832 | U10: 26.5636 | V10: 27.9148 | W10: 31.2627 | X10: 30.7686 | Y10: 29.2371 | Z10: 28.863 | AA10: 25.5243 | AB10: 10 | AC10: 28.0202 | AD10: 22.0414 | AE10: 33.2448 | AF10: 34.7226 | AG10: 28.4683 | AH10: 30.0621 | AI10: 10 | AJ10: 29.2966 | AK10: 25.9193 | AL10: 30.2701 | AM10: 28.9818 | AN10: 25.1609 | AO10: 30.4461 | AP10: 34.7226 | AQ10: 27.6235 | AR10: 34.7064 | AS10: 18.0974 | AT10: 22.7292 | AU10: 10 | AV10: 28.761 | AW10: 25.1346 | AX10: 26.4483 | AY10: 19.9758 | AZ10: 26.57101 | BA10: 1301.9795
A11: 10 | B11: 4.5 | C11: 20.0557 | D11: 27.2212 | E11: 20.5621 | F11: 25.5012 | G11: 31.7211 | H11: 26.6715 | I11: 21.691 | J11: 35.1533 | K11: 28.5596 | L11: 32.5693 | M11: 30.8568 | N11: 10 | O11: 31.4181 | P11: 21.1428 | Q11: 25.1618 | R11: 20.8604 | S11: 29.0981 | T11: 21.2677 | U11: 26.2902 | V11: 26.8559 | W11: 31.2594 | X11: 30.6312 | Y11: 29.2338 | Z11: 28.8826 | AA11: 24.9983 | AB11: 10 | AC11: 27.8887 | AD11: 21.9126 | AE11: 33.1984 | AF11: 34.6816 | AG11: 28.196 | AH11: 30.2172 | AI11: 10 | AJ11: 27.4861 | AK11: 25.06 | AL11: 29.7197 | AM11: 28.5947 | AN11: 25.1576 | AO11: 30.3549 | AP11: 34.6816 | AQ11: 27.4642 | AR11: 34.4314 | AS11: 18.2048 | AT11: 21.9592 | AU11: 10 | AV11: 27.3452 | AW11: 23.1966 | AX11: 24.5055 | AY11: 19.1272 | AZ11: 25.735639 | BA11: 1261.0463
A12: 11 | B12: 5 | C12: 21.3868 | D12: 27.1449 | E12: 19.869 | F12: 26.9291 | G12: 32.4593 | H12: 27.3335 | I12: 22.6357 | J12: 36.9888 | K12: 29.958 | L12: 34.62 | M12: 31.5603 | N12: 10 | O12: 31.7157 | P12: 20.9589 | Q12: 25.0706 | R12: 11.2059 | S12: 29.9122 | T12: 23.2067 | U12: 26.8427 | V12: 26.9372 | W12: 33.3214 | X12: 32.6593 | Y12: 29.5597 | Z12: 30.1576 | AA12: 24.3384 | AB12: 11.8501 | AC12: 28.2278 | AD12: 22.3885 | AE12: 34.7054 | AF12: 36.7097 | AG12: 29.192 | AH12: 30.5855 | AI12: 10.3527 | AJ12: 28.0336 | AK12: 27.2011 | AL12: 29.1423 | AM12: 30.2222 | AN12: 25.9892 | AO12: 31.1753 | AP12: 36.7097 | AQ12: 28.8695 | AR12: 35.4745 | AS12: 19.0921 | AT12: 23.3193 | AU12: 10 | AV12: 29.0788 | AW12: 22.4423 | AX12: 24.1639 | AY12: 17.9628 | AZ12: 26.319592 | BA12: 1289.66
A13: 12 | B13: 5.5 | C13: 23.3799 | D13: 31.5862 | E13: 22.6724 | F13: 28.9616 | G13: 37.1276 | H13: 30.9083 | I13: 24.1994 | J13: 40.8595 | K13: 34.6489 | L13: 38.7721 | M13: 32.8403 | N13: 11.8788 | O13: 36.4517 | P13: 24.0894 | Q13: 26.244 | R13: 10 | S13: 33.7063 | T13: 25.9273 | U13: 29.4015 | V13: 26.7479 | W13: 37.9107 | X13: 36.0559 | Y13: 34.2054 | Z13: 33.3003 | AA13: 25.7582 | AB13: 14.7221 | AC13: 31.5473 | AD13: 25.2908 | AE13: 37.7049 | AF13: 41.3216 | AG13: 31.0488 | AH13: 35.3893 | AI13: 13.0041 | AJ13: 30.2688 | AK13: 31.4539 | AL13: 31.2731 | AM13: 33.3633 | AN13: 28.9063 | AO13: 35.742 | AP13: 41.3216 | AQ13: 32.2126 | AR13: 38.1324 | AS13: 21.8133 | AT13: 25.6083 | AU13: 12.7118 | AV13: 32.1295 | AW13: 23.7222 | AX13: 24.497 | AY13: 19.9116 | AZ13: 29.198576 | BA13: 1430.7302
... A49: 48 | B49: 23.5 | C49: 25.7413 | D49: 52.0389 | E49: 66.9141 | F49: 30.1667 | G49: 50.0114 | H49: 30.6038 | I49: 35.3793 | J49: 94.2971 | K49: 62.455 | L49: 41.4685 | M49: 30.1798 | N49: 50.7587 | O49: 66.2919 | P49: 61.8083 | Q49: 63.4273 | R49: 10 | S49: 54.8874 | T49: 28.4532 | U49: 80.9609 | V49: 10 | W49: 38.7616 | X49: 81.9938 | Y49: 55.3323 | Z49: 65.6138 | AA49: 86.8762 | AB49: 56.3256 | AC49: 51.5463 | AD49: 10 | AE49: 44.8152 | AF49: 68.7139 | AG49: 10 | AH49: 58.9602 | AI49: 15.9387 | AJ49: 60.9814 | AK49: 56.9216 | AL49: 31.9846 | AM49: 34.1976 | AN49: 48.9205 | AO49: 43.3565 | AP49: 95.5925 | AQ49: 86.4978 | AR49: 60.3773 | AS49: 68.8738 | AT49: 47.64 | AU49: 30.2567 | AV49: 80.8074 | AW49: 33.5277 | AX49: 11.5689 | AY49: 32.2322 | AZ49: 49.274647 | BA49: 2414.4577

Sheet Demand_kW
A1: period | B1: hour | C1: BES_TR3_one195_C | D1: BES_TR3_one235_A | E1: BES_TR3_one242_B | F1: BES_TR3_one252_C | G1: BES_TR3_one260_C | H1: BES_TR3_one299_B | I1: BES_TR3_one313_A | J1: BES_TR3_one42_B | K1: BES_TR3_one320_B | L1: BES_TR3_one346_C | M1: BES_TR3_one363_C | N1: BES_TR3_one366_B | O1: BES_TR3_one371_C | P1: BES_TR3_one375_C | Q1: BES_TR3_one410_B | R1: BES_TR3_one50_A | S1: BES_TR3_one423_B | T1: BES_TR3_one446_B | U1: BES_TR3_one469_A | V1: BES_TR3_one477_A | W1: BES_TR3_one480_A | X1: BES_TR3_one482_B | Y1: BES_TR3_one521_C | Z1: BES_TR3_one528_C | AA1: BES_TR3_one61_A | AB1: BES_TR3_one544_A | AC1: BES_TR3_one552_B | AD1: BES_TR3_one559_C | AE1: BES_TR3_one570_B | AF1: BES_TR3_one605_A | AG1: BES_TR3_one614_B | AH1: BES_TR3_one617_A | AI1: BES_TR3_one73_A | AJ1: BES_TR3_one76_A | AK1: BES_TR3_one137_A | AL1: BES_TR3_one176_A | AM1: BES_TR3_two130_C | AN1: BES_TR3_two249_A | AO1: BES_TR3_two267_C | AP1: BES_TR3_two292_B | AQ1: BES_TR3_two308_A | AR1: BES_TR3_two313_C | AS1: BES_TR3_two137_B | AT1: BES_TR3_two316_A | AU1: BES_TR3_two339_A | AV1: BES_TR3_two149_B | AW1: BES_TR3_two225_C | AX1: BES_TR3_two229_A | AY1: BES_TR3_two242_B | AZ1: fleet_average | BA1: fleet_total
A2: 1 | B2: 0 | C2: 0.18965467 | D2: 0.046 | E2: 0.046 | F2: 0.380458 | G2: 0.048 | H2: 0.103571 | I2: 0.33975267 | J2: 0.033 | K2: 0.046 | L2: 0.097584 | M2: 0.054 | N2: 0.59939467 | O2: 0.071858667 | P2: 0.14442867 | Q2: 0.165051 | R2: 0.16039967 | S2: 0.13142 | T2: 0.14851067 | U2: 0.048 | V2: 0.14905333 | W2: 0.14990667 | X2: 0.053 | Y2: 0.147818 | Z2: 0.10956733 | AA2: 0.081002667 | AB2: 0.33479833 | AC2: 0.054 | AD2: 0.06 | AE2: 0.041 | AF2: 0.053 | AG2: 0.059 | AH2: 0.11053 | AI2: 0.498861 | AJ2: 0.15209167 | AK2: 0.043 | AL2: 0.14893333 | AM2: 0.049 | AN2: 0.078668333 | AO2: 0.13787567 | AP2: 0.053 | AQ2: 0.63887067 | AR2: 0.053 | AS2: 0.551988 | AT2: 0.68291433 | AU2: 0.733719 | AV2: 0.101992 | AW2: 0.16035067 | AX2: 0.13304733 | AY2: 0.76860333 | AZ2: 0.18860562 | BA2: 9.2416753
A3: 2 | B3: 0.5 | C3: 0.261132 | D3: 0.107152 | E3: 0.30979867 | F3: 0.124726 | G3: 0.20954793 | H3: 0.170627 | I3: 0.053 | J3: 0.033 | K3: 0.199406 | L3: 0.078174 | M3: 0.17189567 | N3: 0.54421533 | O3: 0.042 | P3: 0.22984733 | Q3: 0.047 | R3: 0.055 | S3: 0.055 | T3: 0.17041067 | U3: 0.091038 | V3: 0.13906 | W3: 0.05 | X3: 0.053 | Y3: 0.105896 | Z3: 0.051982333 | AA3: 0.279574 | AB3: 1.2986227 | AC3: 0.054 | AD3: 0.24276533 | AE3: 0.111968 | AF3: 0.053 | AG3: 0.14754733 | AH3: 0.140936 | AI3: 0.62133567 | AJ3: 0.041 | AK3: 0.043 | AL3: 0.0821 | AM3: 0.22269 | AN3: 0.196272 | AO3: 0.079057 | AP3: 0.053 | AQ3: 0.05 | AR3: 0.053 | AS3: 0.53362567 | AT3: 0.14865333 | AU3: 0.43818267 | AV3: 0.13355967 | AW3: 0.146049 | AX3: 0.17259567 | AY3: 0.109488 | AZ3: 0.17969247 | BA3: 8.8049309
A4: 3 | B4: 1 | C4: 0.079125333 | D4: 0.190764 | E4: 0.057270667 | F4: 0.048 | G4: 0.048 | H4: 0.09758 | I4: 0.16172467 | J4: 0.033 | K4: 0.046 | L4: 0.093702 | M4: 0.078633 | N4: 0.547509 | O4: 0.042 | P4: 0.16108033 | Q4: 0.22065 | R4: 0.055 | S4: 0.086841667 | T4: 0.220458 | U4: 0.162768 | V4: 0.083028 | W4: 0.05 | X4: 0.16059467 | Y4: 0.05 | Z4: 0.16804967 | AA4: 0.049 | AB4: 0.42435667 | AC4: 0.22923 | AD4: 0.152036 | AE4: 0.041 | AF4: 0.053 | AG4: 0.120302 | AH4: 0.036 | AI4: 0.267892 | AJ4: 0.24309 | AK4: 0.39146567 | AL4: 0.042 | AM4: 0.049 | AN4: 0.13705233 | AO4: 0.057 | AP4: 0.053 | AQ4: 0.05 | AR4: 0.053 | AS4: 0.079077 | AT4: 0.143334 | AU4: 0.83146533 | AV4: 0.150777 | AW4: 0.099305667 | AX4: 0.10350933 | AY4: 0.21719867 | AZ4: 0.14316063 | BA4: 7.0148707
A5: 4 | B5: 1.5 | C5: 0.25947267 | D5: 0.072518 | E5: 0.11780067 | F5: 0.16604 | G5: 0.048 | H5: 0.058619 | I5: 0.24287333 | J5: 0.068937 | K5: 0.157568 | L5: 0.051 | M5: 0.082152 | N5: 0.65628367 | O5: 0.20622267 | P5: 0.15299033 | Q5: 0.121536 | R5: 0.11175367 | S5: 0.16326167 | T5: 0.17685333 | U5: 0.125886 | V5: 0.034 | W5: 0.10494867 | X5: 0.053 | Y5: 0.05 | Z5: 0.11082 | AA5: 0.20263 | AB5: 0.10762 | AC5: 0.054 | AD5: 0.19017333 | AE5: 0.111968 | AF5: 0.053 | AG5: 0.079434 | AH5: 0.065812 | AI5: 0.17647033 | AJ5: 0.041 | AK5: 0.21921933 | AL5: 0.18903333 | AM5: 0.049 | AN5: 0.18476233 | AO5: 0.15993267 | AP5: 0.053 | AQ5: 0.05 | AR5: 0.053 | AS5: 0.08518 | AT5: 0.054 | AU5: 0.66541733 | AV5: 0.05 | AW5: 0.246378 | AX5: 0.089882 | AY5: 0.109488 | AZ5: 0.13740688 | BA5: 6.7329373
A6: 5 | B6: 2 | C6: 0.17019167 | D6: 0.19888 | E6: 0.16138267 | F6: 0.048 | G6: 0.071841333 | H6: 0.260159 | I6: 0.086633 | J6: 0.068937 | K6: 0.087838 | L6: 0.051 | M6: 0.08919 | N6: 0.33393733 | O6: 0.042 | P6: 0.096338 | Q6: 0.082456 | R6: 0.176615 | S6: 0.055 | T6: 0.048 | U6: 0.205806 | V6: 0.19107733 | W6: 0.094958 | X6: 0.145224 | Y6: 0.203714 | Z6: 0.095788 | AA6: 0.15794667 | AB6: 0.12892833 | AC6: 0.205335 | AD6: 0.184906 | AE6: 0.041 | AF6: 0.053 | AG6: 0.18841533 | AH6: 0.170154 | AI6: 0.186562 | AJ6: 0.041 | AK6: 0.224648 | AL6: 0.042 | AM6: 0.22269 | AN6: 0.17723033 | AO6: 0.057 | AP6: 0.053 | AQ6: 0.05 | AR6: 0.053 | AS6: 0.046991333 | AT6: 0.054 | AU6: 0.489888 | AV6: 0.23433667 | AW6: 0.14861133 | AX6: 0.20894733 | AY6: 0.033 | AZ6: 0.13301136 | BA6: 6.5175567
A7: 6 | B7: 2.5 | C7: 0.15428933 | D7: 0.046 | E7: 0.062906 | F7: 0.16604 | G7: 0.14336533 | H7: 0.053 | I7: 0.086633 | J7: 0.033 | K7: 0.046 | L7: 0.051 | M7: 0.054 | N7: 0.096 | O7: 0.086788 | P7: 0.30364333 | Q7: 0.09132 | R7: 0.055 | S7: 0.055 | T7: 0.220458 | U7: 0.125886 | V7: 0.146064 | W7: 0.05 | X7: 0.068370667 | Y7: 0.05 | Z7: 0.139949 | AA7: 0.049 | AB7: 0.19354833 | AC7: 0.077895 | AD7: 0.20989533 | AE7: 0.111968 | AF7: 0.053 | AG7: 0.059 | AH7: 0.036 | AI7: 0.27208533 | AJ7: 0.213355 | AK7: 0.11821 | AL7: 0.042 | AM7: 0.049 | AN7: 0.061467333 | AO7: 0.079057 | AP7: 0.053 | AQ7: 0.05 | AR7: 0.053 | AS7: 0.16391333 | AT7: 0.143334 | AU7: 0.56713533 | AV7: 0.05 | AW7: 0.246378 | AX7: 0.14439133 | AY7: 0.109488 | AZ7: 0.11409865 | BA7: 5.590834
A8: 7 | B8: 3 | C8: 0.20433967 | D8: 0.24307667 | E8: 0.235994 | F8: 0.048 | G8: 0.048 | H8: 0.13225333 | I8: 0.19514033 | J8: 0.033 | K8: 0.199406 | L8: 0.120876 | M8: 0.054 | N8: 0.045 | O8: 0.16143467 | P8: 0.093984667 | Q8: 0.192445 | R8: 0.23336867 | S8: 0.19510333 | T8: 0.17685333 | U8: 0.048 | V8: 0.034 | W8: 0.13492067 | X8: 0.053 | Y8: 0.126857 | Z8: 0.095115 | AA8: 0.135562 | AB8: 0.043 | AC8: 0.054 | AD8: 0.06 | AE8: 0.041 | AF8: 0.053 | AG8: 0.059 | AH8: 0.199966 | AI8: 0.17941967 | AJ8: 0.070735 | AK8: 0.043 | AL8: 0.1222 | AM8: 0.049 | AN8: 0.253651 | AO8: 0.13787567 | AP8: 0.053 | AQ8: 0.05 | AR8: 0.053 | AS8: 0.11077 | AT8: 0.054 | AU8: 0.206956 | AV8: 0.05 | AW8: 0.05 | AX8: 0.049 | AY8: 0.058118 | AZ8: 0.1089882 | BA8: 5.3404217
A9: 8 | B9: 3.5 | C9: 0.18184933 | D9: 0.081357333 | E9: 0.13107533 | F9: 0.071608 | G9: 0.048 | H9: 0.18652467 | I9: 0.15615367 | J9: 0.033 | K9: 0.046 | L9: 0.051 | M9: 0.117342 | N9: 0.186658 | O9: 0.042 | P9: 0.18300667 | Q9: 0.083261 | R9: 0.055 | S9: 0.055 | T9: 0.134229 | U9: 0.266384 | V9: 0.188088 | W9: 0.064986 | X9: 0.15290933 | Y9: 0.126857 | Z9: 0.119682 | AA9: 0.20101267 | AB9: 0.18361 | AC9: 0.22923 | AD9: 0.33480133 | AE9: 0.041 | AF9: 0.053 | AG9: 0.20884933 | AH9: 0.036 | AI9: 0.25500233 | AJ9: 0.05284 | AK9: 0.043 | AL9: 0.10883333 | AM9: 0.19111 | AN9: 0.096874333 | AO9: 0.057 | AP9: 0.053 | AQ9: 0.05 | AR9: 0.053 | AS9: 0.17690467 | AT9: 0.098667 | AU9: 0.053 | AV9: 0.127988 | AW9: 0.089284 | AX9: 0.179866 | AY9: 0.19208067 | AZ9: 0.12097806 | BA9: 5.927925
A10: 9 | B10: 4 | C10: 0.14250133 | D10: 0.085777 | E10: 0.47996933 | F10: 0.142432 | G10: 0.048 | H10: 0.053 | I10: 0.17702733 | J10: 0.096888 | K10: 0.136649 | L10: 0.051 | M10: 0.054 | N10: 0.131304 | O10: 0.042 | P10: 0.19059933 | Q10: 0.20534 | R10: 0.65634367 | S10: 0.11868333 | T10: 0.250197 | U10: 0.065308 | V10: 0.103032 | W10: 0.05 | X10: 0.060685333 | Y10: 0.05 | Z10: 0.048 | AA10: 0.073002 | AB10: 0.12091667 | AC10: 0.054 | AD10: 0.06 | AE10: 0.041 | AF10: 0.053 | AG10: 0.059 | AH10: 0.036 | AI10: 0.153649 | AJ10: 0.17536667 | AK10: 0.11821 | AL10: 0.068733333 | AM10: 0.08058 | AN10: 0.05 | AO10: 0.057 | AP10: 0.053 | AQ10: 0.05 | AR10: 0.053 | AS10: 0.034 | AT10: 0.098667 | AU10: 0.17056467 | AV10: 0.15634867 | AW10: 0.17930533 | AX10: 0.17347267 | AY10: 0.092490667 | AZ10: 0.11632741 | BA10: 5.7000433
A11: 10 | B11: 4.5 | C11: 0.11471467 | D11: 0.238657 | E11: 0.28781 | F11: 0.048 | G11: 0.16720667 | H11: 0.17395533 | I11: 0.090784 | J11: 0.040986 | K11: 0.108757 | L11: 0.051 | M11: 0.054 | N11: 0.167341 | O11: 0.20622267 | P11: 0.24723067 | Q11: 0.12355 | R11: 0.91473667 | S11: 0.13142 | T11: 0.060885333 | U11: 0.154578 | V11: 0.080021333 | W11: 0.05 | X11: 0.053 | Y11: 0.203714 | Z11: 0.119682 | AA11: 0.19795 | AB11: 0.068761667 | AC11: 0.173475 | AD11: 0.19043467 | AE11: 0.041 | AF11: 0.053 | AG11: 0.086245333 | AH11: 0.199966 | AI11: 0.17227733 | AJ11: 0.096883333 | AK11: 0.043 | AL11: 0.1623 | AM11: 0.088475 | AN11: 0.15893967 | AO11: 0.15993267 | AP11: 0.053 | AQ11: 0.05 | AR11: 0.053 | AS11: 0.12493933 | AT11: 0.054 | AU11: 0.30198533 | AV11: 0.05 | AW11: 0.1764 | AX11: 0.114433 | AY11: 0.209078 | AZ11: 0.14219854 | BA11: 6.9677287
A12: 11 | B12: 5 | C12: 0.284864 | D12: 0.068098333 | E12: 0.21311333 | F12: 0.16604 | G12: 0.048 | H12: 0.14482267 | I12: 0.20755467 | J12: 0.060951 | K12: 0.046 | L12: 0.093702 | M12: 0.117342 | N12: 0.064317 | O12: 0.042 | P12: 0.184163 | Q12: 0.126776 | R12: 0.47217867 | S12: 0.067736667 | T12: 0.220458 | U12: 0.177114 | V12: 0.188088 | W12: 0.054995333 | X12: 0.16059467 | Y12: 0.05 | Z12: 0.18308167 | AA12: 0.16262667 | AB12: 0.207045 | AC12: 0.109755 | AD12: 0.20436667 | AE12: 0.080426667 | AF12: 0.053 | AG12: 0.181604 | AH12: 0.036 | AI12: 0.16890383 | AJ12: 0.090423333 | AK12: 0.084783333 | AL12: 0.042 | AM12: 0.183215 | AN12: 0.203053 | AO12: 0.057 | AP12: 0.053 | AQ12: 0.05 | AR12: 0.053 | AS12: 0.16273533 | AT12: 0.143334 | AU12: 0.16356667 | AV12: 0.13355967 | AW12: 0.117344 | AX12: 0.14351433 | AY12: 0.058118 | AZ12: 0.13029317 | BA12: 6.3843655
A13: 12 | B13: 5.5 | C13: 0.109212 | D13: 0.25633567 | E13: 0.27591267 | F13: 0.048 | G13: 0.11356367 | H13: 0.053 | I13: 0.164311 | J13: 0.076923 | K13: 0.046 | L13: 0.078174 | M13: 0.054 | N13: 0.057878 | O13: 0.079323333 | P13: 0.193364 | Q13: 0.219842 | R13: 0.055 | S13: 0.18236667 | T13: 0.105984 | U13: 0.125886 | V13: 0.14905333 | W13: 0.14491133 | X13: 0.053 | Y13: 0.203714 | Z13: 0.099770333 | AA13: 0.13232733 | AB13: 0.10762 | AC13: 0.054 | AD13: 0.06 | AE13: 0.072541333 | AF13: 0.055153333 | AG13: 0.059 | AH13: 0.036 | AI13: 0.28361533 | AJ13: 0.19366667 | AK13: 0.076426667 | AL13: 0.14893333 | AM13: 0.049 | AN13: 0.05 | AO13: 0.057 | AP13: 0.053 | AQ13: 0.05 | AR13: 0.053 | AS13: 0.034 | AT13: 0.054 | AU13: 0.24513233 | AV13: 0.137779 | AW13: 0.22142467 | AX13: 0.110323 | AY13: 0.109488 | AZ13: 0.11120318 | BA13: 5.448956
... A49: 48 | B49: 23.5 | C49: 0.93791933 | D49: 0.175948 | E49: 0.175726 | F49: 0.048 | G49: 0.16720667 | H49: 0.170999 | I49: 0.13382667 | J49: 0.033 | K49: 0.224103 | L49: 0.18212233 | M49: 0.08919 | N49: 0.073768 | O49: 0.109182 | P49: 0.14942233 | Q49: 1.4054943 | R49: 0.127969 | S49: 0.17102967 | T49: 0.99138267 | U49: 0.233365 | V49: 0.676671 | W49: 0.23891733 | X49: 0.15290933 | Y49: 0.57235933 | Z49: 0.1793338 | AA49: 0.193012 | AB49: 0.283335 | AC49: 0.093825 | AD49: 0.521636 | AE49: 0.041 | AF49: 0.16086333 | AG49: 0.072622667 | AH49: 0.30495233 | AI49: 0.23604133 | AJ49: 0.4726 | AK49: 0.043 | AL49: 0.16898333 | AM49: 0.48329167 | AN49: 0.79447 | AO49: 0.123171 | AP49: 0.053 | AQ49: 0.05 | AR49: 0.062673067 | AS49: 0.548634 | AT49: 0.64568333 | AU49: 0.16202533 | AV49: 0.453289 | AW49: 0.05 | AX49: 0.056270333 | AY49: 0.16799667 | AZ49: 0.27882082 | BA49: 13.66222

Sheet PV_kW
A1: period | B1: hour | C1: BES_TR3_one195_C | D1: BES_TR3_one235_A | E1: BES_TR3_one242_B | F1: BES_TR3_one252_C | G1: BES_TR3_one260_C | H1: BES_TR3_one299_B | I1: BES_TR3_one313_A | J1: BES_TR3_one42_B | K1: BES_TR3_one320_B | L1: BES_TR3_one346_C | M1: BES_TR3_one363_C | N1: BES_TR3_one366_B | O1: BES_TR3_one371_C | P1: BES_TR3_one375_C | Q1: BES_TR3_one410_B | R1: BES_TR3_one50_A | S1: BES_TR3_one423_B | T1: BES_TR3_one446_B | U1: BES_TR3_one469_A | V1: BES_TR3_one477_A | W1: BES_TR3_one480_A | X1: BES_TR3_one482_B | Y1: BES_TR3_one521_C | Z1: BES_TR3_one528_C | AA1: BES_TR3_one61_A | AB1: BES_TR3_one544_A | AC1: BES_TR3_one552_B | AD1: BES_TR3_one559_C | AE1: BES_TR3_one570_B | AF1: BES_TR3_one605_A | AG1: BES_TR3_one614_B | AH1: BES_TR3_one617_A | AI1: BES_TR3_one73_A | AJ1: BES_TR3_one76_A | AK1: BES_TR3_one137_A | AL1: BES_TR3_one176_A | AM1: BES_TR3_two130_C | AN1: BES_TR3_two249_A | AO1: BES_TR3_two267_C | AP1: BES_TR3_two292_B | AQ1: BES_TR3_two308_A | AR1: BES_TR3_two313_C | AS1: BES_TR3_two137_B | AT1: BES_TR3_two316_A | AU1: BES_TR3_two339_A | AV1: BES_TR3_two149_B | AW1: BES_TR3_two225_C | AX1: BES_TR3_two229_A | AY1: BES_TR3_two242_B | AZ1: fleet_average | BA1: fleet_total
A2: 1 | B2: 0 | C2: 0 | D2: 0 | E2: 0 | F2: 0 | G2: 0 | H2: 0 | I2: 0 | J2: 0 | K2: 0 | L2: 0 | M2: 0 | N2: 0 | O2: 0 | P2: 0 | Q2: 0 | R2: 0 | S2: 0 | T2: 0 | U2: 0 | V2: 0 | W2: 0 | X2: 0 | Y2: 0 | Z2: 0 | AA2: 0 | AB2: 0 | AC2: 0 | AD2: 0 | AE2: 0 | AF2: 0 | AG2: 0 | AH2: 0 | AI2: 0 | AJ2: 0 | AK2: 0 | AL2: 0 | AM2: 0 | AN2: 0 | AO2: 0 | AP2: 0 | AQ2: 0 | AR2: 0 | AS2: 0 | AT2: 0 | AU2: 0 | AV2: 0 | AW2: 0 | AX2: 0 | AY2: 0 | AZ2: 0 | BA2: 0
A3: 2 | B3: 0.5 | C3: 0 | D3: 0 | E3: 0 | F3: 0 | G3: 0 | H3: 0 | I3: 0 | J3: 0 | K3: 0 | L3: 0 | M3: 0 | N3: 0 | O3: 0 | P3: 0 | Q3: 0 | R3: 0 | S3: 0 | T3: 0 | U3: 0 | V3: 0 | W3: 0 | X3: 0 | Y3: 0 | Z3: 0 | AA3: 0 | AB3: 0 | AC3: 0 | AD3: 0 | AE3: 0 | AF3: 0 | AG3: 0 | AH3: 0 | AI3: 0 | AJ3: 0 | AK3: 0 | AL3: 0 | AM3: 0 | AN3: 0 | AO3: 0 | AP3: 0 | AQ3: 0 | AR3: 0 | AS3: 0 | AT3: 0 | AU3: 0 | AV3: 0 | AW3: 0 | AX3: 0 | AY3: 0 | AZ3: 0 | BA3: 0
A4: 3 | B4: 1 | C4: 0 | D4: 0 | E4: 0 | F4: 0 | G4: 0 | H4: 0 | I4: 0 | J4: 0 | K4: 0 | L4: 0 | M4: 0 | N4: 0 | O4: 0 | P4: 0 | Q4: 0 | R4: 0 | S4: 0 | T4: 0 | U4: 0 | V4: 0 | W4: 0 | X4: 0 | Y4: 0 | Z4: 0 | AA4: 0 | AB4: 0 | AC4: 0 | AD4: 0 | AE4: 0 | AF4: 0 | AG4: 0 | AH4: 0 | AI4: 0 | AJ4: 0 | AK4: 0 | AL4: 0 | AM4: 0 | AN4: 0 | AO4: 0 | AP4: 0 | AQ4: 0 | AR4: 0 | AS4: 0 | AT4: 0 | AU4: 0 | AV4: 0 | AW4: 0 | AX4: 0 | AY4: 0 | AZ4: 0 | BA4: 0
A5: 4 | B5: 1.5 | C5: 0 | D5: 0 | E5: 0 | F5: 0 | G5: 0 | H5: 0 | I5: 0 | J5: 0 | K5: 0 | L5: 0 | M5: 0 | N5: 0 | O5: 0 | P5: 0 | Q5: 0 | R5: 0 | S5: 0 | T5: 0 | U5: 0 | V5: 0 | W5: 0 | X5: 0 | Y5: 0 | Z5: 0 | AA5: 0 | AB5: 0 | AC5: 0 | AD5: 0 | AE5: 0 | AF5: 0 | AG5: 0 | AH5: 0 | AI5: 0 | AJ5: 0 | AK5: 0 | AL5: 0 | AM5: 0 | AN5: 0 | AO5: 0 | AP5: 0 | AQ5: 0 | AR5: 0 | AS5: 0 | AT5: 0 | AU5: 0 | AV5: 0 | AW5: 0 | AX5: 0 | AY5: 0 | AZ5: 0 | BA5: 0
A6: 5 | B6: 2 | C6: 0 | D6: 0 | E6: 0 | F6: 0 | G6: 0 | H6: 0 | I6: 0 | J6: 0 | K6: 0 | L6: 0 | M6: 0 | N6: 0 | O6: 0 | P6: 0 | Q6: 0 | R6: 0 | S6: 0 | T6: 0 | U6: 0 | V6: 0 | W6: 0 | X6: 0 | Y6: 0 | Z6: 0 | AA6: 0 | AB6: 0 | AC6: 0 | AD6: 0 | AE6: 0 | AF6: 0 | AG6: 0 | AH6: 0 | AI6: 0 | AJ6: 0 | AK6: 0 | AL6: 0 | AM6: 0 | AN6: 0 | AO6: 0 | AP6: 0 | AQ6: 0 | AR6: 0 | AS6: 0 | AT6: 0 | AU6: 0 | AV6: 0 | AW6: 0 | AX6: 0 | AY6: 0 | AZ6: 0 | BA6: 0
A7: 6 | B7: 2.5 | C7: 0 | D7: 0 | E7: 0 | F7: 0 | G7: 0 | H7: 0 | I7: 0 | J7: 0 | K7: 0 | L7: 0 | M7: 0 | N7: 0 | O7: 0 | P7: 0 | Q7: 0 | R7: 0 | S7: 0 | T7: 0 | U7: 0 | V7: 0 | W7: 0 | X7: 0 | Y7: 0 | Z7: 0 | AA7: 0 | AB7: 0 | AC7: 0 | AD7: 0 | AE7: 0 | AF7: 0 | AG7: 0 | AH7: 0 | AI7: 0 | AJ7: 0 | AK7: 0 | AL7: 0 | AM7: 0 | AN7: 0 | AO7: 0 | AP7: 0 | AQ7: 0 | AR7: 0 | AS7: 0 | AT7: 0 | AU7: 0 | AV7: 0 | AW7: 0 | AX7: 0 | AY7: 0 | AZ7: 0 | BA7: 0
A8: 7 | B8: 3 | C8: 0 | D8: 0 | E8: 0 | F8: 0 | G8: 0 | H8: 0 | I8: 0 | J8: 0 | K8: 0 | L8: 0 | M8: 0 | N8: 0 | O8: 0 | P8: 0 | Q8: 0 | R8: 0 | S8: 0 | T8: 0 | U8: 0 | V8: 0 | W8: 0 | X8: 0 | Y8: 0 | Z8: 0 | AA8: 0 | AB8: 0 | AC8: 0 | AD8: 0 | AE8: 0 | AF8: 0 | AG8: 0 | AH8: 0 | AI8: 0 | AJ8: 0 | AK8: 0 | AL8: 0 | AM8: 0 | AN8: 0 | AO8: 0 | AP8: 0 | AQ8: 0 | AR8: 0 | AS8: 0 | AT8: 0 | AU8: 0 | AV8: 0 | AW8: 0 | AX8: 0 | AY8: 0 | AZ8: 0 | BA8: 0
A9: 8 | B9: 3.5 | C9: 0.0034408035 | D9: 0.0034408035 | E9: 0.0034408035 | F9: 0.0025806026 | G9: 0.0034408035 | H9: 0.0034408035 | I9: 0.0025806026 | J9: 0.003010703 | K9: 0.0034408035 | L9: 0.0034408035 | M9: 0.0017204017 | N9: 0.0017204017 | O9: 0.0034408035 | P9: 0.0034408035 | Q9: 0.0017204017 | R9: 0.0021505022 | S9: 0.003010703 | T9: 0.0034408035 | U9: 0.003010703 | V9: 0.0012903013 | W9: 0.0034408035 | X9: 0.0034408035 | Y9: 0.0034408035 | Z9: 0.0034408035 | AA9: 0.0021505022 | AB9: 0.0034408035 | AC9: 0.003010703 | AD9: 0.0034408035 | AE9: 0.0025806026 | AF9: 0.0034408035 | AG9: 0.0025806026 | AH9: 0.0034408035 | AI9: 0.003010703 | AJ9: 0.0021505022 | AK9: 0.0034408035 | AL9: 0.0017204017 | AM9: 0.0034408035 | AN9: 0.0034408035 | AO9: 0.0034408035 | AP9: 0.0034408035 | AQ9: 0.0025806026 | AR9: 0.0021505022 | AS9: 0.003010703 | AT9: 0.0025806026 | AU9: 0.003010703 | AV9: 0.003010703 | AW9: 0.0017204017 | AX9: 0.0012903013 | AY9: 0.0017204017 | AZ9: 0.0028614845 | BA9: 0.14021274
A10: 9 | B10: 4 | C10: 0.049734493 | D10: 0.049734493 | E10: 0.049734493 | F10: 0.037300869 | G10: 0.049734493 | H10: 0.049734493 | I10: 0.037300869 | J10: 0.043517681 | K10: 0.049734493 | L10: 0.049734493 | M10: 0.024867246 | N10: 0.024867246 | O10: 0.049734493 | P10: 0.049734493 | Q10: 0.024867246 | R10: 0.031084058 | S10: 0.043517681 | T10: 0.049734493 | U10: 0.043517681 | V10: 0.018650435 | W10: 0.049734493 | X10: 0.049734493 | Y10: 0.049734493 | Z10: 0.049734493 | AA10: 0.031084058 | AB10: 0.049734493 | AC10: 0.043517681 | AD10: 0.049734493 | AE10: 0.037300869 | AF10: 0.049734493 | AG10: 0.037300869 | AH10: 0.049734493 | AI10: 0.043517681 | AJ10: 0.031084058 | AK10: 0.049734493 | AL10: 0.024867246 | AM10: 0.049734493 | AN10: 0.049734493 | AO10: 0.049734493 | AP10: 0.049734493 | AQ10: 0.037300869 | AR10: 0.031084058 | AS10: 0.043517681 | AT10: 0.037300869 | AU10: 0.043517681 | AV10: 0.043517681 | AW10: 0.024867246 | AX10: 0.018650435 | AY10: 0.024867246 | AZ10: 0.041360828 | BA10: 2.0266806
A11: 10 | B11: 4.5 | C11: 0.23257356 | D11: 0.23257356 | E11: 0.23257356 | F11: 0.17443017 | G11: 0.23257356 | H11: 0.23257356 | I11: 0.17443017 | J11: 0.20350186 | K11: 0.23257356 | L11: 0.23257356 | M11: 0.11628678 | N11: 0.11628678 | O11: 0.23257356 | P11: 0.23257356 | Q11: 0.11628678 | R11: 0.14535847 | S11: 0.20350186 | T11: 0.23257356 | U11: 0.20350186 | V11: 0.087215084 | W11: 0.23257356 | X11: 0.23257356 | Y11: 0.23257356 | Z11: 0.23257356 | AA11: 0.14535847 | AB11: 0.23257356 | AC11: 0.20350186 | AD11: 0.23257356 | AE11: 0.17443017 | AF11: 0.23257356 | AG11: 0.17443017 | AH11: 0.23257356 | AI11: 0.20350186 | AJ11: 0.14535847 | AK11: 0.23257356 | AL11: 0.11628678 | AM11: 0.23257356 | AN11: 0.23257356 | AO11: 0.23257356 | AP11: 0.23257356 | AQ11: 0.17443017 | AR11: 0.14535847 | AS11: 0.20350186 | AT11: 0.17443017 | AU11: 0.20350186 | AV11: 0.20350186 | AW11: 0.11628678 | AX11: 0.087215084 | AY11: 0.11628678 | AZ11: 0.19341576 | BA11: 9.4773725
A12: 11 | B12: 5 | C12: 0.46134029 | D12: 0.46134029 | E12: 0.46134029 | F12: 0.34600522 | G12: 0.46134029 | H12: 0.46134029 | I12: 0.34600522 | J12: 0.40367275 | K12: 0.46134029 | L12: 0.46134029 | M12: 0.23067014 | N12: 0.23067014 | O12: 0.46134029 | P12: 0.46134029 | Q12: 0.23067014 | R12: 0.28833768 | S12: 0.40367275 | T12: 0.46134029 | U12: 0.40367275 | V12: 0.17300261 | W12: 0.46134029 | X12: 0.46134029 | Y12: 0.46134029 | Z12: 0.46134029 | AA12: 0.28833768 | AB12: 0.46134029 | AC12: 0.40367275 | AD12: 0.46134029 | AE12: 0.34600522 | AF12: 0.46134029 | AG12: 0.34600522 | AH12: 0.46134029 | AI12: 0.40367275 | AJ12: 0.28833768 | AK12: 0.46134029 | AL12: 0.23067014 | AM12: 0.46134029 | AN12: 0.46134029 | AO12: 0.46134029 | AP12: 0.46134029 | AQ12: 0.34600522 | AR12: 0.28833768 | AS12: 0.40367275 | AT12: 0.34600522 | AU12: 0.40367275 | AV12: 0.40367275 | AW12: 0.23067014 | AX12: 0.17300261 | AY12: 0.23067014 | AZ12: 0.38366565 | BA12: 18.799617
A13: 12 | B13: 5.5 | C13: 0.74185798 | D13: 0.74185798 | E13: 0.74185798 | F13: 0.55639348 | G13: 0.74185798 | H13: 0.74185798 | I13: 0.55639348 | J13: 0.64912573 | K13: 0.74185798 | L13: 0.74185798 | M13: 0.37092899 | N13: 0.37092899 | O13: 0.74185798 | P13: 0.74185798 | Q13: 0.37092899 | R13: 0.46366124 | S13: 0.64912573 | T13: 0.74185798 | U13: 0.64912573 | V13: 0.27819674 | W13: 0.74185798 | X13: 0.74185798 | Y13: 0.74185798 | Z13: 0.74185798 | AA13: 0.46366124 | AB13: 0.74185798 | AC13: 0.64912573 | AD13: 0.74185798 | AE13: 0.55639348 | AF13: 0.74185798 | AG13: 0.55639348 | AH13: 0.74185798 | AI13: 0.64912573 | AJ13: 0.46366124 | AK13: 0.74185798 | AL13: 0.37092899 | AM13: 0.74185798 | AN13: 0.74185798 | AO13: 0.74185798 | AP13: 0.74185798 | AQ13: 0.55639348 | AR13: 0.46366124 | AS13: 0.64912573 | AT13: 0.55639348 | AU13: 0.64912573 | AV13: 0.64912573 | AW13: 0.37092899 | AX13: 0.27819674 | AY13: 0.37092899 | AZ13: 0.61695332 | BA13: 30.230713
... A49: 48 | B49: 23.5 | C49: 0 | D49: 0 | E49: 0 | F49: 0 | G49: 0 | H49: 0 | I49: 0 | J49: 0 | K49: 0 | L49: 0 | M49: 0 | N49: 0 | O49: 0 | P49: 0 | Q49: 0 | R49: 0 | S49: 0 | T49: 0 | U49: 0 | V49: 0 | W49: 0 | X49: 0 | Y49: 0 | Z49: 0 | AA49: 0 | AB49: 0 | AC49: 0 | AD49: 0 | AE49: 0 | AF49: 0 | AG49: 0 | AH49: 0 | AI49: 0 | AJ49: 0 | AK49: 0 | AL49: 0 | AM49: 0 | AN49: 0 | AO49: 0 | AP49: 0 | AQ49: 0 | AR49: 0 | AS49: 0 | AT49: 0 | AU49: 0 | AV49: 0 | AW49: 0 | AX49: 0 | AY49: 0 | AZ49: 0 | BA49: 0

Sheet Charge_kW
A1: period | B1: hour | C1: BES_TR3_one195_C | D1: BES_TR3_one235_A | E1: BES_TR3_one242_B | F1: BES_TR3_one252_C | G1: BES_TR3_one260_C | H1: BES_TR3_one299_B | I1: BES_TR3_one313_A | J1: BES_TR3_one42_B | K1: BES_TR3_one320_B | L1: BES_TR3_one346_C | M1: BES_TR3_one363_C | N1: BES_TR3_one366_B | O1: BES_TR3_one371_C | P1: BES_TR3_one375_C | Q1: BES_TR3_one410_B | R1: BES_TR3_one50_A | S1: BES_TR3_one423_B | T1: BES_TR3_one446_B | U1: BES_TR3_one469_A | V1: BES_TR3_one477_A | W1: BES_TR3_one480_A | X1: BES_TR3_one482_B | Y1: BES_TR3_one521_C | Z1: BES_TR3_one528_C | AA1: BES_TR3_one61_A | AB1: BES_TR3_one544_A | AC1: BES_TR3_one552_B | AD1: BES_TR3_one559_C | AE1: BES_TR3_one570_B | AF1: BES_TR3_one605_A | AG1: BES_TR3_one614_B | AH1: BES_TR3_one617_A | AI1: BES_TR3_one73_A | AJ1: BES_TR3_one76_A | AK1: BES_TR3_one137_A | AL1: BES_TR3_one176_A | AM1: BES_TR3_two130_C | AN1: BES_TR3_two249_A | AO1: BES_TR3_two267_C | AP1: BES_TR3_two292_B | AQ1: BES_TR3_two308_A | AR1: BES_TR3_two313_C | AS1: BES_TR3_two137_B | AT1: BES_TR3_two316_A | AU1: BES_TR3_two339_A | AV1: BES_TR3_two149_B | AW1: BES_TR3_two225_C | AX1: BES_TR3_two229_A | AY1: BES_TR3_two242_B | AZ1: fleet_average | BA1: fleet_total
A2: 1 | B2: 0 | C2: 0 | D2: 0 | E2: 0 | F2: 0 | G2: 0 | H2: 0 | I2: 0 | J2: 0 | K2: 0 | L2: 0 | M2: 0 | N2: 0 | O2: 0 | P2: 0 | Q2: 0 | R2: 0 | S2: 0 | T2: 0 | U2: 0 | V2: 0 | W2: 0 | X2: 0 | Y2: 0 | Z2: 0 | AA2: 0 | AB2: 0 | AC2: 0 | AD2: 0 | AE2: 0 | AF2: 0 | AG2: 0 | AH2: 0 | AI2: 0 | AJ2: 0 | AK2: 0 | AL2: 0 | AM2: 0 | AN2: 0 | AO2: 0 | AP2: 0 | AQ2: 0 | AR2: 0 | AS2: 0 | AT2: 0 | AU2: 0 | AV2: 0 | AW2: 0 | AX2: 0 | AY2: 0 | AZ2: 0 | BA2: 0
A3: 2 | B3: 0.5 | C3: 0 | D3: 0 | E3: 0 | F3: 0 | G3: 0 | H3: 0 | I3: 0 | J3: 0 | K3: 0 | L3: 0 | M3: 0 | N3: 0 | O3: 0 | P3: 0 | Q3: 0 | R3: 0 | S3: 0 | T3: 0 | U3: 0 | V3: 0 | W3: 0 | X3: 0 | Y3: 0 | Z3: 0 | AA3: 0 | AB3: 0 | AC3: 0 | AD3: 0 | AE3: 0 | AF3: 0 | AG3: 0 | AH3: 0 | AI3: 0 | AJ3: 0 | AK3: 0 | AL3: 0 | AM3: 0 | AN3: 0 | AO3: 0 | AP3: 0 | AQ3: 0 | AR3: 0 | AS3: 0 | AT3: 0 | AU3: 0 | AV3: 0 | AW3: 0 | AX3: 0 | AY3: 0 | AZ3: 0 | BA3: 0
A4: 3 | B4: 1 | C4: 0 | D4: 0 | E4: 0 | F4: 0 | G4: 0 | H4: 0 | I4: 0 | J4: 0 | K4: 0 | L4: 0 | M4: 0 | N4: 0 | O4: 0 | P4: 0 | Q4: 0 | R4: 0 | S4: 0 | T4: 0 | U4: 0 | V4: 0 | W4: 0 | X4: 0 | Y4: 0 | Z4: 0 | AA4: 0 | AB4: 0 | AC4: 0 | AD4: 0 | AE4: 0 | AF4: 0 | AG4: 0 | AH4: 0 | AI4: 0 | AJ4: 0 | AK4: 0 | AL4: 0 | AM4: 0 | AN4: 0 | AO4: 0 | AP4: 0 | AQ4: 0 | AR4: 0 | AS4: 0 | AT4: 0 | AU4: 0 | AV4: 0 | AW4: 0 | AX4: 0 | AY4: 0 | AZ4: 0 | BA4: 0
A5: 4 | B5: 1.5 | C5: 0 | D5: 0 | E5: 0 | F5: 0 | G5: 0 | H5: 0 | I5: 0 | J5: 0 | K5: 0 | L5: 0 | M5: 0 | N5: 0 | O5: 0 | P5: 0 | Q5: 0 | R5: 0 | S5: 0 | T5: 0 | U5: 0 | V5: 0 | W5: 0 | X5: 0 | Y5: 0 | Z5: 0 | AA5: 0 | AB5: 0 | AC5: 0 | AD5: 0 | AE5: 0 | AF5: 0 | AG5: 0 | AH5: 0 | AI5: 0 | AJ5: 0 | AK5: 0 | AL5: 0 | AM5: 0 | AN5: 0 | AO5: 0 | AP5: 0 | AQ5: 0 | AR5: 0 | AS5: 0 | AT5: 0 | AU5: 0 | AV5: 0 | AW5: 0 | AX5: 0 | AY5: 0 | AZ5: 0 | BA5: 0
A6: 5 | B6: 2 | C6: 0 | D6: 0 | E6: 0 | F6: 0 | G6: 0 | H6: 0 | I6: 0 | J6: 0 | K6: 0 | L6: 0 | M6: 0 | N6: 0 | O6: 0 | P6: 0 | Q6: 0 | R6: 0 | S6: 0 | T6: 0 | U6: 0 | V6: 0 | W6: 0 | X6: 0 | Y6: 0 | Z6: 0 | AA6: 0 | AB6: 0 | AC6: 0 | AD6: 0 | AE6: 0 | AF6: 0 | AG6: 0 | AH6: 0 | AI6: 0 | AJ6: 0 | AK6: 0 | AL6: 0 | AM6: 0 | AN6: 0 | AO6: 0 | AP6: 0 | AQ6: 0 | AR6: 0 | AS6: 0 | AT6: 0 | AU6: 0 | AV6: 0 | AW6: 0 | AX6: 0 | AY6: 0 | AZ6: 0 | BA6: 0
A7: 6 | B7: 2.5 | C7: 0 | D7: 0 | E7: 0 | F7: 0 | G7: 0 | H7: 0 | I7: 0 | J7: 0 | K7: 0 | L7: 0 | M7: 0 | N7: 0 | O7: 0 | P7: 0 | Q7: 0 | R7: 0 | S7: 0 | T7: 0 | U7: 0 | V7: 0 | W7: 0 | X7: 0 | Y7: 0 | Z7: 0 | AA7: 0 | AB7: 0 | AC7: 0 | AD7: 0 | AE7: 0 | AF7: 0 | AG7: 0 | AH7: 0 | AI7: 0 | AJ7: 0 | AK7: 0 | AL7: 0 | AM7: 0 | AN7: 0 | AO7: 0 | AP7: 0 | AQ7: 0 | AR7: 0 | AS7: 0 | AT7: 0 | AU7: 0 | AV7: 0 | AW7: 0 | AX7: 0 | AY7: 0 | AZ7: 0 | BA7: 0
A8: 7 | B8: 3 | C8: 0 | D8: 0 | E8: 0 | F8: 0 | G8: 0 | H8: 0 | I8: 0 | J8: 0 | K8: 0 | L8: 0 | M8: 0 | N8: 0 | O8: 0 | P8: 0 | Q8: 0 | R8: 0 | S8: 0 | T8: 0 | U8: 0 | V8: 0 | W8: 0 | X8: 0 | Y8: 0 | Z8: 0 | AA8: 0 | AB8: 0 | AC8: 0 | AD8: 0 | AE8: 0 | AF8: 0 | AG8: 0 | AH8: 0 | AI8: 0 | AJ8: 0 | AK8: 0 | AL8: 0 | AM8: 0 | AN8: 0 | AO8: 0 | AP8: 0 | AQ8: 0 | AR8: 0 | AS8: 0 | AT8: 0 | AU8: 0 | AV8: 0 | AW8: 0 | AX8: 0 | AY8: 0 | AZ8: 0 | BA8: 0
A9: 8 | B9: 3.5 | C9: 0 | D9: 0 | E9: 0 | F9: 0 | G9: 0 | H9: 0 | I9: 0 | J9: 0 | K9: 0 | L9: 0 | M9: 0 | N9: 0 | O9: 0 | P9: 0 | Q9: 0 | R9: 0 | S9: 0 | T9: 0 | U9: 0 | V9: 0 | W9: 0 | X9: 0 | Y9: 0 | Z9: 0 | AA9: 0 | AB9: 0 | AC9: 0 | AD9: 0 | AE9: 0 | AF9: 0 | AG9: 0 | AH9: 0 | AI9: 0 | AJ9: 0 | AK9: 0 | AL9: 0 | AM9: 0 | AN9: 0 | AO9: 0 | AP9: 0 | AQ9: 0 | AR9: 0 | AS9: 0 | AT9: 0 | AU9: 0 | AV9: 0 | AW9: 0 | AX9: 0 | AY9: 0 | AZ9: 0 | BA9: 0
A10: 9 | B10: 4 | C10: 0 | D10: 0 | E10: 0 | F10: 0 | G10: 0.002 | H10: 0 | I10: 0 | J10: 0 | K10: 0 | L10: 0 | M10: 0 | N10: 0 | O10: 0.008 | P10: 0 | Q10: 0 | R10: 0 | S10: 0 | T10: 0 | U10: 0 | V10: 0 | W10: 0 | X10: 0 | Y10: 0 | Z10: 0.002 | AA10: 0 | AB10: 0 | AC10: 0 | AD10: 0 | AE10: 0 | AF10: 0 | AG10: 0 | AH10: 0.014 | AI10: 0 | AJ10: 0 | AK10: 0 | AL10: 0 | AM10: 0 | AN10: 0 | AO10: 0 | AP10: 0 | AQ10: 0 | AR10: 0 | AS10: 0.01 | AT10: 0 | AU10: 0 | AV10: 0 | AW10: 0 | AX10: 0 | AY10: 0 | AZ10: 0.00073469388 | BA10: 0.036
A11: 10 | B11: 4.5 | C11: 0.118 | D11: 0 | E11: 0 | F11: 0.126 | G11: 0.065 | H11: 0.059 | I11: 0.084 | J11: 0.163 | K11: 0.124 | L11: 0.182 | M11: 0.062 | N11: 0 | O11: 0.026 | P11: 0 | Q11: 0 | R11: 0 | S11: 0.072 | T11: 0.172 | U11: 0.049 | V11: 0.007 | W11: 0.183 | X11: 0.18 | Y11: 0.029 | Z11: 0.113 | AA11: 0 | AB11: 0.164 | AC11: 0.03 | AD11: 0.042 | AE11: 0.133 | AF11: 0.18 | AG11: 0.088 | AH11: 0.033 | AI11: 0.031 | AJ11: 0.048 | AK11: 0.19 | AL11: 0 | AM11: 0.144 | AN11: 0.074 | AO11: 0.073 | AP11: 0.18 | AQ11: 0.124 | AR11: 0.092 | AS11: 0.079 | AT11: 0.12 | AU11: 0 | AV11: 0.154 | AW11: 0 | AX11: 0 | AY11: 0 | AZ11: 0.077408163 | BA11: 3.793
A12: 11 | B12: 5 | C12: 0.176 | D12: 0.393 | E12: 0.248 | F12: 0.18 | G12: 0.413 | H12: 0.317 | I12: 0.138 | J12: 0.343 | K12: 0.415 | L12: 0.368 | M12: 0.113 | N12: 0.166 | O12: 0.419 | P12: 0.277 | Q12: 0.104 | R12: 0 | S12: 0.336 | T12: 0.241 | U12: 0.227 | V12: 0 | W12: 0.406 | X12: 0.301 | Y12: 0.411 | Z12: 0.278 | AA12: 0.126 | AB12: 0.254 | AC12: 0.294 | AD12: 0.257 | AE12: 0.266 | AF12: 0.408 | AG12: 0.164 | AH12: 0.425 | AI12: 0.235 | AJ12: 0.198 | AK12: 0.377 | AL12: 0.189 | AM12: 0.278 | AN12: 0.258 | AO12: 0.404 | AP12: 0.408 | AQ12: 0.296 | AR12: 0.235 | AS12: 0.241 | AT12: 0.203 | AU12: 0.24 | AV12: 0.27 | AW12: 0.113 | AX12: 0.029 | AY12: 0.173 | AZ12: 0.25736735 | BA12: 12.611
A13: 12 | B13: 5.5 | C13: 0.633 | D13: 0.486 | E13: 0.466 | F13: 0.508 | G13: 0.628 | H13: 0.689 | I13: 0.392 | J13: 0.572 | K13: 0.696 | L13: 0.664 | M13: 0.317 | N13: 0.313 | O13: 0.663 | P13: 0.548 | Q13: 0.151 | R13: 0.409 | S13: 0.467 | T13: 0.636 | U13: 0.523 | V13: 0.129 | W13: 0.597 | X13: 0.689 | Y13: 0.538 | Z13: 0.642 | AA13: 0.331 | AB13: 0.634 | AC13: 0.595 | AD13: 0.682 | AE13: 0.484 | AF13: 0.687 | AG13: 0.497 | AH13: 0.706 | AI13: 0.366 | AJ13: 0.27 | AK13: 0.665 | AL13: 0.222 | AM13: 0.693 | AN13: 0.692 | AO13: 0.685 | AP13: 0.689 | AQ13: 0.506 | AR13: 0.411 | AS13: 0.615 | AT13: 0.502 | AU13: 0.404 | AV13: 0.511 | AW13: 0.15 | AX13: 0.168 | AY13: 0.261 | AZ13: 0.5057551 | BA13: 24.782
... A49: 48 | B49: 23.5 | C49: 0 | D49: 0 | E49: 0 | F49: 0 | G49: 0 | H49: 0 | I49: 0 | J49: 0 | K49: 0 | L49: 0 | M49: 0 | N49: 0 | O49: 0 | P49: 0 | Q49: 0 | R49: 0 | S49: 0 | T49: 0 | U49: 0 | V49: 0 | W49: 0 | X49: 0 | Y49: 0 | Z49: 0 | AA49: 0 | AB49: 0 | AC49: 0 | AD49: 0 | AE49: 0 | AF49: 0 | AG49: 0 | AH49: 0 | AI49: 0 | AJ49: 0 | AK49: 0 | AL49: 0 | AM49: 0 | AN49: 0 | AO49: 0 | AP49: 0 | AQ49: 0 | AR49: 0 | AS49: 0 | AT49: 0 | AU49: 0 | AV49: 0 | AW49: 0 | AX49: 0 | AY49: 0 | AZ49: 0 | BA49: 0

Sheet Discharge_kW
A1: period | B1: hour | C1: BES_TR3_one195_C | D1: BES_TR3_one235_A | E1: BES_TR3_one242_B | F1: BES_TR3_one252_C | G1: BES_TR3_one260_C | H1: BES_TR3_one299_B | I1: BES_TR3_one313_A | J1: BES_TR3_one42_B | K1: BES_TR3_one320_B | L1: BES_TR3_one346_C | M1: BES_TR3_one363_C | N1: BES_TR3_one366_B | O1: BES_TR3_one371_C | P1: BES_TR3_one375_C | Q1: BES_TR3_one410_B | R1: BES_TR3_one50_A | S1: BES_TR3_one423_B | T1: BES_TR3_one446_B | U1: BES_TR3_one469_A | V1: BES_TR3_one477_A | W1: BES_TR3_one480_A | X1: BES_TR3_one482_B | Y1: BES_TR3_one521_C | Z1: BES_TR3_one528_C | AA1: BES_TR3_one61_A | AB1: BES_TR3_one544_A | AC1: BES_TR3_one552_B | AD1: BES_TR3_one559_C | AE1: BES_TR3_one570_B | AF1: BES_TR3_one605_A | AG1: BES_TR3_one614_B | AH1: BES_TR3_one617_A | AI1: BES_TR3_one73_A | AJ1: BES_TR3_one76_A | AK1: BES_TR3_one137_A | AL1: BES_TR3_one176_A | AM1: BES_TR3_two130_C | AN1: BES_TR3_two249_A | AO1: BES_TR3_two267_C | AP1: BES_TR3_two292_B | AQ1: BES_TR3_two308_A | AR1: BES_TR3_two313_C | AS1: BES_TR3_two137_B | AT1: BES_TR3_two316_A | AU1: BES_TR3_two339_A | AV1: BES_TR3_two149_B | AW1: BES_TR3_two225_C | AX1: BES_TR3_two229_A | AY1: BES_TR3_two242_B | AZ1: fleet_average | BA1: fleet_total
A2: 1 | B2: 0 | C2: 0.19 | D2: 0.046 | E2: 0.046 | F2: 0.38 | G2: 0.048 | H2: 0.104 | I2: 0.34 | J2: 0.033 | K2: 0.046 | L2: 0.098 | M2: 0.054 | N2: 0.599 | O2: 0.072 | P2: 0.144 | Q2: 0.165 | R2: 0.16 | S2: 0.131 | T2: 0.149 | U2: 0.048 | V2: 0.149 | W2: 0.15 | X2: 0.053 | Y2: 0.148 | Z2: 0.11 | AA2: 0.081 | AB2: 0.335 | AC2: 0.054 | AD2: 0.06 | AE2: 0.041 | AF2: 0.053 | AG2: 0.059 | AH2: 0.111 | AI2: 0.499 | AJ2: 0.152 | AK2: 0.043 | AL2: 0.149 | AM2: 0.049 | AN2: 0.079 | AO2: 0.138 | AP2: 0.053 | AQ2: 0.639 | AR2: 0.053 | AS2: 0.552 | AT2: 0.683 | AU2: 0.734 | AV2: 0.102 | AW2: 0.16 | AX2: 0.133 | AY2: 0.769 | AZ2: 0.18865306 | BA2: 9.244
A3: 2 | B3: 0.5 | C3: 0.261 | D3: 0.107 | E3: 0.31 | F3: 0.125 | G3: 0.21 | H3: 0.171 | I3: 0.053 | J3: 0.033 | K3: 0.199 | L3: 0.078 | M3: 0.172 | N3: 0.544 | O3: 0.042 | P3: 0.23 | Q3: 0.047 | R3: 0.055 | S3: 0.055 | T3: 0.17 | U3: 0.091 | V3: 0.139 | W3: 0.05 | X3: 0.053 | Y3: 0.106 | Z3: 0.052 | AA3: 0.28 | AB3: 1.299 | AC3: 0.054 | AD3: 0.243 | AE3: 0.112 | AF3: 0.053 | AG3: 0.148 | AH3: 0.141 | AI3: 0.621 | AJ3: 0.041 | AK3: 0.043 | AL3: 0.082 | AM3: 0.223 | AN3: 0.196 | AO3: 0.079 | AP3: 0.053 | AQ3: 0.05 | AR3: 0.053 | AS3: 0.534 | AT3: 0.149 | AU3: 0.438 | AV3: 0.134 | AW3: 0.146 | AX3: 0.173 | AY3: 0.109 | AZ3: 0.17973469 | BA3: 8.807
A4: 3 | B4: 1 | C4: 0.079 | D4: 0.191 | E4: 0.057 | F4: 0.048 | G4: 0.048 | H4: 0.098 | I4: 0.162 | J4: 0.033 | K4: 0.046 | L4: 0.094 | M4: 0.079 | N4: 0.548 | O4: 0.042 | P4: 0.161 | Q4: 0.221 | R4: 0.055 | S4: 0.087 | T4: 0.22 | U4: 0.163 | V4: 0.083 | W4: 0.05 | X4: 0.161 | Y4: 0.05 | Z4: 0.168 | AA4: 0.049 | AB4: 0.424 | AC4: 0.229 | AD4: 0.152 | AE4: 0.041 | AF4: 0.053 | AG4: 0.12 | AH4: 0.036 | AI4: 0.268 | AJ4: 0.243 | AK4: 0.391 | AL4: 0.042 | AM4: 0.049 | AN4: 0.137 | AO4: 0.057 | AP4: 0.053 | AQ4: 0.05 | AR4: 0.053 | AS4: 0.079 | AT4: 0.143 | AU4: 0.831 | AV4: 0.151 | AW4: 0.099 | AX4: 0.104 | AY4: 0.217 | AZ4: 0.14316327 | BA4: 7.015
A5: 4 | B5: 1.5 | C5: 0.259 | D5: 0.073 | E5: 0.118 | F5: 0.166 | G5: 0.048 | H5: 0.059 | I5: 0.243 | J5: 0.069 | K5: 0.158 | L5: 0.051 | M5: 0.082 | N5: 0.656 | O5: 0.206 | P5: 0.153 | Q5: 0.122 | R5: 0.112 | S5: 0.163 | T5: 0.177 | U5: 0.126 | V5: 0.034 | W5: 0.105 | X5: 0.053 | Y5: 0.05 | Z5: 0.111 | AA5: 0.203 | AB5: 0.108 | AC5: 0.054 | AD5: 0.19 | AE5: 0.112 | AF5: 0.053 | AG5: 0.079 | AH5: 0.066 | AI5: 0.176 | AJ5: 0.041 | AK5: 0.219 | AL5: 0.189 | AM5: 0.049 | AN5: 0.185 | AO5: 0.16 | AP5: 0.053 | AQ5: 0.05 | AR5: 0.053 | AS5: 0.085 | AT5: 0.054 | AU5: 0.387 | AV5: 0.05 | AW5: 0.246 | AX5: 0.09 | AY5: 0.109 | AZ5: 0.13173469 | BA5: 6.455
A6: 5 | B6: 2 | C6: 0.17 | D6: 0.199 | E6: 0.161 | F6: 0.048 | G6: 0.072 | H6: 0.26 | I6: 0.087 | J6: 0.069 | K6: 0.088 | L6: 0.051 | M6: 0.089 | N6: 0.043 | O6: 0.042 | P6: 0.096 | Q6: 0.082 | R6: 0.177 | S6: 0.055 | T6: 0.048 | U6: 0.206 | V6: 0.191 | W6: 0.095 | X6: 0.145 | Y6: 0.204 | Z6: 0.096 | AA6: 0.158 | AB6: 0.129 | AC6: 0.205 | AD6: 0.185 | AE6: 0.041 | AF6: 0.053 | AG6: 0.188 | AH6: 0.17 | AI6: 0.187 | AJ6: 0.041 | AK6: 0.225 | AL6: 0.042 | AM6: 0.223 | AN6: 0.177 | AO6: 0.057 | AP6: 0.053 | AQ6: 0.05 | AR6: 0.053 | AS6: 0.047 | AT6: 0.054 | AU6: 0 | AV6: 0.234 | AW6: 0.149 | AX6: 0.209 | AY6: 0.033 | AZ6: 0.11708163 | BA6: 5.737
A7: 6 | B7: 2.5 | C7: 0.154 | D7: 0.046 | E7: 0.063 | F7: 0.166 | G7: 0.143 | H7: 0.053 | I7: 0.087 | J7: 0.033 | K7: 0.046 | L7: 0.051 | M7: 0.054 | N7: 0 | O7: 0.087 | P7: 0.304 | Q7: 0.091 | R7: 0.055 | S7: 0.055 | T7: 0.22 | U7: 0.126 | V7: 0.146 | W7: 0.05 | X7: 0.068 | Y7: 0.05 | Z7: 0.14 | AA7: 0.049 | AB7: 0.096 | AC7: 0.078 | AD7: 0.21 | AE7: 0.112 | AF7: 0.053 | AG7: 0.059 | AH7: 0.036 | AI7: 0.272 | AJ7: 0.213 | AK7: 0.118 | AL7: 0.042 | AM7: 0.049 | AN7: 0.061 | AO7: 0.079 | AP7: 0.053 | AQ7: 0.05 | AR7: 0.053 | AS7: 0.164 | AT7: 0.143 | AU7: 0 | AV7: 0.05 | AW7: 0.246 | AX7: 0.144 | AY7: 0.109 | AZ7: 0.098510204 | BA7: 4.827
A8: 7 | B8: 3 | C8: 0.204 | D8: 0.243 | E8: 0.236 | F8: 0.048 | G8: 0.048 | H8: 0.132 | I8: 0.195 | J8: 0.033 | K8: 0.199 | L8: 0.121 | M8: 0.054 | N8: 0 | O8: 0.161 | P8: 0.094 | Q8: 0.192 | R8: 0.233 | S8: 0.195 | T8: 0.177 | U8: 0.048 | V8: 0.034 | W8: 0.135 | X8: 0.053 | Y8: 0.127 | Z8: 0.095 | AA8: 0.136 | AB8: 0 | AC8: 0.054 | AD8: 0.06 | AE8: 0.041 | AF8: 0.053 | AG8: 0.059 | AH8: 0.2 | AI8: 0.179 | AJ8: 0.071 | AK8: 0.043 | AL8: 0.122 | AM8: 0.049 | AN8: 0.254 | AO8: 0.138 | AP8: 0.053 | AQ8: 0.05 | AR8: 0.053 | AS8: 0.111 | AT8: 0.054 | AU8: 0 | AV8: 0.05 | AW8: 0.05 | AX8: 0.049 | AY8: 0.058 | AZ8: 0.10293878 | BA8: 5.044
A9: 8 | B9: 3.5 | C9: 0.178 | D9: 0.078 | E9: 0.128 | F9: 0.069 | G9: 0.045 | H9: 0.183 | I9: 0.154 | J9: 0.03 | K9: 0.043 | L9: 0.048 | M9: 0.116 | N9: 0 | O9: 0.039 | P9: 0.18 | Q9: 0.082 | R9: 0.053 | S9: 0.052 | T9: 0.131 | U9: 0.263 | V9: 0.187 | W9: 0.062 | X9: 0.149 | Y9: 0.123 | Z9: 0.116 | AA9: 0.199 | AB9: 0 | AC9: 0.226 | AD9: 0.331 | AE9: 0.038 | AF9: 0.05 | AG9: 0.206 | AH9: 0.033 | AI9: 0.188 | AJ9: 0.051 | AK9: 0.04 | AL9: 0.107 | AM9: 0.188 | AN9: 0.093 | AO9: 0.054 | AP9: 0.05 | AQ9: 0.047 | AR9: 0.051 | AS9: 0.174 | AT9: 0.096 | AU9: 0 | AV9: 0.125 | AW9: 0.088 | AX9: 0.179 | AY9: 0.19 | AZ9: 0.10842857 | BA9: 5.313
A10: 9 | B10: 4 | C10: 0.093 | D10: 0.036 | E10: 0.43 | F10: 0.105 | G10: 0 | H10: 0.003 | I10: 0.14 | J10: 0.053 | K10: 0.087 | L10: 0.001 | M10: 0.029 | N10: 0 | O10: 0 | P10: 0.141 | Q10: 0.18 | R10: 0.625 | S10: 0.075 | T10: 0.2 | U10: 0.022 | V10: 0.084 | W10: 0.0002655289 | X10: 0.011 | Y10: 0.0002655289 | Z10: 0 | AA10: 0.042 | AB10: 0 | AC10: 0.01 | AD10: 0.01 | AE10: 0.004 | AF10: 0.003 | AG10: 0.022 | AH10: 0 | AI10: 0 | AJ10: 0.144 | AK10: 0.068 | AL10: 0.044 | AM10: 0.031 | AN10: 0.0002655288 | AO10: 0.007 | AP10: 0.003 | AQ10: 0.013 | AR10: 0.022 | AS10: 0 | AT10: 0.061 | AU10: 0 | AV10: 0.113 | AW10: 0.154 | AX10: 0.155 | AY10: 0.068 | AZ10: 0.067138706 | BA10: 3.2897966
A11: 10 | B11: 4.5 | C11: 0 | D11: 0.006 | E11: 0.055 | F11: 0 | G11: 0 | H11: 0 | I11: 0 | J11: 0 | K11: 0 | L11: 0 | M11: 0 | N11: 0 | O11: 0 | P11: 0.015 | Q11: 0.007 | R11: 0.769 | S11: 0 | T11: 0 | U11: 0 | V11: 0 | W11: 0 | X11: 0 | Y11: 0 | Z11: 0 | AA11: 0.053 | AB11: 0 | AC11: 0 | AD11: 0 | AE11: 0 | AF11: 0 | AG11: 0 | AH11: 0 | AI11: 0 | AJ11: 0 | AK11: 0 | AL11: 0.046 | AM11: 0 | AN11: 0 | AO11: 0 | AP11: 0 | AQ11: 0 | AR11: 0 | AS11: 0 | AT11: 0 | AU11: 0 | AV11: 0 | AW11: 0.06 | AX11: 0.027 | AY11: 0.093 | AZ11: 0.023081633 | BA11: 1.131
A12: 11 | B12: 5 | C12: 0 | D12: 0 | E12: 0 | F12: 0 | G12: 0 | H12: 0 | I12: 0 | J12: 0 | K12: 0 | L12: 0 | M12: 0 | N12: 0 | O12: 0 | P12: 0 | Q12: 0 | R12: 0.096 | S12: 0 | T12: 0 | U12: 0 | V12: 0.015 | W12: 0 | X12: 0 | Y12: 0 | Z12: 0 | AA12: 0 | AB12: 0 | AC12: 0 | AD12: 0 | AE12: 0 | AF12: 0 | AG12: 0 | AH12: 0 | AI12: 0 | AJ12: 0 | AK12: 0 | AL12: 0 | AM12: 0 | AN12: 0 | AO12: 0 | AP12: 0 | AQ12: 0 | AR12: 0 | AS12: 0 | AT12: 0 | AU12: 0 | AV12: 0 | AW12: 0 | AX12: 0 | AY12: 0 | AZ12: 0.0022653061 | BA12: 0.111
A13: 12 | B13: 5.5 | C13: 0 | D13: 0 | E13: 0 | F13: 0 | G13: 0 | H13: 0 | I13: 0 | J13: 0 | K13: 0 | L13: 0 | M13: 0 | N13: 0 | O13: 0 | P13: 0 | Q13: 0 | R13: 0 | S13: 0 | T13: 0 | U13: 0 | V13: 0 | W13: 0 | X13: 0 | Y13: 0 | Z13: 0 | AA13: 0 | AB13: 0 | AC13: 0 | AD13: 0 | AE13: 0 | AF13: 0 | AG13: 0 | AH13: 0 | AI13: 0 | AJ13: 0 | AK13: 0 | AL13: 0 | AM13: 0 | AN13: 0 | AO13: 0 | AP13: 0 | AQ13: 0 | AR13: 0 | AS13: 0 | AT13: 0 | AU13: 0 | AV13: 0 | AW13: 0 | AX13: 0 | AY13: 0 | AZ13: 0 | BA13: 0
... A49: 48 | B49: 23.5 | C49: 0.938 | D49: 0.176 | E49: 0.176 | F49: 0.048 | G49: 0.167 | H49: 0.171 | I49: 0.134 | J49: 0.033 | K49: 0.224 | L49: 0.182 | M49: 0.089 | N49: 0.074 | O49: 0.109 | P49: 0.149 | Q49: 1.405 | R49: 0 | S49: 0.171 | T49: 0.991 | U49: 0.233 | V49: 0 | W49: 0.239 | X49: 0.153 | Y49: 0.572 | Z49: 0.179 | AA49: 0.193 | AB49: 0.283 | AC49: 0.094 | AD49: 0 | AE49: 0.041 | AF49: 0.161 | AG49: 0 | AH49: 0.305 | AI49: 0.236 | AJ49: 0.473 | AK49: 0.043 | AL49: 0.169 | AM49: 0.483 | AN49: 0.794 | AO49: 0.123 | AP49: 0.053 | AQ49: 0.05 | AR49: 0.063 | AS49: 0.549 | AT49: 0.646 | AU49: 0.162 | AV49: 0.453 | AW49: 0.05 | AX49: 0.056 | AY49: 0.168 | AZ49: 0.25022449 | BA49: 12.261

Sheet Net_kW
A1: period | B1: hour | C1: BES_TR3_one195_C | D1: BES_TR3_one235_A | E1: BES_TR3_one242_B | F1: BES_TR3_one252_C | G1: BES_TR3_one260_C | H1: BES_TR3_one299_B | I1: BES_TR3_one313_A | J1: BES_TR3_one42_B | K1: BES_TR3_one320_B | L1: BES_TR3_one346_C | M1: BES_TR3_one363_C | N1: BES_TR3_one366_B | O1: BES_TR3_one371_C | P1: BES_TR3_one375_C | Q1: BES_TR3_one410_B | R1: BES_TR3_one50_A | S1: BES_TR3_one423_B | T1: BES_TR3_one446_B | U1: BES_TR3_one469_A | V1: BES_TR3_one477_A | W1: BES_TR3_one480_A | X1: BES_TR3_one482_B | Y1: BES_TR3_one521_C | Z1: BES_TR3_one528_C | AA1: BES_TR3_one61_A | AB1: BES_TR3_one544_A | AC1: BES_TR3_one552_B | AD1: BES_TR3_one559_C | AE1: BES_TR3_one570_B | AF1: BES_TR3_one605_A | AG1: BES_TR3_one614_B | AH1: BES_TR3_one617_A | AI1: BES_TR3_one73_A | AJ1: BES_TR3_one76_A | AK1: BES_TR3_one137_A | AL1: BES_TR3_one176_A | AM1: BES_TR3_two130_C | AN1: BES_TR3_two249_A | AO1: BES_TR3_two267_C | AP1: BES_TR3_two292_B | AQ1: BES_TR3_two308_A | AR1: BES_TR3_two313_C | AS1: BES_TR3_two137_B | AT1: BES_TR3_two316_A | AU1: BES_TR3_two339_A | AV1: BES_TR3_two149_B | AW1: BES_TR3_two225_C | AX1: BES_TR3_two229_A | AY1: BES_TR3_two242_B | AZ1: fleet_average | BA1: fleet_total
A2: 1 | B2: 0 | C2: -0.00034533333 | D2: 0 | E2: 0 | F2: 0.000458 | G2: 0 | H2: -0.000429 | I2: -0.00024733333 | J2: 0 | K2: 0 | L2: -0.000416 | M2: 0 | N2: 0.00039466667 | O2: -0.00014133333 | P2: 0.00042866667 | Q2: 5.1e-05 | R2: 0.00039966667 | S2: 0.00042 | T2: -0.00048933333 | U2: 0 | V2: 5.3333333e-05 | W2: -9.3333333e-05 | X2: 0 | Y2: -0.000182 | Z2: -0.00043266667 | AA2: 2.6666667e-06 | AB2: -0.00020166667 | AC2: 0 | AD2: -6.9388939e-18 | AE2: 0 | AF2: 0 | AG2: 0 | AH2: -0.00047 | AI2: -0.000139 | AJ2: 9.1666667e-05 | AK2: -6.9388939e-18 | AL2: -6.6666667e-05 | AM2: 0 | AN2: -0.00033166667 | AO2: -0.00012433333 | AP2: 0 | AQ2: -0.00012933333 | AR2: 0 | AS2: -1.2e-05 | AT2: -8.5666667e-05 | AU2: -0.000281 | AV2: -8e-06 | AW2: 0.00035066667 | AX2: 4.7333333e-05 | AY2: -0.00039666667 | AZ2: -4.7442177e-05 | BA2: -0.0023246667
