Workbook

Sheet ReadMe
A1: README
A2: Data behind the TR4 rolling-dispatch figures (SOC, demand/PV/dispatch, net, self-consumption, metrics histogram).
A3: Each quantity sheet: rows = 48 half-hour periods (with hour of day), columns = prosumers, plus fleet_average / fleet_total.
A4: Dispatch is the committed slot-1 execution of the rolling horizon (self-consumption baseline, Term 2 + Term 3).
A5: SOC is the realised state at the START of each step (fraction of capacity).
A6: net_kW = (demand - PV) + (charge - discharge); positive = import, negative = export.
A7: Regenerate: python build_workbook.py --force (see README.md for other transformers).

Sheet Summary
A1: quantity | B1: value
A2: run | B2: TR4 exact-QCP rolling (FOR_PolyS=0, FOR_LinearizeVmax=0), 48 steps, all Optimal
A3: source dispatch | B3: FOR_rolling_soc_TR4.csv
A4: source load/PV | B4: TR4_load_PV_48periods.xlsx
A5: prosumers | B5: 46
A6: PV generated kWh/day | B6: 1163
A7: demand kWh/day | B7: 343.4
A8: exported kWh/day | B8: 802
A9: imported kWh/day | B9: 12.4
A10: SCR % (PV used locally) | B10: 31
A11: SSR % (demand met locally) | B11: 96.4
A12: prosumer-periods |net|<50W % | B12: 56.8
A13: SOC min/max over day | B13: 0.10 / 1.00
A14: simultaneous chg+dis rows | B14: 0

Sheet FleetAverage
A1: period | B1: hour | C1: demand_avg_kW | D1: PV_avg_kW | E1: charge_avg_kW | F1: discharge_avg_kW | G1: net_avg_kW | H1: SOC_avg_pct | I1: demand_total_kW | J1: PV_total_kW | K1: net_total_kW
A2: =Demand_kW!A2 -> 1 | B2: =Demand_kW!B2 -> 0 | C2: =AVERAGE(Demand_kW!$C2:$AV2) -> 0.21448886 | D2: =AVERAGE(PV_kW!$C2:$AV2) -> 0 | E2: =AVERAGE(Charge_kW!$C2:$AV2) -> 0 | F2: =AVERAGE(Discharge_kW!$C2:$AV2) -> 0.21452174 | G2: =C2-D2+E2-F2 -> -3.2884058e-05 | H2: =AVERAGE(SOC_pct!$C2:$AV2) -> 40 | I2: =SUM(Demand_kW!$C2:$AV2) -> 9.8664873 | J2: =SUM(PV_kW!$C2:$AV2) -> 0 | K2: =I2-J2+SUM(Charge_kW!$C2:$AV2)-SUM(Discharge_kW!$C2:$AV2) -> -0.0015126667
A3: =Demand_kW!A3 -> 2 | B3: =Demand_kW!B3 -> 0.5 | C3: =AVERAGE(Demand_kW!$C3:$AV3) -> 0.19292379 | D3: =AVERAGE(PV_kW!$C3:$AV3) -> 0 | E3: =AVERAGE(Charge_kW!$C3:$AV3) -> 0 | F3: =AVERAGE(Discharge_kW!$C3:$AV3) -> 0.19295652 | G3: =C3-D3+E3-F3 -> -3.2731884e-05 | H3: =AVERAGE(SOC_pct!$C3:$AV3) -> 37.308487 | I3: =SUM(Demand_kW!$C3:$AV3) -> 8.8744943 | J3: =SUM(PV_kW!$C3:$AV3) -> 0 | K3: =I3-J3+SUM(Charge_kW!$C3:$AV3)-SUM(Discharge_kW!$C3:$AV3) -> -0.0015056667
A4: =Demand_kW!A4 -> 3 | B4: =Demand_kW!B4 -> 1 | C4: =AVERAGE(Demand_kW!$C4:$AV4) -> 0.12976925 | D4: =AVERAGE(PV_kW!$C4:$AV4) -> 0 | E4: =AVERAGE(Charge_kW!$C4:$AV4) -> 0 | F4: =AVERAGE(Discharge_kW!$C4:$AV4) -> 0.12978261 | G4: =C4-D4+E4-F4 -> -1.3355072e-05 | H4: =AVERAGE(SOC_pct!$C4:$AV4) -> 34.88758 | I4: =SUM(Demand_kW!$C4:$AV4) -> 5.9693857 | J4: =SUM(PV_kW!$C4:$AV4) -> 0 | K4: =I4-J4+SUM(Charge_kW!$C4:$AV4)-SUM(Discharge_kW!$C4:$AV4) -> -0.00061433333
A5: =Demand_kW!A5 -> 4 | B5: =Demand_kW!B5 -> 1.5 | C5: =AVERAGE(Demand_kW!$C5:$AV5) -> 0.14419793 | D5: =AVERAGE(PV_kW!$C5:$AV5) -> 0 | E5: =AVERAGE(Charge_kW!$C5:$AV5) -> 0 | F5: =AVERAGE(Discharge_kW!$C5:$AV5) -> 0.14423913 | G5: =C5-D5+E5-F5 -> -4.1202899e-05 | H5: =AVERAGE(SOC_pct!$C5:$AV5) -> 33.259174 | I5: =SUM(Demand_kW!$C5:$AV5) -> 6.6331047 | J5: =SUM(PV_kW!$C5:$AV5) -> 0 | K5: =I5-J5+SUM(Charge_kW!$C5:$AV5)-SUM(Discharge_kW!$C5:$AV5) -> -0.0018953333
A6: =Demand_kW!A6 -> 5 | B6: =Demand_kW!B6 -> 2 | C6: =AVERAGE(Demand_kW!$C6:$AV6) -> 0.13008457 | D6: =AVERAGE(PV_kW!$C6:$AV6) -> 0 | E6: =AVERAGE(Charge_kW!$C6:$AV6) -> 0 | F6: =AVERAGE(Discharge_kW!$C6:$AV6) -> 0.124 | G6: =C6-D6+E6-F6 -> 0.0060845725 | H6: =AVERAGE(SOC_pct!$C6:$AV6) -> 31.449702 | I6: =SUM(Demand_kW!$C6:$AV6) -> 5.9838903 | J6: =SUM(PV_kW!$C6:$AV6) -> 0 | K6: =I6-J6+SUM(Charge_kW!$C6:$AV6)-SUM(Discharge_kW!$C6:$AV6) -> 0.27989033
A7: =Demand_kW!A7 -> 6 | B7: =Demand_kW!B7 -> 2.5 | C7: =AVERAGE(Demand_kW!$C7:$AV7) -> 0.13681141 | D7: =AVERAGE(PV_kW!$C7:$AV7) -> 0 | E7: =AVERAGE(Charge_kW!$C7:$AV7) -> 0 | F7: =AVERAGE(Discharge_kW!$C7:$AV7) -> 0.13543478 | G7: =C7-D7+E7-F7 -> 0.0013766304 | H7: =AVERAGE(SOC_pct!$C7:$AV7) -> 29.893828 | I7: =SUM(Demand_kW!$C7:$AV7) -> 6.293325 | J7: =SUM(PV_kW!$C7:$AV7) -> 0 | K7: =I7-J7+SUM(Charge_kW!$C7:$AV7)-SUM(Discharge_kW!$C7:$AV7) -> 0.063325
A8: =Demand_kW!A8 -> 7 | B8: =Demand_kW!B8 -> 3 | C8: =AVERAGE(Demand_kW!$C8:$AV8) -> 0.14601992 | D8: =AVERAGE(PV_kW!$C8:$AV8) -> 0 | E8: =AVERAGE(Charge_kW!$C8:$AV8) -> 0 | F8: =AVERAGE(Discharge_kW!$C8:$AV8) -> 0.14106522 | G8: =C8-D8+E8-F8 -> 0.0049547029 | H8: =AVERAGE(SOC_pct!$C8:$AV8) -> 28.19465 | I8: =SUM(Demand_kW!$C8:$AV8) -> 6.7169163 | J8: =SUM(PV_kW!$C8:$AV8) -> 0 | K8: =I8-J8+SUM(Charge_kW!$C8:$AV8)-SUM(Discharge_kW!$C8:$AV8) -> 0.22791633
A9: =Demand_kW!A9 -> 8 | B9: =Demand_kW!B9 -> 3.5 | C9: =AVERAGE(Demand_kW!$C9:$AV9) -> 0.14897438 | D9: =AVERAGE(PV_kW!$C9:$AV9) -> 0.0026928027 | E9: =AVERAGE(Charge_kW!$C9:$AV9) -> 0 | F9: =AVERAGE(Discharge_kW!$C9:$AV9) -> 0.1313913 | G9: =C9-D9+E9-F9 -> 0.014890274 | H9: =AVERAGE(SOC_pct!$C9:$AV9) -> 26.423915 | I9: =SUM(Demand_kW!$C9:$AV9) -> 6.8528215 | J9: =SUM(PV_kW!$C9:$AV9) -> 0.12386892 | K9: =I9-J9+SUM(Charge_kW!$C9:$AV9)-SUM(Discharge_kW!$C9:$AV9) -> 0.68495261
A10: =Demand_kW!A10 -> 9 | B10: =Demand_kW!B10 -> 4 | C10: =AVERAGE(Demand_kW!$C10:$AV10) -> 0.1127197 | D10: =AVERAGE(PV_kW!$C10:$AV10) -> 0.038922646 | E10: =AVERAGE(Charge_kW!$C10:$AV10) -> 0.00056521739 | F10: =AVERAGE(Discharge_kW!$C10:$AV10) -> 0.072070989 | G10: =C10-D10+E10-F10 -> 0.0022912773 | H10: =AVERAGE(SOC_pct!$C10:$AV10) -> 24.776093 | I10: =SUM(Demand_kW!$C10:$AV10) -> 5.185106 | J10: =SUM(PV_kW!$C10:$AV10) -> 1.7904417 | K10: =I10-J10+SUM(Charge_kW!$C10:$AV10)-SUM(Discharge_kW!$C10:$AV10) -> 0.10539876
A11: =Demand_kW!A11 -> 10 | B11: =Demand_kW!B11 -> 4.5 | C11: =AVERAGE(Demand_kW!$C11:$AV11) -> 0.13013577 | D11: =AVERAGE(PV_kW!$C11:$AV11) -> 0.18201409 | E11: =AVERAGE(Charge_kW!$C11:$AV11) -> 0.071086957 | F11: =AVERAGE(Discharge_kW!$C11:$AV11) -> 0.01576087 | G11: =C11-D11+E11-F11 -> 0.0034477668 | H11: =AVERAGE(SOC_pct!$C11:$AV11) -> 23.878065 | I11: =SUM(Demand_kW!$C11:$AV11) -> 5.9862453 | J11: =SUM(PV_kW!$C11:$AV11) -> 8.3726481 | K11: =I11-J11+SUM(Charge_kW!$C11:$AV11)-SUM(Discharge_kW!$C11:$AV11) -> 0.15859727
A12: =Demand_kW!A12 -> 11 | B12: =Demand_kW!B12 -> 5 | C12: =AVERAGE(Demand_kW!$C12:$AV12) -> 0.12538939 | D12: =AVERAGE(PV_kW!$C12:$AV12) -> 0.36104892 | E12: =AVERAGE(Charge_kW!$C12:$AV12) -> 0.23558696 | F12: =AVERAGE(Discharge_kW!$C12:$AV12) -> 0 | G12: =C12-D12+E12-F12 -> -7.2579223e-05 | H12: =AVERAGE(SOC_pct!$C12:$AV12) -> 24.482263 | I12: =SUM(Demand_kW!$C12:$AV12) -> 5.7679117 | J12: =SUM(PV_kW!$C12:$AV12) -> 16.60825 | K12: =I12-J12+SUM(Charge_kW!$C12:$AV12)-SUM(Discharge_kW!$C12:$AV12) -> -0.0033386443
A13: =Demand_kW!A13 -> 12 | B13: =Demand_kW!B13 -> 5.5 | C13: =AVERAGE(Demand_kW!$C13:$AV13) -> 0.143186 | D13: =AVERAGE(PV_kW!$C13:$AV13) -> 0.5805845 | E13: =AVERAGE(Charge_kW!$C13:$AV13) -> 0.43876087 | F13: =AVERAGE(Discharge_kW!$C13:$AV13) -> 0.0013695652 | G13: =C13-D13+E13-F13 -> -7.1954029e-06 | H13: =AVERAGE(SOC_pct!$C13:$AV13) -> 27.143804 | I13: =SUM(Demand_kW!$C13:$AV13) -> 6.5865562 | J13: =SUM(PV_kW!$C13:$AV13) -> 26.706887 | K13: =I13-J13+SUM(Charge_kW!$C13:$AV13)-SUM(Discharge_kW!$C13:$AV13) -> -0.00033098853
... A49: =Demand_kW!A49 -> 48 | B49: =Demand_kW!B49 -> 23.5 | C49: =AVERAGE(Demand_kW!$C49:$AV49) -> 0.29912049 | D49: =AVERAGE(PV_kW!$C49:$AV49) -> 0 | E49: =AVERAGE(Charge_kW!$C49:$AV49) -> 0 | F49: =AVERAGE(Discharge_kW!$C49:$AV49) -> 0.2243913 | G49: =C49-D49+E49-F49 -> 0.074729188 | H49: =AVERAGE(SOC_pct!$C49:$AV49) -> 50.31263 | I49: =SUM(Demand_kW!$C49:$AV49) -> 13.759543 | J49: =SUM(PV_kW!$C49:$AV49) -> 0 | K49: =I49-J49+SUM(Charge_kW!$C49:$AV49)-SUM(Discharge_kW!$C49:$AV49) -> 3.4375427

Sheet SOC_pct
A1: period | B1: hour | C1: BES_TR4_one195_C | D1: BES_TR4_one223_B | E1: BES_TR4_one235_A | F1: BES_TR4_one242_B | G1: BES_TR4_one252_C | H1: BES_TR4_one260_C | I1: BES_TR4_one299_B | J1: BES_TR4_one320_B | K1: BES_TR4_one321_C | L1: BES_TR4_one328_A | M1: BES_TR4_one345_A | N1: BES_TR4_one366_B | O1: BES_TR4_one410_B | P1: BES_TR4_one50_A | Q1: BES_TR4_one416_C | R1: BES_TR4_one423_B | S1: BES_TR4_one446_B | T1: BES_TR4_one480_A | U1: BES_TR4_one61_A | V1: BES_TR4_one544_A | W1: BES_TR4_one560_C | X1: BES_TR4_one570_B | Y1: BES_TR4_one585_A | Z1: BES_TR4_one590_A | AA1: BES_TR4_one617_A | AB1: BES_TR4_one76_A | AC1: BES_TR4_one133_A | AD1: BES_TR4_one137_A | AE1: BES_TR4_one176_A | AF1: BES_TR4_three64_A | AG1: BES_TR4_three193_A | AH1: BES_TR4_three232_C | AI1: BES_TR4_three233_A | AJ1: BES_TR4_three248_C | AK1: BES_TR4_three253_C | AL1: BES_TR4_three66_C | AM1: BES_TR4_three312_A | AN1: BES_TR4_three321_B | AO1: BES_TR4_three368_A | AP1: BES_TR4_three388_A | AQ1: BES_TR4_three409_C | AR1: BES_TR4_three76_A | AS1: BES_TR4_three81_A | AT1: BES_TR4_three90_C | AU1: BES_TR4_three97_B | AV1: BES_TR4_three160_C | AW1: fleet_average | AX1: fleet_total
A2: 1 | B2: 0 | C2: 40 | D2: 40 | E2: 40 | F2: 40 | G2: 40 | H2: 40 | I2: 40 | J2: 40 | K2: 40 | L2: 40 | M2: 40 | N2: 40 | O2: 40 | P2: 40 | Q2: 40 | R2: 40 | S2: 40 | T2: 40 | U2: 40 | V2: 40 | W2: 40 | X2: 40 | Y2: 40 | Z2: 40 | AA2: 40 | AB2: 40 | AC2: 40 | AD2: 40 | AE2: 40 | AF2: 40 | AG2: 40 | AH2: 40 | AI2: 40 | AJ2: 40 | AK2: 40 | AL2: 40 | AM2: 40 | AN2: 40 | AO2: 40 | AP2: 40 | AQ2: 40 | AR2: 40 | AS2: 40 | AT2: 40 | AU2: 40 | AV2: 40 | AW2: 40 | AX2: 1840
A3: 2 | B3: 0.5 | C3: 35.3608 | D3: 37.4831 | E3: 37.9551 | F3: 39.2722 | G3: 36.9563 | H3: 38.4466 | I3: 35.7597 | J3: 37.0941 | K3: 37.3157 | L3: 33.8766 | M3: 36.0893 | N3: 37.3609 | O3: 36.0299 | P3: 39.2408 | Q3: 39.3475 | R3: 37.4098 | S3: 36.8357 | T3: 38.6869 | U3: 34.327 | V3: 37.7931 | W3: 38.2298 | X3: 36.639 | Y3: 38.513 | Z3: 39.0938 | AA3: 39.4479 | AB3: 38.4724 | AC3: 37.4028 | AD3: 32.4798 | AE3: 39.6235 | AF3: 39.1657 | AG3: 38.2419 | AH3: 39.1049 | AI3: 34.4958 | AJ3: 39.6737 | AK3: 37.3353 | AL3: 39.2435 | AM3: 38.2718 | AN3: 38.4345 | AO3: 39.4604 | AP3: 36.2602 | AQ3: 33.9145 | AR3: 27.7154 | AS3: 36.9278 | AT3: 38.7995 | AU3: 38.3552 | AV3: 38.2472 | AW3: 37.308487 | AX3: 1716.1904
A4: 3 | B4: 1 | C4: 34.746 | D4: 36.931 | E4: 37.3277 | F4: 36.0784 | G4: 32.8328 | H4: 38.0074 | I4: 35.1072 | J4: 36.3914 | K4: 31.5527 | L4: 29.1853 | M4: 32.9196 | N4: 35.1345 | O4: 34.174 | P4: 36.9214 | Q4: 38.695 | R4: 35.8482 | S4: 36.1204 | T4: 35.1016 | U4: 33.5027 | V4: 35.8934 | W4: 36.815 | X4: 31.7281 | Y4: 36.6607 | Z4: 35.2005 | AA4: 38.8957 | AB4: 37.423 | AC4: 36.2332 | AD4: 31.2058 | AE4: 37.6271 | AF4: 36.5828 | AG4: 35.5777 | AH4: 35.5219 | AI4: 33.7325 | AJ4: 39.3475 | AK4: 35.5723 | AL4: 36.523 | AM4: 36.0629 | AN4: 37.7317 | AO4: 37.3197 | AP4: 35.4027 | AQ4: 33.3874 | AR4: 21.9044 | AS4: 36.1116 | AT4: 36.4165 | AU4: 35.8379 | AV4: 17.5364 | AW4: 34.88758 | AX4: 1604.8287
A5: 4 | B5: 1.5 | C5: 33.2446 | D5: 36.3788 | E5: 34.4727 | F5: 34.3593 | G5: 28.7162 | H5: 37.5682 | I5: 31.4801 | J5: 34.2866 | K5: 30.8625 | L5: 26.5654 | M5: 32.2295 | N5: 32.4888 | O5: 33.5967 | P5: 35.2296 | Q5: 38.0424 | R5: 33.8626 | S5: 33.29 | T5: 34.5997 | U5: 31.8102 | V5: 34.4855 | W5: 36.2002 | X5: 31.0882 | Y5: 35.9957 | Z5: 33.3305 | AA5: 37.5161 | AB5: 33.2556 | AC5: 35.5054 | AD5: 30.5031 | AE5: 37.2507 | AF5: 35.9429 | AG5: 34.5975 | AH5: 33.7655 | AI5: 31.7874 | AJ5: 37.5396 | AK5: 30.464 | AL5: 35.9082 | AM5: 35.4606 | AN5: 37.029 | AO5: 36.7802 | AP5: 33.994 | AQ5: 31.4504 | AR5: 21.026 | AS5: 33.5015 | AT5: 34.4432 | AU5: 35.1478 | AV5: 12.8693 | AW5: 33.259174 | AX5: 1529.922
A6: 5 | B6: 2 | C6: 31.0155 | D6: 34.0867 | E6: 33.8453 | F6: 33.6315 | G6: 25.8137 | H6: 34.9946 | I6: 30.1285 | J6: 32.7827 | K6: 28.8069 | L6: 25.8878 | M6: 31.5393 | N6: 30.9064 | O6: 31.9965 | P6: 33.2032 | Q6: 37.3899 | R6: 32.0837 | S6: 32.2408 | T6: 31.1704 | U6: 29.9248 | V6: 32.1019 | W6: 33.6301 | X6: 27.1188 | Y6: 34.1434 | Z6: 28.5559 | AA6: 36.9639 | AB6: 32.6408 | AC6: 34.4462 | AD6: 29.8003 | AE6: 35.7697 | AF6: 33.9428 | AG6: 32.1443 | AH6: 33.251 | AI6: 29.6313 | AJ6: 37.2133 | AK6: 24.7853 | AL6: 34.9354 | AM6: 32.1258 | AN6: 36.3263 | AO6: 36.2406 | AP6: 30.8053 | AQ6: 30.7007 | AR6: 18.5948 | AS6: 31.8674 | AT6: 34.0166 | AU6: 32.5434 | AV6: 10.9428 | AW6: 31.449702 | AX6: 1446.6863
A7: 6 | B7: 2.5 | C7: 29.9282 | D7: 31.9032 | E7: 31.2941 | F7: 30.4718 | G7: 25.1236 | H7: 33.8838 | I7: 28.8533 | J7: 32.08 | K7: 28.1167 | L7: 24.2193 | M7: 28.7078 | N7: 27.2364 | O7: 29.0814 | P7: 31.3323 | Q7: 36.7374 | R7: 30.4017 | S7: 30.6349 | T7: 29.7013 | U7: 28.9076 | V7: 30.8301 | W7: 33.0152 | X7: 26.4789 | Y7: 32.6564 | Z7: 26.6137 | AA7: 36.4118 | AB7: 29.962 | AC7: 33.0557 | AD7: 29.0024 | AE7: 34.8778 | AF7: 32.5257 | AG7: 29.9937 | AH7: 31.5108 | AI7: 27.7393 | AJ7: 36.8871 | AK7: 20.6234 | AL7: 32.1477 | AM7: 31.5235 | AN7: 35.6236 | AO7: 34.0999 | AP7: 30.1779 | AQ7: 30.1736 | AR7: 17.7037 | AS7: 31.2148 | AT7: 30.6669 | AU7: 30.9857 | AV7: 10 | AW7: 29.893828 | AX7: 1375.1161
A8: 7 | B8: 3 | C8: 27.285 | D8: 31.3511 | E8: 30.363 | F8: 28.7185 | G8: 24.4334 | H8: 32.9785 | I8: 25.6649 | J8: 30.1756 | K8: 27.4266 | L8: 21.5995 | M8: 27.6795 | N8: 25.776 | O8: 28.5042 | P8: 28.4873 | Q8: 36.0849 | R8: 28.2224 | S8: 28.3612 | T8: 28.8018 | U8: 26.3468 | V8: 25.6547 | W8: 31.0673 | X8: 24.1429 | Y8: 31.9913 | Z8: 25.2985 | AA8: 35.308 | AB8: 29.0213 | AC8: 31.7756 | AD8: 26.3001 | AE8: 34.5013 | AF8: 31.8857 | AG8: 28.7108 | AH8: 28.5235 | AI8: 25.2547 | AJ8: 35.4496 | AK8: 14.2419 | AL8: 30.4001 | AM8: 29.3949 | AN8: 34.058 | AO8: 33.5603 | AP8: 26.5965 | AQ8: 28.4592 | AR8: 17.1014 | AS8: 30.5623 | AT8: 29.6603 | AU8: 29.7735 | AV8: 10 | AW8: 28.19465 | AX8: 1296.9539
A9: 8 | B9: 3.5 | C9: 25.7254 | D9: 28.4245 | E9: 29.3305 | F9: 27.9907 | G9: 23.7432 | H9: 30.1993 | I9: 24.4973 | J9: 28.4714 | K9: 25.8586 | L9: 19.986 | M9: 26.5385 | N9: 24.9169 | O9: 26.8858 | P9: 27.6172 | Q9: 35.4323 | R9: 26.8544 | S9: 27.4233 | T9: 26.1401 | U9: 25.619 | V9: 20.146 | W9: 29.8303 | X9: 23.2352 | Y9: 30.5043 | Z9: 19.6391 | AA9: 28.6799 | AB9: 28.4064 | AC9: 30.606 | AD9: 25.5974 | AE9: 32.5049 | AF9: 29.1085 | AG9: 26.287 | AH9: 27.0165 | AI9: 23.1885 | AJ9: 34.7529 | AK9: 10 | AL9: 28.2572 | AM9: 27.5864 | AN9: 33.3046 | AO9: 31.4197 | AP9: 25.5806 | AQ9: 27.4869 | AR9: 15.8253 | AS9: 28.8248 | AT9: 29.2337 | AU9: 26.8236 | AV9: 10 | AW9: 26.423915 | AX9: 1215.5001
A10: 9 | B10: 4 | C10: 23.9072 | D10: 26.9079 | E10: 26.9238 | F10: 25.6116 | G10: 23.0854 | H10: 29.8033 | I10: 22.5942 | J10: 27.7957 | K10: 24.7078 | L10: 17.9723 | M10: 23.8521 | N10: 20.3764 | O10: 24.005 | P10: 25.0206 | Q10: 34.823 | R10: 23.8555 | S10: 24.4977 | T10: 25.6813 | U10: 22.8121 | V10: 17.2662 | W10: 29.2532 | X10: 22.4271 | Y10: 28.6952 | Z10: 18.4015 | AA10: 25.4486 | AB10: 24.1574 | AC10: 29.9213 | AD10: 22.8215 | AE10: 32.1555 | AF10: 28.5117 | AG10: 24.3317 | AH10: 26.5398 | AI10: 20.9427 | AJ10: 34.459 | AK10: 10 | AL10: 25.9331 | AM10: 26.8666 | AN10: 31.833 | AO10: 30.8963 | AP10: 24.5353 | AQ10: 27.0031 | AR10: 13.8223 | AS10: 26.3612 | AT10: 26.7075 | AU10: 26.1766 | AV10: 10 | AW10: 24.776093 | AX10: 1139.7003
A11: 10 | B11: 4.5 | C11: 22.9724 | D11: 25.584 | E11: 26.9205 | F11: 23.7451 | G11: 22.8633 | H11: 29.9697 | I11: 20.186 | J11: 26.081 | K11: 24.4077 | L11: 16.5851 | M11: 23.63 | N11: 20.2471 | O11: 23.6618 | P11: 24.7951 | Q11: 34.7946 | R11: 23.1196 | S11: 24.0165 | T11: 24.6453 | U11: 22.7084 | V11: 16.1159 | W11: 28.1179 | X11: 19.0429 | Y11: 28.6543 | Z11: 15.3138 | AA11: 24.661 | AB11: 23.6067 | AC11: 28.8236 | AD11: 22.4308 | AE11: 30.8436 | AF11: 27.2329 | AG11: 23.3704 | AH11: 24.8382 | AI11: 18.073 | AJ11: 34.5866 | AK11: 10 | AL11: 24.9425 | AM11: 25.4424 | AN11: 31.6528 | AO11: 30.5907 | AP11: 22.1647 | AQ11: 25.4675 | AR11: 13.7478 | AS11: 26.3328 | AT11: 25.2944 | AU11: 26.1106 | AV11: 10 | AW11: 23.878065 | AX11: 1098.391
A12: 11 | B12: 5 | C12: 23.8581 | D12: 26.9332 | E12: 28.9825 | F12: 24.4422 | G12: 24.2122 | H12: 32.2011 | I12: 22.2254 | J12: 26.3691 | K12: 24.1761 | L12: 18.3542 | M12: 22.2789 | N12: 20.7648 | O12: 22.264 | P12: 24.9263 | Q12: 36.834 | R12: 23.6267 | S12: 21.9466 | T12: 25.5025 | U12: 22.9435 | V12: 15.3321 | W12: 29.063 | X12: 20.1086 | Y12: 30.4358 | Z12: 13.641 | AA12: 26.4624 | AB12: 24.695 | AC12: 30.7952 | AD12: 23.1117 | AE12: 31.8814 | AF12: 28.4967 | AG12: 23.4438 | AH12: 24.7422 | AI12: 18.4933 | AJ12: 34.9295 | AK12: 10.6244 | AL12: 24.4583 | AM12: 26.5137 | AN12: 32.3016 | AO12: 30.7813 | AP12: 21.7004 | AQ12: 27.6198 | AR12: 14.0131 | AS12: 28.3722 | AT12: 25.7691 | AU12: 25.5571 | AV12: 10 | AW12: 24.482263 | AX12: 1126.1841
A13: 12 | B13: 5.5 | C13: 26.8266 | D13: 27.4957 | E13: 33.3548 | F13: 28.9975 | G13: 27.4988 | H13: 35.2545 | I13: 24.8639 | J13: 28.9931 | K13: 26.8114 | L13: 21.2066 | M13: 24.9569 | N13: 23.6527 | O13: 22.3759 | P13: 26.3188 | Q13: 41.4571 | R13: 24.2811 | S13: 23.2567 | T13: 28.9227 | U13: 27.3252 | V13: 17.3096 | W13: 33.0687 | X13: 22.7891 | Y13: 33.4859 | Z13: 15.3736 | AA13: 30.028 | AB13: 25.9605 | AC13: 35.3505 | AD13: 23.7989 | AE13: 34.7991 | AF13: 33.1311 | AG13: 27.6086 | AH13: 28.0978 | AI13: 18.6591 | AJ13: 38.5436 | AK13: 10.8313 | AL13: 24.6636 | AM13: 31.1257 | AN13: 32.8433 | AO13: 31.1173 | AP13: 23.0115 | AQ13: 32.3558 | AR13: 18.6814 | AS13: 30.3499 | AT13: 27.0682 | AU13: 30.1463 | AV13: 14.5666 | AW13: 27.143804 | AX13: 1248.615
... A49: 48 | B49: 23.5 | C49: 59.733 | D49: 43.3926 | E49: 59.9502 | F49: 57.4283 | G49: 92.9468 | H49: 75.7714 | I49: 75.586 | J49: 10 | K49: 31.6848 | L49: 81.7175 | M49: 29.2513 | N49: 83.9982 | O49: 55.3686 | P49: 80.9081 | Q49: 39.3093 | R49: 34.2494 | S49: 30.8091 | T49: 66.5637 | U49: 26.2597 | V49: 10 | W49: 10 | X49: 69.0234 | Y49: 60.8426 | Z49: 52.3743 | AA49: 92.6924 | AB49: 46.1983 | AC49: 19.8515 | AD49: 40.1443 | AE49: 64.3509 | AF49: 22.9779 | AG49: 86.1838 | AH49: 82.2217 | AI49: 10 | AJ49: 10 | AK49: 10 | AL49: 61.8124 | AM49: 17.9677 | AN49: 46.337 | AO49: 92.2779 | AP49: 10 | AQ49: 89.4868 | AR49: 58.4046 | AS49: 32.3832 | AT49: 76.9495 | AU49: 24.1777 | AV49: 82.7951 | AW49: 50.31263 | AX49: 2314.381

Sheet Demand_kW
A1: period | B1: hour | C1: BES_TR4_one195_C | D1: BES_TR4_one223_B | E1: BES_TR4_one235_A | F1: BES_TR4_one242_B | G1: BES_TR4_one252_C | H1: BES_TR4_one260_C | I1: BES_TR4_one299_B | J1: BES_TR4_one320_B | K1: BES_TR4_one321_C | L1: BES_TR4_one328_A | M1: BES_TR4_one345_A | N1: BES_TR4_one366_B | O1: BES_TR4_one410_B | P1: BES_TR4_one50_A | Q1: BES_TR4_one416_C | R1: BES_TR4_one423_B | S1: BES_TR4_one446_B | T1: BES_TR4_one480_A | U1: BES_TR4_one61_A | V1: BES_TR4_one544_A | W1: BES_TR4_one560_C | X1: BES_TR4_one570_B | Y1: BES_TR4_one585_A | Z1: BES_TR4_one590_A | AA1: BES_TR4_one617_A | AB1: BES_TR4_one76_A | AC1: BES_TR4_one133_A | AD1: BES_TR4_one137_A | AE1: BES_TR4_one176_A | AF1: BES_TR4_three64_A | AG1: BES_TR4_three193_A | AH1: BES_TR4_three232_C | AI1: BES_TR4_three233_A | AJ1: BES_TR4_three248_C | AK1: BES_TR4_three253_C | AL1: BES_TR4_three66_C | AM1: BES_TR4_three312_A | AN1: BES_TR4_three321_B | AO1: BES_TR4_three368_A | AP1: BES_TR4_three388_A | AQ1: BES_TR4_three409_C | AR1: BES_TR4_three76_A | AS1: BES_TR4_three81_A | AT1: BES_TR4_three90_C | AU1: BES_TR4_three97_B | AV1: BES_TR4_three160_C | AW1: fleet_average | AX1: fleet_total
A2: 1 | B2: 0 | C2: 0.36969767 | D2: 0.20057467 | E2: 0.16296133 | F2: 0.058 | G2: 0.24255333 | H2: 0.12378867 | I2: 0.33791467 | J2: 0.23157467 | K2: 0.21391267 | L2: 0.48797967 | M2: 0.31165067 | N2: 0.210313 | O2: 0.31638167 | P2: 0.060504 | Q2: 0.052 | R2: 0.20641133 | S2: 0.25216933 | T2: 0.10463833 | U2: 0.45208533 | V2: 0.17587333 | W2: 0.14107033 | X2: 0.26784 | Y2: 0.118499 | Z2: 0.072213333 | AA2: 0.044 | AB2: 0.121736 | AC2: 0.20697333 | AD2: 0.59929133 | AE2: 0.03 | AF2: 0.066483333 | AG2: 0.14010567 | AH2: 0.071329333 | AI2: 0.438638 | AJ2: 0.026 | AK2: 0.21235267 | AL2: 0.060285333 | AM2: 0.137718 | AN2: 0.12475933 | AO2: 0.043 | AP2: 0.298028 | AQ2: 0.48496167 | AR2: 0.97896667 | AS2: 0.244828 | AT2: 0.095666667 | AU2: 0.13107167 | AV2: 0.13968533 | AW2: 0.21448886 | AX2: 9.8664873
A3: 2 | B3: 0.5 | C3: 0.049 | D3: 0.044 | E3: 0.05 | F3: 0.25451667 | G3: 0.32860267 | H3: 0.035 | I3: 0.052 | J3: 0.056 | K3: 0.459261 | L3: 0.37385333 | M3: 0.25258933 | N3: 0.17742333 | O3: 0.1479 | P3: 0.18483467 | Q3: 0.052 | R3: 0.12445 | S3: 0.057 | T3: 0.28571767 | U3: 0.065687667 | V3: 0.151388 | W3: 0.112741 | X3: 0.39135033 | Y3: 0.14760967 | Z3: 0.31026533 | AA3: 0.044 | AB3: 0.083625333 | AC3: 0.093208 | AD3: 0.101528 | AE3: 0.159096 | AF3: 0.20583333 | AG3: 0.212309 | AH3: 0.28553033 | AI3: 0.060824 | AJ3: 0.026 | AK3: 0.14049467 | AL3: 0.216797 | AM3: 0.17603333 | AN3: 0.056 | AO3: 0.17059133 | AP3: 0.068335 | AQ3: 0.042 | AR3: 0.463088 | AS3: 0.065038 | AT3: 0.189908 | AU3: 0.200607 | AV3: 1.6504573 | AW3: 0.19292379 | AX3: 8.8744943
A4: 3 | B4: 1 | C4: 0.11964333 | D4: 0.044 | E4: 0.22751067 | F4: 0.13699733 | G4: 0.32805867 | H4: 0.035 | I4: 0.28904 | J4: 0.16772933 | K4: 0.055 | L4: 0.20877733 | M4: 0.055 | N4: 0.21083433 | O4: 0.046 | P4: 0.13482133 | Q4: 0.052 | R4: 0.158235 | S4: 0.22555533 | T4: 0.04 | U4: 0.13487667 | V4: 0.11219067 | W4: 0.049 | X4: 0.051 | Y4: 0.053 | Z4: 0.149017 | AA4: 0.109946 | AB4: 0.332102 | AC4: 0.058 | AD4: 0.056 | AE4: 0.03 | AF4: 0.051 | AG4: 0.078115 | AH4: 0.139973 | AI4: 0.15500467 | AJ4: 0.14407333 | AK4: 0.40708267 | AL4: 0.049 | AM4: 0.048 | AN4: 0.056 | AO4: 0.043 | AP4: 0.112262 | AQ4: 0.154366 | AR4: 0.07 | AS4: 0.208002 | AT4: 0.157248 | AU4: 0.055 | AV4: 0.371924 | AW4: 0.12976925 | AX4: 5.9693857
A5: 4 | B5: 1.5 | C5: 0.17764133 | D5: 0.18266267 | E5: 0.05 | F5: 0.058 | G5: 0.231301 | H5: 0.20509867 | I5: 0.107716 | J5: 0.11984533 | K5: 0.16381267 | L5: 0.054 | M5: 0.055 | N5: 0.126106 | O5: 0.12752 | P5: 0.16148 | Q5: 0.052 | R5: 0.14175967 | S5: 0.083614 | T5: 0.27328533 | U5: 0.150252 | V5: 0.18995267 | W5: 0.20481133 | X5: 0.31632 | Y5: 0.14760967 | Z5: 0.380496 | AA5: 0.044 | AB5: 0.049 | AC5: 0.084406 | AD5: 0.056 | AE5: 0.11802 | AF5: 0.15938333 | AG5: 0.19549933 | AH5: 0.041 | AI5: 0.171822 | AJ5: 0.026 | AK5: 0.45254267 | AL5: 0.077516 | AM5: 0.265747 | AN5: 0.056 | AO5: 0.043 | AP5: 0.25410533 | AQ5: 0.059742 | AR5: 0.19374267 | AS5: 0.130228 | AT5: 0.034 | AU5: 0.20754067 | AV5: 0.15352533 | AW5: 0.14419793 | AX5: 6.6331047
A6: 5 | B6: 2 | C6: 0.086644 | D6: 0.174002 | E6: 0.20330467 | F6: 0.251794 | G6: 0.055 | H6: 0.08852 | I6: 0.101616 | J6: 0.056 | K6: 0.055 | L6: 0.132966 | M6: 0.22564533 | N6: 0.292468 | O6: 0.232311 | P6: 0.149096 | Q6: 0.052 | R6: 0.134043 | S6: 0.12797067 | T6: 0.11707 | U6: 0.081063 | V6: 0.101354 | W6: 0.049 | X6: 0.051 | Y6: 0.118499 | Z6: 0.154775 | AA6: 0.044 | AB6: 0.21347033 | AC6: 0.110812 | AD6: 0.063588 | AE6: 0.071076 | AF6: 0.11293333 | AG6: 0.17138433 | AH6: 0.138676 | AI6: 0.150774 | AJ6: 0.026 | AK6: 0.33166733 | AL6: 0.22216067 | AM6: 0.048 | AN6: 0.056 | AO6: 0.17059133 | AP6: 0.05 | AQ6: 0.042 | AR6: 0.071012 | AS6: 0.052 | AT6: 0.26693733 | AU6: 0.124138 | AV6: 0.355528 | AW6: 0.13008457 | AX6: 5.9838903
A7: 6 | B7: 2.5 | C7: 0.21064067 | D7: 0.044 | E7: 0.074206 | F7: 0.13972 | G7: 0.055 | H7: 0.072138333 | I7: 0.25408933 | J7: 0.151768 | K7: 0.055 | L7: 0.20877733 | M7: 0.081944 | N7: 0.11637467 | O7: 0.046 | P7: 0.22671733 | Q7: 0.052 | R7: 0.17366833 | S7: 0.18119867 | T7: 0.071681667 | U7: 0.20406567 | V7: 0.41243 | W7: 0.155235 | X7: 0.18615333 | Y7: 0.053 | Z7: 0.104809 | AA7: 0.087964 | AB7: 0.074969 | AC7: 0.10201 | AD7: 0.215348 | AE7: 0.03 | AF7: 0.051 | AG7: 0.10223 | AH7: 0.238059 | AI7: 0.19800067 | AJ7: 0.114555 | AK7: 0.50854667 | AL7: 0.13926267 | AM7: 0.16963167 | AN7: 0.12475933 | AO7: 0.043 | AP7: 0.28540167 | AQ7: 0.136624 | AR7: 0.048 | AS7: 0.052 | AT7: 0.080218 | AU7: 0.096602 | AV7: 0.064526 | AW7: 0.13681141 | AX7: 6.293325
A8: 7 | B8: 3 | C8: 0.124288 | D8: 0.233219 | E8: 0.082274667 | F8: 0.058 | G8: 0.055 | H8: 0.22148033 | I8: 0.093044 | J8: 0.13580667 | K8: 0.124951 | L8: 0.128579 | M8: 0.090925333 | N8: 0.068468 | O8: 0.12896567 | P8: 0.069338667 | Q8: 0.052 | R8: 0.10901667 | S8: 0.074742667 | T8: 0.212115 | U8: 0.058 | V8: 0.43899233 | W8: 0.098576333 | X8: 0.07234 | Y8: 0.118499 | Z8: 0.451 | AA8: 0.52819767 | AB8: 0.049 | AC8: 0.093208 | AD8: 0.056 | AE8: 0.159096 | AF8: 0.22131667 | AG8: 0.19315867 | AH8: 0.1201 | AI8: 0.164656 | AJ8: 0.055518333 | AK8: 0.398832 | AL8: 0.17077133 | AM8: 0.14411967 | AN8: 0.060044667 | AO8: 0.17059133 | AP8: 0.080961333 | AQ8: 0.077484 | AR8: 0.10169467 | AS8: 0.138463 | AT8: 0.034 | AU8: 0.23507667 | AV8: 0.165004 | AW8: 0.14601992 | AX8: 6.7169163
A9: 8 | B9: 3.5 | C9: 0.14790067 | D9: 0.12344567 | E9: 0.195236 | F9: 0.19303433 | G9: 0.055 | H9: 0.035 | I9: 0.15510533 | J9: 0.056 | K9: 0.093861667 | L9: 0.163917 | M9: 0.216664 | N9: 0.365277 | O9: 0.23086267 | P9: 0.208648 | Q9: 0.052 | R9: 0.241135 | S9: 0.23442667 | T9: 0.04 | U9: 0.22712867 | V9: 0.231645 | W9: 0.049 | X9: 0.066546667 | Y9: 0.14760967 | Z9: 0.10077453 | AA9: 0.260516 | AB9: 0.34075833 | AC9: 0.058 | AD9: 0.222936 | AE9: 0.03 | AF9: 0.051 | AG9: 0.159256 | AH9: 0.041 | AI9: 0.18026067 | AJ9: 0.026 | AK9: 0.41393567 | AL9: 0.18693133 | AM9: 0.060803333 | AN9: 0.12071467 | AO9: 0.043 | AP9: 0.08459 | AQ9: 0.042 | AR9: 0.16306 | AS9: 0.199767 | AT9: 0.203466 | AU9: 0.055 | AV9: 0.279608 | AW9: 0.14897438 | AX9: 6.8528215
A10: 9 | B10: 4 | C10: 0.118014 | D10: 0.142796 | E10: 0.05 | F10: 0.19847967 | G10: 0.055 | H10: 0.035 | I10: 0.241647 | J10: 0.16772933 | K10: 0.055 | L10: 0.16027833 | M10: 0.055 | N10: 0.060033667 | O10: 0.046 | P10: 0.042834667 | Q10: 0.052 | R10: 0.089725 | S10: 0.057 | T10: 0.13229267 | U10: 0.058 | V10: 0.12274833 | W10: 0.133988 | X10: 0.30077333 | Y10: 0.053 | Z10: 0.27714667 | AA10: 0.10628233 | AB10: 0.074969 | AC10: 0.137218 | AD10: 0.056 | AE10: 0.135624 | AF10: 0.15164167 | AG10: 0.126345 | AH10: 0.17912033 | AI10: 0.24734 | AJ10: 0.026 | AK10: 0.122917 | AL10: 0.10380733 | AM10: 0.16323 | AN10: 0.064089333 | AO10: 0.043 | AP10: 0.20756667 | AQ10: 0.172108 | AR10: 0.055670667 | AS10: 0.052 | AT10: 0.14369 | AU10: 0.055 | AV10: 0.057 | AW10: 0.1127197 | AX10: 5.185106
A11: 10 | B11: 4.5 | C11: 0.12507833 | D11: 0.054977333 | E11: 0.05 | F11: 0.17085333 | G11: 0.055 | H11: 0.035 | I11: 0.052 | J11: 0.11984533 | K11: 0.16381267 | L11: 0.075935 | M11: 0.28210133 | N11: 0.18673333 | O11: 0.19860833 | P11: 0.10467733 | Q11: 0.052 | R11: 0.10046533 | S11: 0.25216933 | T11: 0.15668133 | U11: 0.21175333 | V11: 0.20781933 | W11: 0.11982333 | X11: 0.051 | Y11: 0.074833 | Z11: 0.278662 | AA11: 0.044 | AB11: 0.049 | AC11: 0.058 | AD11: 0.056 | AE11: 0.053472 | AF11: 0.120675 | AG11: 0.22606967 | AH11: 0.21115033 | AI11: 0.05 | AJ11: 0.14407333 | AK11: 0.061 | AL11: 0.15487567 | AM11: 0.137718 | AN11: 0.17512667 | AO11: 0.070341 | AP11: 0.12421267 | AQ11: 0.042 | AR11: 0.209084 | AS11: 0.052 | AT11: 0.103327 | AU11: 0.27667867 | AV11: 0.387612 | AW11: 0.13013577 | AX11: 5.9862453
A12: 11 | B12: 5 | C12: 0.14083633 | D12: 0.29619867 | E12: 0.074206 | F12: 0.058 | G12: 0.055 | H12: 0.190981 | I12: 0.227718 | J12: 0.056 | K12: 0.055 | L12: 0.20877733 | M12: 0.108888 | N12: 0.20564133 | O12: 0.1630974 | P12: 0.10737 | Q12: 0.052 | R12: 0.230393 | S12: 0.057 | T12: 0.158508 | U12: 0.073375333 | V12: 0.11324667 | W12: 0.049 | X12: 0.051 | Y12: 0.19127567 | Z12: 0.13493233 | AA12: 0.087964 | AB12: 0.176288 | AC12: 0.058 | AD12: 0.16982 | AE12: 0.03 | AF12: 0.051 | AG12: 0.092584 | AH12: 0.106562 | AI12: 0.15832833 | AJ12: 0.026 | AK12: 0.21235267 | AL12: 0.212491 | AM12: 0.052984333 | AN12: 0.41338 | AO12: 0.14325033 | AP12: 0.056918 | AQ12: 0.042 | AR12: 0.048 | AS12: 0.28623 | AT12: 0.173314 | AU12: 0.055 | AV12: 0.057 | AW12: 0.12538939 | AX12: 5.7679117
A13: 12 | B13: 5.5 | C13: 0.180754 | D13: 0.060466 | E13: 0.20330467 | F13: 0.15392533 | G13: 0.055 | H13: 0.10263767 | I13: 0.16903433 | J13: 0.063980667 | K13: 0.14049567 | L13: 0.132966 | M13: 0.055 | N13: 0.11861933 | O13: 0.137109 | P13: 0.42596153 | Q13: 0.052 | R13: 0.055 | S13: 0.057 | T13: 0.11895233 | U13: 0.073375333 | V13: 0.088626667 | W13: 0.14107033 | X13: 0.32558333 | Y13: 0.053 | Z13: 0.30658633 | AA13: 0.065982 | AB13: 0.066894633 | AC13: 0.058 | AD13: 0.109116 | AE13: 0.14736 | AF13: 0.18260833 | AG13: 0.22401233 | AH13: 0.24644067 | AI13: 0.18328033 | AJ13: 0.055518333 | AK13: 0.061 | AL13: 0.16185333 | AM13: 0.13273367 | AN13: 0.637632 | AO13: 0.043 | AP13: 0.28661433 | AQ13: 0.172108 | AR13: 0.14771867 | AS13: 0.065038 | AT13: 0.104515 | AU13: 0.055 | AV13: 0.109682 | AW13: 0.143186 | AX13: 6.5865562
... A49: 48 | B49: 23.5 | C49: 0.049 | D49: 0.18702833 | E49: 0.122618 | F49: 0.54888833 | G49: 0.055 | H49: 0.15463133 | I49: 0.179165 | J49: 0.056 | K49: 0.15604033 | L49: 0.082141333 | M49: 0.11786933 | N49: 0.24411667 | O49: 0.46016 | P49: 0.051792 | Q49: 0.477417 | R49: 0.78360033 | S49: 0.30582533 | T49: 0.16039033 | U49: 0.78339367 | V49: 0.67526633 | W49: 0.48963867 | X49: 0.38182567 | Y49: 0.10394367 | Z49: 0.22322167 | AA49: 0.26448167 | AB49: 0.10959433 | AC49: 1.1250727 | AD49: 0.720248 | AE49: 0.03 | AF49: 0.405014 | AG49: 0.10414567 | AH49: 0.29286 | AI49: 0.55756667 | AJ49: 0.66861333 | AK49: 0.47833933 | AL49: 0.57932033 | AM49: 0.12482 | AN49: 0.42183133 | AO49: 0.043 | AP49: 0.170555 | AQ49: 0.042 | AR49: 0.048 | AS49: 0.087455 | AT49: 0.510288 | AU49: 0.070364 | AV49: 0.057 | AW49: 0.29912049 | AX49: 13.759543

Sheet PV_kW
A1: period | B1: hour | C1: BES_TR4_one195_C | D1: BES_TR4_one223_B | E1: BES_TR4_one235_A | F1: BES_TR4_one242_B | G1: BES_TR4_one252_C | H1: BES_TR4_one260_C | I1: BES_TR4_one299_B | J1: BES_TR4_one320_B | K1: BES_TR4_one321_C | L1: BES_TR4_one328_A | M1: BES_TR4_one345_A | N1: BES_TR4_one366_B | O1: BES_TR4_one410_B | P1: BES_TR4_one50_A | Q1: BES_TR4_one416_C | R1: BES_TR4_one423_B | S1: BES_TR4_one446_B | T1: BES_TR4_one480_A | U1: BES_TR4_one61_A | V1: BES_TR4_one544_A | W1: BES_TR4_one560_C | X1: BES_TR4_one570_B | Y1: BES_TR4_one585_A | Z1: BES_TR4_one590_A | AA1: BES_TR4_one617_A | AB1: BES_TR4_one76_A | AC1: BES_TR4_one133_A | AD1: BES_TR4_one137_A | AE1: BES_TR4_one176_A | AF1: BES_TR4_three64_A | AG1: BES_TR4_three193_A | AH1: BES_TR4_three232_C | AI1: BES_TR4_three233_A | AJ1: BES_TR4_three248_C | AK1: BES_TR4_three253_C | AL1: BES_TR4_three66_C | AM1: BES_TR4_three312_A | AN1: BES_TR4_three321_B | AO1: BES_TR4_three368_A | AP1: BES_TR4_three388_A | AQ1: BES_TR4_three409_C | AR1: BES_TR4_three76_A | AS1: BES_TR4_three81_A | AT1: BES_TR4_three90_C | AU1: BES_TR4_three97_B | AV1: BES_TR4_three160_C | AW1: fleet_average | AX1: fleet_total
A2: 1 | B2: 0 | C2: 0 | D2: 0 | E2: 0 | F2: 0 | G2: 0 | H2: 0 | I2: 0 | J2: 0 | K2: 0 | L2: 0 | M2: 0 | N2: 0 | O2: 0 | P2: 0 | Q2: 0 | R2: 0 | S2: 0 | T2: 0 | U2: 0 | V2: 0 | W2: 0 | X2: 0 | Y2: 0 | Z2: 0 | AA2: 0 | AB2: 0 | AC2: 0 | AD2: 0 | AE2: 0 | AF2: 0 | AG2: 0 | AH2: 0 | AI2: 0 | AJ2: 0 | AK2: 0 | AL2: 0 | AM2: 0 | AN2: 0 | AO2: 0 | AP2: 0 | AQ2: 0 | AR2: 0 | AS2: 0 | AT2: 0 | AU2: 0 | AV2: 0 | AW2: 0 | AX2: 0
A3: 2 | B3: 0.5 | C3: 0 | D3: 0 | E3: 0 | F3: 0 | G3: 0 | H3: 0 | I3: 0 | J3: 0 | K3: 0 | L3: 0 | M3: 0 | N3: 0 | O3: 0 | P3: 0 | Q3: 0 | R3: 0 | S3: 0 | T3: 0 | U3: 0 | V3: 0 | W3: 0 | X3: 0 | Y3: 0 | Z3: 0 | AA3: 0 | AB3: 0 | AC3: 0 | AD3: 0 | AE3: 0 | AF3: 0 | AG3: 0 | AH3: 0 | AI3: 0 | AJ3: 0 | AK3: 0 | AL3: 0 | AM3: 0 | AN3: 0 | AO3: 0 | AP3: 0 | AQ3: 0 | AR3: 0 | AS3: 0 | AT3: 0 | AU3: 0 | AV3: 0 | AW3: 0 | AX3: 0
A4: 3 | B4: 1 | C4: 0 | D4: 0 | E4: 0 | F4: 0 | G4: 0 | H4: 0 | I4: 0 | J4: 0 | K4: 0 | L4: 0 | M4: 0 | N4: 0 | O4: 0 | P4: 0 | Q4: 0 | R4: 0 | S4: 0 | T4: 0 | U4: 0 | V4: 0 | W4: 0 | X4: 0 | Y4: 0 | Z4: 0 | AA4: 0 | AB4: 0 | AC4: 0 | AD4: 0 | AE4: 0 | AF4: 0 | AG4: 0 | AH4: 0 | AI4: 0 | AJ4: 0 | AK4: 0 | AL4: 0 | AM4: 0 | AN4: 0 | AO4: 0 | AP4: 0 | AQ4: 0 | AR4: 0 | AS4: 0 | AT4: 0 | AU4: 0 | AV4: 0 | AW4: 0 | AX4: 0
A5: 4 | B5: 1.5 | C5: 0 | D5: 0 | E5: 0 | F5: 0 | G5: 0 | H5: 0 | I5: 0 | J5: 0 | K5: 0 | L5: 0 | M5: 0 | N5: 0 | O5: 0 | P5: 0 | Q5: 0 | R5: 0 | S5: 0 | T5: 0 | U5: 0 | V5: 0 | W5: 0 | X5: 0 | Y5: 0 | Z5: 0 | AA5: 0 | AB5: 0 | AC5: 0 | AD5: 0 | AE5: 0 | AF5: 0 | AG5: 0 | AH5: 0 | AI5: 0 | AJ5: 0 | AK5: 0 | AL5: 0 | AM5: 0 | AN5: 0 | AO5: 0 | AP5: 0 | AQ5: 0 | AR5: 0 | AS5: 0 | AT5: 0 | AU5: 0 | AV5: 0 | AW5: 0 | AX5: 0
A6: 5 | B6: 2 | C6: 0 | D6: 0 | E6: 0 | F6: 0 | G6: 0 | H6: 0 | I6: 0 | J6: 0 | K6: 0 | L6: 0 | M6: 0 | N6: 0 | O6: 0 | P6: 0 | Q6: 0 | R6: 0 | S6: 0 | T6: 0 | U6: 0 | V6: 0 | W6: 0 | X6: 0 | Y6: 0 | Z6: 0 | AA6: 0 | AB6: 0 | AC6: 0 | AD6: 0 | AE6: 0 | AF6: 0 | AG6: 0 | AH6: 0 | AI6: 0 | AJ6: 0 | AK6: 0 | AL6: 0 | AM6: 0 | AN6: 0 | AO6: 0 | AP6: 0 | AQ6: 0 | AR6: 0 | AS6: 0 | AT6: 0 | AU6: 0 | AV6: 0 | AW6: 0 | AX6: 0
A7: 6 | B7: 2.5 | C7: 0 | D7: 0 | E7: 0 | F7: 0 | G7: 0 | H7: 0 | I7: 0 | J7: 0 | K7: 0 | L7: 0 | M7: 0 | N7: 0 | O7: 0 | P7: 0 | Q7: 0 | R7: 0 | S7: 0 | T7: 0 | U7: 0 | V7: 0 | W7: 0 | X7: 0 | Y7: 0 | Z7: 0 | AA7: 0 | AB7: 0 | AC7: 0 | AD7: 0 | AE7: 0 | AF7: 0 | AG7: 0 | AH7: 0 | AI7: 0 | AJ7: 0 | AK7: 0 | AL7: 0 | AM7: 0 | AN7: 0 | AO7: 0 | AP7: 0 | AQ7: 0 | AR7: 0 | AS7: 0 | AT7: 0 | AU7: 0 | AV7: 0 | AW7: 0 | AX7: 0
A8: 7 | B8: 3 | C8: 0 | D8: 0 | E8: 0 | F8: 0 | G8: 0 | H8: 0 | I8: 0 | J8: 0 | K8: 0 | L8: 0 | M8: 0 | N8: 0 | O8: 0 | P8: 0 | Q8: 0 | R8: 0 | S8: 0 | T8: 0 | U8: 0 | V8: 0 | W8: 0 | X8: 0 | Y8: 0 | Z8: 0 | AA8: 0 | AB8: 0 | AC8: 0 | AD8: 0 | AE8: 0 | AF8: 0 | AG8: 0 | AH8: 0 | AI8: 0 | AJ8: 0 | AK8: 0 | AL8: 0 | AM8: 0 | AN8: 0 | AO8: 0 | AP8: 0 | AQ8: 0 | AR8: 0 | AS8: 0 | AT8: 0 | AU8: 0 | AV8: 0 | AW8: 0 | AX8: 0
A9: 8 | B9: 3.5 | C9: 0.003010703 | D9: 0.0025806026 | E9: 0.0034408035 | F9: 0.0034408035 | G9: 0.0025806026 | H9: 0.0034408035 | I9: 0.0034408035 | J9: 0.0021505022 | K9: 0.0021505022 | L9: 0.0034408035 | M9: 0.0025806026 | N9: 0.0034408035 | O9: 0.0012903013 | P9: 0.0017204017 | Q9: 0.0034408035 | R9: 0.0021505022 | S9: 0.0012903013 | T9: 0.0034408035 | U9: 0.0034408035 | V9: 0.0021505022 | W9: 0.003010703 | X9: 0.0021505022 | Y9: 0.0034408035 | Z9: 0.0021505022 | AA9: 0.003010703 | AB9: 0.0021505022 | AC9: 0.0034408035 | AD9: 0.0017204017 | AE9: 0.0021505022 | AF9: 0.0034408035 | AG9: 0.0034408035 | AH9: 0.003010703 | AI9: 0.0012903013 | AJ9: 0.0025806026 | AK9: 0.0017204017 | AL9: 0.0017204017 | AM9: 0.0034408035 | AN9: 0.0034408035 | AO9: 0.0012903013 | AP9: 0.0012903013 | AQ9: 0.0034408035 | AR9: 0.0034408035 | AS9: 0.0034408035 | AT9: 0.0021505022 | AU9: 0.0034408035 | AV9: 0.0034408035 | AW9: 0.0026928027 | AX9: 0.12386892
A10: 9 | B10: 4 | C10: 0.043517681 | D10: 0.037300869 | E10: 0.049734493 | F10: 0.049734493 | G10: 0.037300869 | H10: 0.049734493 | I10: 0.049734493 | J10: 0.031084058 | K10: 0.031084058 | L10: 0.049734493 | M10: 0.037300869 | N10: 0.049734493 | O10: 0.018650435 | P10: 0.024867246 | Q10: 0.049734493 | R10: 0.031084058 | S10: 0.018650435 | T10: 0.049734493 | U10: 0.049734493 | V10: 0.031084058 | W10: 0.043517681 | X10: 0.031084058 | Y10: 0.049734493 | Z10: 0.031084058 | AA10: 0.043517681 | AB10: 0.031084058 | AC10: 0.049734493 | AD10: 0.024867246 | AE10: 0.031084058 | AF10: 0.049734493 | AG10: 0.049734493 | AH10: 0.043517681 | AI10: 0.018650435 | AJ10: 0.037300869 | AK10: 0.024867246 | AL10: 0.024867246 | AM10: 0.049734493 | AN10: 0.049734493 | AO10: 0.018650435 | AP10: 0.018650435 | AQ10: 0.049734493 | AR10: 0.049734493 | AS10: 0.049734493 | AT10: 0.031084058 | AU10: 0.049734493 | AV10: 0.049734493 | AW10: 0.038922646 | AX10: 1.7904417
A11: 10 | B11: 4.5 | C11: 0.20350186 | D11: 0.17443017 | E11: 0.23257356 | F11: 0.23257356 | G11: 0.17443017 | H11: 0.23257356 | I11: 0.23257356 | J11: 0.14535847 | K11: 0.14535847 | L11: 0.23257356 | M11: 0.17443017 | N11: 0.23257356 | O11: 0.087215084 | P11: 0.11628678 | Q11: 0.23257356 | R11: 0.14535847 | S11: 0.087215084 | T11: 0.23257356 | U11: 0.23257356 | V11: 0.14535847 | W11: 0.20350186 | X11: 0.14535847 | Y11: 0.23257356 | Z11: 0.14535847 | AA11: 0.20350186 | AB11: 0.14535847 | AC11: 0.23257356 | AD11: 0.11628678 | AE11: 0.14535847 | AF11: 0.23257356 | AG11: 0.23257356 | AH11: 0.20350186 | AI11: 0.087215084 | AJ11: 0.17443017 | AK11: 0.11628678 | AL11: 0.11628678 | AM11: 0.23257356 | AN11: 0.23257356 | AO11: 0.087215084 | AP11: 0.087215084 | AQ11: 0.23257356 | AR11: 0.23257356 | AS11: 0.23257356 | AT11: 0.14535847 | AU11: 0.23257356 | AV11: 0.23257356 | AW11: 0.18201409 | AX11: 8.3726481
A12: 11 | B12: 5 | C12: 0.40367275 | D12: 0.34600522 | E12: 0.46134029 | F12: 0.46134029 | G12: 0.34600522 | H12: 0.46134029 | I12: 0.46134029 | J12: 0.28833768 | K12: 0.28833768 | L12: 0.46134029 | M12: 0.34600522 | N12: 0.46134029 | O12: 0.17300261 | P12: 0.23067014 | Q12: 0.46134029 | R12: 0.28833768 | S12: 0.17300261 | T12: 0.46134029 | U12: 0.46134029 | V12: 0.28833768 | W12: 0.40367275 | X12: 0.28833768 | Y12: 0.46134029 | Z12: 0.28833768 | AA12: 0.40367275 | AB12: 0.28833768 | AC12: 0.46134029 | AD12: 0.23067014 | AE12: 0.28833768 | AF12: 0.46134029 | AG12: 0.46134029 | AH12: 0.40367275 | AI12: 0.17300261 | AJ12: 0.34600522 | AK12: 0.23067014 | AL12: 0.23067014 | AM12: 0.46134029 | AN12: 0.46134029 | AO12: 0.17300261 | AP12: 0.17300261 | AQ12: 0.46134029 | AR12: 0.46134029 | AS12: 0.46134029 | AT12: 0.28833768 | AU12: 0.46134029 | AV12: 0.46134029 | AW12: 0.36104892 | AX12: 16.60825
A13: 12 | B13: 5.5 | C13: 0.64912573 | D13: 0.55639348 | E13: 0.74185798 | F13: 0.74185798 | G13: 0.55639348 | H13: 0.74185798 | I13: 0.74185798 | J13: 0.46366124 | K13: 0.46366124 | L13: 0.74185798 | M13: 0.55639348 | N13: 0.74185798 | O13: 0.27819674 | P13: 0.37092899 | Q13: 0.74185798 | R13: 0.46366124 | S13: 0.27819674 | T13: 0.74185798 | U13: 0.74185798 | V13: 0.46366124 | W13: 0.64912573 | X13: 0.46366124 | Y13: 0.74185798 | Z13: 0.46366124 | AA13: 0.64912573 | AB13: 0.46366124 | AC13: 0.74185798 | AD13: 0.37092899 | AE13: 0.46366124 | AF13: 0.74185798 | AG13: 0.74185798 | AH13: 0.64912573 | AI13: 0.27819674 | AJ13: 0.55639348 | AK13: 0.37092899 | AL13: 0.37092899 | AM13: 0.74185798 | AN13: 0.74185798 | AO13: 0.27819674 | AP13: 0.27819674 | AQ13: 0.74185798 | AR13: 0.74185798 | AS13: 0.74185798 | AT13: 0.46366124 | AU13: 0.74185798 | AV13: 0.74185798 | AW13: 0.5805845 | AX13: 26.706887
... A49: 48 | B49: 23.5 | C49: 0 | D49: 0 | E49: 0 | F49: 0 | G49: 0 | H49: 0 | I49: 0 | J49: 0 | K49: 0 | L49: 0 | M49: 0 | N49: 0 | O49: 0 | P49: 0 | Q49: 0 | R49: 0 | S49: 0 | T49: 0 | U49: 0 | V49: 0 | W49: 0 | X49: 0 | Y49: 0 | Z49: 0 | AA49: 0 | AB49: 0 | AC49: 0 | AD49: 0 | AE49: 0 | AF49: 0 | AG49: 0 | AH49: 0 | AI49: 0 | AJ49: 0 | AK49: 0 | AL49: 0 | AM49: 0 | AN49: 0 | AO49: 0 | AP49: 0 | AQ49: 0 | AR49: 0 | AS49: 0 | AT49: 0 | AU49: 0 | AV49: 0 | AW49: 0 | AX49: 0

Sheet Charge_kW
A1: period | B1: hour | C1: BES_TR4_one195_C | D1: BES_TR4_one223_B | E1: BES_TR4_one235_A | F1: BES_TR4_one242_B | G1: BES_TR4_one252_C | H1: BES_TR4_one260_C | I1: BES_TR4_one299_B | J1: BES_TR4_one320_B | K1: BES_TR4_one321_C | L1: BES_TR4_one328_A | M1: BES_TR4_one345_A | N1: BES_TR4_one366_B | O1: BES_TR4_one410_B | P1: BES_TR4_one50_A | Q1: BES_TR4_one416_C | R1: BES_TR4_one423_B | S1: BES_TR4_one446_B | T1: BES_TR4_one480_A | U1: BES_TR4_one61_A | V1: BES_TR4_one544_A | W1: BES_TR4_one560_C | X1: BES_TR4_one570_B | Y1: BES_TR4_one585_A | Z1: BES_TR4_one590_A | AA1: BES_TR4_one617_A | AB1: BES_TR4_one76_A | AC1: BES_TR4_one133_A | AD1: BES_TR4_one137_A | AE1: BES_TR4_one176_A | AF1: BES_TR4_three64_A | AG1: BES_TR4_three193_A | AH1: BES_TR4_three232_C | AI1: BES_TR4_three233_A | AJ1: BES_TR4_three248_C | AK1: BES_TR4_three253_C | AL1: BES_TR4_three66_C | AM1: BES_TR4_three312_A | AN1: BES_TR4_three321_B | AO1: BES_TR4_three368_A | AP1: BES_TR4_three388_A | AQ1: BES_TR4_three409_C | AR1: BES_TR4_three76_A | AS1: BES_TR4_three81_A | AT1: BES_TR4_three90_C | AU1: BES_TR4_three97_B | AV1: BES_TR4_three160_C | AW1: fleet_average | AX1: fleet_total
A2: 1 | B2: 0 | C2: 0 | D2: 0 | E2: 0 | F2: 0 | G2: 0 | H2: 0 | I2: 0 | J2: 0 | K2: 0 | L2: 0 | M2: 0 | N2: 0 | O2: 0 | P2: 0 | Q2: 0 | R2: 0 | S2: 0 | T2: 0 | U2: 0 | V2: 0 | W2: 0 | X2: 0 | Y2: 0 | Z2: 0 | AA2: 0 | AB2: 0 | AC2: 0 | AD2: 0 | AE2: 0 | AF2: 0 | AG2: 0 | AH2: 0 | AI2: 0 | AJ2: 0 | AK2: 0 | AL2: 0 | AM2: 0 | AN2: 0 | AO2: 0 | AP2: 0 | AQ2: 0 | AR2: 0 | AS2: 0 | AT2: 0 | AU2: 0 | AV2: 0 | AW2: 0 | AX2: 0
A3: 2 | B3: 0.5 | C3: 0 | D3: 0 | E3: 0 | F3: 0 | G3: 0 | H3: 0 | I3: 0 | J3: 0 | K3: 0 | L3: 0 | M3: 0 | N3: 0 | O3: 0 | P3: 0 | Q3: 0 | R3: 0 | S3: 0 | T3: 0 | U3: 0 | V3: 0 | W3: 0 | X3: 0 | Y3: 0 | Z3: 0 | AA3: 0 | AB3: 0 | AC3: 0 | AD3: 0 | AE3: 0 | AF3: 0 | AG3: 0 | AH3: 0 | AI3: 0 | AJ3: 0 | AK3: 0 | AL3: 0 | AM3: 0 | AN3: 0 | AO3: 0 | AP3: 0 | AQ3: 0 | AR3: 0 | AS3: 0 | AT3: 0 | AU3: 0 | AV3: 0 | AW3: 0 | AX3: 0
A4: 3 | B4: 1 | C4: 0 | D4: 0 | E4: 0 | F4: 0 | G4: 0 | H4: 0 | I4: 0 | J4: 0 | K4: 0 | L4: 0 | M4: 0 | N4: 0 | O4: 0 | P4: 0 | Q4: 0 | R4: 0 | S4: 0 | T4: 0 | U4: 0 | V4: 0 | W4: 0 | X4: 0 | Y4: 0 | Z4: 0 | AA4: 0 | AB4: 0 | AC4: 0 | AD4: 0 | AE4: 0 | AF4: 0 | AG4: 0 | AH4: 0 | AI4: 0 | AJ4: 0 | AK4: 0 | AL4: 0 | AM4: 0 | AN4: 0 | AO4: 0 | AP4: 0 | AQ4: 0 | AR4: 0 | AS4: 0 | AT4: 0 | AU4: 0 | AV4: 0 | AW4: 0 | AX4: 0
A5: 4 | B5: 1.5 | C5: 0 | D5: 0 | E5: 0 | F5: 0 | G5: 0 | H5: 0 | I5: 0 | J5: 0 | K5: 0 | L5: 0 | M5: 0 | N5: 0 | O5: 0 | P5: 0 | Q5: 0 | R5: 0 | S5: 0 | T5: 0 | U5: 0 | V5: 0 | W5: 0 | X5: 0 | Y5: 0 | Z5: 0 | AA5: 0 | AB5: 0 | AC5: 0 | AD5: 0 | AE5: 0 | AF5: 0 | AG5: 0 | AH5: 0 | AI5: 0 | AJ5: 0 | AK5: 0 | AL5: 0 | AM5: 0 | AN5: 0 | AO5: 0 | AP5: 0 | AQ5: 0 | AR5: 0 | AS5: 0 | AT5: 0 | AU5: 0 | AV5: 0 | AW5: 0 | AX5: 0
A6: 5 | B6: 2 | C6: 0 | D6: 0 | E6: 0 | F6: 0 | G6: 0 | H6: 0 | I6: 0 | J6: 0 | K6: 0 | L6: 0 | M6: 0 | N6: 0 | O6: 0 | P6: 0 | Q6: 0 | R6: 0 | S6: 0 | T6: 0 | U6: 0 | V6: 0 | W6: 0 | X6: 0 | Y6: 0 | Z6: 0 | AA6: 0 | AB6: 0 | AC6: 0 | AD6: 0 | AE6: 0 | AF6: 0 | AG6: 0 | AH6: 0 | AI6: 0 | AJ6: 0 | AK6: 0 | AL6: 0 | AM6: 0 | AN6: 0 | AO6: 0 | AP6: 0 | AQ6: 0 | AR6: 0 | AS6: 0 | AT6: 0 | AU6: 0 | AV6: 0 | AW6: 0 | AX6: 0
A7: 6 | B7: 2.5 | C7: 0 | D7: 0 | E7: 0 | F7: 0 | G7: 0 | H7: 0 | I7: 0 | J7: 0 | K7: 0 | L7: 0 | M7: 0 | N7: 0 | O7: 0 | P7: 0 | Q7: 0 | R7: 0 | S7: 0 | T7: 0 | U7: 0 | V7: 0 | W7: 0 | X7: 0 | Y7: 0 | Z7: 0 | AA7: 0 | AB7: 0 | AC7: 0 | AD7: 0 | AE7: 0 | AF7: 0 | AG7: 0 | AH7: 0 | AI7: 0 | AJ7: 0 | AK7: 0 | AL7: 0 | AM7: 0 | AN7: 0 | AO7: 0 | AP7: 0 | AQ7: 0 | AR7: 0 | AS7: 0 | AT7: 0 | AU7: 0 | AV7: 0 | AW7: 0 | AX7: 0
A8: 7 | B8: 3 | C8: 0 | D8: 0 | E8: 0 | F8: 0 | G8: 0 | H8: 0 | I8: 0 | J8: 0 | K8: 0 | L8: 0 | M8: 0 | N8: 0 | O8: 0 | P8: 0 | Q8: 0 | R8: 0 | S8: 0 | T8: 0 | U8: 0 | V8: 0 | W8: 0 | X8: 0 | Y8: 0 | Z8: 0 | AA8: 0 | AB8: 0 | AC8: 0 | AD8: 0 | AE8: 0 | AF8: 0 | AG8: 0 | AH8: 0 | AI8: 0 | AJ8: 0 | AK8: 0 | AL8: 0 | AM8: 0 | AN8: 0 | AO8: 0 | AP8: 0 | AQ8: 0 | AR8: 0 | AS8: 0 | AT8: 0 | AU8: 0 | AV8: 0 | AW8: 0 | AX8: 0
A9: 8 | B9: 3.5 | C9: 0 | D9: 0 | E9: 0 | F9: 0 | G9: 0 | H9: 0 | I9: 0 | J9: 0 | K9: 0 | L9: 0 | M9: 0 | N9: 0 | O9: 0 | P9: 0 | Q9: 0 | R9: 0 | S9: 0 | T9: 0 | U9: 0 | V9: 0 | W9: 0 | X9: 0 | Y9: 0 | Z9: 0 | AA9: 0 | AB9: 0 | AC9: 0 | AD9: 0 | AE9: 0 | AF9: 0 | AG9: 0 | AH9: 0 | AI9: 0 | AJ9: 0 | AK9: 0 | AL9: 0 | AM9: 0 | AN9: 0 | AO9: 0 | AP9: 0 | AQ9: 0 | AR9: 0 | AS9: 0 | AT9: 0 | AU9: 0 | AV9: 0 | AW9: 0 | AX9: 0
A10: 9 | B10: 4 | C10: 0 | D10: 0 | E10: 0 | F10: 0 | G10: 0 | H10: 0.015 | I10: 0 | J10: 0 | K10: 0 | L10: 0 | M10: 0 | N10: 0 | O10: 0 | P10: 0 | Q10: 0 | R10: 0 | S10: 0 | T10: 0 | U10: 0 | V10: 0 | W10: 0 | X10: 0 | Y10: 0 | Z10: 0 | AA10: 0 | AB10: 0 | AC10: 0 | AD10: 0 | AE10: 0 | AF10: 0 | AG10: 0 | AH10: 0 | AI10: 0 | AJ10: 0.011 | AK10: 0 | AL10: 0 | AM10: 0 | AN10: 0 | AO10: 0 | AP10: 0 | AQ10: 0 | AR10: 0 | AS10: 0 | AT10: 0 | AU10: 0 | AV10: 0 | AW10: 0.00056521739 | AX10: 0.026
A11: 10 | B11: 4.5 | C11: 0.078 | D11: 0.119 | E11: 0.183 | F11: 0.062 | G11: 0.119 | H11: 0.198 | I11: 0.181 | J11: 0.026 | K11: 0 | L11: 0.157 | M11: 0 | N11: 0.046 | O11: 0 | P11: 0.012 | Q11: 0.181 | R11: 0.045 | S11: 0 | T11: 0.076 | U11: 0.021 | V11: 0 | W11: 0.084 | X11: 0.094 | Y11: 0.158 | Z11: 0 | AA11: 0.16 | AB11: 0.096 | AC11: 0.175 | AD11: 0.06 | AE11: 0.092 | AF11: 0.112 | AG11: 0.007 | AH11: 0 | AI11: 0.037 | AJ11: 0.03 | AK11: 0.055 | AL11: 0 | AM11: 0.095 | AN11: 0.057 | AO11: 0.017 | AP11: 0 | AQ11: 0.191 | AR11: 0.023 | AS11: 0.181 | AT11: 0.042 | AU11: 0 | AV11: 0 | AW11: 0.071086957 | AX11: 3.27
A12: 11 | B12: 5 | C12: 0.263 | D12: 0.05 | E12: 0.387 | F12: 0.403 | G12: 0.291 | H12: 0.27 | I12: 0.234 | J12: 0.232 | K12: 0.233 | L12: 0.253 | M12: 0.237 | N12: 0.256 | O12: 0.01 | P12: 0.123 | Q12: 0.409 | R12: 0.058 | S12: 0.116 | T12: 0.303 | U12: 0.388 | V12: 0.175 | W12: 0.355 | X12: 0.237 | Y12: 0.27 | Z12: 0.153 | AA12: 0.316 | AB12: 0.112 | AC12: 0.403 | AD12: 0.061 | AE12: 0.258 | AF12: 0.41 | AG12: 0.369 | AH12: 0.297 | AI12: 0.015 | AJ12: 0.32 | AK12: 0.018 | AL12: 0.018 | AM12: 0.408 | AN12: 0.048 | AO12: 0.03 | AP12: 0.116 | AQ12: 0.419 | AR12: 0.413 | AS12: 0.175 | AT12: 0.115 | AU12: 0.406 | AV12: 0.404 | AW12: 0.23558696 | AX12: 10.837
A13: 12 | B13: 5.5 | C13: 0.468 | D13: 0.496 | E13: 0.539 | F13: 0.588 | G13: 0.501 | H13: 0.639 | I13: 0.573 | J13: 0.4 | K13: 0.323 | L13: 0.609 | M13: 0.501 | N13: 0.623 | O13: 0.141 | P13: 0 | Q13: 0.69 | R13: 0.409 | S13: 0.221 | T13: 0.623 | U13: 0.668 | V13: 0.375 | W13: 0.508 | X13: 0.138 | Y13: 0.689 | Z13: 0.157 | AA13: 0.583 | AB13: 0.397 | AC13: 0.684 | AD13: 0.262 | AE13: 0.316 | AF13: 0.559 | AG13: 0.518 | AH13: 0.403 | AI13: 0.095 | AJ13: 0.501 | AK13: 0.31 | AL13: 0.209 | AM13: 0.609 | AN13: 0.104 | AO13: 0.235 | AP13: 0 | AQ13: 0.57 | AR13: 0.594 | AS13: 0.677 | AT13: 0.359 | AU13: 0.687 | AV13: 0.632 | AW13: 0.43876087 | AX13: 20.183
... A49: 48 | B49: 23.5 | C49: 0 | D49: 0 | E49: 0 | F49: 0 | G49: 0 | H49: 0 | I49: 0 | J49: 0 | K49: 0 | L49: 0 | M49: 0 | N49: 0 | O49: 0 | P49: 0 | Q49: 0 | R49: 0 | S49: 0 | T49: 0 | U49: 0 | V49: 0 | W49: 0 | X49: 0 | Y49: 0 | Z49: 0 | AA49: 0 | AB49: 0 | AC49: 0 | AD49: 0 | AE49: 0 | AF49: 0 | AG49: 0 | AH49: 0 | AI49: 0 | AJ49: 0 | AK49: 0 | AL49: 0 | AM49: 0 | AN49: 0 | AO49: 0 | AP49: 0 | AQ49: 0 | AR49: 0 | AS49: 0 | AT49: 0 | AU49: 0 | AV49: 0 | AW49: 0 | AX49: 0

Sheet Discharge_kW
A1: period | B1: hour | C1: BES_TR4_one195_C | D1: BES_TR4_one223_B | E1: BES_TR4_one235_A | F1: BES_TR4_one242_B | G1: BES_TR4_one252_C | H1: BES_TR4_one260_C | I1: BES_TR4_one299_B | J1: BES_TR4_one320_B | K1: BES_TR4_one321_C | L1: BES_TR4_one328_A | M1: BES_TR4_one345_A | N1: BES_TR4_one366_B | O1: BES_TR4_one410_B | P1: BES_TR4_one50_A | Q1: BES_TR4_one416_C | R1: BES_TR4_one423_B | S1: BES_TR4_one446_B | T1: BES_TR4_one480_A | U1: BES_TR4_one61_A | V1: BES_TR4_one544_A | W1: BES_TR4_one560_C | X1: BES_TR4_one570_B | Y1: BES_TR4_one585_A | Z1: BES_TR4_one590_A | AA1: BES_TR4_one617_A | AB1: BES_TR4_one76_A | AC1: BES_TR4_one133_A | AD1: BES_TR4_one137_A | AE1: BES_TR4_one176_A | AF1: BES_TR4_three64_A | AG1: BES_TR4_three193_A | AH1: BES_TR4_three232_C | AI1: BES_TR4_three233_A | AJ1: BES_TR4_three248_C | AK1: BES_TR4_three253_C | AL1: BES_TR4_three66_C | AM1: BES_TR4_three312_A | AN1: BES_TR4_three321_B | AO1: BES_TR4_three368_A | AP1: BES_TR4_three388_A | AQ1: BES_TR4_three409_C | AR1: BES_TR4_three76_A | AS1: BES_TR4_three81_A | AT1: BES_TR4_three90_C | AU1: BES_TR4_three97_B | AV1: BES_TR4_three160_C | AW1: fleet_average | AX1: fleet_total
A2: 1 | B2: 0 | C2: 0.37 | D2: 0.201 | E2: 0.163 | F2: 0.058 | G2: 0.243 | H2: 0.124 | I2: 0.338 | J2: 0.232 | K2: 0.214 | L2: 0.488 | M2: 0.312 | N2: 0.21 | O2: 0.316 | P2: 0.061 | Q2: 0.052 | R2: 0.206 | S2: 0.252 | T2: 0.105 | U2: 0.452 | V2: 0.176 | W2: 0.141 | X2: 0.268 | Y2: 0.118 | Z2: 0.072 | AA2: 0.044 | AB2: 0.122 | AC2: 0.207 | AD2: 0.599 | AE2: 0.03 | AF2: 0.066 | AG2: 0.14 | AH2: 0.071 | AI2: 0.439 | AJ2: 0.026 | AK2: 0.212 | AL2: 0.06 | AM2: 0.138 | AN2: 0.125 | AO2: 0.043 | AP2: 0.298 | AQ2: 0.485 | AR2: 0.979 | AS2: 0.245 | AT2: 0.096 | AU2: 0.131 | AV2: 0.14 | AW2: 0.21452174 | AX2: 9.868
A3: 2 | B3: 0.5 | C3: 0.049 | D3: 0.044 | E3: 0.05 | F3: 0.255 | G3: 0.329 | H3: 0.035 | I3: 0.052 | J3: 0.056 | K3: 0.459 | L3: 0.374 | M3: 0.253 | N3: 0.177 | O3: 0.148 | P3: 0.185 | Q3: 0.052 | R3: 0.124 | S3: 0.057 | T3: 0.286 | U3: 0.066 | V3: 0.151 | W3: 0.113 | X3: 0.391 | Y3: 0.148 | Z3: 0.31 | AA3: 0.044 | AB3: 0.084 | AC3: 0.093 | AD3: 0.102 | AE3: 0.159 | AF3: 0.206 | AG3: 0.212 | AH3: 0.286 | AI3: 0.061 | AJ3: 0.026 | AK3: 0.14 | AL3: 0.217 | AM3: 0.176 | AN3: 0.056 | AO3: 0.171 | AP3: 0.068 | AQ3: 0.042 | AR3: 0.463 | AS3: 0.065 | AT3: 0.19 | AU3: 0.201 | AV3: 1.65 | AW3: 0.19295652 | AX3: 8.876
A4: 3 | B4: 1 | C4: 0.12 | D4: 0.044 | E4: 0.228 | F4: 0.137 | G4: 0.328 | H4: 0.035 | I4: 0.289 | J4: 0.168 | K4: 0.055 | L4: 0.209 | M4: 0.055 | N4: 0.211 | O4: 0.046 | P4: 0.135 | Q4: 0.052 | R4: 0.158 | S4: 0.226 | T4: 0.04 | U4: 0.135 | V4: 0.112 | W4: 0.049 | X4: 0.051 | Y4: 0.053 | Z4: 0.149 | AA4: 0.11 | AB4: 0.332 | AC4: 0.058 | AD4: 0.056 | AE4: 0.03 | AF4: 0.051 | AG4: 0.078 | AH4: 0.14 | AI4: 0.155 | AJ4: 0.144 | AK4: 0.407 | AL4: 0.049 | AM4: 0.048 | AN4: 0.056 | AO4: 0.043 | AP4: 0.112 | AQ4: 0.154 | AR4: 0.07 | AS4: 0.208 | AT4: 0.157 | AU4: 0.055 | AV4: 0.372 | AW4: 0.12978261 | AX4: 5.97
A5: 4 | B5: 1.5 | C5: 0.178 | D5: 0.183 | E5: 0.05 | F5: 0.058 | G5: 0.231 | H5: 0.205 | I5: 0.108 | J5: 0.12 | K5: 0.164 | L5: 0.054 | M5: 0.055 | N5: 0.126 | O5: 0.128 | P5: 0.161 | Q5: 0.052 | R5: 0.142 | S5: 0.084 | T5: 0.273 | U5: 0.15 | V5: 0.19 | W5: 0.205 | X5: 0.316 | Y5: 0.148 | Z5: 0.38 | AA5: 0.044 | AB5: 0.049 | AC5: 0.084 | AD5: 0.056 | AE5: 0.118 | AF5: 0.159 | AG5: 0.195 | AH5: 0.041 | AI5: 0.172 | AJ5: 0.026 | AK5: 0.453 | AL5: 0.078 | AM5: 0.266 | AN5: 0.056 | AO5: 0.043 | AP5: 0.254 | AQ5: 0.06 | AR5: 0.194 | AS5: 0.13 | AT5: 0.034 | AU5: 0.208 | AV5: 0.154 | AW5: 0.14423913 | AX5: 6.635
A6: 5 | B6: 2 | C6: 0.087 | D6: 0.174 | E6: 0.203 | F6: 0.252 | G6: 0.055 | H6: 0.089 | I6: 0.102 | J6: 0.056 | K6: 0.055 | L6: 0.133 | M6: 0.226 | N6: 0.292 | O6: 0.232 | P6: 0.149 | Q6: 0.052 | R6: 0.134 | S6: 0.128 | T6: 0.117 | U6: 0.081 | V6: 0.101 | W6: 0.049 | X6: 0.051 | Y6: 0.118 | Z6: 0.155 | AA6: 0.044 | AB6: 0.213 | AC6: 0.111 | AD6: 0.064 | AE6: 0.071 | AF6: 0.113 | AG6: 0.171 | AH6: 0.139 | AI6: 0.151 | AJ6: 0.026 | AK6: 0.332 | AL6: 0.222 | AM6: 0.048 | AN6: 0.056 | AO6: 0.171 | AP6: 0.05 | AQ6: 0.042 | AR6: 0.071 | AS6: 0.052 | AT6: 0.267 | AU6: 0.124 | AV6: 0.075 | AW6: 0.124 | AX6: 5.704
A7: 6 | B7: 2.5 | C7: 0.211 | D7: 0.044 | E7: 0.074 | F7: 0.14 | G7: 0.055 | H7: 0.072 | I7: 0.254 | J7: 0.152 | K7: 0.055 | L7: 0.209 | M7: 0.082 | N7: 0.116 | O7: 0.046 | P7: 0.227 | Q7: 0.052 | R7: 0.174 | S7: 0.181 | T7: 0.072 | U7: 0.204 | V7: 0.412 | W7: 0.155 | X7: 0.186 | Y7: 0.053 | Z7: 0.105 | AA7: 0.088 | AB7: 0.075 | AC7: 0.102 | AD7: 0.215 | AE7: 0.03 | AF7: 0.051 | AG7: 0.102 | AH7: 0.238 | AI7: 0.198 | AJ7: 0.115 | AK7: 0.509 | AL7: 0.139 | AM7: 0.17 | AN7: 0.125 | AO7: 0.043 | AP7: 0.285 | AQ7: 0.137 | AR7: 0.048 | AS7: 0.052 | AT7: 0.08 | AU7: 0.097 | AV7: 0 | AW7: 0.13543478 | AX7: 6.23
A8: 7 | B8: 3 | C8: 0.124 | D8: 0.233 | E8: 0.082 | F8: 0.058 | G8: 0.055 | H8: 0.221 | I8: 0.093 | J8: 0.136 | K8: 0.125 | L8: 0.129 | M8: 0.091 | N8: 0.068 | O8: 0.129 | P8: 0.069 | Q8: 0.052 | R8: 0.109 | S8: 0.075 | T8: 0.212 | U8: 0.058 | V8: 0.439 | W8: 0.099 | X8: 0.072 | Y8: 0.118 | Z8: 0.451 | AA8: 0.528 | AB8: 0.049 | AC8: 0.093 | AD8: 0.056 | AE8: 0.159 | AF8: 0.221 | AG8: 0.193 | AH8: 0.12 | AI8: 0.165 | AJ8: 0.056 | AK8: 0.338 | AL8: 0.171 | AM8: 0.144 | AN8: 0.06 | AO8: 0.171 | AP8: 0.081 | AQ8: 0.077 | AR8: 0.102 | AS8: 0.138 | AT8: 0.034 | AU8: 0.235 | AV8: 0 | AW8: 0.14106522 | AX8: 6.489
A9: 8 | B9: 3.5 | C9: 0.145 | D9: 0.121 | E9: 0.192 | F9: 0.19 | G9: 0.052 | H9: 0.032 | I9: 0.152 | J9: 0.054 | K9: 0.092 | L9: 0.16 | M9: 0.214 | N9: 0.362 | O9: 0.23 | P9: 0.207 | Q9: 0.049 | R9: 0.239 | S9: 0.233 | T9: 0.037 | U9: 0.224 | V9: 0.229 | W9: 0.046 | X9: 0.064 | Y9: 0.144 | Z9: 0.099 | AA9: 0.258 | AB9: 0.339 | AC9: 0.055 | AD9: 0.221 | AE9: 0.028 | AF9: 0.048 | AG9: 0.156 | AH9: 0.038 | AI9: 0.179 | AJ9: 0.023 | AK9: 0 | AL9: 0.185 | AM9: 0.057 | AN9: 0.117 | AO9: 0.042 | AP9: 0.083 | AQ9: 0.039 | AR9: 0.16 | AS9: 0.196 | AT9: 0.201 | AU9: 0.052 | AV9: 0 | AW9: 0.1313913 | AX9: 6.044
A10: 9 | B10: 4 | C10: 0.074 | D10: 0.105 | E10: 0.0002655128 | F10: 0.149 | G10: 0.018 | H10: 0 | I10: 0.192 | J10: 0.137 | K10: 0.024 | L10: 0.111 | M10: 0.018 | N10: 0.01 | O10: 0.027 | P10: 0.018 | Q10: 0.002 | R10: 0.059 | S10: 0.038 | T10: 0.083 | U10: 0.008 | V10: 0.092 | W10: 0.09 | X10: 0.27 | Y10: 0.003 | Z10: 0.246 | AA10: 0.063 | AB10: 0.044 | AC10: 0.087 | AD10: 0.031 | AE10: 0.105 | AF10: 0.102 | AG10: 0.077 | AH10: 0.136 | AI10: 0.229 | AJ10: 0 | AK10: 0 | AL10: 0.079 | AM10: 0.113 | AN10: 0.014 | AO10: 0.024 | AP10: 0.189 | AQ10: 0.122 | AR10: 0.006 | AS10: 0.002 | AT10: 0.113 | AU10: 0.005 | AV10: 0 | AW10: 0.072070989 | AX10: 3.3152655
A11: 10 | B11: 4.5 | C11: 0 | D11: 0 | E11: 0 | F11: 0 | G11: 0 | H11: 0 | I11: 0 | J11: 0 | K11: 0.018 | L11: 0 | M11: 0.108 | N11: 0 | O11: 0.111 | P11: 0 | Q11: 0 | R11: 0 | S11: 0.165 | T11: 0 | U11: 0 | V11: 0.062 | W11: 0 | X11: 0 | Y11: 0 | Z11: 0.133 | AA11: 0 | AB11: 0 | AC11: 0 | AD11: 0 | AE11: 0 | AF11: 0 | AG11: 0 | AH11: 0.008 | AI11: 0 | AJ11: 0 | AK11: 0 | AL11: 0.039 | AM11: 0 | AN11: 0 | AO11: 0 | AP11: 0.037 | AQ11: 0 | AR11: 0 | AS11: 0 | AT11: 0 | AU11: 0.044 | AV11: 0 | AW11: 0.01576087 | AX11: 0.725
A12: 11 | B12: 5 | C12: 0 | D12: 0 | E12: 0 | F12: 0 | G12: 0 | H12: 0 | I12: 0 | J12: 0 | K12: 0 | L12: 0 | M12: 0 | N12: 0 | O12: 0 | P12: 0 | Q12: 0 | R12: 0 | S12: 0 | T12: 0 | U12: 0 | V12: 0 | W12: 0 | X12: 0 | Y12: 0 | Z12: 0 | AA12: 0 | AB12: 0 | AC12: 0 | AD12: 0 | AE12: 0 | AF12: 0 | AG12: 0 | AH12: 0 | AI12: 0 | AJ12: 0 | AK12: 0 | AL12: 0 | AM12: 0 | AN12: 0 | AO12: 0 | AP12: 0 | AQ12: 0 | AR12: 0 | AS12: 0 | AT12: 0 | AU12: 0 | AV12: 0 | AW12: 0 | AX12: 0
A13: 12 | B13: 5.5 | C13: 0 | D13: 0 | E13: 0 | F13: 0 | G13: 0 | H13: 0 | I13: 0 | J13: 0 | K13: 0 | L13: 0 | M13: 0 | N13: 0 | O13: 0 | P13: 0.055 | Q13: 0 | R13: 0 | S13: 0 | T13: 0 | U13: 0 | V13: 0 | W13: 0 | X13: 0 | Y13: 0 | Z13: 0 | AA13: 0 | AB13: 0 | AC13: 0 | AD13: 0 | AE13: 0 | AF13: 0 | AG13: 0 | AH13: 0 | AI13: 0 | AJ13: 0 | AK13: 0 | AL13: 0 | AM13: 0 | AN13: 0 | AO13: 0 | AP13: 0.008 | AQ13: 0 | AR13: 0 | AS13: 0 | AT13: 0 | AU13: 0 | AV13: 0 | AW13: 0.0013695652 | AX13: 0.063
... A49: 48 | B49: 23.5 | C49: 0.049 | D49: 0.187 | E49: 0.123 | F49: 0.549 | G49: 0.055 | H49: 0.155 | I49: 0.179 | J49: 0 | K49: 0.156 | L49: 0.082 | M49: 0.118 | N49: 0.244 | O49: 0.46 | P49: 0.052 | Q49: 0.477 | R49: 0.784 | S49: 0.306 | T49: 0.16 | U49: 0.783 | V49: 0 | W49: 0 | X49: 0.382 | Y49: 0.104 | Z49: 0.223 | AA49: 0.264 | AB49: 0.11 | AC49: 0.785 | AD49: 0.72 | AE49: 0.03 | AF49: 0.405 | AG49: 0.104 | AH49: 0.293 | AI49: 0 | AJ49: 0 | AK49: 0 | AL49: 0.579 | AM49: 0.125 | AN49: 0.422 | AO49: 0.043 | AP49: 0 | AQ49: 0.042 | AR49: 0.048 | AS49: 0.087 | AT49: 0.51 | AU49: 0.07 | AV49: 0.057 | AW49: 0.2243913 | AX49: 10.322

Sheet Net_kW
A1: period | B1: hour | C1: BES_TR4_one195_C | D1: BES_TR4_one223_B | E1: BES_TR4_one235_A | F1: BES_TR4_one242_B | G1: BES_TR4_one252_C | H1: BES_TR4_one260_C | I1: BES_TR4_one299_B | J1: BES_TR4_one320_B | K1: BES_TR4_one321_C | L1: BES_TR4_one328_A | M1: BES_TR4_one345_A | N1: BES_TR4_one366_B | O1: BES_TR4_one410_B | P1: BES_TR4_one50_A | Q1: BES_TR4_one416_C | R1: BES_TR4_one423_B | S1: BES_TR4_one446_B | T1: BES_TR4_one480_A | U1: BES_TR4_one61_A | V1: BES_TR4_one544_A | W1: BES_TR4_one560_C | X1: BES_TR4_one570_B | Y1: BES_TR4_one585_A | Z1: BES_TR4_one590_A | AA1: BES_TR4_one617_A | AB1: BES_TR4_one76_A | AC1: BES_TR4_one133_A | AD1: BES_TR4_one137_A | AE1: BES_TR4_one176_A | AF1: BES_TR4_three64_A | AG1: BES_TR4_three193_A | AH1: BES_TR4_three232_C | AI1: BES_TR4_three233_A | AJ1: BES_TR4_three248_C | AK1: BES_TR4_three253_C | AL1: BES_TR4_three66_C | AM1: BES_TR4_three312_A | AN1: BES_TR4_three321_B | AO1: BES_TR4_three368_A | AP1: BES_TR4_three388_A | AQ1: BES_TR4_three409_C | AR1: BES_TR4_three76_A | AS1: BES_TR4_three81_A | AT1: BES_TR4_three90_C | AU1: BES_TR4_three97_B | AV1: BES_TR4_three160_C | AW1: fleet_average | AX1: fleet_total
A2: 1 | B2: 0 | C2: -0.00030233333 | D2: -0.00042533333 | E2: -3.8666667e-05 | F2: 0 | G2: -0.00044666667 | H2: -0.00021133333 | I2: -8.5333333e-05 | J2: -0.00042533333 | K2: -8.7333333e-05 | L2: -2.0333333e-05 | M2: -0.00034933333 | N2: 0.000313 | O2: 0.00038166667 | P2: -0.000496 | Q2: 0 | R2: 0.00041133333 | S2: 0.00016933333 | T2: -0.00036166667 | U2: 8.5333333e-05 | V2: -0.00012666667 | W2: 7.0333333e-05 | X2: -0.00016 | Y2: 0.000499 | Z2: 0.00021333333 | AA2: 0 | AB2: -0.000264 | AC2: -2.6666667e-05 | AD2: 0.00029133333 | AE2: -3.469447e-18 | AF2: 0.00048333333 | AG2: 0.00010566667 | AH2: 0.00032933333 | AI2: -0.000362 | AJ2: 0 | AK2: 0.00035266667 | AL2: 0.00028533333 | AM2: -0.000282 | AN2: -0.00024066667 | AO2: -6.9388939e-18 | AP2: 2.8e-05 | AQ2: -3.8333333e-05 | AR2: -3.3333333e-05 | AS2: -0.000172 | AT2: -0.00033333333 | AU2: 7.1666667e-05 | AV2: -0.00031466667 | AW2: -3.2884058e-05 | AX2: -0.0015126667
A3: 2 | B3: 0.5 | C3: 0 | D3: 0 | E3: 0 | F3: -0.00048333333 | G3: -0.00039733333 | H3: 6.9388939e-18 | I3: 0 | J3: 0 | K3: 0.000261 | L3: -0.00014666667 | M3: -0.00041066667 | N3: 0.00042333333 | O3: -0.0001 | P3: -0.00016533333 | Q3: 0 | R3: 0.00045 | S3: 0 | T3: -0.00028233333 | U3: -0.00031233333 | V3: 0.000388 | W3: -0.000259 | X3: 0.00035033333 | Y3: -0.00039033333 | Z3: 0.00026533333 | AA3: 0 | AB3: -0.00037466667 | AC3: 0.000208 | AD3: -0.000472 | AE3: 9.6e-05 | AF3: -0.00016666667 | AG3: 0.000309 | AH3: -0.00046966667 | AI3: -0.000176 | AJ3: 0 | AK3: 0.00049466667 | AL3: -0.000203 | AM3: 3.3333333e-05 | AN3: 0 | AO3: -0.00040866667 | AP3: 0.000335 | AQ3: 6.9388939e-18 | AR3: 8.8e-05 | AS3: 3.8e-05 | AT3: -9.2e-05 | AU3: -0.000393 | AV3: 0.00045733333 | AW3: -3.2731884e-05 | AX3: -0.0015056667
A4: 3 | B4: 1 | C4: -0.00035666667 | D4: 0 | E4: -0.00048933333 | F4: -2.6666667e-06 | G4: 5.8666667e-05 | H4: 6.9388939e-18 | I4: 4e-05 | J4: -0.00027066667 | K4: 0 | L4: -0.00022266667 | M4: 0 | N4: -0.00016566667 | O4: 0 | P4: -0.00017866667 | Q4: 0 | R4: 0.000235 | S4: -0.00044466667 | T4: 0 | U4: -0.00012333333 | V4: 0.00019066667 | W4: 0 | X4: 0 | Y4: 0 | Z4: 1.7e-05 | AA4: -5.4e-05 | AB4: 0.000102 | AC4: 0 | AD4: 0 | AE4: -3.469447e-18 | AF4: 0 | AG4: 0.000115 | AH4: -2.7e-05 | AI4: 4.6666667e-06 | AJ4: 7.3333333e-05 | AK4: 8.2666667e-05 | AL4: 0 | AM4: 0 | AN4: 0 | AO4: -6.9388939e-18 | AP4: 0.000262 | AQ4: 0.000366 | AR4: 1.3877788e-17 | AS4: 2e-06 | AT4: 0.000248 | AU4: 0 | AV4: -7.6e-05 | AW4: -1.3355072e-05 | AX4: -0.00061433333
A5: 4 | B5: 1.5 | C5: -0.00035866667 | D5: -0.00033733333 | E5: 0 | F5: 0 | G5: 0.000301 | H5: 9.8666667e-05 | I5: -0.000284 | J5: -0.00015466667 | K5: -0.00018733333 | L5: 0 | M5: 0 | N5: 0.000106 | O5: -0.00048 | P5: 0.00048 | Q5: 0 | R5: -0.00024033333 | S5: -0.000386 | T5: 0.00028533333 | U5: 0.000252 | V5: -4.7333333e-05 | W5: -0.00018866667 | X5: 0.00032 | Y5: -0.00039033333 | Z5: 0.000496 | AA5: 0 | AB5: 0 | AC5: 0.000406 | AD5: 0 | AE5: 2e-05 | AF5: 0.00038333333 | AG5: 0.00049933333 | AH5: 0 | AI5: -0.000178 | AJ5: 0 | AK5: -0.00045733333 | AL5: -0.000484 | AM5: -0.000253 | AN5: 0 | AO5: -6.9388939e-18 | AP5: 0.00010533333 | AQ5: -0.000258 | AR5: -0.00025733333 | AS5: 0.000228 | AT5: 0 | AU5: -0.00045933333 | AV5: -0.00047466667 | AW5: -4.1202899e-05 | AX5: -0.0018953333
