Workbook

Sheet ReadMe
A1: README
A2: Data behind the TR5 rolling-dispatch figures (SOC, demand/PV/dispatch, net, self-consumption, metrics histogram).
A3: Each quantity sheet: rows = 48 half-hour periods (with hour of day), columns = prosumers, plus fleet_average / fleet_total.
A4: Dispatch is the committed slot-1 execution of the rolling horizon (self-consumption baseline, Term 2 + Term 3).
A5: SOC is the realised state at the START of each step (fraction of capacity).
A6: net_kW = (demand - PV) + (charge - discharge); positive = import, negative = export.
A7: Regenerate: python build_workbook.py --force (see README.md for other transformers).

Sheet Summary
A1: quantity | B1: value
A2: run | B2: TR5 exact-QCP rolling (FOR_PolyS=0, FOR_LinearizeVmax=0), 48 steps, all Optimal
A3: source dispatch | B3: FOR_rolling_soc_TR5.csv
A4: source load/PV | B4: TR5_load_PV_48periods.xlsx
A5: prosumers | B5: 214
A6: PV generated kWh/day | B6: 5100.2
A7: demand kWh/day | B7: 1615.1
A8: exported kWh/day | B8: 3390.9
A9: imported kWh/day | B9: 40.2
A10: SCR % (PV used locally) | B10: 33.5
A11: SSR % (demand met locally) | B11: 97.5
A12: prosumer-periods |net|<50W % | B12: 58.9
A13: SOC min/max over day | B13: 0.10 / 1.00
A14: simultaneous chg+dis rows | B14: 0

Sheet FleetAverage
A1: period | B1: hour | C1: demand_avg_kW | D1: PV_avg_kW | E1: charge_avg_kW | F1: discharge_avg_kW | G1: net_avg_kW | H1: SOC_avg_pct | I1: demand_total_kW | J1: PV_total_kW | K1: net_total_kW
A2: =Demand_kW!A2 -> 1 | B2: =Demand_kW!B2 -> 0 | C2: =AVERAGE(Demand_kW!$C2:$HH2) -> 0.22911749 | D2: =AVERAGE(PV_kW!$C2:$HH2) -> 0 | E2: =AVERAGE(Charge_kW!$C2:$HH2) -> 0 | F2: =AVERAGE(Discharge_kW!$C2:$HH2) -> 0.22659346 | G2: =C2-D2+E2-F2 -> 0.0025240369 | H2: =AVERAGE(SOC_pct!$C2:$HH2) -> 40 | I2: =SUM(Demand_kW!$C2:$HH2) -> 49.031144 | J2: =SUM(PV_kW!$C2:$HH2) -> 0 | K2: =I2-J2+SUM(Charge_kW!$C2:$HH2)-SUM(Discharge_kW!$C2:$HH2) -> 0.5401439
A3: =Demand_kW!A3 -> 2 | B3: =Demand_kW!B3 -> 0.5 | C3: =AVERAGE(Demand_kW!$C3:$HH3) -> 0.19497567 | D3: =AVERAGE(PV_kW!$C3:$HH3) -> 0 | E3: =AVERAGE(Charge_kW!$C3:$HH3) -> 0 | F3: =AVERAGE(Discharge_kW!$C3:$HH3) -> 0.18254206 | G3: =C3-D3+E3-F3 -> 0.012433609 | H3: =AVERAGE(SOC_pct!$C3:$HH3) -> 37.156752 | I3: =SUM(Demand_kW!$C3:$HH3) -> 41.724792 | J3: =SUM(PV_kW!$C3:$HH3) -> 0 | K3: =I3-J3+SUM(Charge_kW!$C3:$HH3)-SUM(Discharge_kW!$C3:$HH3) -> 2.6607923
A4: =Demand_kW!A4 -> 3 | B4: =Demand_kW!B4 -> 1 | C4: =AVERAGE(Demand_kW!$C4:$HH4) -> 0.16011424 | D4: =AVERAGE(PV_kW!$C4:$HH4) -> 0 | E4: =AVERAGE(Charge_kW!$C4:$HH4) -> 0 | F4: =AVERAGE(Discharge_kW!$C4:$HH4) -> 0.14517757 | G4: =C4-D4+E4-F4 -> 0.014936671 | H4: =AVERAGE(SOC_pct!$C4:$HH4) -> 34.866054 | I4: =SUM(Demand_kW!$C4:$HH4) -> 34.264448 | J4: =SUM(PV_kW!$C4:$HH4) -> 0 | K4: =I4-J4+SUM(Charge_kW!$C4:$HH4)-SUM(Discharge_kW!$C4:$HH4) -> 3.1964475
A5: =Demand_kW!A5 -> 4 | B5: =Demand_kW!B5 -> 1.5 | C5: =AVERAGE(Demand_kW!$C5:$HH5) -> 0.15336568 | D5: =AVERAGE(PV_kW!$C5:$HH5) -> 0 | E5: =AVERAGE(Charge_kW!$C5:$HH5) -> 0 | F5: =AVERAGE(Discharge_kW!$C5:$HH5) -> 0.13227103 | G5: =C5-D5+E5-F5 -> 0.021094651 | H5: =AVERAGE(SOC_pct!$C5:$HH5) -> 33.044306 | I5: =SUM(Demand_kW!$C5:$HH5) -> 32.820255 | J5: =SUM(PV_kW!$C5:$HH5) -> 0 | K5: =I5-J5+SUM(Charge_kW!$C5:$HH5)-SUM(Discharge_kW!$C5:$HH5) -> 4.5142553
A6: =Demand_kW!A6 -> 5 | B6: =Demand_kW!B6 -> 2 | C6: =AVERAGE(Demand_kW!$C6:$HH6) -> 0.13142737 | D6: =AVERAGE(PV_kW!$C6:$HH6) -> 0 | E6: =AVERAGE(Charge_kW!$C6:$HH6) -> 0 | F6: =AVERAGE(Discharge_kW!$C6:$HH6) -> 0.11759346 | G6: =C6-D6+E6-F6 -> 0.01383391 | H6: =AVERAGE(SOC_pct!$C6:$HH6) -> 31.384434 | I6: =SUM(Demand_kW!$C6:$HH6) -> 28.125457 | J6: =SUM(PV_kW!$C6:$HH6) -> 0 | K6: =I6-J6+SUM(Charge_kW!$C6:$HH6)-SUM(Discharge_kW!$C6:$HH6) -> 2.9604567
A7: =Demand_kW!A7 -> 6 | B7: =Demand_kW!B7 -> 2.5 | C7: =AVERAGE(Demand_kW!$C7:$HH7) -> 0.11337704 | D7: =AVERAGE(PV_kW!$C7:$HH7) -> 0 | E7: =AVERAGE(Charge_kW!$C7:$HH7) -> 0 | F7: =AVERAGE(Discharge_kW!$C7:$HH7) -> 0.10375701 | G7: =C7-D7+E7-F7 -> 0.0096200355 | H7: =AVERAGE(SOC_pct!$C7:$HH7) -> 29.908575 | I7: =SUM(Demand_kW!$C7:$HH7) -> 24.262688 | J7: =SUM(PV_kW!$C7:$HH7) -> 0 | K7: =I7-J7+SUM(Charge_kW!$C7:$HH7)-SUM(Discharge_kW!$C7:$HH7) -> 2.0586876
A8: =Demand_kW!A8 -> 7 | B8: =Demand_kW!B8 -> 3 | C8: =AVERAGE(Demand_kW!$C8:$HH8) -> 0.13233262 | D8: =AVERAGE(PV_kW!$C8:$HH8) -> 0 | E8: =AVERAGE(Charge_kW!$C8:$HH8) -> 0 | F8: =AVERAGE(Discharge_kW!$C8:$HH8) -> 0.12530841 | G8: =C8-D8+E8-F8 -> 0.0070242072 | H8: =AVERAGE(SOC_pct!$C8:$HH8) -> 28.606679 | I8: =SUM(Demand_kW!$C8:$HH8) -> 28.31918 | J8: =SUM(PV_kW!$C8:$HH8) -> 0 | K8: =I8-J8+SUM(Charge_kW!$C8:$HH8)-SUM(Discharge_kW!$C8:$HH8) -> 1.5031803
A9: =Demand_kW!A9 -> 8 | B9: =Demand_kW!B9 -> 3.5 | C9: =AVERAGE(Demand_kW!$C9:$HH9) -> 0.12485107 | D9: =AVERAGE(PV_kW!$C9:$HH9) -> 0.0025383965 | E9: =AVERAGE(Charge_kW!$C9:$HH9) -> 0 | F9: =AVERAGE(Discharge_kW!$C9:$HH9) -> 0.11176636 | G9: =C9-D9+E9-F9 -> 0.010546314 | H9: =AVERAGE(SOC_pct!$C9:$HH9) -> 27.034064 | I9: =SUM(Demand_kW!$C9:$HH9) -> 26.718128 | J9: =SUM(PV_kW!$C9:$HH9) -> 0.54321685 | K9: =I9-J9+SUM(Charge_kW!$C9:$HH9)-SUM(Discharge_kW!$C9:$HH9) -> 2.2569112
A10: =Demand_kW!A10 -> 9 | B10: =Demand_kW!B10 -> 4 | C10: =AVERAGE(Demand_kW!$C10:$HH10) -> 0.13398744 | D10: =AVERAGE(PV_kW!$C10:$HH10) -> 0.036690808 | E10: =AVERAGE(Charge_kW!$C10:$HH10) -> 0.00034579439 | F10: =AVERAGE(Discharge_kW!$C10:$HH10) -> 0.086228021 | G10: =C10-D10+E10-F10 -> 0.011414405 | H10: =AVERAGE(SOC_pct!$C10:$HH10) -> 25.632061 | I10: =SUM(Demand_kW!$C10:$HH10) -> 28.673312 | J10: =SUM(PV_kW!$C10:$HH10) -> 7.851833 | K10: =I10-J10+SUM(Charge_kW!$C10:$HH10)-SUM(Discharge_kW!$C10:$HH10) -> 2.4426826
A11: =Demand_kW!A11 -> 10 | B11: =Demand_kW!B11 -> 4.5 | C11: =AVERAGE(Demand_kW!$C11:$HH11) -> 0.12940793 | D11: =AVERAGE(PV_kW!$C11:$HH11) -> 0.17157734 | E11: =AVERAGE(Charge_kW!$C11:$HH11) -> 0.06332243 | F11: =AVERAGE(Discharge_kW!$C11:$HH11) -> 0.018014019 | G11: =C11-D11+E11-F11 -> 0.003139002 | H11: =AVERAGE(SOC_pct!$C11:$HH11) -> 24.553457 | I11: =SUM(Demand_kW!$C11:$HH11) -> 27.693297 | J11: =SUM(PV_kW!$C11:$HH11) -> 36.71755 | K11: =I11-J11+SUM(Charge_kW!$C11:$HH11)-SUM(Discharge_kW!$C11:$HH11) -> 0.67174642
A12: =Demand_kW!A12 -> 11 | B12: =Demand_kW!B12 -> 5 | C12: =AVERAGE(Demand_kW!$C12:$HH12) -> 0.11773193 | D12: =AVERAGE(PV_kW!$C12:$HH12) -> 0.34034625 | E12: =AVERAGE(Charge_kW!$C12:$HH12) -> 0.22940654 | F12: =AVERAGE(Discharge_kW!$C12:$HH12) -> 0.006682243 | G12: =C12-D12+E12-F12 -> 0.0001099783 | H12: =AVERAGE(SOC_pct!$C12:$HH12) -> 25.042433 | I12: =SUM(Demand_kW!$C12:$HH12) -> 25.194633 | J12: =SUM(PV_kW!$C12:$HH12) -> 72.834098 | K12: =I12-J12+SUM(Charge_kW!$C12:$HH12)-SUM(Discharge_kW!$C12:$HH12) -> 0.023535357
A13: =Demand_kW!A13 -> 12 | B13: =Demand_kW!B13 -> 5.5 | C13: =AVERAGE(Demand_kW!$C13:$HH13) -> 0.12717219 | D13: =AVERAGE(PV_kW!$C13:$HH13) -> 0.54729359 | E13: =AVERAGE(Charge_kW!$C13:$HH13) -> 0.42164019 | F13: =AVERAGE(Discharge_kW!$C13:$HH13) -> 0.0014813084 | G13: =C13-D13+E13-F13 -> 3.7475957e-05 | H13: =AVERAGE(SOC_pct!$C13:$HH13) -> 27.550279 | I13: =SUM(Demand_kW!$C13:$HH13) -> 27.214848 | J13: =SUM(PV_kW!$C13:$HH13) -> 117.12083 | K13: =I13-J13+SUM(Charge_kW!$C13:$HH13)-SUM(Discharge_kW!$C13:$HH13) -> 0.0080198548
... A49: =Demand_kW!A49 -> 48 | B49: =Demand_kW!B49 -> 23.5 | C49: =AVERAGE(Demand_kW!$C49:$HH49) -> 0.27751476 | D49: =AVERAGE(PV_kW!$C49:$HH49) -> 0 | E49: =AVERAGE(Charge_kW!$C49:$HH49) -> 0 | F49: =AVERAGE(Discharge_kW!$C49:$HH49) -> 0.22183645 | G49: =C49-D49+E49-F49 -> 0.055678316 | H49: =AVERAGE(SOC_pct!$C49:$HH49) -> 49.650557 | I49: =SUM(Demand_kW!$C49:$HH49) -> 59.38816 | J49: =SUM(PV_kW!$C49:$HH49) -> 0 | K49: =I49-J49+SUM(Charge_kW!$C49:$HH49)-SUM(Discharge_kW!$C49:$HH49) -> 11.91516

Sheet SOC_pct
A1: period | B1: hour | C1: BES_TR5_one38_B | D1: BES_TR5_one195_C | E1: BES_TR5_one195_dup_C | F1: BES_TR5_one235_A | G1: BES_TR5_one235_dup_A | H1: BES_TR5_one242_dup_B | I1: BES_TR5_one252_C | J1: BES_TR5_one252_dup_C | K1: BES_TR5_one260_dup_C | L1: BES_TR5_one280_A | M1: BES_TR5_one287_B | N1: BES_TR5_one299_B | O1: BES_TR5_one299_dup_B | P1: BES_TR5_one313_A | Q1: BES_TR5_one313_dup_A | R1: BES_TR5_one42_B | S1: BES_TR5_one320_B | T1: BES_TR5_one321_C | U1: BES_TR5_one328_A | V1: BES_TR5_one345_dup_A | W1: BES_TR5_one346_C | X1: BES_TR5_one366_dup_B | Y1: BES_TR5_one375_C | Z1: BES_TR5_one375_dup_C | AA1: BES_TR5_one410_B | AB1: BES_TR5_one410_dup_B | AC1: BES_TR5_one50_A | AD1: BES_TR5_one416_C | AE1: BES_TR5_one416_dup_C | AF1: BES_TR5_one423_dup_B | AG1: BES_TR5_one446_dup_B | AH1: BES_TR5_one469_A | AI1: BES_TR5_one477_A | AJ1: BES_TR5_one477_dup_A | AK1: BES_TR5_one480_A | AL1: BES_TR5_one480_dup_A | AM1: BES_TR5_one521_dup_C | AN1: BES_TR5_one528_C | AO1: BES_TR5_one528_dup_C | AP1: BES_TR5_one61_dup_A | AQ1: BES_TR5_one544_A | AR1: BES_TR5_one544_dup_A | AS1: BES_TR5_one559_C | AT1: BES_TR5_one590_A | AU1: BES_TR5_one590_dup_A | AV1: BES_TR5_one605_A | AW1: BES_TR5_one605_dup_A | AX1: BES_TR5_one614_B | AY1: BES_TR5_one617_dup_A | AZ1: BES_TR5_one73_A | BA1: BES_TR5_one73_dup_A | BB1: BES_TR5_one76_A | BC1: BES_TR5_one133_A | BD1: BES_TR5_one137_A | BE1: BES_TR5_one176_A | BF1: BES_TR5_four1252_C | BG1: BES_TR5_four171_A | BH1: BES_TR5_four180_A | BI1: BES_TR5_four184_B | BJ1: BES_TR5_four200_A | BK1: BES_TR5_four239_A | BL1: BES_TR5_four259_B | BM1: BES_TR5_four54_C | BN1: BES_TR5_four279_B | BO1: BES_TR5_four288_B | BP1: BES_TR5_four301_C | BQ1: BES_TR5_four326_A | BR1: BES_TR5_four352_A | BS1: BES_TR5_four354_B | BT1: BES_TR5_four358_C | BU1: BES_TR5_four381_A | BV1: BES_TR5_four385_A | BW1: BES_TR5_four396_B | BX1: BES_TR5_four423_C | BY1: BES_TR5_four446_B | BZ1: BES_TR5_four451_C | CA1: BES_TR5_four532_A | CB1: BES_TR5_four548_B | CC1: BES_TR5_four553_B | CD1: BES_TR5_four562_C | CE1: BES_TR5_four70_B | CF1: BES_TR5_four659_B | CG1: BES_TR5_four675_C | CH1: BES_TR5_four704_B | CI1: BES_TR5_four710_C | CJ1: BES_TR5_four734_A | CK1: BES_TR5_four763_A | CL1: BES_TR5_four797_C | CM1: BES_TR5_four840_A | CN1: BES_TR5_four854_A | CO1: BES_TR5_four926_B | CP1: BES_TR5_four958_C | CQ1: BES_TR5_four1027_A | CR1: BES_TR5_four1063_C | CS1: BES_TR5_four1091_B | CT1: BES_TR5_four1103_C | CU1: BES_TR5_four1132_C | CV1: BES_TR5_four1140_A | CW1: BES_TR5_four126_A | CX1: BES_TR5_four1187_A | CY1: BES_TR5_four1207_B | CZ1: BES_TR5_four1216_C | DA1: BES_TR5_four1220_C | DB1: BES_TR5_four1226_A | DC1: BES_TR5_four1244_B | DD1: BES_TR5_five58_dup_C | DE1: BES_TR5_five147_dup_C | DF1: BES_TR5_five149_A | DG1: BES_TR5_five149_dup_A | DH1: BES_TR5_five160_C | DI1: BES_TR5_five160_dup_C | DJ1: BES_TR5_five168_A | DK1: BES_TR5_five170_A | DL1: BES_TR5_five177_A | DM1: BES_TR5_five194_C | DN1: BES_TR5_five194_dup_C | DO1: BES_TR5_five220_C | DP1: BES_TR5_five220_dup_C | DQ1: BES_TR5_five223_dup_A | DR1: BES_TR5_five242_dup_A | DS1: BES_TR5_five243_dup_B | DT1: BES_TR5_five284_C | DU1: BES_TR5_five284_dup_C | DV1: BES_TR5_five285_B | DW1: BES_TR5_five309_C | DX1: BES_TR5_five324_B | DY1: BES_TR5_five345_A | DZ1: BES_TR5_five355_A | EA1: BES_TR5_five78_dup_A | EB1: BES_TR5_five394_C | EC1: BES_TR5_five421_A | ED1: BES_TR5_five421_dup_A | EE1: BES_TR5_five457_B | EF1: BES_TR5_five457_dup_B | EG1: BES_TR5_five466_A | EH1: BES_TR5_five472_dup_A | EI1: BES_TR5_five488_B | EJ1: BES_TR5_five488_dup_B | EK1: BES_TR5_five494_dup_B | EL1: BES_TR5_five512_A | EM1: BES_TR5_five513_dup_B | EN1: BES_TR5_five537_C | EO1: BES_TR5_five537_dup_C | EP1: BES_TR5_five540_A | EQ1: BES_TR5_five545_dup_B | ER1: BES_TR5_five585_dup_A | ES1: BES_TR5_five588_dup_A | ET1: BES_TR5_five108_B | EU1: BES_TR5_five108_dup_B | EV1: BES_TR5_five663_C | EW1: BES_TR5_five663_dup_C | EX1: BES_TR5_five670_C | EY1: BES_TR5_five670_dup_C | EZ1: BES_TR5_five685_dup_B | FA1: BES_TR5_five695_dup_A | FB1: BES_TR5_five704_dup_A | FC1: BES_TR5_five719_A | FD1: BES_TR5_five719_dup_A | FE1: BES_TR5_five735_A | FF1: BES_TR5_five748_dup_B | FG1: BES_TR5_five117_dup_B | FH1: BES_TR5_five750_B | FI1: BES_TR5_five750_dup_B | FJ1: BES_TR5_five778_dup_B | FK1: BES_TR5_five793_A | FL1: BES_TR5_five793_dup_A | FM1: BES_TR5_five799_dup_C | FN1: BES_TR5_five801_dup_C | FO1: BES_TR5_five118_B | FP1: BES_TR5_six64_A | FQ1: BES_TR5_six173_C | FR1: BES_TR5_six186_A | FS1: BES_TR5_six203_A | FT1: BES_TR5_six238_A | FU1: BES_TR5_six249_B | FV1: BES_TR5_six254_B | FW1: BES_TR5_six68_C | FX1: BES_TR5_six317_C | FY1: BES_TR5_six326_A | FZ1: BES_TR5_six342_A | GA1: BES_TR5_six350_B | GB1: BES_TR5_six75_A | GC1: BES_TR5_six385_B | GD1: BES_TR5_six387_A | GE1: BES_TR5_six392_C | GF1: BES_TR5_six431_C | GG1: BES_TR5_six441_A | GH1: BES_TR5_six512_B | GI1: BES_TR5_six518_B | GJ1: BES_TR5_six523_C | GK1: BES_TR5_six534_B | GL1: BES_TR5_six591_C | GM1: BES_TR5_six595_B | GN1: BES_TR5_six643_A | GO1: BES_TR5_six646_B | GP1: BES_TR5_six651_C | GQ1: BES_TR5_six87_A | GR1: BES_TR5_six665_B | GS1: BES_TR5_six718_C | GT1: BES_TR5_six721_A | GU1: BES_TR5_six723_B | GV1: BES_TR5_six740_A | GW1: BES_TR5_six799_B | GX1: BES_TR5_six807_A | GY1: BES_TR5_six852_B | GZ1: BES_TR5_six860_C | HA1: BES_TR5_six885_A | HB1: BES_TR5_six909_C | HC1: BES_TR5_six921_B | HD1: BES_TR5_six929_A | HE1: BES_TR5_six952_A | HF1: BES_TR5_six967_B | HG1: BES_TR5_six111_C | HH1: BES_TR5_six1006_C | HI1: fleet_average | HJ1: fleet_total
A2: 1 | B2: 0 | C2: 40 | D2: 40 | E2: 40 | F2: 40 | G2: 40 | H2: 40 | I2: 40 | J2: 40 | K2: 40 | L2: 40 | M2: 40 | N2: 40 | O2: 40 | P2: 40 | Q2: 40 | R2: 40 | S2: 40 | T2: 40 | U2: 40 | V2: 40 | W2: 40 | X2: 40 | Y2: 40 | Z2: 40 | AA2: 40 | AB2: 40 | AC2: 40 | AD2: 40 | AE2: 40 | AF2: 40 | AG2: 40 | AH2: 40 | AI2: 40 | AJ2: 40 | AK2: 40 | AL2: 40 | AM2: 40 | AN2: 40 | AO2: 40 | AP2: 40 | AQ2: 40 | AR2: 40 | AS2: 40 | AT2: 40 | AU2: 40 | AV2: 40 | AW2: 40 | AX2: 40 | AY2: 40 | AZ2: 40 | BA2: 40 | BB2: 40 | BC2: 40 | BD2: 40 | BE2: 40 | BF2: 40 | BG2: 40 | BH2: 40 | BI2: 40 | BJ2: 40 | BK2: 40 | BL2: 40 | BM2: 40 | BN2: 40 | BO2: 40 | BP2: 40 | BQ2: 40 | BR2: 40 | BS2: 40 | BT2: 40 | BU2: 40 | BV2: 40 | BW2: 40 | BX2: 40 | BY2: 40 | BZ2: 40 | CA2: 40 | CB2: 40 | CC2: 40 | CD2: 40 | CE2: 40 | CF2: 40 | CG2: 40 | CH2: 40 | CI2: 40 | CJ2: 40 | CK2: 40 | CL2: 40 | CM2: 40 | CN2: 40 | CO2: 40 | CP2: 40 | CQ2: 40 | CR2: 40 | CS2: 40 | CT2: 40 | CU2: 40 | CV2: 40 | CW2: 40 | CX2: 40 | CY2: 40 | CZ2: 40 | DA2: 40 | DB2: 40 | DC2: 40 | DD2: 40 | DE2: 40 | DF2: 40 | DG2: 40 | DH2: 40 | DI2: 40 | DJ2: 40 | DK2: 40 | DL2: 40 | DM2: 40 | DN2: 40 | DO2: 40 | DP2: 40 | DQ2: 40 | DR2: 40 | DS2: 40 | DT2: 40 | DU2: 40 | DV2: 40 | DW2: 40 | DX2: 40 | DY2: 40 | DZ2: 40 | EA2: 40 | EB2: 40 | EC2: 40 | ED2: 40 | EE2: 40 | EF2: 40 | EG2: 40 | EH2: 40 | EI2: 40 | EJ2: 40 | EK2: 40 | EL2: 40 | EM2: 40 | EN2: 40 | EO2: 40 | EP2: 40 | EQ2: 40 | ER2: 40 | ES2: 40 | ET2: 40 | EU2: 40 | EV2: 40 | EW2: 40 | EX2: 40 | EY2: 40 | EZ2: 40 | FA2: 40 | FB2: 40 | FC2: 40 | FD2: 40 | FE2: 40 | FF2: 40 | FG2: 40 | FH2: 40 | FI2: 40 | FJ2: 40 | FK2: 40 | FL2: 40 | FM2: 40 | FN2: 40 | FO2: 40 | FP2: 40 | FQ2: 40 | FR2: 40 | FS2: 40 | FT2: 40 | FU2: 40 | FV2: 40 | FW2: 40 | FX2: 40 | FY2: 40 | FZ2: 40 | GA2: 40 | GB2: 40 | GC2: 40 | GD2: 40 | GE2: 40 | GF2: 40 | GG2: 40 | GH2: 40 | GI2: 40 | GJ2: 40 | GK2: 40 | GL2: 40 | GM2: 40 | GN2: 40 | GO2: 40 | GP2: 40 | GQ2: 40 | GR2: 40 | GS2: 40 | GT2: 40 | GU2: 40 | GV2: 40 | GW2: 40 | GX2: 40 | GY2: 40 | GZ2: 40 | HA2: 40 | HB2: 40 | HC2: 40 | HD2: 40 | HE2: 40 | HF2: 40 | HG2: 40 | HH2: 40 | HI2: 40 | HJ2: 8560
A3: 2 | B3: 0.5 | C3: 37.0447 | D3: 30.4881 | E3: 37.8595 | F3: 36.3617 | G3: 38.4687 | H3: 35.2281 | I3: 39.2973 | J3: 37.9647 | K3: 39.3851 | L3: 36.5022 | M3: 31.2176 | N3: 37.9653 | O3: 38.0453 | P3: 39.36 | Q3: 37.5816 | R3: 39.4322 | S3: 38.1782 | T3: 37.9064 | U3: 38.7947 | V3: 30.8045 | W3: 37.683 | X3: 35.1203 | Y3: 39.36 | Z3: 38.9616 | AA3: 39.4228 | AB3: 38.2139 | AC3: 32.4194 | AD3: 38.5646 | AE3: 38.9399 | AF3: 14.5632 | AG3: 35.6448 | AH3: 33.5982 | AI3: 38.0821 | AJ3: 38.3638 | AK3: 32.5769 | AL3: 39.36 | AM3: 39.3851 | AN3: 31.415 | AO3: 38.3271 | AP3: 39.3851 | AQ3: 36.7228 | AR3: 38.3657 | AS3: 38.4749 | AT3: 38.9613 | AU3: 38.2542 | AV3: 37.6086 | AW3: 39.2596 | AX3: 35.0237 | AY3: 39.1788 | AZ3: 29.9727 | BA3: 39.3977 | BB3: 36.7629 | BC3: 39.36 | BD3: 38.719 | BE3: 38.1454 | BF3: 39.3098 | BG3: 28.217 | BH3: 33.3172 | BI3: 39.2596 | BJ3: 30.0378 | BK3: 39.3977 | BL3: 37.0714 | BM3: 10 | BN3: 36.8756 | BO3: 34.2015 | BP3: 36.2343 | BQ3: 36.9133 | BR3: 39.2847 | BS3: 38.1097 | BT3: 39.2847 | BU3: 38.0542 | BV3: 38.6864 | BW3: 39.3726 | BX3: 39.3726 | BY3: 39.3726 | BZ3: 39.3726 | CA3: 38.6243 | CB3: 26.7143 | CC3: 39.3475 | CD3: 37.0957 | CE3: 38.1827 | CF3: 39.36 | CG3: 29.1619 | CH3: 35.8216 | CI3: 39.4855 | CJ3: 39.3977 | CK3: 32.6149 | CL3: 39.3224 | CM3: 38.0586 | CN3: 23.1784 | CO3: 37.9135 | CP3: 35.2758 | CQ3: 37.3763 | CR3: 36.8599 | CS3: 39.3977 | CT3: 37.8218 | CU3: 39.3977 | CV3: 39.4479 | CW3: 37.0136 | CX3: 39.2973 | CY3: 38.1706 | CZ3: 38.3136 | DA3: 39.36 | DB3: 39.3851 | DC3: 36.9337 | DD3: 37.5168 | DE3: 37.4652 | DF3: 36.5467 | DG3: 34.4676 | DH3: 37.4761 | DI3: 39.3851 | DJ3: 38.9574 | DK3: 36.7725 | DL3: 38.5985 | DM3: 37.7669 | DN3: 39.2532 | DO3: 38.77 | DP3: 39.2566 | DQ3: 39.3112 | DR3: 38.1146 | DS3: 37.5813 | DT3: 38.6677 | DU3: 37.8916 | DV3: 37.4876 | DW3: 38.5532 | DX3: 39.4855 | DY3: 34.8496 | DZ3: 37.3337 | EA3: 38.1739 | EB3: 39.4228 | EC3: 39.0652 | ED3: 38.7329 | EE3: 38.6986 | EF3: 39.2973 | EG3: 37.0438 | EH3: 27.8949 | EI3: 35.9236 | EJ3: 39.3977 | EK3: 39.2382 | EL3: 37.7512 | EM3: 39.3977 | EN3: 37.3727 | EO3: 39.5483 | EP3: 39.3726 | EQ3: 38.5816 | ER3: 37.7521 | ES3: 39.3098 | ET3: 31.3844 | EU3: 37.0679 | EV3: 39.0583 | EW3: 38.4796 | EX3: 30.7076 | EY3: 37.9236 | EZ3: 38.767 | FA3: 37.9485 | FB3: 29.4721 | FC3: 37.6581 | FD3: 35.7565 | FE3: 38.6354 | FF3: 39.3475 | FG3: 39.2847 | FH3: 36.2963 | FI3: 31.9196 | FJ3: 38.4144 | FK3: 37.0595 | FL3: 35.9264 | FM3: 38.9725 | FN3: 39.36 | FO3: 39.4102 | FP3: 39.4373 | FQ3: 37.2237 | FR3: 37.5965 | FS3: 38.0809 | FT3: 39.2596 | FU3: 36.9995 | FV3: 35.8367 | FW3: 39.2722 | FX3: 38.9006 | FY3: 34.3168 | FZ3: 39.2723 | GA3: 38.0857 | GB3: 39.4102 | GC3: 33.6718 | GD3: 39.4981 | GE3: 39.2471 | GF3: 36.9533 | GG3: 33.8621 | GH3: 36.6367 | GI3: 39.3475 | GJ3: 38.4661 | GK3: 37.6437 | GL3: 37.8816 | GM3: 39.4604 | GN3: 38.7246 | GO3: 37.5098 | GP3: 38.6487 | GQ3: 39.5483 | GR3: 39.3349 | GS3: 38.0465 | GT3: 39.3349 | GU3: 39.4102 | GV3: 38.298 | GW3: 38.37 | GX3: 38.4415 | GY3: 39.2973 | GZ3: 39.4855 | HA3: 38.5025 | HB3: 36.8068 | HC3: 38.0164 | HD3: 38.1191 | HE3: 27.879 | HF3: 39.2722 | HG3: 38.8644 | HH3: 39.3851 | HI3: 37.156752 | HJ3: 7951.545
A4: 3 | B4: 1 | C4: 36.3922 | D4: 22.612 | E4: 35.4982 | F4: 35.6066 | G4: 37.8663 | H4: 34.7638 | I4: 35.6444 | J4: 35.5225 | K4: 34.3641 | L4: 34.9966 | M4: 23.7096 | N4: 37.1205 | O4: 36.7612 | P4: 38.7201 | Q4: 35.8579 | R4: 38.3677 | S4: 37.6637 | T4: 34.2722 | U4: 36.668 | V4: 30.1143 | W4: 37.0305 | X4: 34.6685 | Y4: 34.0091 | Z4: 35.1909 | AA4: 38.8455 | AB4: 37.5991 | AC4: 26.4254 | AD4: 37.8995 | AE4: 36.4532 | AF4: 10 | AG4: 32.2152 | AH4: 32.8955 | AI4: 35.6961 | AJ4: 37.1587 | AK4: 27.8778 | AL4: 37.0634 | AM4: 38.7702 | AN4: 30.888 | AO4: 37.6369 | AP4: 37.8341 | AQ4: 35.6094 | AR4: 35.4193 | AS4: 34.1701 | AT4: 35.8909 | AU4: 37.3778 | AV4: 35.6394 | AW4: 38.5193 | AX4: 34.4214 | AY4: 38.0294 | AZ4: 25.9803 | BA4: 38.1715 | BB4: 36.0312 | BC4: 38.0119 | BD4: 37.7586 | BE4: 36.8667 | BF4: 37.1708 | BG4: 18.1385 | BH4: 27.5124 | BI4: 37.8232 | BJ4: 29.3226 | BK4: 38.7953 | BL4: 33.1301 | BM4: 10 | BN4: 35.9203 | BO4: 27.5185 | BP4: 35.5817 | BQ4: 35.1135 | BR4: 38.5695 | BS4: 35.1455 | BT4: 38.5695 | BU4: 37.3641 | BV4: 37.3728 | BW4: 37.718 | BX4: 37.7055 | BY4: 36.5924 | BZ4: 37.5988 | CA4: 36.2475 | CB4: 16.4456 | CC4: 38.695 | CD4: 36.4682 | CE4: 37.6055 | CF4: 37.7742 | CG4: 27.8708 | CH4: 34.4453 | CI4: 36.8083 | CJ4: 37.8064 | CK4: 25.3476 | CL4: 38.6448 | CM4: 36.0781 | CN4: 10 | CO4: 36.0249 | CP4: 23.8551 | CQ4: 36.7237 | CR4: 35.8409 | CS4: 38.7953 | CT4: 36.8302 | CU4: 38.7953 | CV4: 38.8957 | CW4: 34.9469 | CX4: 38.5946 | CY4: 36.4191 | CZ4: 35.8776 | DA4: 38.1099 | DB4: 38.7702 | DC4: 32.6723 | DD4: 34.6349 | DE4: 36.6638 | DF4: 35.8189 | DG4: 26.395 | DH4: 34.8506 | DI4: 37.7525 | DJ4: 38.0043 | DK4: 35.093 | DL4: 36.1572 | DM4: 35.2503 | DN4: 38.7512 | DO4: 38.2304 | DP4: 37.7012 | DQ4: 37.8674 | DR4: 35.8986 | DS4: 36.9538 | DT4: 36.5441 | DU4: 35.9666 | DV4: 36.8476 | DW4: 32.9775 | DX4: 37.0725 | DY4: 32.6296 | DZ4: 36.0101 | EA4: 36.6086 | EB4: 38.8455 | EC4: 35.7129 | ED4: 36.7779 | EE4: 36.6268 | EF4: 36.6146 | EG4: 34.8031 | EH4: 16.3832 | EI4: 29.8822 | EJ4: 38.6103 | EK4: 37.5567 | EL4: 36.2492 | EM4: 38.7953 | EN4: 36.4161 | EO4: 37.2193 | EP4: 37.0653 | EQ4: 38.0671 | ER4: 37.2376 | ES4: 37.2042 | ET4: 30.4317 | EU4: 36.4109 | EV4: 37.1736 | EW4: 37.8397 | EX4: 29.1983 | EY4: 37.3088 | EZ4: 32.4284 | FA4: 36.9269 | FB4: 17.3671 | FC4: 35.5016 | FD4: 32.9373 | FE4: 37.9327 | FF4: 38.695 | FG4: 38.5695 | FH4: 35.832 | FI4: 25.0212 | FJ4: 37.6782 | FK4: 35.6795 | FL4: 35.2864 | FM4: 36.6764 | FN4: 37.2867 | FO4: 38.6185 | FP4: 32.5687 | FQ4: 32.793 | FR4: 36.048 | FS4: 34.7231 | FT4: 38.5193 | FU4: 33.4061 | FV4: 33.5649 | FW4: 37.3419 | FX4: 35.7841 | FY4: 25.2677 | FZ4: 36.5695 | GA4: 36.8309 | GB4: 37.9934 | GC4: 30.4667 | GD4: 38.9961 | GE4: 38.4942 | GF4: 34.8757 | GG4: 26.8038 | GH4: 35.9967 | GI4: 38.695 | GJ4: 37.2263 | GK4: 36.4719 | GL4: 37.1538 | GM4: 36.9528 | GN4: 38.1223 | GO4: 36.211 | GP4: 35.9138 | GQ4: 37.5749 | GR4: 37.1291 | GS4: 34.6771 | GT4: 38.6699 | GU4: 38.1366 | GV4: 36.8148 | GW4: 35.2492 | GX4: 37.044 | GY4: 36.4567 | GZ4: 36.9695 | HA4: 37.9127 | HB4: 36.0915 | HC4: 36.5009 | HD4: 34.9525 | HE4: 18.9814 | HF4: 37.3916 | HG4: 36.0462 | HH4: 38.7702 | HI4: 34.866054 | HJ4: 7461.3356
A5: 4 | B5: 1.5 | C5: 34.3789 | D5: 12.8631 | E5: 34.0499 | F5: 31.0714 | G5: 36.335 | H5: 34.2995 | I5: 34.9416 | J5: 34.8198 | K5: 33.1385 | L5: 32.9147 | M5: 14.9028 | N5: 35.5958 | O5: 35.7866 | P5: 38.0801 | Q5: 35.2932 | R5: 36.2602 | S5: 34.9509 | T5: 32.6897 | U5: 36.0155 | V5: 29.4241 | W5: 35.2961 | X5: 33.8433 | Y5: 28.9651 | Z5: 33.6818 | AA5: 38.2683 | AB5: 36.9842 | AC5: 25.7352 | AD5: 35.9505 | AE5: 34.8386 | AF5: 10 | AG5: 31.6631 | AH5: 32.1927 | AI5: 35.0562 | AJ5: 35.0745 | AK5: 22.2512 | AL5: 36.4234 | AM5: 38.1554 | AN5: 28.6862 | AO5: 36.7283 | AP5: 36.6991 | AQ5: 34.5536 | AR5: 34.0325 | AS5: 33.5552 | AT5: 33.4065 | AU5: 36.6876 | AV5: 35.1249 | AW5: 35.5627 | AX5: 31.5928 | AY5: 34.5956 | AZ5: 22.678 | BA5: 36.4774 | BB5: 33.0672 | BC5: 36.7926 | BD5: 37.1186 | BE5: 33.9116 | BF5: 36.0544 | BG5: 10 | BH5: 26.3419 | BI5: 34.441 | BJ5: 28.6073 | BK5: 38.193 | BL5: 32.3772 | BM5: 10 | BN5: 33.2328 | BO5: 24.8084 | BP5: 34.9292 | BQ5: 34.4107 | BR5: 37.8542 | BS5: 34.2825 | BT5: 37.8542 | BU5: 36.6739 | BV5: 36.8206 | BW5: 36.8338 | BX5: 36.5499 | BY5: 34.4367 | BZ5: 36.9713 | CA5: 35.5574 | CB5: 15.768 | CC5: 38.0424 | CD5: 35.8408 | CE5: 37.0283 | CF5: 35.0269 | CG5: 25.6458 | CH5: 32.8145 | CI5: 34.6177 | CJ5: 36.2151 | CK5: 15.9252 | CL5: 37.887 | CM5: 34.0694 | CN5: 10 | CO5: 35.2246 | CP5: 10 | CQ5: 36.0712 | CR5: 35.1256 | CS5: 36.2976 | CT5: 35.9234 | CU5: 38.193 | CV5: 38.3436 | CW5: 33.277 | CX5: 37.8919 | CY5: 34.5898 | CZ5: 34.8898 | DA5: 36.1625 | DB5: 37.1983 | DC5: 28.4666 | DD5: 31.4689 | DE5: 34.2972 | DF5: 31.7513 | DG5: 18.054 | DH5: 34.2232 | DI5: 37.1377 | DJ5: 36.8722 | DK5: 32.2384 | DL5: 35.4168 | DM5: 34.1136 | DN5: 38.2493 | DO5: 34.564 | DP5: 37.0738 | DQ5: 35.4087 | DR5: 33.2297 | DS5: 36.3264 | DT5: 34.8603 | DU5: 32.7287 | DV5: 35.5267 | DW5: 28.4889 | DX5: 36.558 | DY5: 31.5161 | DZ5: 31.688 | EA5: 34.7922 | EB5: 38.2683 | EC5: 34.9613 | ED5: 36.1128 | EE5: 35.9994 | EF5: 35.7263 | EG5: 31.2888 | EH5: 11.2623 | EI5: 28.4587 | EJ5: 36.157 | EK5: 34.7261 | EL5: 35.1567 | EM5: 35.0472 | EN5: 35.4498 | EO5: 36.7676 | EP5: 36.4379 | EQ5: 37.5526 | ER5: 35.3836 | ES5: 36.4395 | ET5: 29.3518 | EU5: 33.2941 | EV5: 36.5462 | EW5: 35.5368 | EX5: 28.4705 | EY5: 34.9745 | EZ5: 28.0379 | FA5: 33.4764 | FB5: 13.6398 | FC5: 33.7295 | FD5: 32.3098 | FE5: 37.23 | FF5: 38.0424 | FG5: 36.53 | FH5: 35.3677 | FI5: 23.4525 | FJ5: 36.5173 | FK5: 33.4699 | FL5: 34.3709 | FM5: 36.0113 | FN5: 35.8276 | FO5: 37.3218 | FP5: 32.1169 | FQ5: 32.1656 | FR5: 35.3453 | FS5: 33.675 | FT5: 35.4138 | FU5: 28.8595 | FV5: 32.1144 | FW5: 36.6141 | FX5: 33.0783 | FY5: 24.6528 | FZ5: 34.8142 | GA5: 36.1533 | GB5: 35.1963 | GC5: 29.5416 | GD5: 35.4887 | GE5: 37.5377 | GF5: 33.3967 | GG5: 24.0296 | GH5: 35.1755 | GI5: 38.0424 | GJ5: 36.3178 | GK5: 35.4817 | GL5: 31.8227 | GM5: 34.6809 | GN5: 37.52 | GO5: 34.8502 | GP5: 34.0164 | GQ5: 36.4131 | GR5: 36.464 | GS5: 34.0873 | GT5: 38.0048 | GU5: 36.3462 | GV5: 35.5545 | GW5: 34.6344 | GX5: 34.1801 | GY5: 35.754 | GZ5: 36.455 | HA5: 36.0262 | HB5: 33.2219 | HC5: 35.4523 | HD5: 33.3239 | HE5: 10 | HF5: 35.2713 | HG5: 35.5192 | HH5: 38.1554 | HI5: 33.044306 | HJ5: 7071.4814
A6: 5 | B6: 2 | C6: 32.7844 | D6: 10 | E6: 32.6015 | F6: 30.582 | G6: 35.7327 | H6: 33.8352 | I6: 34.2389 | J6: 31.534 | K6: 31.1077 | L6: 30.1671 | M6: 10.4969 | N6: 34.2411 | O6: 35.1466 | P6: 37.4401 | Q6: 32.847 | R6: 35.8712 | S6: 33.4764 | T6: 30.4967 | U6: 35.3629 | V6: 26.785 | W6: 34.061 | X6: 30.3263 | Y6: 24.6113 | Z6: 31.3471 | AA6: 37.6911 | AB6: 36.3693 | AC6: 25.0451 | AD6: 34.6863 | AE6: 34.0658 | AF6: 10 | AG6: 31.1109 | AH6: 31.49 | AI6: 31.9491 | AJ6: 34.0583 | AK6: 19.6539 | AL6: 35.7834 | AM6: 37.5405 | AN6: 14.2989 | AO6: 35.2738 | AP6: 36.0842 | AQ6: 33.2674 | AR6: 32.1478 | AS6: 32.4813 | AT6: 30.4278 | AU6: 35.066 | AV6: 31.8992 | AW6: 34.8224 | AX6: 30.9905 | AY6: 34.0309 | AZ6: 20.156 | BA6: 35.7192 | BB6: 32.0625 | BC6: 35.8308 | BD6: 36.4786 | BE6: 32.7161 | BF6: 34.4268 | BG6: 10 | BH6: 23.3958 | BI6: 33.5061 | BJ6: 27.892 | BK6: 37.5907 | BL6: 29.1664 | BM6: 10 | BN6: 31.7686 | BO6: 22.603 | BP6: 32.5213 | BQ6: 29.752 | BR6: 37.1389 | BS6: 32.1859 | BT6: 37.1389 | BU6: 34.7281 | BV6: 35.0917 | BW6: 36.2063 | BX6: 35.2935 | BY6: 33.8093 | BZ6: 36.3439 | CA6: 33.4388 | CB6: 14.9038 | CC6: 37.3899 | CD6: 32.9365 | CE6: 36.4511 | CF6: 34.3869 | CG6: 24.9306 | CH6: 30.2066 | CI6: 33.2184 | CJ6: 35.5229 | CK6: 10 | CL6: 35.687 | CM6: 32.8645 | CN6: 10 | CO6: 33.9295 | CP6: 10 | CQ6: 34.2539 | CR6: 30.352 | CS6: 35.605 | CT6: 33.6604 | CU6: 37.5907 | CV6: 36.2085 | CW6: 31.2734 | CX6: 37.1891 | CY6: 33.0193 | CZ6: 32.4827 | DA6: 35.5225 | DB6: 36.5835 | DC6: 25.8244 | DD6: 28.4375 | DE6: 33.6698 | DF6: 30.053 | DG6: 10 | DH6: 31.0689 | DI6: 36.5228 | DJ6: 35.8108 | DK6: 29.3211 | DL6: 34.2945 | DM6: 29.5732 | DN6: 37.7473 | DO6: 33.8054 | DP6: 36.4464 | DQ6: 34.4644 | DR6: 30.9195 | DS6: 35.699 | DT6: 34.2203 | DU6: 32.1264 | DV6: 33.6952 | DW6: 27.4021 | DX6: 35.3532 | DY6: 30.8636 | DZ6: 29.6685 | EA6: 34.084 | EB6: 37.6911 | EC6: 34.3041 | ED6: 35.4477 | EE6: 34.6979 | EF6: 35.0235 | EG6: 29.6864 | EH6: 10.1112 | EI6: 26.7229 | EJ6: 35.5547 | EK6: 33.0446 | EL6: 33.1307 | EM6: 33.1741 | EN6: 34.0414 | EO6: 36.3159 | EP6: 35.8104 | EQ6: 36.787 | ER6: 34.4752 | ES6: 35.7493 | ET6: 26.9567 | EU6: 30.9215 | EV6: 34.3472 | EW6: 33.6265 | EX6: 27.2016 | EY6: 34.1877 | EZ6: 19.3666 | FA6: 32.8239 | FB6: 10.1407 | FC6: 31.4892 | FD6: 31.6824 | FE6: 36.5273 | FF6: 37.3899 | FG6: 35.8147 | FH6: 34.9034 | FI6: 21.6377 | FJ6: 35.3565 | FK6: 31.7126 | FL6: 30.5506 | FM6: 34.9838 | FN6: 35.1877 | FO6: 36.732 | FP6: 31.6652 | FQ6: 30.0614 | FR6: 34.6425 | FS6: 32.2107 | FT6: 29.2028 | FU6: 24.5125 | FV6: 27.7388 | FW6: 35.6191 | FX6: 30.4006 | FY6: 23.1792 | FZ6: 32.9501 | GA6: 33.9092 | GB6: 34.6066 | GC6: 27.6374 | GD6: 34.7369 | GE6: 35.6309 | GF6: 29.6556 | GG6: 23.007 | GH6: 32.7229 | GI6: 37.3899 | GJ6: 34.9124 | GK6: 32.443 | GL6: 31.0949 | GM6: 33.5344 | GN6: 34.8023 | GO6: 32.5362 | GP6: 32.3282 | GQ6: 35.5556 | GR6: 35.799 | GS6: 30.3741 | GT6: 37.3397 | GU6: 35.5436 | GV6: 32.8044 | GW6: 32.5151 | GX6: 33.4221 | GY6: 34.6626 | GZ6: 34.7579 | HA6: 35.4364 | HB6: 31.6785 | HC6: 33.5129 | HD6: 29.3212 | HE6: 10 | HF6: 34.5435 | HG6: 33.4946 | HH6: 37.5405 | HI6: 31.384434 | HJ6: 6716.2689
A7: 6 | B7: 2.5 | C7: 32.1319 | D7: 10 | E7: 30.3941 | F7: 29.2956 | G7: 35.1303 | H7: 33.3709 | I7: 32.0914 | J7: 30.3423 | K7: 28.2738 | L7: 29.4769 | M7: 10 | N7: 33.6513 | O7: 34.5066 | P7: 36.8001 | Q7: 29.8257 | R7: 33.0882 | S7: 31.9923 | T7: 27.7588 | U7: 32.6834 | V7: 26.0949 | W7: 32.6595 | X7: 29.8746 | Y7: 23.9713 | Z7: 28.0287 | AA7: 37.1138 | AB7: 35.7544 | AC7: 24.3549 | AD7: 33.7645 | AE7: 33.1728 | AF7: 10 | AG7: 30.5588 | AH7: 30.7873 | AI7: 30.7523 | AJ7: 31.53 | AK7: 17.5178 | AL7: 34.3151 | AM7: 36.9256 | AN7: 13.5805 | AO7: 34.5836 | AP7: 34.0131 | AQ7: 32.3222 | AR7: 30.9202 | AS7: 29.0106 | AT7: 27.478 | AU7: 34.0654 | AV7: 31.3847 | AW7: 32.3695 | AX7: 28.7691 | AY7: 30.4567 | AZ7: 19.0372 | BA7: 33.5572 | BB7: 31.1063 | BC7: 34.2252 | BD7: 35.8387 | BE7: 30.0962 | BF7: 32.7991 | BG7: 10 | BH7: 22.7934 | BI7: 32.7657 | BJ7: 27.1768 | BK7: 36.9884 | BL7: 27.3721 | BM7: 10 | BN7: 29.3088 | BO7: 21.1155 | BP7: 30.511 | BQ7: 28.5743 | BR7: 36.4237 | BS7: 29.2175 | BT7: 36.4237 | BU7: 34.038 | BV7: 34.1934 | BW7: 35.5789 | BX7: 33.4532 | BY7: 31.1269 | BZ7: 35.7165 | CA7: 30.9029 | CB7: 13.2933 | CC7: 36.7374 | CD7: 32.3091 | CE7: 34.9674 | CF7: 33.4316 | CG7: 23.7877 | CH7: 29.0276 | CI7: 31.426 | CJ7: 33.0325 | CK7: 10 | CL7: 35.0094 | CM7: 31.2381 | CN7: 10 | CO7: 31.9178 | CP7: 10 | CQ7: 32.795 | CR7: 29.6367 | CS7: 33.197 | CT7: 33.0079 | CU7: 36.9884 | CV7: 33.9696 | CW7: 30.2438 | CX7: 36.4864 | CY7: 31.7574 | CZ7: 30.4071 | DA7: 32.965 | DB7: 35.9686 | DC7: 17.0091 | DD7: 24.8871 | DE7: 31.6511 | DF7: 28.4791 | DG7: 10 | DH7: 27.3724 | DI7: 34.8902 | DJ7: 33.2458 | DK7: 26.5626 | DL7: 31.253 | DM7: 27.4737 | DN7: 35.8577 | DO7: 32.4939 | DP7: 34.2778 | DQ7: 32.9985 | DR7: 29.0986 | DS7: 34.4202 | DT7: 32.5365 | DU7: 28.5078 | DV7: 33.0552 | DW7: 24.7648 | DX7: 33.6305 | DY7: 28.6436 | DZ7: 26.5274 | EA7: 31.4105 | EB7: 37.1138 | EC7: 30.4872 | ED7: 34.7827 | EE7: 32.6262 | EF7: 34.228 | EG7: 26.8823 | EH7: 10 | EI7: 24.6007 | EJ7: 34.9524 | EK7: 31.4588 | EL7: 32.293 | EM7: 32.5718 | EN7: 32.2579 | EO7: 35.4375 | EP7: 35.183 | EQ7: 35.6197 | ER7: 33.9607 | ES7: 32.8298 | ET7: 26.3042 | EU7: 29.6086 | EV7: 33.7197 | EW7: 32.9866 | EX7: 25.9327 | EY7: 33.5728 | EZ7: 18.6786 | FA7: 30.2339 | FB7: 10 | FC7: 30.7865 | FD7: 31.055 | FE7: 35.8245 | FF7: 36.7374 | FG7: 34.059 | FH7: 34.4391 | FI7: 21.0103 | FJ7: 34.7416 | FK7: 30.4681 | FL7: 29.6574 | FM7: 32.6877 | FN7: 32.2953 | FO7: 35.3849 | FP7: 31.2135 | FQ7: 27.8856 | FR7: 33.9398 | FS7: 31.4957 | FT7: 28.4625 | FU7: 20.9052 | FV7: 26.5274 | FW7: 33.956 | FX7: 29.0576 | FY7: 20.9577 | FZ7: 31.0624 | GA7: 32.9842 | GB7: 32.0659 | GC7: 26.7123 | GD7: 34.235 | GE7: 34.878 | GF7: 28.8253 | GG7: 20.5579 | GH7: 32.0829 | GI7: 36.7374 | GJ7: 32.9468 | GK7: 31.5029 | GL7: 26.7601 | GM7: 30.9959 | GN7: 34.2 | GO7: 30.7807 | GP7: 30.9025 | GQ7: 33.278 | GR7: 33.5931 | GS7: 28.7645 | GT7: 36.6746 | GU7: 33.8142 | GV7: 31.6989 | GW7: 29.0029 | GX7: 31.6988 | GY7: 32.2107 | GZ7: 33.4246 | HA7: 34.8466 | HB7: 30.9633 | HC7: 31.9235 | HD7: 26.7474 | HE7: 10 | HF7: 31.2704 | HG7: 31.5654 | HH7: 36.9256 | HI7: 29.908575 | HJ7: 6400.4351
A8: 7 | B8: 3 | C8: 30.956 | D8: 10 | E8: 29.7918 | F8: 25.9567 | G8: 34.1667 | H8: 32.9066 | I8: 30.9638 | J8: 28.4295 | K8: 26.0748 | L8: 28.2648 | M8: 10 | N8: 33.0615 | O8: 33.8666 | P8: 36.1602 | Q8: 29.0522 | R8: 32.6992 | S8: 29.2891 | T8: 25.808 | U8: 32.0309 | V8: 25.1389 | W8: 31.0916 | X8: 26.7253 | Y8: 22.6113 | Z8: 27.3636 | AA8: 36.5366 | AB8: 35.1395 | AC8: 23.6647 | AD8: 31.4731 | AE8: 31.6785 | AF8: 10 | AG8: 30.0067 | AH8: 30.0846 | AI8: 30.1123 | AJ8: 29.8016 | AK8: 16.7195 | AL8: 32.8468 | AM8: 36.3107 | AN8: 11.1394 | AO8: 32.9107 | AP8: 33.3982 | AQ8: 29.8162 | AR8: 29.9391 | AS8: 28.3957 | AT8: 25.692 | AU8: 32.5059 | AV8: 30.8703 | AW8: 31.1255 | AX8: 27.5597 | AY8: 29.4477 | AZ8: 15.706 | BA8: 32.9549 | BB8: 28.0937 | BC8: 33.5852 | BD8: 34.3441 | BE8: 27.955 | BF8: 32.1089 | BG8: 10 | BH8: 21.2889 | BI8: 32.0254 | BJ8: 26.4615 | BK8: 36.386 | BL8: 25.1815 | BM8: 10 | BN8: 27.7556 | BO8: 19.9144 | BP8: 29.1464 | BQ8: 26.0473 | BR8: 35.7084 | BS8: 28.565 | BT8: 35.7084 | BU8: 32.0922 | BV8: 33.6413 | BW8: 33.6675 | BX8: 32.8258 | BY8: 29.3319 | BZ8: 35.0891 | CA8: 29.7351 | CB8: 12.6157 | CC8: 36.0849 | CD8: 31.2676 | CE8: 34.3902 | CF8: 31.9719 | CG8: 21.8943 | CH8: 25.9009 | CI8: 29.5706 | CJ8: 32.4302 | CK8: 10 | CL8: 32.7292 | CM8: 28.3229 | CN8: 10 | CO8: 29.7573 | CP8: 10 | CQ8: 31.784 | CR8: 27.3607 | CS8: 29.7619 | CT8: 30.7449 | CU8: 36.386 | CV8: 33.0038 | CW8: 28.7849 | CX8: 35.7837 | CY8: 30.3438 | CZ8: 29.5305 | DA8: 32.325 | DB8: 35.3537 | DC8: 15.8074 | DD8: 22.6476 | DE8: 30.5019 | DF8: 25.6812 | DG8: 10 | DH8: 26.5448 | DI8: 34.2753 | DJ8: 32.2926 | DK8: 25.7261 | DL8: 30.3426 | DM8: 26.8337 | DN8: 34.9476 | DO8: 29.8083 | DP8: 32.0371 | DQ8: 31.1153 | DR8: 27.4661 | DS8: 32.6528 | DT8: 30.8085 | DU8: 27.9055 | DV8: 30.5427 | DW8: 23.395 | DX8: 33.116 | DY8: 27.5301 | DZ8: 23.9456 | EA8: 30.9085 | EB8: 36.5366 | EC8: 29.9225 | ED8: 33.3436 | EE8: 31.9987 | EF8: 31.4525 | EG8: 26.3224 | EH8: 10 | EI8: 23.7807 | EJ8: 32.314 | EK8: 28.9266 | EL8: 30.3817 | EM8: 28.5218 | EN8: 31.6932 | EO8: 33.5352 | EP8: 34.5556 | EQ8: 35.1052 | ER8: 31.7128 | ES8: 31.2525 | ET8: 23.4817 | EU8: 27.1476 | EV8: 31.5207 | EW8: 29.4568 | EX8: 25.2049 | EY8: 32.786 | EZ8: 18.1766 | FA8: 29.2454 | FB8: 10 | FC8: 30.0838 | FD8: 30.4276 | FE8: 35.1218 | FF8: 35.6694 | FG8: 33.06 | FH8: 33.9748 | FI8: 19.6268 | FJ8: 34.1267 | FK8: 28.198 | FL8: 27.7315 | FM8: 32.0226 | FN8: 31.6553 | FO8: 34.6436 | FP8: 30.7617 | FQ8: 27.1249 | FR8: 32.3415 | FS8: 27.999 | FT8: 27.7221 | FU8: 18.5986 | FV8: 24.1849 | FW8: 33.2282 | FX8: 26.1428 | FY8: 20.3429 | FZ8: 30.4978 | GA8: 32.3066 | GB8: 30.3927 | GC8: 25.997 | GD8: 30.8794 | GE8: 32.7677 | GF8: 26.3283 | GG8: 18.8492 | GH8: 29.4491 | GI8: 36.0849 | GJ8: 31.3757 | GK8: 30.2623 | GL8: 24.9189 | GM8: 28.1884 | GN8: 32.3477 | GO8: 30.0529 | GP8: 27.6959 | GQ8: 32.8263 | GR8: 32.928 | GS8: 28.1747 | GT8: 36.0096 | GU8: 33.2244 | GV8: 29.1313 | GW8: 27.479 | GX8: 29.2034 | GY8: 31.508 | GZ8: 32.9101 | HA8: 32.9601 | HB8: 30.248 | HC8: 30.6264 | HD8: 25.3156 | HE8: 10 | HF8: 30.5426 | HG8: 31.0384 | HH8: 36.3107 | HI8: 28.606679 | HJ8: 6121.8294
A9: 8 | B9: 3.5 | C9: 28.524 | D9: 10 | E9: 25.8923 | F9: 24.8023 | G9: 32.9967 | H9: 32.4424 | I9: 29.1806 | J9: 25.8648 | K9: 23.0358 | L9: 25.1412 | M9: 10 | N9: 31.5368 | O9: 33.2267 | P9: 35.5202 | Q9: 25.873 | R9: 31.1778 | S9: 28.7746 | T9: 25.0001 | U9: 31.3784 | V9: 22.7656 | W9: 30.439 | X9: 25.5324 | Y9: 20.7113 | Z9: 22.3756 | AA9: 35.9594 | AB9: 34.5247 | AC9: 22.9745 | AD9: 30.8081 | AE9: 30.6652 | AF9: 10 | AG9: 29.4545 | AH9: 29.3819 | AI9: 27.3674 | AJ9: 28.6887 | AK9: 12.2758 | AL9: 31.9056 | AM9: 35.6959 | AN9: 10.6123 | AO9: 32.2205 | AP9: 32.5753 | AQ9: 28.1267 | AR9: 26.1763 | AS9: 25.4188 | AT9: 22.6994 | AU9: 31.4432 | AV9: 27.6446 | AW9: 29.4785 | AX9: 26.9573 | AY9: 27.8998 | AZ9: 13.7042 | BA9: 31.0269 | BB9: 27.5415 | BC9: 32.9452 | BD9: 33.5973 | BE9: 27.3526 | BF9: 30.6517 | BG9: 10 | BH9: 18.6768 | BI9: 28.379 | BJ9: 25.7462 | BK9: 35.7837 | BL9: 21.484 | BM9: 10 | BN9: 26.8466 | BO9: 17.691 | BP9: 27.9598 | BQ9: 22.7379 | BR9: 34.9931 | BS9: 25.6263 | BT9: 34.9931 | BU9: 31.402 | BV9: 32.0507 | BW9: 33.0401 | BX9: 31.6786 | BY9: 28.1481 | BZ9: 34.4616 | CA9: 26.2484 | CB9: 10.8187 | CC9: 35.4323 | CD9: 28.7773 | CE9: 33.8129 | CF9: 29.4137 | CG9: 20.2716 | CH9: 20.9661 | CI9: 26.5582 | CJ9: 30.0297 | CK9: 10 | CL9: 32.0516 | CM9: 27.6703 | CN9: 10 | CO9: 28.4127 | CP9: 10 | CQ9: 29.5187 | CR9: 24.3301 | CS9: 26.983 | CT9: 29.8381 | CU9: 35.7837 | CV9: 29.5956 | CW9: 26.7777 | CX9: 35.081 | CY9: 29.6788 | CZ9: 27.4559 | DA9: 30.2033 | DB9: 34.154 | DC9: 13.2767 | DD9: 20.4989 | DE9: 29.8745 | DF9: 24.5351 | DG9: 10 | DH9: 22.2664 | DI9: 33.6604 | DJ9: 31.3395 | DK9: 23.7437 | DL9: 28.8368 | DM9: 23.141 | DN9: 33.9558 | DO9: 27.297 | DP9: 31.4096 | DQ9: 29.6176 | DR9: 25.2502 | DS9: 31.944 | DT9: 28.0368 | DU9: 27.3031 | DV9: 29.9028 | DW9: 22.3419 | DX9: 32.6016 | DY9: 26.8776 | DZ9: 22.1912 | EA9: 29.4785 | EB9: 35.9594 | EC9: 29.3579 | ED9: 31.5605 | EE9: 29.253 | EF9: 30.7498 | EG9: 23.75 | EH9: 10 | EI9: 22.0247 | EJ9: 31.7117 | EK9: 27.5736 | EL9: 28.5845 | EM9: 27.5965 | EN9: 29.0659 | EO9: 33.0834 | EP9: 33.9282 | EQ9: 34.5907 | ER9: 31.1983 | ES9: 30.5623 | ET9: 22.7864 | EU9: 24.7751 | EV9: 30.8933 | EW9: 28.7734 | EX9: 23.395 | EY9: 30.4517 | EZ9: 15.2467 | FA9: 26.3154 | FB9: 10 | FC9: 25.9964 | FD9: 29.8001 | FE9: 34.4191 | FF9: 35.0168 | FG9: 32.3447 | FH9: 33.5105 | FI9: 17.6269 | FJ9: 32.4198 | FK9: 26.0948 | FL9: 25.0059 | FM9: 29.9077 | FN9: 31.0153 | FO9: 34.0539 | FP9: 29.3111 | FQ9: 24.144 | FR9: 31.6388 | FS9: 26.9052 | FT9: 26.9817 | FU9: 15.9605 | FV9: 20.0923 | FW9: 31.6319 | FX9: 24.364 | FY9: 19.0106 | FZ9: 27.3485 | GA9: 31.1343 | GB9: 28.7921 | GC9: 25.2817 | GD9: 29.9758 | GE9: 32.0148 | GF9: 23.0145 | GG9: 17.6007 | GH9: 28.8092 | GI9: 35.4323 | GJ9: 30.7985 | GK9: 27.5241 | GL9: 22.8897 | GM9: 23.9242 | GN9: 30.88 | GO9: 27.163 | GP9: 26.2323 | GQ9: 30.6501 | GR9: 32.263 | GS9: 25.5116 | GT9: 35.3445 | GU9: 32.6346 | GV9: 27.8432 | GW9: 24.5702 | GX9: 28.4881 | GY9: 28.7646 | GZ9: 30.3941 | HA9: 32.3703 | HB9: 27.8733 | HC9: 26.1967 | HD9: 20.8094 | HE9: 10 | HF9: 27.9182 | HG9: 27.7986 | HH9: 35.6959 | HI9: 27.034064 | HJ9: 5785.2896
A10: 9 | B10: 4 | C10: 27.8985 | D10: 10 | E10: 25.3331 | F10: 21.2029 | G10: 32.4159 | H10: 31.9942 | I10: 28.5102 | J10: 24.8029 | K10: 20.0413 | L10: 23.6525 | M10: 10 | N10: 30.2144 | O10: 32.6029 | P10: 34.9234 | Q10: 23.8097 | R10: 30.6432 | S10: 28.3033 | T10: 22.7662 | U10: 29.8315 | V10: 22.1078 | W10: 28.482 | X10: 23.7328 | Y10: 20.0137 | Z10: 21.7483 | AA10: 35.4199 | AB10: 33.926 | AC10: 22.3114 | AD10: 28.5383 | AE10: 16.8389 | AF10: 10 | AG10: 28.9456 | AH10: 28.7115 | AI10: 25.8463 | AJ10: 26.1202 | AK10: 10 | AL10: 29.9534 | AM10: 35.1242 | AN10: 10 | AO10: 31.5573 | AP10: 30.7284 | AQ10: 27.5173 | AR10: 25.5508 | AS10: 23.8727 | AT10: 20.9277 | AU10: 30.5424 | AV10: 27.1733 | AW10: 27.461 | AX10: 26.3766 | AY10: 26.9353 | AZ10: 11.3021 | BA10: 30.0724 | BB10: 25.0813 | BC10: 32.3268 | BD10: 32.9951 | BE10: 26.59 | BF10: 28.8967 | BG10: 10 | BH10: 18.1177 | BI10: 27.0445 | BJ10: 25.058 | BK10: 35.203 | BL10: 20.2847 | BM10: 10 | BN10: 25.637 | BO10: 16.4206 | BP10: 26.2202 | BQ10: 22.0783 | BR10: 34.3211 | BS10: 23.5216 | BT10: 34.3049 | BU10: 30.6025 | BV10: 31.0572 | BW10: 31.4071 | BX10: 30.4012 | BY10: 25.482 | BZ10: 32.731 | CA10: 25.5852 | CB10: 10.1734 | CC10: 34.823 | CD10: 28.1715 | CE10: 32.3563 | CF10: 27.6604 | CG10: 18.8053 | CH10: 16.736 | CI10: 26.0761 | CJ10: 29.2638 | CK10: 10 | CL10: 31.0859 | CM10: 24.4438 | CN10: 10 | CO10: 27.8265 | CP10: 10 | CQ10: 28.904 | CR10: 22.7799 | CS10: 26.4238 | CT10: 28.8897 | CU10: 35.2246 | CV10: 29.0866 | CW10: 25.1816 | CX10: 34.4214 | CY10: 27.7007 | CZ10: 25.3348 | DA10: 29.1599 | DB10: 33.1939 | DC10: 10.8736 | DD10: 18.2396 | DE10: 27.3772 | DF10: 19.9314 | DG10: 10 | DH10: 19.9374 | DI10: 33.0833 | DJ10: 28.9754 | DK10: 22.1009 | DL10: 26.9633 | DM10: 21.7101 | DN10: 32.1748 | DO10: 26.6986 | DP10: 29.7707 | DQ10: 26.8333 | DR10: 22.5086 | DS10: 29.6391 | DT10: 27.44 | DU10: 25.8602 | DV10: 27.6619 | DW10: 20.2803 | DX10: 32.1141 | DY10: 24.8798 | DZ10: 18.7985 | EA10: 27.9217 | EB10: 35.4253 | EC10: 25.4809 | ED10: 30.9333 | EE10: 28.6687 | EF10: 30.0849 | EG10: 22.8278 | EH10: 10 | EI10: 19.8127 | EJ10: 29.4814 | EK10: 27.0305 | EL10: 26.5377 | EM10: 26.3751 | EN10: 28.5228 | EO10: 29.3177 | EP10: 33.3223 | EQ10: 33.9417 | ER10: 30.0179 | ES10: 28.4145 | ET10: 20.9504 | EU10: 23.4946 | EV10: 28.7267 | EW10: 26.004 | EX10: 22.6942 | EY10: 29.8638 | EZ10: 14.4103 | FA10: 25.0387 | FB10: 10 | FC10: 25.0452 | FD10: 29.2051 | FE10: 33.7596 | FF10: 34.3859 | FG10: 31.3889 | FH10: 33.0678 | FI10: 16.4096 | FJ10: 31.8373 | FK10: 25.4245 | FL10: 24.0553 | FM10: 28.726 | FN10: 28.1553 | FO10: 32.5768 | FP10: 28.8864 | FQ10: 23.0105 | FR10: 30.0675 | FS10: 23.0529 | FT10: 26.2684 | FU10: 15.3726 | FV10: 19.5061 | FW10: 30.6025 | FX10: 21.029 | FY10: 15.8999 | FZ10: 26.3545 | GA10: 29.1645 | GB10: 27.4184 | GC10: 24.6043 | GD10: 27.7984 | GE10: 30.9657 | GF10: 20.9531 | GG10: 16.9949 | GH10: 28.1962 | GI10: 34.823 | GJ10: 28.0263 | GK10: 26.6056 | GL10: 18.9987 | GM10: 19.4165 | GN10: 30.2247 | GO10: 25.8503 | GP10: 24.0641 | GQ10: 29.7235 | GR10: 30.1003 | GS10: 22.8896 | GT10: 34.7064 | GU10: 30.2098 | GV10: 27.0741 | GW10: 21.3577 | GX10: 27.0355 | GY10: 27.9971 | GZ10: 29.9228 | HA10: 30.5161 | HB10: 25.8674 | HC10: 20.28 | HD10: 19.5364 | HE10: 10 | HF10: 26.5849 | HG10: 27.1278 | HH10: 35.1134 | HI10: 25.632061 | HJ10: 5485.2611
A11: 10 | B11: 4.5 | C11: 27.636 | D11: 10 | E11: 25.3527 | F11: 19.929 | G11: 31.1966 | H11: 31.764 | I11: 26.1057 | J11: 21.9926 | K11: 17.8638 | L11: 22.4557 | M11: 10 | N11: 30.0927 | O11: 32.1969 | P11: 34.9075 | Q11: 23.479 | R11: 30.8012 | S11: 25.8641 | T11: 20.9742 | U11: 28.4634 | V11: 21.8857 | W11: 27.8866 | X11: 21.6157 | Y11: 17.9518 | Z11: 18.5471 | AA11: 35.3888 | AB11: 33.5451 | AC11: 22.0113 | AD11: 27.9285 | AE11: 16.8105 | AF11: 10 | AG11: 29.0103 | AH11: 28.4769 | AI11: 25.7524 | AJ11: 25.6797 | AK11: 10 | AL11: 29.9375 | AM11: 35.1325 | AN11: 10.0874 | AO11: 30.2744 | AP11: 30.3476 | AQ11: 25.3427 | AR11: 22.1758 | AS11: 23.0089 | AT11: 19.0185 | AU11: 29.4048 | AV11: 26.7469 | AW11: 27.1887 | AX11: 24.1637 | AY11: 24.5632 | AZ11: 11.0647 | BA11: 29.1584 | BB11: 23.9064 | BC11: 27.3858 | BD11: 31.9397 | BE11: 23.2588 | BF11: 28.8306 | BG11: 10 | BH11: 15.7531 | BI11: 26.2154 | BJ11: 24.7328 | BK11: 34.9127 | BL11: 17.7748 | BM11: 10 | BN11: 22.9913 | BO11: 15.219 | BP11: 25.038 | BQ11: 19.8559 | BR11: 34.2299 | BS11: 22.6654 | BT11: 33.9797 | BU11: 29.0163 | BV11: 31.122 | BW11: 30.8349 | BX11: 30.3979 | BY11: 23.7896 | BZ11: 32.7277 | CA11: 22.7488 | CB11: 10 | CC11: 34.7946 | CD11: 25.5792 | CE11: 32.1691 | CF11: 26.1989 | CG11: 18.7142 | CH11: 12.9907 | CI11: 22.2746 | CJ11: 28.1762 | CK11: 10 | CL11: 29.5943 | CM11: 23.4624 | CN11: 10 | CO11: 23.2078 | CP11: 10 | CQ11: 28.7975 | CR11: 18.4006 | CS11: 24.821 | CT11: 27.3356 | CU11: 35.2441 | CV11: 28.676 | CW11: 22.8044 | CX11: 34.3428 | CY11: 26.5983 | CZ11: 25.2534 | DA11: 28.5522 | DB11: 32.9691 | DC11: 10.4112 | DD11: 15.0068 | DE11: 27.3739 | DF11: 19.4376 | DG11: 10 | DH11: 16.5952 | DI11: 33.0146 | DJ11: 28.2135 | DK11: 18.9528 | DL11: 25.6854 | DM11: 20.6153 | DN11: 32.0629 | DO11: 23.9775 | DP11: 29.6113 | DQ11: 25.9356 | DR11: 21.0483 | DS11: 29.4797 | DT11: 26.435 | DU11: 24.2544 | DV11: 27.0006 | DW11: 19.4402 | DX11: 31.9896 | DY11: 24.1279 | DZ11: 16.1551 | EA11: 27.1644 | EB11: 35.4675 | EC11: 25.3843 | ED11: 30.8143 | EE11: 28.5045 | EF11: 29.0623 | EG11: 21.6179 | EH11: 10 | EI11: 19.6031 | EJ11: 29.0549 | EK11: 25.5419 | EL11: 25.7661 | EM11: 22.7929 | EN11: 28.2702 | EO11: 29.4729 | EP11: 31.3271 | EQ11: 32.908 | ER11: 29.1032 | ES11: 26.3991 | ET11: 20.0214 | EU11: 21.0353 | EV11: 28.5673 | EW11: 25.2276 | EX11: 21.3345 | EY11: 28.0915 | EZ11: 12.4259 | FA11: 23.5608 | FB11: 10 | FC11: 22.953 | FD11: 29.0457 | FE11: 33.6809 | FF11: 34.0454 | FG11: 30.2573 | FH11: 32.9156 | FI11: 14.9107 | FJ11: 31.1445 | FK11: 20.6948 | FL11: 21.1937 | FM11: 27.0063 | FN11: 27.9834 | FO11: 32.2991 | FP11: 28.8247 | FQ11: 22.6203 | FR11: 29.7548 | FS11: 21.6785 | FT11: 25.9181 | FU11: 13.7867 | FV11: 18.5288 | FW11: 30.3427 | FX11: 17.2698 | FY11: 10 | FZ11: 24.7743 | GA11: 28.8769 | GB11: 26.2563 | GC11: 24.4351 | GD11: 26.1336 | GE11: 29.8188 | GF11: 18.5569 | GG11: 12.8298 | GH11: 26.1337 | GI11: 34.7946 | GJ11: 27.7611 | GK11: 25.8773 | GL11: 18.5829 | GM11: 18.8896 | GN11: 28.2273 | GO11: 24.4248 | GP11: 21.8182 | GQ11: 28.9283 | GR11: 30.0593 | GS11: 21.9175 | GT11: 34.4314 | GU11: 28.4143 | GV11: 25.1196 | GW11: 19.9377 | GX11: 24.7271 | GY11: 27.7624 | GZ11: 30.0215 | HA11: 30.3944 | HB11: 25.6202 | HC11: 19.952 | HD11: 17.286 | HE11: 10 | HF11: 25.8325 | HG11: 27.2151 | HH11: 34.9666 | HI11: 24.553457 | HJ11: 5254.4399
A12: 11 | B12: 5 | C12: 26.5048 | D12: 10 | E12: 24.3717 | F12: 20.577 | G12: 31.9679 | H12: 32.3311 | I12: 26.7409 | J12: 22.429 | K12: 15.9931 | L12: 22.9031 | M12: 10.2552 | N12: 31.5319 | O12: 32.606 | P12: 36.9582 | Q12: 22.6932 | R12: 30.9767 | S12: 27.4791 | T12: 21.1627 | U12: 29.5178 | V12: 21.7012 | W12: 28.941 | X12: 22.4398 | Y12: 19.3458 | Z12: 19.1302 | AA12: 37.1676 | AB12: 33.9767 | AC12: 23.0318 | AD12: 28.6433 | AE12: 16.2618 | AF12: 10.8305 | AG12: 31.1401 | AH12: 29.8145 | AI12: 27.1439 | AJ12: 26.0744 | AK12: 10 | AL12: 31.9882 | AM12: 37.2057 | AN12: 11.7229 | AO12: 31.295 | AP12: 29.9949 | AQ12: 27.3821 | AR12: 22.9365 | AS12: 23.4475 | AT12: 18.5418 | AU12: 31.082 | AV12: 27.5175 | AW12: 27.495 | AX12: 24.6617 | AY12: 24.1234 | AZ12: 10 | BA12: 30.1426 | BB12: 23.4446 | BC12: 23.4642 | BD12: 33.6621 | BE12: 25.3434 | BF12: 29.1485 | BG12: 10.0751 | BH12: 16.0535 | BI12: 26.7673 | BJ12: 25.7307 | BK12: 35.6839 | BL12: 16.1372 | BM12: 10 | BN12: 23.2832 | BO12: 13.7282 | BP12: 25.1265 | BQ12: 19.9816 | BR12: 36.2128 | BS12: 22.5438 | BT12: 34.9776 | BU12: 29.3801 | BV12: 33.2517 | BW12: 30.948 | BX12: 31.3683 | BY12: 22.266 | BZ12: 34.7897 | CA12: 23.1052 | CB12: 11.3601 | CC12: 36.834 | CD12: 26.3278 | CE12: 32.7474 | CF12: 26.23 | CG12: 20.4772 | CH12: 13.5103 | CI12: 23.7061 | CJ12: 27.4096 | CK12: 10.0226 | CL12: 30.9544 | CM12: 23.2953 | CN12: 11.0303 | CO12: 21.2543 | CP12: 11.3714 | CQ12: 28.7274 | CR12: 18.5778 | CS12: 26.5806 | CT12: 29.375 | CU12: 37.3287 | CV12: 28.2551 | CW12: 21.8322 | CX12: 36.3371 | CY12: 27.7452 | CZ12: 25.0328 | DA12: 28.6126 | DB12: 33.196 | DC12: 11.1855 | DD12: 15.499 | DE12: 28.3402 | DF12: 18.3188 | DG12: 10 | DH12: 16.6257 | DI12: 33.8435 | DJ12: 29.2451 | DK12: 18.9826 | DL12: 24.898 | DM12: 20.0859 | DN12: 32.0772 | DO12: 23.5872 | DP12: 30.0771 | DQ12: 27.7111 | DR12: 20.2915 | DS12: 29.2498 | DT12: 26.478 | DU12: 23.7182 | DV12: 27.2564 | DW12: 19.7782 | DX12: 33.1682 | DY12: 25.0921 | DZ12: 15.2276 | EA12: 27.76 | EB12: 37.5747 | EC12: 24.2228 | ED12: 32.0496 | EE12: 25.7774 | EF12: 30.0598 | EG12: 22.6069 | EH12: 11.2602 | EI12: 19.3033 | EJ12: 30.8112 | EK12: 25.4064 | EL12: 26.1503 | EM12: 22.9504 | EN12: 28.0397 | EO12: 30.0803 | EP12: 32.0757 | EQ12: 33.43 | ER12: 31.2668 | ES12: 27.0913 | ET12: 21.3686 | EU12: 20.5527 | EV12: 26.6724 | EW12: 27.2002 | EX12: 22.267 | EY12: 28.8703 | EZ12: 13.5779 | FA12: 23.7886 | FB12: 10 | FC12: 22.6329 | FD12: 30.4511 | FE12: 35.6752 | FF12: 34.7715 | FG12: 32.2402 | FH12: 33.8111 | FI12: 16.9727 | FJ12: 32.0697 | FK12: 20.0253 | FL12: 21.2716 | FM12: 26.3976 | FN12: 29.3774 | FO12: 33.0816 | FP12: 30.0598 | FQ12: 22.7102 | FR12: 30.7641 | FS12: 22.4069 | FT12: 26.8934 | FU12: 14.0331 | FV12: 16.2585 | FW12: 31.6577 | FX12: 18.2895 | FY12: 10.4316 | FZ12: 25.617 | GA12: 29.0183 | GB12: 26.698 | GC12: 26.0897 | GD12: 27.3236 | GE12: 31.7679 | GF12: 17.7558 | GG12: 11.294 | GH12: 27.0362 | GI12: 36.834 | GJ12: 28.5549 | GK12: 26.051 | GL12: 15.9196 | GM12: 16.703 | GN12: 30.3119 | GO12: 25.0749 | GP12: 23.1276 | GQ12: 29.2136 | GR12: 32.0875 | GS12: 20.6664 | GT12: 35.4745 | GU12: 28.8823 | GV12: 25.5869 | GW12: 21.7035 | GX12: 25.707 | GY12: 27.963 | GZ12: 30.3837 | HA12: 31.3084 | HB12: 24.9203 | HC12: 18.406 | HD12: 17.2566 | HE12: 10.1302 | HF12: 26.7825 | HG12: 29.0302 | HH12: 36.3832 | HI12: 25.042433 | HJ12: 5359.0806
A13: 12 | B13: 5.5 | C13: 29.174 | D13: 14.4119 | E13: 29.04 | F13: 22.7169 | G13: 34.0309 | H13: 33.8671 | I13: 29.0984 | J13: 23.4593 | K13: 15.5127 | L13: 26.6506 | M13: 13.5135 | N13: 33.3789 | O13: 33.9839 | P13: 41.5926 | Q13: 24.1389 | R13: 35.837 | S13: 30.9571 | T13: 20.6045 | U13: 32.187 | V13: 24.7486 | W13: 31.011 | X13: 22.7015 | Y13: 22.6776 | Z13: 22.4187 | AA13: 41.2072 | AB13: 35.3772 | AC13: 25.6671 | AD13: 29.0321 | AE13: 20.4264 | AF13: 14.712 | AG13: 35.8536 | AH13: 33.0898 | AI13: 29.0369 | AJ13: 29.9469 | AK13: 10 | AL13: 35.1315 | AM13: 41.8627 | AN13: 15.0808 | AO13: 33.9303 | AP13: 30.8337 | AQ13: 30.2817 | AR13: 25.0183 | AS13: 24.4247 | AT13: 23.1536 | AU13: 35.0199 | AV13: 31.7001 | AW13: 29.7392 | AX13: 26.4515 | AY13: 25.885 | AZ13: 11.4387 | BA13: 34.1596 | BB13: 24.2067 | BC13: 21.5413 | BD13: 37.2606 | BE13: 27.6413 | BF13: 33.7378 | BG13: 14.5832 | BH13: 19.9316 | BI13: 30.0087 | BJ13: 28.3434 | BK13: 37.747 | BL13: 17.4952 | BM13: 12.4434 | BN13: 24.2107 | BO13: 15.0609 | BP13: 23.8753 | BQ13: 24.3695 | BR13: 40.7795 | BS13: 23.2352 | BT13: 37.5903 | BU13: 29.5828 | BV13: 37.9652 | BW13: 32.4685 | BX13: 36.0139 | BY13: 22.9591 | BZ13: 39.4354 | CA13: 24.1226 | CB13: 14.2103 | CC13: 41.4571 | CD13: 28.3683 | CE13: 35.2124 | CF13: 28.2592 | CG13: 23.6458 | CH13: 16.7889 | CI13: 25.8788 | CJ13: 28.8214 | CK13: 13.2979 | CL13: 33.3149 | CM13: 24.4367 | CN13: 14.4916 | CO13: 20.0888 | CP13: 13.514 | CQ13: 32.6992 | CR13: 18.3818 | CS13: 30.5178 | CT13: 32.3198 | CU13: 41.997 | CV13: 32.9686 | CW13: 23.2327 | CX13: 40.915 | CY13: 29.4162 | CZ13: 28.0542 | DA13: 31.9444 | DB13: 35.8991 | DC13: 14.7492 | DD13: 14.3788 | DE13: 32.3215 | DF13: 17.8476 | DG13: 12.6597 | DH13: 21.0014 | DI13: 37.8492 | DJ13: 30.5455 | DK13: 21.532 | DL13: 26.8989 | DM13: 24.7203 | DN13: 34.4412 | DO13: 24.2365 | DP13: 33.4202 | DQ13: 30.9508 | DR13: 22.2756 | DS13: 32.5929 | DT13: 30.8232 | DU13: 19.2286 | DV13: 27.0851 | DW13: 24.4352 | DX13: 34.7967 | DY13: 27.9851 | DZ13: 12.8211 | EA13: 29.7921 | EB13: 42.2655 | EC13: 27.1192 | ED13: 34.7717 | EE13: 29.6828 | EF13: 33.4851 | EG13: 27.3656 | EH13: 15.8833 | EI13: 21.8505 | EJ13: 34.8282 | EK13: 26.38 | EL13: 30.1317 | EM13: 23.0193 | EN13: 29.2928 | EO13: 34.8073 | EP13: 33.91 | EQ13: 34.9208 | ER13: 34.7377 | ES13: 29.0753 | ET13: 24.7309 | EU13: 23.7216 | EV13: 28.387 | EW13: 30.1532 | EX13: 24.8685 | EY13: 30.877 | EZ13: 16.8545 | FA13: 24.478 | FB13: 10.9284 | FC13: 26.5006 | FD13: 31.3699 | FE13: 40.2531 | FF13: 36.7894 | FG13: 35.1394 | FH13: 35.9984 | FI13: 21.1266 | FJ13: 35.4241 | FK13: 23.3006 | FL13: 23.6415 | FM13: 28.0769 | FN13: 31.327 | FO13: 31.3534 | FP13: 32.9097 | FQ13: 26.0533 | FR13: 33.3881 | FS13: 21.2506 | FT13: 29.4835 | FU13: 14.7184 | FV13: 15.446 | FW13: 34.9104 | FX13: 22.3145 | FY13: 10.9281 | FZ13: 29.5856 | GA13: 30.9228 | GB13: 31.3776 | GC13: 28.809 | GD13: 29.4557 | GE13: 36.3006 | GF13: 17.9578 | GG13: 12.2654 | GH13: 29.7167 | GI13: 41.4571 | GJ13: 28.745 | GK13: 27.026 | GL13: 17.7307 | GM13: 17.3082 | GN13: 34.9802 | GO13: 29.6303 | GP13: 25.7197 | GQ13: 32.7148 | GR13: 36.6993 | GS13: 22.7271 | GT13: 38.1324 | GU13: 31.0812 | GV13: 28.3126 | GW13: 23.4453 | GX13: 28.6247 | GY13: 30.4512 | GZ13: 35.131 | HA13: 34.0435 | HB13: 26.7063 | HC13: 20.1723 | HD13: 21.6986 | HE13: 12.2629 | HF13: 30.8048 | HG13: 31.4937 | HH13: 39.7376 | HI13: 27.550279 | HJ13: 5895.7596
... A49: 48 | B49: 23.5 | C49: 49.7635 | D49: 72.8538 | E49: 74.2656 | F49: 59.3285 | G49: 10 | H49: 54.4445 | I49: 12.2871 | J49: 42.4104 | K49: 58.6079 | L49: 71.2289 | M49: 56.6329 | N49: 90.9578 | O49: 23.2579 | P49: 58.3616 | Q49: 84.2891 | R49: 30.4074 | S49: 87.0082 | T49: 72.7252 | U49: 41.9762 | V49: 10 | W49: 73.951 | X49: 36.4853 | Y49: 89.4146 | Z49: 10 | AA49: 49.441 | AB49: 65.0384 | AC49: 74.8742 | AD49: 15.9391 | AE49: 60.1609 | AF49: 10 | AG49: 74.2077 | AH49: 18.078 | AI49: 73.8114 | AJ49: 69.9487 | AK49: 38.4152 | AL49: 70.1662 | AM49: 61.0234 | AN49: 17.1001 | AO49: 75.3375 | AP49: 38.1122 | AQ49: 47.3884 | AR49: 84.8683 | AS49: 46.7039 | AT49: 77.0984 | AU49: 24.3788 | AV49: 26.8154 | AW49: 45.0843 | AX49: 46.3365 | AY49: 70.3339 | AZ49: 51.7914 | BA49: 62.5834 | BB49: 86.6309 | BC49: 10 | BD49: 21.9803 | BE49: 40.5167 | BF49: 20.7356 | BG49: 39.9539 | BH49: 79.8129 | BI49: 10 | BJ49: 88.1048 | BK49: 38.8804 | BL49: 21.0922 | BM49: 38.2928 | BN49: 32.3322 | BO49: 15.9711 | BP49: 45.9287 | BQ49: 33.8896 | BR49: 95.2411 | BS49: 72.3146 | BT49: 94.3101 | BU49: 13.2087 | BV49: 65.7317 | BW49: 28.1327 | BX49: 38.7445 | BY49: 22.228 | BZ49: 57.1616 | CA49: 10 | CB49: 61.7208 | CC49: 75.9836 | CD49: 40.4321 | CE49: 85.3805 | CF49: 28.6016 | CG49: 42.2803 | CH49: 37.2916 | CI49: 41.9042 | CJ49: 52.6877 | CK49: 13.3032 | CL49: 39.6149 | CM49: 85.8467 | CN49: 18.181 | CO49: 50.0747 | CP49: 37.7619 | CQ49: 46.2569 | CR49: 32.582 | CS49: 69.2273 | CT49: 91.9509 | CU49: 33.7687 | CV49: 41.2645 | CW49: 49.173 | CX49: 78.3175 | CY49: 35.9652 | CZ49: 10 | DA49: 17.3821 | DB49: 89.2376 | DC49: 85.4125 | DD49: 10 | DE49: 79.1003 | DF49: 10 | DG49: 24.9544 | DH49: 33.6331 | DI49: 31.7876 | DJ49: 41.9795 | DK49: 10 | DL49: 10 | DM49: 84.8125 | DN49: 47.5342 | DO49: 50.5507 | DP49: 88.2639 | DQ49: 35.0886 | DR49: 84.0264 | DS49: 90.964 | DT49: 70.8121 | DU49: 46.9122 | DV49: 88.4983 | DW49: 46.1899 | DX49: 54.0488 | DY49: 85.336 | DZ49: 10 | EA49: 89.8281 | EB49: 86.3972 | EC49: 29.85 | ED49: 62.7158 | EE49: 10 | EF49: 73.7648 | EG49: 10 | EH49: 44.7677 | EI49: 64.176 | EJ49: 14.838 | EK49: 65.8581 | EL49: 58.7701 | EM49: 58.4406 | EN49: 10 | EO49: 61.0133 | EP49: 90.6924 | EQ49: 16.9121 | ER49: 93.1797 | ES49: 87.1198 | ET49: 48.2966 | EU49: 41.5784 | EV49: 70.103 | EW49: 59.3752 | EX49: 40.0212 | EY49: 40.5661 | EZ49: 83.3825 | FA49: 75.3475 | FB49: 10 | FC49: 42.1838 | FD49: 52.0681 | FE49: 95.329 | FF49: 10 | FG49: 27.5131 | FH49: 53.49 | FI49: 43.9611 | FJ49: 55.7558 | FK49: 50.5723 | FL49: 10 | FM49: 86.6862 | FN49: 60.5638 | FO49: 70.212 | FP49: 31.0898 | FQ49: 86.8723 | FR49: 57.3269 | FS49: 82.8882 | FT49: 17.2098 | FU49: 57.9436 | FV49: 54.9636 | FW49: 10 | FX49: 39.3431 | FY49: 20.6037 | FZ49: 19.82 | GA49: 69.4492 | GB49: 22.8785 | GC49: 10 | GD49: 30.5323 | GE49: 51.1284 | GF49: 31.6507 | GG49: 89.6888 | GH49: 89.8941 | GI49: 42.0184 | GJ49: 45.9694 | GK49: 50.8125 | GL49: 35.526 | GM49: 63.849 | GN49: 80.3474 | GO49: 10 | GP49: 18.9219 | GQ49: 91.19 | GR49: 87.9797 | GS49: 12.6556 | GT49: 49.875 | GU49: 90.4412 | GV49: 74.7453 | GW49: 36.7257 | GX49: 46.5954 | GY49: 51.6169 | GZ49: 43.8311 | HA49: 58.0757 | HB49: 26.6165 | HC49: 86.4047 | HD49: 60.7474 | HE49: 10 | HF49: 10 | HG49: 88.6773 | HH49: 10 | HI49: 49.650557 | HJ49: 10625.219

Sheet Demand_kW
