Workbook

Sheet ReadMe
A1: README
A2: Data behind the TR6 rolling-dispatch figures (SOC, demand/PV/dispatch, net, self-consumption, metrics histogram).
A3: Each quantity sheet: rows = 48 half-hour periods (with hour of day), columns = prosumers, plus fleet_average / fleet_total.
A4: Dispatch is the committed slot-1 execution of the rolling horizon (self-consumption baseline, Term 2 + Term 3).
A5: SOC is the realised state at the START of each step (fraction of capacity).
A6: net_kW = (demand - PV) + (charge - discharge); positive = import, negative = export.
A7: Regenerate: python build_workbook.py --force (see README.md for other transformers).

Sheet Summary
A1: quantity | B1: value
A2: run | B2: TR6 exact-QCP rolling (FOR_PolyS=0, FOR_LinearizeVmax=0), 48 steps, all Optimal
A3: source dispatch | B3: FOR_rolling_soc_TR6.csv
A4: source load/PV | B4: TR6_load_PV_48periods.xlsx
A5: prosumers | B5: 262
A6: PV generated kWh/day | B6: 6477.2
A7: demand kWh/day | B7: 1888.9
A8: exported kWh/day | B8: 4455.8
A9: imported kWh/day | B9: 56.7
A10: SCR % (PV used locally) | B10: 31.2
A11: SSR % (demand met locally) | B11: 97
A12: prosumer-periods |net|<50W % | B12: 57.5
A13: SOC min/max over day | B13: 0.10 / 1.00
A14: simultaneous chg+dis rows | B14: 0

Sheet FleetAverage
A1: period | B1: hour | C1: demand_avg_kW | D1: PV_avg_kW | E1: charge_avg_kW | F1: discharge_avg_kW | G1: net_avg_kW | H1: SOC_avg_pct | I1: demand_total_kW | J1: PV_total_kW | K1: net_total_kW
A2: =Demand_kW!A2 -> 1 | B2: =Demand_kW!B2 -> 0 | C2: =AVERAGE(Demand_kW!$C2:$JD2) -> 0.24250943 | D2: =AVERAGE(PV_kW!$C2:$JD2) -> 0 | E2: =AVERAGE(Charge_kW!$C2:$JD2) -> 0 | F2: =AVERAGE(Discharge_kW!$C2:$JD2) -> 0.24233588 | G2: =C2-D2+E2-F2 -> 0.00017354847 | H2: =AVERAGE(SOC_pct!$C2:$JD2) -> 40 | I2: =SUM(Demand_kW!$C2:$JD2) -> 63.53747 | J2: =SUM(PV_kW!$C2:$JD2) -> 0 | K2: =I2-J2+SUM(Charge_kW!$C2:$JD2)-SUM(Discharge_kW!$C2:$JD2) -> 0.0454697
A3: =Demand_kW!A3 -> 2 | B3: =Demand_kW!B3 -> 0.5 | C3: =AVERAGE(Demand_kW!$C3:$JD3) -> 0.17665719 | D3: =AVERAGE(PV_kW!$C3:$JD3) -> 0 | E3: =AVERAGE(Charge_kW!$C3:$JD3) -> 0 | F3: =AVERAGE(Discharge_kW!$C3:$JD3) -> 0.17425573 | G3: =C3-D3+E3-F3 -> 0.002401467 | H3: =AVERAGE(SOC_pct!$C3:$JD3) -> 36.959162 | I3: =SUM(Demand_kW!$C3:$JD3) -> 46.284184 | J3: =SUM(PV_kW!$C3:$JD3) -> 0 | K3: =I3-J3+SUM(Charge_kW!$C3:$JD3)-SUM(Discharge_kW!$C3:$JD3) -> 0.62918437
A4: =Demand_kW!A4 -> 3 | B4: =Demand_kW!B4 -> 1 | C4: =AVERAGE(Demand_kW!$C4:$JD4) -> 0.15792867 | D4: =AVERAGE(PV_kW!$C4:$JD4) -> 0 | E4: =AVERAGE(Charge_kW!$C4:$JD4) -> 0 | F4: =AVERAGE(Discharge_kW!$C4:$JD4) -> 0.1510229 | G4: =C4-D4+E4-F4 -> 0.0069057724 | H4: =AVERAGE(SOC_pct!$C4:$JD4) -> 34.772638 | I4: =SUM(Demand_kW!$C4:$JD4) -> 41.377312 | J4: =SUM(PV_kW!$C4:$JD4) -> 0 | K4: =I4-J4+SUM(Charge_kW!$C4:$JD4)-SUM(Discharge_kW!$C4:$JD4) -> 1.8093124
A5: =Demand_kW!A5 -> 4 | B5: =Demand_kW!B5 -> 1.5 | C5: =AVERAGE(Demand_kW!$C5:$JD5) -> 0.14414048 | D5: =AVERAGE(PV_kW!$C5:$JD5) -> 0 | E5: =AVERAGE(Charge_kW!$C5:$JD5) -> 0 | F5: =AVERAGE(Discharge_kW!$C5:$JD5) -> 0.13312595 | G5: =C5-D5+E5-F5 -> 0.011014531 | H5: =AVERAGE(SOC_pct!$C5:$JD5) -> 32.877325 | I5: =SUM(Demand_kW!$C5:$JD5) -> 37.764807 | J5: =SUM(PV_kW!$C5:$JD5) -> 0 | K5: =I5-J5+SUM(Charge_kW!$C5:$JD5)-SUM(Discharge_kW!$C5:$JD5) -> 2.885807
A6: =Demand_kW!A6 -> 5 | B6: =Demand_kW!B6 -> 2 | C6: =AVERAGE(Demand_kW!$C6:$JD6) -> 0.1319296 | D6: =AVERAGE(PV_kW!$C6:$JD6) -> 0 | E6: =AVERAGE(Charge_kW!$C6:$JD6) -> 0 | F6: =AVERAGE(Discharge_kW!$C6:$JD6) -> 0.12270992 | G6: =C6-D6+E6-F6 -> 0.0092196794 | H6: =AVERAGE(SOC_pct!$C6:$JD6) -> 31.206634 | I6: =SUM(Demand_kW!$C6:$JD6) -> 34.565556 | J6: =SUM(PV_kW!$C6:$JD6) -> 0 | K6: =I6-J6+SUM(Charge_kW!$C6:$JD6)-SUM(Discharge_kW!$C6:$JD6) -> 2.415556
A7: =Demand_kW!A7 -> 6 | B7: =Demand_kW!B7 -> 2.5 | C7: =AVERAGE(Demand_kW!$C7:$JD7) -> 0.12875602 | D7: =AVERAGE(PV_kW!$C7:$JD7) -> 0 | E7: =AVERAGE(Charge_kW!$C7:$JD7) -> 0 | F7: =AVERAGE(Discharge_kW!$C7:$JD7) -> 0.12060687 | G7: =C7-D7+E7-F7 -> 0.0081491524 | H7: =AVERAGE(SOC_pct!$C7:$JD7) -> 29.666644 | I7: =SUM(Demand_kW!$C7:$JD7) -> 33.734078 | J7: =SUM(PV_kW!$C7:$JD7) -> 0 | K7: =I7-J7+SUM(Charge_kW!$C7:$JD7)-SUM(Discharge_kW!$C7:$JD7) -> 2.1350779
A8: =Demand_kW!A8 -> 7 | B8: =Demand_kW!B8 -> 3 | C8: =AVERAGE(Demand_kW!$C8:$JD8) -> 0.12085754 | D8: =AVERAGE(PV_kW!$C8:$JD8) -> 0 | E8: =AVERAGE(Charge_kW!$C8:$JD8) -> 0 | F8: =AVERAGE(Discharge_kW!$C8:$JD8) -> 0.10964885 | G8: =C8-D8+E8-F8 -> 0.011208688 | H8: =AVERAGE(SOC_pct!$C8:$JD8) -> 28.153251 | I8: =SUM(Demand_kW!$C8:$JD8) -> 31.664676 | J8: =SUM(PV_kW!$C8:$JD8) -> 0 | K8: =I8-J8+SUM(Charge_kW!$C8:$JD8)-SUM(Discharge_kW!$C8:$JD8) -> 2.9366763
A9: =Demand_kW!A9 -> 8 | B9: =Demand_kW!B9 -> 3.5 | C9: =AVERAGE(Demand_kW!$C9:$JD9) -> 0.13354529 | D9: =AVERAGE(PV_kW!$C9:$JD9) -> 0.002633134 | E9: =AVERAGE(Charge_kW!$C9:$JD9) -> 0 | F9: =AVERAGE(Discharge_kW!$C9:$JD9) -> 0.11508779 | G9: =C9-D9+E9-F9 -> 0.015824371 | H9: =AVERAGE(SOC_pct!$C9:$JD9) -> 26.777397 | I9: =SUM(Demand_kW!$C9:$JD9) -> 34.988866 | J9: =SUM(PV_kW!$C9:$JD9) -> 0.6898811 | K9: =I9-J9+SUM(Charge_kW!$C9:$JD9)-SUM(Discharge_kW!$C9:$JD9) -> 4.1459852
A10: =Demand_kW!A10 -> 9 | B10: =Demand_kW!B10 -> 4 | C10: =AVERAGE(Demand_kW!$C10:$JD10) -> 0.11333703 | D10: =AVERAGE(PV_kW!$C10:$JD10) -> 0.038060175 | E10: =AVERAGE(Charge_kW!$C10:$JD10) -> 0.00034351145 | F10: =AVERAGE(Discharge_kW!$C10:$JD10) -> 0.068360423 | G10: =C10-D10+E10-F10 -> 0.0072599396 | H10: =AVERAGE(SOC_pct!$C10:$JD10) -> 25.333597 | I10: =SUM(Demand_kW!$C10:$JD10) -> 29.694301 | J10: =SUM(PV_kW!$C10:$JD10) -> 9.9717658 | K10: =I10-J10+SUM(Charge_kW!$C10:$JD10)-SUM(Discharge_kW!$C10:$JD10) -> 1.9021042
A11: =Demand_kW!A11 -> 10 | B11: =Demand_kW!B11 -> 4.5 | C11: =AVERAGE(Demand_kW!$C11:$JD11) -> 0.12087219 | D11: =AVERAGE(PV_kW!$C11:$JD11) -> 0.17798091 | E11: =AVERAGE(Charge_kW!$C11:$JD11) -> 0.072698473 | F11: =AVERAGE(Discharge_kW!$C11:$JD11) -> 0.013251908 | G11: =C11-D11+E11-F11 -> 0.0023378497 | H11: =AVERAGE(SOC_pct!$C11:$JD11) -> 24.479179 | I11: =SUM(Demand_kW!$C11:$JD11) -> 31.668515 | J11: =SUM(PV_kW!$C11:$JD11) -> 46.630998 | K11: =I11-J11+SUM(Charge_kW!$C11:$JD11)-SUM(Discharge_kW!$C11:$JD11) -> 0.61251661
A12: =Demand_kW!A12 -> 11 | B12: =Demand_kW!B12 -> 5 | C12: =AVERAGE(Demand_kW!$C12:$JD12) -> 0.11873846 | D12: =AVERAGE(PV_kW!$C12:$JD12) -> 0.35304858 | E12: =AVERAGE(Charge_kW!$C12:$JD12) -> 0.23527099 | F12: =AVERAGE(Discharge_kW!$C12:$JD12) -> 0.00059541985 | G12: =C12-D12+E12-F12 -> 0.00036545777 | H12: =AVERAGE(SOC_pct!$C12:$JD12) -> 25.134405 | I12: =SUM(Demand_kW!$C12:$JD12) -> 31.109478 | J12: =SUM(PV_kW!$C12:$JD12) -> 92.498728 | K12: =I12-J12+SUM(Charge_kW!$C12:$JD12)-SUM(Discharge_kW!$C12:$JD12) -> 0.095749936
A13: =Demand_kW!A13 -> 12 | B13: =Demand_kW!B13 -> 5.5 | C13: =AVERAGE(Demand_kW!$C13:$JD13) -> 0.12401865 | D13: =AVERAGE(PV_kW!$C13:$JD13) -> 0.56771956 | E13: =AVERAGE(Charge_kW!$C13:$JD13) -> 0.44755725 | F13: =AVERAGE(Discharge_kW!$C13:$JD13) -> 0.0038816794 | G13: =C13-D13+E13-F13 -> -2.5331787e-05 | H13: =AVERAGE(SOC_pct!$C13:$JD13) -> 27.784296 | I13: =SUM(Demand_kW!$C13:$JD13) -> 32.492887 | J13: =SUM(PV_kW!$C13:$JD13) -> 148.74252 | K13: =I13-J13+SUM(Charge_kW!$C13:$JD13)-SUM(Discharge_kW!$C13:$JD13) -> -0.0066369283
... A49: =Demand_kW!A49 -> 48 | B49: =Demand_kW!B49 -> 23.5 | C49: =AVERAGE(Demand_kW!$C49:$JD49) -> 0.24186827 | D49: =AVERAGE(PV_kW!$C49:$JD49) -> 0 | E49: =AVERAGE(Charge_kW!$C49:$JD49) -> 0 | F49: =AVERAGE(Discharge_kW!$C49:$JD49) -> 0.18771374 | G49: =C49-D49+E49-F49 -> 0.054154529 | H49: =AVERAGE(SOC_pct!$C49:$JD49) -> 51.583709 | I49: =SUM(Demand_kW!$C49:$JD49) -> 63.369487 | J49: =SUM(PV_kW!$C49:$JD49) -> 0 | K49: =I49-J49+SUM(Charge_kW!$C49:$JD49)-SUM(Discharge_kW!$C49:$JD49) -> 14.188487

Sheet SOC_pct
A1: period | B1: hour | C1: BES_TR6_one38_B | D1: BES_TR6_one242_B | E1: BES_TR6_one252_C | F1: BES_TR6_one260_C | G1: BES_TR6_one280_A | H1: BES_TR6_one287_B | I1: BES_TR6_one299_B | J1: BES_TR6_one313_A | K1: BES_TR6_one320_B | L1: BES_TR6_one346_C | M1: BES_TR6_one416_C | N1: BES_TR6_one446_B | O1: BES_TR6_one477_A | P1: BES_TR6_one480_A | Q1: BES_TR6_one482_B | R1: BES_TR6_one521_C | S1: BES_TR6_one537_A | T1: BES_TR6_one559_C | U1: BES_TR6_one570_B | V1: BES_TR6_one590_A | W1: BES_TR6_one605_A | X1: BES_TR6_one614_B | Y1: BES_TR6_one73_A | Z1: BES_TR6_one76_A | AA1: BES_TR6_one137_A | AB1: BES_TR6_one176_A | AC1: BES_TR6_four149_B | AD1: BES_TR6_four163_C | AE1: BES_TR6_four171_A | AF1: BES_TR6_four184_B | AG1: BES_TR6_four200_A | AH1: BES_TR6_four239_A | AI1: BES_TR6_four259_B | AJ1: BES_TR6_four288_B | AK1: BES_TR6_four289_B | AL1: BES_TR6_four301_C | AM1: BES_TR6_four317_B | AN1: BES_TR6_four354_B | AO1: BES_TR6_four358_C | AP1: BES_TR6_four65_B | AQ1: BES_TR6_four384_B | AR1: BES_TR6_four385_A | AS1: BES_TR6_four396_B | AT1: BES_TR6_four423_C | AU1: BES_TR6_four446_B | AV1: BES_TR6_four451_C | AW1: BES_TR6_four466_C | AX1: BES_TR6_four558_C | AY1: BES_TR6_four70_B | AZ1: BES_TR6_four573_A | BA1: BES_TR6_four664_A | BB1: BES_TR6_four675_C | BC1: BES_TR6_four710_C | BD1: BES_TR6_four727_B | BE1: BES_TR6_four732_B | BF1: BES_TR6_four818_B | BG1: BES_TR6_four821_A | BH1: BES_TR6_four832_A | BI1: BES_TR6_four840_A | BJ1: BES_TR6_four957_A | BK1: BES_TR6_four978_A | BL1: BES_TR6_four988_A | BM1: BES_TR6_four1013_B | BN1: BES_TR6_four1027_A | BO1: BES_TR6_four1063_C | BP1: BES_TR6_four1103_C | BQ1: BES_TR6_four1140_A | BR1: BES_TR6_four1152_B | BS1: BES_TR6_four1220_C | BT1: BES_TR6_five147_dup_C | BU1: BES_TR6_five149_A | BV1: BES_TR6_five168_A | BW1: BES_TR6_five170_A | BX1: BES_TR6_five170_dup_A | BY1: BES_TR6_five186_C | BZ1: BES_TR6_five186_dup_C | CA1: BES_TR6_five194_C | CB1: BES_TR6_five199_dup_C | CC1: BES_TR6_five67_C | CD1: BES_TR6_five67_dup_C | CE1: BES_TR6_five223_A | CF1: BES_TR6_five223_dup_A | CG1: BES_TR6_five242_dup_A | CH1: BES_TR6_five243_B | CI1: BES_TR6_five243_dup_B | CJ1: BES_TR6_five284_C | CK1: BES_TR6_five284_dup_C | CL1: BES_TR6_five285_B | CM1: BES_TR6_five285_dup_B | CN1: BES_TR6_five303_B | CO1: BES_TR6_five78_A | CP1: BES_TR6_five78_dup_A | CQ1: BES_TR6_five394_C | CR1: BES_TR6_five394_dup_C | CS1: BES_TR6_five421_A | CT1: BES_TR6_five445_dup_C | CU1: BES_TR6_five457_B | CV1: BES_TR6_five494_B | CW1: BES_TR6_five499_B | CX1: BES_TR6_five92_dup_A | CY1: BES_TR6_five512_dup_A | CZ1: BES_TR6_five513_B | DA1: BES_TR6_five513_dup_B | DB1: BES_TR6_five520_C | DC1: BES_TR6_five520_dup_C | DD1: BES_TR6_five537_C | DE1: BES_TR6_five537_dup_C | DF1: BES_TR6_five551_C | DG1: BES_TR6_five585_A | DH1: BES_TR6_five588_dup_A | DI1: BES_TR6_five108_dup_B | DJ1: BES_TR6_five649_A | DK1: BES_TR6_five663_C | DL1: BES_TR6_five663_dup_C | DM1: BES_TR6_five670_dup_C | DN1: BES_TR6_five704_A | DO1: BES_TR6_five733_C | DP1: BES_TR6_five735_A | DQ1: BES_TR6_five735_dup_A | DR1: BES_TR6_five748_B | DS1: BES_TR6_five117_dup_B | DT1: BES_TR6_five750_B | DU1: BES_TR6_five778_dup_B | DV1: BES_TR6_five793_A | DW1: BES_TR6_five881_C | DX1: BES_TR6_five905_B | DY1: BES_TR6_five118_B | DZ1: BES_TR6_five118_dup_B | EA1: BES_TR6_five123_B | EB1: BES_TR6_five123_dup_B | EC1: BES_TR6_five129_C | ED1: BES_TR6_six64_A | EE1: BES_TR6_six64_dup_A | EF1: BES_TR6_six154_dup_C | EG1: BES_TR6_six154_tri_C | EH1: BES_TR6_six173_C | EI1: BES_TR6_six173_dup_C | EJ1: BES_TR6_six191_B | EK1: BES_TR6_six191_dup_B | EL1: BES_TR6_six203_A | EM1: BES_TR6_six203_dup_A | EN1: BES_TR6_six203_tri_A | EO1: BES_TR6_six232_C | EP1: BES_TR6_six238_A | EQ1: BES_TR6_six238_tri_A | ER1: BES_TR6_six249_dup_B | ES1: BES_TR6_six269_tri_C | ET1: BES_TR6_six68_C | EU1: BES_TR6_six68_dup_C | EV1: BES_TR6_six68_tri_C | EW1: BES_TR6_six289_C | EX1: BES_TR6_six289_tri_C | EY1: BES_TR6_six317_dup_C | EZ1: BES_TR6_six317_tri_C | FA1: BES_TR6_six326_tri_A | FB1: BES_TR6_six329_A | FC1: BES_TR6_six329_tri_A | FD1: BES_TR6_six342_A | FE1: BES_TR6_six349_dup_A | FF1: BES_TR6_six349_tri_A | FG1: BES_TR6_six350_dup_B | FH1: BES_TR6_six350_tri_B | FI1: BES_TR6_six362_tri_C | FJ1: BES_TR6_six365_tri_C | FK1: BES_TR6_six378_dup_A | FL1: BES_TR6_six378_tri_A | FM1: BES_TR6_six75_tri_A | FN1: BES_TR6_six385_B | FO1: BES_TR6_six385_tri_B | FP1: BES_TR6_six387_dup_A | FQ1: BES_TR6_six392_C | FR1: BES_TR6_six410_tri_A | FS1: BES_TR6_six431_dup_C | FT1: BES_TR6_six431_tri_C | FU1: BES_TR6_six441_dup_A | FV1: BES_TR6_six441_tri_A | FW1: BES_TR6_six484_dup_B | FX1: BES_TR6_six501_dup_A | FY1: BES_TR6_six512_dup_B | FZ1: BES_TR6_six512_tri_B | GA1: BES_TR6_six82_A | GB1: BES_TR6_six82_dup_A | GC1: BES_TR6_six523_dup_C | GD1: BES_TR6_six571_C | GE1: BES_TR6_six571_tri_C | GF1: BES_TR6_six583_dup_A | GG1: BES_TR6_six591_C | GH1: BES_TR6_six591_dup_C | GI1: BES_TR6_six595_tri_B | GJ1: BES_TR6_six625_A | GK1: BES_TR6_six643_A | GL1: BES_TR6_six646_B | GM1: BES_TR6_six646_dup_B | GN1: BES_TR6_six651_dup_C | GO1: BES_TR6_six651_tri_C | GP1: BES_TR6_six87_dup_A | GQ1: BES_TR6_six652_dup_A | GR1: BES_TR6_six652_tri_A | GS1: BES_TR6_six665_tri_B | GT1: BES_TR6_six667_A | GU1: BES_TR6_six667_tri_A | GV1: BES_TR6_six699_C | GW1: BES_TR6_six699_dup_C | GX1: BES_TR6_six699_tri_C | GY1: BES_TR6_six721_A | GZ1: BES_TR6_six723_B | HA1: BES_TR6_six723_dup_B | HB1: BES_TR6_six740_A | HC1: BES_TR6_six740_dup_A | HD1: BES_TR6_six740_tri_A | HE1: BES_TR6_six758_B | HF1: BES_TR6_six758_dup_B | HG1: BES_TR6_six784_dup_B | HH1: BES_TR6_six784_tri_B | HI1: BES_TR6_six90_B | HJ1: BES_TR6_six90_dup_B | HK1: BES_TR6_six799_tri_B | HL1: BES_TR6_six801_C | HM1: BES_TR6_six801_dup_C | HN1: BES_TR6_six801_tri_C | HO1: BES_TR6_six807_A | HP1: BES_TR6_six844_C | HQ1: BES_TR6_six844_dup_C | HR1: BES_TR6_six844_tri_C | HS1: BES_TR6_six852_B | HT1: BES_TR6_six860_C | HU1: BES_TR6_six860_dup_C | HV1: BES_TR6_six869_C | HW1: BES_TR6_six869_tri_C | HX1: BES_TR6_six885_A | HY1: BES_TR6_six885_tri_A | HZ1: BES_TR6_six894_B | IA1: BES_TR6_six894_tri_B | IB1: BES_TR6_six105_dup_A | IC1: BES_TR6_six105_tri_A | ID1: BES_TR6_six914_A | IE1: BES_TR6_six914_tri_A | IF1: BES_TR6_six921_B | IG1: BES_TR6_six929_tri_A | IH1: BES_TR6_six938_dup_A | II1: BES_TR6_six938_tri_A | IJ1: BES_TR6_six945_dup_C | IK1: BES_TR6_six952_A | IL1: BES_TR6_six952_dup_A | IM1: BES_TR6_six967_B | IN1: BES_TR6_six967_tri_B | IO1: BES_TR6_six974_dup_C | IP1: BES_TR6_six974_tri_C | IQ1: BES_TR6_six979_A | IR1: BES_TR6_six990_B | IS1: BES_TR6_six990_dup_B | IT1: BES_TR6_six990_tri_B | IU1: BES_TR6_six111_dup_C | IV1: BES_TR6_six111_tri_C | IW1: BES_TR6_six1006_C | IX1: BES_TR6_six1006_dup_C | IY1: BES_TR6_six1020_A | IZ1: BES_TR6_six1020_dup_A | JA1: BES_TR6_six1020_tri_A | JB1: BES_TR6_six1025_B | JC1: BES_TR6_six1064_C | JD1: BES_TR6_six1064_tri_C | JE1: fleet_average | JF1: fleet_total
A2: 1 | B2: 0 | C2: 40 | D2: 40 | E2: 40 | F2: 40 | G2: 40 | H2: 40 | I2: 40 | J2: 40 | K2: 40 | L2: 40 | M2: 40 | N2: 40 | O2: 40 | P2: 40 | Q2: 40 | R2: 40 | S2: 40 | T2: 40 | U2: 40 | V2: 40 | W2: 40 | X2: 40 | Y2: 40 | Z2: 40 | AA2: 40 | AB2: 40 | AC2: 40 | AD2: 40 | AE2: 40 | AF2: 40 | AG2: 40 | AH2: 40 | AI2: 40 | AJ2: 40 | AK2: 40 | AL2: 40 | AM2: 40 | AN2: 40 | AO2: 40 | AP2: 40 | AQ2: 40 | AR2: 40 | AS2: 40 | AT2: 40 | AU2: 40 | AV2: 40 | AW2: 40 | AX2: 40 | AY2: 40 | AZ2: 40 | BA2: 40 | BB2: 40 | BC2: 40 | BD2: 40 | BE2: 40 | BF2: 40 | BG2: 40 | BH2: 40 | BI2: 40 | BJ2: 40 | BK2: 40 | BL2: 40 | BM2: 40 | BN2: 40 | BO2: 40 | BP2: 40 | BQ2: 40 | BR2: 40 | BS2: 40 | BT2: 40 | BU2: 40 | BV2: 40 | BW2: 40 | BX2: 40 | BY2: 40 | BZ2: 40 | CA2: 40 | CB2: 40 | CC2: 40 | CD2: 40 | CE2: 40 | CF2: 40 | CG2: 40 | CH2: 40 | CI2: 40 | CJ2: 40 | CK2: 40 | CL2: 40 | CM2: 40 | CN2: 40 | CO2: 40 | CP2: 40 | CQ2: 40 | CR2: 40 | CS2: 40 | CT2: 40 | CU2: 40 | CV2: 40 | CW2: 40 | CX2: 40 | CY2: 40 | CZ2: 40 | DA2: 40 | DB2: 40 | DC2: 40 | DD2: 40 | DE2: 40 | DF2: 40 | DG2: 40 | DH2: 40 | DI2: 40 | DJ2: 40 | DK2: 40 | DL2: 40 | DM2: 40 | DN2: 40 | DO2: 40 | DP2: 40 | DQ2: 40 | DR2: 40 | DS2: 40 | DT2: 40 | DU2: 40 | DV2: 40 | DW2: 40 | DX2: 40 | DY2: 40 | DZ2: 40 | EA2: 40 | EB2: 40 | EC2: 40 | ED2: 40 | EE2: 40 | EF2: 40 | EG2: 40 | EH2: 40 | EI2: 40 | EJ2: 40 | EK2: 40 | EL2: 40 | EM2: 40 | EN2: 40 | EO2: 40 | EP2: 40 | EQ2: 40 | ER2: 40 | ES2: 40 | ET2: 40 | EU2: 40 | EV2: 40 | EW2: 40 | EX2: 40 | EY2: 40 | EZ2: 40 | FA2: 40 | FB2: 40 | FC2: 40 | FD2: 40 | FE2: 40 | FF2: 40 | FG2: 40 | FH2: 40 | FI2: 40 | FJ2: 40 | FK2: 40 | FL2: 40 | FM2: 40 | FN2: 40 | FO2: 40 | FP2: 40 | FQ2: 40 | FR2: 40 | FS2: 40 | FT2: 40 | FU2: 40 | FV2: 40 | FW2: 40 | FX2: 40 | FY2: 40 | FZ2: 40 | GA2: 40 | GB2: 40 | GC2: 40 | GD2: 40 | GE2: 40 | GF2: 40 | GG2: 40 | GH2: 40 | GI2: 40 | GJ2: 40 | GK2: 40 | GL2: 40 | GM2: 40 | GN2: 40 | GO2: 40 | GP2: 40 | GQ2: 40 | GR2: 40 | GS2: 40 | GT2: 40 | GU2: 40 | GV2: 40 | GW2: 40 | GX2: 40 | GY2: 40 | GZ2: 40 | HA2: 40 | HB2: 40 | HC2: 40 | HD2: 40 | HE2: 40 | HF2: 40 | HG2: 40 | HH2: 40 | HI2: 40 | HJ2: 40 | HK2: 40 | HL2: 40 | HM2: 40 | HN2: 40 | HO2: 40 | HP2: 40 | HQ2: 40 | HR2: 40 | HS2: 40 | HT2: 40 | HU2: 40 | HV2: 40 | HW2: 40 | HX2: 40 | HY2: 40 | HZ2: 40 | IA2: 40 | IB2: 40 | IC2: 40 | ID2: 40 | IE2: 40 | IF2: 40 | IG2: 40 | IH2: 40 | II2: 40 | IJ2: 40 | IK2: 40 | IL2: 40 | IM2: 40 | IN2: 40 | IO2: 40 | IP2: 40 | IQ2: 40 | IR2: 40 | IS2: 40 | IT2: 40 | IU2: 40 | IV2: 40 | IW2: 40 | IX2: 40 | IY2: 40 | IZ2: 40 | JA2: 40 | JB2: 40 | JC2: 40 | JD2: 40 | JE2: 40 | JF2: 10480
A3: 2 | B3: 0.5 | C3: 33.8087 | D3: 38.5739 | E3: 39.2722 | F3: 38.3101 | G3: 37.0713 | H3: 36.1342 | I3: 37.469 | J3: 38.7017 | K3: 36.9451 | L3: 39.3726 | M3: 39.36 | N3: 36.054 | O3: 25.6393 | P3: 11.3743 | Q3: 38.6496 | R3: 37.6181 | S3: 34.3164 | T3: 35.2227 | U3: 28.3455 | V3: 39.4604 | W3: 38.2415 | X3: 38.5724 | Y3: 37.8265 | Z3: 39.5608 | AA3: 39.2222 | AB3: 33.6871 | AC3: 39.4228 | AD3: 37.0585 | AE3: 39.3475 | AF3: 38.6444 | AG3: 39.3349 | AH3: 38.0029 | AI3: 31.5423 | AJ3: 38.1509 | AK3: 37.3303 | AL3: 39.1181 | AM3: 39.2118 | AN3: 33.7262 | AO3: 39.1389 | AP3: 37.3799 | AQ3: 38.5265 | AR3: 38.7822 | AS3: 38.5298 | AT3: 38.7697 | AU3: 39.3224 | AV3: 37.142 | AW3: 39.4102 | AX3: 39.3851 | AY3: 39.3145 | AZ3: 39.4604 | BA3: 38.9858 | BB3: 38.113 | BC3: 38.0567 | BD3: 38.1166 | BE3: 38.3451 | BF3: 38.0053 | BG3: 37.9222 | BH3: 33.3477 | BI3: 39.2973 | BJ3: 38.4062 | BK3: 38.3468 | BL3: 37.3194 | BM3: 37.8314 | BN3: 36.7201 | BO3: 37.6999 | BP3: 32.307 | BQ3: 38.631 | BR3: 38.8151 | BS3: 39.611 | BT3: 37.2273 | BU3: 35.253 | BV3: 35.5687 | BW3: 37.1295 | BX3: 38.3716 | BY3: 35.2519 | BZ3: 38.6564 | CA3: 37.2409 | CB3: 38.3836 | CC3: 39.3977 | CD3: 39.3726 | CE3: 10 | CF3: 38.8061 | CG3: 39.4228 | CH3: 39.4981 | CI3: 33.4458 | CJ3: 38.3303 | CK3: 37.5324 | CL3: 31.7818 | CM3: 36.924 | CN3: 38.5438 | CO3: 39.2596 | CP3: 35.0878 | CQ3: 33.399 | CR3: 39.3349 | CS3: 35.4186 | CT3: 39.473 | CU3: 38.3239 | CV3: 39.2973 | CW3: 33.0624 | CX3: 37.1531 | CY3: 38.5061 | CZ3: 39.4102 | DA3: 34.9732 | DB3: 38.4137 | DC3: 37.8744 | DD3: 38.4524 | DE3: 38.8729 | DF3: 37.6874 | DG3: 39.3349 | DH3: 38.2704 | DI3: 36.4255 | DJ3: 17.5159 | DK3: 37.8865 | DL3: 39.2272 | DM3: 35.4453 | DN3: 38.7262 | DO3: 34.6598 | DP3: 37.1693 | DQ3: 37.8954 | DR3: 30.4645 | DS3: 39.3977 | DT3: 39.3977 | DU3: 29.8745 | DV3: 39.0783 | DW3: 37.4153 | DX3: 37.7938 | DY3: 37.9733 | DZ3: 38.0063 | EA3: 37.4238 | EB3: 38.5005 | EC3: 39.4228 | ED3: 39.3045 | EE3: 31.4953 | EF3: 38.5059 | EG3: 38.2603 | EH3: 38.6464 | EI3: 37.6121 | EJ3: 39.3475 | EK3: 38.816 | EL3: 37.2716 | EM3: 39.3726 | EN3: 39.3726 | EO3: 34.8571 | EP3: 39.3851 | EQ3: 37.6797 | ER3: 20.3589 | ES3: 21.2785 | ET3: 39.3224 | EU3: 39.4981 | EV3: 39.2722 | EW3: 36.774 | EX3: 38.9151 | EY3: 38.4395 | EZ3: 39.2847 | FA3: 36.4661 | FB3: 32.6188 | FC3: 39.5483 | FD3: 37.3751 | FE3: 31.1093 | FF3: 37.3478 | FG3: 39.473 | FH3: 39.3224 | FI3: 37.3177 | FJ3: 39.3349 | FK3: 39.2722 | FL3: 39.3851 | FM3: 39.3726 | FN3: 37.2981 | FO3: 38.0404 | FP3: 37.5893 | FQ3: 38.1937 | FR3: 37.7621 | FS3: 32.3426 | FT3: 39.3977 | FU3: 39.6361 | FV3: 35.3921 | FW3: 39.2166 | FX3: 37.9985 | FY3: 28.6891 | FZ3: 36.0669 | GA3: 39.5232 | GB3: 38.865 | GC3: 38.3752 | GD3: 38.5369 | GE3: 32.5501 | GF3: 37.3522 | GG3: 38.1804 | GH3: 38.042 | GI3: 35.5528 | GJ3: 31.1459 | GK3: 39.3726 | GL3: 26.5668 | GM3: 38.0977 | GN3: 27.1012 | GO3: 36.5773 | GP3: 39.4228 | GQ3: 39.2345 | GR3: 38.9205 | GS3: 37.4719 | GT3: 39.3851 | GU3: 36.3899 | GV3: 39.4353 | GW3: 39.3098 | GX3: 37.9396 | GY3: 39.2973 | GZ3: 27.9319 | HA3: 37.6201 | HB3: 39.4228 | HC3: 39.4228 | HD3: 35.2258 | HE3: 39.3977 | HF3: 39.3475 | HG3: 35.7366 | HH3: 39.5859 | HI3: 39.4228 | HJ3: 38.021 | HK3: 39.3224 | HL3: 32.4785 | HM3: 39.0983 | HN3: 38.1876 | HO3: 37.9289 | HP3: 38.3509 | HQ3: 38.1364 | HR3: 39.3977 | HS3: 38.1296 | HT3: 38.1451 | HU3: 38.6251 | HV3: 38.9835 | HW3: 39.3224 | HX3: 39.2471 | HY3: 39.4855 | HZ3: 39.3475 | IA3: 39.3349 | IB3: 39.3096 | IC3: 39.4604 | ID3: 38.1311 | IE3: 39.0128 | IF3: 38.2699 | IG3: 31.9831 | IH3: 39.3349 | II3: 21.0899 | IJ3: 31.4304 | IK3: 38.7202 | IL3: 39.2722 | IM3: 38.3305 | IN3: 37.8898 | IO3: 37.4058 | IP3: 35.3608 | IQ3: 37.4831 | IR3: 36.9563 | IS3: 38.4466 | IT3: 32.7895 | IU3: 35.7597 | IV3: 38.9463 | IW3: 38.3828 | IX3: 37.0941 | IY3: 33.8766 | IZ3: 36.0893 | JA3: 38.7955 | JB3: 37.6558 | JC3: 32.6612 | JD3: 39.2408 | JE3: 36.959162 | JF3: 9683.3004
A4: 3 | B4: 1 | C4: 26.9034 | D4: 37.9213 | E4: 38.5444 | F4: 35.1299 | G4: 34.7472 | H4: 35.4691 | I4: 34.1689 | J4: 35.3719 | K4: 36.3428 | L4: 38.1836 | M4: 37.9472 | N4: 30.207 | O4: 18.9001 | P4: 10 | Q4: 37.5256 | R4: 35.6504 | S4: 33.7517 | T4: 33.0822 | U4: 21.7861 | V4: 37.8869 | W4: 35.6577 | X4: 37.9199 | Y4: 36.1145 | Z4: 39.1216 | AA4: 36.4399 | AB4: 30.1956 | AC4: 37.744 | AD4: 35.2685 | AE4: 38.695 | AF4: 35.3217 | AG4: 38.6699 | AH4: 36.4751 | AI4: 30.0023 | AJ4: 37.5611 | AK4: 36.0329 | AL4: 38.2361 | AM4: 38.7224 | AN4: 31.7616 | AO4: 35.7882 | AP4: 35.4345 | AQ4: 37.9744 | AR4: 37.3801 | AS4: 33.4811 | AT4: 38.1046 | AU4: 36.9725 | AV4: 35.5693 | AW4: 36.3408 | AX4: 36.3911 | AY4: 37.7295 | AZ4: 36.6351 | BA4: 35.7102 | BB4: 36.7604 | BC4: 37.4293 | BD4: 36.5926 | BE4: 35.2892 | BF4: 37.3654 | BG4: 37.3199 | BH4: 24.2281 | BI4: 38.5946 | BJ4: 37.9544 | BK4: 36.1324 | BL4: 36.7798 | BM4: 35.9641 | BN4: 34.8331 | BO4: 34.6832 | BP4: 29.7978 | BQ4: 36.7248 | BR4: 38.3131 | BS4: 38.0217 | BT4: 36.5998 | BU4: 30.4581 | BV4: 29.254 | BW4: 36.0748 | BX4: 36.7432 | BY4: 32.5399 | BZ4: 38.0666 | CA4: 35.9362 | CB4: 37.7186 | CC4: 38.7953 | CD4: 38.7451 | CE4: 10 | CF4: 37.4957 | CG4: 37.3267 | CH4: 38.1337 | CI4: 32.2339 | CJ4: 37.7029 | CK4: 36.8423 | CL4: 23.0833 | CM4: 32.0516 | CN4: 38.0293 | CO4: 35.5823 | CP4: 34.4981 | CQ4: 27.794 | CR4: 37.6874 | CS4: 34.9292 | CT4: 37.8818 | CU4: 36.1661 | CV4: 36.7766 | CW4: 31.3678 | CX4: 36.2766 | CY4: 36.8114 | CZ4: 36.4716 | DA4: 33.8306 | DB4: 36.8274 | DC4: 36.959 | DD4: 35.5423 | DE4: 36.3837 | DF4: 36.8313 | DG4: 38.6699 | DH4: 35.7007 | DI4: 33.4545 | DJ4: 12.8768 | DK4: 36.8302 | DL4: 34.9693 | DM4: 34.981 | DN4: 36.7136 | DO4: 33.9194 | DP4: 36.5042 | DQ4: 37.1927 | DR4: 29.812 | DS4: 38.7953 | DT4: 37.4537 | DU4: 24.0473 | DV4: 37.1348 | DW4: 36.7126 | DX4: 36.1915 | DY4: 36.2218 | DZ4: 34.7877 | EA4: 36.7712 | EB4: 37.8354 | EC4: 38.8455 | ED4: 37.8551 | EE4: 27.7624 | EF4: 37.2495 | EG4: 37.5826 | EH4: 36.1718 | EI4: 37.0223 | EJ4: 38.2482 | EK4: 36.939 | EL4: 34.903 | EM4: 38.7451 | EN4: 37.7538 | EO4: 28.7594 | EP4: 38.0053 | EQ4: 36.0729 | ER4: 19.6311 | ES4: 18.7941 | ET4: 36.9587 | EU4: 38.2973 | EV4: 35.4681 | EW4: 36.0713 | EX4: 36.9631 | EY4: 37.1585 | EZ4: 38.5695 | FA4: 33.9148 | FB4: 22.8148 | FC4: 37.6323 | FD4: 36.0771 | FE4: 20.3663 | FF4: 36.6451 | FG4: 38.0301 | FH4: 37.8478 | FI4: 36.7404 | FJ4: 37.818 | FK4: 38.5444 | FL4: 38.7702 | FM4: 37.7337 | FN4: 34.4711 | FO4: 37.3628 | FP4: 35.4035 | FQ4: 37.5788 | FR4: 36.4916 | FS4: 29.4504 | FT4: 38.7953 | FU4: 39.2722 | FV4: 29.7812 | FW4: 36.8089 | FX4: 34.8652 | FY4: 18.7189 | FZ4: 35.4395 | GA4: 39.0463 | GB4: 38.2502 | GC4: 37.3424 | GD4: 37.4676 | GE4: 25.3666 | GF4: 36.7749 | GG4: 35.6926 | GH4: 34.3608 | GI4: 31.8511 | GJ4: 29.4418 | GK4: 36.5823 | GL4: 13.4783 | GM4: 33.0317 | GN4: 12.3638 | GO4: 35.9625 | GP4: 37.4295 | GQ4: 38.4691 | GR4: 36.9622 | GS4: 36.832 | GT4: 38.7702 | GU4: 31.6843 | GV4: 35.6112 | GW4: 37.7171 | GX4: 37.3373 | GY4: 38.5946 | GZ4: 20.9535 | HA4: 34.3433 | HB4: 38.0782 | HC4: 35.5353 | HD4: 33.6607 | HE4: 36.7682 | HF4: 38.695 | HG4: 35.0715 | HH4: 39.1718 | HI4: 36.9205 | HJ4: 36.5311 | HK4: 37.1653 | HL4: 25.6494 | HM4: 38.5712 | HN4: 35.3034 | HO4: 37.3391 | HP4: 37.6607 | HQ4: 35.998 | HR4: 38.2553 | HS4: 36.3846 | HT4: 36.8163 | HU4: 37.9728 | HV4: 35.4753 | HW4: 38.6448 | HX4: 36.2007 | HY4: 38.0805 | HZ4: 37.8592 | IA4: 38.6699 | IB4: 35.2948 | IC4: 38.9208 | ID4: 37.1009 | IE4: 36.5499 | IF4: 37.2778 | IG4: 31.3557 | IH4: 38.6699 | II4: 18.2271 | IJ4: 29.5651 | IK4: 37.0442 | IL4: 36.7647 | IM4: 36.1646 | IN4: 35.3525 | IO4: 35.9815 | IP4: 34.746 | IQ4: 36.931 | IR4: 32.8328 | IS4: 38.0074 | IT4: 26.2944 | IU4: 35.1072 | IV4: 37.0566 | IW4: 36.4574 | IX4: 36.3914 | IY4: 29.1853 | IZ4: 32.9196 | JA4: 35.8626 | JB4: 35.3598 | JC4: 24.9122 | JD4: 36.9214 | JE4: 34.772638 | JF4: 9110.4312
A5: 4 | B5: 1.5 | C5: 25.0186 | D5: 36.9594 | E5: 34.5883 | F5: 33.6993 | G5: 32.0761 | H5: 33.9469 | I5: 31.7433 | J5: 32.4776 | K5: 32.2442 | L5: 36.7138 | M5: 36.3798 | N5: 29.6046 | O5: 16.8311 | P5: 10 | Q5: 36.7978 | R5: 33.1915 | S5: 30.4619 | T5: 18.324 | U5: 20.8382 | V5: 37.0653 | W5: 35.1808 | X5: 36.3954 | Y5: 34.6804 | Z5: 38.6824 | AA5: 35.7623 | AB5: 22.586 | AC5: 35.7678 | AD5: 34.5407 | AE5: 36.5861 | AF5: 35.0581 | AG5: 38.0048 | AH5: 35.9355 | AI5: 26.735 | AJ5: 33.8288 | AK5: 35.3678 | AL5: 35.7959 | AM5: 38.233 | AN5: 29.2895 | AO5: 28.0911 | AP5: 34.1951 | AQ5: 35.5795 | AR5: 36.7151 | AS5: 32.2624 | AT5: 36.8177 | AU5: 35.9232 | AV5: 35.1929 | AW5: 33.0993 | AX5: 35.7762 | AY5: 36.9388 | AZ5: 36.0955 | BA5: 35.0074 | BB5: 35.5349 | BC5: 36.8019 | BD5: 35.8774 | BE5: 34.6241 | BF5: 35.1317 | BG5: 35.2421 | BH5: 22.6139 | BI5: 37.8919 | BJ5: 36.6293 | BK5: 33.1396 | BL5: 36.2403 | BM5: 34.0631 | BN5: 33.6842 | BO5: 32.7801 | BP5: 29.208 | BQ5: 36.0722 | BR5: 37.8112 | BS5: 37.4209 | BT5: 33.9246 | BU5: 29.6926 | BV5: 20.3386 | BW5: 32.0696 | BX5: 35.3348 | BY5: 31.8623 | BZ5: 36.0634 | CA5: 32.3051 | CB5: 36.2079 | CC5: 38.193 | CD5: 38.1177 | CE5: 10 | CF5: 36.7679 | CG5: 34.6803 | CH5: 36.0661 | CI5: 30.5964 | CJ5: 36.6194 | CK5: 31.9703 | CL5: 17.067 | CM5: 28.6746 | CN5: 36.5731 | CO5: 34.8419 | CP5: 33.9083 | CQ5: 27.1415 | CR5: 37.0223 | CS5: 34.4398 | CT5: 36.1327 | CU5: 34.7589 | CV5: 34.8675 | CW5: 29.1091 | CX5: 34.4149 | CY5: 36.322 | CZ5: 35.77 | DA5: 30.6442 | DB5: 36.2753 | DC5: 33.9065 | DD5: 34.8387 | DE5: 35.8817 | DF5: 33.772 | DG5: 38.0048 | DH5: 34.5123 | DI5: 30.9728 | DJ5: 11.4012 | DK5: 34.8612 | DL5: 33.6591 | DM5: 34.5167 | DN5: 36.0861 | DO5: 31.1652 | DP5: 34.9626 | DQ5: 36.49 | DR5: 27.8437 | DS5: 38.193 | DT5: 36.8514 | DU5: 18.5925 | DV5: 36.4321 | DW5: 34.2551 | DX5: 33.398 | DY5: 33.7974 | DZ5: 33.6996 | EA5: 34.282 | EB5: 33.9943 | EC5: 38.2683 | ED5: 36.2151 | EE5: 26.0916 | EF5: 34.7626 | EG5: 36.3149 | EH5: 34.653 | EI5: 34.7979 | EJ5: 36.5531 | EK5: 34.5141 | EL5: 34.2881 | EM5: 38.1177 | EN5: 35.3058 | EO5: 21.4381 | EP5: 37.3904 | EQ5: 32.6179 | ER5: 18.3601 | ES5: 18.1165 | ET5: 36.2811 | EU5: 36.2978 | EV5: 34.2164 | EW5: 35.3686 | EX5: 36.3984 | EY5: 36.5059 | EZ5: 37.8542 | FA5: 32.2941 | FB5: 22.1623 | FC5: 37.1805 | FD5: 33.2871 | FE5: 11.8444 | FF5: 35.9424 | FG5: 37.503 | FH5: 37.1702 | FI5: 34.4408 | FJ5: 37.1529 | FK5: 36.5275 | FL5: 36.9146 | FM5: 37.1063 | FN5: 33.8436 | FO5: 36.6852 | FP5: 34.4095 | FQ5: 35.7725 | FR5: 34.8872 | FS5: 28.1418 | FT5: 38.193 | FU5: 38.9083 | FV5: 27.6186 | FW5: 36.332 | FX5: 32.2566 | FY5: 10 | FZ5: 32.0197 | GA5: 37.3072 | GB5: 35.4791 | GC5: 35.9544 | GD5: 36.7852 | GE5: 18.3028 | GF5: 32.8051 | GG5: 33.5465 | GH5: 32.8398 | GI5: 29.168 | GJ5: 27.5772 | GK5: 35.9549 | GL5: 12.7457 | GM5: 24.9133 | GN5: 11.6485 | GO5: 32.2315 | GP5: 35.9323 | GQ5: 36.7888 | GR5: 36.41 | GS5: 34.2265 | GT5: 38.1554 | GU5: 28.9769 | GV5: 34.508 | GW5: 34.9862 | GX5: 33.4618 | GY5: 37.8919 | GZ5: 10.4699 | HA5: 33.3504 | HB5: 35.6844 | HC5: 34.8166 | HD5: 33.0584 | HE5: 36.1658 | HF5: 38.0424 | HG5: 33.0421 | HH5: 38.7577 | HI5: 36.3433 | HJ5: 34.1574 | HK5: 36.1786 | HL5: 18.779 | HM5: 38.0442 | HN5: 33.2821 | HO5: 34.5703 | HP5: 36.571 | HQ5: 33.2316 | HR5: 36.2128 | HS5: 35.3427 | HT5: 36.1888 | HU5: 35.864 | HV5: 34.8604 | HW5: 35.7683 | HX5: 34.2929 | HY5: 37.566 | HZ5: 35.8356 | IA5: 38.0048 | IB5: 34.5209 | IC5: 34.0085 | ID5: 36.5738 | IE5: 34.8301 | IF5: 36.5626 | IG5: 30.7283 | IH5: 38.0048 | II5: 16.4836 | IJ5: 27.7664 | IK5: 35.1522 | IL5: 35.8089 | IM5: 34.8658 | IN5: 34.6749 | IO5: 35.2765 | IP5: 33.2446 | IQ5: 36.3788 | IR5: 28.7162 | IS5: 37.5682 | IT5: 10 | IU5: 31.4801 | IV5: 36.5044 | IW5: 34.5131 | IX5: 34.2866 | IY5: 26.5654 | IZ5: 32.2295 | JA5: 35.4485 | JB5: 34.7324 | JC5: 24.3081 | JD5: 35.2296 | JE5: 32.877325 | JF5: 8613.8591
A6: 5 | B6: 2 | C6: 22.5017 | D6: 35.0691 | E6: 33.8605 | F6: 31.7208 | G6: 31.3859 | H6: 33.2818 | I6: 30.9891 | J6: 27.6632 | K6: 30.3466 | L6: 36.0864 | M6: 35.7398 | N6: 28.1124 | O6: 15.3262 | P6: 10 | Q6: 36.07 | R6: 32.4385 | S6: 27.5034 | T6: 14.905 | U6: 18.0055 | V6: 36.4289 | W6: 33.7463 | X6: 35.7429 | Y6: 32.8766 | Z6: 38.2432 | AA6: 33.882 | AB6: 19.0202 | AC6: 35.117 | AD6: 33.0064 | AE6: 34.9253 | AF6: 33.877 | AG6: 37.3397 | AH6: 35.3959 | AI6: 25.0851 | AJ6: 32.8792 | AK6: 34.7028 | AL6: 35.2062 | AM6: 36.847 | AN6: 28.6746 | AO6: 19.2355 | AP6: 31.3222 | AQ6: 34.6178 | AR6: 34.7603 | AS6: 31.6099 | AT6: 35.757 | AU6: 34.874 | AV6: 31.4804 | AW6: 28.4589 | AX6: 33.2148 | AY6: 36.2988 | AZ6: 35.0364 | BA6: 33.3703 | BB6: 34.1793 | BC6: 36.1745 | BD6: 33.365 | BE6: 32.3495 | BF6: 34.4917 | BG6: 34.6398 | BH6: 20.7063 | BI6: 37.1891 | BJ6: 35.8417 | BK6: 31.8158 | BL6: 35.0194 | BM6: 30.7725 | BN6: 29.6806 | BO6: 29.9816 | BP6: 25.9875 | BQ6: 33.4495 | BR6: 36.6263 | BS6: 36.3964 | BT6: 33.1997 | BU6: 26.8705 | BV6: 15.7113 | BW6: 31.4171 | BX6: 33.9863 | BY6: 31.1847 | BZ6: 34.8141 | CA6: 31.3767 | CB6: 35.4371 | CC6: 36.5566 | CD6: 37.4903 | CE6: 10 | CF6: 35.108 | CG6: 34.1031 | CH6: 35.2767 | CI6: 29.8811 | CJ6: 35.1451 | CK6: 31.0933 | CL6: 15.9211 | CM6: 27.9969 | CN6: 36.0586 | CO6: 32.237 | CP6: 33.3185 | CQ6: 26.489 | CR6: 36.3572 | CS6: 33.9504 | CT6: 31.7325 | CU6: 33.7395 | CV6: 33.6 | CW6: 26.8357 | CX6: 32.5532 | CY6: 33.9241 | CZ6: 34.1736 | DA6: 30.1925 | DB6: 35.6292 | DC6: 32.0732 | DD6: 33.4255 | DE6: 34.464 | DF6: 33.0818 | DG6: 37.3397 | DH6: 32.5113 | DI6: 28.0846 | DJ6: 10.0207 | DK6: 33.8049 | DL6: 31.9083 | DM6: 31.9158 | DN6: 34.5353 | DO6: 27.2029 | DP6: 33.0394 | DQ6: 34.3854 | DR6: 26.2803 | DS6: 37.5907 | DT6: 36.2491 | DU6: 13.9177 | DV6: 35.7294 | DW6: 31.6704 | DX6: 31.7957 | DY6: 31.8439 | DZ6: 30.5304 | EA6: 32.7609 | EB6: 33.3293 | EC6: 37.6911 | ED6: 35.5752 | EE6: 23.539 | EF6: 33.3557 | EG6: 35.1653 | EH6: 32.1901 | EI6: 34.0446 | EJ6: 35.9006 | EK6: 32.2264 | EL6: 33.1853 | EM6: 37.4903 | EN6: 33.9998 | EO6: 13.4262 | EP6: 36.0106 | EQ6: 31.5698 | ER6: 16.1841 | ES6: 14.7368 | ET6: 33.9175 | EU6: 35.7958 | EV6: 31.4714 | EW6: 34.6659 | EX6: 33.9262 | EY6: 35.3645 | EZ6: 37.1389 | FA6: 30.9983 | FB6: 21.5098 | FC6: 36.7288 | FD6: 31.9931 | FE6: 10 | FF6: 35.2396 | FG6: 36.976 | FH6: 36.3155 | FI6: 33.4809 | FJ6: 36.1093 | FK6: 35.1981 | FL6: 35.9896 | FM6: 36.4788 | FN6: 30.1952 | FO6: 34.6269 | FP6: 31.5308 | FQ6: 35.1576 | FR6: 32.0689 | FS6: 26.0786 | FT6: 37.5907 | FU6: 38.5444 | FV6: 20.7867 | FW6: 34.4061 | FX6: 31.5418 | FY6: 10 | FZ6: 30.3774 | GA6: 36.8304 | GB6: 33.5423 | GC6: 34.6847 | GD6: 33.9885 | GE6: 17.575 | GF6: 31.683 | GG6: 29.1769 | GH6: 30.0511 | GI6: 28.5782 | GJ6: 25.2371 | GK6: 33.9512 | GL6: 10 | GM6: 16.4256 | GN6: 10 | GO6: 30.9912 | GP6: 32.3194 | GQ6: 36.0233 | GR6: 33.9243 | GS6: 33.2762 | GT6: 37.5405 | GU6: 28.2742 | GV6: 33.8677 | GW6: 34.2961 | GX6: 32.6021 | GY6: 37.1891 | GZ6: 10 | HA6: 30.0944 | HB6: 34.7744 | HC6: 33.3384 | HD6: 30.9748 | HE6: 35.5635 | HF6: 37.3899 | HG6: 29.9944 | HH6: 37.8926 | HI6: 34.366 | HJ6: 32.4294 | HK6: 35.1477 | HL6: 10.5436 | HM6: 35.4564 | HN6: 31.3623 | HO6: 33.0452 | HP6: 34.5223 | HQ6: 31.0124 | HR6: 34.6331 | HS6: 34.9161 | HT6: 35.5614 | HU6: 34.4734 | HV6: 32.3177 | HW6: 35.0906 | HX6: 31.9065 | HY6: 36.161 | HZ6: 35.183 | IA6: 37.3397 | IB6: 32.9408 | IC6: 31.2576 | ID6: 34.2018 | IE6: 32.5116 | IF6: 34.5556 | IG6: 30.1009 | IH6: 37.3397 | II6: 14.5113 | IJ6: 27.0888 | IK6: 34.5247 | IL6: 33.424 | IM6: 33.7379 | IN6: 31.382 | IO6: 32.4254 | IP6: 31.0155 | IQ6: 34.0867 | IR6: 25.8137 | IS6: 34.9946 | IT6: 10 | IU6: 30.1285 | IV6: 34.7819 | IW6: 33.1575 | IX6: 32.7827 | IY6: 25.8878 | IZ6: 31.5393 | JA6: 33.2672 | JB6: 31.0369 | JC6: 22.8718 | JD6: 33.2032 | JE6: 31.206634 | JF6: 8176.138
A7: 6 | B7: 2.5 | C7: 21.4928 | D7: 34.4165 | E7: 30.2281 | F7: 28.4076 | G7: 29.3513 | H7: 32.6168 | I7: 28.5777 | J7: 20.9388 | K7: 28.7259 | L7: 34.3358 | M7: 33.3995 | N7: 27.3988 | O7: 12.7976 | P7: 10 | Q7: 35.3422 | R7: 30.0218 | S7: 26.9388 | T7: 14.0079 | U7: 17.2903 | V7: 33.8564 | W7: 32.1202 | X7: 35.0904 | Y7: 32.2743 | Z7: 37.804 | AA7: 32.2022 | AB7: 16.6285 | AC7: 33.1408 | AD7: 29.8092 | AE7: 34.2728 | AF7: 31.3391 | AG7: 36.6746 | AH7: 34.8564 | AI7: 23.2977 | AJ7: 30.2503 | AK7: 32.8434 | AL7: 32.4738 | AM7: 36.3576 | AN7: 28.0598 | AO7: 12.7001 | AP7: 28.9047 | AQ7: 34.0657 | AR7: 34.0952 | AS7: 29.8248 | AT7: 35.0919 | AU7: 32.5241 | AV7: 30.7622 | AW7: 20.9501 | AX7: 32.1673 | AY7: 35.6588 | AZ7: 32.7306 | BA7: 30.7176 | BB7: 32.2272 | BC7: 34.297 | BD7: 32.47 | BE7: 29.9133 | BF7: 33.533 | BG7: 34.0375 | BH7: 18.2266 | BI7: 36.4864 | BJ7: 35.39 | BK7: 30.8409 | BL7: 33.0201 | BM7: 28.7914 | BN7: 28.9425 | BO7: 28.2135 | BP7: 25.22 | BQ7: 32.797 | BR7: 34.9291 | BS7: 35.2307 | BT7: 32.0847 | BU7: 26.1051 | BV7: 12.7654 | BW7: 30.6103 | BX7: 32.078 | BY7: 30.507 | BZ7: 34.168 | CA7: 29.7244 | CB7: 34.2435 | CC7: 35.9543 | CD7: 36.8629 | CE7: 10 | CF7: 34.2636 | CG7: 33.5259 | CH7: 33.8083 | CI7: 29.1658 | CJ7: 34.5177 | CK7: 29.7469 | CL7: 13.911 | CM7: 27.3193 | CN7: 34.6023 | CO7: 30.4242 | CP7: 31.7185 | CQ7: 25.8365 | CR7: 34.7097 | CS7: 33.461 | CT7: 25.9205 | CU7: 31.0256 | CV7: 32.2071 | CW7: 26.1205 | CX7: 31.7752 | CY7: 33.1334 | CZ7: 32.1297 | DA7: 27.0983 | DB7: 33.1027 | DC7: 31.2996 | DD7: 32.8232 | DE7: 32.4328 | DF7: 30.9351 | DG7: 36.6746 | DH7: 30.157 | DI7: 26.2189 | DJ7: 10 | DK7: 33.182 | DL7: 29.9032 | DM7: 31.4515 | DN7: 32.7997 | DO7: 26.4625 | DP7: 30.3566 | DQ7: 33.6827 | DR7: 25.4254 | DS7: 36.9884 | DT7: 34.3052 | DU7: 10 | DV7: 34.0049 | DW7: 30.9677 | DX7: 31.1557 | DY7: 30.2763 | DZ7: 29.8402 | EA7: 31.0924 | EB7: 32.6642 | EC7: 37.1138 | ED7: 34.1018 | EE7: 23.0497 | EF7: 30.5894 | EG7: 33.8386 | EH7: 31.486 | EI7: 32.3106 | EJ7: 34.9502 | EK7: 30.719 | EL7: 31.0211 | EM7: 36.8629 | EN7: 32.7693 | EO7: 11.2606 | EP7: 35.3957 | EQ7: 28.4717 | ER7: 15.4563 | ES7: 12.3913 | ET7: 33.2399 | EU7: 33.5967 | EV7: 28.9685 | EW7: 33.5044 | EX7: 33.3615 | EY7: 33.6644 | EZ7: 36.4237 | FA7: 28.3658 | FB7: 19.6479 | FC7: 35.3253 | FD7: 30.0623 | FE7: 10 | FF7: 32.5874 | FG7: 36.449 | FH7: 33.2985 | FI7: 32.0425 | FJ7: 34.971 | FK7: 34.0407 | FL7: 35.3747 | FM7: 35.8514 | FN7: 28.3147 | FO7: 33.9493 | FP7: 30.2297 | FQ7: 33.7683 | FR7: 31.2772 | FS7: 23.941 | FT7: 36.9884 | FU7: 38.1805 | FV7: 17.885 | FW7: 33.1409 | FX7: 27.9013 | FY7: 10 | FZ7: 28.0004 | GA7: 36.3535 | GB7: 32.3612 | GC7: 33.5335 | GD7: 33.1483 | GE7: 13.929 | GF7: 30.5608 | GG7: 27.2406 | GH7: 29.0116 | GI7: 27.0215 | GJ7: 23.0538 | GK7: 32.5373 | GL7: 10 | GM7: 10 | GN7: 10 | GO7: 30.3764 | GP7: 31.6005 | GQ7: 31.5551 | GR7: 33.3722 | GS7: 32.6362 | GT7: 36.9256 | GU7: 27.5715 | GV7: 29.5808 | GW7: 32.07 | GX7: 31.9998 | GY7: 36.4864 | GZ7: 10 | HA7: 27.9588 | HB7: 32.2787 | HC7: 31.3133 | HD7: 30.3725 | HE7: 34.662 | HF7: 36.4899 | HG7: 28.9073 | HH7: 37.0276 | HI7: 33.2638 | HJ7: 30.7958 | HK7: 34.0285 | HL7: 10 | HM7: 34.9294 | HN7: 30.1534 | HO7: 32.0105 | HP7: 33.8321 | HQ7: 30.41 | HR7: 32.0505 | HS7: 32.5183 | HT7: 33.0051 | HU7: 33.2714 | HV7: 30.3357 | HW7: 32.514 | HX7: 29.5862 | HY7: 35.6465 | HZ7: 32.3237 | IA7: 36.6746 | IB7: 28.5301 | IC7: 28.4387 | ID7: 33.6747 | IE7: 30.2876 | IF7: 33.8404 | IG7: 29.4734 | IH7: 36.6746 | II7: 10.5211 | IJ7: 26.4112 | IK7: 31.5842 | IL7: 32.3456 | IM7: 31.1159 | IN7: 30.3043 | IO7: 31.1552 | IP7: 29.9282 | IQ7: 31.9032 | IR7: 25.1236 | IS7: 33.8838 | IT7: 10 | IU7: 28.8533 | IV7: 33.561 | IW7: 31.1576 | IX7: 32.08 | IY7: 24.2193 | IZ7: 28.7078 | JA7: 31.4654 | JB7: 24.217 | JC7: 22.3196 | JD7: 31.3323 | JE7: 29.666644 | JF7: 7772.6607
A8: 7 | B8: 3 | C8: 18.7875 | D8: 32.2168 | E8: 29.1766 | F8: 27.3987 | G8: 28.6611 | H8: 31.9517 | I8: 27.0098 | J8: 15.2277 | K8: 26.941 | L8: 33.4276 | M8: 32.7596 | N8: 25.9066 | O8: 10.3268 | P8: 10 | Q8: 34.6144 | R8: 28.0119 | S8: 22.7471 | T8: 12.1025 | U8: 16.575 | V8: 32.5649 | W8: 31.4518 | X8: 33.5659 | Y8: 29.6387 | Z8: 37.3648 | AA8: 31.2239 | AB8: 14.4454 | AC8: 31.5357 | AD8: 29.0814 | AE8: 31.1556 | AF8: 30.1163 | AG8: 36.0096 | AH8: 34.3168 | AI8: 20.5802 | AJ8: 28.1973 | AK8: 31.9675 | AL8: 31.884 | AM8: 35.8682 | AN8: 25.7565 | AO8: 10 | AP8: 26.6091 | AQ8: 31.3637 | AR8: 32.5089 | AS8: 28.8892 | AT8: 34.4268 | AU8: 31.8465 | AV8: 28.3554 | AW8: 19.4957 | AX8: 31.5524 | AY8: 35.0188 | AZ8: 32.191 | BA8: 30.0149 | BB8: 29.6386 | BC8: 33.6038 | BD8: 30.8562 | BE8: 29.1996 | BF8: 31.618 | BG8: 33.4351 | BH8: 16.6075 | BI8: 35.7837 | BJ8: 34.7367 | BK8: 27.1196 | BL8: 32.4805 | BM8: 26.4673 | BN8: 24.5885 | BO8: 26.3518 | BP8: 23.7768 | BQ8: 32.1445 | BR8: 34.4272 | BS8: 34.8417 | BT8: 29.7995 | BU8: 25.3396 | BV8: 11.0219 | BW8: 26.4577 | BX8: 31.4757 | BY8: 28.9972 | BZ8: 31.736 | CA8: 26.9298 | CB8: 33.1557 | CC8: 35.352 | CD8: 36.2354 | CE8: 10 | CF8: 33.0115 | CG8: 30.7028 | CH8: 32.0363 | CI8: 28.3087 | CJ8: 32.5874 | CK8: 26.8144 | CL8: 13.2835 | CM8: 26.6417 | CN8: 34.0878 | CO8: 29.6838 | CP8: 31.1287 | CQ8: 25.1839 | CR8: 34.0446 | CS8: 32.9716 | CT8: 19.1183 | CU8: 30.0711 | CV8: 31.5044 | CW8: 22.786 | CX8: 30.3075 | CY8: 32.644 | CZ8: 31.54 | DA8: 26.291 | DB8: 32.5506 | DC8: 27.1873 | DD8: 29.576 | DE8: 31.9308 | DF8: 29.1664 | DG8: 36.0096 | DH8: 29.1369 | DI8: 24.2747 | DJ8: 10 | DK8: 31.1408 | DL8: 27.3183 | DM8: 29.8218 | DN8: 32.1723 | DO8: 25.7222 | DP8: 29.5746 | DQ8: 31.5781 | DR8: 22.7487 | DS8: 36.386 | DT8: 33.7028 | DU8: 10 | DV8: 32.8643 | DW8: 26.6282 | DX8: 28.442 | DY8: 28.072 | DZ8: 27.1486 | EA8: 28.7506 | EB8: 28.8231 | EC8: 36.5366 | ED8: 33.2952 | EE8: 21.146 | EF8: 29.2541 | EG8: 32.7479 | EH8: 30.959 | EI8: 31.067 | EJ8: 33.1062 | EK8: 29.0281 | EL8: 27.6973 | EM8: 36.2354 | EN8: 29.2545 | EO8: 10.5579 | EP8: 34.3134 | EQ8: 27.0668 | ER8: 12.7371 | ES8: 11.7137 | ET8: 31.2977 | EU8: 32.5956 | EV8: 27.2002 | EW8: 30.7372 | EX8: 32.7968 | EY8: 33.0119 | EZ8: 35.7084 | FA8: 26.208 | FB8: 18.9954 | FC8: 34.361 | FD8: 27.346 | FE8: 10 | FF8: 31.8847 | FG8: 35.057 | FH8: 31.6219 | FI8: 30.2213 | FJ8: 34.3059 | FK8: 31.8519 | FL8: 34.7598 | FM8: 34.2125 | FN8: 26.7919 | FO8: 31.8911 | FP8: 27.7502 | FQ8: 32.7364 | FR8: 29.7744 | FS8: 22.7987 | FT8: 36.386 | FU8: 37.8166 | FV8: 13.7012 | FW8: 32.6641 | FX8: 25.8998 | FY8: 10 | FZ8: 26.2954 | GA8: 34.6144 | GB8: 28.8344 | GC8: 32.8559 | GD8: 31.8874 | GE8: 12.2977 | GF8: 26.745 | GG8: 24.9302 | GH8: 25.4139 | GI8: 24.6943 | GJ8: 22.4641 | GK8: 31.6149 | GL8: 10 | GM8: 10 | GN8: 10 | GO8: 27.5829 | GP8: 31.0233 | GQ8: 23.6193 | GR8: 32.82 | GS8: 31.1687 | GT8: 36.3107 | GU8: 25.7898 | GV8: 28.9405 | GW8: 29.9725 | GX8: 28.8963 | GY8: 35.7837 | GZ8: 10 | HA8: 26.0227 | HB8: 31.7015 | HC8: 30.5239 | HD8: 28.2889 | HE8: 32.863 | HF8: 34.2699 | HG8: 27.8202 | HH8: 36.6135 | HI8: 32.6866 | HJ8: 30.1684 | HK8: 33.3509 | HL8: 10 | HM8: 33.8403 | HN8: 26.3431 | HO8: 30.8645 | HP8: 33.142 | HQ8: 27.6436 | HR8: 30.4709 | HS8: 30.6855 | HT8: 32.3777 | HU8: 31.5153 | HV8: 29.7209 | HW8: 31.5365 | HX8: 26.9524 | HY8: 34.2414 | HZ8: 31.6711 | IA8: 36.0096 | IB8: 25.0121 | IC8: 26.9553 | ID8: 33.1477 | IE8: 29.5163 | IF8: 32.8483 | IG8: 28.846 | IH8: 36.0096 | II8: 10 | IJ8: 24.6126 | IK8: 30.9567 | IL8: 31.6178 | IM8: 29.304 | IN8: 24.0143 | IO8: 30.0906 | IP8: 27.285 | IQ8: 31.3511 | IR8: 24.4334 | IS8: 32.9785 | IT8: 10 | IU8: 25.6649 | IV8: 33.0089 | IW8: 30.2515 | IX8: 30.1756 | IY8: 21.5995 | IZ8: 27.6795 | JA8: 29.6922 | JB8: 22.3097 | JC8: 20.8313 | JD8: 28.4873 | JE8: 28.153251 | JF8: 7376.1517
A9: 8 | B9: 3.5 | C9: 16.7474 | D9: 31.5643 | E9: 26.5153 | F9: 24.6037 | G9: 26.8543 | H9: 31.0486 | I9: 25.1581 | J9: 11.9419 | K9: 25.7793 | L9: 32.8002 | M9: 31.0376 | N9: 25.193 | O9: 10 | P9: 10 | Q9: 32.8678 | R9: 26.8537 | S9: 22.0974 | T9: 11.6256 | U9: 13.9751 | V9: 30.4933 | W9: 29.0596 | X9: 32.9134 | Y9: 27.9267 | Z9: 36.9256 | AA9: 28.6421 | AB9: 12.3836 | AC9: 29.854 | AD9: 26.6766 | AE9: 30.5031 | AF9: 29.8528 | AG9: 35.3445 | AH9: 33.7772 | AI9: 19.4526 | AJ9: 26.8938 | AK9: 30.2486 | AL9: 30.4178 | AM9: 35.08 | AN9: 24.9728 | AO9: 10 | AP9: 25.6079 | AQ9: 30.7092 | AR9: 31.4754 | AS9: 28.2366 | AT9: 33.7618 | AU9: 30.8901 | AV9: 27.3569 | AW9: 18.855 | AX9: 29.8561 | AY9: 34.3789 | AZ9: 30.1969 | BA9: 29.3122 | BB9: 28.9986 | BC9: 32.9764 | BD9: 29.0627 | BE9: 27.7071 | BF9: 30.8983 | BG9: 31.3573 | BH9: 11.9307 | BI9: 35.081 | BJ9: 33.2772 | BK9: 26.2729 | BL9: 31.357 | BM9: 24.3548 | BN9: 23.7295 | BO9: 22.8525 | BP9: 23.187 | BQ9: 31.4919 | BR9: 32.0471 | BS9: 34.4527 | BT9: 29.1721 | BU9: 22.7045 | BV9: 10.4195 | BW9: 25.7047 | BX9: 30.6868 | BY9: 25.6283 | BZ9: 29.7328 | CA9: 25.5751 | CB9: 32.4906 | CC9: 34.5773 | CD9: 35.608 | CE9: 10 | CF9: 31.7593 | CG9: 28.7834 | CH9: 30.5329 | CI9: 26.3164 | CJ9: 31.96 | CK9: 25.5617 | CL9: 10.6736 | CM9: 25.9641 | CN9: 33.5734 | CO9: 27.3591 | CP9: 30.5389 | CQ9: 24.5314 | CR9: 32.7246 | CS9: 32.4822 | CT9: 16.4799 | CU9: 29.1668 | CV9: 29.5466 | CW9: 21.4252 | CX9: 28.0517 | CY9: 31.0497 | CZ9: 28.4895 | DA9: 24.4346 | DB9: 31.4344 | DC9: 26.5223 | DD9: 28.2642 | DE9: 30.8184 | DF9: 27.7664 | DG9: 35.3445 | DH9: 26.4747 | DI9: 21.859 | DJ9: 10 | DK9: 30.1567 | DL9: 25.5675 | DM9: 28.3863 | DN9: 29.5133 | DO9: 22.7907 | DP9: 27.2393 | DQ9: 30.8754 | DR9: 22.0962 | DS9: 35.7837 | DT9: 33.1005 | DU9: 10 | DV9: 32.1615 | DW9: 25.9255 | DX9: 26.7599 | DY9: 26.7551 | DZ9: 24.2299 | EA9: 28.0981 | EB9: 28.1581 | EC9: 35.9594 | ED9: 31.933 | EE9: 20.6566 | EF9: 26.6013 | EG9: 31.8933 | EH9: 29.2748 | EI9: 30.4772 | EJ9: 32.4537 | EK9: 27.3347 | EL9: 26.1496 | EM9: 35.608 | EN9: 28.6271 | EO9: 10 | EP9: 33.401 | EQ9: 26.5774 | ER9: 12.0093 | ES9: 10 | ET9: 30.1986 | EU9: 32.0936 | EV9: 24.1359 | EW9: 30.0345 | EX9: 30.3246 | EY9: 32.3594 | EZ9: 34.9931 | FA9: 25.2493 | FB9: 17.1335 | FC9: 33.7629 | FD9: 26.2494 | FE9: 10 | FF9: 29.587 | FG9: 34.4791 | FH9: 30.1792 | FI9: 29.6441 | FJ9: 32.789 | FK9: 31.1241 | FL9: 32.594 | FM9: 33.5851 | FN9: 22.9063 | FO9: 31.2135 | FP9: 25.6332 | FQ9: 32.1215 | FR9: 26.7022 | FS9: 20.0719 | FT9: 35.7837 | FU9: 37.4527 | FV9: 10 | FW9: 30.6506 | FX9: 23.2687 | FY9: 10 | FZ9: 23.5345 | GA9: 34.1376 | GB9: 28.2195 | GC9: 31.7639 | GD9: 31.3102 | GE9: 11.0268 | GF9: 26.0138 | GG9: 21.9836 | GH9: 23.3152 | GI9: 23.7063 | GJ9: 20.2035 | GK9: 29.1196 | GL9: 10 | GM9: 10 | GN9: 10 | GO9: 26.8643 | GP9: 28.129 | GQ9: 22.5998 | GR9: 32.2679 | GS9: 29.0805 | GT9: 35.6959 | GU9: 23.3084 | GV9: 26.9391 | GW9: 28.6499 | GX9: 27.2647 | GY9: 35.081 | GZ9: 10 | HA9: 23.4585 | HB9: 28.6513 | HC9: 27.5625 | HD9: 27.6866 | HE9: 32.2607 | HF9: 33.6174 | HG9: 25.3715 | HH9: 36.1994 | HI9: 30.1843 | HJ9: 27.136 | HK9: 32.6733 | HL9: 10 | HM9: 31.8146 | HN9: 25.1637 | HO9: 28.4496 | HP9: 30.6937 | HQ9: 25.4244 | HR9: 29.8685 | HS9: 30.2588 | HT9: 30.7858 | HU9: 30.3217 | HV9: 28.0198 | HW9: 30.8589 | HX9: 26.1995 | HY9: 33.727 | HZ9: 30.1829 | IA9: 35.3445 | IB9: 20.3351 | IC9: 26.4157 | ID9: 31.6143 | IE9: 26.3334 | IF9: 31.1182 | IG9: 28.2186 | IH9: 35.3445 | II9: 10 | IJ9: 23.935 | IK9: 30.3293 | IL9: 28.8823 | IM9: 28.6891 | IN9: 17.6993 | IO9: 27.034 | IP9: 25.7254 | IQ9: 28.4245 | IR9: 23.7432 | IS9: 30.1993 | IT9: 10 | IU9: 24.4973 | IV9: 31.6208 | IW9: 27.2879 | IX9: 28.4714 | IY9: 19.986 | IZ9: 26.5385 | JA9: 28.7158 | JB9: 19.6764 | JC9: 20.2792 | JD9: 27.6172 | JE9: 26.777397 | JF9: 7015.6781
A10: 9 | B10: 4 | C10: 16.1147 | D10: 30.9441 | E10: 24.5144 | F10: 21.7596 | G10: 26.1911 | H10: 29.7968 | I10: 23.0576 | J10: 10 | K10: 21.6193 | L10: 32.2051 | M10: 29.8225 | N10: 23.6327 | O10: 10 | P10: 10 | Q10: 32.1777 | R10: 23.6122 | S10: 20.8753 | T10: 10.0046 | U10: 12.8376 | V10: 28.819 | W10: 28.6043 | X10: 31.4159 | Y10: 25.3127 | Z10: 36.5296 | AA10: 28.0077 | AB10: 10 | AC10: 28.0327 | AD10: 24.3715 | AE10: 27.9892 | AF10: 26.4698 | AG10: 34.7064 | AH10: 33.2592 | AI10: 17.8183 | AJ10: 24.7962 | AK10: 29.2701 | AL10: 28.5943 | AM10: 34.0199 | AN10: 23.4671 | AO10: 10 | AP10: 22.85 | AQ10: 28.6484 | AR10: 30.8373 | AS10: 26.9633 | AT10: 32.1116 | AU10: 28.4851 | AV10: 25.9767 | AW10: 16.1871 | AX10: 27.9651 | AY10: 33.7821 | AZ10: 28.8585 | BA10: 26.1727 | BB10: 25.1411 | BC10: 32.0631 | BD10: 28.3852 | BE10: 24.5806 | BF10: 28.7875 | BG10: 30.782 | BH10: 10 | BI10: 34.3999 | BJ10: 32.8417 | BK10: 23.2364 | BL10: 29.2819 | BM10: 23.7113 | BN10: 20.8681 | BO10: 22.2914 | BP10: 21.0599 | BQ10: 28.9804 | BR10: 31.5721 | BS10: 33.4714 | BT10: 26.4425 | BU10: 21.7899 | BV10: 10 | BW10: 23.5525 | BX10: 28.262 | BY10: 24.983 | BZ10: 29.1592 | CA10: 22.0792 | CB10: 30.9012 | CC10: 33.1565 | CD10: 35.0238 | CE10: 10 | CF10: 31.0747 | CG10: 28.2439 | CH10: 28.7218 | CI10: 25.6227 | CJ10: 31.3703 | CK10: 23.5073 | CL10: 10 | CM10: 25.308 | CN10: 32.4634 | CO10: 26.6458 | CP10: 29.9923 | CQ10: 23.9221 | CR10: 31.759 | CS10: 32.0252 | CT10: 14.7628 | CU10: 25.9175 | CV10: 27.0962 | CW10: 19.9262 | CX10: 27.3169 | CY10: 29.4986 | CZ10: 27.9429 | DA10: 22.4327 | DB10: 29.4212 | DC10: 23.6107 | DD10: 27.4145 | DE10: 28.525 | DF10: 25.8749 | DG10: 34.7226 | DH10: 25.364 | DI10: 18.9234 | DJ10: 10 | DK10: 29.3916 | DL10: 22.7557 | DM10: 27.9544 | DN10: 28.9182 | DO10: 19.0326 | DP10: 25.0702 | DQ10: 30.1889 | DR10: 20.1604 | DS10: 35.2246 | DT10: 31.1728 | DU10: 10 | DV10: 30.1882 | DW10: 23.4723 | DX10: 26.1469 | DY10: 24.5398 | DZ10: 23.5668 | EA10: 27.4725 | EB10: 25.5689 | EC10: 35.4037 | ED10: 31.053 | EE10: 18.4363 | EF10: 25.4716 | EG10: 30.3629 | EH10: 26.8434 | EI10: 28.1163 | EJ10: 30.8018 | EK10: 24.1752 | EL10: 25.5779 | EM10: 35.013 | EN10: 26.224 | EO10: 10 | EP10: 32.8293 | EQ10: 24.7128 | ER10: 10 | ES10: 10 | ET10: 28.879 | EU10: 30.8362 | EV10: 21.563 | EW10: 26.8517 | EX10: 29.8031 | EY10: 30.9011 | EZ10: 34.3049 | FA10: 21.5713 | FB10: 16.5134 | FC10: 32.0149 | FD10: 23.9732 | FE10: 10 | FF10: 28.5514 | FG10: 33.9844 | FH10: 27.4867 | FI10: 26.9779 | FJ10: 32.1509 | FK10: 28.6078 | FL10: 32.0008 | FM10: 32.7545 | FN10: 22.1799 | FO10: 30.552 | FP10: 25.0721 | FQ10: 30.3422 | FR10: 25.395 | FS10: 19.1828 | FT10: 35.1976 | FU10: 37.1211 | FV10: 10 | FW10: 29.5161 | FX10: 20.5703 | FY10: 10 | FZ10: 21.3264 | GA10: 33.6985 | GB10: 24.603 | GC10: 30.4782 | GD10: 29.3982 | GE10: 10 | GF10: 24.2701 | GG10: 19.8752 | GH10: 20.4535 | GI10: 22.534 | GJ10: 18.7009 | GK10: 28.5246 | GL10: 10 | GM10: 10 | GN10: 10 | GO10: 24.506 | GP10: 25.8148 | GQ10: 20.9972 | GR10: 31.7374 | GS10: 28.4837 | GT10: 35.1242 | GU10: 22.6381 | GV10: 26.4176 | GW10: 25.6921 | GX10: 26.7056 | GY10: 34.3999 | GZ10: 10 | HA10: 21.2035 | HB10: 27.6735 | HC10: 25.9609 | HD10: 26.815 | HE10: 31.6853 | HF10: 31.4298 | HG10: 23.4552 | HH10: 35.8177 | HI10: 29.6503 | HJ10: 25.6786 | HK10: 31.2278 | HL10: 10 | HM10: 31.3253 | HN10: 22.8943 | HO10: 27.448 | HP10: 30.0467 | HQ10: 23.7616 | HR10: 26.569 | HS10: 27.931 | HT10: 29.2371 | HU10: 28.863 | HV10: 25.5405 | HW10: 28.0256 | HX10: 22.0414 | HY10: 33.2556 | HZ10: 28.17 | IA10: 34.7118 | IB10: 10 | IC10: 25.9193 | ID10: 30.2648 | IE10: 25.1609 | IF10: 30.4461 | IG10: 27.6343 | IH10: 34.7226 | II10: 10 | IJ10: 22.7238 | IK10: 28.7394 | IL10: 28.1868 | IM10: 26.4591 | IN10: 14.8468 | IO10: 26.4695 | IP10: 23.891 | IQ10: 26.9079 | IR10: 23.0962 | IS10: 29.8033 | IT10: 10 | IU10: 22.5942 | IV10: 30.0924 | IW10: 26.5488 | IX10: 27.7903 | IY10: 17.9723 | IZ10: 23.8629 | JA10: 27.4903 | JB10: 18.7391 | JC10: 18.8233 | JD10: 25.0206 | JE10: 25.333597 | JF10: 6637.4025
A11: 10 | B11: 4.5 | C11: 14.1129 | D11: 29.2898 | E11: 23.2439 | F11: 21.2414 | G11: 24.5465 | H11: 29.5998 | I11: 22.7951 | J11: 10 | K11: 20.9263 | L11: 30.8524 | M11: 29.8066 | N11: 23.6523 | O11: 10 | P11: 10 | Q11: 31.996 | R11: 23.2493 | S11: 16.433 | T11: 10 | U11: 11.6995 | V11: 28.3791 | W11: 26.5241 | X11: 31.1534 | Y11: 25.0224 | Z11: 36.696 | AA11: 26.6513 | AB11: 10 | AC11: 27.4456 | AD11: 23.1492 | AE11: 27.4007 | AF11: 25.5915 | AG11: 34.4314 | AH11: 33.0316 | AI11: 15.4088 | AJ11: 24.5185 | AK11: 29.1511 | AL11: 28.4726 | AM11: 33.9205 | AN11: 22.4697 | AO11: 10 | AP11: 20.9848 | AQ11: 27.7697 | AR11: 29.2725 | AS11: 25.7662 | AT11: 31.9146 | AU11: 28.3536 | AV11: 24.7843 | AW11: 15.4516 | AX11: 27.6623 | AY11: 33.7662 | AZ11: 28.3714 | BA11: 21.9192 | BB11: 25.1252 | BC11: 31.0729 | BD11: 26.5986 | BE11: 24.5396 | BF11: 28.7716 | BG11: 30.5697 | BH11: 10 | BI11: 34.0092 | BJ11: 32.6239 | BK11: 20.9908 | BL11: 29.0544 | BM11: 22.4991 | BN11: 18.7666 | BO11: 20.7125 | BP11: 19.6161 | BQ11: 28.5503 | BR11: 30.4358 | BS11: 32.9299 | BT11: 22.8086 | BU11: 21.5705 | BV11: 10 | BW11: 23.5241 | BX11: 28.2816 | BY11: 22.1747 | BZ11: 26.7305 | CA11: 20.4641 | CB11: 30.6262 | CC11: 32.9484 | CD11: 35.0204 | CE11: 10 | CF11: 29.9223 | CG11: 25.9332 | CH11: 27.6742 | CI11: 23.8006 | CJ11: 31.289 | CK11: 21.7261 | CL11: 10 | CM11: 24.9425 | CN11: 32.1031 | CO11: 24.8696 | CP11: 30.0232 | CQ11: 23.8936 | CR11: 31.484 | CS11: 32.0039 | CT11: 14.3726 | CU11: 25.1796 | CV11: 26.2663 | CW11: 18.5215 | CX11: 25.1926 | CY11: 29.6198 | CZ11: 27.9738 | DA11: 22.2538 | DB11: 29.486 | DC11: 23.3051 | DD11: 25.101 | DE11: 28.1893 | DF11: 25.228 | DG11: 34.6816 | DH11: 24.5438 | DI11: 16.5806 | DJ11: 10 | DK11: 28.3655 | DL11: 21.6447 | DM11: 25.8216 | DN11: 27.4658 | DO11: 18.6823 | DP11: 24.5186 | DQ11: 29.7202 | DR11: 19.065 | DS11: 35.2441 | DT11: 30.8045 | DU11: 10 | DV11: 29.9636 | DW11: 21.3838 | DX11: 22.7811 | DY11: 24.2433 | DZ11: 21.8429 | EA11: 25.8484 | EB11: 24.3192 | EC11: 35.1386 | ED11: 30.0147 | EE11: 16.7542 | EF11: 23.208 | EG11: 30.1534 | EH11: 26.9307 | EI11: 27.9166 | EJ11: 30.3266 | EK11: 23.8699 | EL11: 22.9006 | EM11: 34.8536 | EN11: 24.5491 | EO11: 10 | EP11: 32.8376 | EQ11: 21.8493 | ER11: 10 | ES11: 10 | ET11: 27.6578 | EU11: 29.5606 | EV11: 20.532 | EW11: 26.7731 | EX11: 28.9955 | EY11: 30.0183 | EZ11: 33.9797 | FA11: 20.9904 | FB11: 16.3289 | FC11: 31.8752 | FD11: 23.5422 | FE11: 10 | FF11: 27.3632 | FG11: 33.9254 | FH11: 27.1991 | FI11: 26.6347 | FJ11: 31.8759 | FK11: 28.0281 | FL11: 31.6979 | FM11: 31.6524 | FN11: 18.959 | FO11: 29.4182 | FP11: 21.3673 | FQ11: 30.1174 | FR11: 23.029 | FS11: 16.261 | FT11: 34.8293 | FU11: 37.2149 | FV11: 10 | FW11: 28.4213 | FX11: 19.4434 | FY11: 10 | FZ11: 19.1044 | GA11: 32.5055 | GB11: 24.1788 | GC11: 30.4247 | GD11: 28.4984 | GE11: 10 | GF11: 22.9622 | GG11: 17.7613 | GH11: 17.9969 | GI11: 21.8809 | GJ11: 16.9043 | GK11: 28.3652 | GL11: 10 | GM11: 10 | GN11: 10 | GO11: 22.3101 | GP11: 24.462 | GQ11: 20.571 | GR11: 31.4973 | GS11: 28.4678 | GT11: 35.1325 | GU11: 19.728 | GV11: 24.0402 | GW11: 25.626 | GX11: 23.3683 | GY11: 34.0092 | GZ11: 10 | HA11: 19.8054 | HB11: 27.2212 | HC11: 20.5621 | HD11: 25.4178 | HE11: 31.473 | HF11: 30.9978 | HG11: 21.8578 | HH11: 35.0699 | HI11: 28.5596 | HJ11: 24.2507 | HK11: 30.9403 | HL11: 10 | HM11: 31.3424 | HN11: 20.8926 | HO11: 25.4954 | HP11: 29.1815 | HQ11: 20.934 | HR11: 26.3736 | HS11: 27.1061 | HT11: 29.2338 | HU11: 28.8826 | HV11: 25.2485 | HW11: 27.9721 | HX11: 21.9126 | HY11: 33.3543 | HZ11: 27.6735 | IA11: 34.5148 | IB11: 10 | IC11: 25.06 | ID11: 29.6363 | IE11: 25.1576 | IF11: 30.3549 | IG11: 27.631 | IH11: 34.6816 | II11: 10 | IJ11: 21.8758 | IK11: 27.0115 | IL11: 27.2259 | IM11: 24.6723 | IN11: 13.2263 | IO11: 26.4132 | IP11: 22.7222 | IQ11: 25.584 | IR11: 23.0302 | IS11: 29.9697 | IT11: 10 | IU11: 20.186 | IV11: 29.9304 | IW11: 24.1656 | IX11: 25.9976 | IY11: 16.5851 | IZ11: 23.7968 | JA11: 25.2457 | JB11: 17.019 | JC11: 18.7392 | JD11: 24.7951 | JE11: 24.479179 | JF11: 6413.5448
A12: 11 | B12: 5 | C12: 14.0261 | D12: 30.6029 | E12: 21.6018 | F12: 19.1132 | G12: 24.562 | H12: 30.1998 | I12: 22.4476 | J12: 10 | K12: 21.8478 | L12: 32.0682 | M12: 31.7878 | N12: 25.2864 | O12: 10 | P12: 10.5349 | Q12: 32.8243 | R12: 22.1187 | S12: 18.0702 | T12: 11.3139 | U12: 12.5095 | V12: 27.8243 | W12: 27.2359 | X12: 32.2078 | Y12: 25.7937 | Z12: 38.9274 | AA12: 27.8563 | AB12: 10.212 | AC12: 27.3633 | AD12: 21.4113 | AE12: 28.8351 | AF12: 26.996 | AG12: 35.4745 | AH12: 33.8593 | AI12: 16.1546 | AJ12: 23.4149 | AK12: 29.5862 | AL12: 29.9118 | AM12: 34.9873 | AN12: 24.2147 | AO12: 11.3797 | AP12: 22.3329 | AQ12: 28.4538 | AR12: 30.3156 | AS12: 26.1639 | AT12: 32.6755 | AU12: 29.5403 | AV12: 23.3173 | AW12: 15.8222 | AX12: 26.1275 | AY12: 35.8169 | AZ12: 28.1505 | BA12: 21.5997 | BB12: 26.0048 | BC12: 33.1349 | BD12: 27.9297 | BE12: 24.9009 | BF12: 29.3879 | BG12: 31.6693 | BH12: 10.8028 | BI12: 34.6901 | BJ12: 32.4605 | BK12: 22.6906 | BL12: 29.8821 | BM12: 21.8137 | BN12: 18.3044 | BO12: 19.1357 | BP12: 20.0442 | BQ12: 28.1033 | BR12: 30.8573 | BS12: 35.2064 | BT12: 23.3786 | BU12: 21.3021 | BV12: 11.9819 | BW12: 23.7076 | BX12: 28.687 | BY12: 22.7026 | BZ12: 27.1847 | CA12: 21.2695 | CB12: 31.6693 | CC12: 34.3092 | CD12: 37.0824 | CE12: 10.3638 | CF12: 31.894 | CG12: 26.5344 | CH12: 27.0611 | CI12: 24.4702 | CJ12: 33.0227 | CK12: 23.2767 | CL12: 10.0856 | CM12: 25.6459 | CN12: 33.6101 | CO12: 24.4421 | CP12: 32.1191 | CQ12: 25.9331 | CR12: 32.2815 | CS12: 33.5334 | CT12: 15.3862 | CU12: 26.5168 | CV12: 25.5636 | CW12: 18.9795 | CX12: 26.9418 | CY12: 29.8171 | CZ12: 27.8418 | DA12: 22.5184 | DB12: 29.7542 | DC12: 24.2259 | DD12: 25.7372 | DE12: 29.9521 | DF12: 26.5615 | DG12: 36.7097 | DH12: 22.8921 | DI12: 16.4162 | DJ12: 10 | DK12: 30.2008 | DL12: 22.7284 | DM12: 27.3738 | DN12: 28.1231 | DO12: 16.9099 | DP12: 24.0651 | DQ12: 28.71 | DR12: 19.9012 | DS12: 37.3287 | DT12: 29.955 | DU12: 10.6593 | DV12: 30.7359 | DW12: 22.7213 | DX12: 23.8468 | DY12: 23.2617 | DZ12: 21.7477 | EA12: 25.6763 | EB12: 25.396 | EC12: 35.9324 | ED12: 31.687 | EE12: 17.0105 | EF12: 23.5947 | EG12: 30.5576 | EH12: 28.0416 | EI12: 28.7332 | EJ12: 31.4947 | EK12: 23.7392 | EL12: 24.9739 | EM12: 36.2589 | EN12: 26.0433 | EO12: 11.9942 | EP12: 34.2224 | EQ12: 22.2193 | ER12: 11.9716 | ES12: 10.783 | ET12: 29.018 | EU12: 31.7356 | EV12: 19.6015 | EW12: 28.7673 | EX12: 30.1775 | EY12: 31.0238 | EZ12: 34.9776 | FA12: 19.3461 | FB12: 16.6232 | FC12: 31.4184 | FD12: 21.9825 | FE12: 10 | FF12: 26.9677 | FG12: 35.4211 | FH12: 25.1843 | FI12: 25.7166 | FJ12: 32.493 | FK12: 27.2775 | FL12: 31.224 | FM12: 32.4011 | FN12: 18.4222 | FO12: 29.1447 | FP12: 21.1948 | FQ12: 30.1333 | FR12: 24.3663 | FS12: 17.5012 | FT12: 35.2722 | FU12: 38.8574 | FV12: 11.7562 | FW12: 30.4325 | FX12: 17.4509 | FY12: 10.5002 | FZ12: 21.1663 | GA12: 34.3747 | GB12: 24.2139 | GC12: 32.4415 | GD12: 30.6056 | GE12: 10 | GF12: 24.4127 | GG12: 17.9111 | GH12: 17.9351 | GI12: 22.1615 | GJ12: 18.0687 | GK12: 28.1571 | GL12: 10.7276 | GM12: 10 | GN12: 10.2343 | GO12: 22.0601 | GP12: 26.0712 | GQ12: 21.5238 | GR12: 30.9981 | GS12: 30.5185 | GT12: 37.2057 | GU12: 20.9015 | GV12: 24.9336 | GW12: 26.7714 | GX12: 25.2985 | GY12: 34.6901 | GZ12: 10 | HA12: 20.1515 | HB12: 27.1449 | HC12: 19.869 | HD12: 26.5173 | HE12: 31.1989 | HF12: 32.3806 | HG12: 23.4592 | HH12: 36.5771 | HI12: 29.958 | HJ12: 24.6444 | HK12: 31.9721 | HL12: 10.0801 | HM12: 31.3083 | HN12: 19.6143 | HO12: 26.7267 | HP12: 30.3239 | HQ12: 21.5597 | HR12: 27.2545 | HS12: 28.1724 | HT12: 29.5597 | HU12: 30.1576 | HV12: 25.6396 | HW12: 28.6395 | HX12: 22.3885 | HY12: 35.5179 | HZ12: 27.7429 | IA12: 35.8863 | IB12: 11.4457 | IC12: 27.2011 | ID12: 28.6941 | IE12: 25.9892 | IF12: 31.1753 | IG12: 29.693 | IH12: 36.7097 | II12: 10.6922 | IJ12: 22.9076 | IK12: 27.4318 | IL12: 28.2884 | IM12: 25.0216 | IN12: 12.2475 | IO12: 26.3726 | IP12: 22.6119 | IQ12: 26.9332 | IR12: 25.0357 | IS12: 32.2011 | IT12: 10.8293 | IU12: 22.2254 | IV12: 29.7811 | IW12: 25.9667 | IX12: 25.9529 | IY12: 18.3542 | IZ12: 23.1753 | JA12: 27.4997 | JB12: 18.1276 | JC12: 19.6506 | JD12: 24.9263 | JE12: 25.134405 | JF12: 6585.2141
