Workbook

Sheet ReadMe
A1: README
A2: Data behind the TR8 rolling-dispatch figures (SOC, demand/PV/dispatch, net, self-consumption, metrics histogram).
A3: Each quantity sheet: rows = 48 half-hour periods (with hour of day), columns = prosumers, plus fleet_average / fleet_total.
A4: Dispatch is the committed slot-1 execution of the rolling horizon (self-consumption baseline, Term 2 + Term 3).
A5: SOC is the realised state at the START of each step (fraction of capacity).
A6: net_kW = (demand - PV) + (charge - discharge); positive = import, negative = export.
A7: Regenerate: python build_workbook.py --force (see README.md for other transformers).

Sheet Summary
A1: quantity | B1: value
A2: run | B2: TR8 exact-QCP rolling (FOR_PolyS=0, FOR_LinearizeVmax=0), 48 steps, all Optimal
A3: source dispatch | B3: FOR_rolling_soc_TR8.csv
A4: source load/PV | B4: TR8_load_PV_48periods.xlsx
A5: prosumers | B5: 124
A6: PV generated kWh/day | B6: 3081.1
A7: demand kWh/day | B7: 851.2
A8: exported kWh/day | B8: 2166.7
A9: imported kWh/day | B9: 25.8
A10: SCR % (PV used locally) | B10: 29.7
A11: SSR % (demand met locally) | B11: 97
A12: prosumer-periods |net|<50W % | B12: 57
A13: SOC min/max over day | B13: 0.10 / 1.00
A14: simultaneous chg+dis rows | B14: 0

Sheet FleetAverage
A1: period | B1: hour | C1: demand_avg_kW | D1: PV_avg_kW | E1: charge_avg_kW | F1: discharge_avg_kW | G1: net_avg_kW | H1: SOC_avg_pct | I1: demand_total_kW | J1: PV_total_kW | K1: net_total_kW
A2: =Demand_kW!A2 -> 1 | B2: =Demand_kW!B2 -> 0 | C2: =AVERAGE(Demand_kW!$C2:$DV2) -> 0.23955602 | D2: =AVERAGE(PV_kW!$C2:$DV2) -> 0 | E2: =AVERAGE(Charge_kW!$C2:$DV2) -> 0 | F2: =AVERAGE(Discharge_kW!$C2:$DV2) -> 0.23916129 | G2: =C2-D2+E2-F2 -> 0.00039472849 | H2: =AVERAGE(SOC_pct!$C2:$DV2) -> 40 | I2: =SUM(Demand_kW!$C2:$DV2) -> 29.704946 | J2: =SUM(PV_kW!$C2:$DV2) -> 0 | K2: =I2-J2+SUM(Charge_kW!$C2:$DV2)-SUM(Discharge_kW!$C2:$DV2) -> 0.048946333
A3: =Demand_kW!A3 -> 2 | B3: =Demand_kW!B3 -> 0.5 | C3: =AVERAGE(Demand_kW!$C3:$DV3) -> 0.16206498 | D3: =AVERAGE(PV_kW!$C3:$DV3) -> 0 | E3: =AVERAGE(Charge_kW!$C3:$DV3) -> 0 | F3: =AVERAGE(Discharge_kW!$C3:$DV3) -> 0.15999194 | G3: =C3-D3+E3-F3 -> 0.0020730435 | H3: =AVERAGE(SOC_pct!$C3:$DV3) -> 36.998769 | I3: =SUM(Demand_kW!$C3:$DV3) -> 20.096057 | J3: =SUM(PV_kW!$C3:$DV3) -> 0 | K3: =I3-J3+SUM(Charge_kW!$C3:$DV3)-SUM(Discharge_kW!$C3:$DV3) -> 0.2570574
A4: =Demand_kW!A4 -> 3 | B4: =Demand_kW!B4 -> 1 | C4: =AVERAGE(Demand_kW!$C4:$DV4) -> 0.12509534 | D4: =AVERAGE(PV_kW!$C4:$DV4) -> 0 | E4: =AVERAGE(Charge_kW!$C4:$DV4) -> 0 | F4: =AVERAGE(Discharge_kW!$C4:$DV4) -> 0.12145968 | G4: =C4-D4+E4-F4 -> 0.0036356632 | H4: =AVERAGE(SOC_pct!$C4:$DV4) -> 34.991258 | I4: =SUM(Demand_kW!$C4:$DV4) -> 15.511822 | J4: =SUM(PV_kW!$C4:$DV4) -> 0 | K4: =I4-J4+SUM(Charge_kW!$C4:$DV4)-SUM(Discharge_kW!$C4:$DV4) -> 0.45082223
A5: =Demand_kW!A5 -> 4 | B5: =Demand_kW!B5 -> 1.5 | C5: =AVERAGE(Demand_kW!$C5:$DV5) -> 0.13857775 | D5: =AVERAGE(PV_kW!$C5:$DV5) -> 0 | E5: =AVERAGE(Charge_kW!$C5:$DV5) -> 0 | F5: =AVERAGE(Discharge_kW!$C5:$DV5) -> 0.12979839 | G5: =C5-D5+E5-F5 -> 0.0087793624 | H5: =AVERAGE(SOC_pct!$C5:$DV5) -> 33.467018 | I5: =SUM(Demand_kW!$C5:$DV5) -> 17.183641 | J5: =SUM(PV_kW!$C5:$DV5) -> 0 | K5: =I5-J5+SUM(Charge_kW!$C5:$DV5)-SUM(Discharge_kW!$C5:$DV5) -> 1.0886409
A6: =Demand_kW!A6 -> 5 | B6: =Demand_kW!B6 -> 2 | C6: =AVERAGE(Demand_kW!$C6:$DV6) -> 0.11135694 | D6: =AVERAGE(PV_kW!$C6:$DV6) -> 0 | E6: =AVERAGE(Charge_kW!$C6:$DV6) -> 0 | F6: =AVERAGE(Discharge_kW!$C6:$DV6) -> 0.10301613 | G6: =C6-D6+E6-F6 -> 0.0083408065 | H6: =AVERAGE(SOC_pct!$C6:$DV6) -> 31.837924 | I6: =SUM(Demand_kW!$C6:$DV6) -> 13.80826 | J6: =SUM(PV_kW!$C6:$DV6) -> 0 | K6: =I6-J6+SUM(Charge_kW!$C6:$DV6)-SUM(Discharge_kW!$C6:$DV6) -> 1.03426
A7: =Demand_kW!A7 -> 6 | B7: =Demand_kW!B7 -> 2.5 | C7: =AVERAGE(Demand_kW!$C7:$DV7) -> 0.12965302 | D7: =AVERAGE(PV_kW!$C7:$DV7) -> 0 | E7: =AVERAGE(Charge_kW!$C7:$DV7) -> 0 | F7: =AVERAGE(Discharge_kW!$C7:$DV7) -> 0.12269355 | G7: =C7-D7+E7-F7 -> 0.0069594726 | H7: =AVERAGE(SOC_pct!$C7:$DV7) -> 30.544951 | I7: =SUM(Demand_kW!$C7:$DV7) -> 16.076975 | J7: =SUM(PV_kW!$C7:$DV7) -> 0 | K7: =I7-J7+SUM(Charge_kW!$C7:$DV7)-SUM(Discharge_kW!$C7:$DV7) -> 0.8629746
A8: =Demand_kW!A8 -> 7 | B8: =Demand_kW!B8 -> 3 | C8: =AVERAGE(Demand_kW!$C8:$DV8) -> 0.1092713 | D8: =AVERAGE(PV_kW!$C8:$DV8) -> 0 | E8: =AVERAGE(Charge_kW!$C8:$DV8) -> 0 | F8: =AVERAGE(Discharge_kW!$C8:$DV8) -> 0.10104032 | G8: =C8-D8+E8-F8 -> 0.0082309758 | H8: =AVERAGE(SOC_pct!$C8:$DV8) -> 29.005632 | I8: =SUM(Demand_kW!$C8:$DV8) -> 13.549641 | J8: =SUM(PV_kW!$C8:$DV8) -> 0 | K8: =I8-J8+SUM(Charge_kW!$C8:$DV8)-SUM(Discharge_kW!$C8:$DV8) -> 1.020641
A9: =Demand_kW!A9 -> 8 | B9: =Demand_kW!B9 -> 3.5 | C9: =AVERAGE(Demand_kW!$C9:$DV9) -> 0.14391197 | D9: =AVERAGE(PV_kW!$C9:$DV9) -> 0.0026465051 | E9: =AVERAGE(Charge_kW!$C9:$DV9) -> 0 | F9: =AVERAGE(Discharge_kW!$C9:$DV9) -> 0.12418548 | G9: =C9-D9+E9-F9 -> 0.017079979 | H9: =AVERAGE(SOC_pct!$C9:$DV9) -> 27.737964 | I9: =SUM(Demand_kW!$C9:$DV9) -> 17.845084 | J9: =SUM(PV_kW!$C9:$DV9) -> 0.32816663 | K9: =I9-J9+SUM(Charge_kW!$C9:$DV9)-SUM(Discharge_kW!$C9:$DV9) -> 2.1179174
A10: =Demand_kW!A10 -> 9 | B10: =Demand_kW!B10 -> 4 | C10: =AVERAGE(Demand_kW!$C10:$DV10) -> 0.11276629 | D10: =AVERAGE(PV_kW!$C10:$DV10) -> 0.038253445 | E10: =AVERAGE(Charge_kW!$C10:$DV10) -> 0.00031451613 | F10: =AVERAGE(Discharge_kW!$C10:$DV10) -> 0.067915573 | G10: =C10-D10+E10-F10 -> 0.006911791 | H10: =AVERAGE(SOC_pct!$C10:$DV10) -> 26.179535 | I10: =SUM(Demand_kW!$C10:$DV10) -> 13.98302 | J10: =SUM(PV_kW!$C10:$DV10) -> 4.7434272 | K10: =I10-J10+SUM(Charge_kW!$C10:$DV10)-SUM(Discharge_kW!$C10:$DV10) -> 0.85706208
A11: =Demand_kW!A11 -> 10 | B11: =Demand_kW!B11 -> 4.5 | C11: =AVERAGE(Demand_kW!$C11:$DV11) -> 0.11641532 | D11: =AVERAGE(PV_kW!$C11:$DV11) -> 0.1788847 | E11: =AVERAGE(Charge_kW!$C11:$DV11) -> 0.083451613 | F11: =AVERAGE(Discharge_kW!$C11:$DV11) -> 0.020725806 | G11: =C11-D11+E11-F11 -> 0.00025642459 | H11: =AVERAGE(SOC_pct!$C11:$DV11) -> 25.330335 | I11: =SUM(Demand_kW!$C11:$DV11) -> 14.4355 | J11: =SUM(PV_kW!$C11:$DV11) -> 22.181703 | K11: =I11-J11+SUM(Charge_kW!$C11:$DV11)-SUM(Discharge_kW!$C11:$DV11) -> 0.031796649
A12: =Demand_kW!A12 -> 11 | B12: =Demand_kW!B12 -> 5 | C12: =AVERAGE(Demand_kW!$C12:$DV12) -> 0.11359415 | D12: =AVERAGE(PV_kW!$C12:$DV12) -> 0.35484137 | E12: =AVERAGE(Charge_kW!$C12:$DV12) -> 0.24564516 | F12: =AVERAGE(Discharge_kW!$C12:$DV12) -> 0.0044193548 | G12: =C12-D12+E12-F12 -> -2.1419302e-05 | H12: =AVERAGE(SOC_pct!$C12:$DV12) -> 26.012711 | I12: =SUM(Demand_kW!$C12:$DV12) -> 14.085674 | J12: =SUM(PV_kW!$C12:$DV12) -> 44.00033 | K12: =I12-J12+SUM(Charge_kW!$C12:$DV12)-SUM(Discharge_kW!$C12:$DV12) -> -0.0026559934
A13: =Demand_kW!A13 -> 12 | B13: =Demand_kW!B13 -> 5.5 | C13: =AVERAGE(Demand_kW!$C13:$DV13) -> 0.1087806 | D13: =AVERAGE(PV_kW!$C13:$DV13) -> 0.57060246 | E13: =AVERAGE(Charge_kW!$C13:$DV13) -> 0.46278226 | F13: =AVERAGE(Discharge_kW!$C13:$DV13) -> 0.00097580645 | G13: =C13-D13+E13-F13 -> -1.5400902e-05 | H13: =AVERAGE(SOC_pct!$C13:$DV13) -> 28.731836 | I13: =SUM(Demand_kW!$C13:$DV13) -> 13.488795 | J13: =SUM(PV_kW!$C13:$DV13) -> 70.754705 | K13: =I13-J13+SUM(Charge_kW!$C13:$DV13)-SUM(Discharge_kW!$C13:$DV13) -> -0.0019097119
... A49: =Demand_kW!A49 -> 48 | B49: =Demand_kW!B49 -> 23.5 | C49: =AVERAGE(Demand_kW!$C49:$DV49) -> 0.23287321 | D49: =AVERAGE(PV_kW!$C49:$DV49) -> 0 | E49: =AVERAGE(Charge_kW!$C49:$DV49) -> 0 | F49: =AVERAGE(Discharge_kW!$C49:$DV49) -> 0.18972581 | G49: =C49-D49+E49-F49 -> 0.043147404 | H49: =AVERAGE(SOC_pct!$C49:$DV49) -> 51.675614 | I49: =SUM(Demand_kW!$C49:$DV49) -> 28.876278 | J49: =SUM(PV_kW!$C49:$DV49) -> 0 | K49: =I49-J49+SUM(Charge_kW!$C49:$DV49)-SUM(Discharge_kW!$C49:$DV49) -> 5.3502781

Sheet SOC_pct
A1: period | B1: hour | C1: BES_TR8_one223_B | D1: BES_TR8_one252_C | E1: BES_TR8_one280_A | F1: BES_TR8_one313_A | G1: BES_TR8_one321_C | H1: BES_TR8_one345_A | I1: BES_TR8_one375_C | J1: BES_TR8_one410_B | K1: BES_TR8_one416_C | L1: BES_TR8_one423_B | M1: BES_TR8_one446_B | N1: BES_TR8_one469_A | O1: BES_TR8_one477_A | P1: BES_TR8_one482_B | Q1: BES_TR8_one61_A | R1: BES_TR8_one552_B | S1: BES_TR8_one560_C | T1: BES_TR8_one73_A | U1: BES_TR8_one137_A | V1: BES_TR8_four50_C | W1: BES_TR8_four171_A | X1: BES_TR8_four180_A | Y1: BES_TR8_four200_A | Z1: BES_TR8_four239_A | AA1: BES_TR8_four259_B | AB1: BES_TR8_four265_C | AC1: BES_TR8_four54_C | AD1: BES_TR8_four288_B | AE1: BES_TR8_four289_B | AF1: BES_TR8_four292_C | AG1: BES_TR8_four301_C | AH1: BES_TR8_four326_A | AI1: BES_TR8_four352_A | AJ1: BES_TR8_four358_C | AK1: BES_TR8_four368_C | AL1: BES_TR8_four372_C | AM1: BES_TR8_four381_A | AN1: BES_TR8_four385_A | AO1: BES_TR8_four423_C | AP1: BES_TR8_four437_A | AQ1: BES_TR8_four446_B | AR1: BES_TR8_four466_C | AS1: BES_TR8_four467_C | AT1: BES_TR8_four548_B | AU1: BES_TR8_four558_C | AV1: BES_TR8_four562_C | AW1: BES_TR8_four590_A | AX1: BES_TR8_four604_A | AY1: BES_TR8_four78_B | AZ1: BES_TR8_four734_A | BA1: BES_TR8_four797_C | BB1: BES_TR8_four846_C | BC1: BES_TR8_four854_A | BD1: BES_TR8_four936_C | BE1: BES_TR8_four950_B | BF1: BES_TR8_four978_A | BG1: BES_TR8_four104_A | BH1: BES_TR8_four988_A | BI1: BES_TR8_four1013_B | BJ1: BES_TR8_four1027_A | BK1: BES_TR8_four1132_C | BL1: BES_TR8_four126_A | BM1: BES_TR8_four1187_A | BN1: BES_TR8_four1207_B | BO1: BES_TR8_five168_A | BP1: BES_TR8_five186_C | BQ1: BES_TR8_five194_C | BR1: BES_TR8_five223_A | BS1: BES_TR8_five303_B | BT1: BES_TR8_five324_B | BU1: BES_TR8_five345_A | BV1: BES_TR8_five421_A | BW1: BES_TR8_five488_B | BX1: BES_TR8_five513_B | BY1: BES_TR8_five537_C | BZ1: BES_TR8_five540_A | CA1: BES_TR8_five551_C | CB1: BES_TR8_five631_B | CC1: BES_TR8_five649_A | CD1: BES_TR8_five663_C | CE1: BES_TR8_five670_C | CF1: BES_TR8_five704_A | CG1: BES_TR8_five719_A | CH1: BES_TR8_five750_B | CI1: BES_TR8_five793_A | CJ1: BES_TR8_five801_C | CK1: BES_TR8_five905_B | CL1: BES_TR8_five118_B | CM1: BES_TR8_five123_B | CN1: BES_TR8_six64_A | CO1: BES_TR8_six154_C | CP1: BES_TR8_six173_C | CQ1: BES_TR8_six232_C | CR1: BES_TR8_six238_A | CS1: BES_TR8_six269_C | CT1: BES_TR8_six289_C | CU1: BES_TR8_six317_C | CV1: BES_TR8_six326_A | CW1: BES_TR8_six329_A | CX1: BES_TR8_six342_A | CY1: BES_TR8_six350_B | CZ1: BES_TR8_six365_C | DA1: BES_TR8_six75_A | DB1: BES_TR8_six385_B | DC1: BES_TR8_six431_C | DD1: BES_TR8_six571_C | DE1: BES_TR8_six595_B | DF1: BES_TR8_six643_A | DG1: BES_TR8_six652_A | DH1: BES_TR8_six667_A | DI1: BES_TR8_six699_C | DJ1: BES_TR8_six723_B | DK1: BES_TR8_six740_A | DL1: BES_TR8_six90_B | DM1: BES_TR8_six801_C | DN1: BES_TR8_six807_A | DO1: BES_TR8_six844_C | DP1: BES_TR8_six860_C | DQ1: BES_TR8_six909_C | DR1: BES_TR8_six914_A | DS1: BES_TR8_six111_C | DT1: BES_TR8_six1006_C | DU1: BES_TR8_six1020_A | DV1: BES_TR8_six1064_C | DW1: fleet_average | DX1: fleet_total
A2: 1 | B2: 0 | C2: 40 | D2: 40 | E2: 40 | F2: 40 | G2: 40 | H2: 40 | I2: 40 | J2: 40 | K2: 40 | L2: 40 | M2: 40 | N2: 40 | O2: 40 | P2: 40 | Q2: 40 | R2: 40 | S2: 40 | T2: 40 | U2: 40 | V2: 40 | W2: 40 | X2: 40 | Y2: 40 | Z2: 40 | AA2: 40 | AB2: 40 | AC2: 40 | AD2: 40 | AE2: 40 | AF2: 40 | AG2: 40 | AH2: 40 | AI2: 40 | AJ2: 40 | AK2: 40 | AL2: 40 | AM2: 40 | AN2: 40 | AO2: 40 | AP2: 40 | AQ2: 40 | AR2: 40 | AS2: 40 | AT2: 40 | AU2: 40 | AV2: 40 | AW2: 40 | AX2: 40 | AY2: 40 | AZ2: 40 | BA2: 40 | BB2: 40 | BC2: 40 | BD2: 40 | BE2: 40 | BF2: 40 | BG2: 40 | BH2: 40 | BI2: 40 | BJ2: 40 | BK2: 40 | BL2: 40 | BM2: 40 | BN2: 40 | BO2: 40 | BP2: 40 | BQ2: 40 | BR2: 40 | BS2: 40 | BT2: 40 | BU2: 40 | BV2: 40 | BW2: 40 | BX2: 40 | BY2: 40 | BZ2: 40 | CA2: 40 | CB2: 40 | CC2: 40 | CD2: 40 | CE2: 40 | CF2: 40 | CG2: 40 | CH2: 40 | CI2: 40 | CJ2: 40 | CK2: 40 | CL2: 40 | CM2: 40 | CN2: 40 | CO2: 40 | CP2: 40 | CQ2: 40 | CR2: 40 | CS2: 40 | CT2: 40 | CU2: 40 | CV2: 40 | CW2: 40 | CX2: 40 | CY2: 40 | CZ2: 40 | DA2: 40 | DB2: 40 | DC2: 40 | DD2: 40 | DE2: 40 | DF2: 40 | DG2: 40 | DH2: 40 | DI2: 40 | DJ2: 40 | DK2: 40 | DL2: 40 | DM2: 40 | DN2: 40 | DO2: 40 | DP2: 40 | DQ2: 40 | DR2: 40 | DS2: 40 | DT2: 40 | DU2: 40 | DV2: 40 | DW2: 40 | DX2: 4960
A3: 2 | B3: 0.5 | C3: 38.7712 | D3: 39.3851 | E3: 39.3145 | F3: 39.2596 | G3: 39.4102 | H3: 38.113 | I3: 38.3451 | J3: 36.7974 | K3: 37.7617 | L3: 38.0053 | M3: 37.9222 | N3: 37.2066 | O3: 33.3477 | P3: 37.7427 | Q3: 39.0545 | R3: 32.5584 | S3: 27.9381 | T3: 37.6999 | U3: 39.0874 | V3: 37.068 | W3: 37.1441 | X3: 39.2847 | Y3: 39.611 | Z3: 39.3098 | AA3: 39.1926 | AB3: 37.5954 | AC3: 37.6623 | AD3: 36.7855 | AE3: 32.9732 | AF3: 37.2273 | AG3: 35.253 | AH3: 33.9218 | AI3: 39.2479 | AJ3: 37.7004 | AK3: 38.3716 | AL3: 39.4353 | AM3: 39.0108 | AN3: 38.6564 | AO3: 38.7427 | AP3: 39.4228 | AQ3: 38.3836 | AR3: 10 | AS3: 38.8061 | AT3: 39.4981 | AU3: 38.3303 | AV3: 37.5324 | AW3: 39.2471 | AX3: 39.2596 | AY3: 38.6002 | AZ3: 33.399 | BA3: 35.4186 | BB3: 37.266 | BC3: 39.6235 | BD3: 36.3203 | BE3: 38.4427 | BF3: 33.0624 | BG3: 36.7023 | BH3: 37.7509 | BI3: 37.1531 | BJ3: 38.8886 | BK3: 38.4524 | BL3: 39.0237 | BM3: 38.0791 | BN3: 37.6874 | BO3: 15.5794 | BP3: 39.3726 | BQ3: 35.4453 | BR3: 39.1535 | BS3: 34.6598 | BT3: 37.1693 | BU3: 37.8954 | BV3: 39.3977 | BW3: 38.5522 | BX3: 38.4234 | BY3: 36.5939 | BZ3: 39.4604 | CA3: 39.2847 | CB3: 37.9733 | CC3: 37.4238 | CD3: 38.5005 | CE3: 39.4228 | CF3: 31.4953 | CG3: 37.3305 | CH3: 37.6121 | CI3: 38.5231 | CJ3: 36.1515 | CK3: 37.2716 | CL3: 39.3726 | CM3: 39.3726 | CN3: 38.1338 | CO3: 37.5492 | CP3: 39.3851 | CQ3: 20.3589 | CR3: 39.4855 | CS3: 34.3369 | CT3: 38.0592 | CU3: 21.2785 | CV3: 39.3224 | CW3: 39.4981 | CX3: 39.2722 | CY3: 38.875 | CZ3: 38.4261 | DA3: 39.2847 | DB3: 38.7451 | DC3: 36.0414 | DD3: 39.473 | DE3: 38.0584 | DF3: 30.9732 | DG3: 39.2722 | DH3: 39.3726 | DI3: 37.0521 | DJ3: 36.5725 | DK3: 38.0404 | DL3: 37.9065 | DM3: 37.9094 | DN3: 39.5734 | DO3: 39.5232 | DP3: 37.7621 | DQ3: 38.1762 | DR3: 35.3921 | DS3: 30.5027 | DT3: 37.7689 | DU3: 37.8994 | DV3: 38.865 | DW3: 36.998769 | DX3: 4587.8473
A4: 3 | B4: 1 | C4: 38.2316 | D4: 36.3911 | E4: 37.7295 | F4: 38.5193 | G4: 38.8204 | H4: 36.7604 | I4: 35.2892 | J4: 36.4084 | K4: 35.5428 | L4: 37.3654 | M4: 37.3199 | N4: 34.8881 | O4: 24.2281 | P4: 37.178 | Q4: 37.4132 | R4: 27.7467 | S4: 17.6617 | T4: 34.6832 | U4: 37.5871 | V4: 35.3599 | W4: 36.5418 | X4: 38.5695 | Y4: 38.0217 | Z4: 38.6197 | AA4: 37.2466 | AB4: 34.8614 | AC4: 36.0668 | AD4: 35.5979 | AE4: 26.278 | AF4: 36.5998 | AG4: 30.4581 | AH4: 27.5684 | AI4: 35.4513 | AJ4: 37.0604 | AK4: 36.7432 | AL4: 38.8706 | AM4: 35.4005 | AN4: 38.0666 | AO4: 34.5887 | AP4: 38.8455 | AQ4: 37.7186 | AR4: 10 | AS4: 37.4957 | AT4: 38.1337 | AU4: 37.7029 | AV4: 36.8423 | AW4: 38.4942 | AX4: 37.0908 | AY4: 37.5684 | AZ4: 27.794 | BA4: 34.9292 | BB4: 36.2472 | BC4: 37.5977 | BD4: 35.2104 | BE4: 36.6855 | BF4: 31.3678 | BG4: 36.0179 | BH4: 36.7631 | BI4: 36.2766 | BJ4: 37.8812 | BK4: 35.5423 | BL4: 37.4825 | BM4: 35.9654 | BN4: 36.8313 | BO4: 10 | BP4: 38.7451 | BQ4: 34.981 | BR4: 35.4909 | BS4: 33.9194 | BT4: 36.5042 | BU4: 37.1927 | BV4: 38.7953 | BW4: 37.9247 | BX4: 37.7834 | BY4: 35.5444 | BZ4: 36.807 | CA4: 38.5695 | CB4: 36.2218 | CC4: 36.7712 | CD4: 37.8354 | CE4: 38.8455 | CF4: 27.7624 | CG4: 33.7658 | CH4: 37.0223 | CI4: 35.6747 | CJ4: 35.5367 | CK4: 34.903 | CL4: 38.7451 | CM4: 37.7538 | CN4: 36.3381 | CO4: 35.6051 | CP4: 38.0053 | CQ4: 19.6311 | CR4: 36.6127 | CS4: 30.2809 | CT4: 37.4695 | CU4: 18.7941 | CV4: 36.9587 | CW4: 38.2973 | CX4: 35.4681 | CY4: 38.4483 | CZ4: 37.7736 | DA4: 38.5695 | DB4: 38.2558 | DC4: 34.8722 | DD4: 38.0301 | DE4: 35.7589 | DF4: 24.601 | DG4: 38.5444 | DH4: 37.8513 | DI4: 34.5082 | DJ4: 33.44 | DK4: 37.3628 | DL4: 34.6182 | DM4: 36.2931 | DN4: 39.1467 | DO4: 37.7882 | DP4: 36.4916 | DQ4: 37.5864 | DR4: 29.7812 | DS4: 10 | DT4: 37.1164 | DU4: 37.0525 | DV4: 38.2502 | DW4: 34.991258 | DX4: 4338.916
A5: 4 | B5: 1.5 | C5: 35.9688 | D5: 35.7762 | E5: 36.9388 | F5: 37.7789 | G5: 38.2307 | H5: 35.5349 | I5: 34.6241 | J5: 36.0194 | K5: 34.5227 | L5: 35.1317 | M5: 35.2421 | N5: 34.2983 | O5: 22.6139 | P5: 34.4228 | Q5: 35.2243 | R5: 20.7369 | S5: 10 | T5: 32.7801 | U5: 36.4395 | V5: 34.6195 | W5: 33.6904 | X5: 37.8542 | Y5: 37.4209 | Z5: 35.931 | AA5: 36.5815 | AB5: 33.8558 | AC5: 35.4394 | AD5: 34.9579 | AE5: 25.5878 | AF5: 33.9246 | AG5: 29.6926 | AH5: 22.7464 | AI5: 34.185 | AJ5: 36.2252 | AK5: 35.3348 | AL5: 38.116 | AM5: 34.773 | AN5: 36.0634 | AO5: 33.8652 | AP5: 38.2683 | AQ5: 36.2079 | AR5: 10 | AS5: 36.7679 | AT5: 36.0661 | AU5: 36.6194 | AV5: 31.9703 | AW5: 37.7413 | AX5: 35.0087 | AY5: 36.9661 | AZ5: 27.1415 | BA5: 34.4398 | BB5: 34.6442 | BC5: 37.2213 | BD5: 32.7277 | BE5: 34.429 | BF5: 29.1091 | BG5: 32.9446 | BH5: 36.0456 | BI5: 34.4149 | BJ5: 36.8738 | BK5: 34.8387 | BL5: 36.8425 | BM5: 34.9007 | BN5: 33.772 | BO5: 10 | BP5: 38.1177 | BQ5: 34.5167 | BR5: 34.8258 | BS5: 31.1652 | BT5: 34.9626 | BU5: 36.49 | BV5: 38.193 | BW5: 33.7636 | BX5: 37.0914 | BY5: 33.2372 | BZ5: 36.2674 | CA5: 37.8542 | CB5: 33.7974 | CC5: 34.282 | CD5: 33.9943 | CE5: 38.2683 | CF5: 26.0916 | CG5: 32.0746 | CH5: 34.7979 | CI5: 35.0347 | CJ5: 33.2562 | CK5: 34.2881 | CL5: 38.1177 | CM5: 35.3058 | CN5: 35.8236 | CO5: 34.9525 | CP5: 37.3904 | CQ5: 18.3601 | CR5: 35.6985 | CS5: 26.8593 | CT5: 36.8797 | CU5: 18.1165 | CV5: 36.2811 | CW5: 36.2978 | CX5: 34.2164 | CY5: 38.0217 | CZ5: 36.1998 | DA5: 37.8542 | DB5: 36.2354 | DC5: 33.703 | DD5: 37.503 | DE5: 35.0562 | DF5: 18.2533 | DG5: 36.5275 | DH5: 36.5528 | DI5: 33.2576 | DJ5: 31.3456 | DK5: 36.6852 | DL5: 32.256 | DM5: 35.6595 | DN5: 37.2529 | DO5: 36.7331 | DP5: 34.8872 | DQ5: 36.1522 | DR5: 27.6186 | DS5: 10 | DT5: 34.5345 | DU5: 36.3624 | DV5: 35.4791 | DW5: 33.467018 | DX5: 4149.9102
A6: 5 | B6: 2 | C6: 35.4292 | D6: 33.2148 | E6: 36.2988 | F6: 37.0386 | G6: 37.6409 | H6: 34.1793 | I6: 32.3495 | J6: 33.9156 | K6: 32.2843 | L6: 34.4917 | M6: 34.6398 | N6: 33.1323 | O6: 20.7063 | P6: 32.9066 | Q6: 33.5924 | R6: 17.4485 | S6: 10 | T6: 29.9816 | U6: 34.3272 | V6: 32.1049 | W6: 31.5516 | X6: 35.6525 | Y6: 36.3964 | Z6: 35.2409 | AA6: 35.9165 | AB6: 30.021 | AC6: 33.5707 | AD6: 31.1958 | AE6: 24.8976 | AF6: 33.1997 | AG6: 26.8705 | AH6: 20.6526 | AI6: 32.6071 | AJ6: 33.6326 | AK6: 33.9863 | AL6: 35.6518 | AM6: 34.1456 | AN6: 34.8141 | AO6: 31.0283 | AP6: 37.6911 | AQ6: 35.4371 | AR6: 10 | AS6: 35.108 | AT6: 35.2767 | AU6: 35.1451 | AV6: 31.0933 | AW6: 36.9884 | AX6: 32.8398 | AY6: 35.4711 | AZ6: 26.489 | BA6: 33.9504 | BB6: 32.4559 | BC6: 35.1954 | BD6: 31.9974 | BE6: 32.6718 | BF6: 26.8357 | BG6: 32.1253 | BH6: 33.5262 | BI6: 32.5532 | BJ6: 35.6065 | BK6: 33.4255 | BL6: 33.9409 | BM6: 31.1947 | BN6: 33.0818 | BO6: 10 | BP6: 37.4903 | BQ6: 31.9158 | BR6: 34.1607 | BS6: 27.2029 | BT6: 33.0394 | BU6: 34.3854 | BV6: 37.5907 | BW6: 32.8285 | BX6: 35.5669 | BY6: 32.5471 | BZ6: 34.1905 | CA6: 37.1389 | CB6: 31.8439 | CC6: 32.7609 | CD6: 33.3293 | CE6: 37.6911 | CF6: 23.539 | CG6: 31.5601 | CH6: 34.0446 | CI6: 33.5578 | CJ6: 32.6413 | CK6: 33.1853 | CL6: 37.4903 | CM6: 33.9998 | CN6: 34.7967 | CO6: 31.2101 | CP6: 36.0106 | CQ6: 16.1841 | CR6: 34.3958 | CS6: 25.1489 | CT6: 34.9389 | CU6: 14.7368 | CV6: 33.9175 | CW6: 35.7959 | CX6: 31.4714 | CY6: 36.7892 | CZ6: 35.5472 | DA6: 37.1389 | DB6: 35.746 | DC6: 30.6524 | DD6: 36.976 | DE6: 34.3535 | DF6: 12.1907 | DG6: 35.1981 | DH6: 35.4785 | DI6: 30.715 | DJ6: 30.3869 | DK6: 34.6269 | DL6: 29.2834 | DM6: 34.2943 | DN6: 36.1416 | DO6: 33.4562 | DP6: 32.0689 | DQ6: 33.8543 | DR6: 20.7867 | DS6: 10 | DT6: 33.882 | DU6: 35.6722 | DV6: 33.5423 | DW6: 31.837924 | DX6: 3947.9026
A7: 6 | B7: 2.5 | C7: 34.8035 | D7: 32.1673 | E7: 35.6588 | F7: 36.2982 | G7: 37.0511 | H7: 32.2272 | I7: 29.9133 | J7: 32.128 | K7: 31.6067 | L7: 33.533 | M7: 34.0375 | N7: 31.0059 | O7: 18.2266 | P7: 32.3419 | Q7: 31.4917 | R7: 16.2666 | S7: 10 | T7: 28.2135 | U7: 32.426 | V7: 31.3645 | W7: 29.4173 | X7: 34.9373 | Y7: 35.2307 | Z7: 33.1881 | AA7: 33.8281 | AB7: 28.1281 | AC7: 32.2618 | AD7: 30.5558 | AE7: 24.2075 | AF7: 32.0847 | AG7: 26.1051 | AH7: 20.0753 | AI7: 28.8468 | AJ7: 32.9927 | AK7: 32.078 | AL7: 35.0871 | AM7: 30.4448 | AN7: 34.168 | AO7: 29.0832 | AP7: 37.1138 | AQ7: 34.2435 | AR7: 10 | AS7: 34.2636 | AT7: 33.8083 | AU7: 34.5177 | AV7: 29.7469 | AW7: 36.2354 | AX7: 32.0994 | AY7: 34.8687 | AZ7: 25.8365 | BA7: 33.461 | BB7: 31.6034 | BC7: 34.819 | BD7: 30.8512 | BE7: 30.4153 | BF7: 26.1205 | BG7: 30.0085 | BH7: 32.8987 | BI7: 31.7752 | BJ7: 34.859 | BK7: 32.8232 | BL7: 32.8283 | BM7: 30.3834 | BN7: 30.9351 | BO7: 10 | BP7: 36.8629 | BQ7: 31.4515 | BR7: 31.0769 | BS7: 26.4625 | BT7: 30.3566 | BU7: 33.6827 | BV7: 36.9884 | BW7: 30.2056 | BX7: 34.9269 | BY7: 30.7789 | BZ7: 33.0744 | CA7: 36.4237 | CB7: 30.2763 | CC7: 31.0924 | CD7: 32.6642 | CE7: 37.1138 | CF7: 23.0497 | CG7: 28.3068 | CH7: 32.3106 | CI7: 32.6167 | CJ7: 30.9665 | CK7: 31.0211 | CL7: 36.8629 | CM7: 32.7693 | CN7: 32.9156 | CO7: 30.5576 | CP7: 35.3957 | CQ7: 15.4563 | CR7: 31.9116 | CS7: 24.4336 | CT7: 34.1107 | CU7: 12.3913 | CV7: 33.2399 | CW7: 33.5967 | CX7: 28.9685 | CY7: 36.2014 | CZ7: 33.9734 | DA7: 36.4237 | DB7: 35.2567 | DC7: 28.8452 | DD7: 36.449 | DE7: 31.104 | DF7: 10.3908 | DG7: 34.0407 | DH7: 34.4041 | DI7: 27.3181 | DJ7: 25.4634 | DK7: 33.9493 | DL7: 28.5305 | DM7: 31.9371 | DN7: 35.715 | DO7: 32.9793 | DP7: 31.2772 | DQ7: 32.8099 | DR7: 17.885 | DS7: 10 | DT7: 32.5279 | DU7: 33.4149 | DV7: 32.3612 | DW7: 30.544951 | DX7: 3787.5739
A8: 7 | B8: 3 | C8: 32.6269 | D8: 31.5524 | E8: 35.0188 | F8: 35.5578 | G8: 36.4613 | H8: 29.6386 | I8: 29.1996 | J8: 30.8037 | K8: 27.9604 | L8: 31.618 | M8: 33.4351 | N8: 30.4162 | O8: 16.6075 | P8: 30.4828 | Q8: 29.8194 | R8: 13.21 | S8: 10 | T8: 26.3518 | U8: 30.6908 | V8: 29.979 | W8: 26.5614 | X8: 32.7356 | Y8: 34.8417 | Z8: 31.8621 | AA8: 33.1631 | AB8: 26.2622 | AC8: 30.1029 | AD8: 29.2771 | AE8: 23.5173 | AF8: 29.7995 | AG8: 25.3396 | AH8: 19.4981 | AI8: 28.37 | AJ8: 30.4001 | AK8: 31.4757 | AL8: 34.1425 | AM8: 29.5461 | AN8: 31.736 | AO8: 26.904 | AP8: 36.5366 | AQ8: 33.1557 | AR8: 10 | AS8: 33.0115 | AT8: 32.0363 | AU8: 32.5874 | AV8: 26.8144 | AW8: 35.4825 | AX8: 28.7317 | AY8: 33.3737 | AZ8: 25.1839 | BA8: 32.9716 | BB8: 30.1255 | BC8: 33.3704 | BD8: 26.6012 | BE8: 29.0096 | BF8: 22.786 | BG8: 28.0389 | BH8: 31.1902 | BI8: 30.3075 | BJ8: 34.3194 | BK8: 29.576 | BL8: 32.1884 | BM8: 28.1606 | BN8: 29.1664 | BO8: 10 | BP8: 36.2354 | BQ8: 29.8218 | BR8: 29.6516 | BS8: 25.7222 | BT8: 29.5746 | BU8: 31.5781 | BV8: 36.386 | BW8: 27.7322 | BX8: 34.2869 | BY8: 29.1904 | BZ8: 32.3426 | CA8: 35.7084 | CB8: 28.072 | CC8: 28.7506 | CD8: 28.8231 | CE8: 36.5366 | CF8: 21.146 | CG8: 27.7924 | CH8: 31.067 | CI8: 29.2324 | CJ8: 29.7459 | CK8: 27.6973 | CL8: 36.2354 | CM8: 29.2545 | CN8: 32.4011 | CO8: 27.4952 | CP8: 34.3134 | CQ8: 12.7371 | CR8: 31.3971 | CS8: 22.7232 | CT8: 33.1236 | CU8: 11.7137 | CV8: 31.2977 | CW8: 32.5956 | CX8: 27.2002 | CY8: 35.1712 | CZ8: 33.3209 | DA8: 35.7084 | DB8: 34.7673 | DC8: 25.3615 | DD8: 35.057 | DE8: 30.1123 | DF8: 10 | DG8: 31.8519 | DH8: 33.7767 | DI8: 24.2053 | DJ8: 23.8269 | DK8: 31.8911 | DL8: 27.7776 | DM8: 31.1234 | DN8: 35.2883 | DO8: 30.3822 | DP8: 29.7744 | DQ8: 30.1223 | DR8: 13.7012 | DS8: 10 | DT8: 30.6476 | DU8: 32.7247 | DV8: 28.8344 | DW8: 29.005632 | DX8: 3596.6984
A9: 8 | B9: 3.5 | C9: 32.0873 | D9: 29.8561 | E9: 34.3789 | F9: 34.8175 | G9: 35.8715 | H9: 28.9986 | I9: 27.7071 | J9: 29.2357 | K9: 26.807 | L9: 30.8983 | M9: 31.3573 | N9: 29.8264 | O9: 11.9307 | P9: 29.022 | Q9: 28.8167 | R9: 12.6328 | S9: 10 | T9: 22.8525 | U9: 28.1307 | V9: 28.1095 | W9: 25.9591 | X9: 32.0203 | Y9: 34.4527 | Z9: 30.8994 | AA9: 31.8575 | AB9: 22.3155 | AC9: 28.3286 | AD9: 26.1537 | AE9: 22.8271 | AF9: 29.1721 | AG9: 22.7045 | AH9: 18.9209 | AI9: 24.5916 | AJ9: 29.5649 | AK9: 30.6868 | AL9: 31.8683 | AM9: 27.9507 | AN9: 29.7328 | AO9: 24.2776 | AP9: 35.9594 | AQ9: 32.4906 | AR9: 10 | AS9: 31.7593 | AT9: 30.5329 | AU9: 31.96 | AV9: 25.5617 | AW9: 34.7296 | AX9: 27.8485 | AY9: 31.5444 | AZ9: 24.5314 | BA9: 32.4822 | BB9: 28.1634 | BC9: 32.4167 | BD9: 26.0868 | BE9: 27.9553 | BF9: 21.4252 | BG9: 25.7578 | BH9: 29.6618 | BI9: 28.0517 | BJ9: 33.7798 | BK9: 28.2642 | BL9: 29.8086 | BM9: 25.5042 | BN9: 27.7664 | BO9: 10 | BP9: 35.608 | BQ9: 28.3863 | BR9: 28.9865 | BS9: 22.7907 | BT9: 27.2393 | BU9: 30.8754 | BV9: 35.7837 | BW9: 27.1048 | BX9: 33.0746 | BY9: 28.5002 | BZ9: 29.8814 | CA9: 34.9931 | CB9: 26.7551 | CC9: 28.0981 | CD9: 28.1581 | CE9: 35.9594 | CF9: 20.6566 | CG9: 27.2779 | CH9: 30.4772 | CI9: 28.5925 | CJ9: 28.6768 | CK9: 26.1496 | CL9: 35.608 | CM9: 28.6271 | CN9: 30.0075 | CO9: 26.1627 | CP9: 33.401 | CQ9: 12.0093 | CR9: 30.7227 | CS9: 22.008 | CT9: 31.3418 | CU9: 10 | CV9: 30.1986 | CW9: 32.0936 | CX9: 24.1359 | CY9: 34.3148 | CZ9: 32.4124 | DA9: 34.9931 | DB9: 32.7469 | DC9: 23.867 | DD9: 34.4791 | DE9: 29.2306 | DF9: 10 | DG9: 31.1241 | DH9: 32.2554 | DI9: 23.4255 | DJ9: 22.2861 | DK9: 31.2135 | DL9: 27.0247 | DM9: 29.6261 | DN9: 34.8617 | DO9: 28.6473 | DP9: 26.7022 | DQ9: 29.5325 | DR9: 10 | DS9: 10 | DT9: 29.9951 | DU9: 30.5458 | DV9: 28.2195 | DW9: 27.737964 | DX9: 3439.5075
A10: 9 | B10: 4 | C10: 30.6216 | D10: 27.9705 | E10: 33.7659 | F10: 34.0987 | G10: 19.179 | H10: 25.1411 | I10: 24.5806 | J10: 27.8801 | K10: 24.3279 | L10: 28.7767 | M10: 30.7982 | N10: 28.6574 | O10: 10 | P10: 27.1577 | Q10: 26.4731 | R10: 10 | S10: 10 | T10: 22.286 | U10: 26.4854 | V10: 27.4123 | W10: 22.105 | X10: 29.9943 | Y10: 33.4606 | Z10: 28.5265 | AA10: 30.4475 | AB10: 21.1556 | AC10: 26.9887 | AD10: 24.9964 | AE10: 22.1801 | AF10: 26.4317 | AG10: 21.7791 | AH10: 18.3868 | AI10: 23.507 | AJ10: 28.9627 | AK10: 28.2512 | AL10: 31.3306 | AM10: 25.149 | AN10: 29.1862 | AO10: 21.2101 | AP10: 35.4199 | AQ10: 30.912 | AR10: 10 | AS10: 31.0747 | AT10: 28.7218 | AU10: 31.3757 | AV10: 23.5073 | AW10: 34.0199 | AX10: 26.8494 | AY10: 30.9357 | AZ10: 23.9113 | BA10: 32.0252 | BB10: 26.9788 | BC10: 31.4237 | BD10: 23.3275 | BE10: 26.2859 | BF10: 19.9208 | BG10: 24.7904 | BH10: 28.6956 | BI10: 27.3169 | BJ10: 32.3262 | BK10: 27.4307 | BL10: 28.212 | BM10: 24.5214 | BN10: 25.8479 | BO10: 10 | BP10: 35.013 | BQ10: 27.9652 | BR10: 25.1803 | BS10: 19.0272 | BT10: 25.0594 | BU10: 30.2159 | BV10: 35.2138 | BW10: 22.6792 | BX10: 32.1081 | BY10: 26.865 | BZ10: 29.3742 | CA10: 34.3211 | CB10: 24.5344 | CC10: 27.4887 | CD10: 25.5581 | CE10: 35.4091 | CF10: 18.4633 | CG10: 26.8066 | CH10: 28.1325 | CI10: 25.5573 | CJ10: 26.8884 | CK10: 25.5617 | CL10: 35.013 | CM10: 26.2132 | CN10: 29.5146 | CO10: 24.8488 | CP10: 32.8293 | CQ10: 10 | CR10: 28.4591 | CS10: 21.3359 | CT10: 30.7898 | CU10: 10 | CV10: 28.8844 | CW10: 30.8092 | CX10: 21.5361 | CY10: 33.3942 | CZ10: 31.1161 | DA10: 34.3211 | DB10: 32.2845 | DC10: 22.0217 | DD10: 33.9736 | DE10: 25.8928 | DF10: 10 | DG10: 28.6348 | DH10: 31.5718 | DI10: 19.3542 | DJ10: 18.9328 | DK10: 30.5736 | DL10: 26.3042 | DM10: 28.2548 | DN10: 32.6199 | DO10: 26.4788 | DP10: 25.3788 | DQ10: 28.273 | DR10: 10 | DS10: 10 | DT10: 29.3642 | DU10: 29.7988 | DV10: 24.5707 | DW10: 26.179535 | DX10: 3246.2623
A11: 10 | B11: 4.5 | C11: 29.6186 | D11: 27.7457 | E11: 33.516 | F11: 33.6704 | G11: 19.2099 | H11: 25.1252 | I11: 24.5396 | J11: 27.0238 | K11: 22.3409 | L11: 28.6048 | M11: 30.8178 | N11: 27.0591 | O11: 10 | P11: 25.3345 | Q11: 24.977 | R11: 10 | S11: 10 | T11: 20.629 | U11: 24.9733 | V11: 25.5218 | W11: 21.3025 | X11: 29.5204 | Y11: 32.763 | Z11: 28.4604 | AA11: 30.3285 | AB11: 18.9437 | AC11: 25.2786 | AD11: 22.7317 | AE11: 22.1141 | AF11: 22.6418 | AG11: 21.4037 | AH11: 18.429 | AI11: 23.1388 | AJ11: 26.721 | AK11: 28.1169 | AL11: 29.0665 | AM11: 24.6528 | AN11: 27.1476 | AO11: 19.5344 | AP11: 35.3888 | AQ11: 30.793 | AR11: 10 | AS11: 29.9223 | AT11: 27.6742 | AU11: 31.3724 | AV11: 21.7261 | AW11: 33.8911 | AX11: 25.3563 | AY11: 28.8874 | AZ11: 23.7268 | BA11: 32.0039 | BB11: 26.403 | BC11: 30.6817 | BD11: 21.2008 | BE11: 25.6634 | BF11: 18.4381 | BG11: 23.5478 | BH11: 26.7585 | BI11: 25.1926 | BJ11: 32.0987 | BK11: 25.3513 | BL11: 27.6886 | BM11: 23.3464 | BN11: 24.811 | BO11: 10 | BP11: 34.8536 | BQ11: 25.9885 | BR11: 25.0613 | BS11: 18.5989 | BT11: 24.3518 | BU11: 30.1372 | BV11: 35.0795 | BW11: 22.6758 | BX11: 32.0142 | BY11: 25.8108 | BZ11: 27.1888 | CA11: 34.2299 | CB11: 24.1599 | CC11: 26.0986 | CD11: 24.1524 | CE11: 35.222 | CF11: 17.1712 | CG11: 25.7394 | CH11: 28.1634 | CI11: 24.5173 | CJ11: 26.8196 | CK11: 22.6504 | CL11: 34.8536 | CM11: 24.3823 | CN11: 27.6893 | CO11: 22.9437 | CP11: 32.8376 | CQ11: 10 | CR11: 27.3459 | CS11: 21.1342 | CT11: 30.2693 | CU11: 10 | CV11: 27.7412 | CW11: 29.1436 | CX11: 20.115 | CY11: 33.5719 | CZ11: 30.7756 | DA11: 34.2299 | DB11: 32.1852 | DC11: 20.4544 | DD11: 33.7586 | DE11: 25.5022 | DF11: 10 | DG11: 28.4452 | DH11: 30.774 | DI11: 17.8273 | DJ11: 17.219 | DK11: 29.7518 | DL11: 26.0193 | DM11: 28.3422 | DN11: 32.5239 | DO11: 25.2521 | DP11: 22.7788 | DQ11: 26.2175 | DR11: 10.0196 | DS11: 10 | DT11: 28.1467 | DU11: 29.4207 | DV11: 23.6784 | DW11: 25.330335 | DX11: 3140.9615
A12: 11 | B12: 5 | C12: 30.4463 | D12: 26.5757 | E12: 34.5817 | F12: 34.3174 | G12: 21.3058 | H12: 26.0048 | I12: 24.9009 | J12: 26.6457 | K12: 23.0444 | L12: 28.5599 | M12: 32.9024 | N12: 29.155 | O12: 11.4594 | P12: 26.411 | Q12: 25.7482 | R12: 10 | S12: 10.7035 | T12: 18.6875 | U12: 26.2277 | V12: 27.4821 | W12: 21.3362 | X12: 29.2914 | Y12: 34.383 | Z12: 30.4659 | AA12: 30.7473 | AB12: 18.0664 | AC12: 26.4661 | AD12: 23.9964 | AE12: 24.1196 | AF12: 22.5455 | AG12: 20.4056 | AH12: 20.5362 | AI12: 22.7542 | AJ12: 28.4434 | AK12: 27.8378 | AL12: 30.2 | AM12: 24.1295 | AN12: 29.2434 | AO12: 19.9219 | AP12: 37.1676 | AQ12: 32.4928 | AR12: 12.0055 | AS12: 31.894 | AT12: 27.0611 | AU12: 33.4344 | AV12: 23.2767 | AW12: 35.8401 | AX12: 26.3316 | AY12: 30.972 | AZ12: 25.1096 | BA12: 33.5334 | BB12: 27.3512 | BC12: 21.2067 | BD12: 21.4888 | BE12: 26.0093 | BF12: 18.5678 | BG12: 22.5255 | BH12: 27.5072 | BI12: 26.9418 | BJ12: 32.9264 | BK12: 26.9724 | BL12: 27.2975 | BM12: 24.0273 | BN12: 24.4686 | BO12: 10.6339 | BP12: 36.2589 | BQ12: 28.1973 | BR12: 25.7815 | BS12: 16.4617 | BT12: 23.1687 | BU12: 30.8698 | BV12: 36.5074 | BW12: 22.1509 | BX12: 33.4556 | BY12: 27.8163 | BZ12: 28.6732 | CA12: 36.2128 | CB12: 22.8134 | CC12: 26.9287 | CD12: 24.5725 | CE12: 36.3441 | CF12: 19.0692 | CG12: 27.903 | CH12: 29.965 | CI12: 24.9263 | CJ12: 28.5645 | CK12: 23.7386 | CL12: 36.2589 | CM12: 25.2198 | CN12: 28.309 | CO12: 23.7184 | CP12: 34.2224 | CQ12: 10.6583 | CR12: 26.8866 | CS12: 22.321 | CT12: 31.0354 | CU12: 10.4547 | CV12: 29.4297 | CW12: 29.6768 | CX12: 17.3604 | CY12: 35.2827 | CZ12: 31.5016 | DA12: 36.2128 | DB12: 31.9889 | DC12: 19.0161 | DD12: 34.5976 | DE12: 26.183 | DF12: 10.503 | DG12: 29.4113 | DH12: 32.6572 | DI12: 17.3103 | DJ12: 16.7103 | DK12: 30.819 | DL12: 27.3117 | DM12: 28.5893 | DN12: 34.2384 | DO12: 27.2069 | DP12: 23.1311 | DQ12: 27.3284 | DR12: 12.1042 | DS12: 10.9067 | DT12: 27.9011 | DU12: 30.1129 | DV12: 21.5285 | DW12: 26.012711 | DX12: 3225.5762
A13: 12 | B13: 5.5 | C13: 32.5659 | D13: 29.2788 | E13: 37.2622 | F13: 36.2562 | G13: 25.9854 | H13: 30.559 | I13: 28.1368 | J13: 30.2033 | K13: 21.8168 | L13: 31.8917 | M13: 36.6411 | N13: 31.9329 | O13: 14.1784 | P13: 30.3191 | Q13: 25.2481 | R13: 10.2552 | S13: 12.0027 | T13: 19.2075 | U13: 30.2352 | V13: 30.5744 | W13: 20.6624 | X13: 31.7704 | Y13: 36.6697 | Z13: 35.0552 | AA13: 34.7078 | AB13: 20.713 | AC13: 31.1118 | AD13: 27.5221 | AE13: 28.7088 | AF13: 25.4498 | AG13: 22.9732 | AH13: 25.227 | AI13: 25.1533 | AJ13: 31.0206 | AK13: 31.0356 | AL13: 32.9482 | AM13: 24.3793 | AN13: 33.4142 | AO13: 23.3163 | AP13: 38.4057 | AQ13: 35.5971 | AR13: 16.5948 | AS13: 36.4493 | AT13: 29.2145 | AU13: 37.9042 | AV13: 26.4553 | AW13: 40.3729 | AX13: 27.7142 | AY13: 34.536 | AZ13: 28.4301 | BA13: 37.0008 | BB13: 31.0062 | BC13: 23.6639 | BD13: 21.9971 | BE13: 29.888 | BF13: 21.1805 | BG13: 22.8546 | BH13: 29.5477 | BI13: 30.2106 | BJ13: 34.2038 | BK13: 30.471 | BL13: 31.2806 | BM13: 22.7454 | BN13: 24.1609 | BO13: 14.4958 | BP13: 39.602 | BQ13: 32.9024 | BR13: 29.742 | BS13: 16.2361 | BT13: 26.4779 | BU13: 35.4477 | BV13: 39.8731 | BW13: 25.8737 | BX13: 36.8767 | BY13: 31.031 | BZ13: 31.0576 | CA13: 40.7795 | CB13: 26.2356 | CC13: 31.046 | CD13: 25.9745 | CE13: 39.0811 | CF13: 22.3528 | CG13: 32.6504 | CH13: 33.3205 | CI13: 23.4118 | CJ13: 31.48 | CK13: 25.0282 | CL13: 39.602 | CM13: 25.9891 | CN13: 30.4511 | CO13: 25.3219 | CP13: 38.8794 | CQ13: 10.8161 | CR13: 27.7299 | CS13: 26.8876 | CT13: 35.0637 | CU13: 12.521 | CV13: 33.3789 | CW13: 31.179 | CX13: 18.6593 | CY13: 39.7707 | CZ13: 33.5196 | DA13: 40.7795 | DB13: 34.805 | DC13: 18.2658 | DD13: 35.95 | DE13: 28.1558 | DF13: 13.3852 | DG13: 33.2705 | DH13: 36.6772 | DI13: 20.1203 | DJ13: 20.5614 | DK13: 34.7682 | DL13: 30.5419 | DM13: 32.5266 | DN13: 37.6564 | DO13: 30.6062 | DP13: 25.5379 | DQ13: 30.054 | DR13: 15.0565 | DS13: 12.551 | DT13: 29.919 | DU13: 31.3917 | DV13: 21.1473 | DW13: 28.731836 | DX13: 3562.7477
... A49: 48 | B49: 23.5 | C49: 61.0848 | D49: 88.8216 | E49: 95.0331 | F49: 65.3605 | G49: 76.349 | H49: 50.2746 | I49: 21.7744 | J49: 64.8234 | K49: 45.5772 | L49: 31.6046 | M49: 80.5809 | N49: 30.0548 | O49: 63.9648 | P49: 41.5574 | Q49: 73.756 | R49: 33.9866 | S49: 25.909 | T49: 12.9149 | U49: 22.5474 | V49: 43.0793 | W49: 64.1292 | X49: 90.8141 | Y49: 58.2403 | Z49: 90.3485 | AA49: 92.715 | AB49: 10 | AC49: 42.2163 | AD49: 85.1275 | AE49: 36.1625 | AF49: 90.6258 | AG49: 10 | AH49: 59.5585 | AI49: 75.6159 | AJ49: 52.1862 | AK49: 10 | AL49: 10 | AM49: 21.2083 | AN49: 76.7996 | AO49: 68.282 | AP49: 81.8513 | AQ49: 31.7814 | AR49: 85.8286 | AS49: 31.9509 | AT49: 77.7894 | AU49: 91.7884 | AV49: 10 | AW49: 30.5354 | AX49: 48.7048 | AY49: 10 | AZ49: 10 | BA49: 43.9113 | BB49: 67.3196 | BC49: 80.1824 | BD49: 11.6709 | BE49: 52.0934 | BF49: 17.9594 | BG49: 54.8456 | BH49: 55.9713 | BI49: 88.2997 | BJ49: 56.0297 | BK49: 26.8513 | BL49: 79.5024 | BM49: 38.1727 | BN49: 62.1059 | BO49: 39.6217 | BP49: 10 | BQ49: 74.2504 | BR49: 87.7314 | BS49: 10 | BT49: 14.0155 | BU49: 73.0014 | BV49: 45.1415 | BW49: 86.6899 | BX49: 92.9273 | BY49: 83.4543 | BZ49: 54.4366 | CA49: 74.2272 | CB49: 46.9482 | CC49: 67.3619 | CD49: 56.1759 | CE49: 88.1624 | CF49: 10 | CG49: 68.0592 | CH49: 76.7015 | CI49: 84.2552 | CJ49: 32.0082 | CK49: 77.9816 | CL49: 94.7467 | CM49: 48.8163 | CN49: 28.0243 | CO49: 84.8242 | CP49: 10 | CQ49: 49.2992 | CR49: 36.1708 | CS49: 17.4269 | CT49: 86.129 | CU49: 29.1234 | CV49: 56.0708 | CW49: 64.5044 | CX49: 10 | CY49: 64.1264 | CZ49: 17.6738 | DA49: 44.9047 | DB49: 18.733 | DC49: 40.1746 | DD49: 82.3714 | DE49: 39.2085 | DF49: 10 | DG49: 66.8422 | DH49: 75.9605 | DI49: 24.7038 | DJ49: 78.8312 | DK49: 10 | DL49: 48.928 | DM49: 66.9818 | DN49: 40.4063 | DO49: 78.824 | DP49: 86.139 | DQ49: 73.3901 | DR49: 67.1623 | DS49: 41.1209 | DT49: 10 | DU49: 24.7765 | DV49: 10 | DW49: 51.675614 | DX49: 6407.7761

Sheet Demand_kW
A1: period | B1: hour | C1: BES_TR8_one223_B | D1: BES_TR8_one252_C | E1: BES_TR8_one280_A | F1: BES_TR8_one313_A | G1: BES_TR8_one321_C | H1: BES_TR8_one345_A | I1: BES_TR8_one375_C | J1: BES_TR8_one410_B | K1: BES_TR8_one416_C | L1: BES_TR8_one423_B | M1: BES_TR8_one446_B | N1: BES_TR8_one469_A | O1: BES_TR8_one477_A | P1: BES_TR8_one482_B | Q1: BES_TR8_one61_A | R1: BES_TR8_one552_B | S1: BES_TR8_one560_C | T1: BES_TR8_one73_A | U1: BES_TR8_one137_A | V1: BES_TR8_four50_C | W1: BES_TR8_four171_A | X1: BES_TR8_four180_A | Y1: BES_TR8_four200_A | Z1: BES_TR8_four239_A | AA1: BES_TR8_four259_B | AB1: BES_TR8_four265_C | AC1: BES_TR8_four54_C | AD1: BES_TR8_four288_B | AE1: BES_TR8_four289_B | AF1: BES_TR8_four292_C | AG1: BES_TR8_four301_C | AH1: BES_TR8_four326_A | AI1: BES_TR8_four352_A | AJ1: BES_TR8_four358_C | AK1: BES_TR8_four368_C | AL1: BES_TR8_four372_C | AM1: BES_TR8_four381_A | AN1: BES_TR8_four385_A | AO1: BES_TR8_four423_C | AP1: BES_TR8_four437_A | AQ1: BES_TR8_four446_B | AR1: BES_TR8_four466_C | AS1: BES_TR8_four467_C | AT1: BES_TR8_four548_B | AU1: BES_TR8_four558_C | AV1: BES_TR8_four562_C | AW1: BES_TR8_four590_A | AX1: BES_TR8_four604_A | AY1: BES_TR8_four78_B | AZ1: BES_TR8_four734_A | BA1: BES_TR8_four797_C | BB1: BES_TR8_four846_C | BC1: BES_TR8_four854_A | BD1: BES_TR8_four936_C | BE1: BES_TR8_four950_B | BF1: BES_TR8_four978_A | BG1: BES_TR8_four104_A | BH1: BES_TR8_four988_A | BI1: BES_TR8_four1013_B | BJ1: BES_TR8_four1027_A | BK1: BES_TR8_four1132_C | BL1: BES_TR8_four126_A | BM1: BES_TR8_four1187_A | BN1: BES_TR8_four1207_B | BO1: BES_TR8_five168_A | BP1: BES_TR8_five186_C | BQ1: BES_TR8_five194_C | BR1: BES_TR8_five223_A | BS1: BES_TR8_five303_B | BT1: BES_TR8_five324_B | BU1: BES_TR8_five345_A | BV1: BES_TR8_five421_A | BW1: BES_TR8_five488_B | BX1: BES_TR8_five513_B | BY1: BES_TR8_five537_C | BZ1: BES_TR8_five540_A | CA1: BES_TR8_five551_C | CB1: BES_TR8_five631_B | CC1: BES_TR8_five649_A | CD1: BES_TR8_five663_C | CE1: BES_TR8_five670_C | CF1: BES_TR8_five704_A | CG1: BES_TR8_five719_A | CH1: BES_TR8_five750_B | CI1: BES_TR8_five793_A | CJ1: BES_TR8_five801_C | CK1: BES_TR8_five905_B | CL1: BES_TR8_five118_B | CM1: BES_TR8_five123_B | CN1: BES_TR8_six64_A | CO1: BES_TR8_six154_C | CP1: BES_TR8_six173_C | CQ1: BES_TR8_six232_C | CR1: BES_TR8_six238_A | CS1: BES_TR8_six269_C | CT1: BES_TR8_six289_C | CU1: BES_TR8_six317_C | CV1: BES_TR8_six326_A | CW1: BES_TR8_six329_A | CX1: BES_TR8_six342_A | CY1: BES_TR8_six350_B | CZ1: BES_TR8_six365_C | DA1: BES_TR8_six75_A | DB1: BES_TR8_six385_B | DC1: BES_TR8_six431_C | DD1: BES_TR8_six571_C | DE1: BES_TR8_six595_B | DF1: BES_TR8_six643_A | DG1: BES_TR8_six652_A | DH1: BES_TR8_six667_A | DI1: BES_TR8_six699_C | DJ1: BES_TR8_six723_B | DK1: BES_TR8_six740_A | DL1: BES_TR8_six90_B | DM1: BES_TR8_six801_C | DN1: BES_TR8_six807_A | DO1: BES_TR8_six844_C | DP1: BES_TR8_six860_C | DQ1: BES_TR8_six909_C | DR1: BES_TR8_six914_A | DS1: BES_TR8_six111_C | DT1: BES_TR8_six1006_C | DU1: BES_TR8_six1020_A | DV1: BES_TR8_six1064_C | DW1: fleet_average | DX1: fleet_total
A2: 1 | B2: 0 | C2: 0.097928 | D2: 0.049 | E2: 0.054624333 | F2: 0.059 | G2: 0.047 | H2: 0.15037667 | I2: 0.13188267 | J2: 0.25522033 | K2: 0.17837333 | L2: 0.15895567 | M2: 0.16558 | N2: 0.22261 | O2: 0.53012433 | P2: 0.17988933 | Q2: 0.075348 | R2: 0.59302333 | S2: 0.961224 | T2: 0.18330067 | U2: 0.072729333 | V2: 0.23365 | W2: 0.227586 | X2: 0.057 | Y2: 0.031 | Z2: 0.055 | AA2: 0.064342 | AB2: 0.19162733 | AC2: 0.186292 | AD2: 0.25616833 | AE2: 0.55997167 | AF2: 0.220962 | AG2: 0.37828833 | AH2: 0.484378 | AI2: 0.059936 | AJ2: 0.18326 | AK2: 0.12977033 | AL2: 0.045 | AM2: 0.078828 | AN2: 0.107072 | AO2: 0.10019833 | AP2: 0.046 | AQ2: 0.12881 | AR2: 2.4385167 | AS2: 0.095141333 | AT2: 0.04 | AU2: 0.13306133 | AV2: 0.196642 | AW2: 0.06 | AX2: 0.059 | AY2: 0.11155267 | AZ2: 0.52604 | BA2: 0.36509733 | BB2: 0.21787367 | BC2: 0.03 | BD2: 0.29324033 | BE2: 0.124101 | BF2: 0.55286467 | BG2: 0.262799 | BH2: 0.179234 | BI2: 0.226871 | BJ2: 0.088565667 | BK2: 0.12333067 | BL2: 0.077798667 | BM2: 0.15307767 | BN2: 0.18429467 | BO2: 1.9461 | BP2: 0.05 | BQ2: 0.36297033 | BR2: 0.067455 | BS2: 0.425566 | BT2: 0.22558267 | BU2: 0.16771533 | BV2: 0.048 | BW2: 0.11537867 | BX2: 0.12564 | BY2: 0.27143133 | BZ2: 0.043 | CA2: 0.057 | CB2: 0.16150667 | CC2: 0.20530233 | CD2: 0.11949867 | CE2: 0.046 | CF2: 0.67774833 | CG2: 0.212737 | CH2: 0.19029333 | CI2: 0.117696 | CJ2: 0.30668767 | CK2: 0.21742667 | CL2: 0.05 | CM2: 0.05 | CN2: 0.14871667 | CO2: 0.195304 | CP2: 0.049 | CQ2: 1.565217 | CR2: 0.041 | CS2: 0.45129867 | CT2: 0.154661 | CU2: 1.4919313 | CV2: 0.054 | CW2: 0.04 | CX2: 0.058 | CY2: 0.089653 | CZ2: 0.125422 | DA2: 0.057 | DB2: 0.10000033 | DC2: 0.31546233 | DD2: 0.042 | DE2: 0.154724 | DF2: 0.71935233 | DG2: 0.058 | DH2: 0.05 | DI2: 0.234921 | DJ2: 0.27314067 | DK2: 0.15616267 | DL2: 0.166834 | DM2: 0.16659933 | DN2: 0.034 | DO2: 0.038 | DP2: 0.17833867 | DQ2: 0.145344 | DR2: 0.36720933 | DS2: 0.75684533 | DT2: 0.177796 | DU2: 0.167398 | DV2: 0.090446 | DW2: 0.23955602 | DX2: 29.704946
A3: 2 | B3: 0.5 | C3: 0.043 | D3: 0.238596 | E3: 0.12630973 | F3: 0.059 | G3: 0.047 | H3: 0.10778667 | I3: 0.243526 | J3: 0.031 | K3: 0.176826 | L3: 0.051 | M3: 0.048 | N3: 0.18476 | O3: 0.72674733 | P3: 0.045 | Q3: 0.13079333 | R3: 0.38345067 | S3: 0.81893333 | T3: 0.240402 | U3: 0.11955267 | V3: 0.136124 | W3: 0.048 | X3: 0.057 | Y3: 0.12665333 | Z3: 0.055 | AA3: 0.155078 | AB3: 0.21787233 | AC3: 0.12714933 | AD3: 0.094640333 | AE3: 0.53354867 | AF3: 0.05 | AG3: 0.382116 | AH3: 0.506309 | AI3: 0.302552 | AJ3: 0.051 | AK3: 0.12977033 | AL3: 0.045 | AM3: 0.28771267 | AN3: 0.047 | AO3: 0.33103167 | AP3: 0.046 | AQ3: 0.053 | AR3: 0.055 | AS3: 0.10442667 | AT3: 0.10873 | AU3: 0.05 | AV3: 0.055 | AW3: 0.06 | AX3: 0.17284 | AY3: 0.082220667 | AZ3: 0.44666333 | BA3: 0.039 | BB3: 0.081188667 | BC3: 0.16144 | BD3: 0.08845 | BE3: 0.140036 | BF3: 0.135042 | BG3: 0.054537333 | BH3: 0.078718667 | BI3: 0.069851 | BJ3: 0.080281 | BK3: 0.231904 | BL3: 0.12282467 | BM3: 0.16844567 | BN3: 0.068223333 | BO3: 0.53397667 | BP3: 0.05 | BQ3: 0.037 | BR3: 0.291881 | BS3: 0.059 | BT3: 0.053 | BU3: 0.056 | BV3: 0.048 | BW3: 0.05 | BX3: 0.051 | BY3: 0.083636 | BZ3: 0.211454 | CA3: 0.057 | CB3: 0.13958 | CC3: 0.052 | CD3: 0.053 | CE3: 0.046 | CF3: 0.297479 | CG3: 0.28407 | CH3: 0.047 | CI3: 0.22699267 | CJ3: 0.049 | CK3: 0.18875867 | CL3: 0.05 | CM3: 0.129002 | CN3: 0.1431 | CO3: 0.154932 | CP3: 0.10996 | CQ3: 0.058 | CR3: 0.22893267 | CS3: 0.32322667 | CT3: 0.047 | CU3: 0.197982 | CV3: 0.18836 | CW3: 0.095692 | CX3: 0.303148 | CY3: 0.034 | CZ3: 0.052 | DA3: 0.057 | DB3: 0.039 | DC3: 0.093176 | DD3: 0.114984 | DE3: 0.18325333 | DF3: 0.50780433 | DG3: 0.058 | DH3: 0.121232 | DI3: 0.20272267 | DJ3: 0.249628 | DK3: 0.054 | DL3: 0.26204667 | DM3: 0.12880467 | DN3: 0.034 | DO3: 0.13825867 | DP3: 0.101252 | DQ3: 0.047 | DR3: 0.44713533 | DS3: 1.7480433 | DT3: 0.052 | DU3: 0.067488667 | DV3: 0.049 | DW3: 0.16206498 | DX3: 20.096057
A4: 3 | B4: 1 | C4: 0.18032 | D4: 0.049 | E4: 0.063017867 | F4: 0.059 | G4: 0.047 | H4: 0.097662 | I4: 0.053 | J4: 0.031 | K4: 0.081294667 | L4: 0.17800667 | M4: 0.16558 | N4: 0.047 | O4: 0.12863667 | P4: 0.21956267 | Q4: 0.174438 | R4: 0.55861667 | S4: 0.67008867 | T4: 0.151653 | U4: 0.091458667 | V4: 0.059 | W4: 0.22722767 | X4: 0.057 | Y4: 0.04788 | Z4: 0.214258 | AA4: 0.053 | AB4: 0.080133333 | AC4: 0.05 | AD4: 0.051 | AE4: 0.055 | AF4: 0.213191 | AG4: 0.061 | AH4: 0.38427 | AI4: 0.10091467 | AJ4: 0.06656 | AK4: 0.11222933 | AL4: 0.060137333 | AM4: 0.05 | AN4: 0.159635 | AO4: 0.057654667 | AP4: 0.046 | AQ4: 0.12038667 | AR4: 0.055 | AS4: 0.058 | AT4: 0.16476667 | AU4: 0.086339333 | AV4: 0.388255 | AW4: 0.06 | AX4: 0.16592267 | AY4: 0.048 | AZ4: 0.052 | BA4: 0.039 | BB4: 0.12774933 | BC4: 0.03 | BD4: 0.197847 | BE4: 0.17982 | BF4: 0.17999733 | BG4: 0.24491667 | BH4: 0.057179667 | BI4: 0.148361 | BJ4: 0.080281 | BK4: 0.056076667 | BL4: 0.051 | BM4: 0.084846 | BN4: 0.24379633 | BO4: 0.077342667 | BP4: 0.05 | BQ4: 0.037 | BR4: 0.053 | BS4: 0.21948667 | BT4: 0.12285 | BU4: 0.056 | BV4: 0.048 | BW4: 0.33160767 | BX4: 0.055146667 | BY4: 0.183862 | BZ4: 0.043 | CA4: 0.057 | CB4: 0.19320133 | CC4: 0.19836767 | CD4: 0.30609733 | CE4: 0.046 | CF4: 0.13314267 | CG4: 0.13477667 | CH4: 0.17726667 | CI4: 0.051 | CJ4: 0.18173333 | CK4: 0.049 | CL4: 0.05 | CM4: 0.19508633 | CN4: 0.041 | CO4: 0.052 | CP4: 0.049 | CQ4: 0.10128 | CR4: 0.072853333 | CS4: 0.272669 | CT4: 0.047 | CU4: 0.054 | CV4: 0.054 | CW4: 0.15934 | CX4: 0.099752 | CY4: 0.034 | CZ4: 0.125422 | DA4: 0.057 | DB4: 0.16100067 | DC4: 0.093176 | DD4: 0.042 | DE4: 0.056 | DF4: 0.50585267 | DG4: 0.160725 | DH4: 0.10347667 | DI4: 0.099667333 | DJ4: 0.16691067 | DK4: 0.054 | DL4: 0.18824737 | DM4: 0.050497667 | DN4: 0.150915 | DO4: 0.084082 | DP4: 0.127852 | DQ4: 0.114288 | DR4: 0.17234133 | DS4: 0.257956 | DT4: 0.20575067 | DU4: 0.055 | DV4: 0.22083133 | DW4: 0.12509534 | DX4: 15.511822
A5: 4 | B5: 1.5 | C5: 0.043 | D5: 0.204124 | E5: 0.051 | F5: 0.059 | G5: 0.047 | H5: 0.10803133 | I5: 0.18126367 | J5: 0.16764933 | K5: 0.17837333 | L5: 0.051 | M5: 0.048 | N5: 0.09292 | O5: 0.152019 | P5: 0.120828 | Q5: 0.130044 | R5: 0.26205633 | S5: 0.35930333 | T5: 0.22301567 | U5: 0.16832933 | V5: 0.200394 | W5: 0.170445 | X5: 0.17545333 | Y5: 0.08164 | Z5: 0.055 | AA5: 0.053 | AB5: 0.30560067 | AC5: 0.14891733 | AD5: 0.29980867 | AE5: 0.055 | AF5: 0.057771 | AG5: 0.22489267 | AH5: 0.16685667 | AI5: 0.125744 | AJ5: 0.2066 | AK5: 0.10746933 | AL5: 0.19637333 | AM5: 0.05 | AN5: 0.099563 | AO5: 0.226074 | AP5: 0.046 | AQ5: 0.061423333 | AR5: 0.055 | AS5: 0.13228267 | AT5: 0.06291 | AU5: 0.11748733 | AV5: 0.069886667 | AW5: 0.06 | AX5: 0.17284 | AY5: 0.119142 | AZ5: 0.052 | BA5: 0.039 | BB5: 0.17438093 | BC5: 0.16144 | BD5: 0.058193333 | BE5: 0.140036 | BF5: 0.181166 | BG5: 0.065288 | BH5: 0.200773 | BI5: 0.148361 | BJ5: 0.10099267 | BK5: 0.11261333 | BL5: 0.23122867 | BM5: 0.295335 | BN5: 0.055 | BO5: 0.14737067 | BP5: 0.05 | BQ5: 0.20726533 | BR5: 0.053 | BS5: 0.31576 | BT5: 0.15326133 | BU5: 0.16771533 | BV5: 0.048 | BW5: 0.074517 | BX5: 0.12149333 | BY5: 0.055 | BZ5: 0.165512 | CA5: 0.057 | CB5: 0.15567667 | CC5: 0.12121833 | CD5: 0.053 | CE5: 0.046 | CF5: 0.20341667 | CG5: 0.041 | CH5: 0.060026667 | CI5: 0.117696 | CJ5: 0.049 | CK5: 0.087885333 | CL5: 0.05 | CM5: 0.104069 | CN5: 0.08184 | CO5: 0.298236 | CP5: 0.10996 | CQ5: 0.17341333 | CR5: 0.10382067 | CS5: 0.136302 | CT5: 0.154661 | CU5: 0.269334 | CV5: 0.18836 | CW5: 0.04 | CX5: 0.21875 | CY5: 0.098215 | CZ5: 0.052 | DA5: 0.057 | DB5: 0.039 | DC5: 0.243106 | DD5: 0.042 | DE5: 0.056 | DF5: 0.48313667 | DG5: 0.10593833 | DH5: 0.085616 | DI5: 0.202619 | DJ5: 0.076396 | DK5: 0.16402133 | DL5: 0.23688333 | DM5: 0.108793 | DN5: 0.088560333 | DO5: 0.26114233 | DP5: 0.22459067 | DQ5: 0.183122 | DR5: 0.54443433 | DS5: 0.52382167 | DT5: 0.052 | DU5: 0.055 | DV5: 0.154344 | DW5: 0.13857775 | DX5: 17.183641
A6: 5 | B6: 2 | C6: 0.049866 | D6: 0.083472 | E6: 0.051 | F6: 0.059 | G6: 0.047 | H6: 0.155561 | I6: 0.194145 | J6: 0.142454 | K6: 0.054 | L6: 0.076401333 | M6: 0.048 | N6: 0.16945333 | O6: 0.19760967 | P6: 0.045 | Q6: 0.16741367 | R6: 0.094186 | S6: 0.52779667 | T6: 0.140902 | U6: 0.15150867 | V6: 0.059 | W6: 0.17008667 | X6: 0.057 | Y6: 0.092893333 | Z6: 0.163585 | AA6: 0.16642 | AB6: 0.150845 | AC6: 0.10430067 | AD6: 0.051 | AE6: 0.055 | AF6: 0.088855 | AG6: 0.061 | AH6: 0.046 | AI6: 0.29966067 | AJ6: 0.051 | AK6: 0.15207133 | AL6: 0.045 | AM6: 0.29491967 | AN6: 0.051489667 | AO6: 0.155007 | AP6: 0.046 | AQ6: 0.095116667 | AR6: 0.055 | AS6: 0.067285333 | AT6: 0.11701167 | AU6: 0.05 | AV6: 0.10729467 | AW6: 0.06 | AX6: 0.059 | AY6: 0.048 | AZ6: 0.052 | BA6: 0.039 | BB6: 0.067937333 | BC6: 0.03 | BD6: 0.091342333 | BE6: 0.17982 | BF6: 0.057 | BG6: 0.16868667 | BH6: 0.05 | BI6: 0.062 | BJ6: 0.059569333 | BK6: 0.048 | BL6: 0.088664 | BM6: 0.064649667 | BN6: 0.171073 | BO6: 0.14694267 | BP6: 0.05 | BQ6: 0.037 | BR6: 0.245752 | BS6: 0.059 | BT6: 0.213798 | BU6: 0.056 | BV6: 0.048 | BW6: 0.20902267 | BX6: 0.051 | BY6: 0.140908 | BZ6: 0.088942 | CA6: 0.057 | CB6: 0.124928 | CC6: 0.13296667 | CD6: 0.053 | CE6: 0.046 | CF6: 0.039 | CG6: 0.25925333 | CH6: 0.13818667 | CI6: 0.074999 | CJ6: 0.13346667 | CK6: 0.17246733 | CL6: 0.05 | CM6: 0.098061333 | CN6: 0.14990667 | CO6: 0.052 | CP6: 0.049 | CQ6: 0.058 | CR6: 0.19796533 | CS6: 0.057 | CT6: 0.065999 | CU6: 0.186912 | CV6: 0.054 | CW6: 0.175252 | CX6: 0.19946 | CY6: 0.046843 | CZ6: 0.125422 | DA6: 0.057 | DB6: 0.039 | DC6: 0.14401467 | DD6: 0.042 | DE6: 0.25895533 | DF6: 0.14343333 | DG6: 0.092241667 | DH6: 0.085616 | DI6: 0.27069733 | DJ6: 0.39235667 | DK6: 0.054 | DL6: 0.06 | DM6: 0.18784733 | DN6: 0.034 | DO6: 0.038 | DP6: 0.063094667 | DQ6: 0.083232 | DR6: 0.23124367 | DS6: 0.301805 | DT6: 0.10790933 | DU6: 0.17988667 | DV6: 0.094118 | DW6: 0.11135694 | DX6: 13.80826
A7: 6 | B7: 2.5 | C7: 0.173454 | D7: 0.049 | E7: 0.051 | F7: 0.059 | G7: 0.047 | H7: 0.20629267 | I7: 0.056878333 | J7: 0.105536 | K7: 0.290577 | L7: 0.15260533 | M7: 0.048 | N7: 0.047 | O7: 0.129028 | P7: 0.14815067 | Q7: 0.13325967 | R7: 0.24358 | S7: 0.38999733 | T7: 0.14836267 | U7: 0.138282 | V7: 0.110416 | W7: 0.227586 | X7: 0.17545333 | Y7: 0.031 | Z7: 0.105673 | AA7: 0.053 | AB7: 0.14870067 | AC7: 0.17204667 | AD7: 0.10189567 | AE7: 0.055 | AF7: 0.182107 | AG7: 0.061 | AH7: 0.046 | AI7: 0.038 | AJ7: 0.2066 | AK7: 0.048 | AL7: 0.075274667 | AM7: 0.071621 | AN7: 0.19380393 | AO7: 0.17366167 | AP7: 0.046 | AQ7: 0.086693333 | AR7: 0.055 | AS7: 0.099784 | AT7: 0.14121167 | AU7: 0.15382667 | AV7: 0.23369467 | AW7: 0.06 | AX7: 0.26837867 | AY7: 0.119142 | AZ7: 0.052 | BA7: 0.039 | BB7: 0.11778067 | BC7: 0.115436 | BD7: 0.33868467 | BE7: 0.112024 | BF7: 0.26572667 | BG7: 0.15696 | BH7: 0.136156 | BI7: 0.116957 | BJ7: 0.043 | BK7: 0.25877467 | BL7: 0.051 | BM7: 0.17713667 | BN7: 0.14095167 | BO7: 0.141535 | BP7: 0.05 | BQ7: 0.129872 | BR7: 0.113584 | BS7: 0.059 | BT7: 0.062313333 | BU7: 0.16771533 | BV7: 0.048 | BW7: 0.197102 | BX7: 0.051 | BY7: 0.12659 | BZ7: 0.058314 | CA7: 0.057 | CB7: 0.17566 | CC7: 0.18661933 | CD7: 0.30609733 | CE7: 0.046 | CF7: 0.15170667 | CG7: 0.041 | CH7: 0.099106667 | CI7: 0.26969233 | CJ7: 0.097266667 | CK7: 0.26487667 | CL7: 0.05 | CM7: 0.280096 | CN7: 0.041 | CO7: 0.24404267 | CP7: 0.086253333 | CQ7: 0.21669333 | CR7: 0.041 | CS7: 0.136302 | CT7: 0.078665 | CU7: 0.054 | CV7: 0.15477 | CW7: 0.07978 | CX7: 0.14091267 | CY7: 0.082096667 | CZ7: 0.052 | DA7: 0.057 | DB7: 0.039 | DC7: 0.27761867 | DD7: 0.11092933 | DE7: 0.079022 | DF7: 0.15543533 | DG7: 0.17442167 | DH7: 0.05 | DI7: 0.24806567 | DJ7: 0.130412 | DK7: 0.16402133 | DL7: 0.06 | DM7: 0.064843333 | DN7: 0.034 | DO7: 0.20696733 | DP7: 0.11975733 | DQ7: 0.214178 | DR7: 0.33340967 | DS7: 0.155168 | DT7: 0.14984133 | DU7: 0.055 | DV7: 0.28105833 | DW7: 0.12965302 | DX7: 16.076975
A8: 7 | B8: 3 | C8: 0.043 | D8: 0.13518 | E8: 0.051 | F8: 0.059 | G8: 0.047 | H8: 0.051 | I8: 0.11893167 | J8: 0.12495733 | K8: 0.091917 | L8: 0.057350333 | M8: 0.16558 | N8: 0.047 | O8: 0.37269867 | P8: 0.116412 | Q8: 0.079906 | R8: 0.046 | S8: 0.30843467 | T8: 0.278864 | U8: 0.20401333 | V8: 0.148978 | W8: 0.048 | X8: 0.057 | Y8: 0.031 | Z8: 0.076717 | AA8: 0.104039 | AB8: 0.31450933 | AC8: 0.14139467 | AD8: 0.248913 | AE8: 0.055 | AF8: 0.05 | AG8: 0.20999333 | AH8: 0.046 | AI8: 0.30109733 | AJ8: 0.06656 | AK8: 0.062867333 | AL8: 0.181236 | AM8: 0.12713333 | AN8: 0.159635 | AO8: 0.20930133 | AP8: 0.046 | AQ8: 0.053 | AR8: 0.055 | AS8: 0.099784 | AT8: 0.11980833 | AU8: 0.05 | AV8: 0.099824 | AW8: 0.06 | AX8: 0.070384 | AY8: 0.14577333 | AZ8: 0.052 | BA8: 0.039 | BB8: 0.15636 | BC8: 0.076004 | BD8: 0.041 | BE8: 0.084012 | BF8: 0.10844367 | BG8: 0.18178233 | BH8: 0.12179667 | BI8: 0.179765 | BJ8: 0.043 | BK8: 0.10453667 | BL8: 0.18964367 | BM8: 0.211694 | BN8: 0.111568 | BO8: 0.15277833 | BP8: 0.05 | BQ8: 0.11439333 | BR8: 0.053 | BS8: 0.23360933 | BT8: 0.18610867 | BU8: 0.056 | BV8: 0.048 | BW8: 0.05 | BX8: 0.096613333 | BY8: 0.055 | BZ8: 0.19614 | CA8: 0.057 | CB8: 0.10494467 | CC8: 0.052 | CD8: 0.053 | CE8: 0.046 | CF8: 0.039 | CG8: 0.041 | CH8: 0.047 | CI8: 0.051 | CJ8: 0.0852 | CK8: 0.123334 | CL8: 0.05 | CM8: 0.05 | CN8: 0.19074667 | CO8: 0.10619333 | CP8: 0.072706667 | CQ8: 0.058 | CR8: 0.053741333 | CS8: 0.057 | CT8: 0.141995 | CU8: 0.163242 | CV8: 0.08759 | CW8: 0.04 | CX8: 0.24420067 | CY8: 0.068248 | CZ8: 0.072395 | DA8: 0.057 | DB8: 0.16100067 | DC8: 0.11910133 | DD8: 0.046054667 | DE8: 0.070264667 | DF8: 0.1978 | DG8: 0.058 | DH8: 0.121232 | DI8: 0.062142 | DJ8: 0.12278933 | DK8: 0.054 | DL8: 0.06 | DM8: 0.11931733 | DN8: 0.034 | DO8: 0.13825867 | DP8: 0.24482733 | DQ8: 0.047 | DR8: 0.52019367 | DS8: 0.057037333 | DT8: 0.052 | DU8: 0.17364233 | DV8: 0.049 | DW8: 0.1092713 | DX8: 13.549641
A9: 8 | B9: 3.5 | C9: 0.118526 | D9: 0.152416 | E9: 0.051 | F9: 0.059 | G9: 1.3336807 | H9: 0.31085133 | I9: 0.25259867 | J9: 0.11061 | K9: 0.19928067 | L9: 0.17165633 | M9: 0.048 | N9: 0.0965964 | O9: 0.503246 | P9: 0.15158333 | Q9: 0.18848667 | R9: 0.231711 | S9: 1.1998113 | T9: 0.046 | U9: 0.134554 | V9: 0.059 | W9: 0.30885767 | X9: 0.163608 | Y9: 0.08164 | Z9: 0.192541 | AA9: 0.115381 | AB9: 0.094586 | AC9: 0.11022333 | AD9: 0.095661333 | AE9: 0.055 | AF9: 0.220962 | AG9: 0.075899333 | AH9: 0.046 | AI9: 0.089444333 | AJ9: 0.051 | AK9: 0.19667333 | AL9: 0.045 | AM9: 0.22499333 | AN9: 0.047 | AO9: 0.247892 | AP9: 0.046 | AQ9: 0.12881 | AR9: 0.055 | AS9: 0.058 | AT9: 0.14605167 | AU9: 0.05 | AV9: 0.166732 | AW9: 0.06 | AX9: 0.081768 | AY9: 0.051952333 | AZ9: 0.052 | BA9: 0.039 | BB9: 0.097843333 | BC9: 0.082576 | BD9: 0.22117833 | BE9: 0.136483 | BF9: 0.122035 | BG9: 0.078384 | BH9: 0.078718667 | BI9: 0.062 | BJ9: 0.117562 | BK9: 0.069434667 | BL9: 0.130249 | BM9: 0.080038333 | BN9: 0.154175 | BO9: 0.054 | BP9: 0.05 | BQ9: 0.037 | BR9: 0.306336 | BS9: 0.30163867 | BT9: 0.176294 | BU9: 0.056 | BV9: 0.048 | BW9: 0.35612467 | BX9: 0.080026667 | BY9: 0.133749 | BZ9: 0.043 | CA9: 0.057 | CB9: 0.17954667 | CC9: 0.052 | CD9: 0.20977533 | CE9: 0.046 | CF9: 0.178223 | CG9: 0.041 | CH9: 0.19029333 | CI9: 0.24316767 | CJ9: 0.14553333 | CK9: 0.049 | CL9: 0.05 | CM9: 0.19495033 | CN9: 0.041 | CO9: 0.10728533 | CP9: 0.049 | CQ9: 0.18062667 | CR9: 0.18168433 | CS9: 0.057 | CT9: 0.047 | CU9: 0.17888 | CV9: 0.107744 | CW9: 0.103648 | CX9: 0.20847333 | CY9: 0.07681 | CZ9: 0.105027 | DA9: 0.057 | DB9: 0.039 | DC9: 0.14834067 | DD9: 0.042 | DE9: 0.26771267 | DF9: 0.15866333 | DG9: 0.201815 | DH9: 0.057914667 | DI9: 0.32745733 | DJ9: 0.27067267 | DK9: 0.054 | DL9: 0.06 | DM9: 0.112722 | DN9: 0.18209233 | DO9: 0.176246 | DP9: 0.10761533 | DQ9: 0.10252433 | DR9: 0.075624 | DS9: 0.029 | DT9: 0.052 | DU9: 0.061244333 | DV9: 0.29163967 | DW9: 0.14391197 | DX9: 17.845084
A10: 9 | B10: 4 | C10: 0.104794 | D10: 0.049 | E10: 0.051 | F10: 0.059 | G10: 0.047 | H10: 0.051 | I10: 0.053 | J10: 0.105536 | K10: 0.18321333 | L10: 0.051 | M10: 0.048 | N10: 0.17710667 | O10: 0.16964 | P10: 0.188804 | Q10: 0.14409267 | R10: 0.106055 | S10: 0.103304 | T10: 0.14448067 | U10: 0.170238 | V10: 0.200394 | W10: 0.088815 | X10: 0.068845333 | Y10: 0.092893333 | Z10: 0.055 | AA10: 0.053 | AB10: 0.20735433 | AC10: 0.18601133 | AD10: 0.23021 | AE10: 0.055 | AF10: 0.33932033 | AG10: 0.061 | AH10: 0.046 | AI10: 0.072864 | AJ10: 0.22216 | AK10: 0.048 | AL10: 0.21151067 | AM10: 0.064414 | AN10: 0.212198 | AO10: 0.183274 | AP10: 0.046 | AQ10: 0.053 | AR10: 0.055 | AS10: 0.141568 | AT10: 0.10835333 | AU10: 0.05 | AV10: 0.18546333 | AW10: 0.06 | AX10: 0.150072 | AY10: 0.212963 | AZ10: 0.052 | BA10: 0.039 | BB10: 0.095614667 | BC10: 0.108864 | BD10: 0.18813 | BE10: 0.099337 | BF10: 0.149248 | BG10: 0.117672 | BH10: 0.179234 | BI10: 0.21902 | BJ10: 0.043 | BK10: 0.20922667 | BL10: 0.085223 | BM10: 0.11849967 | BN10: 0.10128167 | BO10: 0.14694267 | BP10: 0.05 | BQ10: 0.20726533 | BR10: 0.053 | BS10: 0.059 | BT10: 0.093692 | BU10: 0.056 | BV10: 0.048 | BW10: 0.05 | BX10: 0.051 | BY10: 0.133749 | BZ10: 0.211454 | CA10: 0.057 | CB10: 0.067145 | CC10: 0.160514 | CD10: 0.149322 | CE10: 0.046 | CF10: 0.152701 | CG10: 0.13477667 | CH10: 0.047 | CI10: 0.10152667 | CJ10: 0.049 | CK10: 0.26309267 | CL10: 0.05 | CM10: 0.183207 | CN10: 0.17032667 | CO10: 0.18912133 | CP10: 0.049 | CQ10: 0.094066667 | CR10: 0.107355 | CS10: 0.065811333 | CT10: 0.084998 | CU10: 0.168124 | CV10: 0.134616 | CW10: 0.151384 | CX10: 0.13189933 | CY10: 0.034 | CZ10: 0.052 | DA10: 0.057 | DB10: 0.039 | DC10: 0.143548 | DD10: 0.042 | DE10: 0.056 | DF10: 0.15573867 | DG10: 0.064848333 | DH10: 0.11331733 | DI10: 0.165199 | DJ10: 0.18630667 | DK10: 0.10901067 | DL10: 0.06 | DM10: 0.042 | DN10: 0.057383 | DO10: 0.147496 | DP10: 0.23827667 | DQ10: 0.19488567 | DR10: 0.048 | DS10: 0.176196 | DT10: 0.12188667 | DU10: 0.055 | DV10: 0.083538333 | DW10: 0.11276629 | DX10: 13.98302
A11: 10 | B11: 4.5 | C11: 0.043 | D11: 0.238596 | E11: 0.051 | F11: 0.059 | G11: 0.047 | H11: 0.15469333 | I11: 0.20058567 | J11: 0.20456733 | K11: 0.054 | L11: 0.17800667 | M11: 0.048 | N11: 0.047 | O11: 0.103352 | P11: 0.10819 | Q11: 0.048 | R11: 0.118279 | S11: 0.054 | T11: 0.21287 | U11: 0.121506 | V11: 0.059 | W11: 0.113304 | X11: 0.163608 | Y11: 0.031 | Z11: 0.055 | AA11: 0.16642 | AB11: 0.21526967 | AC11: 0.12743 | AD11: 0.12059867 | AE11: 0.055 | AF11: 0.182107 | AG11: 0.22489267 | AH11: 0.046 | AI11: 0.23414633 | AJ11: 0.051 | AK11: 0.19667333 | AL11: 0.045 | AM11: 0.15798667 | AN11: 0.047 | AO11: 0.19826767 | AP11: 0.046 | AQ11: 0.053 | AR11: 0.055 | AS11: 0.058 | AT11: 0.16514333 | AU11: 0.05 | AV11: 0.066206 | AW11: 0.06 | AX11: 0.059 | AY11: 0.048 | AZ11: 0.052 | BA11: 0.039 | BB11: 0.14862 | BC11: 0.98764333 | BD11: 0.061715 | BE11: 0.201946 | BF11: 0.13387333 | BG11: 0.16868667 | BH11: 0.05 | BI11: 0.077702 | BJ11: 0.043 | BK11: 0.05996 | BL11: 0.23466967 | BM11: 0.056 | BN11: 0.114505 | BO11: 0.14737067 | BP11: 0.05 | BQ11: 0.037 | BR11: 0.13973 | BS11: 0.28660267 | BT11: 0.26871067 | BU11: 0.16771533 | BV11: 0.048 | BW11: 0.27440133 | BX11: 0.07588 | BY11: 0.055 | BZ11: 0.043 | CA11: 0.057 | CB11: 0.281733 | CC11: 0.159072 | CD11: 0.13723133 | CE11: 0.046 | CF11: 0.064524333 | CG11: 0.041 | CH11: 0.073053333 | CI11: 0.051 | CJ11: 0.049 | CK11: 0.049 | CL11: 0.05 | CM11: 0.100274 | CN11: 0.06142 | CO11: 0.10582933 | CP11: 0.10996 | CQ11: 0.058 | CR11: 0.12381867 | CS11: 0.12749067 | CT11: 0.135662 | CU11: 0.163242 | CV11: 0.054 | CW11: 0.04 | CX11: 0.306724 | CY11: 0.081091 | CZ11: 0.052 | DA11: 0.057 | DB11: 0.16100067 | DC11: 0.20183867 | DD11: 0.042 | DE11: 0.056 | DF11: 0.15896667 | DG11: 0.14702833 | DH11: 0.065829333 | DI11: 0.24469867 | DJ11: 0.273114 | DK11: 0.10901067 | DL11: 0.06 | DM11: 0.21069367 | DN11: 0.080766 | DO11: 0.059484 | DP11: 0.114166 | DQ11: 0.047 | DR11: 0.048 | DS11: 0.036009333 | DT11: 0.135864 | DU11: 0.055 | DV11: 0.229473 | DW11: 0.11641532 | DX11: 14.4355
A12: 11 | B12: 5 | C12: 0.043 | D12: 0.049 | E12: 0.051 | F12: 0.059 | G12: 0.047 | H12: 0.058098333 | I12: 0.174823 | J12: 0.031 | K12: 0.328494 | L12: 0.051 | M12: 0.130306 | N12: 0.21537333 | O12: 0.22060067 | P12: 0.057638 | Q12: 0.27052633 | R12: 0.150403 | S12: 0.11563 | T12: 0.069292 | U12: 0.10650467 | V12: 0.18754 | W12: 0.28436867 | X12: 0.068845333 | Y12: 0.14353333 | Z12: 0.055 | AA12: 0.053 | AB12: 0.054 | AC12: 0.05 | AD12: 0.14916367 | AE12: 0.055 | AF12: 0.088855 | AG12: 0.061 | AH12: 0.046 | AI12: 0.19125667 | AJ12: 0.17548 | AK12: 0.062867333 | AL12: 0.045 | AM12: 0.208554 | AN12: 0.092054 | AO12: 0.16078733 | AP12: 0.29405033 | AQ12: 0.12881 | AR12: 0.055 | AS12: 0.058 | AT12: 0.04 | AU12: 0.065574 | AV12: 0.122236 | AW12: 0.06 | AX12: 0.16592267 | AY12: 0.14577333 | AZ12: 0.052 | BA12: 0.039 | BB12: 0.137718 | BC12: 0.24377333 | BD12: 0.12799167 | BE12: 0.11791 | BF12: 0.057 | BG12: 0.143864 | BH12: 0.05 | BI12: 0.171914 | BJ12: 0.117562 | BK12: 0.093898333 | BL12: 0.051 | BM12: 0.33283067 | BN12: 0.19751667 | BO12: 0.061733333 | BP12: 0.05 | BQ12: 0.044739333 | BR12: 0.053 | BS12: 0.24864467 | BT12: 0.053 | BU12: 0.056 | BV12: 0.048 | BW12: 0.13172333 | BX12: 0.10076 | BY12: 0.176703 | BZ12: 0.134884 | CA12: 0.057 | CB12: 0.043 | CC12: 0.096788333 | CD12: 0.221866 | CE12: 0.046 | CF12: 0.170599 | CG12: 0.041 | CH12: 0.16424 | CI12: 0.293694 | CJ12: 0.14553333 | CK12: 0.17415533 | CL12: 0.05 | CM12: 0.27788333 | CN12: 0.041 | CO12: 0.20403467 | CP12: 0.049 | CQ12: 0.21669333 | CR12: 0.098336 | CS12: 0.057 | CT12: 0.047 | CU12: 0.220716 | CV12: 0.054 | CW12: 0.04 | CX12: 0.058 | CY12: 0.063967 | CZ12: 0.052 | DA12: 0.057 | DB12: 0.039 | DC12: 0.23278967 | DD12: 0.11092933 | DE12: 0.056 | DF12: 0.14847567 | DG12: 0.119635 | DH12: 0.10540267 | DI12: 0.15486867 | DJ12: 0.120348 | DK12: 0.054 | DL12: 0.06 | DM12: 0.112722 | DN12: 0.15870933 | DO12: 0.160366 | DP12: 0.075236667 | DQ12: 0.047 | DR12: 0.199932 | DS12: 0.085074667 | DT12: 0.052 | DU12: 0.11744333 | DV12: 0.14570733 | DW12: 0.11359415 | DX12: 14.085674
