Workbook

Sheet 1_Summary
B2: TR9 rolling flexibility operating region (FOR)
B3: How the region is built, column by column — 48 half-hourly rolling steps × 12 boundary directions, measured at the feeder PCC with TR9's batteries as the flexible resource.
B6: WHAT THIS WORKBOOK IS
B7: Purpose | C7: Each half-hour of the day has its own FOR: the set of active/reactive power (P,Q) that can be presented at the feeder's point of common coupling for the next time slot, when TR9's batteries are the flexible resource. IMPORTANT: the PCC is the feeder's slack/HV bus, so every (P,Q) here is a whole-feeder quantity — all nine transformers, all 172+ loads and every PV panel — not TR9's own connection point. The eight other transformers are lumped as passive loads in this run, their batteries idle. The optimizer finds the region by pushing the operating point as far as it will go in 12 compass directions (0°,30°,…,330°). Joining those 12 points gives the boundary. This file shows the numbers and the formulas that turn them into the two pictures you have seen (absolute and deviation). Two flexibilities live here and must not be confused: the PV (uncontrollable, already in the baseline) and the battery (controllable — the deviation the operator can move).
B8: Sign convention | C8: P > 0 = IMPORT from the grid. P < 0 = EXPORT (surplus sent to the grid). Q > 0 = the inverters absorb reactive power. Q < 0 = they inject it. Units: MW / MVAr (per-unit × 1 MVA base).
B10: AT A GLANCE (LIVE COUNTS FROM 4_ALL_PERIODS)
B11: Rolling steps | C11: =MAX('4_All_periods'!A2:A577) -> 48
B12: Boundary points solved | C12: =COUNTA('4_All_periods'!A2:A577) -> 576
B13: Solves that are not optimal | C13: =COUNTIF('4_All_periods'!G2:G577,"<>Optimal") -> 0
B14: Points at the 1.10 pu voltage wall | C14: =COUNTIF('4_All_periods'!H2:H577,">=1.0999") -> 254
B16: CONTENTS — HOW THE TABS ARE ORGANISED
B17: 1_Summary | C17: This page: purpose, sign convention, column glossary and the recipe for building one FOR by hand.
B18: 2_Sample_00h00 | C18: Worked example for period 1 = 00:00. The P/Q numbers are typed in, so you can overwrite them and watch the charts move.
B19: 3_Sample_12h00 | C19: Worked example for period 25 = 12:00, in the midday solar window. Same layout, numbers typed in.
B20: 4_All_periods | C20: Master data. All 48 periods × 12 directions = 576 boundary points, with the baseline and the deviation of each.
B21: P02_00h30 … P48_23h30 | C21: One tab per rolling step, each with its own absolute and deviation chart. These read from 4_All_periods, so they follow the master data.
B23: COLUMN GLOSSARY
B24: now | C24: Rolling step = which half-hour we are planning from. 1 = 00:00, 2 = 00:30, … 48 = 23:30.
B25: target | C25: The service slot being offered = the next half-hour (t+1), so target = now + 1. The last step (now = 48 = 23:30) offers slot 1 = 00:00.
B26: angle_deg | C26: Direction the optimizer pushes in. 0° = as much IMPORT as possible, 90° = as much +Q, 180° = as much EXPORT, 270° = as much −Q. The 12 angles trace the boundary.
B27: P | C27: Active power at the PCC at that boundary point (MW). + import / − export.
B28: Q | C28: Reactive power at the PCC at that boundary point (MVAr).
B29: proj | C29: ‘Support’ value = how far the region reaches in the push direction. proj = P·cos(angle) + Q·sin(angle). (Column F recomputes it so you can check.)
B30: status | C30: Solver result. ‘Optimal’ = a valid boundary point. All 576 are Optimal here.
B31: VmaxTrue | C31: The TRUE highest voltage anywhere in the network at that point (per-unit). When it equals 1.10000 the over-voltage limit is what stops the region — the binding wall.
B32: VminTrue | C32: The true lowest network voltage (pu). Watches the under-voltage limit (0.94). (in the source CSV; not carried into this workbook)
B33: OVviol / UVviol | C33: Over-/under-voltage violation (pu). ≈0 means the point is genuinely AC-feasible. (in the source CSV; not carried into this workbook)
B34: LinErr | C34: Internal linearization-error check (pu). Small = the linear model tracked the exact AC solve. (in the source CSV; not carried into this workbook)
B35: B_P , B_Q | C35: The BASELINE for that half-hour = the PCC power with every battery ON THE FEEDER switched OFF. It is the whole feeder's passive imbalance: load − PV summed over all nine transformers, plus the network losses. Sanity check at period 25: B_P = −2.2582 MW, the nine transformers' load − PV sum to −2.2803 MW, and the 22 kW gap is losses. TR9 alone is only −0.1784 MW. This is the UNCONTROLLABLE part: the PV / self-consumption commitment already serving local load, neighbours' load and losses — nobody is paid for it. The batteries deviate around this point. Read from FOR_rolling_baseline.csv, one series shared by all nine per-transformer runs.
B36: dP , dQ | C36: The DEVIATION = P − B_P and Q − B_Q. This is the CONTROLLABLE flexibility a DSO/TSO can dispatch — the effect of TR9's batteries at the PCC (battery power, to within a small network-loss term). PV is NOT here; it is already inside the baseline. dP > 0 = the batteries can still charge (import more); dP < 0 = they can still discharge (export more). Use the deviation, not the absolute point, for fairness allocation and dispatch: the absolute regions of all nine transformers overlap on the shared baseline, so only the deviation separates them. Reference: measured from the batteries-OFF baseline, not from the committed self-consumption schedule.
B38: STEP BY STEP: HOW TO BUILD ONE FOR BY HAND
B39: Step 1 | C39: Pick a half-hour (a ‘now’ value, e.g. 25 = 12:00).
B40: Step 2 | C40: Read its 12 boundary vertices (angle, P, Q) — columns A,B,C on the sample sheets. Each came from ONE optimization solve that maximised the push in that direction.
B41: Step 3 | C41: Read the baseline B = (B_P, B_Q) for that half-hour (the batteries-off PCC point).
B42: Step 4 | C42: Compute the deviation for every vertex: dP = P − B_P , dQ = Q − B_Q. (Column D,E do this with a formula.)
B43: Step 5 | C43: Plot P vs Q → the ABSOLUTE FOR (where the region really sits).
B44: Step 6 | C44: Plot dP vs dQ → the DEVIATION FOR (centred on the self-consumption plan). Right of the vertical axis = battery can still charge; left = still discharge.
B45: Step 7 | C45: Read the flexibility off it: import-reach = max(dP over the 12 points, but ≥0); export-reach = −min(dP), ≥0. If both > 0 the region straddles zero (can do both).
B47: COLOUR KEY
B48: INPUT | C48: Numbers straight from the optimizer. Safe to overwrite on the two sample tabs if you want to test a what-if.
...

Sheet 2_Sample_00h00
A1: TR9 rolling FOR — period 1 = 00:00 (worked example)
A3: BASELINE B ≈ load − PV, batteries OFF — the all-idle PCC point (also carries losses). This is the UNCONTROLLABLE PV commitment; the battery deviates around it:
A4: B_P (MW) = | B4: 0.5454 | C4: B_Q (MVAr) = | D4: 0.112
A6: angle_deg | B6: P_abs (MW) | C6: Q_abs (MVAr) | D6: dP = P − B_P | E6: dQ = Q − B_Q | F6: proj check | G6: battery side
A7: 0 | B7: 0.775 | C7: 0.0853 | D7: =B7-$B$4 -> 0.2296 | E7: =C7-$D$4 -> -0.0267 | F7: =B7*COS(RADIANS(A7))+C7*SIN(RADIANS(A7)) -> 0.775 | G7: =IF(D7>0,"charge/import","discharge/export") -> charge/import
A8: 30 | B8: 0.7285 | C8: 0.2533 | D8: =B8-$B$4 -> 0.1831 | E8: =C8-$D$4 -> 0.1413 | F8: =B8*COS(RADIANS(A8))+C8*SIN(RADIANS(A8)) -> 0.75754951 | G8: =IF(D8>0,"charge/import","discharge/export") -> charge/import
A9: 60 | B9: 0.6073 | C9: 0.3755 | D9: =B9-$B$4 -> 0.0619 | E9: =C9-$D$4 -> 0.2635 | F9: =B9*COS(RADIANS(A9))+C9*SIN(RADIANS(A9)) -> 0.62884254 | G9: =IF(D9>0,"charge/import","discharge/export") -> charge/import
A10: 90 | B10: 0.4554 | C10: 0.4146 | D10: =B10-$B$4 -> -0.09 | E10: =C10-$D$4 -> 0.3026 | F10: =B10*COS(RADIANS(A10))+C10*SIN(RADIANS(A10)) -> 0.4146 | G10: =IF(D10>0,"charge/import","discharge/export") -> discharge/export
A11: 120 | B11: 0.2923 | C11: 0.3713 | D11: =B11-$B$4 -> -0.2531 | E11: =C11-$D$4 -> 0.2593 | F11: =B11*COS(RADIANS(A11))+C11*SIN(RADIANS(A11)) -> 0.17540523 | G11: =IF(D11>0,"charge/import","discharge/export") -> discharge/export
A12: 150 | B12: 0.2578 | C12: 0.3477 | D12: =B12-$B$4 -> -0.2876 | E12: =C12-$D$4 -> 0.2357 | F12: =B12*COS(RADIANS(A12))+C12*SIN(RADIANS(A12)) -> -0.049411349 | G12: =IF(D12>0,"charge/import","discharge/export") -> discharge/export
A13: 180 | B13: 0.2551 | C13: -0.1119 | D13: =B13-$B$4 -> -0.2903 | E13: =C13-$D$4 -> -0.2239 | F13: =B13*COS(RADIANS(A13))+C13*SIN(RADIANS(A13)) -> -0.2551 | G13: =IF(D13>0,"charge/import","discharge/export") -> discharge/export
A14: 210 | B14: 0.2667 | C14: -0.1651 | D14: =B14-$B$4 -> -0.2787 | E14: =C14-$D$4 -> -0.2771 | F14: =B14*COS(RADIANS(A14))+C14*SIN(RADIANS(A14)) -> -0.14841898 | G14: =IF(D14>0,"charge/import","discharge/export") -> discharge/export
A15: 240 | B15: 0.3065 | C15: -0.194 | D15: =B15-$B$4 -> -0.2389 | E15: =C15-$D$4 -> -0.306 | F15: =B15*COS(RADIANS(A15))+C15*SIN(RADIANS(A15)) -> 0.014758928 | G15: =IF(D15>0,"charge/import","discharge/export") -> discharge/export
A16: 270 | B16: 0.4468 | C16: -0.2297 | D16: =B16-$B$4 -> -0.0986 | E16: =C16-$D$4 -> -0.3417 | F16: =B16*COS(RADIANS(A16))+C16*SIN(RADIANS(A16)) -> 0.2297 | G16: =IF(D16>0,"charge/import","discharge/export") -> discharge/export
A17: 300 | B17: 0.6119 | C17: -0.1854 | D17: =B17-$B$4 -> 0.0665 | E17: =C17-$D$4 -> -0.2974 | F17: =B17*COS(RADIANS(A17))+C17*SIN(RADIANS(A17)) -> 0.46651111 | G17: =IF(D17>0,"charge/import","discharge/export") -> charge/import
A18: 330 | B18: 0.7327 | C18: -0.0647 | D18: =B18-$B$4 -> 0.1873 | E18: =C18-$D$4 -> -0.1767 | F18: =B18*COS(RADIANS(A18))+C18*SIN(RADIANS(A18)) -> 0.66688681 | G18: =IF(D18>0,"charge/import","discharge/export") -> charge/import
A19: (close) | B19: =B7 -> 0.775 | C19: =C7 -> 0.0853 | D19: =D7 -> 0.2296 | E19: =E7 -> -0.0267
A21: Interpretation (all computed live):
A22: P width (MW) | C22: =MAX(B7:B18)-MIN(B7:B18) -> 0.5199
A23: import-reach (charge) | C23: =MAX(0,MAX(D7:D18)) -> 0.2296
A24: export-reach (dischg) | C24: =MAX(0,-MIN(D7:D18)) -> 0.2903
A25: verdict | C25: =IF(AND(C23>0.02,C24>0.02),"two-sided → can charge (import) or discharge (export)",IF(C23<=0.02,"one-sided → discharge/export only (no import headroom)","one-sided → charge/import only (no export headroom)")) -> two-sided → can charge (import) or discharge (export)
A26: what stops it | C26: =IF(AND(C23>0.02,C24>0.02),"both directions have headroom",IF(C23<=0.02,"blocked at 0°: Vmax there = "&TEXT('4_All_periods'!H2,"0.00000")&" pu"&IF('4_All_periods'!H2>=1.0999," → over-voltage limit is active"," → clear of the limit, so the battery bounds it"),"blocked at 180°: Vmax there = "&TEXT('4_All_periods'!H8,"0.00000")&" pu"&IF('4_All_periods'!H8>=1.0999," → over-voltage limit is active"," → clear of the limit, so the battery bounds it"))) -> both directions have headroom
A27: Tip: change any light-blue P/Q or the pink baseline and the amber cells + both charts update automatically.

Sheet 3_Sample_12h00
A1: TR9 rolling FOR — period 25 = 12:00 (worked example)
A3: BASELINE B ≈ load − PV, batteries OFF — the all-idle PCC point (also carries losses). This is the UNCONTROLLABLE PV commitment; the battery deviates around it:
A4: B_P (MW) = | B4: -2.2582 | C4: B_Q (MVAr) = | D4: 0.2073
A6: angle_deg | B6: P_abs (MW) | C6: Q_abs (MVAr) | D6: dP = P − B_P | E6: dQ = Q − B_Q | F6: proj check | G6: battery side
A7: 0 | B7: -2.259 | C7: 0.2471 | D7: =B7-$B$4 -> -0.0008 | E7: =C7-$D$4 -> 0.0398 | F7: =B7*COS(RADIANS(A7))+C7*SIN(RADIANS(A7)) -> -2.259 | G7: =IF(D7>0,"charge/import","discharge/export") -> discharge/export
A8: 30 | B8: -2.274 | C8: 0.515 | D8: =B8-$B$4 -> -0.0158 | E8: =C8-$D$4 -> 0.3077 | F8: =B8*COS(RADIANS(A8))+C8*SIN(RADIANS(A8)) -> -1.7118418 | G8: =IF(D8>0,"charge/import","discharge/export") -> discharge/export
A9: 60 | B9: -2.2778 | C9: 0.5183 | D9: =B9-$B$4 -> -0.0196 | E9: =C9-$D$4 -> 0.311 | F9: =B9*COS(RADIANS(A9))+C9*SIN(RADIANS(A9)) -> -0.69003903 | G9: =IF(D9>0,"charge/import","discharge/export") -> discharge/export
A10: 90 | B10: -2.3207 | C10: 0.5227 | D10: =B10-$B$4 -> -0.0625 | E10: =C10-$D$4 -> 0.3154 | F10: =B10*COS(RADIANS(A10))+C10*SIN(RADIANS(A10)) -> 0.5227 | G10: =IF(D10>0,"charge/import","discharge/export") -> discharge/export
A11: 120 | B11: -2.4081 | C11: 0.5033 | D11: =B11-$B$4 -> -0.1499 | E11: =C11-$D$4 -> 0.296 | F11: =B11*COS(RADIANS(A11))+C11*SIN(RADIANS(A11)) -> 1.6399206 | G11: =IF(D11>0,"charge/import","discharge/export") -> discharge/export
A12: 150 | B12: -2.5088 | C12: 0.396 | D12: =B12-$B$4 -> -0.2506 | E12: =C12-$D$4 -> 0.1887 | F12: =B12*COS(RADIANS(A12))+C12*SIN(RADIANS(A12)) -> 2.3706845 | G12: =IF(D12>0,"charge/import","discharge/export") -> discharge/export
A13: 180 | B13: -2.5456 | C13: 0.2774 | D13: =B13-$B$4 -> -0.2874 | E13: =C13-$D$4 -> 0.0701 | F13: =B13*COS(RADIANS(A13))+C13*SIN(RADIANS(A13)) -> 2.5456 | G13: =IF(D13>0,"charge/import","discharge/export") -> discharge/export
A14: 210 | B14: -2.5269 | C14: 0.2235 | D14: =B14-$B$4 -> -0.2687 | E14: =C14-$D$4 -> 0.0162 | F14: =B14*COS(RADIANS(A14))+C14*SIN(RADIANS(A14)) -> 2.0766096 | G14: =IF(D14>0,"charge/import","discharge/export") -> discharge/export
A15: 240 | B15: -2.3268 | C15: 0.0122 | D15: =B15-$B$4 -> -0.0686 | E15: =C15-$D$4 -> -0.1951 | F15: =B15*COS(RADIANS(A15))+C15*SIN(RADIANS(A15)) -> 1.1528345 | G15: =IF(D15>0,"charge/import","discharge/export") -> discharge/export
A16: 270 | B16: -2.2763 | C16: -0.0009 | D16: =B16-$B$4 -> -0.0181 | E16: =C16-$D$4 -> -0.2082 | F16: =B16*COS(RADIANS(A16))+C16*SIN(RADIANS(A16)) -> 0.0009 | G16: =IF(D16>0,"charge/import","discharge/export") -> discharge/export
A17: 300 | B17: -2.2673 | C17: -0.0003 | D17: =B17-$B$4 -> -0.0091 | E17: =C17-$D$4 -> -0.2076 | F17: =B17*COS(RADIANS(A17))+C17*SIN(RADIANS(A17)) -> -1.1333902 | G17: =IF(D17>0,"charge/import","discharge/export") -> discharge/export
A18: 330 | B18: -2.2673 | C18: -0.0003 | D18: =B18-$B$4 -> -0.0091 | E18: =C18-$D$4 -> -0.2076 | F18: =B18*COS(RADIANS(A18))+C18*SIN(RADIANS(A18)) -> -1.9633894 | G18: =IF(D18>0,"charge/import","discharge/export") -> discharge/export
A19: (close) | B19: =B7 -> -2.259 | C19: =C7 -> 0.2471 | D19: =D7 -> -0.0008 | E19: =E7 -> 0.0398
A21: Interpretation (all computed live):
A22: P width (MW) | C22: =MAX(B7:B18)-MIN(B7:B18) -> 0.2866
A23: import-reach (charge) | C23: =MAX(0,MAX(D7:D18)) -> 0
A24: export-reach (dischg) | C24: =MAX(0,-MIN(D7:D18)) -> 0.2874
A25: verdict | C25: =IF(AND(C23>0.02,C24>0.02),"two-sided → can charge (import) or discharge (export)",IF(C23<=0.02,"one-sided → discharge/export only (no import headroom)","one-sided → charge/import only (no export headroom)")) -> one-sided → discharge/export only (no import headroom)
A26: what stops it | C26: =IF(AND(C23>0.02,C24>0.02),"both directions have headroom",IF(C23<=0.02,"blocked at 0°: Vmax there = "&TEXT('4_All_periods'!H290,"0.00000")&" pu"&IF('4_All_periods'!H290>=1.0999," → over-voltage limit is active"," → clear of the limit, so the battery bounds it"),"blocked at 180°: Vmax there = "&TEXT('4_All_periods'!H296,"0.00000")&" pu"&IF('4_All_periods'!H296>=1.0999," → over-voltage limit is active"," → clear of the limit, so the battery bounds it"))) -> blocked at 0°: Vmax there = 1.10000 pu → over-voltage limit is active
A27: Tip: change any light-blue P/Q or the pink baseline and the amber cells + both charts update automatically.

Sheet 4_All_periods
A1: now | B1: hour | C1: angle_deg | D1: P (MW) | E1: Q (MVAr) | F1: proj | G1: status | H1: VmaxTrue (pu) | I1: B_P (MW) | J1: B_Q (MVAr) | K1: dP = P−B_P | L1: dQ = Q−B_Q
A2: 1 | B2: 00:00 | C2: 0 | D2: 0.775 | E2: 0.0853 | F2: 0.775 | G2: Optimal | H2: 1.02746 | I2: 0.5454 | J2: 0.112 | K2: =D2-I2 -> 0.2296 | L2: =E2-J2 -> -0.0267
A3: 1 | B3: 00:00 | C3: 30 | D3: 0.7285 | E3: 0.2533 | F3: 0.7575 | G3: Optimal | H3: 1.00921 | I3: 0.5454 | J3: 0.112 | K3: =D3-I3 -> 0.1831 | L3: =E3-J3 -> 0.1413
A4: 1 | B4: 00:00 | C4: 60 | D4: 0.6073 | E4: 0.3755 | F4: 0.6288 | G4: Optimal | H4: 1.00492 | I4: 0.5454 | J4: 0.112 | K4: =D4-I4 -> 0.0619 | L4: =E4-J4 -> 0.2635
A5: 1 | B5: 00:00 | C5: 90 | D5: 0.4554 | E5: 0.4146 | F5: 0.4146 | G5: Optimal | H5: 1.00925 | I5: 0.5454 | J5: 0.112 | K5: =D5-I5 -> -0.09 | L5: =E5-J5 -> 0.3026
A6: 1 | B6: 00:00 | C6: 120 | D6: 0.2923 | E6: 0.3713 | F6: 0.1754 | G6: Optimal | H6: 1.02738 | I6: 0.5454 | J6: 0.112 | K6: =D6-I6 -> -0.2531 | L6: =E6-J6 -> 0.2593
A7: 1 | B7: 00:00 | C7: 150 | D7: 0.2578 | E7: 0.3477 | F7: -0.0495 | G7: Optimal | H7: 1.04445 | I7: 0.5454 | J7: 0.112 | K7: =D7-I7 -> -0.2876 | L7: =E7-J7 -> 0.2357
A8: 1 | B8: 00:00 | C8: 180 | D8: 0.2551 | E8: -0.1119 | F8: -0.2551 | G8: Optimal | H8: 1.09999 | I8: 0.5454 | J8: 0.112 | K8: =D8-I8 -> -0.2903 | L8: =E8-J8 -> -0.2239
A9: 1 | B9: 00:00 | C9: 210 | D9: 0.2667 | E9: -0.1651 | F9: -0.1484 | G9: Optimal | H9: 1.1 | I9: 0.5454 | J9: 0.112 | K9: =D9-I9 -> -0.2787 | L9: =E9-J9 -> -0.2771
A10: 1 | B10: 00:00 | C10: 240 | D10: 0.3065 | E10: -0.194 | F10: 0.0147 | G10: Optimal | H10: 1.1 | I10: 0.5454 | J10: 0.112 | K10: =D10-I10 -> -0.2389 | L10: =E10-J10 -> -0.306
A11: 1 | B11: 00:00 | C11: 270 | D11: 0.4468 | E11: -0.2297 | F11: 0.2297 | G11: Optimal | H11: 1.09527 | I11: 0.5454 | J11: 0.112 | K11: =D11-I11 -> -0.0986 | L11: =E11-J11 -> -0.3417
A12: 1 | B12: 00:00 | C12: 300 | D12: 0.6119 | E12: -0.1854 | F12: 0.4665 | G12: Optimal | H12: 1.07527 | I12: 0.5454 | J12: 0.112 | K12: =D12-I12 -> 0.0665 | L12: =E12-J12 -> -0.2974
A13: 1 | B13: 00:00 | C13: 330 | D13: 0.7327 | E13: -0.0647 | F13: 0.6669 | G13: Optimal | H13: 1.04676 | I13: 0.5454 | J13: 0.112 | K13: =D13-I13 -> 0.1873 | L13: =E13-J13 -> -0.1767
... A577: 48 | B577: 23:30 | C577: 330 | D577: 0.8068 | E577: -0.0642 | F577: 0.7308 | G577: Optimal | H577: 1.04899 | I577: 0.6488 | J577: 0.1337 | K577: =D577-I577 -> 0.158 | L577: =E577-J577 -> -0.1979

Sheet P02_00h30
A1: TR9 rolling FOR — period 2 = 00:30
A3: BASELINE B ≈ load − PV, batteries OFF — the all-idle PCC point (also carries losses). This is the UNCONTROLLABLE PV commitment; the battery deviates around it:
A4: B_P (MW) = | B4: ='4_All_periods'!I14 -> 0.4511 | C4: B_Q (MVAr) = | D4: ='4_All_periods'!J14 -> 0.0924
A6: angle_deg | B6: P_abs (MW) | C6: Q_abs (MVAr) | D6: dP = P − B_P | E6: dQ = Q − B_Q | F6: proj check | G6: battery side
A7: ='4_All_periods'!C14 -> 0 | B7: ='4_All_periods'!D14 -> 0.6851 | C7: ='4_All_periods'!E14 -> 0.0676 | D7: =B7-$B$4 -> 0.234 | E7: =C7-$D$4 -> -0.0248 | F7: =B7*COS(RADIANS(A7))+C7*SIN(RADIANS(A7)) -> 0.6851 | G7: =IF(D7>0,"charge/import","discharge/export") -> charge/import
A8: ='4_All_periods'!C15 -> 30 | B8: ='4_All_periods'!D15 -> 0.6367 | C8: ='4_All_periods'!E15 -> 0.2389 | D8: =B8-$B$4 -> 0.1856 | E8: =C8-$D$4 -> 0.1465 | F8: =B8*COS(RADIANS(A8))+C8*SIN(RADIANS(A8)) -> 0.67084837 | G8: =IF(D8>0,"charge/import","discharge/export") -> charge/import
A9: ='4_All_periods'!C16 -> 60 | B9: ='4_All_periods'!D16 -> 0.522 | C9: ='4_All_periods'!E16 -> 0.355 | D9: =B9-$B$4 -> 0.0709 | E9: =C9-$D$4 -> 0.2626 | F9: =B9*COS(RADIANS(A9))+C9*SIN(RADIANS(A9)) -> 0.56843902 | G9: =IF(D9>0,"charge/import","discharge/export") -> charge/import
A10: ='4_All_periods'!C17 -> 90 | B10: ='4_All_periods'!D17 -> 0.3646 | C10: ='4_All_periods'!E17 -> 0.3963 | D10: =B10-$B$4 -> -0.0865 | E10: =C10-$D$4 -> 0.3039 | F10: =B10*COS(RADIANS(A10))+C10*SIN(RADIANS(A10)) -> 0.3963 | G10: =IF(D10>0,"charge/import","discharge/export") -> discharge/export
A11: ='4_All_periods'!C18 -> 120 | B11: ='4_All_periods'!D18 -> 0.2101 | C11: ='4_All_periods'!E18 -> 0.3565 | D11: =B11-$B$4 -> -0.241 | E11: =C11-$D$4 -> 0.2641 | F11: =B11*COS(RADIANS(A11))+C11*SIN(RADIANS(A11)) -> 0.20368806 | G11: =IF(D11>0,"charge/import","discharge/export") -> discharge/export
A12: ='4_All_periods'!C19 -> 150 | B12: ='4_All_periods'!D19 -> 0.187 | C12: ='4_All_periods'!E19 -> 0.3413 | D12: =B12-$B$4 -> -0.2641 | E12: =C12-$D$4 -> 0.2489 | F12: =B12*COS(RADIANS(A12))+C12*SIN(RADIANS(A12)) -> 0.0087032495 | G12: =IF(D12>0,"charge/import","discharge/export") -> discharge/export
A13: ='4_All_periods'!C20 -> 180 | B13: ='4_All_periods'!D20 -> 0.1845 | C13: ='4_All_periods'!E20 -> -0.1443 | D13: =B13-$B$4 -> -0.2666 | E13: =C13-$D$4 -> -0.2367 | F13: =B13*COS(RADIANS(A13))+C13*SIN(RADIANS(A13)) -> -0.1845 | G13: =IF(D13>0,"charge/import","discharge/export") -> discharge/export
A14: ='4_All_periods'!C21 -> 210 | B14: ='4_All_periods'!D21 -> 0.1963 | C14: ='4_All_periods'!E21 -> -0.1915 | D14: =B14-$B$4 -> -0.2548 | E14: =C14-$D$4 -> -0.2839 | F14: =B14*COS(RADIANS(A14))+C14*SIN(RADIANS(A14)) -> -0.074250787 | G14: =IF(D14>0,"charge/import","discharge/export") -> discharge/export
A15: ='4_All_periods'!C22 -> 240 | B15: ='4_All_periods'!D22 -> 0.2297 | C15: ='4_All_periods'!E22 -> -0.2154 | D15: =B15-$B$4 -> -0.2214 | E15: =C15-$D$4 -> -0.3078 | F15: =B15*COS(RADIANS(A15))+C15*SIN(RADIANS(A15)) -> 0.071691872 | G15: =IF(D15>0,"charge/import","discharge/export") -> discharge/export
A16: ='4_All_periods'!C23 -> 270 | B16: ='4_All_periods'!D23 -> 0.3579 | C16: ='4_All_periods'!E23 -> -0.2485 | D16: =B16-$B$4 -> -0.0932 | E16: =C16-$D$4 -> -0.3409 | F16: =B16*COS(RADIANS(A16))+C16*SIN(RADIANS(A16)) -> 0.2485 | G16: =IF(D16>0,"charge/import","discharge/export") -> discharge/export
A17: ='4_All_periods'!C24 -> 300 | B17: ='4_All_periods'!D24 -> 0.5222 | C17: ='4_All_periods'!E24 -> -0.2044 | D17: =B17-$B$4 -> 0.0711 | E17: =C17-$D$4 -> -0.2968 | F17: =B17*COS(RADIANS(A17))+C17*SIN(RADIANS(A17)) -> 0.43811559 | G17: =IF(D17>0,"charge/import","discharge/export") -> charge/import
A18: ='4_All_periods'!C25 -> 330 | B18: ='4_All_periods'!D25 -> 0.6424 | C18: ='4_All_periods'!E25 -> -0.0842 | D18: =B18-$B$4 -> 0.1913 | E18: =C18-$D$4 -> -0.1766 | F18: =B18*COS(RADIANS(A18))+C18*SIN(RADIANS(A18)) -> 0.59843472 | G18: =IF(D18>0,"charge/import","discharge/export") -> charge/import
A19: (close) | B19: =B7 -> 0.6851 | C19: =C7 -> 0.0676 | D19: =D7 -> 0.234 | E19: =E7 -> -0.0248
A21: Interpretation (all computed live):
A22: P width (MW) | C22: =MAX(B7:B18)-MIN(B7:B18) -> 0.5006
A23: import-reach (charge) | C23: =MAX(0,MAX(D7:D18)) -> 0.234
A24: export-reach (dischg) | C24: =MAX(0,-MIN(D7:D18)) -> 0.2666
A25: verdict | C25: =IF(AND(C23>0.02,C24>0.02),"two-sided → can charge (import) or discharge (export)",IF(C23<=0.02,"one-sided → discharge/export only (no import headroom)","one-sided → charge/import only (no export headroom)")) -> two-sided → can charge (import) or discharge (export)
A26: what stops it | C26: =IF(AND(C23>0.02,C24>0.02),"both directions have headroom",IF(C23<=0.02,"blocked at 0°: Vmax there = "&TEXT('4_All_periods'!H14,"0.00000")&" pu"&IF('4_All_periods'!H14>=1.0999," → over-voltage limit is active"," → clear of the limit, so the battery bounds it"),"blocked at 180°: Vmax there = "&TEXT('4_All_periods'!H20,"0.00000")&" pu"&IF('4_All_periods'!H20>=1.0999," → over-voltage limit is active"," → clear of the limit, so the battery bounds it"))) -> both directions have headroom
A27: Tip: change any light-blue P/Q or the pink baseline and the amber cells + both charts update automatically.

Sheet P03_01h00
A1: TR9 rolling FOR — period 3 = 01:00
A3: BASELINE B ≈ load − PV, batteries OFF — the all-idle PCC point (also carries losses). This is the UNCONTROLLABLE PV commitment; the battery deviates around it:
A4: B_P (MW) = | B4: ='4_All_periods'!I26 -> 0.3612 | C4: B_Q (MVAr) = | D4: ='4_All_periods'!J26 -> 0.0739
A6: angle_deg | B6: P_abs (MW) | C6: Q_abs (MVAr) | D6: dP = P − B_P | E6: dQ = Q − B_Q | F6: proj check | G6: battery side
A7: ='4_All_periods'!C26 -> 0 | B7: ='4_All_periods'!D26 -> 0.669 | C7: ='4_All_periods'!E26 -> 0.0631 | D7: =B7-$B$4 -> 0.3078 | E7: =C7-$D$4 -> -0.0108 | F7: =B7*COS(RADIANS(A7))+C7*SIN(RADIANS(A7)) -> 0.669 | G7: =IF(D7>0,"charge/import","discharge/export") -> charge/import
A8: ='4_All_periods'!C27 -> 30 | B8: ='4_All_periods'!D27 -> 0.6206 | C8: ='4_All_periods'!E27 -> 0.2354 | D8: =B8-$B$4 -> 0.2594 | E8: =C8-$D$4 -> 0.1615 | F8: =B8*COS(RADIANS(A8))+C8*SIN(RADIANS(A8)) -> 0.65515537 | G8: =IF(D8>0,"charge/import","discharge/export") -> charge/import
A9: ='4_All_periods'!C28 -> 60 | B9: ='4_All_periods'!D28 -> 0.5037 | C9: ='4_All_periods'!E28 -> 0.3528 | D9: =B9-$B$4 -> 0.1425 | E9: =C9-$D$4 -> 0.2789 | F9: =B9*COS(RADIANS(A9))+C9*SIN(RADIANS(A9)) -> 0.55738376 | G9: =IF(D9>0,"charge/import","discharge/export") -> charge/import
A10: ='4_All_periods'!C29 -> 90 | B10: ='4_All_periods'!D29 -> 0.3485 | C10: ='4_All_periods'!E29 -> 0.3931 | D10: =B10-$B$4 -> -0.0127 | E10: =C10-$D$4 -> 0.3192 | F10: =B10*COS(RADIANS(A10))+C10*SIN(RADIANS(A10)) -> 0.3931 | G10: =IF(D10>0,"charge/import","discharge/export") -> discharge/export
A11: ='4_All_periods'!C30 -> 120 | B11: ='4_All_periods'!D30 -> 0.2004 | C11: ='4_All_periods'!E30 -> 0.3553 | D11: =B11-$B$4 -> -0.1608 | E11: =C11-$D$4 -> 0.2814 | F11: =B11*COS(RADIANS(A11))+C11*SIN(RADIANS(A11)) -> 0.20749883 | G11: =IF(D11>0,"charge/import","discharge/export") -> discharge/export
A12: ='4_All_periods'!C31 -> 150 | B12: ='4_All_periods'!D31 -> 0.1855 | C12: ='4_All_periods'!E31 -> 0.3457 | D12: =B12-$B$4 -> -0.1757 | E12: =C12-$D$4 -> 0.2718 | F12: =B12*COS(RADIANS(A12))+C12*SIN(RADIANS(A12)) -> 0.012202288 | G12: =IF(D12>0,"charge/import","discharge/export") -> discharge/export
A13: ='4_All_periods'!C32 -> 180 | B13: ='4_All_periods'!D32 -> 0.1833 | C13: ='4_All_periods'!E32 -> -0.1595 | D13: =B13-$B$4 -> -0.1779 | E13: =C13-$D$4 -> -0.2334 | F13: =B13*COS(RADIANS(A13))+C13*SIN(RADIANS(A13)) -> -0.1833 | G13: =IF(D13>0,"charge/import","discharge/export") -> discharge/export
A14: ='4_All_periods'!C33 -> 210 | B14: ='4_All_periods'!D33 -> 0.1941 | C14: ='4_All_periods'!E33 -> -0.2041 | D14: =B14-$B$4 -> -0.1671 | E14: =C14-$D$4 -> -0.278 | F14: =B14*COS(RADIANS(A14))+C14*SIN(RADIANS(A14)) -> -0.066045531 | G14: =IF(D14>0,"charge/import","discharge/export") -> discharge/export
A15: ='4_All_periods'!C34 -> 240 | B15: ='4_All_periods'!D34 -> 0.2168 | C15: ='4_All_periods'!E34 -> -0.2201 | D15: =B15-$B$4 -> -0.1444 | E15: =C15-$D$4 -> -0.294 | F15: =B15*COS(RADIANS(A15))+C15*SIN(RADIANS(A15)) -> 0.082212191 | G15: =IF(D15>0,"charge/import","discharge/export") -> discharge/export
A16: ='4_All_periods'!C35 -> 270 | B16: ='4_All_periods'!D35 -> 0.3423 | C16: ='4_All_periods'!E35 -> -0.2518 | D16: =B16-$B$4 -> -0.0189 | E16: =C16-$D$4 -> -0.3257 | F16: =B16*COS(RADIANS(A16))+C16*SIN(RADIANS(A16)) -> 0.2518 | G16: =IF(D16>0,"charge/import","discharge/export") -> discharge/export
A17: ='4_All_periods'!C36 -> 300 | B17: ='4_All_periods'!D36 -> 0.5064 | C17: ='4_All_periods'!E36 -> -0.2077 | D17: =B17-$B$4 -> 0.1452 | E17: =C17-$D$4 -> -0.2816 | F17: =B17*COS(RADIANS(A17))+C17*SIN(RADIANS(A17)) -> 0.43307348 | G17: =IF(D17>0,"charge/import","discharge/export") -> charge/import
A18: ='4_All_periods'!C37 -> 330 | B18: ='4_All_periods'!D37 -> 0.6266 | C18: ='4_All_periods'!E37 -> -0.0877 | D18: =B18-$B$4 -> 0.2654 | E18: =C18-$D$4 -> -0.1616 | F18: =B18*COS(RADIANS(A18))+C18*SIN(RADIANS(A18)) -> 0.58650152 | G18: =IF(D18>0,"charge/import","discharge/export") -> charge/import
A19: (close) | B19: =B7 -> 0.669 | C19: =C7 -> 0.0631 | D19: =D7 -> 0.3078 | E19: =E7 -> -0.0108
A21: Interpretation (all computed live):
A22: P width (MW) | C22: =MAX(B7:B18)-MIN(B7:B18) -> 0.4857
A23: import-reach (charge) | C23: =MAX(0,MAX(D7:D18)) -> 0.3078
A24: export-reach (dischg) | C24: =MAX(0,-MIN(D7:D18)) -> 0.1779
A25: verdict | C25: =IF(AND(C23>0.02,C24>0.02),"two-sided → can charge (import) or discharge (export)",IF(C23<=0.02,"one-sided → discharge/export only (no import headroom)","one-sided → charge/import only (no export headroom)")) -> two-sided → can charge (import) or discharge (export)
A26: what stops it | C26: =IF(AND(C23>0.02,C24>0.02),"both directions have headroom",IF(C23<=0.02,"blocked at 0°: Vmax there = "&TEXT('4_All_periods'!H26,"0.00000")&" pu"&IF('4_All_periods'!H26>=1.0999," → over-voltage limit is active"," → clear of the limit, so the battery bounds it"),"blocked at 180°: Vmax there = "&TEXT('4_All_periods'!H32,"0.00000")&" pu"&IF('4_All_periods'!H32>=1.0999," → over-voltage limit is active"," → clear of the limit, so the battery bounds it"))) -> both directions have headroom
A27: Tip: change any light-blue P/Q or the pink baseline and the amber cells + both charts update automatically.

Sheet P04_01h30
A1: TR9 rolling FOR — period 4 = 01:30
A3: BASELINE B ≈ load − PV, batteries OFF — the all-idle PCC point (also carries losses). This is the UNCONTROLLABLE PV commitment; the battery deviates around it:
A4: B_P (MW) = | B4: ='4_All_periods'!I38 -> 0.3453 | C4: B_Q (MVAr) = | D4: ='4_All_periods'!J38 -> 0.0707
A6: angle_deg | B6: P_abs (MW) | C6: Q_abs (MVAr) | D6: dP = P − B_P | E6: dQ = Q − B_Q | F6: proj check | G6: battery side
A7: ='4_All_periods'!C38 -> 0 | B7: ='4_All_periods'!D38 -> 0.638 | C7: ='4_All_periods'!E38 -> 0.0561 | D7: =B7-$B$4 -> 0.2927 | E7: =C7-$D$4 -> -0.0146 | F7: =B7*COS(RADIANS(A7))+C7*SIN(RADIANS(A7)) -> 0.638 | G7: =IF(D7>0,"charge/import","discharge/export") -> charge/import
A8: ='4_All_periods'!C39 -> 30 | B8: ='4_All_periods'!D39 -> 0.5894 | C8: ='4_All_periods'!E39 -> 0.2293 | D8: =B8-$B$4 -> 0.2441 | E8: =C8-$D$4 -> 0.1586 | F8: =B8*COS(RADIANS(A8))+C8*SIN(RADIANS(A8)) -> 0.62508537 | G8: =IF(D8>0,"charge/import","discharge/export") -> charge/import
A9: ='4_All_periods'!C40 -> 60 | B9: ='4_All_periods'!D40 -> 0.4739 | C9: ='4_All_periods'!E40 -> 0.3459 | D9: =B9-$B$4 -> 0.1286 | E9: =C9-$D$4 -> 0.2752 | F9: =B9*COS(RADIANS(A9))+C9*SIN(RADIANS(A9)) -> 0.53650819 | G9: =IF(D9>0,"charge/import","discharge/export") -> charge/import
A10: ='4_All_periods'!C41 -> 90 | B10: ='4_All_periods'!D41 -> 0.3176 | C10: ='4_All_periods'!E41 -> 0.3868 | D10: =B10-$B$4 -> -0.0277 | E10: =C10-$D$4 -> 0.3161 | F10: =B10*COS(RADIANS(A10))+C10*SIN(RADIANS(A10)) -> 0.3868 | G10: =IF(D10>0,"charge/import","discharge/export") -> discharge/export
A11: ='4_All_periods'!C42 -> 120 | B11: ='4_All_periods'!D42 -> 0.1751 | C11: ='4_All_periods'!E42 -> 0.351 | D11: =B11-$B$4 -> -0.1702 | E11: =C11-$D$4 -> 0.2803 | F11: =B11*COS(RADIANS(A11))+C11*SIN(RADIANS(A11)) -> 0.21642492 | G11: =IF(D11>0,"charge/import","discharge/export") -> discharge/export
A12: ='4_All_periods'!C43 -> 150 | B12: ='4_All_periods'!D43 -> 0.167 | C12: ='4_All_periods'!E43 -> 0.3459 | D12: =B12-$B$4 -> -0.1783 | E12: =C12-$D$4 -> 0.2752 | F12: =B12*COS(RADIANS(A12))+C12*SIN(RADIANS(A12)) -> 0.028323758 | G12: =IF(D12>0,"charge/import","discharge/export") -> discharge/export
A13: ='4_All_periods'!C44 -> 180 | B13: ='4_All_periods'!D44 -> 0.1648 | C13: ='4_All_periods'!E44 -> -0.1805 | D13: =B13-$B$4 -> -0.1805 | E13: =C13-$D$4 -> -0.2512 | F13: =B13*COS(RADIANS(A13))+C13*SIN(RADIANS(A13)) -> -0.1648 | G13: =IF(D13>0,"charge/import","discharge/export") -> discharge/export
A14: ='4_All_periods'!C45 -> 210 | B14: ='4_All_periods'!D45 -> 0.174 | C14: ='4_All_periods'!E45 -> -0.2157 | D14: =B14-$B$4 -> -0.1713 | E14: =C14-$D$4 -> -0.2864 | F14: =B14*COS(RADIANS(A14))+C14*SIN(RADIANS(A14)) -> -0.04283842 | G14: =IF(D14>0,"charge/import","discharge/export") -> discharge/export
A15: ='4_All_periods'!C46 -> 240 | B15: ='4_All_periods'!D46 -> 0.1923 | C15: ='4_All_periods'!E46 -> -0.2285 | D15: =B15-$B$4 -> -0.153 | E15: =C15-$D$4 -> -0.2992 | F15: =B15*COS(RADIANS(A15))+C15*SIN(RADIANS(A15)) -> 0.1017368 | G15: =IF(D15>0,"charge/import","discharge/export") -> discharge/export
A16: ='4_All_periods'!C47 -> 270 | B16: ='4_All_periods'!D47 -> 0.3116 | C16: ='4_All_periods'!E47 -> -0.2582 | D16: =B16-$B$4 -> -0.0337 | E16: =C16-$D$4 -> -0.3289 | F16: =B16*COS(RADIANS(A16))+C16*SIN(RADIANS(A16)) -> 0.2582 | G16: =IF(D16>0,"charge/import","discharge/export") -> discharge/export
A17: ='4_All_periods'!C48 -> 300 | B17: ='4_All_periods'!D48 -> 0.4756 | C17: ='4_All_periods'!E48 -> -0.2142 | D17: =B17-$B$4 -> 0.1303 | E17: =C17-$D$4 -> -0.2849 | F17: =B17*COS(RADIANS(A17))+C17*SIN(RADIANS(A17)) -> 0.42330264 | G17: =IF(D17>0,"charge/import","discharge/export") -> charge/import
A18: ='4_All_periods'!C49 -> 330 | B18: ='4_All_periods'!D49 -> 0.5957 | C18: ='4_All_periods'!E49 -> -0.0942 | D18: =B18-$B$4 -> 0.2504 | E18: =C18-$D$4 -> -0.1649 | F18: =B18*COS(RADIANS(A18))+C18*SIN(RADIANS(A18)) -> 0.56299133 | G18: =IF(D18>0,"charge/import","discharge/export") -> charge/import
A19: (close) | B19: =B7 -> 0.638 | C19: =C7 -> 0.0561 | D19: =D7 -> 0.2927 | E19: =E7 -> -0.0146
A21: Interpretation (all computed live):
A22: P width (MW) | C22: =MAX(B7:B18)-MIN(B7:B18) -> 0.4732
A23: import-reach (charge) | C23: =MAX(0,MAX(D7:D18)) -> 0.2927
A24: export-reach (dischg) | C24: =MAX(0,-MIN(D7:D18)) -> 0.1805
A25: verdict | C25: =IF(AND(C23>0.02,C24>0.02),"two-sided → can charge (import) or discharge (export)",IF(C23<=0.02,"one-sided → discharge/export only (no import headroom)","one-sided → charge/import only (no export headroom)")) -> two-sided → can charge (import) or discharge (export)
A26: what stops it | C26: =IF(AND(C23>0.02,C24>0.02),"both directions have headroom",IF(C23<=0.02,"blocked at 0°: Vmax there = "&TEXT('4_All_periods'!H38,"0.00000")&" pu"&IF('4_All_periods'!H38>=1.0999," → over-voltage limit is active"," → clear of the limit, so the battery bounds it"),"blocked at 180°: Vmax there = "&TEXT('4_All_periods'!H44,"0.00000")&" pu"&IF('4_All_periods'!H44>=1.0999," → over-voltage limit is active"," → clear of the limit, so the battery bounds it"))) -> both directions have headroom
A27: Tip: change any light-blue P/Q or the pink baseline and the amber cells + both charts update automatically.

Sheet P05_02h00
A1: TR9 rolling FOR — period 5 = 02:00
A3: BASELINE B ≈ load − PV, batteries OFF — the all-idle PCC point (also carries losses). This is the UNCONTROLLABLE PV commitment; the battery deviates around it:
A4: B_P (MW) = | B4: ='4_All_periods'!I50 -> 0.3146 | C4: B_Q (MVAr) = | D4: ='4_All_periods'!J50 -> 0.0643
A6: angle_deg | B6: P_abs (MW) | C6: Q_abs (MVAr) | D6: dP = P − B_P | E6: dQ = Q − B_Q | F6: proj check | G6: battery side
A7: ='4_All_periods'!C50 -> 0 | B7: ='4_All_periods'!D50 -> 0.6293 | C7: ='4_All_periods'!E50 -> 0.0555 | D7: =B7-$B$4 -> 0.3147 | E7: =C7-$D$4 -> -0.0088 | F7: =B7*COS(RADIANS(A7))+C7*SIN(RADIANS(A7)) -> 0.6293 | G7: =IF(D7>0,"charge/import","discharge/export") -> charge/import
A8: ='4_All_periods'!C51 -> 30 | B8: ='4_All_periods'!D51 -> 0.5809 | C8: ='4_All_periods'!E51 -> 0.2273 | D8: =B8-$B$4 -> 0.2663 | E8: =C8-$D$4 -> 0.163 | F8: =B8*COS(RADIANS(A8))+C8*SIN(RADIANS(A8)) -> 0.61672416 | G8: =IF(D8>0,"charge/import","discharge/export") -> charge/import
A9: ='4_All_periods'!C52 -> 60 | B9: ='4_All_periods'!D52 -> 0.4653 | C9: ='4_All_periods'!E52 -> 0.344 | D9: =B9-$B$4 -> 0.1507 | E9: =C9-$D$4 -> 0.2797 | F9: =B9*COS(RADIANS(A9))+C9*SIN(RADIANS(A9)) -> 0.53056274 | G9: =IF(D9>0,"charge/import","discharge/export") -> charge/import
A10: ='4_All_periods'!C53 -> 90 | B10: ='4_All_periods'!D53 -> 0.3084 | C10: ='4_All_periods'!E53 -> 0.3851 | D10: =B10-$B$4 -> -0.0062 | E10: =C10-$D$4 -> 0.3208 | F10: =B10*COS(RADIANS(A10))+C10*SIN(RADIANS(A10)) -> 0.3851 | G10: =IF(D10>0,"charge/import","discharge/export") -> discharge/export
A11: ='4_All_periods'!C54 -> 120 | B11: ='4_All_periods'!D54 -> 0.1734 | C11: ='4_All_periods'!E54 -> 0.3526 | D11: =B11-$B$4 -> -0.1412 | E11: =C11-$D$4 -> 0.2883 | F11: =B11*COS(RADIANS(A11))+C11*SIN(RADIANS(A11)) -> 0.21866056 | G11: =IF(D11>0,"charge/import","discharge/export") -> discharge/export
A12: ='4_All_periods'!C55 -> 150 | B12: ='4_All_periods'!D55 -> 0.1693 | C12: ='4_All_periods'!E55 -> 0.35 | D12: =B12-$B$4 -> -0.1453 | E12: =C12-$D$4 -> 0.2857 | F12: =B12*COS(RADIANS(A12))+C12*SIN(RADIANS(A12)) -> 0.028381899 | G12: =IF(D12>0,"charge/import","discharge/export") -> discharge/export
A13: ='4_All_periods'!C56 -> 180 | B13: ='4_All_periods'!D56 -> 0.1672 | C13: ='4_All_periods'!E56 -> -0.1886 | D13: =B13-$B$4 -> -0.1474 | E13: =C13-$D$4 -> -0.2529 | F13: =B13*COS(RADIANS(A13))+C13*SIN(RADIANS(A13)) -> -0.1672 | G13: =IF(D13>0,"charge/import","discharge/export") -> discharge/export
A14: ='4_All_periods'!C57 -> 210 | B14: ='4_All_periods'!D57 -> 0.1762 | C14: ='4_All_periods'!E57 -> -0.2231 | D14: =B14-$B$4 -> -0.1384 | E14: =C14-$D$4 -> -0.2874 | F14: =B14*COS(RADIANS(A14))+C14*SIN(RADIANS(A14)) -> -0.041043676 | G14: =IF(D14>0,"charge/import","discharge/export") -> discharge/export
A15: ='4_All_periods'!C58 -> 240 | B15: ='4_All_periods'!D58 -> 0.1915 | C15: ='4_All_periods'!E58 -> -0.2337 | D15: =B15-$B$4 -> -0.1231 | E15: =C15-$D$4 -> -0.298 | F15: =B15*COS(RADIANS(A15))+C15*SIN(RADIANS(A15)) -> 0.10664014 | G15: =IF(D15>0,"charge/import","discharge/export") -> discharge/export
A16: ='4_All_periods'!C59 -> 270 | B16: ='4_All_periods'!D59 -> 0.3028 | C16: ='4_All_periods'!E59 -> -0.2601 | D16: =B16-$B$4 -> -0.0118 | E16: =C16-$D$4 -> -0.3244 | F16: =B16*COS(RADIANS(A16))+C16*SIN(RADIANS(A16)) -> 0.2601 | G16: =IF(D16>0,"charge/import","discharge/export") -> discharge/export
A17: ='4_All_periods'!C60 -> 300 | B17: ='4_All_periods'!D60 -> 0.4667 | C17: ='4_All_periods'!E60 -> -0.2161 | D17: =B17-$B$4 -> 0.1521 | E17: =C17-$D$4 -> -0.2804 | F17: =B17*COS(RADIANS(A17))+C17*SIN(RADIANS(A17)) -> 0.42049809 | G17: =IF(D17>0,"charge/import","discharge/export") -> charge/import
A18: ='4_All_periods'!C61 -> 330 | B18: ='4_All_periods'!D61 -> 0.5867 | C18: ='4_All_periods'!E61 -> -0.0963 | D18: =B18-$B$4 -> 0.2721 | E18: =C18-$D$4 -> -0.1606 | F18: =B18*COS(RADIANS(A18))+C18*SIN(RADIANS(A18)) -> 0.5562471 | G18: =IF(D18>0,"charge/import","discharge/export") -> charge/import
A19: (close) | B19: =B7 -> 0.6293 | C19: =C7 -> 0.0555 | D19: =D7 -> 0.3147 | E19: =E7 -> -0.0088
A21: Interpretation (all computed live):
A22: P width (MW) | C22: =MAX(B7:B18)-MIN(B7:B18) -> 0.4621
A23: import-reach (charge) | C23: =MAX(0,MAX(D7:D18)) -> 0.3147
A24: export-reach (dischg) | C24: =MAX(0,-MIN(D7:D18)) -> 0.1474
A25: verdict | C25: =IF(AND(C23>0.02,C24>0.02),"two-sided → can charge (import) or discharge (export)",IF(C23<=0.02,"one-sided → discharge/export only (no import headroom)","one-sided → charge/import only (no export headroom)")) -> two-sided → can charge (import) or discharge (export)
A26: what stops it | C26: =IF(AND(C23>0.02,C24>0.02),"both directions have headroom",IF(C23<=0.02,"blocked at 0°: Vmax there = "&TEXT('4_All_periods'!H50,"0.00000")&" pu"&IF('4_All_periods'!H50>=1.0999," → over-voltage limit is active"," → clear of the limit, so the battery bounds it"),"blocked at 180°: Vmax there = "&TEXT('4_All_periods'!H56,"0.00000")&" pu"&IF('4_All_periods'!H56>=1.0999," → over-voltage limit is active"," → clear of the limit, so the battery bounds it"))) -> both directions have headroom
A27: Tip: change any light-blue P/Q or the pink baseline and the amber cells + both charts update automatically.

Sheet P06_02h30
A1: TR9 rolling FOR — period 6 = 02:30
A3: BASELINE B ≈ load − PV, batteries OFF — the all-idle PCC point (also carries losses). This is the UNCONTROLLABLE PV commitment; the battery deviates around it:
A4: B_P (MW) = | B4: ='4_All_periods'!I62 -> 0.3055 | C4: B_Q (MVAr) = | D4: ='4_All_periods'!J62 -> 0.0625
A6: angle_deg | B6: P_abs (MW) | C6: Q_abs (MVAr) | D6: dP = P − B_P | E6: dQ = Q − B_Q | F6: proj check | G6: battery side
A7: ='4_All_periods'!C62 -> 0 | B7: ='4_All_periods'!D62 -> 0.6328 | C7: ='4_All_periods'!E62 -> 0.055 | D7: =B7-$B$4 -> 0.3273 | E7: =C7-$D$4 -> -0.0075 | F7: =B7*COS(RADIANS(A7))+C7*SIN(RADIANS(A7)) -> 0.6328 | G7: =IF(D7>0,"charge/import","discharge/export") -> charge/import
A8: ='4_All_periods'!C63 -> 30 | B8: ='4_All_periods'!D63 -> 0.5845 | C8: ='4_All_periods'!E63 -> 0.2275 | D8: =B8-$B$4 -> 0.279 | E8: =C8-$D$4 -> 0.165 | F8: =B8*COS(RADIANS(A8))+C8*SIN(RADIANS(A8)) -> 0.61994185 | G8: =IF(D8>0,"charge/import","discharge/export") -> charge/import
A9: ='4_All_periods'!C64 -> 60 | B9: ='4_All_periods'!D64 -> 0.4671 | C9: ='4_All_periods'!E64 -> 0.3456 | D9: =B9-$B$4 -> 0.1616 | E9: =C9-$D$4 -> 0.2831 | F9: =B9*COS(RADIANS(A9))+C9*SIN(RADIANS(A9)) -> 0.53284838 | G9: =IF(D9>0,"charge/import","discharge/export") -> charge/import
A10: ='4_All_periods'!C65 -> 90 | B10: ='4_All_periods'!D65 -> 0.3122 | C10: ='4_All_periods'!E65 -> 0.3858 | D10: =B10-$B$4 -> 0.0067 | E10: =C10-$D$4 -> 0.3233 | F10: =B10*COS(RADIANS(A10))+C10*SIN(RADIANS(A10)) -> 0.3858 | G10: =IF(D10>0,"charge/import","discharge/export") -> charge/import
A11: ='4_All_periods'!C66 -> 120 | B11: ='4_All_periods'!D66 -> 0.1862 | C11: ='4_All_periods'!E66 -> 0.3571 | D11: =B11-$B$4 -> -0.1193 | E11: =C11-$D$4 -> 0.2946 | F11: =B11*COS(RADIANS(A11))+C11*SIN(RADIANS(A11)) -> 0.21615767 | G11: =IF(D11>0,"charge/import","discharge/export") -> discharge/export
A12: ='4_All_periods'!C67 -> 150 | B12: ='4_All_periods'!D67 -> 0.1838 | C12: ='4_All_periods'!E67 -> 0.3556 | D12: =B12-$B$4 -> -0.1217 | E12: =C12-$D$4 -> 0.2931 | F12: =B12*COS(RADIANS(A12))+C12*SIN(RADIANS(A12)) -> 0.018624531 | G12: =IF(D12>0,"charge/import","discharge/export") -> discharge/export
A13: ='4_All_periods'!C68 -> 180 | B13: ='4_All_periods'!D68 -> 0.1816 | C13: ='4_All_periods'!E68 -> -0.1997 | D13: =B13-$B$4 -> -0.1239 | E13: =C13-$D$4 -> -0.2622 | F13: =B13*COS(RADIANS(A13))+C13*SIN(RADIANS(A13)) -> -0.1816 | G13: =IF(D13>0,"charge/import","discharge/export") -> discharge/export
A14: ='4_All_periods'!C69 -> 210 | B14: ='4_All_periods'!D69 -> 0.1899 | C14: ='4_All_periods'!E69 -> -0.2288 | D14: =B14-$B$4 -> -0.1156 | E14: =C14-$D$4 -> -0.2913 | F14: =B14*COS(RADIANS(A14))+C14*SIN(RADIANS(A14)) -> -0.050058224 | G14: =IF(D14>0,"charge/import","discharge/export") -> discharge/export
A15: ='4_All_periods'!C70 -> 240 | B15: ='4_All_periods'!D70 -> 0.1993 | C15: ='4_All_periods'!E70 -> -0.2353 | D15: =B15-$B$4 -> -0.1062 | E15: =C15-$D$4 -> -0.2978 | F15: =B15*COS(RADIANS(A15))+C15*SIN(RADIANS(A15)) -> 0.10412578 | G15: =IF(D15>0,"charge/import","discharge/export") -> discharge/export
A16: ='4_All_periods'!C71 -> 270 | B16: ='4_All_periods'!D71 -> 0.3066 | C16: ='4_All_periods'!E71 -> -0.2593 | D16: =B16-$B$4 -> 0.0011 | E16: =C16-$D$4 -> -0.3218 | F16: =B16*COS(RADIANS(A16))+C16*SIN(RADIANS(A16)) -> 0.2593 | G16: =IF(D16>0,"charge/import","discharge/export") -> charge/import
A17: ='4_All_periods'!C72 -> 300 | B17: ='4_All_periods'!D72 -> 0.4705 | C17: ='4_All_periods'!E72 -> -0.2153 | D17: =B17-$B$4 -> 0.165 | E17: =C17-$D$4 -> -0.2778 | F17: =B17*COS(RADIANS(A17))+C17*SIN(RADIANS(A17)) -> 0.42170527 | G17: =IF(D17>0,"charge/import","discharge/export") -> charge/import
A18: ='4_All_periods'!C73 -> 330 | B18: ='4_All_periods'!D73 -> 0.5905 | C18: ='4_All_periods'!E73 -> -0.0954 | D18: =B18-$B$4 -> 0.285 | E18: =C18-$D$4 -> -0.1579 | F18: =B18*COS(RADIANS(A18))+C18*SIN(RADIANS(A18)) -> 0.559088 | G18: =IF(D18>0,"charge/import","discharge/export") -> charge/import
A19: (close) | B19: =B7 -> 0.6328 | C19: =C7 -> 0.055 | D19: =D7 -> 0.3273 | E19: =E7 -> -0.0075
A21: Interpretation (all computed live):
A22: P width (MW) | C22: =MAX(B7:B18)-MIN(B7:B18) -> 0.4512
A23: import-reach (charge) | C23: =MAX(0,MAX(D7:D18)) -> 0.3273
A24: export-reach (dischg) | C24: =MAX(0,-MIN(D7:D18)) -> 0.1239
A25: verdict | C25: =IF(AND(C23>0.02,C24>0.02),"two-sided → can charge (import) or discharge (export)",IF(C23<=0.02,"one-sided → discharge/export only (no import headroom)","one-sided → charge/import only (no export headroom)")) -> two-sided → can charge (import) or discharge (export)
A26: what stops it | C26: =IF(AND(C23>0.02,C24>0.02),"both directions have headroom",IF(C23<=0.02,"blocked at 0°: Vmax there = "&TEXT('4_All_periods'!H62,"0.00000")&" pu"&IF('4_All_periods'!H62>=1.0999," → over-voltage limit is active"," → clear of the limit, so the battery bounds it"),"blocked at 180°: Vmax there = "&TEXT('4_All_periods'!H68,"0.00000")&" pu"&IF('4_All_periods'!H68>=1.0999," → over-voltage limit is active"," → clear of the limit, so the battery bounds it"))) -> both directions have headroom
A27: Tip: change any light-blue P/Q or the pink baseline and the amber cells + both charts update automatically.

Sheet P07_03h00
A1: TR9 rolling FOR — period 7 = 03:00
A3: BASELINE B ≈ load − PV, batteries OFF — the all-idle PCC point (also carries losses). This is the UNCONTROLLABLE PV commitment; the battery deviates around it:
A4: B_P (MW) = | B4: ='4_All_periods'!I74 -> 0.3093 | C4: B_Q (MVAr) = | D4: ='4_All_periods'!J74 -> 0.0632
A6: angle_deg | B6: P_abs (MW) | C6: Q_abs (MVAr) | D6: dP = P − B_P | E6: dQ = Q − B_Q | F6: proj check | G6: battery side
A7: ='4_All_periods'!C74 -> 0 | B7: ='4_All_periods'!D74 -> 0.636 | C7: ='4_All_periods'!E74 -> 0.0577 | D7: =B7-$B$4 -> 0.3267 | E7: =C7-$D$4 -> -0.0055 | F7: =B7*COS(RADIANS(A7))+C7*SIN(RADIANS(A7)) -> 0.636 | G7: =IF(D7>0,"charge/import","discharge/export") -> charge/import
A8: ='4_All_periods'!C75 -> 30 | B8: ='4_All_periods'!D75 -> 0.5875 | C8: ='4_All_periods'!E75 -> 0.2294 | D8: =B8-$B$4 -> 0.2782 | E8: =C8-$D$4 -> 0.1662 | F8: =B8*COS(RADIANS(A8))+C8*SIN(RADIANS(A8)) -> 0.62348992 | G8: =IF(D8>0,"charge/import","discharge/export") -> charge/import
A9: ='4_All_periods'!C76 -> 60 | B9: ='4_All_periods'!D76 -> 0.4724 | C9: ='4_All_periods'!E76 -> 0.3459 | D9: =B9-$B$4 -> 0.1631 | E9: =C9-$D$4 -> 0.2827 | F9: =B9*COS(RADIANS(A9))+C9*SIN(RADIANS(A9)) -> 0.53575819 | G9: =IF(D9>0,"charge/import","discharge/export") -> charge/import
A10: ='4_All_periods'!C77 -> 90 | B10: ='4_All_periods'!D77 -> 0.3152 | C10: ='4_All_periods'!E77 -> 0.3871 | D10: =B10-$B$4 -> 0.0059 | E10: =C10-$D$4 -> 0.3239 | F10: =B10*COS(RADIANS(A10))+C10*SIN(RADIANS(A10)) -> 0.3871 | G10: =IF(D10>0,"charge/import","discharge/export") -> charge/import
A11: ='4_All_periods'!C78 -> 120 | B11: ='4_All_periods'!D78 -> 0.1996 | C11: ='4_All_periods'!E78 -> 0.3624 | D11: =B11-$B$4 -> -0.1097 | E11: =C11-$D$4 -> 0.2992 | F11: =B11*COS(RADIANS(A11))+C11*SIN(RADIANS(A11)) -> 0.21404761 | G11: =IF(D11>0,"charge/import","discharge/export") -> discharge/export
A12: ='4_All_periods'!C79 -> 150 | B12: ='4_All_periods'!D79 -> 0.1982 | C12: ='4_All_periods'!E79 -> 0.3615 | D12: =B12-$B$4 -> -0.1111 | E12: =C12-$D$4 -> 0.2983 | F12: =B12*COS(RADIANS(A12))+C12*SIN(RADIANS(A12)) -> 0.009103765 | G12: =IF(D12>0,"charge/import","discharge/export") -> discharge/export
A13: ='4_All_periods'!C80 -> 180 | B13: ='4_All_periods'!D80 -> 0.1958 | C13: ='4_All_periods'!E80 -> -0.2016 | D13: =B13-$B$4 -> -0.1135 | E13: =C13-$D$4 -> -0.2648 | F13: =B13*COS(RADIANS(A13))+C13*SIN(RADIANS(A13)) -> -0.1958 | G13: =IF(D13>0,"charge/import","discharge/export") -> discharge/export
A14: ='4_All_periods'!C81 -> 210 | B14: ='4_All_periods'!D81 -> 0.2031 | C14: ='4_All_periods'!E81 -> -0.231 | D14: =B14-$B$4 -> -0.1062 | E14: =C14-$D$4 -> -0.2942 | F14: =B14*COS(RADIANS(A14))+C14*SIN(RADIANS(A14)) -> -0.06038976 | G14: =IF(D14>0,"charge/import","discharge/export") -> discharge/export
A15: ='4_All_periods'!C82 -> 240 | B15: ='4_All_periods'!D82 -> 0.211 | C15: ='4_All_periods'!E82 -> -0.2363 | D15: =B15-$B$4 -> -0.0983 | E15: =C15-$D$4 -> -0.2995 | F15: =B15*COS(RADIANS(A15))+C15*SIN(RADIANS(A15)) -> 0.099141803 | G15: =IF(D15>0,"charge/import","discharge/export") -> discharge/export
A16: ='4_All_periods'!C83 -> 270 | B16: ='4_All_periods'!D83 -> 0.3094 | C16: ='4_All_periods'!E83 -> -0.258 | D16: =B16-$B$4 -> 0.0001 | E16: =C16-$D$4 -> -0.3212 | F16: =B16*COS(RADIANS(A16))+C16*SIN(RADIANS(A16)) -> 0.258 | G16: =IF(D16>0,"charge/import","discharge/export") -> charge/import
A17: ='4_All_periods'!C84 -> 300 | B17: ='4_All_periods'!D84 -> 0.4733 | C17: ='4_All_periods'!E84 -> -0.214 | D17: =B17-$B$4 -> 0.164 | E17: =C17-$D$4 -> -0.2772 | F17: =B17*COS(RADIANS(A17))+C17*SIN(RADIANS(A17)) -> 0.42197944 | G17: =IF(D17>0,"charge/import","discharge/export") -> charge/import
A18: ='4_All_periods'!C85 -> 330 | B18: ='4_All_periods'!D85 -> 0.5934 | C18: ='4_All_periods'!E85 -> -0.0941 | D18: =B18-$B$4 -> 0.2841 | E18: =C18-$D$4 -> -0.1573 | F18: =B18*COS(RADIANS(A18))+C18*SIN(RADIANS(A18)) -> 0.56094947 | G18: =IF(D18>0,"charge/import","discharge/export") -> charge/import
A19: (close) | B19: =B7 -> 0.636 | C19: =C7 -> 0.0577 | D19: =D7 -> 0.3267 | E19: =E7 -> -0.0055
A21: Interpretation (all computed live):
A22: P width (MW) | C22: =MAX(B7:B18)-MIN(B7:B18) -> 0.4402
A23: import-reach (charge) | C23: =MAX(0,MAX(D7:D18)) -> 0.3267
A24: export-reach (dischg) | C24: =MAX(0,-MIN(D7:D18)) -> 0.1135
A25: verdict | C25: =IF(AND(C23>0.02,C24>0.02),"two-sided → can charge (import) or discharge (export)",IF(C23<=0.02,"one-sided → discharge/export only (no import headroom)","one-sided → charge/import only (no export headroom)")) -> two-sided → can charge (import) or discharge (export)
A26: what stops it | C26: =IF(AND(C23>0.02,C24>0.02),"both directions have headroom",IF(C23<=0.02,"blocked at 0°: Vmax there = "&TEXT('4_All_periods'!H74,"0.00000")&" pu"&IF('4_All_periods'!H74>=1.0999," → over-voltage limit is active"," → clear of the limit, so the battery bounds it"),"blocked at 180°: Vmax there = "&TEXT('4_All_periods'!H80,"0.00000")&" pu"&IF('4_All_periods'!H80>=1.0999," → over-voltage limit is active"," → clear of the limit, so the battery bounds it"))) -> both directions have headroom
A27: Tip: change any light-blue P/Q or the pink baseline and the amber cells + both charts update automatically.

Sheet P08_03h30
A1: TR9 rolling FOR — period 8 = 03:30
A3: BASELINE B ≈ load − PV, batteries OFF — the all-idle PCC point (also carries losses). This is the UNCONTROLLABLE PV commitment; the battery deviates around it:
A4: B_P (MW) = | B4: ='4_All_periods'!I86 -> 0.3123 | C4: B_Q (MVAr) = | D4: ='4_All_periods'!J86 -> 0.0645
A6: angle_deg | B6: P_abs (MW) | C6: Q_abs (MVAr) | D6: dP = P − B_P | E6: dQ = Q − B_Q | F6: proj check | G6: battery side
A7: ='4_All_periods'!C86 -> 0 | B7: ='4_All_periods'!D86 -> 0.5677 | C7: ='4_All_periods'!E86 -> 0.0512 | D7: =B7-$B$4 -> 0.2554 | E7: =C7-$D$4 -> -0.0133 | F7: =B7*COS(RADIANS(A7))+C7*SIN(RADIANS(A7)) -> 0.5677 | G7: =IF(D7>0,"charge/import","discharge/export") -> charge/import
A8: ='4_All_periods'!C87 -> 30 | B8: ='4_All_periods'!D87 -> 0.5191 | C8: ='4_All_periods'!E87 -> 0.2241 | D8: =B8-$B$4 -> 0.2068 | E8: =C8-$D$4 -> 0.1596 | F8: =B8*COS(RADIANS(A8))+C8*SIN(RADIANS(A8)) -> 0.56160379 | G8: =IF(D8>0,"charge/import","discharge/export") -> charge/import
A9: ='4_All_periods'!C88 -> 60 | B9: ='4_All_periods'!D88 -> 0.4039 | C9: ='4_All_periods'!E88 -> 0.3407 | D9: =B9-$B$4 -> 0.0916 | E9: =C9-$D$4 -> 0.2762 | F9: =B9*COS(RADIANS(A9))+C9*SIN(RADIANS(A9)) -> 0.49700486 | G9: =IF(D9>0,"charge/import","discharge/export") -> charge/import
A10: ='4_All_periods'!C89 -> 90 | B10: ='4_All_periods'!D89 -> 0.2468 | C10: ='4_All_periods'!E89 -> 0.382 | D10: =B10-$B$4 -> -0.0655 | E10: =C10-$D$4 -> 0.3175 | F10: =B10*COS(RADIANS(A10))+C10*SIN(RADIANS(A10)) -> 0.382 | G10: =IF(D10>0,"charge/import","discharge/export") -> discharge/export
A11: ='4_All_periods'!C90 -> 120 | B11: ='4_All_periods'!D90 -> 0.1424 | C11: ='4_All_periods'!E90 -> 0.361 | D11: =B11-$B$4 -> -0.1699 | E11: =C11-$D$4 -> 0.2965 | F11: =B11*COS(RADIANS(A11))+C11*SIN(RADIANS(A11)) -> 0.24143517 | G11: =IF(D11>0,"charge/import","discharge/export") -> discharge/export
A12: ='4_All_periods'!C91 -> 150 | B12: ='4_All_periods'!D91 -> 0.1414 | C12: ='4_All_periods'!E91 -> 0.3604 | D12: =B12-$B$4 -> -0.1709 | E12: =C12-$D$4 -> 0.2959 | F12: =B12*COS(RADIANS(A12))+C12*SIN(RADIANS(A12)) -> 0.057744008 | G12: =IF(D12>0,"charge/import","discharge/export") -> discharge/export
A13: ='4_All_periods'!C92 -> 180 | B13: ='4_All_periods'!D92 -> 0.1394 | C13: ='4_All_periods'!E92 -> -0.2162 | D13: =B13-$B$4 -> -0.1729 | E13: =C13-$D$4 -> -0.2807 | F13: =B13*COS(RADIANS(A13))+C13*SIN(RADIANS(A13)) -> -0.1394 | G13: =IF(D13>0,"charge/import","discharge/export") -> discharge/export
A14: ='4_All_periods'!C93 -> 210 | B14: ='4_All_periods'!D93 -> 0.1458 | C14: ='4_All_periods'!E93 -> -0.2395 | D14: =B14-$B$4 -> -0.1665 | E14: =C14-$D$4 -> -0.304 | F14: =B14*COS(RADIANS(A14))+C14*SIN(RADIANS(A14)) -> -0.0065165039 | G14: =IF(D14>0,"charge/import","discharge/export") -> discharge/export
A15: ='4_All_periods'!C94 -> 240 | B15: ='4_All_periods'!D94 -> 0.1533 | C15: ='4_All_periods'!E94 -> -0.2446 | D15: =B15-$B$4 -> -0.159 | E15: =C15-$D$4 -> -0.3091 | F15: =B15*COS(RADIANS(A15))+C15*SIN(RADIANS(A15)) -> 0.13517981 | G15: =IF(D15>0,"charge/import","discharge/export") -> discharge/export
A16: ='4_All_periods'!C95 -> 270 | B16: ='4_All_periods'!D95 -> 0.242 | C16: ='4_All_periods'!E95 -> -0.2634 | D16: =B16-$B$4 -> -0.0703 | E16: =C16-$D$4 -> -0.3279 | F16: =B16*COS(RADIANS(A16))+C16*SIN(RADIANS(A16)) -> 0.2634 | G16: =IF(D16>0,"charge/import","discharge/export") -> discharge/export
A17: ='4_All_periods'!C96 -> 300 | B17: ='4_All_periods'!D96 -> 0.4055 | C17: ='4_All_periods'!E96 -> -0.2195 | D17: =B17-$B$4 -> 0.0932 | E17: =C17-$D$4 -> -0.284 | F17: =B17*COS(RADIANS(A17))+C17*SIN(RADIANS(A17)) -> 0.39284258 | G17: =IF(D17>0,"charge/import","discharge/export") -> charge/import
A18: ='4_All_periods'!C97 -> 330 | B18: ='4_All_periods'!D97 -> 0.5252 | C18: ='4_All_periods'!E97 -> -0.0998 | D18: =B18-$B$4 -> 0.2129 | E18: =C18-$D$4 -> -0.1643 | F18: =B18*COS(RADIANS(A18))+C18*SIN(RADIANS(A18)) -> 0.50473654 | G18: =IF(D18>0,"charge/import","discharge/export") -> charge/import
A19: (close) | B19: =B7 -> 0.5677 | C19: =C7 -> 0.0512 | D19: =D7 -> 0.2554 | E19: =E7 -> -0.0133
A21: Interpretation (all computed live):
A22: P width (MW) | C22: =MAX(B7:B18)-MIN(B7:B18) -> 0.4283
A23: import-reach (charge) | C23: =MAX(0,MAX(D7:D18)) -> 0.2554
A24: export-reach (dischg) | C24: =MAX(0,-MIN(D7:D18)) -> 0.1729
A25: verdict | C25: =IF(AND(C23>0.02,C24>0.02),"two-sided → can charge (import) or discharge (export)",IF(C23<=0.02,"one-sided → discharge/export only (no import headroom)","one-sided → charge/import only (no export headroom)")) -> two-sided → can charge (import) or discharge (export)
A26: what stops it | C26: =IF(AND(C23>0.02,C24>0.02),"both directions have headroom",IF(C23<=0.02,"blocked at 0°: Vmax there = "&TEXT('4_All_periods'!H86,"0.00000")&" pu"&IF('4_All_periods'!H86>=1.0999," → over-voltage limit is active"," → clear of the limit, so the battery bounds it"),"blocked at 180°: Vmax there = "&TEXT('4_All_periods'!H92,"0.00000")&" pu"&IF('4_All_periods'!H92>=1.0999," → over-voltage limit is active"," → clear of the limit, so the battery bounds it"))) -> both directions have headroom
A27: Tip: change any light-blue P/Q or the pink baseline and the amber cells + both charts update automatically.

Sheet P09_04h00
A1: TR9 rolling FOR — period 9 = 04:00
A3: BASELINE B ≈ load − PV, batteries OFF — the all-idle PCC point (also carries losses). This is the UNCONTROLLABLE PV commitment; the battery deviates around it:
A4: B_P (MW) = | B4: ='4_All_periods'!I98 -> 0.2443 | C4: B_Q (MVAr) = | D4: ='4_All_periods'!J98 -> 0.0593
A6: angle_deg | B6: P_abs (MW) | C6: Q_abs (MVAr) | D6: dP = P − B_P | E6: dQ = Q − B_Q | F6: proj check | G6: battery side
A7: ='4_All_periods'!C98 -> 0 | B7: ='4_All_periods'!D98 -> 0.4081 | C7: ='4_All_periods'!E98 -> 0.0588 | D7: =B7-$B$4 -> 0.1638 | E7: =C7-$D$4 -> -0.0005 | F7: =B7*COS(RADIANS(A7))+C7*SIN(RADIANS(A7)) -> 0.4081 | G7: =IF(D7>0,"charge/import","discharge/export") -> charge/import
A8: ='4_All_periods'!C99 -> 30 | B8: ='4_All_periods'!D99 -> 0.3607 | C8: ='4_All_periods'!E99 -> 0.2255 | D8: =B8-$B$4 -> 0.1164 | E8: =C8-$D$4 -> 0.1662 | F8: =B8*COS(RADIANS(A8))+C8*SIN(RADIANS(A8)) -> 0.42512536 | G8: =IF(D8>0,"charge/import","discharge/export") -> charge/import
A9: ='4_All_periods'!C100 -> 60 | B9: ='4_All_periods'!D100 -> 0.2456 | C9: ='4_All_periods'!E100 -> 0.3421 | D9: =B9-$B$4 -> 0.0013 | E9: =C9-$D$4 -> 0.2828 | F9: =B9*COS(RADIANS(A9))+C9*SIN(RADIANS(A9)) -> 0.41906729 | G9: =IF(D9>0,"charge/import","discharge/export") -> charge/import
A10: ='4_All_periods'!C101 -> 90 | B10: ='4_All_periods'!D101 -> 0.0862 | C10: ='4_All_periods'!E101 -> 0.3843 | D10: =B10-$B$4 -> -0.1581 | E10: =C10-$D$4 -> 0.325 | F10: =B10*COS(RADIANS(A10))+C10*SIN(RADIANS(A10)) -> 0.3843 | G10: =IF(D10>0,"charge/import","discharge/export") -> discharge/export
A11: ='4_All_periods'!C102 -> 120 | B11: ='4_All_periods'!D102 -> -0.0107 | C11: ='4_All_periods'!E102 -> 0.3656 | D11: =B11-$B$4 -> -0.255 | E11: =C11-$D$4 -> 0.3063 | F11: =B11*COS(RADIANS(A11))+C11*SIN(RADIANS(A11)) -> 0.32196889 | G11: =IF(D11>0,"charge/import","discharge/export") -> discharge/export
A12: ='4_All_periods'!C103 -> 150 | B12: ='4_All_periods'!D103 -> -0.0116 | C12: ='4_All_periods'!E103 -> 0.3651 | D12: =B12-$B$4 -> -0.2559 | E12: =C12-$D$4 -> 0.3058 | F12: =B12*COS(RADIANS(A12))+C12*SIN(RADIANS(A12)) -> 0.19259589 | G12: =IF(D12>0,"charge/import","discharge/export") -> discharge/export
A13: ='4_All_periods'!C104 -> 180 | B13: ='4_All_periods'!D104 -> -0.0131 | C13: ='4_All_periods'!E104 -> -0.2082 | D13: =B13-$B$4 -> -0.2574 | E13: =C13-$D$4 -> -0.2675 | F13: =B13*COS(RADIANS(A13))+C13*SIN(RADIANS(A13)) -> 0.0131 | G13: =IF(D13>0,"charge/import","discharge/export") -> discharge/export
A14: ='4_All_periods'!C105 -> 210 | B14: ='4_All_periods'!D105 -> -0.0059 | C14: ='4_All_periods'!E105 -> -0.2385 | D14: =B14-$B$4 -> -0.2502 | E14: =C14-$D$4 -> -0.2978 | F14: =B14*COS(RADIANS(A14))+C14*SIN(RADIANS(A14)) -> 0.12435955 | G14: =IF(D14>0,"charge/import","discharge/export") -> discharge/export
A15: ='4_All_periods'!C106 -> 240 | B15: ='4_All_periods'!D106 -> 0.0026 | C15: ='4_All_periods'!E106 -> -0.2441 | D15: =B15-$B$4 -> -0.2417 | E15: =C15-$D$4 -> -0.3034 | F15: =B15*COS(RADIANS(A15))+C15*SIN(RADIANS(A15)) -> 0.2100968 | G15: =IF(D15>0,"charge/import","discharge/export") -> discharge/export
A16: ='4_All_periods'!C107 -> 270 | B16: ='4_All_periods'!D107 -> 0.0839 | C16: ='4_All_periods'!E107 -> -0.262 | D16: =B16-$B$4 -> -0.1604 | E16: =C16-$D$4 -> -0.3213 | F16: =B16*COS(RADIANS(A16))+C16*SIN(RADIANS(A16)) -> 0.262 | G16: =IF(D16>0,"charge/import","discharge/export") -> discharge/export
A17: ='4_All_periods'!C108 -> 300 | B17: ='4_All_periods'!D108 -> 0.2455 | C17: ='4_All_periods'!E108 -> -0.2184 | D17: =B17-$B$4 -> 0.0012 | E17: =C17-$D$4 -> -0.2777 | F17: =B17*COS(RADIANS(A17))+C17*SIN(RADIANS(A17)) -> 0.31188995 | G17: =IF(D17>0,"charge/import","discharge/export") -> charge/import
A18: ='4_All_periods'!C109 -> 330 | B18: ='4_All_periods'!D109 -> 0.3649 | C18: ='4_All_periods'!E109 -> -0.099 | D18: =B18-$B$4 -> 0.1206 | E18: =C18-$D$4 -> -0.1583 | F18: =B18*COS(RADIANS(A18))+C18*SIN(RADIANS(A18)) -> 0.36551267 | G18: =IF(D18>0,"charge/import","discharge/export") -> charge/import
A19: (close) | B19: =B7 -> 0.4081 | C19: =C7 -> 0.0588 | D19: =D7 -> 0.1638 | E19: =E7 -> -0.0005
A21: Interpretation (all computed live):
A22: P width (MW) | C22: =MAX(B7:B18)-MIN(B7:B18) -> 0.4212
A23: import-reach (charge) | C23: =MAX(0,MAX(D7:D18)) -> 0.1638
A24: export-reach (dischg) | C24: =MAX(0,-MIN(D7:D18)) -> 0.2574
A25: verdict | C25: =IF(AND(C23>0.02,C24>0.02),"two-sided → can charge (import) or discharge (export)",IF(C23<=0.02,"one-sided → discharge/export only (no import headroom)","one-sided → charge/import only (no export headroom)")) -> two-sided → can charge (import) or discharge (export)
A26: what stops it | C26: =IF(AND(C23>0.02,C24>0.02),"both directions have headroom",IF(C23<=0.02,"blocked at 0°: Vmax there = "&TEXT('4_All_periods'!H98,"0.00000")&" pu"&IF('4_All_periods'!H98>=1.0999," → over-voltage limit is active"," → clear of the limit, so the battery bounds it"),"blocked at 180°: Vmax there = "&TEXT('4_All_periods'!H104,"0.00000")&" pu"&IF('4_All_periods'!H104>=1.0999," → over-voltage limit is active"," → clear of the limit, so the battery bounds it"))) -> both directions have headroom
A27: Tip: change any light-blue P/Q or the pink baseline and the amber cells + both charts update automatically.

Sheet P10_04h30
A1: TR9 rolling FOR — period 10 = 04:30
